File: Test_12.csv
Time On Sample,Displacement Into Surface,Load On Sample,Harmonic Contact Stiffness,Harmonic Displacement,Harmonic Load
0,0,0,-459.1150507,0.260534401,2.261943449
0.2,-0.016282975,0.000759521,7068.536116,0.177320236,2.333854944
0.4,0.181413487,0.00150283,12913.85363,0.159893188,2.398139491
0.6,0.139785375,0.002264272,15393.2886,0.155100749,2.454797032
0.8,0.245242158,0.003014569,17561.55931,0.152051017,2.641113199
1,0.111374366,0.003783,18342.86404,0.15379372,2.78493618
1.2,0.51557138,0.004510662,19666.64331,0.153793725,2.962535846
1.4,0.538344847,0.005267224,21913.45583,0.147694257,3.139045897
1.6,0.470540608,0.00603065,25907.6848,0.134623969,3.378750887
1.8,0.809505064,0.006763254,32186.65519,0.120246655,3.76445808
2,0.811919323,0.007521359,37819.83445,0.111968805,4.138179968
2.2,0.85505217,0.00827532,43001.53265,0.10674069,4.510812311
2.4,0.914804929,0.009027082,45579.85345,0.107176367,4.879086373
2.6,0.686204799,0.009800693,44721.98609,0.114147186,5.207046343
2.8,0.912155189,0.010539862,45373.41263,0.128960182,6.039476505
3,0.907090872,0.011296535,48044.43679,0.138980737,6.811980357
3.2,0.839702444,0.012057931,48828.18683,0.153358054,7.573588513
3.4,0.850426902,0.012813408,48366.82801,0.167735372,8.158686662
3.6,0.970841798,0.013560574,46744.41213,0.196054333,9.10552147
3.8,1.069651003,0.014309376,46553.59073,0.221759236,10.18637319
4,0.979825893,0.015072471,45128.18397,0.252256575,11.26504568
4.2,1.088606957,0.015820517,44051.11577,0.277525803,12.11708808
4.4,1.110965251,0.016575112,42516.66577,0.313251261,13.19902932
4.6,1.044407809,0.017336444,42080.71911,0.339391837,14.12298311
4.8,1.279499079,0.01807492,42113.68124,0.372503243,15.50237665
5,1.408223863,0.018821455,41905.39114,0.400386531,16.5124066
5.2,1.149708147,0.019597331,41193.01721,0.439161715,17.75015584
5.4,0.990080029,0.020365714,40537.33869,0.476194196,18.89965021
5.6,0.65760577,0.021150982,39461.23124,0.514533699,19.86391775
5.8,0.906823834,0.021888388,37646.83017,0.574221362,21.13435454
6,0.605928331,0.022663687,35585.16958,0.636958737,22.17162312
6.2,0.632441565,0.023417968,33306.17405,0.710152355,23.14133894
6.4,0.570870053,0.024178922,30899.09914,0.793366525,24.00645599
6.6,0.817595151,0.024916518,28895.15052,0.87091692,24.68634686
6.8,0.621403555,0.025687672,27024.46002,0.954566758,25.35752066
7,0.986959966,0.026416263,25176.14135,1.049544218,26.04503863
7.2,0.859740387,0.027182191,23849.70736,1.125351886,26.54515036
7.4,0.754957489,0.027946419,22393.98467,1.216843902,27.07359072
7.6,1.28006364,0.028662921,21256.74954,1.294830008,27.45711954
7.8,1.04564658,0.029436971,20418.92194,1.359310083,27.80904969
8,1.200962987,0.03018149,19738.48432,1.419869107,28.20783202
8.2,1.40115276,0.03092261,19411.97555,1.456465939,28.5238071
8.4,1.082805889,0.031703018,19360.7736,1.481299459,28.9737984
8.6,1.407643894,0.032434693,19709.98221,1.477814083,29.40417835
8.8,1.58955193,0.033177197,20081.63226,1.479556809,29.91627567
9,1.777276886,0.03391926,20490.25079,1.473457361,30.3215953
9.2,1.555324641,0.034692364,21159.32312,1.457772993,30.86528958
9.4,1.974895319,0.03541686,21776.92603,1.442088689,31.3316255
9.6,1.236899379,0.036229064,22448.98649,1.425097248,31.83827363
9.8,1.969752619,0.036929824,23491.7217,1.391985913,32.47458263
10,2.036153295,0.037681078,24333.35589,1.367152369,32.99866512
10.2,2.068483453,0.038434915,25441.58455,1.335348004,33.65676441
10.4,2.147348954,0.039185224,26714.32319,1.299186878,34.37043188
10.6,1.766677945,0.039970353,27890.25752,1.269125174,35.03506788
10.8,2.172952821,0.040695856,29095.69196,1.240370577,35.65612253
11,1.971775275,0.041467384,30432.15278,1.214229978,36.41555147
11.2,1.436540455,0.042264224,30934.96267,1.214229938,36.96578233
11.4,1.047559579,0.043049984,30308.9574,1.258233214,37.50729728
11.6,1.571003779,0.04376661,28856.03515,1.331426884,37.81019825
11.8,2.133504449,0.044480275,26455.93804,1.454287667,37.99542592
12,2.491582018,0.045209429,24827.03661,1.548393801,38.09130863
12.2,2.798138321,0.045942485,23807.69593,1.615923675,38.23949052
12.4,2.564552222,0.046716467,23862.21223,1.621587445,38.50098652
12.6,2.50464268,0.04747729,24976.93765,1.570177628,38.97276939
12.8,2.676578877,0.048220547,27148.49665,1.475635873,39.63086917
13,2.386485573,0.048998811,30072.23441,1.368895136,40.47637367
13.2,2.973084943,0.049710649,32773.96974,1.288295063,41.32623817
13.4,2.784372208,0.050481231,34356.20092,1.249955526,41.95056049
13.6,2.580701687,0.051252946,35361.38668,1.232964133,42.56071838
13.8,2.549045747,0.052011628,35629.36112,1.242984685,43.26675864
14,2.869728857,0.052743613,35623.74316,1.258669066,43.8780072
14.2,2.869650474,0.053499902,35576.26345,1.27391774,44.38465652
14.4,2.856276278,0.054257199,35420.92232,1.295701558,44.96212776
14.6,2.91852202,0.055008766,35274.32927,1.313999974,45.41538818
14.8,2.852795559,0.055770029,35185.52039,1.335783788,46.03426286
15,2.664082824,0.05654061,35092.2369,1.356260562,46.57795709
15.2,2.909976989,0.057278262,34995.22702,1.372380614,46.99090412
15.4,2.844250527,0.058039525,35025.3273,1.387193606,47.53568828
15.6,2.820904471,0.058797577,34985.39021,1.401570926,47.97260505
15.8,2.692022896,0.059563625,34825.89079,1.424226087,48.52174729
16,2.825733635,0.060309777,34790.12718,1.440346129,49.01859083
16.2,2.886317402,0.061061469,34718.25909,1.454723457,49.41737315
16.4,2.854661462,0.061820151,34532.68627,1.475200246,49.86736481
16.6,2.776470175,0.062582357,34320.66613,1.494370001,50.23128053
16.8,2.731518422,0.063342046,34294.57848,1.508747319,50.72703391
17,2.827003699,0.064091093,34228.85303,1.521381946,51.08877094
17.2,2.904622727,0.064841494,34205.50943,1.535323601,51.52241931
17.4,3.318376551,0.065566427,34250.30477,1.546215557,51.94408346
17.6,3.046564972,0.066343303,34536.69882,1.545779853,52.34722312
17.8,3.310325398,0.0670796,34808.4442,1.548393942,52.83426087
18,3.08338719,0.067853076,35120.56339,1.546215537,53.21778844
18.2,3.122780756,0.068606373,35615.11555,1.539244721,53.71136307
18.4,2.939884933,0.069376512,36305.59891,1.525738735,54.25069897
18.6,3.199490417,0.070113124,36720.46888,1.521817677,54.69524359
18.8,3.36353224,0.070856976,37235.00084,1.51528255,55.17465418
19,3.220108363,0.071624124,37820.15363,1.507440362,55.73033373
19.2,3.503397022,0.07235894,38389.16116,1.500033894,56.2903727
19.4,3.308451863,0.073129992,38718.82803,1.498726847,56.73273701
19.6,3.467507759,0.073874221,39291.69068,1.492191719,57.34071662
19.8,3.637782,0.0746176,39704.25848,1.48827065,57.81576902
20,3.347688667,0.07539586,40164.74096,1.485656564,58.39432908
20.2,3.672942246,0.076127497,40653.74687,1.482606864,58.97833863
20.4,3.532842318,0.076894392,41083.40221,1.47912144,59.45883784
20.6,3.507834285,0.077652567,41366.46953,1.481299822,59.9480542
20.8,3.765362313,0.078389334,41488.31127,1.491320408,60.52770546
21,3.584959446,0.079159283,41508.81672,1.503955007,61.05614557
21.2,3.717839212,0.079905495,41440.59943,1.516153963,61.45383857
21.4,3.683690306,0.080664362,41257.48581,1.534888048,61.92562153
21.6,3.809922166,0.081411077,41121.23994,1.549701062,62.30806063
21.8,3.891280652,0.082161192,41052.97452,1.564949748,62.81035196
22,4.268471026,0.082888892,40999.31687,1.578020084,63.25598659
22.2,3.95178551,0.083672547,40989.7068,1.587604933,63.62208086
22.4,4.083831933,0.084433666,41087.60368,1.595011449,64.07969994
22.6,4.000652346,0.085211114,41255.26994,1.598061177,64.47085478
22.8,3.989766895,0.085994773,41584.55946,1.596318472,64.91430909
23,4.002147885,0.08678444,42114.38371,1.588911976,65.43403341
23.2,3.874090545,0.087592821,42699.19678,1.580634111,65.99080239
23.4,4.084243597,0.088387569,43128.69345,1.575841695,66.43316807
23.6,4.212128812,0.089188435,43603.81377,1.570177918,66.90822038
23.8,3.97437715,0.090029309,44061.1327,1.567999512,67.49985525
24,4.102259102,0.090850701,44383.15235,1.569742242,68.04681952
24.2,4.329858344,0.091672888,44578.1315,1.572356319,68.46303517
24.4,4.415357221,0.092514269,44939.84141,1.571484977,69.00564066
24.6,4.396150195,0.093372102,45199.89263,1.57235633,69.4665281
24.8,4.586350951,0.094222352,45709.0887,1.568435264,70.09412029
25,4.562155277,0.095097656,46167.5182,1.563207146,70.57788865
25.2,4.477296062,0.095986252,46788.73425,1.556236316,71.19567393
25.4,4.793802889,0.096853248,47172.80118,1.554057969,71.66309979
25.6,4.507841645,0.097774766,47713.14241,1.551008205,72.31792955
25.8,4.639866175,0.09867367,47939.35731,1.55362228,72.78208626
26,5.036974595,0.099561598,48072.59212,1.561028825,73.32905121
26.2,4.598107118,0.100522028,48153.15357,1.569306633,73.86184862
26.4,4.915437681,0.101434618,48134.7408,1.578020198,74.26063193
26.6,4.720877855,0.102395221,48006.95071,1.593268856,74.81522152
26.8,5.181966437,0.103315794,48074.75911,1.599368379,75.23034891
27,5.767701895,0.104235885,48112.42975,1.608081976,75.73917966
27.2,5.585602397,0.105223787,48451.7196,1.607646282,76.2861423
27.4,5.84641827,0.106187788,49116.50128,1.59544737,76.76991194
27.6,5.831344382,0.107182485,50360.46954,1.57061381,77.49992279
27.8,6.08052328,0.108167119,51593.0439,1.546215954,78.16673993
28,6.227488999,0.109169479,53424.25857,1.510054826,79.0427535
28.2,5.924888271,0.110216079,54862.58567,1.486092586,79.86864541
28.4,6.113400165,0.111235754,55519.75089,1.479993135,80.48752137
28.6,5.893895,0.112296794,56044.98232,1.48086447,81.30905563
28.8,5.975206035,0.113345543,56206.01556,1.487399627,81.90613961
29,5.906937431,0.114416283,56136.48803,1.500905601,82.57731331
29.2,6.328950451,0.115460246,56202.50091,1.508747817,83.14171197
29.4,6.041297466,0.116568922,56473.81528,1.513975908,83.86518443
29.6,6.315391045,0.117645939,56685.12698,1.518332702,84.43394043
29.8,6.329383465,0.118753519,56987.04266,1.523996505,85.22823609
30,6.616769358,0.119851612,57228.37036,1.527917623,85.79699217
30.2,6.479518308,0.120992917,57467.17151,1.534452756,86.49867387
30.4,6.421209366,0.12213965,57886.19313,1.53663114,87.23304296
30.6,6.595575425,0.123280168,58239.01185,1.537938188,87.85300832
30.8,6.710939452,0.124436734,58742.30793,1.53575982,88.51873533
31,6.65844192,0.125617679,59304.65927,1.534017111,89.29232892
31.2,6.851915175,0.126791645,59970.76374,1.530096038,90.0997002
31.4,6.85509013,0.127991985,60603.64771,1.524432245,90.74472493
31.6,7.094263954,0.129186466,61134.25403,1.522253892,91.41154209
31.8,6.90630767,0.130425479,61791.12436,1.520946842,92.27121101
32,7.042435003,0.131652286,62569.95968,1.516590092,93.13632877
32.2,6.75475614,0.132923644,62973.95804,1.520075477,93.90011562
32.4,7.189204444,0.13415276,62932.50719,1.530967438,94.47540959
32.6,7.110930732,0.135433362,63023.93045,1.539680963,95.10517998
32.8,7.012711258,0.136728267,63133.05371,1.550137192,95.88857936
33,7.233589398,0.138011813,62994.08998,1.564950221,96.58263596
33.2,7.232591493,0.139325183,63103.00693,1.573228078,97.27669111
33.4,7.318845283,0.140645266,63420.8285,1.574535119,97.86723767
33.6,7.085997308,0.142002791,63905.25416,1.575406448,98.69421948
33.8,7.348416452,0.143336245,64241.14191,1.576713509,99.30219998
34,7.556819188,0.144687304,64736.42689,1.57714921,100.0768845
34.2,7.72782529,0.146054689,65087.27396,1.57845626,100.6826857
34.4,7.601335209,0.147458599,65488.85993,1.581070308,101.4399354
34.6,7.738681839,0.148856405,65697.15972,1.585862768,102.0522737
34.8,7.834892311,0.150271274,65916.86996,1.593269282,102.8367638
35,8.049931916,0.151691342,66488.68974,1.591090925,103.6081795
35.2,7.821636736,0.153159435,67173.97155,1.58499143,104.2673676
35.4,7.863826069,0.154621631,67982.35943,1.578456287,105.0878133
35.6,8.111267299,0.156082888,68694.05439,1.572792521,105.8189152
35.8,8.354551247,0.1575592,69667.53319,1.564079017,106.7668413
36,8.277486644,0.159074792,70034.93927,1.567564423,107.5774802
36.2,8.257757863,0.160601148,69904.8536,1.578456338,108.166937
36.4,8.249244991,0.162142003,69743.80656,1.591962314,108.906754
36.6,8.633787371,0.163668418,69753.65391,1.600240214,109.5332583
36.8,8.407966013,0.165256693,69739.3865,1.61069643,110.2507382
37,8.491685457,0.166837349,69792.64648,1.618974297,110.9289952
37.2,8.783149576,0.168418148,70279.54147,1.618538655,111.6426643
37.4,9.192611625,0.170005657,70836.95894,1.616795997,112.3672301
37.6,9.280062956,0.171633648,71228.51476,1.617667362,113.0307781
37.8,9.481772655,0.173269325,71880.82749,1.61592468,113.9165986
38,9.329478474,0.174948413,72651.2151,1.609389515,114.6411613
38.2,9.30349191,0.17663483,73500.39063,1.603290041,115.5444135
38.4,9.591616453,0.178314272,73989.67027,1.601983045,116.2297543
38.6,9.451779023,0.180043249,74538.6851,1.600676002,116.9750187
38.8,9.588658144,0.181768461,75373.76812,1.596319253,117.951273
39,9.479561805,0.183529679,75654.01168,1.599368979,118.6333426
39.2,9.792605006,0.185276517,75952.91109,1.604161459,119.4734023
39.4,9.758292047,0.187067405,76277.04345,1.606775517,120.1630992
39.6,9.67660985,0.188879954,76586.92261,1.609825247,120.8647811
39.8,9.891587813,0.190688046,76821.76247,1.6167961,121.7484226
40,9.711012168,0.192544403,77160.55409,1.619410141,122.4381187
40.2,9.75147661,0.194402575,77488.87246,1.624202591,123.2596541
40.4,9.944009049,0.196267898,77636.02446,1.629866412,123.9090383
40.6,9.804973943,0.198177114,77551.03811,1.639886961,124.5279131
40.8,9.963429823,0.200082868,77399.61863,1.653392958,125.3047767
41,10.07617671,0.202021059,76974.42539,1.669077333,125.8103374
41.2,10.14571061,0.203972392,76658.63778,1.683890351,126.4466459
41.4,10.21939791,0.205933112,76592.12327,1.692168218,126.9761768
41.6,10.18006602,0.207931942,76786.72806,1.695653629,127.5667235
41.8,10.1049984,0.209953661,76929.0934,1.701753096,128.2673159
42,9.911096142,0.212004717,77337.91699,1.700446045,128.8600402
42.2,10.06288201,0.214050057,77774.58414,1.700881742,129.5715295
42.4,10.11910089,0.216123157,78000.24526,1.705238518,130.2448835
42.6,10.47114853,0.218194533,78444.85896,1.703495855,130.8506862
42.8,10.44592383,0.220315739,79106.8901,1.697832057,131.5098755
43,10.07168041,0.22248463,79915.51489,1.691296865,132.3085273
43.2,10.23009747,0.22463468,80557.78161,1.686068765,132.9557322
43.4,10.48656778,0.226798901,81533.09848,1.67648391,133.7936122
43.6,10.15718741,0.229029561,81991.60626,1.675612521,134.4647848
43.8,10.37958015,0.231240559,82281.04089,1.679969316,135.286321
44,10.87619572,0.233453007,82129.84899,1.689118586,135.8147657
44.2,10.54929767,0.235750335,81750.58374,1.703931558,136.4260117
44.4,10.44094607,0.238054047,81221.175,1.720051585,136.8596595
44.6,10.84448,0.240341933,80848.17157,1.733557613,137.3314457
44.8,10.92226261,0.242677554,80393.24078,1.75011334,137.8860369
45,10.70670236,0.245059037,80461.21764,1.75490576,138.3589086
45.2,10.81937897,0.247439417,80864.66771,1.754470099,138.9854117
45.4,11.09077068,0.249831636,81503.44019,1.74924202,139.6446029
45.6,11.11286187,0.252266831,81901.51993,1.747934993,140.2068212
45.8,10.96127247,0.254739709,82122.71352,1.750113356,140.7483351
46,11.32489231,0.257198229,81980.12857,1.759698299,141.2822266
46.2,11.93614294,0.259662827,81733.00115,1.770154615,141.6864609
46.4,12.23743078,0.262175474,81422.42327,1.782789281,142.1506197
46.6,12.38996755,0.264724785,81615.66019,1.784096331,142.6060609
46.8,13.05355854,0.267260885,82324.22863,1.775818554,143.1748212
47,13.13794609,0.269866459,83800.88865,1.754470406,143.9778336
47.2,13.42924578,0.272482447,85295.63244,1.732250927,144.7252809
47.4,13.7363301,0.275123485,87125.66592,1.706110361,145.6775665
47.6,14.09908647,0.277786899,88547.43171,1.687811979,146.5078209
47.8,13.85106153,0.280523525,90003.20506,1.671256231,147.5516265
48,14.13320334,0.283247253,90791.29953,1.664721116,148.3328497
48.2,14.24498802,0.286011306,91640.7665,1.659928681,149.2949401
48.4,14.42740237,0.28879772,92649.48137,1.65165085,150.0968645
48.6,14.58405161,0.291614093,93537.62881,1.645987069,150.9347444
48.8,14.72490755,0.294460003,94423.45777,1.642937349,151.9829111
49,14.53585623,0.297359584,95054.29263,1.641630298,152.7989971
49.2,14.83625291,0.300251207,95976.13753,1.637273562,153.8068503
49.4,14.64968528,0.303208888,96486.19741,1.639016254,154.7852828
49.6,14.87195964,0.306165167,96937.56575,1.640758989,155.6754626
49.8,14.90974966,0.30916521,97522.46567,1.639887637,156.5176997
50,14.97578854,0.312193166,98312.15974,1.637709263,157.5647761
50.2,14.98282235,0.315256059,98784.53426,1.638144943,158.377595
50.4,15.15688008,0.318337124,99267.4814,1.639887672,159.361477
50.6,14.94618486,0.321478453,99375.96608,1.645987126,160.1764733
50.8,15.42271278,0.324598886,99453.60949,1.652522335,160.9773102
51,15.44136061,0.327785648,99589.62053,1.659493169,161.9154298
51.2,15.64697595,0.330990117,99807.39884,1.663849964,162.6857569
51.4,15.60079645,0.334245706,100344.1064,1.665592668,163.6718168
51.6,15.68507708,0.33752402,101230.3377,1.660364557,164.5565482
51.8,16.05770576,0.340813447,101989.3202,1.657314864,165.4783264
52,15.78465048,0.34418503,102414.3549,1.660364573,166.5046989
52.2,15.94453524,0.347557621,102653.1928,1.664721362,167.3621912
52.4,16.12768234,0.350962233,102845.0619,1.669513831,168.2033407
52.6,15.92399845,0.354430563,102821.3245,1.677355994,168.9496942
52.8,16.38011455,0.357883548,102879.6949,1.686069587,169.912877
53,16.3313991,0.361409738,103339.4381,1.686940937,170.6973668
53.2,16.48045348,0.364956347,104041.4896,1.686069603,171.7019511
53.4,16.36981803,0.368558299,104409.0989,1.688247977,172.4722756
53.6,16.20474703,0.372200504,104639.633,1.692169052,173.2404212
53.8,16.07540276,0.375876566,105434.4057,1.689990654,174.3114663
54,16.57511157,0.379541673,105788.9828,1.691733423,175.0992294
54.2,16.58286882,0.383281079,105687.1803,1.701318318,175.9621683
54.4,16.62552165,0.387055425,105601.3534,1.708724832,176.6485976
54.6,17.6483205,0.390792897,105570.9529,1.71526011,177.3481098
54.8,18.24024537,0.394600927,105302.5721,1.725716429,178.042171
55,18.25836593,0.398490941,104868.9806,1.739658096,178.7732721
55.2,18.33921998,0.40241524,105389.6314,1.739222431,179.6024355
55.4,18.13046796,0.406400841,106294.3692,1.732251577,180.365132
55.6,18.34925367,0.4103939,107039.9627,1.72876619,181.16161
55.8,18.40432806,0.414439624,108186.8413,1.721795367,182.2293882
56,18.76021419,0.418503067,109274.252,1.713081872,183.0727185
56.2,18.93161418,0.42262133,110168.7231,1.708725125,184.0827509
56.4,19.24759978,0.426769975,110601.3064,1.709160841,184.8432731
56.6,19.14476003,0.430992066,111541.4211,1.703061354,185.7519733
56.8,19.66100077,0.435209456,112971.3639,1.692169492,186.9712065
57,19.94123372,0.439487283,113777.7995,1.688248433,187.8504916
57.2,19.64890802,0.443851683,114865.3859,1.683020277,188.9999847
57.4,20.30888943,0.448187439,115764.718,1.678227909,189.9163192
57.6,20.47193214,0.452604518,116515.4888,1.676049545,190.862067
57.8,20.5078264,0.457075635,117012.7556,1.679534968,192.0170117
58,20.74979534,0.461598646,117683.2064,1.678227967,192.9453273
58.2,20.90866535,0.466127808,118673.6032,1.674306894,194.1187948
58.4,21.26945496,0.470710086,119338.9513,1.672999907,195.0373052
58.6,20.97209344,0.475388484,120161.2584,1.670385812,196.0560503
58.8,21.28799107,0.480090888,121331.8787,1.665593403,197.38206
59,21.47840546,0.484826709,121956.4323,1.66515775,198.340883
59.2,21.32063146,0.489612383,122343.2439,1.669950182,199.4969148
59.4,21.80437002,0.494421481,122983.6272,1.669514563,200.468816
59.6,21.7811972,0.499317435,123486.4528,1.670821594,201.4712196
59.8,22.03806007,0.504241393,124239.4677,1.671257303,202.7590935
60,22.31485883,0.509213332,124815.215,1.671693014,203.739709
60.2,21.95344953,0.514283787,125847.1312,1.668207558,205.0253984
60.4,22.26264088,0.519353994,126485.2423,1.667771919,206.0027452
60.6,22.12558264,0.52450909,127345.4687,1.66559352,207.0618058
60.8,22.43641963,0.52968202,127749.083,1.670821683,208.333337
61,22.46138788,0.534928684,128287.9408,1.671693042,209.3117711
61.2,23.03064605,0.540186593,128310.4583,1.68084233,210.4492874
61.4,22.89023056,0.545551368,128032.8552,1.691298566,211.284986
61.6,23.41127437,0.550919788,127820.8226,1.700883526,212.1544681
61.8,23.10879873,0.556404656,127936.4929,1.708290004,213.2832595
62,23.42207778,0.561897826,127982.0925,1.714389523,214.120052
62.2,24.16746279,0.567413206,128603.0815,1.714825291,215.2455862
62.4,24.38349847,0.573024359,129256.7786,1.71308261,216.1531998
62.6,24.51060927,0.578698648,129768.9077,1.713518305,217.0836944
62.8,24.83299365,0.584414991,130371.5962,1.7143897,218.2833134
63,24.93848058,0.590204992,130885.3943,1.713954037,219.1941954
63.2,25.32233989,0.59603203,131113.1313,1.718310866,220.2892169
63.4,25.49761142,0.60193355,131326.902,1.721360631,221.1325467
63.6,25.60556335,0.607899387,131777.7874,1.721796313,222.0804735
63.8,26.16888826,0.61389048,132452.8905,1.722232059,223.2790067
64,26.51448421,0.619958566,133205.1822,1.72005372,224.2073244
64.2,26.48861794,0.626115871,134547.3555,1.713518562,225.4712248
64.4,26.41371346,0.632338609,135809.4081,1.706112045,226.539003
64.6,26.49003923,0.638612296,137198.4649,1.698269864,227.7179194
64.8,26.63948209,0.644943522,138708.4146,1.69042769,229.157243
65,27.13377571,0.651312093,138924.2775,1.694784527,230.1117119
65.2,27.389565,0.657762952,139114.7415,1.700884042,231.2797339
65.4,27.53897729,0.664286561,139076.0873,1.709597607,232.3486039
65.6,27.63602677,0.670879804,138906.0152,1.718746838,233.2169924
65.8,27.78458713,0.677535271,138942.5306,1.725717699,234.1333226
66,28.37189962,0.684224295,140062.7213,1.721796674,235.3612749
66.2,28.05591517,0.691049308,141015.9784,1.718311222,236.3854672
66.4,28.64736106,0.697873717,141673.3697,1.719182643,237.5698368
66.6,29.04018942,0.704781813,141897.3651,1.723103788,238.5090508
66.8,29.31666812,0.71176826,141967.6139,1.729203314,239.4733237
67,29.50421971,0.718831724,141763.2343,1.739223917,240.5062385
67.2,29.50644921,0.725980215,141788.6304,1.744887717,241.3354007
67.4,29.68566821,0.733187032,142450.7764,1.745323424,242.4336905
67.6,30.02941181,0.740453538,143230.7652,1.743145075,243.3990529
67.8,30.65318749,0.747771891,144294.2181,1.737917024,244.4701075
68,31.10576749,0.755177018,145341.9882,1.733995985,245.724208
68.2,30.99741724,0.762699099,146201.8095,1.730510555,246.7200743
68.4,31.25219773,0.770269141,147392.7934,1.724411104,248.0177559
68.6,31.27262688,0.777932966,148761.0107,1.716568916,249.1781485
68.8,31.65369358,0.785646469,150567.4179,1.705677029,250.4725622
69,31.96162085,0.793442822,153140.596,1.689557003,252.1167277
69.2,32.2653807,0.80131794,154925.1565,1.67953646,253.3751857
69.4,32.56248006,0.80927274,156450.8344,1.674744045,254.9082144
69.6,32.59572727,0.817327539,157086.1925,1.676486761,256.1503253
69.8,32.84626553,0.825447132,157092.3519,1.683893309,257.3161691
70,32.99831849,0.83365573,156689.0965,1.69565662,258.5375795
70.2,33.4129513,0.841926856,156208.8854,1.708291317,259.7175897
70.4,33.31983575,0.850319734,156178.1725,1.71482647,260.7090968
70.6,33.41658812,0.858782456,156195.8713,1.720925968,261.683175
70.8,33.7983567,0.867308537,156452.9895,1.726589823,262.9972014
71,33.93538499,0.875938793,156562.8689,1.731817972,263.9680106
71.2,34.38235894,0.884632247,156564.0501,1.739224545,265.109886
71.4,34.74497347,0.893419574,156538.2102,1.746195431,266.0964968
71.6,34.9742,0.902305281,156823.7966,1.750116558,267.1354056
71.8,35.03762972,0.911292945,157390.212,1.750987923,268.1661401
72,35.46626544,0.920343108,157997.1393,1.75229501,269.3537775
72.2,35.45321523,0.929517771,158847.8705,1.749680946,270.3583616
72.4,35.82573,0.93875527,159761.1296,1.747938283,271.6353434
72.6,36.18618065,0.948086552,160187.206,1.750116717,272.6540967
72.8,36.27072755,0.957532403,160120.2862,1.75708757,273.5911283
73,36.43877398,0.967066472,160315.355,1.762315724,274.6872381
73.2,36.55362178,0.976700405,160359.507,1.767543871,275.5262099
73.4,36.53798867,0.986441009,161149.3403,1.767108194,276.7105727
73.6,36.67191833,0.99626805,161567.6244,1.768850923,277.6737554
73.8,37.01690391,1.006177812,162181.9418,1.76841529,278.6598211
74,37.39677529,1.016184467,162964.7188,1.767543984,279.86925
74.2,37.99684324,1.026274902,163124.9973,1.77102948,280.7343769
74.4,38.38249947,1.036483094,163205.963,1.776257661,281.8119685
74.6,39.05981719,1.046771576,163958.095,1.774079359,282.7969494
74.8,39.51441298,1.05718033,165059.4339,1.768851285,283.8963326
75,39.65155366,1.067717807,166814.9265,1.758830718,285.2779108
75.2,40.16262341,1.078332643,169129.3983,1.743146386,286.5930291
75.4,40.45263265,1.089070979,172347.9833,1.721798217,288.3646761
75.6,40.5639617,1.099930813,174981.9487,1.705678158,289.9129575
75.8,41.27441784,1.110854227,177261.7428,1.693914946,291.5080997
76,41.13558381,1.121952147,179511.2226,1.683894345,293.3146052
76.2,41.53105923,1.133120826,180252.0948,1.684765749,294.6493353
76.4,41.6830274,1.144477382,179714.7792,1.6978361,296.06687
76.6,41.82002858,1.155892685,178558.2582,1.71482755,297.200025
76.8,42.43650255,1.167328129,177827.6056,1.727026603,298.1653942
77,42.96320204,1.178943233,176619.4998,1.744018101,299.2342712
77.2,43.0162181,1.190711175,176204.2416,1.753167343,300.1658552
77.4,43.34676637,1.202576237,177341.0441,1.750117641,301.5463469
77.6,43.45375912,1.214577442,178856.6164,1.742711134,302.8276834
77.8,43.97456626,1.226667705,179931.5019,1.738790099,304.0937723
78,44.27763444,1.238896046,181029.4561,1.736611749,305.6093701
78.2,44.34883657,1.251264867,181780.83,1.735740404,306.773034
78.4,44.57209031,1.26374649,181551.0487,1.74445399,308.0696264
78.6,44.78867622,1.276353882,181213.1357,1.753603253,309.0502438
78.8,45.15066542,1.289077049,181487.9929,1.758831433,310.1616119
79,45.98463731,1.301892084,182286.5639,1.76013857,311.4756473
79.2,46.64657359,1.314848994,184005.0751,1.753603485,312.961832
79.4,47.34837679,1.327933146,186010.5651,1.743147303,314.276955
79.6,47.5174937,1.341189195,188846.8835,1.726591565,315.8720905
79.8,47.91926702,1.354560699,191978.9006,1.708293143,317.6143208
80,48.39248425,1.368061112,196154.5158,1.684330914,319.8523074
80.2,48.52912845,1.381722654,198654.2224,1.672567628,321.5389665
80.4,48.85521689,1.39550691,201410.874,1.661675719,323.691964
80.6,49.41894688,1.409411469,202579.7117,1.66080443,325.3372256
80.8,50.01257039,1.423453398,203540.4789,1.663854247,327.3965252
81,50.05190021,1.437678441,203497.3075,1.671696457,328.8347593
81.2,50.42526588,1.452021061,203378.3696,1.679538707,330.2305061
81.4,50.54266328,1.46652718,203464.0319,1.687380927,331.9313292
81.6,51.07719526,1.481147237,203156.3783,1.696965908,333.2540789
81.8,51.18706723,1.495946561,202955.679,1.706115163,334.6639863
82,51.56864982,1.510873765,202763.7513,1.715700133,336.2100944
82.2,52.1247168,1.525937721,202756.5471,1.722235371,337.4652894
82.4,52.75721097,1.541147253,202743.7759,1.729641982,338.9667293
82.6,53.37139906,1.556510985,203249.4105,1.731820445,340.327615
82.8,53.40469947,1.572073214,203883.9087,1.733127482,341.7298942
83,53.9498659,1.587752851,205035.1951,1.73138484,343.3849625
83.2,54.50165525,1.603589549,206531.1981,1.727463805,345.1413612
83.4,55.52957763,1.619548958,207170.7822,1.728770963,346.4913578
83.6,55.95666748,1.635714583,207384.3552,1.733127799,347.7988511
83.8,56.39037948,1.65204209,207691.3093,1.738791667,349.4582762
84,56.73847324,1.668540181,207736.2942,1.74445553,350.6339301
84.2,57.23944317,1.6851924,207441.0023,1.754040515,352.0067992
84.4,57.80935885,1.702006766,207840.411,1.757090337,353.1650239
84.6,58.59530561,1.718973547,208995.7029,1.755347713,354.4964924
84.8,59.14106864,1.736129017,210240.9436,1.75447643,356.2387291
85,59.05275738,1.753505207,211327.8299,1.752733704,357.5756307
85.2,59.36911148,1.771025063,212996.4435,1.748376962,359.3145935
85.4,59.91146744,1.788703805,214229.9868,1.745327282,360.6776577
85.6,60.14632813,1.80658357,215478.5576,1.742277565,362.1322398
85.8,60.80496624,1.824610601,217575.6867,1.735306794,364.1109145
86,61.17605229,1.842840864,218967.6115,1.731385735,365.5905593
86.2,61.80222384,1.861234751,220883.887,1.725721994,367.5332776
86.4,62.05857451,1.879841645,222589.0281,1.721365244,369.4051675
86.6,62.80933584,1.898597762,223865.0469,1.719186943,370.9959555
86.8,63.09055664,1.917578088,224619.0778,1.720929693,372.5801988
87,63.60608693,1.936731396,226279.1913,1.717880008,374.5708555
87.2,63.92464137,1.956092842,227237.165,1.718097887,376.1589146
87.4,64.40396189,1.975636675,228360.8342,1.717444429,377.8461254
87.6,65.14418279,1.995357094,230101.0065,1.712216378,379.527349
87.8,65.5295385,2.015302647,232839.1536,1.703067178,381.8873691
88,65.75157234,2.035461085,233766.3667,1.703938564,383.536986
88.2,66.520367,2.05578053,234578.0711,1.706988406,385.4873345
88.4,66.75563211,2.07634456,234250.1579,1.716137685,386.8558426
88.6,67.53931942,2.09707342,232525.4016,1.73443628,388.0162517
88.8,67.80401883,2.11805012,230213.1543,1.757962956,389.3618792
89,68.4081452,2.13921173,229486.5112,1.768419317,390.4688954
89.2,69.15433754,2.160575121,229682.4216,1.773647554,391.9529076
89.4,69.98567251,2.182146894,231137.9392,1.769073033,393.5017505
89.6,70.2502361,2.203978385,233984.4556,1.75578487,395.3959775
89.8,70.82098564,2.226005873,237566.7938,1.738357796,397.4269521
90,71.49931355,2.248246639,240554.0489,1.726158878,399.4720927
90.2,71.86058223,2.270735087,243304.1767,1.716138314,401.4834499
90.4,71.85825585,2.293475937,246533.1852,1.705246349,403.8216738
90.6,72.62996294,2.316386325,248009.4874,1.703503728,405.5998713
90.8,73.40828144,2.339526361,248936.3157,1.705682215,407.4129352
91,73.93726516,2.3629178,250700.6398,1.703503887,409.5790161
91.2,74.17785701,2.386566216,252332.5078,1.702196881,411.790854
91.4,74.78737195,2.410424148,253124.8191,1.703939671,413.4775241
91.6,75.40765173,2.434520922,254820.9246,1.700889995,415.4344099
91.8,75.81266585,2.458876286,256807.5555,1.697840293,417.9295396
92,76.30489537,2.483469632,257752.34,1.698711711,419.7131801
92.2,77.38210477,2.508265502,258885.2657,1.700018877,421.9381102
92.4,78.047933,2.533342021,259759.8952,1.701325994,423.697784
92.6,78.85665207,2.558659476,259789.6805,1.707861275,425.3975339
92.8,79.06286067,2.584277165,259843.1372,1.716139201,427.5527139
93,79.62718643,2.610125014,259501.3358,1.72441717,429.1010098
93.2,80.38509238,2.636217798,258755.1683,1.736180595,430.8759402
93.4,80.88119379,2.662592711,257752.672,1.74750831,432.1616459
93.6,81.56755058,2.689218064,257742.3172,1.753172222,433.6707205
93.8,82.71008025,2.716076271,258353.8209,1.756657796,435.6385131
94,83.34815409,2.74324276,259504.316,1.756222197,437.5234882
94.2,84.21385475,2.770803449,261226.1852,1.751429835,439.2374066
94.4,84.84934807,2.798521286,264000.541,1.741844974,441.4002223
94.6,85.2355215,2.826395488,266010.6878,1.736181195,443.2862819
94.8,85.94322252,2.854666367,267725.7629,1.733131529,445.2595153
95,86.80378128,2.883209556,270504.1214,1.725725089,447.6391615
95.2,87.15406437,2.912078397,271998.1087,1.723982417,449.443503
95.4,87.60651358,2.941229604,273419.963,1.724418153,451.6498985
95.6,88.32317226,2.97065356,274548.3347,1.72485392,453.4433526
95.8,88.92261387,3.000382005,276685.5213,1.721368561,455.9733558
96,89.77213716,3.030390154,277519.3756,1.722675702,457.7515581
96.2,90.4437799,3.060713271,279264.7134,1.720497388,460.0505741
96.4,91.39126421,3.091320126,280829.0538,1.718319107,461.9965741
96.6,91.92320273,3.122266101,282896.0761,1.715705097,464.6246373
96.8,92.5415152,3.153516553,283738.5545,1.717447891,466.4126422
97,93.33927252,3.185067199,285250.2578,1.717447988,468.7312741
97.2,93.78796198,3.216961435,286502.5176,1.717448044,470.6216949
97.4,94.51165956,3.249155267,288604.8093,1.714398377,473.091774
97.6,95.37158878,3.281662305,290296.2223,1.712655764,475.2219117
97.8,96.19739547,3.314497942,292097.6847,1.710477467,477.3716599
98,96.95500825,3.347668644,294152.2359,1.708299162,479.9398031
98.2,97.62365178,3.381178859,296711.4841,1.703506769,482.6060065
98.4,98.80413438,3.41498666,297959.9465,1.703942591,484.6250151
98.6,99.13944176,3.449198449,299024.0893,1.705685351,486.7671264
98.8,100.1652509,3.483701071,301000.9586,1.704814115,489.5662663
99,101.5524877,3.518522924,302640.0492,1.703942922,491.723655
99.2,102.5150307,3.553726866,302889.544,1.710913916,493.9801856
99.4,103.1800216,3.589307105,303632.0919,1.713963751,495.9577805
99.6,103.942182,3.625237382,305634.4539,1.711349766,498.2230236
99.8,104.5729879,3.661538698,308044.9068,1.708300094,501.0602918
100,105.3583009,3.698192841,309380.2577,1.708300187,503.2165788
100.2,106.0887098,3.735219395,312156.0109,1.703072115,506.0996106
100.4,106.7700309,3.772621705,312700.6267,1.70699332,508.1665503
100.6,107.5219268,3.810394548,311602.3137,1.718321082,509.9458443
100.8,108.4382994,3.848534397,309955.8541,1.734005669,512.171868
101,109.056284,3.88708,308195.2508,1.748383178,513.6210178
101.2,110.0323659,3.925985753,306048.6891,1.765810499,515.3120623
101.4,110.9003564,3.965290632,305928.1918,1.772781483,517.21884
101.6,111.7524952,4.004991591,306890.5021,1.77365295,519.0090329
101.8,112.4283998,4.045104883,308699.9756,1.770603277,520.9038207
102,113.4491033,4.085594864,312479.5933,1.758840043,523.450183
102.2,114.0168498,4.126526133,315736.3619,1.748819473,525.6217187
102.4,114.7956038,4.167852453,320079.0052,1.735313489,528.4328436
102.6,115.6773352,4.209586273,323371.6282,1.726599997,530.9051094
102.8,116.748467,4.251724914,327149.4455,1.717450852,534.0638176
103,117.8585884,4.294283899,328946.895,1.71527258,536.2397271
103.2,118.9137962,4.337274761,330540.9404,1.716144069,539.0094538
103.4,120.239009,4.380676877,331124.819,1.72006535,541.0339191
103.6,121.3264878,4.424533432,332790.3447,1.719194122,543.3231459
103.8,122.0449346,4.468858537,335592.9498,1.715273088,546.3630805
104,122.7117888,4.513632952,338718.9165,1.708302286,548.9127044
104.2,123.8472533,4.558821497,343779.1977,1.694796334,552.2936873
104.4,125.0200405,4.604461251,347764.688,1.685647187,555.5842359
104.6,125.5300354,4.650610934,349645.1637,1.683468847,557.7797452
104.8,126.5751179,4.697184915,350374.7682,1.689568497,560.9537071
105,127.5361955,4.74423327,349506.4258,1.700024942,563.0457187
105.2,128.4145138,4.791760745,346635.8704,1.720502028,565.3305844
105.4,129.7390013,4.83973173,345714.3238,1.732265561,567.6176401
105.6,130.247374,4.88824687,345911.8384,1.737929472,569.7216238
105.8,131.2563444,4.937211247,348258.3879,1.734008471,572.1535851
106,132.4817113,4.98665116,351686.8876,1.726602051,575.2055216
106.2,133.4685034,5.036605917,354421.3339,1.721374005,577.6658124
106.4,134.7099161,5.087043284,356448.3206,1.720938475,580.5662981
106.6,135.7663517,5.138001588,357062.4068,1.72529541,582.8958419
106.8,136.8235369,5.189471885,355541.586,1.740108682,585.3179997
107,137.7667935,5.241467903,355139.5125,1.747951052,587.1822917
107.2,138.7847569,5.293980585,356129.6854,1.750565262,589.6709129
107.4,139.9559553,5.347009293,357446.3052,1.750129726,591.7324253
107.6,141.0053281,5.400580155,359144.051,1.748822814,594.1251651
107.8,141.9208252,5.454697985,363275.7989,1.738802268,597.4451318
108,143.2201567,5.509328937,366137.605,1.732702894,600.0024056
108.2,144.1570863,5.564536551,368406.656,1.730960286,602.9584541
108.4,145.4994544,5.620267871,369863.9377,1.73139613,605.2433345
108.6,146.2126688,5.676607011,371898.3443,1.730089176,607.8049513
108.8,147.5581822,5.733463997,371994.8758,1.737931598,610.576873
109,148.5894878,5.790916234,371913.6108,1.744466941,612.5958912
109.2,149.9921577,5.848917264,371432.4341,1.754052097,615.0572849
109.4,151.1138579,5.907522494,371602.5546,1.760151772,617.435867
109.6,152.0435042,5.966731191,372402.0568,1.762330294,619.5006428
109.8,153.3237369,6.026508054,373599.153,1.763637497,621.7484804
110,154.4617737,6.086896368,375489.1315,1.762766276,624.3809319
110.2,155.6861379,6.147884772,378112.4128,1.758845297,627.1550341
110.4,156.7832622,6.209495634,379319.6939,1.759716796,629.3320419
110.6,158.0182338,6.271715022,380394.309,1.761459675,631.580967
110.8,159.1575414,6.33456673,383656.2429,1.754488914,634.2319439
111,160.3964685,6.398042285,387911.7661,1.744904077,637.5290435
111.2,161.763268,6.462145969,390777.1795,1.739240385,640.1593276
111.4,162.8648768,6.52691406,395625.3974,1.727041439,643.608963
111.6,164.0436651,6.592326878,398668.0825,1.721377723,646.4854854
111.8,165.3935347,6.658384017,400388.2432,1.72224925,649.8490546
112,166.9310508,6.725428468,401866.0273,1.722685118,652.4052509
112.2,167.9126292,6.792514846,403952.9873,1.723556601,655.6652994
112.4,169.3835047,6.860577245,406220.9122,1.722249734,658.2879602
112.6,170.6182681,6.929341345,409741.6382,1.716586022,661.2658173
112.8,172.1346303,6.99877498,413641.396,1.711793705,665.0292685
113,173.3375953,7.068930163,415078.5601,1.715279305,668.3034891
113.2,174.3285436,7.139806284,414585.6901,1.723557381,670.6363092
113.4,176.0016289,7.211342597,411084.5221,1.74359895,672.9397323
113.6,177.4759913,7.283612892,407193.8594,1.764076182,674.6449708
113.8,178.7266998,7.35662615,403665.0043,1.782810663,676.1922148
114,179.9889257,7.430372162,402013.1371,1.795009919,678.1949022
114.2,181.5161228,7.504839006,403822.6949,1.793703065,680.6977141
114.4,183.073948,7.580051761,407423.5147,1.784989619,683.1645716
114.6,184.2045196,7.656052799,412837.1949,1.770176569,686.1293533
114.8,185.5568467,7.732800594,419906.8874,1.751442404,690.0213732
115,187.0154194,7.81031122,424464.1814,1.74098621,692.9741823
115.2,188.0666786,7.88863158,428051.5193,1.736193835,696.4990052
115.4,189.9720805,7.967673966,429581.5044,1.737065431,699.1380294
115.6,191.1959366,8.047562336,429455.8884,1.744036499,701.6223124
115.8,192.6897404,8.128231635,429138.8365,1.753186013,704.619796
116,194.2540505,8.209705714,428820.2392,1.759721443,706.719468
116.2,195.5938608,8.292014186,429326.7847,1.764514116,709.5164669
116.4,196.9019619,8.375151825,430244.8693,1.766692692,711.8438518
116.6,198.3171294,8.459116091,432869.5387,1.763207408,714.493758
116.8,200.0836762,8.543897051,436134.4765,1.759286482,717.8813228
117,201.4877716,8.629557262,438788.4656,1.756236881,720.5660959
117.2,202.7803762,8.71608664,441783.5262,1.753187264,723.8032843
117.4,204.6653462,8.803440302,444647.3856,1.750573394,727.1919424
117.6,205.9942375,8.891713906,446351.4074,1.750573565,730.045601
117.8,207.6670223,8.980848118,448242.8808,1.749266718,732.7957605
118,209.6197122,9.070856675,450161.648,1.748831275,736.1255869
118.2,211.1658991,9.16180048,451987.8233,1.747960098,738.8648471
118.4,212.5390928,9.253671155,455060.0096,1.744474805,742.3580908
118.6,214.2644843,9.346437854,458168.3815,1.740553871,745.4525615
118.8,216.029616,9.440133696,461875.9696,1.735325884,748.6505442
119,217.8128803,9.534769617,467190.5764,1.726612439,752.6515488
119.2,219.1738449,9.630388355,472052.379,1.717898942,756.0194925
119.4,221.1869932,9.726918178,478631.6336,1.706135737,760.3386644
119.6,222.9589971,9.824436263,482822.0624,1.700907747,764.0236923
119.8,224.1458203,9.922978526,485767.9119,1.700907887,768.4158369
120,226.3014344,10.02243707,486583.9805,1.704829295,771.4830881
120.2,227.9807257,10.12293133,486321.2246,1.713543165,775.0722295
120.4,229.6016867,10.22443961,485203.1044,1.723128399,777.7058093
120.6,231.3820381,10.32695574,485230.184,1.729663868,780.7196584
120.8,233.3134685,10.4304901,487047.784,1.732278204,784.563776
121,235.1018013,10.53507574,488922.161,1.732714105,787.5449403
121.2,236.7794441,10.64072047,490616.7747,1.734892728,791.2920742
121.4,238.6123158,10.74741481,492495.0418,1.734892952,794.3451513
121.5,240.0455716,10.8011241,494502.0189,1.73315039,796.5635979
121.8,241.7108787,10.80153538,497158.9485,1.735764695,801.5408704
122,242.8036896,10.8014512,500346.0651,1.733150724,804.799852
122.2,243.6463688,10.80138597,505700.5552,1.726179883,808.9446547
122.4,244.1554004,10.80134602,509251.1853,1.723130158,812.3452595
122.6,244.8601332,10.80129124,512376.6618,1.721823192,815.9594314
122.8,245.1630761,10.8012669,516124.5783,1.720080494,820.356995
123,245.6845728,10.80122601,516170.6916,1.726180134,823.2008259
123.2,246.4437364,10.8011671,516489.0579,1.733151172,826.9217791
123.4,246.9930718,10.8011241,517532.092,1.736201028,829.8811041
123.6,247.2723311,10.80110156,518514.4736,1.739686536,833.1204447
123.8,247.685382,10.80106888,521069.5484,1.740122272,837.2793951
124,247.7336226,10.80106384,524824.1308,1.735329755,840.6799836
124.2,247.9576203,10.80104549,527748.5212,1.734458416,844.727791
124.4,248.0075228,10.80104033,528345.5236,1.738379581,847.7699065
124.6,248.6370501,10.80099125,527132.1923,1.747529025,850.6573249
124.8,248.785011,10.80097865,522424.6982,1.768006199,853.6667576
125,249.2175905,10.8009445,518066.7065,1.785433619,855.4809285
125.2,249.4332782,10.80092677,513356.2442,1.805039435,857.6590142
125.4,249.4640677,10.80092306,511445.6854,1.815495861,859.4982311
125.6,249.5571824,10.80091462,509606.7253,1.825952294,861.3243722
125.8,249.7915677,10.80089548,510546.8516,1.829002115,864.0167423
126,250.3409032,10.80085248,511383.1344,1.830744923,865.9714771
126.2,250.1556319,10.80086513,513481.7154,1.829873534,868.6594677
126.4,250.2770007,10.80085455,516977.2208,1.824645342,871.5577623
126.6,250.510555,10.80083548,521218.8685,1.816803058,874.3307605
126.8,250.5006253,10.80083485,523865.5402,1.81375327,877.0122238
127,250.5123018,10.80083258,528327.8638,1.806346642,880.4106307
127.2,250.7043059,10.80081665,529225.1877,1.808089405,882.8077179
127.4,250.8605769,10.80080343,525131.7396,1.824645426,884.8256306
127.6,251.2021616,10.80077616,522032.2912,1.837280314,886.3761223
127.8,251.3293475,10.80076514,519532.7042,1.848608122,887.9342319
128,251.5221826,10.80074915,514504.4737,1.867778254,889.046703
128.2,251.513084,10.80074846,512805.473,1.876927624,890.5710306
128.4,251.8006535,10.80072529,515252.0946,1.873006505,892.3644949
128.6,251.7732728,10.80072598,517667.5586,1.86952103,894.286516
128.8,251.9004587,10.80071496,519121.4858,1.869521049,896.4645972
129,252.1007728,10.8006984,521583.1299,1.865599919,898.4116893
129.2,252.047631,10.80070105,523167.5688,1.86516423,900.5984831
129.4,252.3742577,10.80067492,522554.4292,1.869956801,902.0781483
129.6,252.4116952,10.8006707,521627.7892,1.875620704,903.5251161
129.8,252.3278063,10.80067567,521451.7088,1.879541854,905.3240125
130,252.6818561,10.80064747,520855.2205,1.884334429,906.9823715
130.2,252.552262,10.8006559,520243.3197,1.888691257,908.2005209
130.4,252.9046498,10.80062782,519574.0091,1.8943552,909.6028294
130.6,252.8781,10.80062845,517774.9998,1.9026332,910.567111
130.8,252.7933801,10.80063349,516394.9461,1.90960414,911.4681909
131,253.0593436,10.80061195,514432.2404,1.918753547,912.3137202
131.2,252.9870886,10.80061605,512744.5881,1.926595857,913.1374413
131.4,253.0934995,10.8006066,511829.4655,1.931388401,913.8118995
131.502,253.5578692,10.80057071,511992.4992,1.932259832,914.3894006
132.3,253.5796938,10.66025089,1.7977E+308,1.940537843,0
132.5,253.0259936,10.55235865,1.7977E+308,1.873442391,0
132.7,252.8246387,10.44443971,1.7977E+308,1.732280661,0
132.9,252.8468239,10.33650383,1.7977E+308,1.527509056,0
133.1,252.5773268,10.22859006,1.7977E+308,1.216866148,0
133.3,252.4341422,10.12066671,1.7977E+308,0.810372722,0
133.5,252.3258598,10.01274072,1.7977E+308,0.491016157,0
133.7,252.126998,9.904821597,1.7977E+308,0.240497706,0
133.9,251.9879685,9.796897937,1.7977E+308,0.077116112,0
134.1,251.6727662,9.688987625,1.7977E+308,0.008278,0
134.3,251.4689184,9.581068876,1.7977E+308,0.005228211,0
134.5,251.2442955,9.473151701,1.7977E+308,0.009149369,0
134.7,250.9299243,9.365241326,1.7977E+308,0.008278,0
134.9,250.3704071,9.257349526,1.7977E+308,0.007406631,0
135.1,250.3676621,9.149415539,1.7977E+308,0.022655578,0
135.3,250.3050849,9.041486086,1.7977E+308,0.040954315,0
135.5,249.7472298,8.93359416,1.7977E+308,0.05315347,0
135.7,249.7270337,8.825661496,1.7977E+308,0.060995785,0
135.9,249.802403,8.717721591,1.7977E+308,0.06360989,0
136.1,249.2138008,8.609831994,1.7977E+308,0.056203257,0
136.3,249.267564,8.501893726,1.7977E+308,0.048796626,0
136.5,248.741287,8.393999407,1.7977E+308,0.04095431,0
136.7,248.7626411,8.286063595,1.7977E+308,0.029626522,0
136.9,248.5222292,8.178147616,1.7977E+308,0.022219891,0
137.1,247.9568951,8.070256256,1.7977E+308,0.015684629,0
137.3,247.938361,7.962323466,1.7977E+308,0.01481326,0
137.5,247.5699747,7.854417184,1.7977E+308,0.016120312,0
137.7,247.4874534,7.746489242,1.7977E+308,0.018298733,0
137.9,247.1897023,7.638577608,1.7977E+308,0.022219889,0
138.1,247.0008126,7.530657726,1.7977E+308,0.022655573,0
138.3,247.089478,7.422716813,1.7977E+308,0.02657673,0
138.5,246.546581,7.314823753,1.7977E+308,0.028319465,0
138.7,246.4798488,7.206894615,1.7977E+308,0.031804938,0
138.9,246.1363925,7.098986444,1.7977E+308,0.036161778,0
139.1,245.9375308,6.991067317,1.7977E+308,0.047053879,0
139.3,245.6755129,6.883152976,1.7977E+308,0.053589139,0
139.5,245.6116892,6.775223617,1.7977E+308,0.057074611,0
139.7,245.3895594,6.667306253,1.7977E+308,0.056203242,0
139.9,245.2455439,6.559382971,1.7977E+308,0.055767558,0
140.1,244.8879607,6.45147587,1.7977E+308,0.046618192,0
140.3,244.5083559,6.343570438,1.7977E+308,0.04008293,0
140.5,244.3202972,6.235650492,1.7977E+308,0.038340194,0
140.7,244.24941,6.127721669,1.7977E+308,0.037033141,0
140.9,244.0725699,6.019800874,1.7977E+308,0.033111985,0
141.1,243.9057018,5.911879323,1.7977E+308,0.032240616,0
141.3,243.5983943,5.803968413,1.7977E+308,0.034419036,0
141.5,243.2923332,5.696057408,1.7977E+308,0.040518611,0
141.7,243.0967956,5.588138029,1.7977E+308,0.050975026,0
141.9,242.6914297,5.480234549,1.7977E+308,0.05271776,0
142.1,242.616803,5.372306009,1.7977E+308,0.044657607,0
142.3,242.2887204,5.264396673,1.7977E+308,0.036597452,0
142.5,241.9755959,5.156486204,1.7977E+308,0.022219881,0
142.7,241.8236859,5.048563519,1.7977E+308,0.008277995,0
142.9,241.4411726,4.940658307,1.7977E+308,0.014813254,0
143.1,241.2921712,4.832735403,1.7977E+308,0.023091248,0
143.3,240.9138129,4.724829876,1.7977E+308,0.03006219,0
143.5,240.7498534,4.616908105,1.7977E+308,0.034419029,0
143.7,240.4828496,4.508994141,1.7977E+308,0.030062189,0
143.9,240.3770602,4.401067962,1.7977E+308,0.022655563,0
144.1,239.6064688,4.293192154,1.7977E+308,0.014813252,0
144.3,239.8771237,4.185237453,1.7977E+308,0.008277994,0
144.5,239.5843588,4.077325441,1.7977E+308,0.025705349,0
144.7,239.1727605,3.969422433,1.7977E+308,0.039211548,0
144.9,238.8160084,3.861515269,1.7977E+308,0.050103643,0
145.1,238.364522,3.753615283,1.7977E+308,0.059688686,0
145.3,238.5404426,3.645667759,1.7977E+308,0.060560054,0
145.5,238.4346532,3.537741581,1.7977E+308,0.056203216,0
145.7,237.9981249,3.429840461,1.7977E+308,0.051410692,0
145.9,237.7469102,3.321925301,1.7977E+308,0.047053853,0
146.1,237.3020718,3.214024812,1.7977E+308,0.038775859,0
146.3,237.1522394,3.10610197,1.7977E+308,0.032676285,0
146.5,236.8229104,2.998192728,1.7977E+308,0.027448079,0
146.7,236.5018915,2.890282857,1.7977E+308,0.020041454,0
146.9,236.3470731,2.782360393,1.7977E+308,0.010020727,0
147.1,235.9014038,2.674459966,1.7977E+308,0.004356838,0
147.3,235.5688366,2.566011306,1.7977E+308,0.020041453,0
147.5,235.280972,2.458638587,1.7977E+308,0.029626495,0
147.7,235.0796174,2.350719649,1.7977E+308,0.036597434,0
147.9,234.7718946,2.24280877,1.7977E+308,0.037904485,0
148.1,234.6802323,2.134881521,1.7977E+308,0.032240596,0
148.3,234.3666925,2.026971083,1.7977E+308,0.024398288,0
148.5,233.7340477,1.919084823,1.7977E+308,0.020477134,0
148.7,233.7038797,1.811152915,1.7977E+308,0.01176346,0
148.9,233.3263526,1.703247325,1.7977E+308,0.008713674,0
149.1,232.7618501,1.595355902,1.7977E+308,0.024398286,0
149.3,232.6494128,1.487430227,1.7977E+308,0.042261316,0
149.5,232.4347623,1.379512297,1.7977E+308,0.060560029,0
149.7,231.7788495,1.2716278,1.7977E+308,0.066659597,0
149.9,231.4004916,1.163722273,1.7977E+308,0.057074556,0
150.044,230.8811665,1.086049001,1.7977E+308,0.044875412,0
225.3,230.5264164,0.954417498,1.7977E+308,0.049232271,0
225.5,230.2486096,0.846504353,1.7977E+308,0.049667953,0
225.7,229.9550137,0.738592404,1.7977E+308,0.048360901,0
225.9,229.7278981,0.630675418,1.7977E+308,0.045746798,0
226.1,229.2365237,0.522778454,1.7977E+308,0.045746796,0
226.3,228.6371189,0.414889675,1.7977E+308,0.046182478,0
226.5,227.8881338,0.307012231,1.7977E+308,0.042697006,0
226.7,226.887355,0.199153864,1.7977E+308,0.035726063,0
226.9,225.6094371,0.091316495,1.7977E+308,0.028755122,0
227.058,224.7177471,0.006116043,1.7977E+308,0.023091233,0
,,,,,