File: Test_15.csv
Time On Sample,Displacement Into Surface,Load On Sample,Harmonic Contact Stiffness,Harmonic Displacement,Harmonic Load
0,0,0,-418.567569,0.370339951,2.204258896
0.2,-0.250155075,0.000777061,4106.583516,0.254881021,2.27508282
0.4,-0.018317362,0.001517664,9024.879248,0.220025501,2.337189985
0.6,0.190251738,0.002260027,12901.77943,0.183862896,2.402565946
0.8,0.053946681,0.003028476,16727.68532,0.155107087,2.521332231
1,0.176089487,0.003777377,20352.64241,0.136372243,2.671696921
1.2,0.129534813,0.004539037,23378.47674,0.125479891,2.820971991
1.388,0.341246225,0.005235674,25384.97971,0.120687258,2.969157498
1.6,0.539194242,0.006021683,25707.3606,0.124172813,3.114074206
1.8,0.333914756,0.006792793,28378.71088,0.124172811,3.442043494
2,0.422817087,0.007541651,32385.63736,0.121122953,3.83647838
2.2,0.376262819,0.008300754,36256.942,0.119380177,4.23200284
2.4,0.5008985,0.009050691,41591.55159,0.114151849,4.629706543
2.6,0.641324203,0.009795652,48617.02314,0.105873662,5.021962251
2.8,1.048508608,0.010516652,55712.07145,0.103695195,5.646302653
3,0.721899886,0.011296938,57928.91594,0.112844768,6.391588355
3.2,0.662879684,0.012060766,55723.27762,0.130708226,7.118350956
3.4,0.748458531,0.012806092,51950.93484,0.154235707,7.827680013
3.6,0.722679815,0.013563624,47659.94279,0.182991517,8.519575389
3.8,0.596347424,0.014328761,44828.59014,0.213925795,9.36728347
4,1.024306782,0.015051972,44789.67373,0.239631754,10.50046676
4.2,0.75337654,0.015828046,45722.11486,0.259673677,11.66306889
4.4,1.043386229,0.016561691,46431.46431,0.280587,12.83765691
4.6,1.000156048,0.017320542,46509.02822,0.30411448,13.932704
4.8,0.919529871,0.018082222,46595.612,0.328949042,15.07787263
5,0.865496403,0.01884189,45724.41351,0.365547345,16.40718349
5.2,0.934454208,0.019592255,43606.54215,0.412166616,17.60138427
5.4,0.838869633,0.020355066,41070.58853,0.466628375,18.72802968
5.6,0.71627684,0.02111992,38711.27422,0.525447074,19.85794382
5.8,0.426233094,0.02189744,36574.85905,0.585137153,20.88107713
6,0.582032707,0.022641237,34285.42422,0.656155296,21.95542198
6.2,0.444066007,0.023407255,31813.52592,0.738501472,22.94695704
6.4,0.032693042,0.024193954,29235.39577,0.830868595,23.76088713
6.6,0.506358602,0.024913708,26678.6015,0.930642568,24.32747916
6.8,1.015758131,0.025630758,23934.55013,1.054379726,24.83741219
7,0.548291157,0.026421698,21612.31216,1.183345143,25.27325132
7.2,0.963369676,0.027145883,20177.16973,1.278762184,25.58705638
7.4,1.061413257,0.027894047,19117.72531,1.364593936,25.98149139
7.6,1.006548766,0.028653777,19088.22135,1.391606964,26.5273805
7.8,1.006116224,0.029409391,19565.45489,1.385507248,27.08416567
8,1.009423282,0.030164721,20206.33439,1.36633671,27.63114443
8.2,0.687385177,0.03094466,21231.00615,1.333223928,28.36008589
8.4,0.789168356,0.031692542,21905.58899,1.317538954,28.93539436
8.6,0.671561695,0.032457018,22203.78369,1.325817131,29.58588488
8.8,0.846890333,0.033199337,22072.91034,1.352394491,30.07075675
9,0.841056148,0.033955358,21788.6352,1.385942932,30.42814528
9.2,0.933282574,0.034703963,21187.08192,1.441276092,30.79425074
9.4,1.003902426,0.035454202,20718.36047,1.48963815,31.13529539
9.6,0.927431358,0.036215566,20332.14201,1.529286308,31.38045509
9.8,1.570625478,0.036922494,20036.4285,1.564141901,31.63324309
10,2.001077941,0.037645513,19986.7719,1.584619574,31.95358593
10.2,2.187209886,0.038387012,20378.15469,1.572855852,32.28482439
10.4,2.06420157,0.039151894,21314.5797,1.5314649,32.79475664
10.6,1.955320633,0.039915707,23121.14327,1.449118696,33.48229347
10.8,2.109042711,0.040659658,25544.52784,1.350651838,34.24283409
11,1.96858293,0.04142586,27993.96703,1.265255774,34.96196934
11.2,1.836433371,0.042191433,30818.02665,1.185523737,35.87178453
11.4,1.764948433,0.042952418,32452.88763,1.149361119,36.51028948
11.6,2.054127129,0.043686123,33589.73858,1.13541893,37.26756141
11.8,2.052448056,0.044441827,33685.67713,1.150668226,37.88427447
12,1.995921517,0.045201681,33373.1863,1.179859729,38.51842132
12.2,2.035793554,0.045954242,33050.91602,1.208179853,39.11443215
12.4,2.058214124,0.046708124,32844.26606,1.229093174,39.58513914
12.6,2.021632118,0.047466469,32800.07615,1.24782802,40.17134335
12.8,2.059842111,0.048219156,33073.18381,1.255234825,40.76735425
13,2.186140459,0.04896518,33374.42868,1.263077331,41.4167556
13.2,2.402189209,0.049704415,33647.969,1.268305681,41.92995732
13.4,2.253419201,0.050471245,34055.62922,1.272226916,42.59788136
13.6,2.401324129,0.051215635,34307.55695,1.280069425,43.23420751
13.8,2.215989144,0.05198523,34177.3648,1.30011134,43.7593941
14,2.444503229,0.052723522,33902.18559,1.327995787,44.31944854
14.2,2.438669044,0.053479539,33555.17811,1.354573131,44.72695875
14.4,2.699593001,0.054215379,33083.60934,1.38942869,45.19439742
14.6,2.281571785,0.055002575,32683.00669,1.422541407,45.64766973
14.8,2.608146497,0.055733449,32575.11993,1.441711983,46.08459981
15,2.446911153,0.056501221,32599.74651,1.452604322,46.48993037
15.2,2.58567484,0.057246301,32707.33865,1.462625302,46.98896709
15.4,2.702831949,0.057993015,32853.69152,1.47046781,47.47383922
15.6,2.557386027,0.058759592,33081.72791,1.472210573,47.89115525
15.8,2.857368034,0.059492477,33268.46086,1.480488794,48.4446724
16,2.882281674,0.060246168,33310.04824,1.491381152,48.82712183
16.2,2.819106954,0.061006522,33382.9384,1.502709195,49.28039497
16.4,3.162302126,0.061736137,33393.63864,1.513601586,49.64432214
16.6,2.909654326,0.062510822,33110.47578,1.538000434,50.02350202
16.8,3.076672775,0.063253764,32908.46858,1.559785162,50.44735655
17,3.247846339,0.063996391,32976.651,1.565449206,50.77096794
17.2,3.347551987,0.064744423,33279.47725,1.563706441,51.22097275
17.4,3.446426614,0.065492518,33784.60793,1.554556875,51.70475501
17.6,3.30679784,0.066258654,34405.49328,1.539743259,52.12425056
17.8,3.379910775,0.067008697,35320.89915,1.516651475,52.65924401
18,3.438065309,0.067759872,36359.31501,1.491816914,53.26615099
18.2,3.521150513,0.068509162,37162.87522,1.477439015,53.84254913
18.4,3.552712334,0.069262348,37722.62756,1.469596524,54.31652501
18.6,3.584274155,0.070015534,38533.72987,1.455218619,54.92779045
18.8,3.538550901,0.070774566,38988.0814,1.451733062,55.46714189
19,3.673990512,0.071519894,39184.67902,1.45826849,56.02937556
19.2,3.816909325,0.072264657,39522.47364,1.456961423,56.52296447
19.4,3.756227669,0.07302482,40045.00347,1.451297393,57.13313985
19.6,3.78031029,0.073778571,40440.6353,1.450861702,57.72588214
19.8,3.855916295,0.074528425,41227.42266,1.438662273,58.3316996
20,3.789417482,0.075289027,41971.41787,1.427334218,58.87976784
20.2,3.702974133,0.076051139,42635.32849,1.422541574,59.54551287
20.4,3.571654977,0.076820427,43047.34482,1.426462811,60.19164496
20.6,3.769421866,0.077557258,43073.73183,1.43779088,60.65145638
20.8,3.329794031,0.078346085,42655.75361,1.46393249,61.12216192
21,3.711216249,0.079072807,42106.88315,1.494431123,61.59613889
21.2,3.801780657,0.079821529,41606.98921,1.523622646,62.05486051
21.4,4.070183709,0.080557677,41248.99048,1.546714468,62.49396997
21.6,4.258807576,0.081306418,41276.26753,1.554556985,62.88077814
21.8,4.093414725,0.082089442,41597.57742,1.553249886,63.35911191
22,3.870680064,0.082884794,42133.98342,1.546714451,63.94749484
22.2,4.292817531,0.08363903,42846.40724,1.534079364,64.5489551
22.4,4.001105529,0.084455212,43648.6365,1.520572814,65.18201132
22.6,4.165623542,0.085244817,44079.68276,1.516651584,65.64945006
22.8,4.21130408,0.086051451,44523.48735,1.515344507,66.21386275
23,4.177205193,0.08687216,44947.32632,1.516651587,66.81858998
23.2,4.23991912,0.087693669,45210.61985,1.522751314,67.39716769
23.4,4.293074962,0.088524261,45420.66885,1.526672569,67.85262043
23.6,4.55273854,0.089347572,45664.66129,1.531465234,68.41049622
23.8,4.439271748,0.090207414,45815.8612,1.538436331,68.93568275
24,4.629126754,0.091052952,45849.88655,1.549328708,69.48157278
24.2,4.472859579,0.091933204,45808.30067,1.560221048,69.91959126
24.4,4.685149473,0.092794143,45751.83699,1.572856205,70.41427011
24.6,4.802285902,0.093671106,45701.66169,1.585055658,70.88279824
24.8,4.759449112,0.094569016,45728.45443,1.594205233,71.34696749
25,4.73613993,0.095474373,45968.0026,1.596819397,71.86561674
25.2,4.925986552,0.096372688,46267.71987,1.59594803,72.31235322
25.4,5.122895428,0.097279519,46642.13391,1.595076665,72.87567679
25.6,5.143210571,0.098208955,46990.55747,1.593769585,73.37634786
25.8,5.401196669,0.099129611,47561.75185,1.586362812,73.92714122
26,5.224556544,0.100092508,48107.37506,1.580263077,74.48501556
26.2,5.224507174,0.101051563,48759.73712,1.571984886,75.11153526
26.4,5.567668541,0.101994296,49469.3706,1.562399647,75.74132501
26.6,5.339915935,0.102989988,50095.15612,1.553250045,76.26977994
26.8,5.447063824,0.103970106,50577.14654,1.549764504,76.87450805
27,5.500193687,0.104964168,51069.01255,1.546714652,77.51955115
27.2,5.633100129,0.10596212,51746.77122,1.539743555,78.22125372
27.4,5.581517955,0.106984284,52440.5183,1.530158283,78.79329327
27.6,5.722731382,0.108001994,53442.50998,1.515780387,79.54620706
27.8,5.723500378,0.109040618,54438.13872,1.502709558,80.27732833
28,5.760001699,0.110086858,55467.50201,1.491381514,81.10215529
28.2,5.892899944,0.111136397,55876.1254,1.492252914,81.69598756
28.4,6.047403106,0.112194803,55783.23368,1.507937925,82.35737508
28.6,5.971711322,0.113281426,55525.94704,1.527108468,82.97517771
28.8,6.007374819,0.114370525,55355.80401,1.542357773,83.54176974
29,5.814505397,0.115487833,55238.8234,1.554557194,84.02990937
29.2,5.885899348,0.116596326,55628.60078,1.555864285,84.71090943
29.4,5.886654638,0.117721171,56565.18973,1.543664846,85.49215241
29.6,5.867463589,0.118858849,57535.1996,1.528415546,86.1284785
29.8,6.126663274,0.119986786,58837.52181,1.510552108,87.07861052
30,6.149019716,0.12114418,59605.8821,1.50227392,87.75525173
30.2,6.261955759,0.122306368,60058.04076,1.503581016,88.53322628
30.4,6.320042464,0.123484366,60112.02479,1.51447338,89.28287119
30.6,6.509428845,0.124664273,59767.13733,1.531465479,89.79498354
30.8,6.7337163,0.125853334,59393.32533,1.550200359,90.37574122
31,6.88570289,0.127059866,59299.18354,1.562835511,91.02950159
31.2,6.809987372,0.128295777,59643.23633,1.565885364,91.74536814
31.4,6.646181476,0.129550871,60065.84135,1.565013959,92.34682646
31.6,6.536390059,0.130814373,60588.54793,1.56414256,93.08339523
31.8,6.757343619,0.132065376,61211.12875,1.561092725,93.78291919
32,6.981619262,0.133328784,61571.71289,1.565885387,94.51731017
32.2,6.992320097,0.134621016,61588.69635,1.575034971,95.05448295
32.4,7.094431339,0.135919379,61465.97179,1.589412895,95.69516804
32.6,6.968840308,0.137248131,61353.18029,1.602919407,96.30207426
32.8,6.947956016,0.138582199,60884.10513,1.623832733,96.8109174
33,7.185517614,0.13991009,60471.56718,1.643439006,97.34700141
33.2,7.303409826,0.141260487,60197.00756,1.657381239,97.74252654
33.4,7.165344932,0.1426438,59872.52702,1.674373303,98.23720437
33.6,7.379631402,0.144014343,60036.29169,1.679165967,98.78636341
33.8,7.309705952,0.145420221,60749.11626,1.669580684,99.37256807
34,7.465816418,0.146823002,61652.55072,1.656945568,100.059016
34.2,7.89034496,0.148219488,62575.53925,1.643003398,100.6713732
34.4,7.920135504,0.149660079,63965.51625,1.621218685,101.4885734
34.6,7.984826716,0.151112388,65026.52872,1.607712168,102.2861604
34.8,8.057825824,0.15257873,65615.1232,1.603790928,102.9649816
35,8.006169201,0.154069211,66210.4227,1.598998286,103.6067556
35.2,8.19052064,0.155556701,66832.14513,1.595512752,104.3901786
35.4,8.157972771,0.157075721,67235.86526,1.595948444,105.1507191
35.6,8.393011776,0.158589689,67614.52693,1.596384166,105.8916479
35.8,8.303118499,0.160143523,67946.6877,1.59769124,106.5879019
36,8.416823296,0.161697522,68184.72505,1.60030542,107.1882715
36.2,8.323600972,0.163282786,68477.8651,1.603790966,107.9586182
36.4,8.422342344,0.164869482,68816.83265,1.606840838,108.7060841
36.6,8.453768352,0.166477184,69178.99137,1.607276538,109.324977
36.8,8.477712566,0.168101749,69521.63214,1.609019319,110.0179623
37,8.495837049,0.169742937,69913.11593,1.611633488,110.8199078
37.2,8.769082876,0.171381266,70384.36743,1.610326436,111.4660419
37.4,8.659224624,0.173065136,70760.7483,1.612504897,112.2538219
37.6,8.685651401,0.1747556,70802.03853,1.6203474,112.8454749
37.8,8.621494005,0.176469921,70878.74892,1.629061282,113.4970553
38,8.619659204,0.178205352,70880.93675,1.640389337,114.2096533
38.2,8.956880261,0.179923897,70665.86893,1.653460208,114.7119608
38.4,8.93759122,0.181678031,70326.46139,1.671759371,115.2948964
38.6,9.096136847,0.183445057,70209.49461,1.68265175,115.7765005
38.8,9.021993301,0.18524743,70081.38301,1.693979797,116.3016873
39,9.007680505,0.187063418,69937.40409,1.705743546,116.8671895
39.2,9.447103215,0.188863254,69832.96419,1.714457486,117.3041213
39.4,9.25162167,0.190729422,69981.22643,1.718814409,117.8859666
39.6,9.169156258,0.19260564,70160.01458,1.722299955,118.4678123
39.8,9.216327386,0.194490926,70312.63939,1.725785517,118.9940892
40,9.205323923,0.196399504,70554.48342,1.727092601,119.4789611
40.2,9.308167528,0.198318612,71033.95012,1.724914142,120.0880478
40.4,9.504913636,0.200249896,71430.39056,1.723171389,120.6001608
40.6,9.475618445,0.202217917,71887.61271,1.721864304,121.2375767
40.8,9.72679034,0.20418412,72509.39372,1.716200307,121.8521126
41,9.976297029,0.206170361,73214.75557,1.707922144,122.4437665
41.2,9.948238943,0.208197596,74088.56,1.69790117,123.1879631
41.4,10.0398449,0.21023615,74743.8422,1.690930071,123.7883334
41.6,10.04335919,0.212301755,76027.8358,1.673502296,124.6512961
41.8,10.10795037,0.21438346,77109.5028,1.660431471,125.4456149
42,10.39774541,0.216468982,77738.85018,1.656074561,126.1059143
42.2,10.57160943,0.218584276,77962.84664,1.661302915,126.8664561
42.4,10.5821741,0.220733215,77980.06411,1.668274029,127.4254206
42.6,10.70492341,0.2228952,77624.9004,1.683959044,128.0475829
42.8,10.78736469,0.225081873,77328.9053,1.697029889,128.6021899
43,10.81495497,0.227294617,77580.02858,1.697901281,129.1764093
43.2,11.11096211,0.229509181,78616.86112,1.685266178,130.0034171
43.4,11.382035,0.231748065,79874.29307,1.667838433,130.7497951
43.6,11.41750932,0.234027396,81966.93686,1.638646908,131.8012593
43.8,11.21530745,0.236347725,83631.60457,1.619040632,132.7699118
44,11.65382053,0.238642653,84585.95481,1.611633874,133.5947421
44.2,11.71920065,0.240989116,85505.12612,1.607276938,134.5993533
44.4,11.48374673,0.243381972,85804.33854,1.611198169,135.3424589
44.6,11.61643215,0.24577084,85561.19185,1.625576102,136.1487637
44.8,12.39398751,0.248134898,85673.78154,1.632547302,136.9191159
45,12.00561396,0.250611148,86113.90249,1.632982954,137.6491453
45.2,12.33191619,0.253057854,86526.5145,1.635597158,138.543709
45.4,12.48286867,0.255542551,87271.5777,1.63211162,139.4894828
45.6,12.35126937,0.258073718,88178.17847,1.624269105,140.3197571
45.8,12.44736633,0.26061296,89248.71384,1.614683835,141.2873224
46,12.56174173,0.263176339,90003.65693,1.609891211,142.1502864
46.2,12.39273421,0.265787029,91115.54753,1.602048695,143.240975
46.4,12.62593762,0.268393442,91773.97059,1.600305944,144.1039396
46.6,12.45027358,0.27105708,91898.14858,1.609891205,145.0649654
46.8,12.68429962,0.273716202,91986.14221,1.619040817,145.9083178
47,12.90751812,0.276402932,92286.00394,1.622962093,146.6819353
47.2,12.8091264,0.279141269,92248.1353,1.634290141,147.5982881
47.4,12.9808128,0.281886436,92521.05557,1.638211412,148.3566509
47.6,12.76274503,0.284688923,93362.30579,1.633854444,149.3525439
47.8,13.13719217,0.287474452,93899.62316,1.633854487,150.2623625
48,13.06038938,0.290322354,94332.80173,1.637340036,151.2615251
48.2,13.03178137,0.293195182,94775.77156,1.637775728,152.0318721
48.4,13.14776677,0.296085896,95032.2574,1.643004077,152.9820039
48.6,13.34768089,0.298999256,95375.97681,1.646053963,153.7578011
48.8,13.37058247,0.301955239,96012.1504,1.645618272,154.6687067
49,13.12755197,0.304961051,96647.35058,1.64605394,155.6983769
49.2,13.5401938,0.307947445,96988.05695,1.64910385,156.4698165
49.4,13.62208371,0.310988966,97245.76394,1.655203584,157.3807227
49.6,13.83028427,0.314051369,97068.57674,1.665660278,158.0715307
49.8,13.87559941,0.317157008,96922.35805,1.676116954,158.8342511
50,14.1735406,0.320274658,96990.18604,1.683959492,159.7146507
50.2,14.34349927,0.323433312,97265.38543,1.686137985,160.4261611
50.4,14.53672154,0.326621952,97788.71634,1.686138009,161.364308
50.6,14.88534005,0.3298308,98424.79746,1.682652494,162.1368369
50.8,15.2580531,0.333070133,98724.39667,1.685266705,162.9649359
51,15.30333788,0.336366827,98742.27188,1.693109215,163.8387958
51.2,15.4749329,0.339687116,98566.8806,1.702258823,164.4871094
51.4,15.19195295,0.343075336,98286.3314,1.71445824,165.2563644
51.6,15.23223563,0.346472811,98039.15903,1.724914916,165.8382114
51.8,15.42375908,0.349893031,98292.9657,1.728836192,166.5682452
52,15.44159322,0.353360917,98960.885,1.727093417,167.437746
52.2,15.71537694,0.356844239,99803.26269,1.720993726,168.174318
52.4,15.53458543,0.360397104,100919.0939,1.712715508,169.1298962
52.6,15.62470183,0.363964892,101884.2417,1.704873017,169.9427386
52.8,15.54362175,0.36758155,102504.9113,1.70313023,170.7969843
53,15.95616364,0.371197153,102783.7531,1.707922921,171.6882806
53.2,15.55097297,0.374911199,102650.7538,1.716201072,172.2951848
53.4,15.70588599,0.378619885,102355.6715,1.728400541,173.0328454
53.6,15.83503136,0.382367914,102209.8197,1.73711445,173.6234096
53.8,15.99242553,0.386151456,102358.0022,1.741907111,174.3381886
54,16.30687703,0.38996112,102698.0322,1.743214234,175.1248825
54.2,16.90054627,0.393787801,103276.0003,1.740164443,175.8320383
54.4,17.1077836,0.397682303,104163.6168,1.734064744,176.7374978
54.6,17.13468268,0.401629628,104793.9254,1.731450581,177.5993718
54.8,17.52805671,0.40558876,105530.0345,1.725786598,178.2978091
55,17.57322566,0.409614194,106498.7645,1.719686879,179.2664644
55.2,17.52115846,0.413687424,107095.7925,1.718815485,180.1860863
55.4,17.86298981,0.417771578,107425.6184,1.72012261,180.8965084
55.6,17.73943831,0.421952795,108159.5526,1.717944124,181.8542666
55.8,18.08624265,0.426119294,108290.3895,1.723608197,182.6082725
56,18.33830705,0.430313703,108573.2136,1.726222396,183.3045291
56.2,18.38759168,0.434586939,108995.5065,1.728836572,184.2023607
56.4,18.33880872,0.43891067,109500.0105,1.728400872,184.9443779
56.6,18.46037863,0.443264909,110147.5068,1.727093804,185.8640018
56.8,18.6176756,0.447660121,111111.7825,1.720558403,186.782536
57,18.89213985,0.452090605,111872.5465,1.71620149,187.6139038
57.2,19.07850853,0.456572345,112954.9829,1.708794703,188.6958784
57.4,19.24243245,0.461100727,113707.6485,1.704873471,189.5544849
57.6,19.38889764,0.465676021,114399.9265,1.703566405,190.5928754
57.8,19.35419242,0.470311035,114770.0391,1.706180571,191.4885271
58,19.70756774,0.474963005,114959.9798,1.710101866,192.247982
58.2,19.74306914,0.479686144,115135.9323,1.715765903,193.1741421
58.4,19.74241349,0.484459439,115372.0423,1.718815768,193.9390419
58.6,19.95532323,0.489264494,115704.8502,1.721865657,194.8728313
58.8,20.52514984,0.494090867,115968.9333,1.724915589,195.7445167
59,20.41228301,0.499017453,116611.5712,1.722737103,196.5715229
59.2,20.60148532,0.503970717,117581.9548,1.718380179,197.6175408
59.4,20.67973809,0.508982125,118567.5024,1.712280463,198.5164623
59.6,20.58679206,0.514056728,119838.8938,1.704002253,199.6278535
59.8,21.23220228,0.519126217,121316.7096,1.693545654,200.7447002
60,21.14090207,0.524302719,122129.3809,1.690495782,201.6730391
60.2,21.42106111,0.529502884,122366.4004,1.695724153,202.6972663
60.4,21.52503488,0.534768647,121980.2147,1.707487924,203.4392851
60.6,21.83675611,0.540071617,121350.4642,1.724044367,204.2869973
60.8,22.51287271,0.545400113,120935.0315,1.736243902,205.0344699
61,22.46848338,0.550836959,121245.7354,1.737986678,205.7895624
61.2,22.42782502,0.556327787,122539.7223,1.728837079,206.8933273
61.4,22.41291964,0.561871793,124303.7333,1.714023459,208.0951574
61.6,22.83179969,0.567438617,125708.8368,1.702695436,209.1291917
61.8,23.13432757,0.57307016,127055.5226,1.693981583,210.3026946
62,22.92909102,0.578796922,127798.5403,1.69398156,211.4652963
62.2,23.16179478,0.584547918,128210.8171,1.696160059,212.36204
62.4,23.19504367,0.590371908,128840.1191,1.697467147,213.4963145
62.6,24.58202082,0.596151425,129406.3678,1.697903011,214.4083246
62.8,24.67757798,0.602087148,130053.1887,1.698338715,215.4608798
63,24.75068803,0.608084217,131362.9865,1.691803301,216.7651326
63.2,25.22683499,0.614110996,132120.3266,1.689624888,217.7534054
63.4,25.3905074,0.620222085,132865.3121,1.689624904,218.9944623
63.6,25.36802075,0.626408646,133602.8966,1.687882125,220.0110595
63.8,25.33721399,0.63265796,134614.758,1.683960869,221.1943656
64,25.25071866,0.638974286,135333.5614,1.684396551,222.4299718
64.2,25.75507112,0.645309244,135644.1631,1.687882174,223.3822888
64.4,25.92035578,0.651733554,136221.8783,1.690060669,224.6266149
64.6,25.74740349,0.658248225,136640.0534,1.692239121,225.5811025
64.8,25.85283377,0.664807112,137074.3914,1.694853308,226.6761532
65,26.12778244,0.671418986,137009.4358,1.703131545,227.7962656
65.2,26.0237737,0.678126079,137322.6865,1.705745704,228.7529341
65.4,26.4881745,0.684857491,137765.9705,1.70835993,229.9231696
65.6,26.92929593,0.691658141,138171.212,1.711409847,231.1010334
65.8,27.07539305,0.698549516,138583.3308,1.714024036,232.1296184
66,27.15167316,0.705515465,139393.1004,1.712281266,233.1451275
66.2,27.3417924,0.712542778,140137.8957,1.712716985,234.3513177
66.4,27.68979495,0.7196288,140557.281,1.714895502,235.2818406
66.6,27.81922691,0.726802535,140906.3733,1.719688164,236.4346396
66.8,27.95612664,0.734047763,140799.1923,1.728402081,237.3836834
67,28.11628345,0.74136416,140906.0448,1.733630442,238.2531868
67.2,28.16008523,0.748762884,141407.9027,1.735808923,239.3656704
67.4,28.57368084,0.75620781,141878.7983,1.737116059,240.2765812
67.6,28.9947438,0.763726936,142435.0391,1.738423195,241.3629186
67.8,29.62105769,0.771306029,143240.2676,1.736244796,242.4383617
68,29.779493,0.778996691,144073.267,1.733194951,243.4124661
68.2,30.1415169,0.786749221,145023.9044,1.730580825,244.6317351
68.4,30.25837634,0.794598205,145881.8473,1.727530974,245.6505132
68.6,30.60957202,0.802508365,147822.7213,1.715331555,247.0811635
68.8,30.46961986,0.81053524,150437.2585,1.696596651,248.5248829
69,30.80915577,0.818606334,152253.3792,1.685704315,249.795362
69.2,30.85366524,0.826780952,154313.2465,1.674376249,251.3731042
69.4,30.92309238,0.835035771,156537.1203,1.662176796,253.0870474
69.6,31.2426446,0.843354449,157227.5287,1.662612528,254.324839
69.8,31.40927508,0.851768512,157106.816,1.671326451,255.6051216
70,31.55677859,0.860268462,157040.3742,1.680040371,256.9703935
70.2,31.74332664,0.868850916,156244.1567,1.694418333,257.927066
70.4,31.8160107,0.877528166,155588.7348,1.709231977,259.0722373
70.6,32.15128453,0.886272657,155573.5395,1.71620314,260.0169266
70.8,32.80067153,0.895081211,155547.3316,1.724481426,261.1065352
71,33.75087527,0.903955345,155774.6803,1.730145577,262.2756894
71.2,33.7827831,0.912988368,157088.8404,1.723610154,263.4404729
71.4,34.26758471,0.922077793,158555.4344,1.717074785,264.8743944
71.6,34.53547448,0.931274986,159923.5067,1.710103694,266.0718709
71.8,34.81332185,0.940563887,161505.4917,1.701825519,267.4905345
72,34.87758114,0.949962395,163555.097,1.690933148,269.1456393
72.2,34.90609137,0.959458022,164483.3364,1.689626067,270.4008598
72.4,35.20134525,0.969028759,165396.9267,1.690497493,271.9230366
72.6,35.12096086,0.978724154,166015.3911,1.692240266,273.0867309
72.8,35.28986828,0.988498039,166856.5657,1.693547372,274.4378384
73,35.60252731,0.998359186,167000.9773,1.70182562,275.8379797
73.2,35.62514308,1.00834152,167113.9937,1.707925357,276.9352085
73.4,36.21865668,1.018380666,167166.5398,1.715767943,278.2438272
73.6,36.78721532,1.028574236,166591.8539,1.727096088,279.152563
73.8,37.0391537,1.038791639,165872.5566,1.740166978,280.1473724
74,37.88192597,1.049118363,165040.9721,1.754545025,281.1825056
74.2,37.94185671,1.059608349,164661.591,1.764130331,282.2143581
74.4,38.283488,1.070182278,165187.3831,1.764130373,283.1917365
74.6,38.51125207,1.080871017,166573.6636,1.757594972,284.5526517
74.8,38.94426213,1.091651575,167714.7135,1.752802377,285.7544868
75,39.01326623,1.102568111,169273.6933,1.74408848,286.9476025
75.2,39.44125548,1.113567227,171228.3154,1.734067539,288.5100963
75.4,39.44789772,1.12470877,171954.4577,1.733631846,289.6498201
75.6,39.52225065,1.1359573,172826.4641,1.733196161,291.0052852
75.8,39.91736105,1.147294798,173787.2459,1.731889123,292.3389633
76,40.02907395,1.158767788,174578.1482,1.731017747,293.4841357
76.2,40.0622367,1.170362036,175552.9011,1.730146362,294.9256793
76.4,40.79427265,1.182019704,176405.5117,1.729275059,296.1111765
76.6,41.10038985,1.193826975,177205.0618,1.730146487,297.4917058
76.8,41.04997863,1.205779866,177804.0478,1.73232496,298.7937793
77,41.75453429,1.217795242,178004.7433,1.736681999,299.8550611
77.2,42.14203484,1.229955523,177905.8378,1.74496026,301.1004815
77.4,42.22868504,1.242260665,177902.4285,1.750624313,302.0789456
77.6,42.82805789,1.25465039,178195.8648,1.754981341,303.3603258
77.8,43.33267414,1.26717189,179009.4911,1.754110012,304.5621633
78,43.84890478,1.27981816,180147.5621,1.750188816,305.7541953
78.2,43.97661114,1.29262084,181916.6637,1.742346314,307.2992529
78.4,44.34570976,1.305533947,184242.5291,1.729711187,308.8720979
78.6,44.39401222,1.318600801,186158.6314,1.720997286,310.3980865
78.8,45.10171214,1.331748428,186740.4825,1.723175849,311.7317703
79,45.49360158,1.345052289,187259.5263,1.727097153,313.2376042
79.2,45.68436177,1.358504997,187324.8949,1.732761216,314.3718841
79.4,46.00640242,1.372082891,186713.3849,1.744960738,315.57372
79.6,46.50127459,1.385784141,186475.5907,1.752367618,316.5532782
79.8,46.92548777,1.399628324,187519.6174,1.750189194,317.9141974
80,47.15023283,1.413626879,188943.8075,1.74539657,319.4908549
80.2,47.30514945,1.427771286,190561.6397,1.737989763,320.7831252
80.4,47.53982189,1.442051697,193173.1784,1.724918928,322.6147497
80.6,47.95231089,1.456462126,195261.861,1.714897976,324.0922564
80.8,48.76699302,1.470986961,196914.2141,1.709669726,325.7114177
81,49.1553361,1.485690009,198684.6966,1.704877122,327.5637473
81.2,49.29268612,1.500559846,200098.0619,1.700955878,329.0695795
81.4,49.72918146,1.515556277,201796.7173,1.696598978,330.9240905
81.6,50.0351819,1.530713348,202841.2846,1.695291928,332.3689077
81.8,50.60459315,1.546002601,204074.4855,1.694856296,334.3628873
82,50.66788562,1.561483971,204982.4965,1.694420612,335.7946256
82.2,51.33780181,1.577074816,205445.7466,1.698777649,337.5336429
82.4,52.05506156,1.592818779,205688.6452,1.703134691,338.9163602
82.6,52.59694986,1.608734144,206313.6143,1.706620322,340.6226858
82.8,52.78479596,1.624836329,207436.5733,1.705748954,342.2788836
83,53.08812886,1.641091559,208836.4537,1.702263425,343.8490057
83.2,53.26428892,1.657519842,211115.0446,1.694420923,345.8386223
83.4,54.11687745,1.674061667,212266.9219,1.693549631,347.4065743
83.6,54.30129514,1.690820427,213668.9757,1.692242567,349.3275467
83.8,54.78901035,1.707724637,214181.708,1.696599583,350.9390764
84,54.69082564,1.724842994,212691.5579,1.71577019,352.3915151
84.2,55.35217089,1.74207566,211422.5916,1.731019624,353.4549776
84.4,55.74756046,1.759501726,211367.8033,1.738426502,354.9368447
84.6,56.1753322,1.777100465,211085.415,1.745833384,356.1201601
84.8,56.77842227,1.794862574,211277.6716,1.750190417,357.4887115
85,57.14464166,1.812821373,213336.3065,1.74191224,359.3148913
85.2,57.35875472,1.830971951,215073.1073,1.735376829,360.8120091
85.4,58.17450137,1.849259217,216374.0748,1.734069839,362.5608345
85.6,58.5913265,1.867760631,218012.7919,1.731020018,364.3194609
85.8,59.0180944,1.886447173,219595.5001,1.727534503,366.0192479
86,59.62682712,1.905307601,220860.5592,1.725356096,367.5523296
86.2,59.8981333,1.924383004,222453.8589,1.721870562,369.4144659
86.4,60.13118181,1.943653092,223675.4232,1.719256415,370.9028674
86.6,60.73649911,1.963088533,225258.6905,1.71577092,372.890313
86.8,61.51380777,1.982706104,226596.9831,1.713592532,374.6336912
87,61.88305142,2.002551756,227598.2125,1.713592577,376.2212495
87.2,62.07359282,2.022610372,228895.8356,1.713592601,378.2097782
87.4,63.23972665,2.042796395,229968.0913,1.714899828,380.1144248
87.6,63.66206003,2.06324184,230559.5177,1.71707836,381.5058554
87.8,64.21981803,2.083882349,230297.3662,1.725792349,383.0890588
88,64.69111637,2.104736803,230087.4891,1.734506329,384.7975642
88.2,64.90393231,2.125820382,230836.818,1.735377748,386.2369346
88.4,65.60452691,2.147078739,232583.5138,1.731020871,388.1884262
88.6,66.04414539,2.168570497,234180.1458,1.726663963,389.7890614
88.8,66.56683217,2.190271851,237814.3538,1.712286052,392.2766347
89,66.94156163,2.212202609,239866.9319,1.705750655,394.0287237
89.2,67.12512006,2.234368208,241449.491,1.704007893,396.2155606
89.4,67.5305271,2.256739571,241351.8931,1.710979081,397.6985179
89.6,68.12703446,2.279321203,240705.6426,1.722742951,399.4201018
89.8,68.94954493,2.302112597,239433.1837,1.737556723,400.8257058
90,69.35235077,2.325164705,239329.1268,1.744092217,402.1582986
90.2,69.96453844,2.348432558,239709.9382,1.749320647,403.9071235
90.4,70.4329214,2.371945142,240702.1778,1.748885009,405.3639332
90.6,70.6203799,2.395715289,242135.7033,1.746706551,407.2533085
90.8,71.45932516,2.419674857,243190.127,1.746270957,408.9552853
91,71.93922876,2.443902366,243545.5856,1.74932089,410.3227471
91.2,72.62766171,2.468481022,243966.9431,1.753242242,412.1053512
91.4,73.12745161,2.49307426,244672.6789,1.754985089,413.8814147
91.6,73.51831801,2.518047244,245833.5709,1.753242352,415.3295055
91.8,74.16260766,2.543251818,247265.1463,1.751063949,417.0685255
92,74.92652493,2.568700496,249742.3517,1.743657202,419.2030749
92.2,75.44192458,2.594423934,252194.8216,1.735379033,420.935555
92.4,75.77695039,2.62041948,254988.613,1.727536538,423.1616216
92.6,76.58229583,2.646640361,257325.8351,1.72056549,424.9932599
92.8,76.96543782,2.673156913,260494.3583,1.710108821,427.2367627
93,77.96765246,2.699892765,263363.2622,1.702702098,429.7003779
93.2,78.49156828,2.726934946,264467.1314,1.704880644,431.9286279
93.4,79.30339175,2.754227051,264830.8817,1.709237706,433.6099028
93.6,79.77860576,2.781818892,264650.5665,1.717515999,435.5526765
93.8,80.54588171,2.809665749,264102.1967,1.727101416,437.3254778
94,81.17100759,2.837803283,264684.3339,1.728844279,438.9337464
94.2,82.18542475,2.866193933,266788.3706,1.724051737,441.2622515
94.4,82.61600006,2.894914278,268257.7131,1.721437609,443.0742722
94.6,83.46162758,2.923891687,270706.0426,1.715773653,445.4409096
94.8,83.8493129,2.95319493,273180.6482,1.710109643,447.6299318
95,84.50537329,2.982771708,274605.1582,1.710763267,449.7721079
95.2,85.18507079,3.012643654,275348.6185,1.714466771,451.7573806
95.4,85.55640951,3.042839057,277590.6185,1.710981242,454.2242531
95.6,86.36440491,3.073304437,278724.3143,1.711417035,456.0733294
95.8,87.01362549,3.104087825,279024.7654,1.716645475,458.0030319
96,87.4425747,3.135197042,279397.0406,1.721873889,460.1768015
96.2,88.05097641,3.166603667,279517.176,1.727102319,461.8983881
96.4,88.92193266,3.198305953,278398.6474,1.740173333,463.7365731
96.6,89.37400047,3.230358557,278802.1541,1.743658966,465.3840639
96.8,89.96479872,3.262722575,280306.1797,1.742351942,467.4259935
97,90.88047708,3.295387137,281914.4761,1.741480663,469.6411798
97.2,91.49859541,3.328402656,283733.9723,1.737995158,471.4913421
97.4,91.6787095,3.361782959,286608.6602,1.730588334,473.9582128
97.6,92.65572584,3.395437964,287493.944,1.731895542,475.7321089
97.8,93.80138711,3.429418423,287752.2354,1.737124041,477.6956026
98,94.51236664,3.463773432,288877.0239,1.737995527,479.9293083
98.2,94.9822933,3.498491726,289560.3871,1.73973837,481.7206292
98.4,95.65659738,3.533543326,290661.9765,1.740609848,483.9292734
98.6,96.73721815,3.568916311,292672.6572,1.736253007,485.9036623
98.8,97.37318253,3.604678538,295434.8417,1.72928193,488.1722342
99,97.71823003,3.640822127,299016.0697,1.719696635,490.8918956
99.2,98.32000749,3.677309268,302336.4606,1.711854158,493.6322657
99.4,99.18433157,3.714143043,304650.4144,1.707497295,495.8627095
99.6,99.99956623,3.751350585,306139.6472,1.707933089,498.3720868
99.8,100.7831624,3.78893437,305986.6839,1.715340029,500.505552
100,101.5658676,3.826896005,305607.3388,1.722746983,502.2936143
100.2,102.2928333,3.865243164,304686.0735,1.7340752,504.4020186
100.4,102.9499315,3.903980885,303390.1482,1.74540341,505.9154959
100.6,103.6825913,3.943102141,304354.6662,1.747581986,508.1786229
100.8,104.305493,3.982624732,306742.9892,1.742789391,510.4384806
101,105.3563113,4.022511898,308298.6457,1.741482426,512.3213426
101.2,106.1128818,4.062822085,310974.3218,1.736689847,514.9287882
101.4,107.2740989,4.103506588,314879.5186,1.726668946,517.7280124
101.6,107.7903729,4.144648889,316066.4939,1.727540403,519.7067468
101.8,108.6938406,4.186175103,317573.5618,1.727540512,522.0167349
102,109.3969641,4.228133749,320381.4739,1.722312227,524.833382
102.2,110.081738,4.270515371,323143.0301,1.715776847,527.0910602
102.4,110.9692153,4.313307226,325267.1345,1.713598465,529.9164312
102.6,111.8433278,4.356530213,326700.5052,1.713162872,532.08041
102.8,112.594379,4.400196749,328032.495,1.714034357,534.4742922
103,113.4351117,4.444295065,327419.4392,1.724491201,536.9052246
103.2,114.4851934,4.488820651,326130.2056,1.735819466,538.5451077
103.4,115.2177508,4.53381776,325981.7249,1.74409781,540.8256714
103.6,116.0557772,4.579259049,327248.3994,1.744097912,542.843643
103.8,116.864645,4.625158976,328978.2686,1.742790918,545.1612554
104,117.7000325,4.671517989,332271.8991,1.735819855,547.9648342
104.2,118.5744044,4.718339918,334745.1244,1.732770077,550.6888698
104.4,119.4370671,4.765633144,335549.3946,1.735384368,552.7471588
104.6,120.4085192,4.813393245,335481.2803,1.743227046,555.0517033
104.8,121.2843267,4.861640572,335565.6414,1.749326923,557.0947378
105,121.9647654,4.910387371,336080.3286,1.752376891,558.9797741
105.2,123.2459605,4.959578269,337697.8337,1.751941349,561.5458325
105.4,124.3924503,5.009273633,338800.9481,1.752377186,563.5180487
105.6,125.3194691,5.059484924,340374.4881,1.751505903,565.8770727
105.8,126.1051327,5.110211399,342094.9946,1.750198906,568.2829447
106,127.2405789,5.161421027,343871.7152,1.749327647,570.8773275
106.2,127.9438078,5.213178076,345766.4882,1.746713545,573.0838004
106.4,128.9901695,5.265428931,349348.6586,1.738435409,576.0137833
106.6,129.9358931,5.318212515,351687.1177,1.73451424,578.3074287
106.8,130.9837493,5.371518409,354177.3231,1.731028781,581.0151322
107,131.8944004,5.425370462,355356.5902,1.732335986,583.2739112
107.2,132.9188167,5.479754932,356429.8273,1.735821695,585.9968662
107.4,134.0794351,5.534675449,356824.7013,1.74192161,588.5128013
107.6,134.7978579,5.590181303,358160.5372,1.742357396,590.7029334
107.8,135.9907103,5.646208865,359548.0171,1.743228937,593.1458647
108,137.0970462,5.70280588,360515.4312,1.746714658,595.7478777
108.2,138.455925,5.759952453,360899.7975,1.751071806,597.7255515
108.4,139.1798054,5.817721429,362460.5241,1.751943292,600.4158136
108.6,140.3099676,5.87603985,362908.5956,1.755864715,602.3651531
108.8,141.2713374,5.934957263,363215.457,1.761093215,604.4866479
109,142.1768863,5.994771816,364219.6129,1.763707517,606.9764258
109.2,143.3117997,6.054569047,364669.6441,1.766757546,608.8396894
109.4,144.7349372,6.115247792,364829.3521,1.772421801,611.1442486
109.6,145.7956486,6.17656367,366208.3159,1.772857631,613.6089723
109.8,146.6318838,6.238512749,368888.4549,1.767629351,616.054076
110,147.7306259,6.301064193,372637.4566,1.758044115,618.5678329
110.2,148.9198505,6.364237374,378926.9632,1.740180614,622.0295513
110.4,150.1887533,6.428039104,384921.2877,1.722752817,625.0619687
110.6,151.6865031,6.492466272,391148.2651,1.706632141,628.7677678
110.8,152.7973049,6.557571698,395974.2068,1.695739802,632.2305745
111,153.8365341,6.623336662,400151.6734,1.688333045,636.0213521
111.2,154.7264883,6.689773815,402249.3062,1.687461752,638.9546031
111.4,155.9200783,6.756855541,402401.2586,1.695304472,642.1526386
111.6,157.3533139,6.824592846,402016.1473,1.703582921,644.6206459
111.8,158.8915669,6.893002973,400560.2267,1.716218373,647.0919249
112,159.8762438,6.962142542,397341.9766,1.736260647,649.4901834
112.2,160.9285394,7.031971607,394151.702,1.754124435,651.1507804
112.4,162.2503934,7.102481836,391530.9622,1.770681162,653.2537647
112.6,163.3868147,7.173714591,391022.5994,1.777216789,655.0843446
112.8,164.7616287,7.245644004,393149.2544,1.774602764,657.5828588
113,166.0926989,7.318298799,397583.4585,1.764146146,660.7373185
113.2,167.6106354,7.391668564,404095.6906,1.745846963,663.8601845
113.4,168.9240212,7.465790693,412076.9839,1.724933555,667.8612687
113.6,170.5730261,7.540629492,417170.2267,1.714041268,671.0353516
113.8,171.6347874,7.616264055,421146.3427,1.707941603,674.4371453
114,173.063744,7.692632944,423994.3049,1.706198975,677.9849588
114.2,174.5150171,7.769764658,425678.5379,1.707941944,681.3856738
114.4,175.4575753,7.847709474,426990.1902,1.709684849,684.2045258
114.6,177.0058318,7.926391436,428275.3032,1.71273493,687.5856301
114.8,179.0010584,8.005830026,428799.5658,1.717963566,690.6442324
115,180.3196978,8.086118069,430052.4595,1.720142217,693.4151497
115.2,181.4985955,8.167223468,430740.9279,1.725806459,696.6230013
115.4,182.5676674,8.24915209,431511.7823,1.729292178,699.2511728
115.6,184.2914626,8.331853926,433517.2667,1.729728086,702.6072281
115.8,185.789916,8.41540389,435120.6756,1.731035364,705.6592752
116,187.1461293,8.499804124,435671.9186,1.734956832,708.1937573
116.2,188.3576083,8.585063261,436215.0563,1.740621072,711.292645
116.4,189.8922231,8.671154548,436887.4387,1.744542556,713.7236173
116.6,191.508973,8.75810449,437650.089,1.749771152,716.7015768
116.8,192.9651946,8.845940196,440105.5121,1.748464233,719.6926092
117,194.5018864,8.934652438,442584.1138,1.747593019,723.0083481
117.2,195.6553302,9.024284934,445641.4324,1.743236159,725.9034805
117.4,197.0737307,9.114797815,449003.3195,1.739315029,729.4447626
117.6,198.74379,9.206201044,451333.3107,1.737136729,732.1786562
117.8,199.9674384,9.298556542,452582.1231,1.739315378,735.2808173
118,201.3114392,9.391830633,455600.4329,1.736701339,738.8754906
118.2,202.9370118,9.486020502,458512.0225,1.733215932,741.7510331
118.4,204.3679722,9.58117147,462560.8614,1.727987699,745.6399008
118.6,205.8303601,9.677275884,466650.1959,1.721452368,748.8390519
118.8,207.3216808,9.77434384,473265.9578,1.709252933,752.9611025
119,209.038888,9.872369809,478313.8688,1.702717629,757.2509624
119.2,210.8972147,9.971370015,480929.4382,1.701410746,760.5296697
119.4,212.2484525,10.07140345,483207.4109,1.702718008,764.5046195
119.6,213.6743237,10.17243623,484088.8836,1.707946584,768.2660093
119.8,215.4582097,10.27445671,483146.482,1.717532211,771.3344218
120,216.8164432,10.3775347,482889.0858,1.724067884,774.1108031
120.2,218.2310225,10.48164396,483655.3007,1.729296463,777.7436175
120.4,219.8847738,10.58678106,484029.1582,1.734089371,780.492771
120.6,221.8101059,10.69295376,483180.0768,1.743675022,783.5927877
120.8,223.4543788,10.80021453,483278.8138,1.749339333,786.4814095
121,225.1948807,10.90854574,484679.0046,1.751082348,789.305749
121.2,226.9726063,11.01796251,485182.8799,1.756746677,792.5332482
121.4,228.9205197,11.12846575,486572.0114,1.75936112,795.6801226
121.6,230.9197812,11.24007523,489693.6256,1.755875754,798.6646466
121.8,232.6280021,11.35282827,494317.3873,1.748904742,802.2397301
122,234.0834082,11.46673325,498644.0363,1.743240803,806.1177153
122.2,235.9209092,11.58175356,503772.5421,1.7353984,810.1874891
122.4,237.7499163,11.69793014,508767.2736,1.726684592,813.7288017
122.6,239.7308177,11.81526245,513493.5657,1.720149307,818.0688049
122.8,241.3492003,11.93380102,515449.3799,1.719713799,821.179716
123,243.3147669,12.0535042,516788.4244,1.723199645,825.1263673
123.2,245.2842689,12.08048659,518336.945,1.72624979,828.9607932
123.4,246.7602931,12.08037413,519583.5488,1.729299876,832.0967592
123.6,247.8756476,12.08028896,520822.66,1.734092727,835.8254581
123.8,248.7259014,12.08022384,523750.8332,1.733221426,839.4026895
124,249.680866,12.08015079,527601.0716,1.728864522,842.9570443
124.2,249.8455146,12.08013753,530917.6925,1.727121736,847.1684065
124.4,250.0990842,12.08011754,531838.1456,1.731914486,851.031093
124.6,250.8462897,12.08006021,531458.9749,1.738450102,853.7965609
124.8,251.1688353,12.08003501,530170.7647,1.748906985,856.8278795
125,251.5179742,12.08000779,527814.4322,1.763285187,859.671783
125.2,251.6119847,12.07999987,525501.5155,1.775920552,861.8488348
125.4,251.8971338,12.07997749,523362.4167,1.788991642,864.5717891
125.6,252.1315896,12.07995894,524318.4702,1.791605883,867.081177
125.8,252.5995667,12.07992274,525749.1625,1.792913047,869.9643126
126,252.4525766,12.07993305,526918.5282,1.794655838,873.1220052
126.2,252.7576705,12.07990916,529069.7202,1.792913069,875.8667563
126.4,252.8176086,12.07990382,531131.2499,1.792477376,879.1780887
126.6,253.605535,12.07984341,529994.2695,1.800755809,881.8672882
126.8,253.373779,12.07986013,529948.5594,1.805984204,884.4224191
127,253.4578172,12.07985296,530868.8957,1.808162725,886.8184848
127.2,253.6598625,12.07983687,531472.1363,1.812084068,889.7005176
127.4,253.9558151,12.07981368,533252.476,1.811648404,892.1085768
127.6,254.0747568,12.07980387,536581.3461,1.807727103,895.2935216
127.8,254.1779088,12.07979526,536429.1208,1.81295554,897.7909165
128,254.2253813,12.07979086,535066.6854,1.820798181,899.7751058
128.2,254.5308908,12.07976694,534337.7401,1.82776945,902.2921262
128.4,254.3780833,12.07977769,533163.629,1.834740663,904.0670988
128.6,254.4783267,12.0797693,532305.7904,1.842147609,906.3247827
128.8,254.588958,12.07976012,536028.9775,1.836483499,909.0052352
129,254.7058221,12.07975047,539914.6103,1.830383689,911.5799974
129.2,254.5077232,12.07976465,542006.279,1.830383665,914.3465157
129.4,255.2540978,12.07970738,543725.8195,1.830601611,916.7317106
129.6,255.1902114,12.0797114,543787.6244,1.835176474,918.9556086
129.8,254.947652,12.07972894,541527.378,1.845633291,920.7011592
130,255.567709,12.07968123,540136.016,1.853911707,922.7561959
130.2,255.4872018,12.07968651,540287.1062,1.856961612,924.5344417
130.4,255.5450623,12.07968132,540889.1038,1.85914013,926.7485392
130.6,255.4948879,12.07968431,542401.3039,1.858268721,928.6008797
130.8,255.7621697,12.07966328,545170.8398,1.854783141,931.0143844
131,255.905627,12.07965162,547616.2225,1.852604651,933.5771626
131.2,255.9331546,12.07964873,548689.7831,1.853040357,935.5035982
131.4,256.3088868,12.0796195,548472.8006,1.85826883,937.6120173
131.6,256.214252,12.07962585,548045.1908,1.863061533,939.2311779
131.8,256.2201726,12.07962459,546234.6237,1.871775576,940.6956198
132,256.3449316,12.07961435,544210.1619,1.881361036,942.1742317
132.2,256.4987769,12.0796019,542397.1168,1.890510796,943.5711168
132.4,256.4423697,12.07960536,541089.9239,1.897046322,944.6204169
132.6,256.8031433,12.07957726,538969.6281,1.906196117,945.75254
132.8,256.7508913,12.0795804,537281.3529,1.91360304,946.6754374
133,256.5000215,12.07959857,534815.489,1.922752744,947.2485629
133.7,256.9519012,12.01254607,1.7977E+308,1.976779863,0
133.9,256.8473739,11.89180456,1.7977E+308,1.981572569,0
134.1,256.4461664,11.77108548,1.7977E+308,1.904017565,0
134.3,256.3466253,11.65034358,1.7977E+308,1.741936423,0
134.5,256.1166115,11.52961155,1.7977E+308,1.515371381,0
134.7,255.9672082,11.40887343,1.7977E+308,1.147203219,0
134.9,255.7588013,11.28813977,1.7977E+308,0.757249969,0
135.1,255.7049673,11.16739441,1.7977E+308,0.456179928,0
135.3,255.4940673,11.04666094,1.7977E+308,0.216108157,0
135.5,255.097846,10.92594149,1.7977E+308,0.06143397,0
135.7,254.6916523,10.80522278,1.7977E+308,0.023963605,0
135.9,254.5580388,10.68448347,1.7977E+308,0.028756326,0
136.1,254.3039249,10.56375326,1.7977E+308,0.029192027,0
136.3,254.1595079,10.44301476,1.7977E+308,0.028320623,0
136.5,253.9386354,10.32228204,1.7977E+308,0.033549045,0
136.7,253.7003112,10.20155064,1.7977E+308,0.037906063,0
136.9,253.2076897,10.08083848,1.7977E+308,0.034420447,0
137.1,253.5768536,9.960061129,1.7977E+308,0.032241938,0
137.3,253.0285526,9.839353177,1.7977E+308,0.031806235,0
137.5,252.5899485,9.718636927,1.7977E+308,0.036163253,0
137.7,252.4646454,9.59789698,1.7977E+308,0.037470358,0
137.9,252.3002835,9.477159987,1.7977E+308,0.038777463,0
138.1,252.2846772,9.356411742,1.7977E+308,0.034420445,0
138.3,251.7031348,9.235706304,1.7977E+308,0.027449214,0
138.5,251.675894,9.114958939,1.7977E+308,0.01437816,0
138.7,251.2946315,8.994238352,1.7977E+308,0.005228422,0
138.9,251.0829005,8.873504942,1.7977E+308,0.007842632,0
139.1,250.8404212,8.752773857,1.7977E+308,0.018735177,0
139.3,250.4383828,8.632054842,1.7977E+308,0.023963598,0
139.5,250.4485386,8.511304648,1.7977E+308,0.022220791,0
139.7,250.0880521,8.39058249,1.7977E+308,0.024399299,0
139.9,249.7034655,8.269862155,1.7977E+308,0.025706403,0
140.1,249.6030935,8.149120321,1.7977E+308,0.027884912,0
140.3,249.2467621,8.028397849,1.7977E+308,0.025706403,0
140.5,248.9128688,7.907673679,1.7977E+308,0.023963595,0
140.7,248.613048,7.786946932,1.7977E+308,0.027449208,0
140.9,248.5691865,7.666200824,1.7977E+308,0.029192015,0
141.1,248.3607797,7.545467162,1.7977E+308,0.030063418,0
141.3,248.0734244,7.424739472,1.7977E+308,0.024399295,0
141.5,247.5891135,7.30402668,1.7977E+308,0.019170874,0
141.7,247.6109038,7.183275606,1.7977E+308,0.014378156,0
141.9,247.2811657,7.062551122,1.7977E+308,0.00784263,0
142.1,246.9505966,6.941826701,1.7977E+308,0.006971227,0
142.3,246.7446829,6.821092851,1.7977E+308,0.017428066,0
142.5,246.6135626,6.700353343,1.7977E+308,0.026142099,0
142.7,246.1525207,6.579638791,1.7977E+308,0.029627712,0
142.9,245.9756934,6.458902741,1.7977E+308,0.028320606,0
143.1,245.8379247,6.338163736,1.7977E+308,0.023092187,0
143.3,245.3769789,6.216845433,1.7977E+308,0.012635347,0
143.5,245.2698626,6.096707853,1.7977E+308,0.005228419,0
143.7,244.8894313,5.975987203,1.7977E+308,0.004357016,0
143.9,244.5721588,5.855261776,1.7977E+308,0.00261421,0
144.1,244.3479624,5.734529309,1.7977E+308,0.001307105,0
144.3,244.3432556,5.613176496,1.7977E+308,0.000871403,0
144.5,244.4223874,5.492421085,1.7977E+308,0.004792717,0
144.7,243.9196979,5.372313426,1.7977E+308,0.009585435,0
144.9,243.5434218,5.251592462,1.7977E+308,0.012199644,0
145.1,243.3233806,5.130859681,1.7977E+308,0.017428062,0
145.3,243.0426737,5.010131488,1.7977E+308,0.028320601,0
145.5,242.6813563,4.889409392,1.7977E+308,0.035509675,0
145.7,242.240675,4.7686933,1.7977E+308,0.037906033,0
145.9,242.1232668,4.647952755,1.7977E+308,0.037906032,0
146.1,241.9048877,4.527219848,1.7977E+308,0.033113315,0
146.3,241.5664238,4.406496024,1.7977E+308,0.02614209,0
146.5,241.3185429,4.285765348,1.7977E+308,0.025270687,0
146.7,241.0386671,4.165037092,1.7977E+308,0.031370507,0
146.9,240.8036673,4.044305442,1.7977E+308,0.036163223,0
147.1,240.3343153,3.923591519,1.7977E+308,0.031370505,0
147.3,240.3087366,3.802844028,1.7977E+308,0.025270685,0
147.5,239.9989435,3.682118035,1.7977E+308,0.00893188,0
147.7,239.703278,3.561390974,1.7977E+308,0.016120953,0
147.9,239.1857259,3.440680696,1.7977E+308,0.030934802,0
148.1,239.0280125,3.3199432,1.7977E+308,0.031370503,0
148.3,238.6022899,3.199225976,1.7977E+308,0.0309348,0
148.5,238.6203406,3.078475185,1.7977E+308,0.027449189,0
148.7,238.1518197,2.957761198,1.7977E+308,0.019606563,0
148.9,237.8320543,2.83703596,1.7977E+308,0.016556653,0
149.1,237.4059162,2.716318768,1.7977E+308,0.021349367,0
149.3,236.9747919,2.595601952,1.7977E+308,0.027449186,0
149.5,236.7073818,2.474872754,1.7977E+308,0.031370497,0
149.7,236.4175336,2.354145252,1.7977E+308,0.030499094,0
149.9,236.137658,2.233416997,1.7977E+308,0.024834976,0
150.1,235.9782825,2.112679626,1.7977E+308,0.018735157,0
150.3,235.3493717,1.991977772,1.7977E+308,0.012635338,0
150.5,235.0005201,1.871254733,1.7977E+308,0.00348561,0
150.7,234.4813061,1.750544581,1.7977E+308,0.009585428,0
150.9,234.1798235,1.62981796,1.7977E+308,0.02047796,0
151.1,233.6390026,1.509109442,1.7977E+308,0.035291802,0
151.3,233.6499895,1.388359185,1.7977E+308,0.047491438,0
151.5,233.0385306,1.267656011,1.7977E+308,0.050105643,0
151.6,232.7376594,1.208109047,1.7977E+308,0.051848447,0
226.9,231.945474,1.033181247,1.7977E+308,0.034420405,0
227.1,231.7611675,0.912445762,1.7977E+308,0.030063391,0
227.3,231.3558054,0.791726998,1.7977E+308,0.028756287,0
227.5,230.8889466,0.671012886,1.7977E+308,0.03006339,0
227.7,230.6481297,0.550281676,1.7977E+308,0.028320584,0
227.9,229.9411016,0.42958573,1.7977E+308,0.018299453,0
228.1,229.2116356,0.308891481,1.7977E+308,0.011763934,0
228.3,228.2054348,0.188218165,1.7977E+308,0.016992347,0
228.5,226.8983991,0.067567604,1.7977E+308,0.017863748,0
228.606,226.4275484,0.003606024,1.7977E+308,0.017863748,0
,,,,,