File: TestGB_4.csv
Time On Sample,Displacement Into Surface,Load On Sample,Harmonic Contact Stiffness,Harmonic Displacement,Harmonic Load
0,0,0,-169.7053574,0.429984409,2.180133596
0.2,0.381233596,0.000729234,3589.657946,0.267487775,2.258579228
0.4,0.302960996,0.001491682,10553.65395,0.200398006,2.328308631
0.6,0.452364507,0.002235515,14616.03184,0.173387842,2.393679974
0.8,0.428102832,0.002992482,15755.20937,0.162496646,2.449245598
1,0.427938241,0.003747627,17814.07041,0.15160545,2.62356913
1.2,0.606424441,0.00448926,19211.8334,0.148991565,2.788086988
1.4,0.615400123,0.005243714,20316.45741,0.149862861,2.952604825
1.6,0.762310836,0.005987734,21250.63099,0.151605454,3.111675072
1.8,0.787905197,0.006740929,23031.97562,0.150734158,3.347011849
2,0.969715139,0.007482309,25668.91843,0.149862865,3.70982274
2.2,1.030208726,0.008232864,30199.4626,0.139407317,4.08134979
2.4,0.618731838,0.009019116,35163.05464,0.129823061,4.453966269
2.6,0.810512985,0.009759741,39902.29783,0.123288345,4.826582863
2.8,0.910060467,0.010507343,41537.40153,0.125902233,5.144723342
3,1.011269818,0.011254818,45730.60078,0.131130008,5.881240313
3.2,1.026062039,0.01200883,44871.86501,0.148991571,6.542580246
3.4,1.218674127,0.012749391,43519.82202,0.169031375,7.193024985
3.6,1.306173071,0.013497902,42403.20232,0.189071179,7.853275453
3.8,1.421092837,0.014244338,41807.16015,0.207368392,8.531503015
4,1.307921227,0.015008027,41083.76791,0.234378559,9.552929954
4.2,1.153618386,0.015774826,40393.2076,0.25833919,10.43653235
4.4,1.43015481,0.016509038,39394.79249,0.288834547,11.43998237
4.6,1.637723717,0.017248467,38965.14974,0.317151664,12.40638864
4.8,1.519566502,0.018012531,38648.62296,0.341983592,13.22461968
5,1.471623208,0.018771284,38967.36309,0.370954175,14.39476643
5.2,1.530454932,0.019521962,39270.63804,0.396875227,15.43090206
5.4,1.515333531,0.020278233,39043.10055,0.430420114,16.5422146
5.6,1.448694223,0.021038401,38044.34216,0.471371014,17.60340913
5.8,1.414461341,0.021796117,37234.29121,0.50709414,18.49028012
6,1.504037623,0.022544469,36624.70062,0.549351989,19.65933746
6.2,1.154880761,0.023326005,35880.33138,0.591609821,20.73033742
6.4,1.01428833,0.024091767,34877.956,0.638224138,21.74904045
6.6,1.332371453,0.024822838,33803.75184,0.682660238,22.5454815
6.8,1.25409907,0.025583886,32380.64904,0.73711622,23.32884776
7,1.113506638,0.026349648,30273.6709,0.819453663,24.26256811
7.2,1.471474596,0.027077701,28285.34162,0.903969376,25.0285026
7.4,1.182975913,0.027854649,26505.92588,0.991098935,25.73015453
7.6,1.358138395,0.028596528,25346.77494,1.057317428,26.27818435
7.8,1.484275774,0.029342115,24384.36822,1.120050735,26.82839332
8,1.454197561,0.030099517,23564.64626,1.183655326,27.48537511
8.2,1.494748739,0.030851575,23162.22226,1.22329929,27.97892868
8.4,1.476303602,0.031608097,22857.28738,1.2625076,28.55855451
8.6,1.560063348,0.032356889,22601.88084,1.294745553,29.01833288
8.8,1.551589419,0.033112655,22346.30658,1.328290442,29.4770218
9,2.081560738,0.033827697,22066.2684,1.367063158,29.98473995
9.2,1.709968639,0.034610927,21807.05119,1.400172364,30.3333865
9.4,1.423962751,0.035387685,21558.27726,1.436331113,30.76810543
9.6,1.851729181,0.036110456,21429.0909,1.461598736,31.10476853
9.8,1.852395528,0.036865531,21444.2719,1.479460302,31.46975835
10,2.089047141,0.037602755,21604.19046,1.493401062,31.91210484
10.2,2.098022828,0.0383572,22030.47172,1.484252458,32.29888526
10.4,2.296451479,0.039097315,22946.78686,1.454628422,32.86870573
10.6,2.477430519,0.03983875,24018.23066,1.415855776,33.39603474
10.8,2.463970987,0.04059489,25333.12112,1.369677096,33.99963003
11,2.541914203,0.041344117,27345.42617,1.300409083,34.79280239
11.2,2.602407805,0.042094663,29082.2526,1.250745225,35.53803576
11.4,2.201732996,0.04288009,30227.36114,1.225041964,36.15252555
11.6,2.039536269,0.04364748,31232.72228,1.209358626,36.86071474
11.8,2.504694758,0.044367421,31605.45319,1.213279499,37.40765567
12,2.269375829,0.045140341,31355.47581,1.244210483,38.03086195
12.2,2.619865422,0.045868953,31042.05864,1.271656335,38.47211916
12.4,2.777577713,0.046615927,30568.28909,1.30781513,38.96458359
12.6,2.554723391,0.047384121,30054.16463,1.343102594,39.33393126
12.8,2.659256501,0.048131335,29850.42426,1.36967713,39.82312697
13,2.662415651,0.048886216,30037.50469,1.377083147,40.2959796
13.2,2.622366229,0.049644366,30384.12292,1.379697032,40.84509874
13.4,2.641313127,0.050398053,30871.85481,1.376211852,41.39966563
13.6,2.657767223,0.051151928,31470.21975,1.365320656,41.88014501
13.8,2.803847039,0.051895999,32134.19616,1.357043361,42.53603777
14,2.696491954,0.052659239,32502.7381,1.356607704,43.03177021
14.2,2.885780344,0.053400042,32846.83418,1.360092907,43.60921733
14.4,2.680375035,0.054170697,33040.80609,1.365756313,44.05374193
14.6,2.922843208,0.054907478,33113.60674,1.379261424,44.58760848
14.8,2.809671584,0.055671157,33003.19004,1.397558629,45.01252191
15,2.982341294,0.056413216,32662.37768,1.428489652,45.50716557
15.2,2.796878401,0.057182362,32508.48417,1.447222497,45.87978169
15.4,2.810008762,0.057936488,32397.67071,1.466826658,46.31885917
15.6,2.744200382,0.058696585,32299.22318,1.485995163,46.76338425
15.8,2.729909916,0.059452785,32420.09221,1.492529882,47.15888086
16,2.872665999,0.060197107,32793.70291,1.489044715,47.59795872
16.2,2.951440155,0.060946267,33105.65187,1.489916021,48.08061722
16.4,3.112476791,0.061689205,33349.06415,1.492529927,48.55564935
16.6,2.868017573,0.062462812,33700.85171,1.490787311,49.04484427
16.8,3.339823577,0.063182245,33983.23567,1.49122301,49.48283343
17,3.102842762,0.063955286,34233.03226,1.492529931,49.91537325
17.2,3.366084301,0.064690493,34589.63071,1.491223017,50.4383445
17.4,3.062628754,0.065468561,34903.57347,1.489480398,50.85781016
17.6,3.15885253,0.066216401,35166.02455,1.492094297,51.35790101
17.8,3.313241697,0.066959841,35280.61539,1.498629033,51.76974101
18,3.081246486,0.067732504,35139.60928,1.518668821,52.23714553
18.2,3.491563373,0.068456587,35013.09138,1.534352192,52.56509282
18.4,3.414121912,0.06921756,34941.25641,1.55003551,52.96712639
18.6,3.749654734,0.069947298,35190.56457,1.552649439,53.41710001
18.8,3.464479728,0.070723982,35576.70497,1.547421634,53.82131209
19,3.298959246,0.071491616,36491.03461,1.523896623,54.40747469
19.2,3.741682576,0.072213246,37540.78395,1.496886497,55.02196649
19.4,3.920999778,0.072954798,38427.68455,1.475104122,55.53077393
19.6,3.663245596,0.073729408,39058.27988,1.466391138,56.13545817
19.8,3.977174137,0.074460778,39343.30818,1.46769811,56.61484889
20,3.768445071,0.075231679,39369.83751,1.481203184,57.16396761
20.2,3.609572059,0.07599881,39125.86828,1.500371679,57.53113623
20.4,3.853701568,0.076738975,38691.50503,1.528688828,57.9527821
20.6,3.734711616,0.077514286,38513.84712,1.548292971,58.38096392
20.8,3.688011702,0.078291906,38501.24555,1.560055469,58.75467015
21,4.117435876,0.079041123,38693.92392,1.564411992,59.17522681
21.2,4.286776453,0.079817535,39084.9212,1.562233773,59.6655124
21.4,4.34643244,0.080610258,39708.65489,1.552213877,60.20591565
21.6,4.220788834,0.081424916,40297.15642,1.540887016,60.66787282
21.8,4.240557405,0.082236845,40848.26141,1.531302764,61.14617328
22,4.338432512,0.08305092,41327.06603,1.527817592,61.74650025
22.2,4.29837124,0.083883595,41499.61292,1.533916662,62.25530726
22.4,4.503434259,0.08470596,41599.99604,1.542193998,62.74668265
22.6,4.538154417,0.085549655,41688.78851,1.548728724,63.13782131
22.8,4.428290659,0.086412827,41939.24026,1.550471306,63.56927173
23,4.420630441,0.0872769,42389.97963,1.547857418,64.15979283
23.2,4.349817856,0.088154335,43211.19675,1.532174084,64.78082053
23.4,4.495877695,0.089024257,43848.51573,1.520847252,65.27982229
23.6,4.402627077,0.089921052,44516.74854,1.511698636,65.90302867
23.8,4.353414556,0.090823442,44789.39959,1.512569928,66.37697086
24,4.673135429,0.091706815,45052.44606,1.518233388,67.01652159
24.2,4.782628501,0.092615138,45052.58934,1.530867195,67.55692506
24.4,4.741720986,0.09354417,44984.1089,1.542629689,67.963317
24.6,4.770610468,0.094477245,44837.61945,1.559184319,68.43943836
24.8,4.595919593,0.095434921,45034.44086,1.563105134,68.88178406
25,4.74196782,0.096377923,45411.2983,1.564412096,69.49518568
25.2,4.786640547,0.097338155,45744.17825,1.563976455,69.97021751
25.4,4.792257828,0.098310997,46171.92353,1.562233865,70.53132177
25.6,4.774607408,0.099295296,46539.86525,1.562233865,71.10114171
25.8,5.004573836,0.100270738,46560.04632,1.570946853,71.53368299
26,5.36084072,0.101246452,46519.46348,1.581402447,71.96077708
26.2,5.040725502,0.102283272,46694.67804,1.58663019,72.49355268
26.4,5.108654977,0.103300969,47041.28583,1.586194551,73.03722461
26.6,5.184061229,0.104328369,47678.11443,1.577917248,73.64953651
26.8,5.306829112,0.105362415,48199.16282,1.570946895,74.13328493
27,5.210228645,0.106423697,48769.08382,1.564412165,74.68022488
27.2,5.044658951,0.107500764,49158.11083,1.565283445,75.2936254
27.4,5.197335395,0.10856446,49173.30767,1.576174665,75.83620818
27.6,5.421470491,0.109633457,49180.45517,1.584452005,76.25567532
27.8,5.377212076,0.110733617,49357.43348,1.589679778,76.81460018
28,6.089933133,0.111787295,49713.4076,1.587501619,77.3179622
28.2,6.589102429,0.112867558,50310.54722,1.579660011,77.9531557
28.4,6.809075998,0.113980142,51314.79067,1.561362817,78.65807761
28.6,6.956756494,0.115109416,52320.61829,1.542629966,79.2736587
28.8,6.6341263,0.116285676,53898.91274,1.513005861,80.09842613
29,6.911428889,0.117428251,55183.90562,1.491659135,80.84366056
29.2,6.971855778,0.118598685,57065.7154,1.460292479,81.76648659
29.4,6.914288094,0.119789903,58820.41312,1.43371794,82.72744517
29.6,7.037031274,0.120979476,60095.44323,1.418905918,83.63719699
29.8,6.834877184,0.122205645,60715.34267,1.416727659,84.39223517
30,6.908590396,0.123429354,61252.52287,1.417163316,85.1788711
30.2,7.107773738,0.124649666,61178.16306,1.431975373,86.02325172
30.4,7.451538723,0.125865048,60934.12426,1.451143927,86.79463518
30.6,7.31335877,0.127135507,60890.52367,1.462470766,87.38624565
30.8,7.380417626,0.128403023,61002.50825,1.471619385,88.05630229
31,7.546355636,0.129675937,61279.56293,1.479896719,88.9181153
31.2,7.370777547,0.130987497,61795.1674,1.482074943,89.76685282
31.4,7.584074707,0.132282722,62346.20902,1.480332374,90.47613291
31.6,7.521499534,0.133611968,62854.48597,1.481203666,91.29327471
31.8,7.356717303,0.134962279,63098.96666,1.486431428,91.97967305
32,7.541756346,0.136299556,63760.33353,1.485995801,92.91666353
32.2,7.74341195,0.137648989,64126.96359,1.491223601,93.7730294
32.4,7.521288794,0.139044174,64405.22344,1.498629598,94.60651294
32.6,7.672253031,0.140424894,64779.61947,1.500807856,95.26022752
32.8,8.01682279,0.141804909,65322.68789,1.500372246,95.99020909
33,8.518436987,0.143186866,65572.19902,1.509085264,96.89778382
33.2,8.324556728,0.144635689,66057.50367,1.510827838,97.7345365
33.4,8.22872445,0.146091517,66708.70304,1.509520885,98.6323026
33.6,8.433688175,0.147539018,67181.92152,1.509520908,99.35792584
33.8,8.643635186,0.149000771,67538.13554,1.511699173,100.0889963
34,8.63172033,0.150494064,68331.41293,1.508213988,101.1022526
34.2,8.676306649,0.151998021,69162.90358,1.503857513,102.0664804
34.4,8.57880074,0.153527956,69593.43163,1.505164449,102.7997288
34.6,8.696504463,0.155056803,69895.73608,1.511263538,103.6898696
34.8,8.837471891,0.156599394,70117.10106,1.517362629,104.4198508
35,8.735803961,0.158175863,70158.87636,1.529996417,105.3176168
35.2,8.919144089,0.159746471,69934.71147,1.546986724,106.1118802
35.4,8.864834399,0.161350997,69869.47662,1.55831357,106.7721299
35.6,8.860378255,0.162967657,70014.66164,1.567462185,107.5707504
35.8,9.339523462,0.164563914,70316.86952,1.57138307,108.2538842
36,9.187986752,0.166224064,70688.90109,1.574432596,108.9838637
36.2,9.188508432,0.167889318,71377.97071,1.57269,109.884899
36.4,9.208138932,0.16956995,72215.59631,1.567897877,110.8153516
36.6,9.334957325,0.171259269,73373.68754,1.554828449,111.6586429
36.8,9.485039189,0.172963813,74547.80279,1.542194666,112.5651267
37,9.737323304,0.174677666,75511.33961,1.533917381,113.4857749
37.2,9.948057928,0.176412048,76639.98199,1.524333143,114.5949102
37.4,9.83887993,0.178188193,77542.48172,1.516927114,115.495945
37.6,9.924137802,0.179967449,77917.58944,1.521283606,116.4786951
37.8,9.747648433,0.181784328,78268.31495,1.525204427,117.312179
38,9.783875446,0.183603252,79373.61525,1.519976651,118.4943115
38.2,9.835887318,0.185439215,79948.50531,1.521283601,119.340871
38.4,9.918640828,0.187291378,80379.9483,1.528253981,120.3770072
38.6,10.07908376,0.189156312,80909.94892,1.529996593,121.2268359
38.8,9.963653424,0.191060823,81123.72021,1.536531305,122.0363508
39,9.850712858,0.19298421,80757.01817,1.556135465,123.0147416
39.2,9.984972286,0.194908162,80415.06013,1.570947521,123.7065893
39.4,10.37557199,0.196832001,80070.67504,1.587066551,124.5607777
39.6,10.17163483,0.198820454,79725.11429,1.600571626,125.2068636
39.8,10.58840276,0.200781511,79204.15885,1.617997605,125.8540427
40,10.48167868,0.202802025,79155.32494,1.628017504,126.7398242
40.2,10.82781078,0.204808608,79295.01821,1.634552269,127.5733113
40.4,10.59228535,0.206879623,79656.19535,1.635859189,128.242277
40.6,10.65838594,0.208948377,80239.38785,1.635859198,129.1367755
40.8,10.99536796,0.211017329,80936.0822,1.631502756,129.9136077
41,11.31655891,0.213108372,81607.05017,1.628888905,130.7231253
41.2,11.49731854,0.215231147,82650.88448,1.621482907,131.710234
41.4,11.57420793,0.21738312,83364.96561,1.617562083,132.5110339
41.6,11.43421991,0.219573138,84326.39299,1.611898641,133.5090363
41.8,11.54018511,0.221766405,85157.66357,1.607106524,134.361044
42,11.75666114,0.223973244,85865.47303,1.604928309,135.2424692
42.2,11.96897894,0.226202804,86429.811,1.60623528,136.2099669
42.4,11.78576823,0.228484712,86961.27786,1.607977854,137.1905366
42.6,12.05042773,0.230755568,87241.46908,1.61189872,137.9662782
42.8,11.72511988,0.233094072,87479.90219,1.616690817,138.7463749
43,11.87344116,0.235419988,87978.47373,1.619740373,139.783602
43.2,11.79325163,0.237786763,88473.33825,1.620176014,140.5909376
43.4,11.8293892,0.240168425,88932.87767,1.623661207,141.549718
43.6,11.96191141,0.24256672,89097.25224,1.6297603,142.2927737
43.8,12.19912756,0.244981183,89128.09342,1.638037647,143.0227556
44,12.00009908,0.247453028,89151.02764,1.648928833,143.9477591
44.2,12.13011685,0.249924693,88918.74051,1.661127003,144.5742361
44.4,12.12302642,0.252431661,88592.20914,1.676374695,145.3216488
44.6,12.17492837,0.254959225,88413.54601,1.686830262,145.9067232
44.8,12.38885857,0.257499971,88067.96455,1.700335388,146.4765453
45,12.31611218,0.260088073,87373.93975,1.7212465,147.1095576
45.2,12.42533641,0.262688208,86738.75312,1.739979393,147.6891846
45.4,12.85363546,0.26529032,86578.43812,1.748256766,148.1718466
45.6,13.57275761,0.267896395,86438.75422,1.756098527,148.6545104
45.8,13.7110521,0.270572827,86759.92289,1.756969842,149.3746862
46,14.00223433,0.273264607,87339.94204,1.752177748,149.977195
46.2,14.31501659,0.275981766,88697.24206,1.736058799,150.842278
46.4,14.35857156,0.278746741,89805.44307,1.723425003,151.559185
46.6,14.40876962,0.281538911,91620.84542,1.701642592,152.5648148
46.8,14.41076898,0.284362788,93268.13025,1.682474065,153.4680297
47,14.49253359,0.287209054,94521.29657,1.670275922,154.3777826
47.2,14.49867855,0.290089717,95266.74837,1.667226385,155.3463683
47.4,14.68180809,0.292985744,95717.04495,1.667226409,156.1166624
47.6,14.57078202,0.295933215,95883.35727,1.672889827,157.0166079
47.8,14.62178117,0.298913045,96158.18791,1.675068077,157.7705584
48,14.8904829,0.301891412,96994.33016,1.669404681,158.6487158
48.2,14.93566077,0.304901454,98400.77895,1.657206533,159.7480454
48.4,14.89441417,0.307963581,99486.29875,1.648493562,160.6599758
48.6,15.11158349,0.311036685,100622.0066,1.641087566,161.7691122
48.8,15.1135357,0.314157241,101212.1149,1.64065192,162.6745056
49,15.06978152,0.317312514,101170.5638,1.649364885,163.5036324
49.2,15.39163372,0.320471709,100855.5523,1.662870025,164.3970442
49.4,15.50907085,0.323678155,100466.9439,1.675939493,165.07146
49.6,15.67054242,0.32691352,100326.1199,1.686830725,165.9103942
49.8,16.20509868,0.330153023,100195.463,1.695979408,166.5946191
50,16.19954198,0.333465989,100324.6069,1.701642839,167.3540172
50.2,16.53217055,0.336786699,101044.0736,1.699464638,168.2920989
50.4,16.51663202,0.340167188,102154.3525,1.689880372,169.1386583
50.6,16.89827509,0.343551444,103377.9047,1.68116745,170.2172902
50.8,17.00238042,0.346990777,104926.7324,1.666791065,171.231637
51,17.21782555,0.350456292,106934.1344,1.648493856,172.5532304
51.2,17.39587308,0.353959407,108206.1081,1.638909612,173.5741155
51.4,17.5498179,0.357499594,109520.8015,1.631067958,174.8052778
51.6,17.58160958,0.361084653,110243.1695,1.628889721,175.7291939
51.8,17.58348189,0.364707878,110352.3245,1.635860099,176.6541994
52,17.71580523,0.368357666,110089.4549,1.650236517,177.7350078
52.2,17.80823786,0.37204712,109656.7021,1.663741633,178.4944063
52.4,17.90232646,0.375773533,109100.3452,1.679860641,179.3801896
52.6,17.94239834,0.379541418,109103.9378,1.686831032,180.1406771
52.8,17.96085986,0.383348892,109459.6179,1.68900927,180.9687147
53,17.94192324,0.387197351,110382.6581,1.685524087,182.1192524
53.2,18.29025384,0.391056628,111047.8297,1.683781537,182.9767104
53.4,18.05858547,0.394998822,111510.7774,1.686831051,183.9910546
53.6,18.08616261,0.398960831,111501.8304,1.694237082,184.7526309
53.8,18.37464709,0.402942819,111308.3874,1.704257031,185.4815256
54,18.5451324,0.406973842,110635.6487,1.722554293,186.3171916
54.2,18.53197459,0.411059255,110394.1297,1.73257421,186.9589208
54.4,18.55786422,0.415182694,110300.2488,1.741722836,187.7303036
54.6,19.14961419,0.41930463,110356.6071,1.748257637,188.5027812
54.8,19.73471012,0.423468456,110754.4391,1.748693357,189.2382149
55,19.79298639,0.427714252,111501.2638,1.744336883,190.048821
55.2,20.01578109,0.431990148,112498.1605,1.737366536,191.0326627
55.4,19.9111805,0.436333475,113680.2032,1.726910958,191.9173549
55.6,20.03591115,0.440702902,115744.2961,1.706871142,193.1387118
55.8,19.99943335,0.445128534,117221.6072,1.694672981,194.1585055
56,20.44738379,0.449561919,118576.6228,1.685088765,195.2491228
56.2,20.42543319,0.454075619,119680.6215,1.679860976,196.4367026
56.4,20.91740891,0.45859569,120234.497,1.679861036,197.3399219
56.6,20.92411113,0.463198095,120206.004,1.689009659,198.3782379
56.8,20.75049302,0.467860395,119865.4937,1.700336504,199.1496189
57,21.26363562,0.472517211,119591.6271,1.710792135,199.9449762
57.2,21.33845233,0.47725423,119446.9374,1.721247713,200.8754304
57.4,21.19804919,0.482055188,119180.3219,1.731267616,201.543307
57.6,21.58611334,0.486864168,119267.6239,1.737802395,202.4225565
57.8,21.72904387,0.491739993,120019.0827,1.734317225,203.2952662
58,21.77474716,0.496672241,120875.521,1.729960746,204.2333464
58.2,21.71823752,0.501661754,121724.8863,1.726039904,205.268393
58.4,22.24337475,0.506657177,122681.0999,1.719505239,206.1944936
58.6,22.64718744,0.511711941,123440.9563,1.717327047,207.2960059
58.8,23.16981587,0.516808432,123609.7013,1.72124795,208.1240491
59,23.47223823,0.521972957,123703.2746,1.726911422,208.9782388
59.2,23.64668826,0.527199165,124112.6963,1.729960986,209.9686176
59.4,23.82694649,0.532477447,124356.2579,1.733446199,210.7323759
59.6,23.98393011,0.537810457,125036.6108,1.733010572,211.7739622
59.8,24.48906724,0.543170611,125796.6243,1.730396743,212.640139
60,24.61279636,0.548613645,126798.1698,1.725168975,213.6403226
60.2,24.74399522,0.554110698,127857.1976,1.719941208,214.785414
60.4,24.68323916,0.559677588,128987.928,1.713842121,215.9631882
60.6,24.96398877,0.565274463,129915.2151,1.709050021,216.9143451
60.8,25.05361425,0.570942037,130933.9571,1.7033866,217.9188871
61,25.30277031,0.57665454,131634.1239,1.704257929,219.1631261
61.2,25.01845655,0.582464912,132231.502,1.704257897,220.0946658
61.4,24.92358685,0.588319274,132935.8599,1.705129185,221.2517391
61.6,25.87319396,0.594153109,133443.9144,1.706436247,222.1604122
61.8,26.11898924,0.600098982,133592.526,1.712099713,223.0777943
62,26.23016343,0.6061149,134122.6949,1.714713621,224.2533914
62.2,26.40780289,0.612186042,134390.6747,1.71994143,225.3549024
62.4,26.64858377,0.618313475,134365.9664,1.726476193,226.1578838
62.6,26.75391234,0.624512741,134429.8523,1.73301094,227.1602472
62.8,27.0237563,0.63076174,135043.0128,1.732139677,228.1081357
63,27.12324842,0.637086604,135747.5423,1.730397096,229.0963351
63.2,27.14877717,0.643480599,136610.4923,1.727783208,230.2283508
63.4,27.00063014,0.649951875,137841.1256,1.719941514,231.2764713
63.6,27.20395862,0.656461494,139261.8511,1.711664213,232.5490372
63.8,27.54188831,0.663026277,140116.4246,1.709050362,233.6254909
64,27.70115631,0.66967066,140711.9434,1.709486032,234.6823313
64.2,28.17035277,0.676358302,141545.4588,1.708614793,235.9603483
64.4,28.48166076,0.683125,141627.3366,1.713842619,236.8308811
64.6,28.67496505,0.689968697,142069.257,1.717327835,237.9857787
64.8,28.84748501,0.696882758,142613.773,1.718199156,238.9805166
65,29.20113796,0.703852542,143219.9313,1.719070498,240.054791
65.2,29.48664305,0.7108975,143589.8129,1.723427024,241.2260333
65.4,29.58600721,0.718027482,144276.3118,1.72255574,242.1967997
65.6,29.54409507,0.725276424,144569.414,1.727347875,243.3495154
65.8,29.53957505,0.732522436,144562.2757,1.734318259,244.2592683
66,29.79844434,0.73985791,144543.1127,1.741288675,245.1570396
66.2,29.70747786,0.747293668,144987.3924,1.744338208,246.2814267
66.4,30.08930211,0.754768055,145214.8683,1.747823448,247.1247239
66.6,30.15120405,0.762342008,145840.6573,1.748259107,248.2360389
66.8,30.37014082,0.769979973,146465.6468,1.746952189,249.1959121
67,30.92143977,0.777669619,147411.7952,1.743902716,250.4771995
67.2,31.544187,0.78543097,147670.6174,1.746081039,251.360811
67.4,31.77139625,0.793300464,147821.5608,1.750437559,252.4078471
67.6,32.13071178,0.801238956,148131.386,1.75261585,253.294724
67.8,32.60302195,0.809248672,148569.4329,1.754358507,254.2306312
68,32.88254215,0.817353543,149738.1609,1.750002053,255.5151832
68.2,33.07230831,0.825546664,151180.0876,1.741289098,256.585099
68.4,33.41578458,0.833810417,153169.0699,1.72909097,257.9993055
68.6,33.48919341,0.842177631,154931.5829,1.717764106,259.1923355
68.8,33.85590936,0.850606602,156863.1123,1.705565979,260.5324546
69,33.91682733,0.859143487,158639.5237,1.697288657,262.1700111
69.2,34.36660983,0.867736555,159397.2771,1.696853064,263.3456129
69.4,34.58953305,0.876433056,160198.8441,1.69772439,264.7914148
69.6,34.91298567,0.885209294,160505.5329,1.701645273,265.8853015
69.8,35.36605037,0.894063657,160405.9171,1.709487013,266.9247139
70,35.6462662,0.903020093,160377.7432,1.718635679,268.2495785
70.2,36.17741051,0.912047464,160682.7093,1.722120938,269.2682915
70.4,36.19502174,0.921204539,161398.4461,1.72342789,270.5866158
70.6,36.38877684,0.930440323,162299.6934,1.721249675,271.7197239
70.8,36.67890581,0.93976165,163768.4735,1.714279321,272.9792181
71,36.7446671,0.949193457,165877.6597,1.703823758,274.6941317
71.2,36.97992435,0.958707185,167281.4076,1.698160347,276.0015642
71.4,37.06061224,0.968328184,168611.754,1.695110813,277.5879129
71.6,37.93067439,0.977985912,169447.9316,1.694675276,278.7646112
71.8,37.90580255,0.987808726,169473.1092,1.703388259,280.1809927
72,38.36950569,0.997693077,169170.9096,1.713408246,281.3206418
72.2,38.7368044,1.007684165,169053.5994,1.72081433,282.3339047
72.4,38.80993565,1.01779791,169138.7002,1.727784725,283.6478724
72.6,39.08330645,1.027998011,168914.0683,1.736933393,284.8169361
72.8,39.36995594,1.038299687,169121.1018,1.741289927,285.8857637
73,39.79036979,1.048694611,169359.7822,1.745210814,286.9404277
73.2,40.12767338,1.05920032,169172.4066,1.75392385,288.0887932
73.4,40.6028957,1.069801042,168823.9677,1.762636893,288.9331816
73.6,41.04070888,1.08051161,169012.9454,1.767429087,290.0978893
73.8,41.31439496,1.091342305,169262.8624,1.770478673,291.080645
74,41.19461521,1.10231175,169811.7059,1.770914306,292.1189599
74.2,41.72710325,1.113341932,171117.2355,1.765686581,293.4656196
74.4,41.44608664,1.12454471,172629.5155,1.757409212,294.6183329
74.6,41.63993249,1.135823833,174189.6477,1.750874499,296.0652245
74.8,42.22637792,1.147186561,175798.9833,1.743032886,297.3617672
75,42.91501045,1.158655678,177725.504,1.733013038,298.7629061
75.2,43.22721037,1.170268306,179360.1152,1.726913987,300.3329158
75.4,43.96483145,1.181965038,180297.8294,1.725171481,301.5684484
75.6,44.51298028,1.193793725,181791.2322,1.719943757,303.1232077
75.8,44.43209101,1.205789052,182869.9296,1.717329853,304.4469792
76,44.60628022,1.217885404,183774.5243,1.716458578,305.8415742
76.2,44.75219828,1.230105319,185762.8722,1.70730996,307.5238029
76.4,45.07259354,1.242434984,188176.0475,1.695983116,309.3825372
76.6,45.07804403,1.254912389,189777.077,1.690319677,310.8708288
76.8,45.52719492,1.267481408,190867.5558,1.689012784,312.291575
77,45.77440806,1.280192151,191227.8217,1.695983206,314.020655
77.2,46.14042489,1.29302154,190597.5099,1.708181436,315.1646624
77.4,46.63937117,1.305969748,189489.4031,1.725171827,316.4317871
77.6,47.01947279,1.319057024,189152.1052,1.733884864,317.4810061
77.8,47.79591051,1.332245664,189339.4774,1.738241456,318.6500781
78,47.93001281,1.345615728,190323.056,1.737370175,320.2473247
78.2,48.06077003,1.35912026,192209.483,1.729092853,321.9535227
78.4,48.2189266,1.372758417,193870.2621,1.722122483,323.392788
78.6,48.60640003,1.386516218,195177.7826,1.719508635,325.0575887
78.8,49.64032063,1.400363091,196241.0754,1.717766163,326.4598239
79,50.29115715,1.414378067,197258.5501,1.716894945,327.9241568
79.2,50.85389194,1.428540679,197869.4215,1.719944562,329.5682584
79.4,51.03935861,1.44287423,198212.2124,1.722558484,330.8255731
79.6,51.90783288,1.45729979,199314.2263,1.721251643,332.4969193
79.8,52.30680452,1.471906102,200445.3266,1.719073445,333.9743226
80,52.51048258,1.486673975,201614.9416,1.716895224,335.4942136
80.2,53.35977543,1.501541038,203720.739,1.709489284,337.380196
80.4,53.58168678,1.516605379,205548.3779,1.703390217,338.9240578
80.6,53.79111003,1.531821942,207196.9447,1.699905047,340.8067598
80.8,54.14010648,1.547180675,208197.4968,1.699905091,342.3713241
81,54.67687031,1.562679406,209466.6427,1.698598208,344.051382
81.2,55.25432532,1.578330858,210007.1571,1.702954776,345.7793792
81.4,55.39634407,1.594172687,210050.7976,1.709053892,347.1412889
81.6,55.95131351,1.61014224,210704.116,1.712539159,348.8562105
81.8,56.36832183,1.626282663,211758.1353,1.711667911,350.3826437
82,56.94733721,1.642573055,212035.1099,1.71776708,352.1476845
82.2,57.42162843,1.65903522,213329.0869,1.715153241,353.6752078
82.4,57.49621236,1.675693107,215834.2889,1.706004606,355.7583823
82.6,58.00451916,1.692485399,217452.6774,1.701648171,357.3970364
82.8,58.31337411,1.709461505,218722.1884,1.700341261,359.0247938
83,58.77841825,1.726596322,221236.7834,1.692935271,361.25833
83.2,59.57828909,1.743965182,221703.9967,1.696856218,362.7575313
83.4,59.88539984,1.761459585,221399.7935,1.707747503,364.4571974
83.6,60.22407244,1.77903835,221250.7476,1.715153594,365.745022
83.8,60.49872064,1.79688745,220204.789,1.729965726,367.3074074
84,61.02428359,1.814896747,219101.1911,1.743470939,368.520059
84.2,61.67030378,1.833077909,218070.3589,1.756976168,369.8394874
84.4,62.0719992,1.851460386,217484.5034,1.765689219,370.9104981
84.6,62.82930678,1.870000244,217040.0023,1.774402315,372.2451812
84.8,63.31819177,1.888746977,217968.3956,1.772659778,373.55698
85,63.70982709,1.907689426,219488.2912,1.767432029,375.0594425
85.2,64.22108724,1.926813176,222438.5073,1.753491295,377.0064352
85.4,64.85529571,1.946119729,226433.6781,1.733887124,379.2040214
85.6,65.02082424,1.965655979,229786.9244,1.718203745,381.0529492
85.8,65.23617788,1.985384624,232328.4378,1.709055122,382.9062371
86,65.86198348,2.005280284,235482.3869,1.698599598,385.3533243
86.2,66.44454852,2.025379281,236642.4284,1.69859967,387.0660697
86.4,67.04951684,2.045678352,236265.0444,1.709055347,388.7788166
86.6,67.35863873,2.066203898,235503.8546,1.720382289,390.1309251
86.8,68.03500259,2.086907701,235435.1634,1.726917125,391.627947
87,68.53517456,2.107832511,235448.8736,1.73432324,393.4910466
87.2,69.43748728,2.128937137,235681.618,1.738244204,394.8834768
87.4,70.18521187,2.150265136,237866.4294,1.731273895,396.9764719
87.6,70.3554002,2.17185127,239938.5481,1.723432214,398.6652426
87.8,70.95182553,2.193621737,242082.5544,1.716897535,400.498926
88,71.252402,2.215633443,245007.088,1.707748919,402.9558132
88.2,71.46735669,2.237872618,247471.8142,1.701214193,405.2187644
88.4,72.34868859,2.260284549,248546.6224,1.701649954,406.9849054
88.6,73.07958484,2.282933228,249335.2378,1.706006551,409.0746307
88.8,73.6351169,2.305822791,249675.1121,1.710798773,410.7405267
89,74.55954923,2.328914205,249733.6096,1.717769289,412.4009858
89.2,75.37509175,2.352245995,250577.0615,1.720818945,414.4144474
89.4,75.45770907,2.375867737,251254.9645,1.723432859,416.0378418
89.6,76.36873462,2.399663958,252120.6588,1.726046872,418.0229798
89.8,76.89832129,2.423728311,253001.4813,1.727353894,419.6986827
90,77.38881543,2.448037326,254152.7223,1.726918304,421.459368
90.2,77.80365533,2.472596306,254863.4748,1.730403557,423.4848067
90.4,78.09796988,2.497411154,256185.1091,1.728660994,425.1681318
90.6,78.61327456,2.522458578,259016.0523,1.719948049,427.5454898
90.8,79.05624757,2.547763135,260828.2562,1.716027253,429.4565291
91,79.57271821,2.573316817,262358.4272,1.714284712,431.4231359
91.2,79.8481756,2.599146426,263701.0317,1.714720403,433.6327022
91.4,80.48795852,2.62520784,264652.7258,1.716245251,435.5851461
91.6,81.0903076,2.651533946,264814.3282,1.722126609,437.4406241
91.8,81.51188539,2.678138297,265810.482,1.722562315,439.295009
92,82.4868262,2.704967851,267700.3314,1.718205927,441.3324453
92.2,83.0462546,2.732098682,270564.9091,1.709928635,443.8928444
92.4,83.89106733,2.759480375,271961.6997,1.708621787,445.8245945
92.6,84.4828154,2.787156163,273890.9139,1.706007957,448.1779849
92.8,85.01178355,2.815113658,274792.8179,1.708186276,450.0868482
93,85.80494581,2.843331937,274479.2268,1.71864199,452.2495773
93.2,86.45763429,2.87184433,274151.1292,1.726919435,453.865362
93.4,87.09781318,2.900644139,274044.7962,1.735196879,455.8308826
93.6,87.73794611,2.929733238,273029.7809,1.74695953,457.2276708
93.8,88.47940721,2.959107077,273221.2326,1.751751782,458.7650106
94,89.31804136,2.988768749,274712.0164,1.750880586,460.9092179
94.2,89.80514074,3.018755045,276641.4197,1.747831093,463.0850169
94.4,90.47416805,3.049028711,279113.7951,1.740425113,464.9895252
94.6,90.8847248,3.07962615,283695.2757,1.723870433,467.7569347
94.8,91.86359543,3.110488062,286159.1899,1.717771442,469.9447282
95,92.19012915,3.141709391,288123.1377,1.714721927,472.174999
95.2,93.13067753,3.173197807,289622.2195,1.714286392,474.5654433
95.4,93.93573246,3.205012962,289640.7194,1.719949954,476.3152423
95.6,94.74489135,3.237147406,289067.9056,1.729970026,478.3090985
95.8,95.46176463,3.269611638,289266.5826,1.735197928,480.1754756
96,95.9666964,3.302418215,289713.6887,1.739118851,481.9808354
96.2,96.79979711,3.335529442,290130.297,1.744782419,484.0629429
96.4,97.97851608,3.368947002,290934.7506,1.746960821,485.7626336
96.6,98.79987752,3.402727446,291838.0816,1.750010482,487.907934
96.8,99.94774455,3.436822579,293217.2691,1.749139324,489.7656059
97,100.4657045,3.471308234,295123.6461,1.745654181,491.8106634
97.2,100.8290545,3.506151991,298015.3443,1.738248158,494.318765
97.4,101.2496837,3.541341399,302177.0514,1.724743025,497.1101458
97.6,102.2045514,3.576843827,305711.2415,1.713416212,499.4374006
97.8,102.9117422,3.612721774,308947.9904,1.704703275,501.9967193
98,103.5823144,3.64896292,311467.8391,1.701218148,504.987491
98.2,104.5818812,3.685543255,312754.4247,1.70121827,507.1480493
98.4,105.5456592,3.722493788,312481.6269,1.710367065,509.5308721
98.6,106.3598089,3.759826956,311737.9701,1.719951495,511.2360043
98.8,106.9063362,3.797555525,310804.7877,1.730842847,513.0544418
99,107.9231156,3.835627406,309490.2228,1.745219469,515.1420028
99.2,108.8002363,3.874092499,308561.6513,1.756110865,516.695692
99.4,109.7728538,3.912936696,308330.9642,1.764388365,518.6143753
99.6,110.7329453,3.952172073,308514.9963,1.770487607,520.5777316
99.8,111.6514271,3.991804923,310131.0158,1.768745118,522.5290999
100,112.4177834,4.031847492,312703.5709,1.762210443,524.6090306
100.2,113.2430727,4.072287923,315933.0699,1.752626213,526.7968247
100.4,113.8414178,4.113357677,319270.261,1.743913258,529.4672748
100.6,114.2511391,4.154442907,322726.4115,1.735200279,532.2216158
100.8,115.1792691,4.196109132,325646.4615,1.728229969,534.6447513
101,116.1554935,4.238402276,327890.0674,1.724309225,537.0025167
101.2,116.991289,4.280705267,329947.3458,1.722131071,539.7503297
101.4,117.9798762,4.323635577,332142.36,1.718210328,542.0318304
101.6,119.1055003,4.366986662,333403.4592,1.719517421,544.709923
101.8,120.2327171,4.410773403,332745.9191,1.728230596,546.795311
102,121.0848224,4.455020949,332582.9934,1.734329827,548.7597556
102.2,121.8554248,4.499719282,333500.9022,1.737379486,551.2678709
102.4,122.7655541,4.544856085,334160.1799,1.740429163,553.2748088
102.6,123.7121727,4.590443712,336907.7409,1.736072762,556.0640286
102.8,124.5664841,4.636496456,340686.0292,1.726488527,558.68328
103,125.4024413,4.683013302,343325.6992,1.722132112,561.1783259
103.2,126.2732238,4.729994743,344438.2257,1.725181784,563.8629505
103.4,127.1422694,4.77744838,345108.4557,1.729538412,566.4059362
103.6,128.0145631,4.825378626,344652.1735,1.737380257,568.2178472
103.8,128.8668377,4.873791876,343962.002,1.746964708,570.1354441
104,130.1270275,4.922660622,344207.2614,1.753935299,572.5814727
104.2,130.9168262,4.972055964,345154.5333,1.757420616,574.9326989
104.4,131.837004,5.021937588,346050.1875,1.759598993,576.7805676
104.6,133.1866993,5.072287443,348325.3675,1.75698525,579.3736867
104.8,134.1499263,5.123172307,350398.7276,1.753935806,581.7183822
105,135.2069686,5.174560833,352605.9978,1.751322025,584.4727429
105.2,136.1226687,5.226475923,354481.2638,1.748708227,586.6572771
105.4,137.4279981,5.278882699,356091.5477,1.748272738,589.2710969
105.6,138.5919838,5.331826587,356134.7652,1.753500712,591.2290153
105.8,139.6129628,5.385313087,357292.402,1.754372145,593.3776004
106,140.6803893,5.43933337,359356.6737,1.753500974,596.2321994
106.2,141.670452,5.49390229,361405.5111,1.750451539,598.5202424
106.4,142.6770464,5.549018086,363458.3493,1.748273401,601.2212182
106.6,143.6802291,5.604688025,366665.2416,1.74043178,603.6901234
106.8,144.7979931,5.660908651,369178.9548,1.736511054,606.328999
107,145.8134615,5.717701819,369322.1508,1.743045965,609.1432863
107.2,146.9202429,5.775058489,368966.6402,1.750016544,611.0903104
107.4,147.9396838,5.832998186,370137.0021,1.752630587,613.7139305
107.6,148.787858,5.891532925,370973.4554,1.75611592,616.2111602
107.8,149.8694337,5.950638131,372262.2773,1.756116056,618.3837171
108,150.8885944,6.01034178,375033.1824,1.750888349,621.0149646
108.2,152.2342206,6.070620463,378894.8863,1.742611111,624.1060042
108.4,153.5211692,6.13150933,380706.3514,1.742175621,626.8734519
108.6,154.5163589,6.193035178,381867.8879,1.743482703,629.1102895
108.8,155.9144581,6.255148597,381441.0985,1.751760279,631.1728132
109,156.947674,6.317913738,380112.235,1.764830001,633.6101277
109.2,158.1012765,6.381300444,379593.9079,1.772236247,635.4198748
109.4,159.4271987,6.445310935,380718.355,1.774850329,637.957433
109.6,160.38865,6.509992287,382031.5073,1.774850452,639.999245
109.8,161.6981635,6.575297021,385962.7027,1.765266251,642.6915177
110,163.0046645,6.641258021,391718.6285,1.75045421,646.1464619
110.2,164.4768341,6.707866643,395814.86,1.740870024,648.8725165
110.4,165.9526368,6.775143543,400388.4898,1.730850184,652.2708131
110.6,167.1117425,6.843120469,403448.6468,1.726493795,655.5209221
110.8,168.2881895,6.911779053,405085.2851,1.726493941,658.2644006
111,169.5467905,6.981121167,405825.0657,1.72954367,660.8564365
111.2,171.0346215,7.051142619,407307.3023,1.731286467,663.984531
111.4,171.9373559,7.121911959,407797.2045,1.73520746,666.4131267
111.6,173.7523545,7.193323059,410076.6791,1.734772031,669.5771864
111.8,175.046237,7.265491296,413064.8373,1.73085131,672.4732034
112,176.3782278,7.338381575,416464.996,1.726059286,675.5174024
112.2,177.925317,7.41198805,419002.8017,1.725188169,678.8950033
112.4,179.2055555,7.486354226,421405.847,1.724752674,682.1756261
112.6,180.8529531,7.561439549,422892.1076,1.725624184,684.7905589
112.8,182.3730963,7.637288964,423396.501,1.730416562,687.4512463
113,184.0152675,7.713891222,421741.4146,1.743922031,690.3036986
113.2,185.0149959,7.791311781,421935.1199,1.749150002,692.5808571
113.4,186.2763485,7.869490305,424257.6397,1.748714506,695.7895723
113.6,187.6946251,7.948442404,426408.9895,1.746972068,698.2802923
113.8,188.8352398,8.028208939,429911.6995,1.74130871,701.1861154
114,190.5740082,8.108731462,435144.0868,1.732160192,705.2141781
114.2,191.8564589,8.190097607,438868.6542,1.727368158,708.7769961
114.4,193.24431,8.272273166,440106.9966,1.729110945,711.3668637
114.6,194.9286776,8.355251928,441333.0598,1.732596386,714.7096085
114.8,196.4284429,8.439078288,442124.8452,1.736081804,717.4607341
115,197.8449799,8.523753183,444867.2694,1.733032401,720.5724909
115.2,199.550551,8.60925694,448583.1728,1.728240415,724.3543222
115.4,200.882891,8.695647979,452762.2724,1.720398802,727.5445228
115.6,202.649678,8.782874062,457648.9958,1.712557241,731.580215
115.8,204.1263257,8.87099859,460228.8438,1.711686113,734.9338525
116,206.0532058,8.959974286,461806.6629,1.713864619,738.0358268
116.2,207.3957885,9.04988843,463662.2886,1.716043057,741.6389624
116.4,208.8661936,9.140696113,464194.4665,1.721271092,744.4641769
116.6,210.5051361,9.232403353,465656.6368,1.72475653,747.8875512
116.8,211.9237313,9.325048715,468302.1253,1.723449741,751.1899819
117,213.3205741,9.418626509,471711.8713,1.719529021,754.558874
117.2,215.2748332,9.513102085,475270.721,1.716915332,758.6032948
117.4,216.938941,9.608549074,477236.8364,1.718658155,762.2674609
117.6,218.6220083,9.704953445,477147.2427,1.724757529,764.998988
117.8,220.319879,9.802325294,475456.0945,1.736084765,767.6422613
118,221.8281383,9.900689941,471847.7425,1.75438246,770.4816462
118.2,223.284722,10.00004667,469372.3542,1.767016637,772.5267558
118.4,225.1308616,10.10037216,468633.1481,1.77485866,775.3291114
118.6,226.5904504,10.20173536,471930.3777,1.76919533,778.1891935
118.8,228.4137504,10.30460726,477341.5398,1.75743287,781.5243308
119,229.542378,10.40753198,483329.0531,1.746105979,785.7386931
119.2,231.5557184,10.5119436,489085.151,1.735650503,789.8234398
119.4,232.8110677,10.61746186,493935.9616,1.727373209,793.2587927
119.6,234.6819811,10.72399366,495317.4143,1.730858682,796.937137
119.8,236.7596308,10.83158012,496230.5736,1.734779836,800.0042569
120,238.8337851,10.94024807,498356.4007,1.735215748,803.2958252
120.2,240.3593401,11.05004946,500474.4958,1.737394215,807.0961854
120.4,242.0609357,11.06650215,500750.6347,1.743057946,809.805929
120.6,242.9616399,11.06643283,503611.3487,1.742622402,813.4668023
120.8,243.9495939,11.06635691,504798.3493,1.745672114,816.4401874
121,244.8984933,11.06628394,507035.296,1.746979199,820.2862859
121.2,245.5324632,11.06623479,508797.1126,1.747414934,823.2345923
121.4,246.0783525,11.06619231,510936.2595,1.747850659,827.0240235
121.6,246.7920936,11.06613713,511211.0676,1.751771649,829.5931759
121.8,247.4144302,11.06608886,514243.0059,1.749157793,833.5743635
122,247.8356773,11.0660558,516101.0747,1.749593503,836.8157511
122.2,248.018442,11.06604078,519594.349,1.746543937,840.6727176
122.4,248.2759921,11.0660201,524554.6224,1.738702166,844.1592424
122.6,248.8409934,11.06597617,531285.002,1.728246498,848.807227
122.8,249.6145629,11.06591647,534923.5759,1.726068314,852.4746352
123,249.317039,11.06593777,536667.7473,1.728682215,855.9633191
123.2,249.675134,11.06590949,535130.242,1.740880623,859.3223716
123.4,250.1196477,11.06587467,531799.8176,1.756128633,861.5178062
123.6,250.0921823,11.06587555,525764.2173,1.780525361,863.8047425
123.8,250.4602487,11.06584652,521938.4634,1.797080333,865.7452232
124,250.8723554,11.06581415,519744.8074,1.809714401,868.2871258
124.2,250.9013945,11.06581076,518642.1384,1.817120566,870.1502358
124.4,251.0583998,11.06579769,518145.5699,1.823655421,872.677968
124.6,251.365807,11.06577324,518171.5705,1.827140711,874.6761889
124.8,251.5743312,11.06575627,516755.8657,1.834982543,876.5512898
125,251.4687565,11.06576306,514342.4241,1.846745239,878.5560321
125.2,251.8226968,11.06573509,514186.6546,1.851101843,880.2295752
125.4,252.0669518,11.06571542,514467.1567,1.855022783,882.355271
125.6,251.9854747,11.06572038,514929.7151,1.858508018,884.4341004
125.8,252.1615919,11.06570586,515224.2279,1.861557631,886.1337872
126,252.1603014,11.06570476,516363.9664,1.861993292,888.0197746
126.2,252.3763041,11.06568723,514836.4952,1.870270786,889.7085654
126.4,252.6139115,11.06566806,513860.6204,1.875934345,891.0105719
126.6,252.5731509,11.06566995,514139.5777,1.878112622,892.8595135
126.8,252.8601999,11.06564704,516386.1215,1.874191757,894.7890942
127,252.9557149,11.06563862,517849.8628,1.872884805,896.732288
127.2,252.9972183,11.06563428,520292.0079,1.868963908,898.770267
127.4,253.0441229,11.06562954,521383.2599,1.869835228,900.8796104
127.6,253.4159287,11.06560022,520722.5267,1.87506315,902.1805333
127.8,253.2762851,11.06560958,519852.9338,1.881162317,903.5838522
128,253.3609978,11.06560198,518758.2711,1.888568481,905.1309973
128.2,253.5221579,11.06558859,518816.1998,1.891618096,906.4090316
128.4,253.5619994,11.06558438,521114.2876,1.888568512,908.3146299
128.6,253.8070854,11.06556464,525352.4607,1.878984115,910.3379108
128.8,253.9408242,11.06555333,527794.7103,1.875063231,912.2816477
129,253.9814966,11.06554906,531533.2973,1.868092743,914.8496906
129.2,254.121883,11.06553724,533485.2526,1.865914484,917.0984993
129.4,253.9830704,11.06554654,533661.0584,1.868092748,918.7012024
129.6,253.9921668,11.06554466,531593.8548,1.877241526,920.2734019
129.8,254.3253334,11.06551826,530796.1857,1.882033788,921.7486515
130,254.3020227,11.06551883,528281.3111,1.891618218,922.7782619
130.2,254.5612349,11.06549803,526261.8779,1.900331374,924.0050923
130.9,255.2359384,10.99407385,1.7977E+308,1.949996253,0
131.1,254.8554581,10.88345189,1.7977E+308,1.91862897,0
131.3,254.7608244,10.77280831,1.7977E+308,1.808843649,0
131.5,254.2789682,10.66219402,1.7977E+308,1.622818488,0
131.7,254.3721291,10.55153624,1.7977E+308,1.368831067,0
131.9,253.8836254,10.44092245,1.7977E+308,1.012900102,0
132.1,253.9618292,10.3302658,1.7977E+308,0.634750734,0
132.3,253.4309471,10.21965521,1.7977E+308,0.363772713,0
132.5,253.4044512,10.10900648,1.7977E+308,0.148123021,0
132.7,253.3024269,9.997810215,1.7977E+308,0.008713119,0
132.9,252.96673,9.887738116,1.7977E+308,0.041822969,0
133.1,252.581264,9.777116534,1.7977E+308,0.041822968,0
133.3,252.3877474,9.666480434,1.7977E+308,0.040951656,0
133.5,252.2939446,9.555836793,1.7977E+308,0.040080344,0
133.7,251.8694241,9.445218164,1.7977E+308,0.033545504,0
133.9,251.9999777,9.334557554,1.7977E+308,0.024832386,0
134.1,251.8637965,9.223917117,1.7977E+308,0.012634021,0
134.3,251.6245777,9.113284474,1.7977E+308,0.003485247,0
134.5,251.1992262,9.002665908,1.7977E+308,0.01263402,0
134.7,250.8395197,8.892042378,1.7977E+308,0.021782793,0
134.9,250.5354869,8.781414637,1.7977E+308,0.03049591,0
135.1,250.3311679,8.670779354,1.7977E+308,0.036159435,0
135.3,250.0379374,8.560150796,1.7977E+308,0.037902058,0
135.5,249.8768278,8.449512245,1.7977E+308,0.037466402,0
135.7,249.6916206,8.338875516,1.7977E+308,0.032674187,0
135.9,249.4573875,8.228242496,1.7977E+308,0.017861889,0
136.1,249.3627539,8.117598917,1.7977E+308,0.003049591,0
136.3,249.0646256,8.006417482,1.7977E+308,0.012198363,0
136.5,249.0638892,7.895766801,1.7977E+308,0.018297544,0
136.7,248.5237789,7.785710163,1.7977E+308,0.020911478,0
136.9,248.4275713,7.674513455,1.7977E+308,0.019604511,0
137.1,248.3660876,7.564420617,1.7977E+308,0.017861887,0
137.3,248.1168975,7.453788728,1.7977E+308,0.010891395,0
137.5,247.8004004,7.343161929,1.7977E+308,0.007406148,0
137.7,247.5080009,7.232533308,1.7977E+308,0.010020083,0
137.9,247.3385818,7.121895386,1.7977E+308,0.010455738,0
138.1,247.1500509,7.011258909,1.7977E+308,0.016554919,0
138.3,246.9764771,6.9006213,1.7977E+308,0.01437664,0
138.5,246.7015276,6.789991359,1.7977E+308,0.010891393,0
138.7,246.1839409,6.67937977,1.7977E+308,0.000435656,0
138.9,246.1358404,6.568732672,1.7977E+308,0.004356557,0
139.1,245.8874812,6.45810072,1.7977E+308,0.008713114,0
139.3,245.6790076,6.347465751,1.7977E+308,0.013069671,0
139.5,245.3974104,6.236836313,1.7977E+308,0.014376638,0
139.7,245.2288223,6.126198328,1.7977E+308,0.011327048,0
139.9,244.869116,6.015574797,1.7977E+308,0.007841802,0
140.1,244.6082926,5.904943788,1.7977E+308,0.003920901,0
140.3,244.6823416,5.794287451,1.7977E+308,0.001742623,0
140.5,244.2403714,5.683670143,1.7977E+308,0.01306967,0
140.7,244.0701214,5.573032283,1.7977E+308,0.025268028,0
140.9,243.6672058,5.462412021,1.7977E+308,0.037466385,0
141.1,243.5193914,5.351772464,1.7977E+308,0.048357776,0
141.3,243.1987397,5.24114598,1.7977E+308,0.054892609,0
141.5,243.0135327,5.130509251,1.7977E+308,0.05576392,0
141.7,242.7236261,5.019880442,1.7977E+308,0.051407363,0
141.9,242.5018573,4.909246479,1.7977E+308,0.04661515,0
142.1,242.1521225,4.798622194,1.7977E+308,0.037030726,0
142.3,242.0275747,4.687980878,1.7977E+308,0.019168846,0
142.5,241.8897318,4.577340567,1.7977E+308,0.006534834,0
142.7,241.4809996,4.466720744,1.7977E+308,0.006534834,0
142.9,241.2185143,4.356089861,1.7977E+308,0.016990567,0
143.1,241.1911876,4.245441191,1.7977E+308,0.025703679,0
143.3,240.659475,4.134830671,1.7977E+308,0.023961055,0
143.5,240.4439383,4.024196236,1.7977E+308,0.024396711,0
143.7,240.1465533,3.913567992,1.7977E+308,0.016990566,0
143.9,240.1707453,3.802915426,1.7977E+308,0.013940977,0
144.1,240.1205675,3.692268485,1.7977E+308,0.017426221,0
144.3,239.6042275,3.581656801,1.7977E+308,0.024832365,0
144.5,239.1788764,3.471038236,1.7977E+308,0.030495885,0
144.7,238.9330102,3.360406095,1.7977E+308,0.032238507,0
144.9,238.709995,3.249772226,1.7977E+308,0.032674162,0
145.1,238.3203747,3.139150958,1.7977E+308,0.027881951,0
145.3,238.131013,3.028514544,1.7977E+308,0.021347118,0
145.5,237.8062067,2.917888374,1.7977E+308,0.014812286,0
145.7,237.6899684,2.807246429,1.7977E+308,0.010020076,0
145.9,237.366824,2.696620134,1.7977E+308,0.014812285,0
146.1,236.9954846,2.585997483,1.7977E+308,0.026139326,0
146.3,236.7504494,2.47536528,1.7977E+308,0.031367191,0
146.5,236.3084794,2.364747971,1.7977E+308,0.036595055,0
146.7,236.2653646,2.254100496,1.7977E+308,0.0361594,0
146.9,235.8907015,2.143478097,1.7977E+308,0.032674155,0
147.1,235.3822556,2.032865816,1.7977E+308,0.024832357,0
147.3,234.9868188,1.922244988,1.7977E+308,0.010455729,0
147.5,234.719348,1.811614482,1.7977E+308,0.010891384,0
147.7,234.4011894,1.700987809,1.7977E+308,0.031802841,0
147.9,234.3098796,1.590343979,1.7977E+308,0.044436846,0
148.1,233.7773363,1.479733521,1.7977E+308,0.047050777,0
148.3,233.4674872,1.36910622,1.7977E+308,0.043565533,0
148.5,233.1526524,1.258479295,1.7977E+308,0.031367183,0
148.7,232.6940635,1.147863244,1.7977E+308,0.026139318,0
223.9,231.7926144,1.042364122,1.7977E+308,0.021347118,0
224.1,231.3315325,0.931748259,1.7977E+308,0.020911461,0
224.3,231.0673855,0.821117501,1.7977E+308,0.02004015,0
224.5,230.745903,0.710491079,1.7977E+308,0.023525393,0
224.7,230.2133596,0.599880621,1.7977E+308,0.022218426,0
224.9,229.7839418,0.488709116,1.7977E+308,0.017426216,0
225.1,229.3527742,0.378090991,1.7977E+308,0.010455729,0
225.3,228.5327228,0.267502278,1.7977E+308,0.004356554,0
225.5,227.4583133,0.157486051,1.7977E+308,0.009584417,0
225.7,226.3756824,0.046917199,1.7977E+308,0.010455727,0
225.786,225.6801032,-0.000610008,1.7977E+308,0.010891382,0
,,,,,