File: Test_2.csv
Time On Sample,Displacement Into Surface,Load On Sample,Harmonic Contact Stiffness,Harmonic Displacement,Harmonic Load
0,0,0,-339.9179097,0.399081204,2.203121346
0.2,-0.105470163,0.000767476,3407.415923,0.276655636,2.269585427
0.4,0.334190263,0.001493664,7622.921121,0.236573252,2.321885097
0.6,0.37081969,0.002250378,11448.42746,0.21086824,2.435200941
0.8,0.355927626,0.003010993,14198.83674,0.187777296,2.541979318
1,0.365965316,0.00376972,16655.65563,0.166429065,2.647668131
1.2,0.410073668,0.004525867,18914.14905,0.152051686,2.752267375
1.4,0.632845253,0.005268483,21070.90053,0.140724055,2.842702157
1.6,0.758390802,0.006018462,25519.58134,0.127218033,3.132529229
1.8,0.639624765,0.006786944,28579.76418,0.122425571,3.399475182
2,0.618084767,0.007548063,29810.9532,0.12503964,3.663152415
2.2,0.840856538,0.008289532,29820.55531,0.132446172,3.923560977
2.4,0.829288795,0.00904767,29609.39607,0.14246677,4.202492277
2.6,0.573409466,0.009824313,30228.96807,0.160329573,4.778877601
2.8,0.797012399,0.010564639,30806.8508,0.176885347,5.308411293
3,0.862726894,0.011316924,30760.60907,0.195619511,5.831407504
3.2,0.903511634,0.012071097,31207.23423,0.209996892,6.35331412
3.4,1.199410861,0.012805947,32032.79848,0.21871046,6.804398416
3.6,0.930235657,0.013583596,35612.13981,0.219581812,7.618311163
3.8,0.979745811,0.014337107,39573.0584,0.217403422,8.399536739
4,0.773725987,0.015109973,44380.09534,0.211303924,9.18838925
4.2,1.046772937,0.015846554,48057.05399,0.210432572,9.970704507
4.4,1.078001272,0.016601451,50182.10714,0.216532067,10.78025904
4.6,0.963390545,0.017367393,50960.47246,0.231780803,11.7717726
4.8,0.906118253,0.018128993,50675.01978,0.255743103,12.89403523
5,1.068227797,0.018873976,49575.64668,0.284062189,13.90625089
5.2,1.020927407,0.01963482,47984.27325,0.31760941,14.9402579
5.4,0.966979082,0.020396168,46237.91416,0.348978239,15.77596221
5.6,0.927988609,0.021156383,44682.42102,0.392981736,17.13684185
5.8,0.783046683,0.021924622,43359.68496,0.434371161,18.36261403
6,0.833387829,0.022678071,42317.15119,0.472710844,19.5001308
6.2,0.874172569,0.023432244,41088.48361,0.512793239,20.54013056
6.4,1.030880667,0.024177636,39742.5205,0.555925387,21.53872654
6.6,0.994798666,0.024937631,38988.63235,0.601235919,22.8549336
6.8,0.590171803,0.025725538,38080.12434,0.639575583,23.76799734
7,0.68995696,0.026475243,36307.05975,0.698827821,24.81834811
7.2,0.977130167,0.027214542,33731.12613,0.777249912,25.76409996
7.4,0.757815076,0.027984628,31422.92362,0.85218655,26.45815917
7.6,0.826438041,0.028736693,27958.16768,0.977226196,27.23829527
7.8,0.496184947,0.029518968,25503.67998,1.081353261,27.67739367
8,1.217967468,0.030221563,23159.20583,1.20421457,28.13610598
8.2,0.968320571,0.030997733,21585.36077,1.307034605,28.55123382
8.4,1.156190863,0.031740765,20601.89265,1.380664239,28.8661214
8.6,1.067756377,0.032504724,19945.20473,1.438173754,29.18100857
8.8,1.655333743,0.033217482,19674.97886,1.474770783,29.56072642
9,1.737252583,0.033968538,19652.09572,1.49481199,29.96114553
9.2,1.913488999,0.03471245,19945.53589,1.498733112,30.45690256
9.4,1.879484476,0.035472285,20616.33904,1.480434623,30.95374893
9.6,1.700056378,0.036243134,21607.81634,1.44732306,31.50289477
9.8,2.187083753,0.036963507,23123.34772,1.395913077,32.23400056
10,1.818189507,0.037748706,24397.78997,1.356266323,32.82237066
10.2,1.633775458,0.038519934,25921.26731,1.314876874,33.60577517
10.4,1.792561045,0.039265168,26543.98268,1.308341715,34.1799818
10.6,1.568259388,0.040039417,26503.66947,1.332739676,34.74982934
10.8,1.887426402,0.040772503,25892.21521,1.376307528,35.10067317
11,2.194128545,0.041506533,24841.16883,1.443402,35.43626287
11.2,2.183391794,0.042264605,24199.47609,1.490455255,35.68904438
11.4,2.092879822,0.043028719,24126.63578,1.508753732,36.01809616
11.6,2.549160511,0.04375142,24813.15608,1.48871258,36.56397419
11.8,2.256717508,0.044530828,26009.02407,1.44340201,37.10331355
12,2.16786752,0.045294816,27658.71159,1.384149759,37.72546084
12.2,2.2460469,0.046046153,29834.03428,1.31444125,38.53828428
12.4,2.193760554,0.046807372,31253.27213,1.276972914,39.18222329
12.6,2.221249429,0.047562549,32352.83822,1.258674434,39.92640345
12.8,2.309400712,0.048313131,32752.90237,1.263902583,40.58668636
13,2.40419993,0.04906321,32559.58969,1.284379467,41.03559158
13.2,2.498168157,0.049813351,32089.35209,1.317491022,41.55640885
13.4,2.558896709,0.05056601,31705.47834,1.344938756,41.95628318
13.6,2.540681031,0.051324647,31422.77351,1.373257844,42.50216046
13.8,2.602240574,0.052077243,31182.56831,1.396348795,42.90530352
14,2.420319492,0.05284828,31204.64756,1.412033197,43.43265768
14.2,2.618992699,0.053590491,31577.89042,1.411161857,43.89136938
14.4,2.485269146,0.054357877,32018.71558,1.408547772,44.37187188
14.6,2.606660107,0.055105941,32308.36994,1.415954319,44.94498886
14.8,2.562683679,0.05586653,32721.80093,1.415954311,45.48650778
15,2.451396908,0.056632217,33058.49782,1.416389983,45.93650221
15.2,2.672506897,0.057372728,33076.93317,1.430767384,46.43770743
15.4,2.682544943,0.058129226,32946.27956,1.446887485,46.82995482
15.6,2.882880137,0.05887131,32881.04837,1.462571922,47.34750365
15.8,3.138891795,0.059609178,32837.22506,1.473463898,47.72122845
16,2.825673982,0.060390157,32670.15893,1.492198038,48.18538689
16.2,3.167277807,0.061121542,32611.17809,1.504832744,48.55257481
16.4,3.449881212,0.061857395,32725.94907,1.512239304,48.95136019
16.6,3.214776635,0.062632458,33247.54969,1.507446818,49.49069953
16.8,3.170800205,0.063393045,33658.77491,1.504397066,49.91454425
17,3.091922115,0.064156276,34292.85117,1.494812136,50.45933173
17.2,2.95902955,0.064923598,35118.72256,1.477384992,51.01937325
17.4,3.182632523,0.065663919,36014.02223,1.456472458,51.55108676
17.6,3.193501561,0.066420352,36779.15771,1.441659398,52.09042661
17.8,3.171130923,0.067179303,37656.92919,1.425974978,52.7278283
18,3.374790092,0.067921135,38534.95169,1.412033294,53.37285745
18.2,3.155474363,0.068695001,39322.34373,1.399398603,53.92963009
18.4,3.556909618,0.069421854,39832.20747,1.395913215,54.46025438
18.6,3.61597619,0.070174636,40432.67229,1.393299152,55.16303072
18.8,3.861184966,0.07091332,41118.0289,1.386764001,55.83856824
19,3.533840274,0.071695368,41647.22366,1.382407187,56.37681783
19.2,3.378510922,0.072464388,41992.26257,1.387199633,57.03383143
19.4,3.386886985,0.073221009,42243.26482,1.391992095,57.56227547
19.6,3.384460153,0.073978449,42405.55674,1.40331973,58.24652891
19.8,3.497541202,0.07472714,42367.71157,1.415954412,58.72485292
20,3.361324665,0.075494713,42141.09919,1.436431278,59.29143188
20.2,3.69711156,0.076226537,41808.03912,1.45952226,59.82423519
20.4,3.567542958,0.076993605,41428.3001,1.48174184,60.23609438
20.6,3.806934788,0.07773273,41153.26557,1.501783066,60.67192536
20.8,3.976523296,0.07847714,40742.70689,1.527923781,61.12301004
21,3.959138608,0.079235712,40636.37364,1.544479555,61.60242337
21.2,3.597723243,0.08002034,40861.47437,1.547093586,62.02735663
21.4,4.233498254,0.080729442,41590.92461,1.536201697,62.63970009
21.6,4.341177862,0.081478541,42444.01993,1.519645933,63.20301093
21.8,4.213686734,0.082245451,43915.53531,1.486534368,63.94719074
22,4.251147512,0.082999901,45235.29609,1.459522317,64.7055354
22.2,4.245396001,0.083762068,46171.55343,1.442530863,65.30698117
22.4,4.37384848,0.084521732,47130.51267,1.426410779,65.96835394
22.6,4.383467888,0.085298034,48064.96638,1.414211787,66.80732728
22.8,4.536016687,0.086071289,48402.0476,1.418132907,67.53080585
23,4.375280252,0.086876097,48686.14089,1.421618318,68.09629502
23.2,4.644580926,0.087656261,48881.49412,1.430331911,68.78490787
23.4,4.428996455,0.088481344,48891.73343,1.441659526,69.33187394
23.6,4.559518903,0.089288112,48495.29084,1.468235916,69.98779895
23.8,4.532567038,0.090115155,48211.99463,1.486970081,70.45086842
24,4.694664571,0.090935971,47694.52945,1.51485351,71.00328387
24.2,4.703858242,0.091776736,47053.43684,1.545786672,71.49904076
24.4,4.846009292,0.0926159,46568.16877,1.569313317,71.88257182
24.6,4.790798052,0.093480599,46405.76434,1.584562052,72.36743294
24.8,5.047622957,0.094330255,46444.93242,1.592839969,72.8424887
25,5.010691145,0.09520864,46700.88565,1.595018356,73.38073904
25.2,4.975420616,0.096091308,47037.40403,1.593275639,73.84707729
25.4,5.157867893,0.096970771,47494.73857,1.589354555,74.35373062
25.6,5.09018515,0.097878062,48086.15203,1.584126407,74.99222162
25.8,5.580512146,0.098752097,48582.0149,1.581512391,75.59693777
26,5.226965272,0.09969902,48892.70814,1.581948031,76.06327513
26.2,5.348744358,0.100619394,49388.61161,1.579769653,76.67997522
26.4,5.292274174,0.101562535,49878.92035,1.575412863,77.20406108
26.6,5.177217542,0.102519596,50388.41701,1.573234459,77.87741838
26.8,5.532085405,0.103450617,50749.42899,1.571927463,78.3764452
27,5.450680905,0.104424287,51249.83986,1.569313384,79.01602585
27.2,5.466500948,0.105400215,51633.64022,1.569749065,79.64253191
27.4,5.224711881,0.106405527,51717.384,1.576719892,80.14155675
27.6,5.448276791,0.107385537,52038.94942,1.579769665,80.78985491
27.8,5.520599577,0.108386867,52320.54213,1.581076708,81.28125381
28,5.70510468,0.109389864,52764.22366,1.580205372,81.9142981
28.2,5.853044546,0.110405612,53404.70066,1.574541569,82.5789399
28.4,5.82481244,0.111445072,54215.43164,1.563213929,83.18038555
28.6,5.842283237,0.112491532,55152.17508,1.550143581,83.85810165
28.8,5.51156667,0.113574919,56161.76666,1.537073195,84.63823651
29,5.900487589,0.114614265,56978.09099,1.528795348,85.39113484
29.2,5.884713663,0.115694945,57686.19337,1.523131528,86.15710657
29.4,5.901346697,0.116784058,57952.46747,1.5257456,86.76182114
29.6,5.897203215,0.117885531,57971.36033,1.534459167,87.36762534
29.8,6.341793721,0.11896404,58064.74214,1.54360846,88.05841786
30,5.820769596,0.120126992,58421.75579,1.547093831,88.77317738
30.2,5.972847297,0.121250171,58713.09697,1.550579269,89.34738422
30.4,6.036007027,0.122391512,59136.123,1.551450635,89.94883053
30.6,6.069249221,0.123546577,59744.20866,1.551014959,90.73986237
30.8,6.123264368,0.124711705,60009.39913,1.556678781,91.4393702
31,6.261207858,0.125882183,59887.16483,1.571056186,92.0854892
31.2,6.524629299,0.127054875,59774.06094,1.582383851,92.58124733
31.4,6.477257779,0.128263085,59572.22718,1.595889872,93.07918322
31.6,6.655914216,0.129466156,59596.29286,1.6059105,93.74273564
31.8,6.566158253,0.130701757,59998.03674,1.606781846,94.43570538
32,6.467259404,0.131950461,60706.44284,1.599810984,95.1504666
32.2,6.440654909,0.133206037,61278.65071,1.594582837,95.73447906
32.4,6.498809592,0.134467895,62060.58961,1.585433603,96.3860456
32.6,6.546159372,0.135743184,62928.674,1.577591393,97.21957124
32.8,6.476337213,0.137040238,63485.82331,1.576720033,98.00079709
33,6.555260597,0.138338911,63626.67945,1.581948178,98.5292413
33.2,6.884310524,0.139631822,63819.154,1.588919063,99.24509412
33.4,6.732213906,0.140974322,63745.70478,1.599375337,99.78770228
33.6,6.562664335,0.14233148,63631.12978,1.612881349,100.4795824
33.8,7.277288294,0.143635046,63528.02387,1.624644745,101.0897482
34,7.38196191,0.144998018,63653.98693,1.629437219,101.620372
34.2,7.994369609,0.146336108,63911.0297,1.632487038,102.2654037
34.4,7.802374648,0.147748975,64288.57092,1.631615659,102.8548635
34.6,7.895407785,0.149154299,65140.9327,1.622902102,103.6698666
34.8,7.875423729,0.150582348,65984.47723,1.612445818,104.331239
35,7.901972964,0.152021173,67120.88511,1.598068433,105.1941833
35.2,7.859547537,0.153479741,68078.98878,1.587612146,106.0200813
35.4,8.193559284,0.154924297,68878.94052,1.579769972,106.7359345
35.6,7.878563748,0.156432812,69331.05884,1.579769937,107.4452467
35.8,7.921723497,0.157929081,69663.38193,1.583691048,108.2384582
36,8.090360662,0.159431004,69797.68157,1.591968957,108.9913557
36.2,7.928260519,0.160973092,69809.79868,1.600682508,109.5753679
36.4,8.222372672,0.16249596,69645.82634,1.613317215,110.1517548
36.6,8.307072341,0.164050055,69723.75551,1.623337828,110.9264436
36.8,8.238035953,0.165631478,69708.55305,1.633794103,111.6052489
37,8.478126166,0.167205306,69854.96823,1.638586593,112.1707402
37.2,8.416563659,0.16881792,70104.78488,1.643379049,112.8985766
37.4,8.286026231,0.170451902,70342.86356,1.646428783,113.496753
37.6,8.300078853,0.172091284,70592.10844,1.649478534,114.1232592
37.8,8.486144261,0.173734062,70648.11802,1.657756446,114.8020659
38,8.678023979,0.175392991,70437.26639,1.669955464,115.300003
38.2,8.84663328,0.177070267,70319.41858,1.681283124,115.9079876
38.4,9.069254387,0.178760401,70454.91913,1.685639934,116.4582244
38.6,8.986898602,0.180490781,70619.63743,1.689561031,117.0171763
38.8,9.057027158,0.182226863,71701.54219,1.67518365,117.7994922
39,9.087680814,0.183983344,72843.73653,1.658627873,118.5000895
39.2,8.897287724,0.185774177,73960.11712,1.645557498,119.3761077
39.4,9.00438703,0.187560341,74690.55443,1.639458012,120.0952283
39.6,9.445542405,0.18933905,75317.86185,1.635972634,120.8197987
39.8,9.748334712,0.191146223,75417.4994,1.64425056,121.5781452
40,10.26676666,0.192955206,75467.12491,1.650785796,122.1534443
40.2,9.960435782,0.194845007,76081.6883,1.64817169,122.9521017
40.4,10.33426916,0.196702087,76786.32234,1.642072234,123.6635969
40.6,10.74300125,0.198575231,77742.94622,1.631615997,124.4644378
40.8,10.52640855,0.200514791,78611.24939,1.624209438,125.3764116
41,10.84330991,0.202433121,79309.95777,1.618981332,126.1271313
41.2,10.80911389,0.204397555,79927.64393,1.617238614,127.0369269
41.4,10.84347161,0.206376481,80459.05785,1.615931583,127.8072576
41.6,11.01452441,0.208365019,80977.27939,1.615495923,128.5961113
41.8,10.82616983,0.21040068,82053.50208,1.607218011,129.5821767
42,11.19582179,0.212424663,83053.72944,1.598504482,130.4222421
42.2,11.2118865,0.21447529,84263.28468,1.588919556,131.4845785
42.4,11.0064868,0.216573778,85098.69621,1.584562749,132.3649545
42.6,11.26477585,0.21866862,86045.26115,1.578898957,133.2965439
42.8,11.07017319,0.220803116,86906.73711,1.576284865,134.3545206
43,11.3675147,0.222921404,87456.83299,1.577374093,135.2523333
43.2,11.41264574,0.225085587,88132.32808,1.576720581,136.1893691
43.4,11.78476886,0.227246704,88641.088,1.578027657,137.0501365
43.6,11.57353179,0.229474022,89064.21825,1.583691455,138.1440691
43.8,11.70715306,0.231697425,89279.3519,1.589355291,138.9329235
44,11.80296062,0.233945992,89395.79172,1.598940229,139.9080943
44.2,11.9498706,0.236213465,89337.45003,1.608525174,140.6272151
44.4,11.85412715,0.238522158,89346.35132,1.617238734,141.3790222
44.6,12.14645351,0.240824556,89605.85493,1.623773945,142.3661801
44.8,12.04571674,0.243179984,90004.90113,1.625516648,143.1604803
45,12.01644157,0.245553605,90506.5655,1.627695038,144.1487254
45.2,12.02040231,0.247948511,90825.49461,1.63030911,144.9027122
45.4,12.38085498,0.250340577,91245.34523,1.631616186,145.709001
45.6,12.19451077,0.252798243,91691.30784,1.635101594,146.7430073
45.8,12.37379934,0.255252737,91584.47403,1.644686543,147.4555914
46,12.46832275,0.257738352,91920.12258,1.649043339,148.3937172
46.2,12.18224764,0.260277793,92439.83326,1.648607628,149.1782093
46.4,12.42052475,0.262802867,93074.62446,1.646429263,149.9812288
46.6,12.42528894,0.265371014,93889.19017,1.644250871,151.0577301
46.8,12.59957149,0.267952147,94946.94758,1.635972998,151.93484
47,12.80958261,0.270556379,95860.97021,1.632051915,153.0189699
47.2,12.78109469,0.273205102,96273.37508,1.633794626,153.8415989
47.4,12.93542093,0.275866382,96258.61127,1.642072537,154.6130204
47.6,13.08309498,0.278554862,95811.16827,1.659064016,155.5446091
47.8,13.48587946,0.281250979,95106.52489,1.676926882,156.128625
48,13.8811807,0.283974834,94393.85105,1.696968142,156.8510169
48.2,14.07288442,0.286741441,94057.32929,1.708731493,157.4132394
48.4,14.08425832,0.289549566,93982.86928,1.716573703,158.0473728
48.6,14.00671154,0.292392608,94511.33245,1.716138016,158.9190335
48.8,14.27817709,0.295237825,95557.42995,1.705681763,159.7176945
49,14.37097469,0.298125248,97068.50975,1.689561665,160.7680466
49.2,14.37235849,0.301048564,98331.0722,1.676926988,161.6571407
49.4,14.87898117,0.303962727,99845.41987,1.66342101,162.8066476
49.6,15.21192174,0.306919393,100729.5831,1.658628581,163.7360587
49.8,15.39610988,0.309917231,101016.9859,1.664292425,164.6981559
50,15.38750293,0.312959846,101009.4591,1.672134641,165.4096491
50.2,15.76779572,0.316003346,100839.5232,1.683898006,166.2562529
50.4,15.63286814,0.319116807,100753.913,1.692175891,166.9350578
50.6,15.5810349,0.322254978,100839.9114,1.699582422,167.8590186
50.8,15.93721408,0.325393625,100978.3254,1.703503572,168.5269311
51,15.79645456,0.328601832,101450.5378,1.704374911,169.4312782
51.2,15.65070399,0.331842464,101956.1126,1.70306786,170.1700097
51.4,16.03595257,0.335075399,102461.3156,1.702632227,170.9654041
51.6,16.0198265,0.338371382,103109.9452,1.702196547,171.9471121
51.8,15.91477901,0.34170686,103765.4973,1.699582463,172.7218002
52,15.95348794,0.345064837,104447.4405,1.698275432,173.7035086
52.2,16.20492565,0.348440369,105166.0327,1.694790032,174.5217821
52.4,16.43558316,0.351851374,105981.9151,1.689997594,175.3869078
52.6,16.60806572,0.355301162,107069.8521,1.683026755,176.5396805
52.8,16.46725849,0.358809437,107527.0846,1.683026739,177.3525035
53,16.65551881,0.362327862,108187.0794,1.682591083,178.378886
53.2,16.87784421,0.365879085,108246.6148,1.690433325,179.3050279
53.4,16.6672167,0.369498957,108141.5233,1.697839838,179.8737852
53.6,16.95850305,0.373116991,107965.946,1.710910234,180.7912108
53.8,16.81101943,0.376804711,107962.8644,1.718316754,181.4558505
54,17.14799872,0.380492686,108197.9768,1.72310926,182.3013654
54.2,16.91989701,0.384260748,108512.3684,1.727030342,183.1839198
54.4,17.51364118,0.388004037,108730.5006,1.730515842,183.8954182
54.6,17.92705393,0.391798715,108811.9477,1.735744037,184.6341549
54.8,18.2399105,0.395639215,108913.0563,1.740100862,185.3086052
55,18.31094204,0.399536493,109033.2288,1.745764694,186.1083554
55.2,18.78167491,0.403442747,109285.2714,1.749250181,186.9179144
55.4,18.54356461,0.40744207,109727.5596,1.748814474,187.6544658
55.6,19.09987714,0.41142117,110309.3363,1.746636148,188.4258912
55.8,19.08030522,0.415484116,111103.437,1.742279358,189.3520309
56,19.2643201,0.419572269,111466.0493,1.742715059,190.0711534
56.2,19.42589161,0.423703409,112313.9931,1.737486933,191.0223545
56.4,19.74866914,0.427863865,113084.0833,1.733130185,191.8362713
56.6,20.19816646,0.43205654,113889.293,1.72920913,192.6937719
56.8,20.04020122,0.436337563,114566.7663,1.728773432,193.6689416
57,20.19094304,0.440638069,115454.9531,1.723545305,194.4893941
57.2,20.14597912,0.444996809,116275.9593,1.721366906,195.4863561
57.4,20.2044669,0.449391304,116842.4998,1.720931234,196.3340473
57.6,20.58329543,0.453805704,117567.9599,1.718317207,197.2275035
57.8,20.48471144,0.458300765,118744.5747,1.710474977,198.2931083
58,20.36742295,0.462842317,119694.0104,1.706118175,199.3881315
58.2,20.30871222,0.46742496,120400.6056,1.703068417,200.2641505
58.4,20.61313812,0.472026009,120804.2814,1.70437549,201.1151125
58.6,20.7575905,0.47668553,121278.3139,1.70698958,202.2341092
58.8,20.89164804,0.481392645,121436.4013,1.711346384,203.0240534
59,21.15741044,0.486137096,121921.3328,1.71352481,204.0689601
59.2,21.20378311,0.490945919,122297.2779,1.71570321,204.8937699
59.4,21.27840189,0.49580073,122787.0715,1.716138897,205.7349236
59.6,21.88277096,0.500664177,123461.3698,1.716574648,206.8866117
59.8,21.77912617,0.505630407,123505.3832,1.722238461,207.6493143
60,21.76189675,0.510639847,123271.5278,1.732694752,208.5580212
60.2,21.81280077,0.515694385,123185.7208,1.739229941,209.2804112
60.4,22.57086772,0.520771838,123430.2858,1.743586821,210.2850083
60.6,22.63339354,0.525901603,123780.9807,1.744893865,211.0444438
60.8,22.86750711,0.531095904,125359.6248,1.733130564,212.1928598
61,22.91879391,0.536356272,126730.0494,1.723109956,213.1723899
61.2,23.0909818,0.5416603,128400.9647,1.711782326,214.4036133
61.4,23.29349248,0.547015308,129748.2827,1.703068772,215.4561465
61.6,23.34433836,0.552435609,131063.3231,1.695226559,216.5762315
61.8,23.78158745,0.557880768,131804.6927,1.694790931,217.7758601
62,23.57065316,0.563429969,132637.3212,1.691741155,218.7684615
62.2,23.77603759,0.569003204,133665.605,1.688255748,220.0519854
62.4,24.44593833,0.574597151,134365.3243,1.686948789,221.0958074
62.6,24.69617855,0.580279343,134900.3046,1.688255855,222.1875656
62.8,24.44615178,0.586056613,135375.382,1.691741258,223.4100682
63,24.72379649,0.591851781,135399.0514,1.698276475,224.294807
63.2,24.80033158,0.597720491,134876.4664,1.712653889,225.3059353
63.4,24.58019272,0.603670702,134087.734,1.728773983,226.0522927
63.6,24.81542865,0.609646013,133367.9784,1.744022774,226.8019238
63.8,25.45617977,0.61565048,132629.1198,1.760142973,227.619114
64,25.40885886,0.621767705,132267.4183,1.769727905,228.2532471
64.2,26.44929847,0.627863375,132244.3293,1.776263217,229.0944119
64.4,26.8988921,0.634065344,132919.7473,1.773213519,229.9159574
64.6,27.02023347,0.640354485,134216.2411,1.763628596,230.8845926
64.8,27.05181752,0.646713595,136264.4592,1.746637119,232.1485024
65,27.51384598,0.653103913,138177.2152,1.730952731,233.2402646
65.2,27.97503327,0.659558478,140627.5816,1.712218588,234.6730626
65.4,28.24757474,0.666092232,142087.8838,1.703505032,235.8280168
65.6,28.25252588,0.672712099,142502.9801,1.706119112,236.9045195
65.8,28.37546753,0.679389419,142716.0384,1.71178295,238.0376804
66,27.92667503,0.686177227,142105.6391,1.725724633,239.0368173
66.2,28.68696716,0.692941292,141507.6406,1.737488056,239.7733797
66.4,29.14061191,0.699796697,141480.3654,1.743587615,240.6363299
66.6,29.22279163,0.706749253,142819.5676,1.736616764,241.92639
66.8,29.70716111,0.713741049,143912.0577,1.730517313,242.9397022
67,29.64638766,0.720844614,145697.0526,1.719189653,244.3103893
67.2,29.74016767,0.72800778,147184.976,1.710040396,245.4381026
67.4,30.28848974,0.735208218,148733.0784,1.701326882,246.6780478
67.6,30.47947306,0.742508292,149600.5811,1.701762584,248.1260979
67.8,30.33721631,0.749907009,149892.7868,1.705683685,249.1187008
68,30.84561572,0.757330551,150409.8584,1.709169178,250.39896
68.2,31.00914096,0.764854831,150264.4298,1.717447098,251.3207441
68.4,30.78291817,0.772484426,149409.5618,1.73269584,252.1194014
68.6,31.24640789,0.78013819,148529.4803,1.749687381,253.1185492
68.8,31.35505111,0.787895838,148024.5141,1.760579377,253.8627324
69,31.36728668,0.795738854,147390.5903,1.773649753,254.6973485
69.2,31.5149617,0.803650241,147551.0042,1.777135204,255.4807558
69.4,32.23102374,0.811597965,148250.0051,1.775392576,256.3916518
69.6,32.63545048,0.819649214,149176.5874,1.77321423,257.5476973
69.8,33.4204595,0.827752459,149650.7065,1.773650006,258.3790551
70,33.49661796,0.835990888,149769.961,1.778878166,259.3346152
70.2,33.89186485,0.84428793,150350.57,1.778006856,260.1681463
70.4,34.12339273,0.852680756,151191.8402,1.774521451,261.0964689
70.6,34.22942714,0.861167458,153153.4706,1.761015409,262.4791443
70.8,34.55399937,0.869722768,155933.9658,1.740102846,263.9914817
71,34.59602005,0.878385585,158795.701,1.718318889,265.3621706
71.2,34.89314199,0.887116013,161502.8989,1.700456076,267.0564665
71.4,35.31822305,0.895924448,162983.8383,1.693485258,268.3748605
71.6,35.76905087,0.904819367,164225.678,1.689564198,269.7281216
71.8,36.22069548,0.913803685,165582.8938,1.686078817,271.2938496
72,36.14298263,0.922918483,166443.5067,1.685643129,272.5435935
72.2,36.33117329,0.932104552,168038.172,1.680415,274.1594399
72.4,36.34899552,0.941395949,169715.5162,1.673008454,275.5944131
72.6,36.61028414,0.950762155,171244.3543,1.667344654,277.1078393
72.8,36.62059763,0.960241554,172203.2682,1.667780335,278.7934159
73,36.91426491,0.96979462,172383.8609,1.67300852,280.047524
73.2,37.08326785,0.979453205,171843.6113,1.68607892,281.4160351
73.4,37.22566354,0.989210923,171370.7917,1.697406599,282.5121523
73.6,37.60903192,0.999048248,170772.1154,1.710041344,283.638781
73.8,37.84903808,1.008995644,170380.5516,1.721804715,284.9212154
74,38.06077456,1.019045189,170407.0856,1.727468572,285.8778686
74.2,38.70502736,1.029162954,171506.5112,1.725290252,287.3193877
74.4,38.83529421,1.039421415,172202.1467,1.725290268,288.5048499
74.6,39.4803455,1.0497438,173118.9914,1.725290345,290.0433419
74.8,40.27579025,1.060158644,173731.9685,1.72572612,291.1470954
75,40.41390205,1.07072795,174169.4814,1.729647251,292.5384876
75.2,40.78425985,1.081385696,173757.1997,1.738796564,293.4515593
75.4,41.1604176,1.092150116,173764.9222,1.744896121,294.5095449
75.6,41.07618737,1.103057722,174151.4913,1.749688585,295.8943963
75.8,41.55909326,1.114031828,174679.4459,1.750995682,296.932771
76,41.56706843,1.125152355,175470.8121,1.751431363,298.2566073
76.2,41.99467791,1.136352755,176221.5137,1.752302774,299.5401369
76.4,42.4800236,1.147661419,176336.6547,1.758402346,300.6569605
76.6,42.7305954,1.159101325,176410.7459,1.763630531,301.59618
76.8,43.57655636,1.170610913,176607.4217,1.768858788,302.8012651
77,43.68997746,1.182291807,177032.4123,1.770165841,303.7753494
77.2,44.378428,1.194046366,178256.1812,1.76580913,305.1198985
77.4,44.5732491,1.205956716,179597.0054,1.759273961,306.3326014
77.6,44.94463749,1.217973325,180822.6617,1.753610173,307.6063236
77.8,45.21088593,1.230118498,182624.2811,1.744896614,309.192753
78,45.87058099,1.242417783,184234.4912,1.737490141,310.5046143
78.2,46.05826131,1.254815288,186176.2888,1.728776573,312.1161029
78.4,46.21518506,1.267276613,188007.1454,1.72049868,313.5554376
78.6,46.34299409,1.279928353,190073.0287,1.711785103,315.1091776
78.8,47.01757731,1.292665594,191927.2781,1.706121349,316.9059017
79,47.40669361,1.30555239,192674.403,1.706992754,318.2482675
79.2,47.92334708,1.318558536,193039.208,1.712220971,319.7900279
79.4,48.3302885,1.33170373,192843.676,1.720498933,321.0158095
79.6,48.49123453,1.344999625,193040.6208,1.725291429,322.3113204
79.8,48.68041317,1.358426896,193232.9674,1.730955287,323.7386707
80,48.82303464,1.371992732,193887.5516,1.731826664,324.9600898
80.2,49.30468027,1.385669078,195796.9399,1.724420168,326.7208551
80.4,49.51124483,1.39950381,197806.1444,1.715270919,328.2680595
80.6,49.89894415,1.413463703,199648.8854,1.70830009,329.887179
80.8,50.12457721,1.427576181,201372.5938,1.703507641,331.7754206
81,50.43661117,1.441823967,201323.6463,1.710042874,333.0709344
81.2,50.56580356,1.456228701,199463.4687,1.731391195,334.2956223
81.4,51.22265463,1.470738009,197530.16,1.752303902,335.1629376
81.6,51.23463056,1.485442286,194669.2918,1.781930122,336.057481
81.8,51.88728007,1.500245114,193197.2612,1.798921717,336.743926
82,52.34212916,1.515212,193213.3894,1.805021291,337.8106298
82.2,52.6831081,1.530337663,194352.651,1.800664536,338.8544515
82.4,53.14455716,1.545606022,196567.5524,1.78802988,340.1946404
82.6,53.17220253,1.561060707,198727.7879,1.776702209,341.623078
82.8,53.9277748,1.576615069,201116.911,1.764503267,343.2923249
83,54.76725275,1.592319384,202567.2391,1.759710892,344.8308224
83.2,54.87958502,1.60823687,202966.4746,1.761889302,345.9552695
83.4,55.42151631,1.624281483,202879.1462,1.76798889,347.01217
83.6,55.52548758,1.640520766,203761.1644,1.767988905,348.5582835
83.8,55.99922575,1.656894919,204372.3496,1.768860323,349.7284984
84,56.34496451,1.673443438,205438.445,1.767117639,351.179823
84.2,56.79372027,1.690150287,206819.5377,1.763196579,352.7390173
84.4,57.26239324,1.707023468,208606.7675,1.755354395,354.2045084
84.6,57.5199665,1.724082245,209560.6147,1.754047391,355.5860983
84.8,57.77252655,1.741312835,211028.8049,1.74969062,357.2640535
85,58.52864218,1.75867823,212274.0894,1.746205274,358.6184127
85.2,59.14013693,1.776229154,213967.023,1.740977187,360.3650178
85.4,59.4192056,1.793981467,214508.8835,1.743155616,361.7030251
85.6,60.08632072,1.8118827,215498.1804,1.742720022,363.1565347
85.8,60.43347407,1.829988132,217139.514,1.738798945,364.8889708
86,60.87034601,1.848268703,219345.4693,1.730956759,366.7902939
86.2,60.86509923,1.866766655,221661.6925,1.721371795,368.4617068
86.4,61.22878486,1.885422256,224492.8295,1.7091728,370.2943847
86.6,61.82179542,1.904247923,227582.0075,1.697845189,372.6609609
86.8,62.01340515,1.923293276,229090.4542,1.695231132,374.3759606
87,62.5997073,1.942499897,229774.2364,1.697845282,375.9743839
87.2,63.10786524,1.961905368,229062.7735,1.710915745,377.6534331
87.4,63.48137093,1.981516092,228095.5481,1.723986192,378.9369648
87.6,64.44402113,2.001279127,227132.6418,1.738363752,380.5212288
87.8,64.82826691,2.021284637,227048.5097,1.744463321,381.7829696
88,65.26981945,2.041486797,227278.3543,1.750127217,383.370494
88.2,65.44791414,2.061911924,228991.5695,1.744463397,384.8741156
88.4,66.41625305,2.08248219,231519.4025,1.734007189,386.6599538
88.6,66.77294634,2.103305702,234487.7067,1.722679547,388.917568
88.8,67.27087566,2.124327623,235632.0468,1.723115287,390.8025493
89,68.29562272,2.145520714,236419.0963,1.72398677,392.272411
89.2,68.45859336,2.166992312,236815.2136,1.728779273,394.027726
89.4,68.9796889,2.188652403,236725.7726,1.73575022,395.4354718
89.6,69.53814468,2.210527244,237162.2796,1.740978451,397.2583489
89.8,70.50624653,2.232590631,238654.0051,1.737493125,398.8654973
90,71.03804036,2.254908808,240730.4989,1.731829345,400.8616158
90.2,71.52907974,2.277454435,242428.0105,1.727472601,402.548294
90.4,72.00512519,2.30022777,244236.9393,1.722680174,404.3166905
90.6,72.62572762,2.323218778,246707.5965,1.715709362,406.6778209
90.8,73.20723652,2.346443904,249203.1475,1.708302865,408.9245445
91,73.79701832,2.369901684,250005.0136,1.709609976,410.6351952
91.2,74.19438704,2.393610032,250271.9604,1.713966828,412.2477809
91.4,74.8397701,2.417538705,250687.4339,1.71832371,414.173081
91.6,75.41946627,2.44171281,250421.6642,1.726601708,415.9033447
91.8,75.56118885,2.466163182,249156.0431,1.740979181,417.4788793
92,76.07391221,2.490830855,249427.6275,1.744900368,418.9051501
92.2,77.0261932,2.515712953,250754.1907,1.744029122,420.838083
92.4,77.4021386,2.540888794,251776.2338,1.744464849,422.4811754
92.6,78.01529325,2.566299575,252240.3586,1.748386048,424.1013933
92.8,78.52785675,2.59197346,253887.9695,1.745772027,426.0975144
93,78.76698146,2.617926126,255445.7227,1.742286612,427.7438744
93.2,79.74191204,2.644083528,256503.3785,1.743158091,429.6473896
93.4,80.34866949,2.670531687,257724.2073,1.741851123,431.3384301
93.6,81.17310579,2.697229146,261186.8212,1.729652165,433.8107034
93.8,81.93185077,2.724199882,263156.0295,1.724859768,435.5856444
94,82.64110843,2.751445243,264714.2295,1.724424173,437.7975071
94.2,83.26265248,2.778970982,265793.7465,1.724424247,439.5048914
94.4,84.07320435,2.806758781,267084.9767,1.723552983,441.3364927
94.6,84.99340343,2.834817622,267939.475,1.727038539,443.6355266
94.8,85.44653755,2.86319398,268930.1113,1.727038594,445.4159089
95,86.09034014,2.891840958,270427.1878,1.725731629,447.6811598
95.2,86.82675316,2.920768611,272237.4216,1.72181059,449.5389107
95.4,87.4629732,2.950068143,274370.5847,1.717018177,451.5513781
95.6,87.78796163,2.979537896,276980.361,1.711354365,454.1424077
95.8,88.57988747,3.009493439,279051.6966,1.707433332,456.1919249
96,89.13414822,3.039467092,282588.6193,1.697412738,458.8940955
96.2,89.80467662,3.069884571,285968.2678,1.687609996,461.4262953
96.4,90.65631381,3.100593952,288666.3278,1.681728404,464.0195144
96.6,91.24489165,3.131630476,290804.8252,1.678678706,466.4852483
96.8,92.03784526,3.162963174,292494.4481,1.676936075,468.687307
97,92.50333598,3.194635669,292435.0656,1.68608543,471.1715615
97.2,92.99619905,3.22662421,291202.0866,1.699155918,472.905095
97.4,93.69011238,3.258918793,290251.4748,1.712662112,475.097347
97.6,94.38729817,3.291537558,289368.5595,1.723989903,476.8080039
97.8,95.18996853,3.324476186,288252.988,1.737496112,478.6766529
98,96.08399607,3.357738647,288608.7837,1.74141735,480.3426429
98.2,97.24721371,3.391314884,289886.0271,1.741853172,482.562145
98.4,97.57439432,3.425292179,291111.3673,1.741417531,484.4460383
98.6,98.40926015,3.459572179,293102.7129,1.738803545,486.9150475
98.8,99.3845099,3.494185806,294702.4945,1.737060938,488.8577937
99,100.2217588,3.529157887,295748.0089,1.739675126,491.0849155
99.2,100.8054976,3.56450056,296528.2867,1.741853603,492.8304383
99.4,101.6393103,3.600179313,297376.5828,1.744032111,494.6718499
99.6,102.0991172,3.63624438,298121.2792,1.74838898,497.0264451
99.8,102.391836,3.672684138,299246.2404,1.747953334,498.8362453
100,103.6276791,3.709418049,300706.3816,1.747082122,501.1309337
100.2,103.8887033,3.746594932,302366.3624,1.744032385,503.0398865
100.4,104.7056056,3.784102973,304596.3561,1.738368626,505.16132
100.6,105.4858842,3.82199058,307919.335,1.729655093,508.026936
100.8,106.6791083,3.860227333,311192.1036,1.720505928,510.3085487
101,107.5731122,3.898871041,316479.0399,1.704385822,513.3801014
101.2,108.5252243,3.937898451,321042.45,1.692622531,516.5780459
101.4,109.7997014,3.977293516,323744.1369,1.688701549,519.360867
101.6,110.1267777,4.017156546,325522.4329,1.687830227,521.7143722
101.8,110.9449104,4.057382682,325292.652,1.697415317,524.3718818
102,111.7480208,4.098014138,323397.6513,1.712228583,526.0999783
102.2,112.4845866,4.139058874,322055.2441,1.725734798,528.2301289
102.4,113.4304984,4.180499927,321802.8039,1.733577182,530.2229976
102.6,114.1702565,4.22237293,321449.0967,1.741419546,532.090558
102.8,115.0562036,4.26465562,322700.3124,1.742291015,534.4767659
103,116.0675639,4.307353688,325462.5274,1.734884547,536.7213303
103.2,116.9625162,4.350489608,328707.5371,1.72704238,539.6359845
103.4,117.9945146,4.394048428,330012.0565,1.72704251,541.9056102
103.6,118.4472373,4.438088894,331863.2252,1.726171199,544.7396223
103.8,119.4549969,4.482529622,332373.4699,1.730092456,546.7357638
104,120.189287,4.527437716,331522.843,1.741855954,548.936738
104.2,121.3556247,4.572764107,330347.8854,1.753183824,550.5340985
104.4,121.936036,4.618590479,329627.0906,1.762333215,552.2796226
104.6,122.9759165,4.664842329,329650.254,1.769304253,554.4936817
104.8,123.9974413,4.711560234,330693.832,1.76974006,556.3645218
105,124.9873135,4.758749842,333361.5513,1.763640634,558.8575123
105.2,126.0427594,4.806408662,336629.0144,1.75405576,561.1042592
105.4,126.9136474,4.854560303,340290.1653,1.743599497,563.5798141
105.6,127.6431887,4.903206396,344084.5624,1.734450263,566.7396217
105.8,128.7549121,4.952312236,346143.946,1.731400622,569.0146996
106,129.5050723,5.001939025,347275.3657,1.734014806,571.6525988
106.2,130.5235662,5.052043909,348128.6415,1.737500386,574.2218637
106.4,131.5153881,5.102654281,349673.1603,1.737064824,576.5437906
106.6,132.5561583,5.153769487,351578.0357,1.73532222,578.9158409
106.8,133.9483596,5.205371456,354194.9175,1.73183693,581.8152596
107,134.9391059,5.257522458,356940.2137,1.726608862,584.2483252
107.2,135.8192461,5.31020573,358952.6233,1.726608968,587.0365918
107.4,136.7815711,5.363412074,359895.3312,1.730094543,589.4315236
107.6,137.9989281,5.417133502,359809.0856,1.738808336,592.0105996
107.8,138.9577585,5.471414399,358604.257,1.750136195,593.8247841
108,139.7486403,5.526253491,358192.46,1.75884994,596.1684986
108.2,141.0205835,5.581606859,358511.3177,1.762335555,598.0153787
108.4,142.0398145,5.63753567,359296.904,1.76407841,600.0703632
108.6,143.0423361,5.6940277,360781.6476,1.764514216,602.840112
108.8,144.2874194,5.751070849,362978.4969,1.760157543,605.1108391
109,145.4842135,5.80869163,364807.8829,1.758850642,607.6659479
109.2,146.3335575,5.866917859,366371.5881,1.757979381,609.8407808
109.4,147.7250364,5.925687849,368310.4498,1.756890344,612.4280367
109.6,148.6660192,5.985082606,370502.8877,1.754929887,614.9891308
109.8,150.2584117,6.045024617,373410.5481,1.751008936,617.8068415
110,151.2602827,6.105613804,376508.0809,1.7449095,620.2464482
110.2,152.0061088,6.166831233,380637.9852,1.736631618,623.486892
110.4,153.4191307,6.228612993,383592.6628,1.731839277,626.2108929
110.6,154.3862221,6.291049312,387084.2786,1.724868468,629.050379
110.8,155.4234335,6.354107663,389961.5592,1.721383129,632.3148027
111,156.5768844,6.417790714,391725.5247,1.720511901,634.8546595
111.2,157.99283,6.482093714,394349.733,1.718333656,638.1158267
111.4,159.3679539,6.547045951,397049.9063,1.714848356,641.0098044
111.6,160.3486642,6.612680695,398789.154,1.715284156,643.8460205
111.8,161.7431084,6.678943286,399739.9502,1.719641153,646.9404833
112,163.4839744,6.745845573,400525.1963,1.724433876,649.8998474
112.2,164.6704558,6.813462194,400146.7912,1.731840632,652.1727604
112.4,165.8252512,6.881760612,399594.5837,1.740118752,654.4925213
112.6,167.0140088,6.950742549,398936.1915,1.748832561,656.8133743
112.8,168.3991881,7.020402784,399601.9753,1.753189563,659.5798733
113,169.6192744,7.090952632,400853.5533,1.755368128,662.3964873
113.2,170.7142389,7.161864861,402488.5119,1.754932579,664.7859827
113.4,171.9577535,7.23401905,404899.4205,1.751882947,667.4228159
113.6,173.0533499,7.306185467,408493.69,1.746219196,670.8223564
113.8,174.2451691,7.379435206,411271.7824,1.741862506,673.3894566
114,175.6342347,7.453404335,414372.7861,1.737941523,676.686585
114.2,176.6970142,7.528139581,416818.6585,1.734891867,679.3484762
114.4,178.1510766,7.603595668,418964.1921,1.733584991,682.1716373
114.6,179.3191538,7.679831824,422854.2525,1.727921245,685.9449099
114.8,180.6940289,7.756818089,426460.0537,1.721386156,688.9162533
115,182.021414,7.834581546,430985.13,1.713979692,692.7124141
115.2,183.2946599,7.913130424,433891.3773,1.710930058,695.6477969
115.4,184.8511523,7.992447085,437463.9603,1.707880456,699.5278643
115.6,186.5462957,8.072550189,438689.1017,1.710930444,702.4861449
115.8,188.2687344,8.153455892,436313.6893,1.727050953,705.3430985
116,189.5979797,8.235204448,435645.2825,1.735329107,707.6781263
116.2,191.2329037,8.317751099,435290.4215,1.7436073,710.6167951
116.4,192.8361179,8.401129589,435003.52,1.750578439,713.0662393
116.6,193.9713445,8.485381549,435794.3548,1.75406405,715.6736563
116.8,195.776225,8.570428849,439364.2648,1.74883606,719.1048264
117,197.1056361,8.656367024,440927.6739,1.749271906,721.7416686
117.2,198.2687097,8.743180082,442442.5831,1.751014785,724.8884356
117.4,199.8338503,8.830834378,444129.9043,1.75145066,727.6462332
117.6,201.4811207,8.919361836,445867.1865,1.752757913,730.9183198
117.8,202.8839348,9.008797545,447085.6907,1.754500822,733.4941502
118,203.9558669,9.099156023,450126.7889,1.751451163,736.8762646
118.2,205.6600487,9.190373853,453060.3093,1.74753021,739.5981118
118.4,207.3931702,9.28250576,455149.1702,1.747094736,742.5672976
118.6,208.9042667,9.375580088,457157.3711,1.748401974,746.0496735
118.8,210.5548233,9.469579155,458813.9136,1.749273543,748.7649803
119,212.2742034,9.564517336,461172.9365,1.749273753,752.0425195
119.2,213.587071,9.660440195,463055.4928,1.749273919,754.7185964
119.4,215.4607135,9.757284111,465921.5401,1.746660028,757.8294359
119.6,217.0923792,9.85511938,470763.7573,1.738817904,761.7955915
119.8,218.6756907,9.953941265,473934.6227,1.73620399,765.512233
120,220.4292004,10.05374314,475586.5399,1.736639886,768.356121
120.2,221.8052748,10.15457646,477187.5771,1.738818479,771.9158541
120.4,223.3706574,10.2564085,477282.8476,1.744482571,774.6344334
120.6,225.1968131,10.3592437,476747.4159,1.752325121,777.3039915
120.8,227.0178187,10.46311254,477810.0756,1.755810827,780.5695543
121,228.880209,10.56802188,477863.2387,1.760603588,782.9514637
121.2,230.3618316,10.67401403,479655.1482,1.761475138,786.3183463
121.4,231.9920349,10.78106,482056.5566,1.759296914,789.3104169
121.6,234.1115297,10.88914408,485799.1431,1.753197576,792.5258683
121.8,235.6408383,10.99835922,488934.0184,1.750147966,796.1390052
122,237.4292464,11.10865159,492275.7809,1.745791334,799.2934321
122.2,239.2931,11.22004657,495066.4404,1.744920193,803.060211
122.4,240.9024883,11.33257994,498538.9708,1.741434897,806.3072445
122.6,242.6396719,11.44623425,502010.9188,1.739692365,810.2472653
122.8,244.2378962,11.56104109,505453.9233,1.736207074,813.4528976
123,246.2447923,11.67697029,507064.7521,1.739692801,817.1761005
123.2,247.9714545,11.79408554,506966.5865,1.74579261,819.8413026
123.4,249.8400319,11.91236667,504535.7073,1.758427724,822.3408935
123.6,251.3255846,11.91522978,500136.4951,1.777162393,825.0028203
123.8,252.3038657,11.91515557,497031.6601,1.790668774,826.9346996
124,253.2863018,11.91508105,496991.4107,1.795897126,829.6587104
124.2,253.755176,11.91504543,500253.1673,1.791540325,832.8730168
124.4,254.5074234,11.91498834,505041.452,1.7828267,835.9631199
124.6,254.766053,11.91496864,511106.1112,1.771498898,839.3702761
124.8,255.5216244,11.9149113,517438.2742,1.761042528,843.4475488
125,255.8824679,11.91488386,520855.5636,1.757121398,846.6258947
125.2,256.207578,11.91485913,522555.2313,1.759735554,850.2182834
125.4,256.7063685,11.91482124,525038.0027,1.758428556,853.3421552
125.6,256.7672186,11.91481652,527053.161,1.759735622,857.137198
125.8,257.1106109,11.9147904,529033.6492,1.759735663,860.1619094
126,257.4681303,11.91476321,531656.0735,1.759735707,863.7662873
126.2,257.5401989,11.91475764,533114.1261,1.76147846,866.5959514
126.4,257.9625369,11.91472554,531745.125,1.771499289,869.1684893
126.6,257.9901467,11.91472334,531455.1975,1.779341641,872.4230933
126.8,258.0559827,11.91471824,531704.7066,1.783698509,874.908449
127,258.4400944,11.91468904,532828.7526,1.786748358,878.1053192
127.2,258.4918034,11.91468501,535811.3942,1.783262877,881.0428556
127.4,258.9536142,11.91464992,540046.8978,1.776727643,884.4500206
127.6,258.7464646,11.9146655,543583.14,1.773677816,888.2842744
127.8,259.2012118,11.91463094,545383.1924,1.774113558,891.2033047
128,259.281175,11.91462477,547052.4268,1.775856312,894.7880548
128.2,259.3407786,11.91462015,545962.541,1.783698668,897.2309159
128.4,259.5910982,11.91460108,543986.253,1.79459085,899.5321407
128.6,259.6980691,11.91459286,541798.3578,1.806790073,902.229968
128.8,259.98246,11.91457121,539635.7372,1.81768226,904.1236875
129,260.09691,11.91456243,537456.1603,1.829445799,906.3050498
129.2,260.0808919,11.91456353,537618.9581,1.833366971,908.2510552
129.4,260.3058658,11.91454638,539044.9099,1.833802686,910.6132937
129.6,260.618511,11.91452259,540100.3787,1.835981156,913.3895817
129.8,260.6249301,11.91452199,540308.7628,1.83903096,915.2713029
130,260.7738669,11.9145106,539646.7293,1.84556627,917.5648961
130.2,260.8384565,11.9145056,538419.1382,1.852537256,919.1480708
130.4,260.9333778,11.9144983,534883.1831,1.867350595,920.7802791
130.6,261.2123672,11.91447706,532697.5438,1.877153568,922.0186105
130.8,260.88763,11.91450154,532350.9564,1.881292545,923.5794321
131,260.9883684,11.9144938,533816.6231,1.880421186,925.6398507
131.2,261.1547564,11.91448108,533842.0324,1.883035324,927.0508758
131.4,261.4029985,11.91446217,535549.2044,1.880856926,928.8955606
131.6,261.1289528,11.91448281,539027.119,1.873885913,931.366736
131.8,261.2363392,11.91447457,540925.6527,1.87127181,933.1493096
132,260.9672796,11.91449484,541466.7551,1.873885892,935.1236329
132.2,261.3513913,11.91446563,542184.4546,1.875193,936.7580306
132.4,261.6316272,11.9144443,542309.5702,1.87824284,938.31398
132.6,261.786381,11.91443246,538523.6999,1.893491874,939.4536978
132.8,261.7059599,11.91443844,535730.4386,1.904384017,940.2174977
133,261.6621031,11.91444165,534977.2839,1.909176558,941.4672548
133.2,261.7561935,11.91443441,532588.9761,1.918761665,942.3934095
133.4,261.9275675,11.91442132,531303.9836,1.924425608,943.1931756
134.1,261.8607139,11.82155074,1.7977E+308,2.004156158,0
134.3,261.5715241,11.70250169,1.7977E+308,2.004156116,0
134.5,261.2682072,11.58345371,1.7977E+308,1.927039631,0
134.7,261.2241644,11.4643861,1.7977E+308,1.761043219,0
134.9,260.8419018,11.3453441,1.7977E+308,1.531436602,0
135.1,260.4405261,11.22630355,1.7977E+308,1.12363439,0
135.3,260.4047934,11.1072353,1.7977E+308,0.744587501,0
135.5,260.1355477,10.98818474,1.7977E+308,0.440042927,0
135.7,259.849682,10.86913544,1.7977E+308,0.209129307,0
135.9,259.7250315,10.75007393,1.7977E+308,0.049232524,0
136.1,259.4026015,10.6310274,1.7977E+308,0.011327837,0
136.3,258.9895917,10.51198773,1.7977E+308,0.004792546,0
136.5,259.1109193,10.39290759,1.7977E+308,0.011763523,0
136.7,258.8965201,10.27385288,1.7977E+308,0.009585093,0
136.9,258.6438946,10.15480106,1.7977E+308,0.007406662,0
137.1,258.4793559,10.03574257,1.7977E+308,0.003049802,0
137.3,258.1311647,9.916697993,1.7977E+308,0.007842348,0
137.5,257.7912835,9.797652784,1.7977E+308,0.012634894,0
137.7,257.8627507,9.67857642,1.7977E+308,0.012199208,0
137.9,257.4198247,9.559539016,1.7977E+308,0.014377637,0
138.1,257.4106842,9.440468757,1.7977E+308,0.015249009,0
138.3,257.1231565,9.321419583,1.7977E+308,0.008278033,0
138.5,256.7126398,9.202379723,1.7977E+308,0.006535289,0
138.7,256.5688763,9.083319661,1.7977E+308,0.013070579,0
138.9,256.1325984,8.964281753,1.7977E+308,0.024398412,0
139.1,255.8641839,8.845231131,1.7977E+308,0.03529056,0
139.3,255.7752667,8.726166914,1.7977E+308,0.039211733,0
139.5,255.6373202,8.607106411,1.7977E+308,0.044439964,0
139.7,255.6281797,8.488036152,1.7977E+308,0.044004278,0
139.9,255.0506308,8.369008944,1.7977E+308,0.034419186,0
140.1,254.6608893,8.249967511,1.7977E+308,0.028319583,0
140.3,254.7323565,8.130891147,1.7977E+308,0.02221998,0
140.5,254.3725313,8.011847449,1.7977E+308,0.027012525,0
140.7,254.1838934,7.892790785,1.7977E+308,0.032240755,0
140.9,254.0260028,7.773731792,1.7977E+308,0.02744821,0
141.1,253.720193,7.654684002,1.7977E+308,0.020477235,0
141.3,253.4924978,7.535630297,1.7977E+308,0.022219978,0
141.5,253.0828122,7.416590374,1.7977E+308,0.032676438,0
141.7,252.8509621,7.297536983,1.7977E+308,0.048796813,0
141.9,252.9132881,7.178461312,1.7977E+308,0.059253273,0
142.1,252.5476459,7.059418054,1.7977E+308,0.060124643,0
142.3,252.3199508,6.940364348,1.7977E+308,0.053153669,0
142.5,252.13713,6.821307243,1.7977E+308,0.046182696,0
142.7,251.6543159,6.70227286,1.7977E+308,0.034419178,0
142.9,251.5022423,6.583213427,1.7977E+308,0.016991746,0
143.1,251.1698404,6.464167651,1.7977E+308,0.005228229,0
143.3,250.9463003,6.34511363,1.7977E+308,0.011763516,0
143.5,250.5740101,6.226070876,1.7977E+308,0.021784288,0
143.7,250.3313569,6.107018303,1.7977E+308,0.027448202,0
143.9,250.2519964,5.987953363,1.7977E+308,0.027883888,0
144.1,249.9441092,5.86890573,1.7977E+308,0.025705459,0
144.3,249.6287429,5.749858665,1.7977E+308,0.021348601,0
144.5,249.4612958,5.630800396,1.7977E+308,0.013506257,0
144.7,249.1097808,5.511756068,1.7977E+308,0.007406657,0
144.9,248.8218377,5.392706925,1.7977E+308,0.010020771,0
145.1,248.2584162,5.273678647,1.7977E+308,0.013941942,0
145.3,248.2268386,5.154610087,1.7977E+308,0.017427427,0
145.5,247.994573,5.035556728,1.7977E+308,0.021784284,0
145.7,247.7897306,4.916501291,1.7977E+308,0.023962712,0
145.9,247.3783832,4.797461495,1.7977E+308,0.02004154,0
146.1,247.269522,4.678398788,1.7977E+308,0.015248998,0
146.3,247.1432097,4.559337404,1.7977E+308,0.012199198,0
146.5,247.1220196,4.440268058,1.7977E+308,0.006535285,0
146.7,246.6475158,4.321233045,1.7977E+308,0.01699174,0
146.9,246.1484973,4.202199889,1.7977E+308,0.030497993,0
147.1,245.8792519,4.08314933,1.7977E+308,0.039211705,0
147.3,245.7176219,3.96409062,1.7977E+308,0.047489731,0
147.5,245.3594589,3.845046796,1.7977E+308,0.050103843,0
147.7,245.1084958,3.725994852,1.7977E+308,0.040518759,0
147.9,244.8799697,3.606941209,1.7977E+308,0.031805047,0
148.1,244.5837167,3.487892696,1.7977E+308,0.025705448,0
148.3,244.1565803,3.368854096,1.7977E+308,0.021348592,0
148.5,244.016972,3.249793718,1.7977E+308,0.010020768,0
148.7,243.7593608,3.130742278,1.7977E+308,0.009585082,0
148.9,243.2105767,3.011117537,1.7977E+308,0.019170163,0
149.1,243.0211079,2.892060936,1.7977E+308,0.026576817,0
149.3,242.9254482,2.773592584,1.7977E+308,0.033112099,0
149.5,242.4692267,2.654556186,1.7977E+308,0.031805041,0
149.7,241.8601001,2.53553137,1.7977E+308,0.027883871,0
149.9,242.0204848,2.416448271,1.7977E+308,0.021784274,0
150.1,241.5767284,2.29741093,1.7977E+308,0.016120362,0
150.3,240.9659398,2.178386239,1.7977E+308,0.010456451,0
150.5,240.9833915,2.059313966,1.7977E+308,0.00479254,0
150.7,240.4025192,1.940287009,1.7977E+308,0.003485483,0
150.9,240.1440771,1.821235632,1.7977E+308,0.001307056,0
151.1,239.742702,1.70219508,1.7977E+308,0.009585079,0
151.3,239.4427096,1.58314685,1.7977E+308,0.023962697,0
151.5,238.8659924,1.464119579,1.7977E+308,0.037904629,0
151.7,238.6997919,1.345061215,1.7977E+308,0.041390111,0
151.9,237.9410845,1.226047728,1.7977E+308,0.037033255,0
227.1,237.5920082,1.113510206,1.7977E+308,0.009149393,0
227.3,237.4116806,0.994452912,1.7977E+308,0.011327819,0
227.5,236.9288671,0.875418529,1.7977E+308,0.020041526,0
227.7,236.7518635,0.756360983,1.7977E+308,0.030933659,0
227.9,236.2881631,0.637325152,1.7977E+308,0.043568532,0
228.1,235.7762644,0.518292972,1.7977E+308,0.051846551,0
228.3,235.0898546,0.399274008,1.7977E+308,0.048796752,0
228.5,234.4491501,0.280251583,1.7977E+308,0.04051873,0
228.7,233.5275659,0.161250431,1.7977E+308,0.02744817,0
228.9,233.1029229,0.042211642,1.7977E+308,0.013070557,0
228.96,233.044171,0.006494806,1.7977E+308,0.010892131,0
,,,,,