File: Test_6.csv
Time On Sample,Displacement Into Surface,Load On Sample,Harmonic Contact Stiffness,Harmonic Displacement,Harmonic Load
0,0,0,495.7567659,0.294507139,2.243372095
0.2,0.127444476,0.000749397,5615.606455,0.199968607,2.302207519
0.4,0.248241275,0.001499297,15915.79764,0.141154312,2.418788791
0.6,0.056597404,0.00227134,21141.35787,0.123292191,2.521205946
0.8,0.294559995,0.003009532,23865.69016,0.113271979,2.620354531
1,0.486819796,0.003751184,24799.87362,0.113271981,2.71732401
1.2,0.541971219,0.004503214,25424.12091,0.113707643,2.805577124
1.4,0.725921425,0.005245495,28607.86705,0.112836321,3.157500036
1.6,0.822620843,0.005994381,30176.88795,0.117628598,3.496348409
1.8,0.984966096,0.006738298,31509.23278,0.122856538,3.835196784
2,0.805786825,0.007508064,32141.56338,0.12982712,4.162060122
2.2,0.59835492,0.008279968,32707.40245,0.141154316,4.601146502
2.4,0.705025857,0.009028099,33831.37993,0.155095484,5.242888272
2.6,1.055168049,0.009757803,35545.1837,0.162501733,5.748437033
2.8,0.688191838,0.010541783,37769.05651,0.171214959,6.358581857
3,0.695978547,0.011297399,40226.95,0.177314219,6.970905886
3.2,0.894886035,0.012038549,42546.22075,0.183413483,7.61918497
3.4,1.035626331,0.012784101,45500.21175,0.193433699,8.58343193
3.6,0.814899063,0.013557012,46191.18002,0.210424494,9.480127005
3.8,0.997187355,0.01429942,45869.34529,0.231336248,10.35830001
4,0.861633478,0.015065885,45139.48119,0.254426304,11.22230877
4.2,1.04558369,0.015808168,44041.61887,0.278387689,11.98934822
4.4,1.185908508,0.016553752,43727.94698,0.309319658,13.26084683
4.6,1.15921038,0.017311978,43730.89291,0.335459347,14.42883857
4.8,1.406313552,0.018049481,43605.13329,0.356371105,15.33207118
5,1.068420928,0.018831261,42270.91949,0.392095338,16.43577957
5.2,1.036737041,0.019589864,40802.35522,0.428255241,17.34554925
5.4,1.058234589,0.020344442,39013.59706,0.482712928,18.6911368
5.6,1.130420693,0.021095184,37387.94322,0.534556646,19.80029323
5.8,0.930051941,0.021866555,35882.96267,0.583786388,20.69589867
6,1.129374913,0.022607674,34381.20949,0.641293713,21.72769757
6.2,1.301276211,0.023350868,33056.56272,0.691830455,22.54049801
6.4,1.390912475,0.024100289,31159.32219,0.765892915,23.60498317
6.6,1.274886153,0.024865277,29160.66152,0.844747638,24.49078278
6.8,1.402331095,0.025611837,27577.98938,0.912275177,25.14233059
7,1.414272604,0.02636714,25577.87034,1.005071082,25.87886284
7.2,1.489367071,0.027117662,24176.78284,1.082183174,26.47484374
7.4,1.162276921,0.027898625,23315.86059,1.140126125,26.97712338
7.6,1.495799931,0.028629587,22377.93299,1.208525012,27.57964207
7.8,1.213581618,0.029407154,21660.42716,1.262111353,27.9991164
8,1.416643915,0.030147991,20865.61136,1.327024935,28.49159078
8.2,1.458499983,0.030901029,20255.27212,1.378432997,28.87075243
8.4,1.561847089,0.031649414,19692.12841,1.427662758,29.19543689
8.6,2.165432106,0.032359937,19373.21184,1.469486326,29.59094239
8.8,2.371818259,0.033100524,19530.07985,1.47863524,29.96574608
9,2.231694088,0.033867337,20133.98666,1.460337442,30.43316054
9.2,2.235325998,0.03462327,21372.90148,1.413285999,31.0411265
9.4,1.732903273,0.035417505,23703.12173,1.326153647,31.91494043
9.6,1.515499831,0.036190167,26552.11882,1.232050742,32.8497695
9.8,2.116591969,0.036900879,28449.67744,1.181949719,33.55470579
10,1.855978602,0.037676811,29887.86118,1.158859638,34.39256525
10.2,1.794795633,0.03843765,29812.96203,1.18064271,34.9547701
10.4,2.552108268,0.039136539,28753.52513,1.236843111,35.40039521
10.6,2.629695622,0.039886875,27154.92489,1.320490135,35.81006403
10.8,2.421432725,0.040658847,26561.35138,1.362749286,36.16525517
11,2.871290174,0.041381008,26444.56549,1.384096745,36.56076076
11.2,2.626465033,0.042155747,27327.80625,1.367105922,37.22756172
11.4,2.722333508,0.0429047,28869.68791,1.319618824,37.84860239
11.6,2.647024215,0.043666609,31030.95254,1.257754878,38.67447702
11.8,2.638191725,0.044423486,32621.13464,1.218981001,39.36415882
12,2.493912751,0.045190615,34176.06446,1.18804902,40.17042155
12.2,2.612217146,0.04593787,35182.02616,1.174107861,40.85901405
12.4,2.618341936,0.046693615,35426.8472,1.182821093,41.50184547
12.6,2.661859929,0.047446531,35384.56965,1.20329719,42.19697505
12.8,2.360529509,0.048225546,35171.77833,1.228565535,42.82237312
13,2.730614794,0.048953744,34881.39604,1.253398276,43.31157944
13.2,2.64782686,0.04971622,34517.62627,1.28171627,43.81821751
13.4,2.495238284,0.050483978,34159.83396,1.314826534,44.4523323
13.6,2.600247319,0.051232239,33921.62929,1.34183756,45.01235842
13.8,2.612188831,0.051987544,33725.40555,1.362749316,45.45362404
14,2.612496901,0.05274373,33619.86162,1.382789748,46.00820227
14.2,2.828854584,0.053483564,33517.61381,1.400216232,46.47125928
14.4,2.612282082,0.054256166,33446.12825,1.416335689,46.94085261
14.6,2.55691583,0.055016565,33327.57029,1.435940454,47.47581895
14.8,2.837257437,0.055751556,33386.06524,1.445525037,47.89965245
15,2.746990862,0.056514598,33421.47824,1.459466199,48.41391733
15.2,2.528756441,0.057287325,33580.16667,1.465565439,48.844287
15.4,2.824886288,0.058021121,33806.42473,1.470357747,49.30952337
15.6,3.133480543,0.058753974,34016.15253,1.476892703,49.8510277
15.8,3.013299404,0.059519281,33954.45412,1.491269523,50.24326362
16,3.262064537,0.060256663,33784.81512,1.512181306,50.6921567
16.2,3.316385013,0.061008762,33348.48188,1.540934976,51.01793066
16.4,3.432196537,0.061756207,32760.13037,1.574480931,51.30557062
16.6,3.334450716,0.0625236,31875.66682,1.623710678,51.55616593
16.8,3.293210782,0.063282932,31164.17945,1.663355878,51.72177662
17,3.8361358,0.063998051,30483.3036,1.701694161,51.92007496
17.2,4.08573251,0.064731588,30497.07283,1.70648647,52.1597755
17.4,4.47908473,0.065458028,31418.24588,1.672940574,52.63372853
17.6,4.047293526,0.066246922,32978.71704,1.612383563,53.15997749
17.8,4.222934187,0.066989841,36133.04515,1.501289875,54.0414197
18,4.342069559,0.067737036,39484.30341,1.401523381,54.87601128
18.2,4.05071062,0.068515301,42968.82276,1.314826696,55.7901386
18.4,3.936346193,0.06928017,46352.70391,1.24729914,56.87205636
18.6,3.734730955,0.070051641,47848.31898,1.226387367,57.61948364
18.8,3.352797377,0.07083676,47686.95997,1.24729909,58.3451193
19,3.471932742,0.071583954,45419.67578,1.319618924,58.84631031
19.2,3.329315676,0.072350959,42543.23981,1.411107842,59.09145763
19.4,3.618797863,0.07308526,38666.04081,1.546598624,59.14593542
19.6,4.520697685,0.07377321,34860.98979,1.699515948,58.94873038
19.8,4.575849127,0.074525249,32617.51222,1.801896435,58.77004515
20,4.575326238,0.075281502,31550.72331,1.854611491,58.74716492
20.2,4.620506159,0.076034296,32121.2882,1.829343125,59.00865575
20.4,4.386483464,0.076808222,34153.00768,1.741339451,59.57739739
20.6,4.688429525,0.077545051,38456.68419,1.582322998,60.63098824
20.8,4.594837352,0.078319319,42521.586,1.461209059,61.59414547
21,4.529496588,0.079099243,46947.05777,1.355343281,62.74034648
21.2,4.700978237,0.079869009,49423.73536,1.308727505,63.58692313
21.4,4.409613809,0.080681751,50831.29678,1.293914985,64.53591585
21.6,4.755179105,0.08145413,50679.25698,1.312212803,65.22069595
21.8,4.699804853,0.082264805,50190.74406,1.337916836,65.83247506
22,4.459956153,0.083097562,49562.46328,1.368413122,66.48293239
22.2,4.523406599,0.083915646,49215.78774,1.388453565,67.02443638
22.4,4.507914512,0.084747989,48858.64013,1.412414953,67.75007318
22.6,4.912471489,0.085556772,48670.64873,1.427663149,68.25780241
22.8,4.538001946,0.086432997,48660.27351,1.441168623,68.92896078
23,4.590229095,0.087285494,48699.91059,1.452931494,69.57724013
23.2,4.762528626,0.088137496,48648.87004,1.46600136,70.10458042
23.4,4.57460555,0.089025358,48668.45374,1.481249496,70.80079893
23.6,4.75396548,0.089894198,48608.84136,1.496497677,71.40876557
23.8,4.798292976,0.090782099,48345.54929,1.51435981,71.84131504
24,4.8604847,0.091677559,48079.18948,1.53483591,72.39153541
24.2,4.84414925,0.092587989,48051.30084,1.546163113,72.87638281
24.4,4.928358539,0.0934999,47959.81726,1.561411285,73.46037955
24.6,4.553045348,0.094455995,48192.93808,1.566639184,74.0345685
24.8,4.760233771,0.095377295,48617.78185,1.564025235,74.54665478
25,4.449732498,0.096347226,49314.28379,1.555747635,75.19384361
25.2,4.670213271,0.097286469,49644.08061,1.556618983,75.72881097
25.4,4.522577149,0.098263226,50100.09356,1.556183306,76.4054177
25.6,5.008962134,0.099201555,50235.16192,1.560975638,76.88699862
25.8,4.799831899,0.100202184,50208.38129,1.57273848,77.45682961
26,4.822537978,0.101195222,49971.98271,1.590164949,77.97545306
26.2,5.005617782,0.102186153,49922.49187,1.600185187,78.40146572
26.4,4.980955953,0.103202761,49980.21502,1.610205403,78.98001411
26.6,4.800071971,0.104241474,50235.58649,1.611512369,79.43108487
26.8,4.893403208,0.1052698,50577.46873,1.61151238,79.98348445
27,4.993380504,0.106307841,51039.96937,1.609334084,80.5914511
27.2,5.120777808,0.10735437,51486.55785,1.605848807,81.0991793
27.4,4.900001107,0.108437794,51912.43414,1.605413121,81.73220402
27.6,5.494394697,0.109470127,52106.81075,1.609334144,82.2007109
27.8,5.276107475,0.110574725,52446.0479,1.611512428,82.78470585
28,5.210715193,0.111678719,52974.75696,1.608027129,83.399209
28.2,5.395440184,0.112774836,53354.08676,1.606720166,83.90802716
28.4,5.271877171,0.113905344,53794.09027,1.604541845,84.46696317
28.6,5.291237522,0.115036339,54523.52952,1.595828615,85.14248108
28.8,5.436071054,0.116169247,55058.11781,1.590600692,85.7057762
29,5.424682259,0.117325323,55598.40661,1.587115399,86.38347334
29.2,5.674213145,0.118473208,56101.04334,1.582758811,86.95112729
29.4,5.322957915,0.119678248,56713.5877,1.578402156,87.70182231
29.6,5.847532897,0.120828893,57028.99207,1.578402215,88.25422377
29.8,5.474668926,0.122059286,57492.22105,1.576223867,88.93300873
30,5.629462784,0.123261898,57951.67974,1.5749169,89.62595998
30.2,5.662934502,0.124485922,58303.31062,1.575352566,90.19906074
30.4,5.721333086,0.125720274,58828.61423,1.57448125,90.94757812
30.6,5.783884507,0.126966675,59249.96122,1.574045596,91.51305265
30.8,5.809871677,0.128228426,59588.00061,1.577966555,92.20055537
31,6.113397561,0.129481867,59851.79064,1.58319453,92.87062686
31.2,6.062101379,0.130774913,60041.49222,1.587551142,93.4252049
31.4,5.958452649,0.132084825,60126.22089,1.59495738,94.00593187
31.6,6.300196571,0.133374001,60490.76419,1.596264404,94.68036189
31.8,6.309554283,0.134701511,61083.3045,1.592779112,95.40273029
32,6.524157095,0.136026673,61544.34674,1.592779137,96.10875625
32.2,6.622423329,0.137374075,61838.39129,1.594957457,96.66660373
32.4,7.506775976,0.138675047,62445.51604,1.591036601,97.33340973
32.6,7.65905042,0.140044923,63006.7377,1.588858311,98.06449486
32.8,7.378392302,0.141461456,63640.61254,1.585808648,98.85441388
33,7.370286938,0.142871501,64489.48837,1.575352767,99.5114094
33.2,7.377136618,0.144294525,65731.29754,1.557490639,100.2904343
33.4,7.597540855,0.145715595,67129.94701,1.540064195,101.2764736
33.6,7.697453526,0.147160334,68245.29836,1.529608325,102.2221988
33.8,7.647791046,0.148630753,68900.4978,1.526123027,102.9554625
34,7.674574561,0.150110239,69274.83113,1.530043986,103.7813378
34.2,7.571725895,0.151614388,69515.55561,1.535271917,104.4906313
34.4,7.892663445,0.153108991,69599.42438,1.545727834,105.3698957
34.6,8.196150862,0.154604742,69976.36126,1.546599191,106.0366988
34.8,8.963310618,0.156088028,70391.80134,1.549213245,106.8887271
35,9.066530588,0.157636662,71170.54349,1.54485664,107.7908708
35.2,8.865616539,0.159223971,71605.23932,1.545292281,108.5241334
35.4,8.972155359,0.160803748,72414.66258,1.540064352,109.3718004
35.6,9.1385208,0.16239494,72931.53047,1.542678341,110.3175264
35.8,9.141184459,0.16401469,73184.41465,1.547470622,111.0300888
36,9.07404487,0.165655877,73180.97357,1.559233484,111.8657694
36.2,9.222121431,0.167297214,73269.84575,1.567511075,112.5619897
36.4,9.128385849,0.16897349,73217.03527,1.580580919,113.4379834
36.6,9.378665254,0.170640412,73466.06516,1.584501903,114.1385625
36.8,9.466073735,0.172336467,74051.36118,1.584066252,115.0287215
37,9.342415537,0.174065569,74571.04264,1.583194916,115.7619845
37.2,9.625094252,0.175781337,75036.78395,1.58363061,116.5279363
37.4,9.490628056,0.177545916,75597.78793,1.582759272,117.3287511
37.6,9.655304835,0.179305514,76215.63954,1.582759292,118.2701192
37.8,9.454356172,0.181110522,76679.24814,1.583194932,119.019725
38,9.386358314,0.182923565,77320.66389,1.58188794,119.9501964
38.2,9.574293409,0.184735355,77871.38663,1.5814523,120.7510128
38.4,10.09627177,0.186539938,78235.5455,1.584501991,121.5267722
38.6,9.744076705,0.188429223,78361.19427,1.594086513,122.4125706
38.8,9.707643672,0.19031331,78238.41448,1.605413717,123.0499542
39,10.03599932,0.192188604,77926.42856,1.622404565,123.7995632
39.2,9.910647486,0.194117308,77514.4882,1.6389597,124.3988123
39.4,10.48039113,0.196012386,77275.70702,1.653772268,125.1658555
39.6,10.71525463,0.197952015,77360.00498,1.659000233,125.7487635
39.8,10.77644426,0.199924356,77359.04689,1.667277818,126.4733113
40,11.00756219,0.201903596,77422.79509,1.672505786,127.0649356
40.2,11.52286549,0.203881198,77984.23263,1.668584888,127.7655164
40.4,11.10167299,0.205949786,78713.92606,1.663792562,128.6436872
40.6,11.24179113,0.207996421,79443.26223,1.657693313,129.3595194
40.8,11.30338019,0.210069675,81047.76063,1.638524202,130.3815134
41,11.37950776,0.212162657,82339.35239,1.62414737,131.2248217
41.2,11.4701738,0.214275567,83462.97093,1.613255838,132.0648617
41.4,11.25296553,0.216433141,84539.16318,1.606720885,133.1467787
41.6,11.4204886,0.218583159,84835.5237,1.610641861,133.8822228
41.8,11.41849227,0.220767609,84635.76109,1.624583043,134.7070086
42,11.45928692,0.222970775,84568.29333,1.633731944,135.3770792
42.2,11.58649796,0.225189509,84604.88613,1.641573878,136.082017
42.4,11.6829599,0.227432993,85093.41384,1.643316538,137.0353689
42.6,11.75615137,0.229700742,85552.28389,1.642445217,137.7653644
42.8,11.68641397,0.232002104,86097.10568,1.642445217,138.694747
43,11.66486863,0.23432292,86312.45657,1.64810882,139.528249
43.2,11.81449748,0.236654023,85968.27333,1.662485679,140.2059467
43.4,12.00068487,0.239005854,85471.26324,1.679040853,140.7627058
43.6,11.97580449,0.2413973,85063.37657,1.696031664,141.4240597
43.8,12.20934907,0.243793169,84894.17238,1.706487578,141.9524905
44,12.18778488,0.246232544,84662.69953,1.719557433,142.6007701
44.2,12.39306908,0.24867911,84887.14406,1.723042754,143.2348869
44.4,12.39559497,0.251165631,85454.36953,1.719121798,143.8602862
44.6,12.34992116,0.253680761,86080.53021,1.715200837,144.6338627
44.8,12.37819883,0.256215668,86644.32653,1.710844222,145.2799635
45,12.50037103,0.258768765,87485.3466,1.703002324,146.1308993
45.2,12.64248218,0.261346151,88403.3116,1.69341778,146.9131936
45.4,12.64000205,0.263960457,88888.40891,1.691675134,147.6519054
45.6,12.50622598,0.266610832,89332.58231,1.692546443,148.4810486
45.8,13.25991173,0.269220515,89593.71065,1.695596166,149.1315126
46,13.5399457,0.271892426,89875.32143,1.699952819,149.9116291
46.2,13.9537601,0.274581004,90198.04137,1.702131179,150.5915082
46.4,14.14819656,0.277313225,91007.81564,1.696031936,151.3683557
46.6,14.07339734,0.280093419,92593.98924,1.679041113,152.4121396
46.8,14.44731254,0.282867407,94711.30404,1.653772765,153.5561654
47,14.34923754,0.285705195,96350.28261,1.636346276,154.5062481
47.2,14.64835731,0.288541256,97856.07139,1.622405129,155.5293335
47.4,14.8976149,0.291409631,99265.49029,1.613256257,156.7844918
47.6,15.30807432,0.294294553,99870.57368,1.612820642,157.6681159
47.8,15.51909853,0.297223671,100363.468,1.616305963,158.7336936
48,15.52653265,0.300197562,100681.1693,1.619791261,159.591166
48.2,15.79737662,0.303181422,100980.6295,1.62371225,160.4595354
48.4,15.75577451,0.306219031,101477.3217,1.627197542,161.6318863
48.6,15.79477076,0.309281023,101927.0795,1.628940196,162.5122391
48.8,15.89192939,0.31236932,102178.1234,1.635039476,163.538592
49,15.99157596,0.315488557,102613.4471,1.636782136,164.4004234
49.2,15.91006809,0.318652747,103506.9721,1.632425508,165.3766556
49.4,16.19002319,0.321821187,104466.6532,1.628068921,166.4193527
49.6,16.38936999,0.325027738,105417.5269,1.625019311,167.5917058
49.8,16.32612801,0.328286472,106384.9232,1.62196967,168.7716826
50,16.65260152,0.331548319,106810.558,1.624148018,169.6912618
50.2,16.28355548,0.334895822,106818.3049,1.631989894,170.5618062
50.4,16.65239747,0.338220717,106401.3541,1.64767377,171.5827137
50.6,16.73787642,0.341600749,105963.6306,1.661179303,172.3268731
50.8,17.08759558,0.344994648,105745.002,1.673377882,173.2671536
51,16.92793021,0.348461424,106127.4275,1.675556175,174.0821328
51.2,17.07737682,0.35193941,106664.7896,1.675991855,174.9363377
51.4,16.9193623,0.35547572,107665.2458,1.67207088,176.1032395
51.6,17.45768746,0.358994717,108840.5374,1.663357702,177.055507
51.8,17.65697492,0.362574715,109883.0024,1.658565444,178.2333074
52,17.6692875,0.366223317,110208.4618,1.661615081,179.1005862
52.2,17.90512567,0.369873419,110857.8848,1.660308123,180.0365074
52.4,17.98058546,0.373553894,111312.1053,1.663793429,181.2001432
52.6,17.84663423,0.377305913,111443.7677,1.669457022,182.0173012
52.8,18.21374654,0.381057467,112051.4835,1.67032839,183.1003133
53,18.08476908,0.384884517,112318.8185,1.673813672,183.9283668
53.2,17.90094212,0.388753891,112341.5369,1.680784245,184.7520616
53.4,18.58629429,0.392596051,112904.8236,1.682962637,185.8808372
53.6,18.56532337,0.396530645,113171.4916,1.686447932,186.7219668
53.8,18.66982128,0.400495331,112980.4604,1.698210822,187.6360958
54,18.88399972,0.404491513,113186.7784,1.702567469,188.4183917
54.2,18.87298132,0.40854502,113512.1925,1.705617104,189.230103
54.4,19.11872343,0.412619704,113660.5915,1.712587728,190.2335769
54.6,18.97556924,0.41676481,114290.5787,1.71215205,191.2370478
54.8,19.63760979,0.420890291,115164.7622,1.706488522,192.1097793
55,20.53148195,0.425039694,116312.122,1.699518036,193.2549007
55.2,20.73897352,0.429283137,116836.9809,1.699082399,194.143972
55.4,20.76364686,0.433582957,117360.3099,1.699082403,195.0711757
55.6,20.93290061,0.43791488,117780.7912,1.70213206,196.1280364
55.8,21.21598912,0.442281719,117856.9736,1.707795702,196.9212288
56,21.19244594,0.446715855,117868.0372,1.713894971,197.6882686
56.2,21.68907746,0.451154879,118454.6645,1.713023707,198.5784328
56.4,21.56538931,0.45568557,119874.3381,1.703874788,199.8477517
56.6,21.51149471,0.460256204,120987.4867,1.696468523,200.8076418
56.8,21.80742752,0.46484618,122248.9975,1.689933627,202.029025
57,21.98369457,0.469491355,123393.4585,1.683398716,203.0194239
57.2,22.16909476,0.474182642,124371.5547,1.679477779,204.0697478
57.4,22.06448197,0.478943055,125226.4002,1.679042105,205.3575901
57.6,21.93867207,0.483752793,125565.9182,1.682091724,206.2651807
57.8,21.99525049,0.488597105,126680.283,1.677299448,207.4920097
58,22.31689785,0.49346988,127402.2678,1.677299488,208.6970505
58.2,22.67302231,0.498389056,127786.2967,1.680349163,209.6678395
58.4,22.78068148,0.50337657,128178.2848,1.683834477,210.674581
58.6,23.35657942,0.508378596,128312.7109,1.6912408,211.7793865
58.8,23.28764333,0.51347994,128079.2188,1.700825363,212.5823812
59,23.64622876,0.518599947,128269.8885,1.706924678,213.6359759
59.2,23.58517048,0.523803367,128328.7487,1.71302395,214.5185075
59.4,23.88972696,0.529031006,128590.1426,1.716509283,215.4380875
59.6,23.87684785,0.534335184,129306.1038,1.715637961,216.5625
59.8,24.17307791,0.539669249,129714.2507,1.716944981,217.4330492
60,24.36709121,0.545064598,129683.442,1.724786923,218.4517768
60.2,24.36332706,0.550529215,129879.1722,1.728272229,219.3070711
60.4,24.31634418,0.556052026,130079.6815,1.733500165,220.3650191
60.6,24.68649516,0.561598549,130490.1337,1.734371542,221.2028839
60.8,24.75998401,0.567223458,131062.2199,1.734807214,222.2858944
61,25.05533063,0.572887901,131970.0132,1.730014966,223.2294444
61.2,25.40966646,0.578604804,133193.1149,1.722608751,224.2558004
61.4,25.46650893,0.584401868,134511.5157,1.716073824,225.5763317
61.6,25.51752542,0.590257481,135070.1638,1.716073831,226.499177
61.8,25.79704696,0.596154765,136033.6088,1.713459892,227.7281881
62,25.58961564,0.602148173,136851.7454,1.711281557,228.7240312
62.2,25.84252745,0.608166772,137074.2393,1.715202549,229.6294468
62.4,26.03726235,0.614250201,137719.6621,1.716945223,230.9031282
62.6,26.38737734,0.620383041,138127.3995,1.718687915,231.8183511
62.8,26.50564426,0.626595083,137822.5488,1.730450814,232.8338094
63,26.62473223,0.632869428,137114.0668,1.744392024,233.5322101
63.2,26.83355402,0.639200099,136671.8768,1.755719272,234.2741932
63.4,26.98336743,0.645598832,136010.131,1.770531812,235.1382052
63.6,27.26944832,0.65205158,135860.0713,1.777502446,235.8039211
63.8,27.57463104,0.658567652,136695.5655,1.774017186,236.7845164
64,27.77344027,0.665157216,138155.4255,1.763125652,237.7520353
64.2,28.26639942,0.67179059,139857.5939,1.750055842,238.816528
64.4,28.22337767,0.678531509,142335.4243,1.731322355,240.2939522
64.6,28.18449998,0.685339735,144372.9377,1.71650983,241.493542
64.8,28.4173359,0.692195659,145875.365,1.709103599,242.8227908
65,28.4407585,0.699136525,146729.3475,1.706925291,243.8916368
65.2,28.8381028,0.706118626,147239.6131,1.708667989,244.9637542
65.4,29.16729712,0.713175968,147206.6605,1.71781694,246.2156467
65.6,29.32530202,0.72031736,146867.1857,1.727401534,247.0480617
65.8,29.494929,0.72752959,147004.9661,1.733500829,248.1779236
66,29.96036687,0.734791681,146978.8753,1.739600161,249.0136113
66.2,30.54046587,0.742118171,147800.5828,1.73916457,250.2807609
66.4,30.3494206,0.749576842,148719.551,1.735679249,251.2820515
66.6,30.46831219,0.757086909,150029.9393,1.730015652,252.5851505
66.8,30.73011723,0.764661476,150538.827,1.73088701,253.5167163
67,31.0567252,0.77230723,151465.9935,1.7291444,254.7696989
67.2,31.78883037,0.779999071,151579.5997,1.73437244,255.7437617
67.4,32.03979633,0.787804758,151414.7423,1.742650059,256.6873126
67.6,31.87277597,0.795720594,151737.7125,1.746571003,257.8062744
67.8,32.2117988,0.803677459,152213.8242,1.74744237,258.750916
68,32.40788348,0.811725109,152986.0058,1.74657107,259.9374344
68.2,32.53581642,0.819858819,153905.1386,1.74352145,261.0051915
68.4,32.76262084,0.828066797,154548.4216,1.743085816,262.0620545
68.6,32.79829088,0.836371848,154887.0607,1.746571122,263.2431231
68.8,32.79655439,0.844763078,155086.9417,1.750056423,264.1616107
69,33.07151483,0.853217654,155081.0298,1.756591396,265.2250117
69.2,33.36391197,0.861755843,155081.5644,1.761819384,266.1228024
69.4,33.76764439,0.870371391,155680.7843,1.761819435,267.1393541
69.6,33.97193218,0.879088612,156202.7186,1.763562111,268.2561421
69.8,34.70884567,0.887897387,156381.6998,1.767483166,269.1168933
70,34.78265149,0.89675623,156582.3367,1.772711128,270.1399783
70.2,34.88967452,0.905746359,157116.184,1.773582468,271.0715421
70.4,34.8388004,0.914838797,157409.7435,1.776632101,271.9715079
70.6,35.11697276,0.923997492,158405.1616,1.773146836,273.1057293
70.8,35.6361095,0.933230054,159903.4705,1.763562323,274.1669541
71,35.83448013,0.942579661,162400.9297,1.746135844,275.6607257
71.2,36.08684838,0.952019062,164409.2876,1.733065996,276.9518413
71.4,36.27023168,0.961558695,165987.4546,1.724788429,278.2614793
71.6,36.38047509,0.971199576,167673.168,1.717817841,279.8064579
71.8,36.73832983,0.98091855,168496.8261,1.717382223,280.9690099
72,37.05628287,0.990738248,168331.7603,1.726966841,282.162068
72.2,37.66173319,1.000634724,167932.7611,1.73742282,283.1383093
72.4,37.74199955,1.010670576,167954.476,1.743957771,284.1722906
72.6,38.27180051,1.020772936,167423.9166,1.756156393,285.270561
72.8,38.82485227,1.03097521,166882.2537,1.766612367,286.0855497
73,39.6263455,1.041261166,166511.206,1.776197048,287.0607053
73.2,39.69740639,1.051705968,166791.7064,1.778811034,287.9966272
73.4,40.21550842,1.062221475,167326.9447,1.7788111,288.9892111
73.6,40.0098254,1.072897624,168783.4524,1.771404809,290.3119185
73.8,40.56653339,1.083622882,170390.1639,1.762255957,291.5632707
74,40.78128311,1.094482539,172525.5522,1.749186104,292.9638867
74.2,40.86804729,1.105460942,174640.4722,1.736551895,294.3476127
74.4,41.20532912,1.116530583,176092.1731,1.730888317,295.7836403
74.6,41.78232598,1.127693154,177084.765,1.72914574,297.1368654
74.8,41.82499612,1.139008533,178047.1213,1.727620921,298.4879045
75,42.4061119,1.150396725,178398.5221,1.730888466,299.7212802
75.2,42.31412985,1.161950473,178687.2284,1.734373757,300.8478704
75.4,42.65713825,1.173587146,178953.4508,1.738730429,302.0343919
75.6,43.06826699,1.185335691,179527.5039,1.740908795,303.401779
75.8,43.37467571,1.197210141,180602.5806,1.738730518,304.85415
76,43.9004396,1.209187249,181968.3542,1.733066967,306.1311071
76.2,43.80836364,1.22133168,183237.1478,1.728274664,307.4483681
76.4,43.98674663,1.233577566,184941.3488,1.721739744,309.1992738
76.6,44.15223013,1.245947552,186004.0301,1.719561453,310.5100007
76.8,44.45189443,1.258431099,186509.0853,1.723918118,312.0114011
77,44.91066817,1.271027889,186158.5953,1.733067096,313.036672
77.2,45.61040101,1.283732847,186029.272,1.740909114,314.1458417
77.4,46.04503647,1.296585634,186145.2287,1.747879777,315.5263047
77.6,46.34669737,1.309577627,186367.7647,1.751800782,316.6114984
77.8,46.74472924,1.322692726,187115.9793,1.752672152,318.0268264
78,47.05964387,1.335945994,187934.1366,1.751800874,319.1643191
78.2,46.99811118,1.349361006,188769.1394,1.750929541,320.3050751
78.4,47.54980767,1.362864074,189599.7026,1.752672253,321.8413441
78.6,48.10148257,1.376503058,190015.6138,1.755286309,322.9221838
78.8,48.08725,1.3903219,190980.5386,1.754850645,324.3799989
79,48.78346864,1.404225635,192173.6793,1.750929765,325.5937652
79.2,49.15475859,1.418293823,193817.3765,1.743959202,326.99384
79.4,49.56591231,1.432500242,196611.6544,1.729582372,328.9375984
79.6,50.25957078,1.446827914,198850.1323,1.718255217,330.4618866
79.8,50.56930147,1.461328779,201047.7412,1.709541994,332.3293757
80,51.27454742,1.475945258,202382.2753,1.705621111,333.7839331
80.2,51.23439614,1.490765411,203544.585,1.705185444,335.6143721
80.4,51.71191124,1.505694897,204060.535,1.708670807,337.0776427
80.6,51.87529845,1.520798242,204276.3144,1.715205775,338.6836382
80.8,52.55635158,1.536013963,204721.8187,1.7182555,340.024883
81,53.21993021,1.551383909,205505.5117,1.72086956,341.7071553
81.2,53.47049559,1.566939798,205987.4795,1.723483571,343.0287804
81.4,53.81327307,1.582644816,206190.499,1.728275908,344.3972586
81.6,54.26986742,1.598499074,207172.4382,1.728711628,346.0708109
81.8,55.0928913,1.614484702,207586.3297,1.731761371,347.3347
82,55.37160871,1.630672302,208213.1668,1.734375386,348.9363403
82.2,55.85222436,1.647007212,209183.7142,1.733504118,350.3407756
82.4,55.90154394,1.663539104,210603.3454,1.731325809,352.1625003
82.6,56.59400278,1.680188169,211632.4198,1.729583241,353.599626
82.8,57.13436877,1.697016022,213273.5347,1.724791011,355.3973886
83,57.76611388,1.714005992,214241.1986,1.723484099,356.8181706
83.2,58.03386986,1.731194439,214966.868,1.724791122,358.2629154
83.4,58.41211655,1.748547124,216312.192,1.723919843,360.1925113
83.6,59.24154873,1.766039905,216636.8874,1.728276577,361.5097889
83.8,59.4510542,1.783755491,216793.0654,1.735247218,363.0918164
84,59.63809537,1.801650722,217500.9436,1.738296885,364.7294101
84.2,60.16331014,1.819700117,217590.1226,1.743524911,366.0281612
84.4,60.73503005,1.837927458,217526.7568,1.74962427,367.3421659
84.6,60.85800051,1.856371922,217892.0721,1.753545257,368.8620878
84.8,61.75539968,1.874942719,217371.6794,1.762258637,369.942936
85,62.12095244,1.893740649,216945.1274,1.771407616,371.284176
85.2,62.61278169,1.912717758,217134.512,1.775764313,372.4445537
85.4,63.10707353,1.931885372,218091.6426,1.775328712,373.7618261
85.6,63.41935371,1.951259413,219653.3968,1.771407781,375.3798108
85.8,63.77148921,1.970825107,222742.4433,1.75703093,377.2298709
86,64.10448131,1.990588808,224951.8135,1.747882038,378.7704969
86.2,64.68590006,2.010532154,227558.2217,1.736554858,380.4930843
86.4,65.01882878,2.030694723,230021.2946,1.728277293,382.6950681
86.6,65.38080905,2.05105765,231433.1472,1.724792029,384.2727406
86.8,66.15242203,2.071594058,232223.4812,1.726534778,386.0781353
87,66.4586624,2.092372261,233918.4017,1.722613844,388.0589407
87.2,66.95100553,2.113345072,235047.8071,1.721306914,389.6987205
87.4,67.53970702,2.134521231,236808.5741,1.716950349,391.5084715
87.6,67.88903981,2.156036933,238151.9986,1.716514729,393.4718443
87.8,68.59651815,2.177525291,238622.8119,1.720000124,394.9667179
88,69.18594801,2.199347271,238439.6699,1.729149134,396.6893056
88.2,70.02130842,2.221369915,238368.9425,1.736119855,398.1471379
88.4,70.47605211,2.243642677,238337.0928,1.743526195,399.8817065
88.6,71.28142716,2.266112569,239435.1161,1.741783639,401.3940169
88.8,72.11751206,2.2888058,242178.2346,1.730892148,403.5142937
89,73.10064145,2.311715951,245030.7747,1.718693681,405.4395469
89.2,73.17715215,2.334925223,247315.94,1.711287408,407.3952875
89.4,73.79956941,2.358326094,249924.8721,1.704316862,409.8228148
89.6,74.39452747,2.381964335,252017.4981,1.70039596,412.0607593
89.8,75.21796306,2.405822569,253601.6715,1.698653403,413.9206358
90,75.47048796,2.429963886,255526.1944,1.696475115,416.2021568
90.2,76.61792313,2.454279822,256921.2408,1.695603925,418.1078005
90.4,76.64019347,2.478925583,258825.819,1.692118617,420.1997356
90.6,76.95409301,2.50379687,259241.0504,1.698217951,422.3614064
90.8,77.95183674,2.528866005,258301.2214,1.709980997,423.8355867
91,78.21247482,2.554243035,256475.9277,1.728278916,425.4829901
91.2,78.65339175,2.579861149,255904.1105,1.737863578,426.9331901
91.4,79.01574153,2.605743103,254624.6588,1.753111862,428.5925789
91.6,79.67885919,2.631862461,254969.1892,1.756597257,430.010096
91.8,80.3697725,2.658242082,256772.3976,1.752676367,432.0541047
92,80.92644287,2.684897086,259484.5807,1.7422205,433.8910959
92.2,81.44318444,2.711822555,261606.9568,1.735685603,435.7248189
92.4,82.19587706,2.739000585,264284.7968,1.728279406,438.1872156
92.6,82.87830978,2.766457028,265846.6593,1.725665505,439.9730012
92.8,83.38494958,2.794202749,267366.3483,1.725229899,442.1640947
93,83.90982634,2.822225742,266812.9098,1.736121569,443.9520582
93.2,84.30544328,2.850540169,266766.1208,1.74265658,445.5068526
93.4,84.91581948,2.879122795,267122.2956,1.746577635,447.1346526
93.6,85.73929262,2.907976349,267776.8256,1.749627384,449.0849639
93.8,86.33711268,2.937137018,268485.2752,1.751587947,450.838062
94,87.3079896,2.966562108,270507.5956,1.746142269,452.8090783
94.2,88.33490983,2.996278057,272513.7774,1.74091442,454.6972902
94.4,89.00363676,3.026318914,274320.4213,1.739171843,457.038747
94.6,90.00054707,3.056636606,275267.5502,1.740043299,458.725392
94.8,90.74313359,3.087278398,275412.619,1.746578357,460.611419
95,91.36767413,3.11823698,275071.8524,1.75442039,462.0278477
95.2,92.08523338,3.149499577,274462.8705,1.76400509,463.4715173
95.4,92.64402831,3.181088392,274325.4641,1.772282793,465.3139586
95.6,93.38475429,3.212980679,274867.2806,1.774461204,466.7652557
95.8,93.90023771,3.245210408,276750.8399,1.770540292,468.7852929
96,94.54862418,3.277753823,278389.4437,1.766619395,470.4893644
96.2,95.05153971,3.310635308,280643.7303,1.760520154,472.6978928
96.4,95.55190984,3.343847385,282874.8007,1.753985252,474.6797957
96.6,96.57989022,3.3773529,286489.6779,1.742222437,477.2217412
96.8,97.13499759,3.411231127,289651.1407,1.731766557,479.3169573
97,97.96759348,3.445428636,294209.425,1.716518399,482.1726883
97.2,98.41207372,3.479999299,297947.7227,1.70475551,484.5991255
97.4,99.02435388,3.514904509,300897.7013,1.697784951,487.1203591
97.6,100.1659037,3.550120052,302333.9489,1.697349423,489.3016661
97.8,100.874464,3.585722421,302234.1684,1.705627137,491.7259309
98,101.2863126,3.621705004,301725.6318,1.715647475,493.8930579
98.2,102.1675996,3.658013384,301738.4394,1.721746888,495.7202538
98.4,103.1543614,3.694678657,302416.5449,1.724796661,497.7719014
98.6,103.8726626,3.731732606,303435.6681,1.726975073,500.1035563
98.8,104.7496192,3.769146931,306037.7765,1.721311538,502.6945296
99,105.9721981,3.80691075,307894.8596,1.717826368,504.8616739
99.2,106.7775717,3.845085712,309689.1069,1.714776812,507.1541078
99.4,107.5562934,3.883646243,312181.9436,1.710420258,510.0425264
99.6,108.1380145,3.922609157,314370.9715,1.706499345,512.2902843
99.8,108.7687005,3.961959862,316319.7367,1.706499422,514.97931
100,109.1965678,4.001721307,318358.6175,1.704756815,517.2401396
100.2,110.0830652,4.041847339,319369.4601,1.708677906,519.5020673
100.4,110.7451375,4.082393672,320139.9592,1.714341631,522.1605891
100.6,111.534283,4.123337692,320533.0299,1.718698377,524.0814885
100.8,112.8418865,4.164653646,321230.5891,1.722619521,526.5820394
101,113.7505599,4.206415007,321514.4668,1.728283277,528.9311338
101.2,114.7073629,4.248592329,322533.933,1.72959039,531.290037
101.4,115.4397374,4.29121044,322471.8469,1.735689791,533.1401135
101.6,116.6548358,4.334220124,322671.2416,1.742224917,535.4380072
101.8,117.5449574,4.377686611,322540.5866,1.748760004,537.1725968
102,118.629456,4.421575034,323297.4658,1.751809795,539.4138318
102.2,119.4521299,4.465924304,323519.513,1.75703788,541.2857033
102.4,120.2614376,4.510720193,324950.4664,1.75616665,543.3743941
102.6,121.0723357,4.555965974,325523.0468,1.760087739,545.6232479
102.8,121.6779127,4.601681912,325404.812,1.765751464,547.2870114
103,122.8193907,4.647816325,323361.2893,1.781871224,548.9758453
103.2,123.7862919,4.694427651,322737.2761,1.789713322,550.4772733
103.4,124.3791833,4.741535768,323708.2148,1.79145606,552.5572434
103.6,125.4165672,4.78908323,326051.2569,1.785356875,554.4846876
103.8,126.4696636,4.837107296,330619.7333,1.770108717,557.1704606
104,127.4321079,4.885620748,335031.7051,1.755296212,559.5642317
104.2,128.5540206,4.934609426,339489.4063,1.74179072,562.2009765
104.4,129.7007841,4.984088411,341443.3108,1.741355195,565.0894107
104.6,130.5998404,5.034083461,341485.8732,1.747454625,567.0059576
104.8,131.3758336,5.084590054,340950.5633,1.75747503,569.1131721
105,132.3129131,5.135848611,342435.6488,1.758346478,571.5341815
105.2,133.3513297,5.187358308,343946.58,1.757910941,573.6675555
105.4,134.6414471,5.239368296,347397.1605,1.749197787,576.1158128
105.6,135.348184,5.29168078,352775.5442,1.733949575,579.387758
105.8,136.2376083,5.34476945,357422.677,1.720444046,582.0506486
106,137.4659828,5.398365836,360255.297,1.716523203,585.0502206
106.2,138.6277945,5.452505646,362047.029,1.716087678,587.5998053
106.4,139.8435327,5.507185522,363304.9032,1.717394823,590.0807512
106.6,140.733444,5.56243942,364409.7275,1.720880259,592.9364935
106.8,141.5110865,5.61825696,363704.8955,1.731336336,595.4610087
107,142.6218582,5.674610025,364246.5748,1.734821799,597.5170276
107.2,143.469123,5.731549399,365187.2125,1.737435899,599.8356195
107.4,144.2556362,5.789065401,366929.3525,1.738742995,602.8144783
107.6,145.3436991,5.847136437,367967.3725,1.740485793,605.0568095
107.8,146.6119896,5.905777223,371363.1411,1.734386623,608.1239377
108,147.8253427,5.965011472,375723.8615,1.723495119,610.9328405
108.2,148.7884796,6.024859828,380411.2616,1.711732251,614.016305
108.4,149.9177148,6.085296711,384991.4552,1.702583398,617.8428487
108.6,151.2039067,6.146328828,387132.8924,1.700840888,620.5373488
108.8,152.3890385,6.207982176,388634.8253,1.703019362,623.7613725
109,153.2728452,6.270279998,387274.896,1.713911126,625.8468037
109.2,154.9617618,6.333141962,385212.767,1.728288318,627.975843
109.4,155.7298641,6.396706121,383418.526,1.742665402,630.5581071
109.6,157.3637352,6.460841712,383044.5099,1.750943264,633.053233
109.8,158.6086103,6.525651105,382666.6254,1.757478415,635.08529
110,159.7225045,6.591121266,384547.505,1.756171554,637.8996403
110.2,160.9734041,6.657238984,386847.1616,1.752686377,640.4459647
110.4,162.2104873,6.724021834,389609.416,1.747894195,643.1339331
110.6,163.3161707,6.791485667,393613.016,1.739181001,646.3862843
110.8,164.5679971,6.859616184,396337.9095,1.735260157,649.0437456
111,165.5446638,6.928452175,398429.1769,1.735695944,652.1577218
111.2,166.8980655,6.997951063,401145.14,1.732210773,654.9600967
111.4,168.4200433,7.06813553,404197.9644,1.728289958,657.8093286
111.6,169.4532987,7.139062383,407161.6567,1.726983087,661.1575609
111.8,170.7851752,7.210675502,410701.2251,1.721319574,663.9784591
112,172.073727,7.283011373,414758.2385,1.715656066,667.5489693
112.2,173.4211624,7.356069559,415935.6845,1.7187059,670.1704804
112.4,174.8598879,7.429854873,416566.7305,1.724805413,673.5209065
112.6,175.953643,7.504407728,416303.4094,1.731340551,675.8776484
112.8,177.3622169,7.579685597,415169.8498,1.742232395,678.6941928
113,178.9277242,7.655707811,415255.7352,1.747024927,680.9539805
113.2,180.5163775,7.732492271,415654.4942,1.750510458,683.3728443
113.4,181.8647577,7.810066362,416892.4617,1.75312463,686.4181939
113.6,183.2944493,7.888413631,417518.2962,1.756610144,688.7531578
113.8,184.5644696,7.967560299,417911.2251,1.761838309,691.4444003
114,185.9789524,8.04749113,418098.5468,1.766630825,693.6377218
114.2,187.2429021,8.128236464,418094.8942,1.772730326,695.8452027
114.4,188.3413596,8.209805656,418275.1777,1.779265474,698.5756668
114.6,189.5369106,8.292186873,419491.1068,1.780572627,700.7253991
114.8,191.283264,8.375353941,423085.1285,1.775344836,703.8187056
115,192.8624597,8.459369242,426552.3057,1.770552692,706.8836777
115.2,194.5487166,8.544220635,430751.9257,1.762710886,709.9813403
115.4,195.9689273,8.62994483,433774.7093,1.757918719,712.5647272
115.6,197.2261308,8.716542679,438018.0263,1.750512526,716.1188989
115.8,198.7732053,8.803988315,440475.6721,1.747463043,718.809067
116,200.417364,8.89230532,444221.3993,1.741363898,722.4297172
116.2,201.7447816,8.981533625,446829.2733,1.737878719,725.3879073
116.4,203.3147006,9.071640032,452135.4179,1.726115881,728.8581972
116.6,204.8969404,9.162650899,458001.9744,1.714353041,732.9582521
116.8,206.451613,9.254578064,462885.3688,1.705204203,736.3969463
117,208.2587545,9.347409772,467407.484,1.699976404,740.6059659
117.2,209.8754553,9.44118863,471210.1508,1.695619918,744.1263799
117.4,211.2302502,9.535929547,472493.0374,1.700412429,748.0531913
117.6,212.8765654,9.631600035,473066.2896,1.705204975,751.0996485
117.8,214.5069394,9.728233041,474346.9209,1.709126185,754.8281704
118,216.3208043,9.825822946,476812.9865,1.70738373,758.0217282
118.2,217.9334181,9.924408602,478733.6902,1.709562266,762.216579
118.4,219.4361863,10.02399314,480028.2729,1.711740789,765.2913633
118.6,221.263706,10.12455339,481083.4217,1.716533361,768.9915669
118.8,223.0503477,10.22612722,482217.1749,1.719583256,772.0347662
119,224.4213408,10.32875313,480706.598,1.730475135,774.6225155
119.2,226.2674868,10.43237399,479630.5026,1.740060067,777.3148792
119.4,227.9273296,10.53704999,481002.3771,1.74354562,780.8581835
119.6,229.8471001,10.642758,483071.8909,1.744852861,784.4123927
119.8,231.3055116,10.74956331,483423.6619,1.749645396,787.0153999
120,233.0163688,10.85742239,487111.9345,1.746160258,790.8071248
120.2,234.7129273,10.96636616,490147.7161,1.743546454,793.9690858
120.4,236.5838166,11.07639138,492210.8864,1.743982353,797.1299632
120.6,238.2409701,11.18753822,494410.9198,1.744418225,800.7833161
120.8,240.3001378,11.29977116,496444.3373,1.743982809,803.7317388
121,242.345,11.4131328,498389.2405,1.745290067,807.2707035
121.2,244.0340244,11.52766034,501307.5206,1.742676261,810.5819375
121.3,244.7775021,11.5801524,503237.5276,1.741369345,813.0607095
121.5,246.0601242,11.58005466,505371.9134,1.740933832,816.1038947
121.7,246.7610643,11.58000095,508541.0148,1.739191241,820.0884385
121.9,247.7794366,11.57992321,511058.8286,1.737884358,823.2057024
122.1,248.4695741,11.57987032,513466.894,1.737013104,826.4090333
122.3,249.0749522,11.57982384,515524.645,1.740062863,830.5700788
122.5,249.4908681,11.5797917,518102.8069,1.739191575,833.7123807
122.7,249.9175867,11.57975874,521299.0532,1.73832029,837.5966721
122.9,250.1914059,11.57973736,523657.0189,1.738320324,840.8043454
123.1,250.700391,11.57969818,525374.217,1.741370071,844.5393696
123.3,251.1777991,11.57966138,528045.0924,1.740934461,848.1436499
123.5,251.6136584,11.57962773,528510.4301,1.745726877,851.1192502
123.7,251.5525948,11.5796317,528696.7647,1.75226191,854.6973565
123.9,252.127227,11.57958754,528810.8786,1.757054343,857.4376205
124.1,252.3545116,11.57956968,529927.839,1.760104057,860.976514
124.3,252.6208521,11.57954887,529781.7097,1.766203461,864.0828554
124.5,252.6295904,11.57954754,531104.2307,1.767510472,866.9037237
124.7,253.0737596,11.57951327,532265.5385,1.770995882,870.4153893
124.9,253.2262565,11.57950107,532629.4464,1.775788265,873.0499461
125.1,253.5125405,11.57947874,532124.2589,1.784066019,875.9634377
125.3,253.8544997,11.5794522,531962.9265,1.790601103,878.5990934
125.5,253.7020289,11.57946308,529035.904,1.804978174,880.9601632
125.7,253.9991155,11.57943993,526993.2103,1.815434277,882.8461992
125.9,254.133331,11.57942911,525310.0556,1.825454691,885.1440833
126.1,254.0656196,11.57943358,524586.5431,1.831554055,886.9799886
126.3,254.1803072,11.57942424,523994.6822,1.837653442,889.1002728
126.5,254.3211705,11.57941292,525810.5958,1.836782122,891.6335032
126.7,254.6352921,11.57938849,527631.2275,1.835475155,893.80065
126.9,254.9265619,11.57936578,530509.0687,1.832425507,896.7141409
127.1,255.1388891,11.57934905,530185.8653,1.837871403,898.7968408
127.3,255.2739356,11.57933817,529684.6173,1.84331729,900.5799114
127.5,255.1031833,11.57935043,527128.3135,1.855516012,902.4060043
127.7,255.2843489,11.57933606,524164.3095,1.868150449,903.954274
127.9,255.5290841,11.57931688,522328.9392,1.876428205,905.2704706
128.1,255.7131581,11.57930229,522610.5694,1.878170905,906.7588165
128.3,255.4364565,11.57932257,524348.5225,1.87599252,908.6982188
128.5,255.6213615,11.57930792,527286.5833,1.870764515,911.1105103
128.7,255.974539,11.57928053,528462.1155,1.870328893,912.8222219
128.9,256.0958744,11.57927068,529565.6087,1.871635918,914.9218058
129.1,256.2458785,11.57925867,529369.5557,1.875556962,916.3491343
129.3,256.1681953,11.57926389,527517.4911,1.884706013,917.6729447
129.5,256.2783126,11.5792549,525668.1214,1.893855087,918.9379273
129.7,256.4200069,11.57924351,524732.411,1.89951881,920.0067908
129.9,256.6182075,11.57922785,524434.655,1.903439863,921.403614
130.1,256.6618468,11.57922389,523711.4279,1.907796563,922.4005623
130.3,256.7678092,11.57921521,523161.0572,1.911717606,923.5337082
130.5,257.2153024,11.57918068,522393.755,1.916510031,924.6832128
130.7,257.046212,11.57919282,521136.7194,1.92260938,925.6747038
130.9,256.9460925,11.57919974,519901.9232,1.928273071,926.3349721
131.1,256.9107891,11.57920175,519751.0009,1.931322752,927.338454
131.292,257.4325876,11.57916163,520327.8398,1.931322818,928.1371245
132,257.5608724,11.48247435,1.7977E+308,1.968354749,0
132.2,257.1226685,11.36672813,1.7977E+308,1.967919019,0
132.4,257.1680921,11.25094531,1.7977E+308,1.892983874,0
132.6,256.7988591,11.13519387,1.7977E+308,1.736142817,0
132.8,256.4080208,11.01944406,1.7977E+308,1.50436662,0
133,256.1767297,10.90368219,1.7977E+308,1.11487811,0
133.2,255.8365809,10.78792855,1.7977E+308,0.703170467,0
133.4,255.8122026,10.67215101,1.7977E+308,0.408657929,0
133.6,255.7180224,10.55637875,1.7977E+308,0.170346747,0
133.8,255.3712258,10.44062561,1.7977E+308,0.011763074,0
134,255.0518513,10.3248704,1.7977E+308,0.017426776,0
134.2,255.2152734,10.20907865,1.7977E+308,0.011327405,0
134.4,254.6723667,10.09334036,1.7977E+308,0.002614016,0
134.6,254.5665528,9.97756898,1.7977E+308,0.008277718,0
134.8,254.3793035,9.861803768,1.7977E+308,0.011763073,0
135,253.9926201,9.74605365,1.7977E+308,0.019169453,0
135.2,253.7189493,9.630294979,1.7977E+308,0.030932525,0
135.4,253.5699248,9.514526874,1.7977E+308,0.040517251,0
135.6,253.494026,9.398753234,1.7977E+308,0.041824259,0
135.8,253.1563702,9.282999405,1.7977E+308,0.04051725,0
136,252.8286861,9.167244822,1.7977E+308,0.035724886,0
136.2,252.7070837,9.051474642,1.7977E+308,0.028754176,0
136.4,252.5854814,8.935704461,1.7977E+308,0.02614016,0
136.6,252.4239922,8.819937299,1.7977E+308,0.029189845,0
136.8,252.0971391,8.704182653,1.7977E+308,0.027447167,0
137,251.9173685,8.588416875,1.7977E+308,0.023090473,0
137.2,251.6569934,8.472657197,1.7977E+308,0.019169449,0
137.4,251.6276292,8.356880035,1.7977E+308,0.017426772,0
137.6,251.0863846,8.241141616,1.7977E+308,0.023526141,0
137.8,251.0553586,8.12536458,1.7977E+308,0.027882834,0
138,250.8190817,8.009603079,1.7977E+308,0.025268818,0
138.2,250.4315674,7.893853024,1.7977E+308,0.018298109,0
138.4,250.2950076,7.778083975,1.7977E+308,0.015248424,0
138.6,250.1227158,7.662317631,1.7977E+308,0.01742677,0
138.8,249.7152582,7.546569086,1.7977E+308,0.029189839,0
139,249.4881221,7.430806893,1.7977E+308,0.0339822,0
139.2,249.4787013,7.315028221,1.7977E+308,0.027882831,0
139.4,248.9873153,7.199286028,1.7977E+308,0.020040784,0
139.6,248.6180825,7.08353459,1.7977E+308,0.006535038,0
139.8,248.7283221,6.967746862,1.7977E+308,0.010020392,0
140,248.4721019,6.85198687,1.7977E+308,0.015684091,0
140.2,247.9075902,6.736250212,1.7977E+308,0.011763068,0
140.4,247.3339377,6.620514245,1.7977E+308,0.009584722,0
140.6,247.6927307,6.504128811,1.7977E+308,0.007842045,0
140.8,247.0077276,6.388401273,1.7977E+308,0.013070075,0
141,246.898498,6.273209049,1.7977E+308,0.016119759,0
141.2,246.5974972,6.156873553,1.7977E+308,0.020912119,0
141.4,246.636181,6.041670134,1.7977E+308,0.021783457,0
141.6,246.1589216,5.925926872,1.7977E+308,0.026575817,0
141.8,246.0024184,5.810159333,1.7977E+308,0.033110853,0
142,245.8309576,5.694392926,1.7977E+308,0.039210221,0
142.2,245.6661447,5.578626015,1.7977E+308,0.041388566,0
142.4,245.1780826,5.462883571,1.7977E+308,0.046180924,0
142.6,245.1595212,5.347105591,1.7977E+308,0.044438248,0
142.8,244.5767281,5.231370317,1.7977E+308,0.034417857,0
143,244.5972225,5.115589381,1.7977E+308,0.024833138,0
143.2,244.1864411,4.999841087,1.7977E+308,0.019169439,0
143.4,244.0789654,4.884069837,1.7977E+308,0.024833137,0
143.6,243.7296762,4.76831689,1.7977E+308,0.039645884,0
143.8,243.4169498,4.652561174,1.7977E+308,0.050973278,0
144,243.0959137,4.536806088,1.7977E+308,0.054458629,0
144.2,242.8056237,4.421048675,1.7977E+308,0.047270089,0
144.4,242.3636808,4.30530274,1.7977E+308,0.037467535,0
144.6,242.2528812,4.189531741,1.7977E+308,0.028754154,0
144.8,242.0265762,4.073769485,1.7977E+308,0.017862429,0
145,241.6860123,3.958015877,1.7977E+308,0.016991091,0
145.2,241.1194233,3.842279376,1.7977E+308,0.027011476,0
145.4,241.163185,3.726496679,1.7977E+308,0.036596194,0
145.6,240.8936693,3.610737694,1.7977E+308,0.038774538,0
145.8,240.5148806,3.494986979,1.7977E+308,0.040952881,0
146,240.324723,3.379221987,1.7977E+308,0.036596192,0
146.2,239.9999476,3.263467184,1.7977E+308,0.025704467,0
146.4,239.8613104,3.147698292,1.7977E+308,0.021347778,0
146.6,239.3528897,3.031957388,1.7977E+308,0.022219115,0
146.8,239.0368396,2.916201925,1.7977E+308,0.024397459,0
147,238.7764647,2.800442247,1.7977E+308,0.026140134,0
147.2,238.3897817,2.68469213,1.7977E+308,0.023961789,0
147.4,238.1867441,2.568928113,1.7977E+308,0.017426755,0
147.6,237.3862361,2.453209316,1.7977E+308,0.009149046,0
147.8,237.6925855,2.337406745,1.7977E+308,0.002614013,0
148,237.0350051,2.221677131,1.7977E+308,0.001307007,0
148.2,236.8967834,2.105908208,1.7977E+308,0.004356688,0
148.4,236.4195244,1.990164946,1.7977E+308,0.013941402,0
148.6,236.2148248,1.874401055,1.7977E+308,0.026140129,0
148.8,235.9087464,1.758644836,1.7977E+308,0.037031849,0
149,235.4057272,1.642903524,1.7977E+308,0.046180892,0
149.2,234.935116,1.527159759,1.7977E+308,0.047487897,0
149.4,234.6464881,1.41140222,1.7977E+308,0.041388533,0
149.6,234.4243381,1.295639649,1.7977E+308,0.031368151,0
149.8,233.9130092,1.179898966,1.7977E+308,0.016991081,0
225,233.3661808,1.06970263,1.7977E+308,0.049230578,0
225.2,233.0044272,0.953950626,1.7977E+308,0.041388538,0
225.4,232.627716,0.838199753,1.7977E+308,0.034417836,0
225.6,232.3332712,0.722442655,1.7977E+308,0.026140128,0
225.8,231.76876,0.606705996,1.7977E+308,0.011327388,0
226,231.3804152,0.490956005,1.7977E+308,0.00348535,0
226.2,230.7552429,0.375223938,1.7977E+308,0.013505731,0
226.4,230.0669167,0.259496651,1.7977E+308,0.021347768,0
226.6,228.6872203,0.143821691,1.7977E+308,0.029625471,0
226.8,227.5509994,0.028128304,1.7977E+308,0.033982155,0
226.848,226.7913226,0.00039875,1.7977E+308,0.035289159,0
,,,,,