File: Test_5.csv
Time On Sample,Displacement Into Surface,Load On Sample,Harmonic Contact Stiffness,Harmonic Displacement,Harmonic Load
0,0,0,-373.2034139,0.451349347,2.188905956
0.2,0.252701522,0.00074009,2087.602077,0.297995134,2.264084938
0.4,0.24614122,0.001499808,6834.21945,0.219575362,2.331637036
0.6,0.506321453,0.002239331,12629.80379,0.169909509,2.399189167
0.8,0.413340541,0.003005592,17431.64281,0.141155592,2.501606862
0.99,0.564161094,0.003715434,20943.89218,0.125471638,2.657412535
1.2,0.581371262,0.004508604,23802.89489,0.117193996,2.812128643
1.4,0.734357125,0.0052536,25435.15236,0.115887001,2.973382068
1.6,0.726966275,0.006010737,26271.47477,0.118936659,3.124829519
1.8,0.717913491,0.006768001,27861.99461,0.124600309,3.440799033
2,0.935714815,0.00750809,29282.52593,0.133313619,3.826499794
2.2,0.930816868,0.008265039,31695.24474,0.136363277,4.224185575
2.4,1.058873711,0.009011923,33912.4038,0.139412937,4.613154977
2.6,0.753165553,0.009791646,35852.11255,0.142898257,4.999945167
2.8,1.07733071,0.010523683,39008.59441,0.145947918,5.564332171
3,1.0765876,0.011280318,43579.59193,0.146383584,6.249659157
3.2,1.271121841,0.01202217,45463.50611,0.155096895,6.921911616
3.4,1.311927104,0.012775659,46672.51119,0.165552866,7.587626747
3.6,1.311183995,0.013532295,46470.86541,0.181236821,8.258789593
3.8,1.295483471,0.014290063,46760.75952,0.197792108,9.04871339
4,1.376175172,0.015040533,46077.343,0.223060704,10.0445622
4.2,1.284856609,0.015804026,45158.02548,0.25007196,11.02079902
4.4,1.230931582,0.016564688,43640.42973,0.281875536,11.99485679
4.6,1.712980572,0.017284773,43085.76418,0.308451138,12.9634671
4.8,1.612521365,0.018048958,43089.76353,0.332412736,13.99091277
5,1.440598955,0.018818553,43298.78523,0.359423989,15.22537291
5.2,1.311055889,0.01958494,43311.19052,0.385999578,16.40971376
5.4,1.630235255,0.020317356,43045.86947,0.414753506,17.56681624
5.6,1.375216099,0.021093242,41895.14966,0.453963388,18.69667947
5.8,1.118535011,0.021869254,40805.51632,0.493608935,19.76225916
6,0.890937789,0.022643064,39012.94814,0.548502771,20.9357044
6.2,1.077162354,0.023385544,37044.58056,0.604267954,21.8389416
6.4,1.275850832,0.024130866,34381.14886,0.682687741,22.85222342
6.6,0.921947157,0.024910452,31733.52447,0.768949479,23.73475853
6.8,1.073270489,0.02565936,29254.55186,0.860003563,24.47020505
7,1.040951217,0.0264146,27037.44119,0.956721287,25.19366623
7.2,1.082586846,0.027171812,25263.24855,1.047775367,25.84521726
7.4,1.540538379,0.027889936,23988.58531,1.120967194,26.33224667
7.6,1.392714026,0.028657707,22656.28851,1.205050614,26.89118566
7.8,1.656218575,0.029394337,21766.69186,1.269093458,27.36187163
8,1.615589026,0.030153993,21098.40317,1.321373309,27.75519923
8.2,1.56083303,0.030914719,20356.82832,1.381059471,28.19537737
8.4,1.561751855,0.031671229,19943.15321,1.418962365,28.52333197
8.6,1.981893781,0.032396001,19815.48537,1.446844997,28.98966001
8.8,2.078789354,0.033145246,19929.67916,1.459479306,29.42330116
9,2.338970046,0.03388213,20262.52413,1.45686534,29.84277837
9.2,2.191145685,0.034649903,21086.18924,1.433775056,30.43113524
9.4,2.298012869,0.035398393,22109.18731,1.399357495,30.9857164
9.6,2.192567852,0.036162958,23350.71744,1.36145459,31.66886417
9.8,1.668315213,0.036959229,24472.17391,1.329215297,32.31387705
10,2.123357779,0.03768136,25248.1382,1.316145376,32.95998102
10.2,2.600421001,0.038401824,25380.48317,1.327037057,33.42195109
10.4,2.589706281,0.039159217,25294.06059,1.350562993,33.9405769
10.6,2.875231493,0.039894183,25281.01857,1.367118309,34.34589004
10.8,2.594867802,0.040671991,25504.42913,1.374524596,34.81875439
11,2.581244695,0.041429604,26414.31297,1.354048318,35.45287257
11.2,2.841425397,0.042166489,27754.34709,1.313095787,36.04558834
11.4,2.703572641,0.042933508,29635.43594,1.260380251,36.85185514
11.6,2.499657966,0.043705528,31066.10208,1.22509133,37.5066745
11.8,2.559575487,0.044457574,32097.83841,1.208100382,38.16258384
12,2.975978092,0.045182632,32764.91822,1.206357755,38.86643405
12.2,3.141013013,0.04592672,32874.00057,1.222477395,39.50817929
12.4,2.876437699,0.046703334,32900.69156,1.240339656,40.11178974
12.6,2.943002963,0.047454877,32855.95811,1.257330618,40.61298296
12.8,2.708757968,0.048229194,33254.5954,1.259073261,41.21223511
13,2.981818671,0.048965104,33697.21842,1.261687278,41.88339858
13.2,3.044229097,0.049716962,34080.35921,1.264083443,42.48319609
13.4,2.843222803,0.050488763,34383.20491,1.270400573,43.09824677
13.6,2.951336445,0.051237161,34569.9743,1.280638725,43.67843249
13.8,3.169968776,0.051977192,34543.68216,1.301332856,44.30546899
14,3.126430836,0.052737071,34493.55173,1.317016811,44.77724425
14.2,3.065027093,0.053498303,34151.1489,1.346642062,45.31875057
14.4,3.036862053,0.054257018,33947.72277,1.367118336,45.7523915
14.6,3.217269877,0.054999943,33787.0685,1.388465964,46.30697282
14.8,3.246857085,0.055754287,33576.05524,1.408942246,46.77112131
15,3.380315242,0.056500767,33316.06308,1.433775194,47.27340436
15.2,3.424028899,0.057254041,33328.20072,1.445102502,47.70159755
15.4,3.566627702,0.057999829,33289.94956,1.459915145,48.19516425
15.6,3.598707813,0.058753985,33219.31221,1.47342078,48.5808651
15.8,3.475812465,0.059519873,33245.4575,1.485183737,49.02649085
16,3.944566061,0.060240969,33303.7672,1.496075424,49.51787921
16.2,4.117910672,0.060984431,33139.36565,1.513066398,49.88069984
16.4,4.198602393,0.061734907,32928.58906,1.536156681,50.29363952
16.6,4.357405073,0.06247947,33023.19248,1.543998678,50.64556476
16.8,4.350014222,0.063236616,33526.12228,1.536156699,51.11298186
17,4.478071101,0.063983506,34527.12799,1.511323777,51.70787649
17.2,4.063506099,0.064771478,35760.4112,1.478213153,52.26463577
17.4,4.327010703,0.065508114,37857.96108,1.421140995,53.06763483
17.6,4.069498589,0.066284196,39612.8198,1.380624076,53.85428959
17.8,4.357932223,0.067018945,40435.26333,1.369732466,54.47969222
18,4.199305258,0.06778754,40756.71753,1.373217776,55.012482
18.2,4.494386636,0.068521786,40968.22196,1.38149545,55.64877999
18.4,4.398082245,0.069285664,40894.38673,1.396743735,56.19791315
18.6,4.375733976,0.070043942,41130.82936,1.403278717,56.81350901
18.8,4.535367627,0.070788442,41741.27256,1.398050746,57.43564261
19,4.38754324,0.07155622,42438.24258,1.388466091,58.01419344
19.2,4.346913683,0.072315882,42937.64112,1.388901753,58.70169952
19.4,4.713458286,0.073044718,43131.39109,1.398486431,59.34889345
19.6,4.244049409,0.073836843,43199.39067,1.408506694,59.83918979
19.8,4.709479164,0.074558192,43419.31722,1.418527048,60.55829427
20,4.505979941,0.075330185,43631.38891,1.423755015,61.07909865
20.2,4.511884573,0.076086325,44133.98872,1.422448019,61.76660496
20.4,4.497845981,0.076843974,44969.17213,1.411120714,62.50314099
20.6,4.579368671,0.077594388,45346.59427,1.409813726,63.06208053
20.8,4.314377842,0.078371036,45442.03163,1.418091346,63.67331727
21,4.69421778,0.079099801,45127.4702,1.439874662,64.287825
21.2,4.818118596,0.079854733,44802.31325,1.463400616,64.88380919
21.4,4.789120166,0.080628733,44339.5527,1.487797885,65.29239077
21.6,4.912187581,0.081399046,43882.57089,1.515244829,65.80556918
21.8,4.646360886,0.082206527,43522.14722,1.538335076,66.26535868
22,5.380187074,0.082946287,43238.9375,1.557068775,66.65759901
22.2,5.162554013,0.083765759,42660.80759,1.587129676,67.07162775
22.4,5.151830624,0.084577679,42579.83494,1.599763977,67.45405978
22.6,4.949152397,0.085412298,42585.66233,1.611962591,67.91820752
22.8,5.408754132,0.086204998,42844.83994,1.614576637,68.36274564
23,5.412984261,0.087040332,43967.3689,1.591050697,69.00231168
23.2,5.240216913,0.087897569,45169.25879,1.565782075,69.65168304
23.4,5.482101131,0.088731782,46034.26241,1.549662476,70.18774271
23.6,5.6234369,0.089582135,47108.82014,1.530928872,70.89595084
23.8,5.61436613,0.090452544,47989.95757,1.517423238,71.55186011
24,5.631054007,0.09132951,48254.00666,1.522215562,72.15111306
24.2,5.489856594,0.092227363,48344.29683,1.529621863,72.62288795
24.4,5.473302192,0.093129303,48375.08603,1.541384832,73.21233459
24.6,5.577238118,0.094022085,48363.91757,1.553583481,73.76582643
24.8,5.706931897,0.094926439,48383.83705,1.563603804,74.27246791
25,5.64300875,0.095854504,48465.5719,1.570574447,74.73225795
25.2,5.854965423,0.096770967,48758.2811,1.572752799,75.32061596
25.4,5.92233222,0.097707727,49282.26703,1.56752482,75.94928682
25.6,5.809377528,0.09866748,49649.2221,1.56534648,76.44176309
25.8,5.986429051,0.099614932,49961.97175,1.566653497,77.0105092
26,5.888013237,0.100592813,50148.33676,1.571445809,77.59341812
26.2,5.942493933,0.101568931,50157.40241,1.58190179,78.15344721
26.4,5.982015683,0.102555788,50229.9617,1.590615107,78.6497377
26.6,6.139117795,0.10354367,50467.69298,1.59410045,79.16672989
26.8,5.907740866,0.104571068,51015.59294,1.588872438,79.73547434
27,6.195717177,0.105569336,52031.03376,1.573624174,80.4534891
27.2,6.247697026,0.106595626,53185.25423,1.555326225,81.18021949
27.4,6.263112664,0.107634925,54122.42382,1.540513597,81.79145731
27.6,6.458431174,0.108671026,55306.74459,1.522651328,82.59772528
27.8,6.661226752,0.109716914,55908.65339,1.518294694,83.26453116
28,6.628441258,0.110791317,56540.70749,1.514373701,84.03157462
28.2,6.554105676,0.111879547,56851.06124,1.516116356,84.64934926
28.4,6.620617386,0.112968129,57021.91903,1.523522679,85.34993051
28.6,6.810941592,0.114058099,57293.6407,1.529186353,86.05051214
28.8,6.579963358,0.11519101,57769.33273,1.529186329,86.71186838
29,6.933569197,0.11629092,58004.21722,1.536157018,87.4080927
29.2,6.760339644,0.117441982,58353.79961,1.537463997,87.98882247
29.4,6.695965057,0.118596255,58766.00672,1.539206656,88.72208945
29.6,7.15343645,0.119722457,59025.88795,1.542909862,89.37091863
29.8,7.265223373,0.120886496,59219.03053,1.549227025,90.10146292
30,7.166773578,0.1220781,59488.63848,1.551405344,90.68219302
30.2,7.074138669,0.123281149,59731.6413,1.55706899,91.39693773
30.4,7.187997358,0.124480591,59944.09286,1.564039651,92.08989225
30.6,7.176793456,0.125701646,60218.69392,1.567089312,92.64665259
30.8,7.348816051,0.126920877,60541.04709,1.570138993,93.29602546
31,7.364614704,0.128164422,60876.9592,1.573624318,94.0009647
31.2,7.420297838,0.129417384,61350.36538,1.573624325,94.72115783
31.4,7.513372532,0.130680063,61916.87033,1.571446008,95.4773063
31.6,7.660458115,0.131951383,62229.13232,1.572753022,96.05585831
31.8,7.537892599,0.133255852,62672.54792,1.573842172,96.80328938
32,7.436514677,0.134571839,62970.57436,1.577109654,97.47336246
32.2,7.733168292,0.135870754,63147.32728,1.583644672,98.16740754
32.4,7.958772086,0.137188079,63216.76135,1.592793676,98.84837731
32.6,8.202655059,0.138517352,63451.6927,1.595843364,99.40513881
32.8,8.130768076,0.139884061,63748.82928,1.598893018,100.0512423
33,8.181862174,0.141255113,64378.06997,1.596279028,100.8139277
33.2,8.108308897,0.142649373,65039.26269,1.59235803,101.5580904
33.4,8.274903139,0.144039335,65723.77709,1.588437058,102.343657
33.6,8.178493789,0.145463351,66197.91566,1.586694385,102.9592526
33.8,8.062969896,0.146903165,66762.37128,1.584080379,103.6663704
34,8.226648947,0.148336147,67204.43636,1.584951729,104.4562953
34.2,8.412761829,0.149781932,67599.65501,1.586258748,105.2211607
34.4,8.740136964,0.151231491,68065.36371,1.586258785,106.0121762
34.6,8.973610407,0.15270275,68380.63192,1.587130143,106.6136092
34.8,8.685233592,0.154228516,68518.02189,1.593229431,107.2967561
35,9.244441708,0.155705121,68692.9013,1.600200145,108.0638025
35.2,9.062423985,0.157253041,69095.18055,1.603249786,108.8482781
35.4,9.308352337,0.158783857,69465.14624,1.604992477,109.4725918
35.6,9.488631774,0.160335049,70105.34877,1.6036855,110.2810393
35.8,9.656444214,0.161902774,70897.57771,1.598457531,111.0676958
36,9.200197171,0.163533612,71632.68931,1.592793827,111.7791701
36.2,9.601506529,0.165115651,72368.8867,1.588872881,112.6595292
36.4,9.437755079,0.166756662,73064.53981,1.585387538,113.5268104
36.6,9.687823108,0.168382603,73522.1246,1.584516235,114.221945
36.8,9.68610521,0.17004411,74128.60981,1.581902241,115.0434661
37,9.788255666,0.171714409,74986.18316,1.576238598,115.9924654
37.2,9.676013697,0.173417785,75758.28888,1.571010598,116.7627768
37.4,9.556290288,0.175138895,76726.52728,1.564911266,117.7390135
37.6,9.751501034,0.176853268,77272.77535,1.564475622,118.4897151
37.8,9.462254682,0.17862163,77776.20251,1.566218254,119.3450108
38,10.16185749,0.180332587,77844.56051,1.576674309,120.2242821
38.2,9.973983664,0.182128268,77774.40546,1.586694601,120.9128772
38.4,9.919892835,0.183931803,77764.83541,1.597150573,121.7463829
38.6,10.29457865,0.185720846,77958.60038,1.60281427,122.5559211
38.8,9.987867797,0.187579639,78075.72088,1.609784888,123.3218737
39,10.14067932,0.189422187,78292.31361,1.614141564,124.0213661
39.2,10.40982343,0.191274384,78518.38433,1.620676581,124.8744855
39.4,10.66400714,0.193146452,78509.93063,1.62895426,125.4987999
39.6,10.341496,0.195081188,78650.94953,1.636796207,126.284364
39.8,10.26245544,0.197016801,78835.94731,1.642895519,127.0078251
40,10.57064293,0.198942301,79086.9475,1.646816547,127.6659156
40.2,10.87384153,0.20088761,79399.68209,1.65117324,128.446036
40.4,10.87456462,0.20287559,79769.74677,1.652480238,129.095408
40.6,10.63762606,0.204911563,80029.60231,1.657708201,129.8907789
40.8,10.90757804,0.206909116,80257.7511,1.662064891,130.6011674
41,10.96562831,0.208953187,80289.20143,1.66903555,131.2113159
41.2,11.04195663,0.211016368,80467.3587,1.674699215,131.9652854
41.4,11.00859385,0.213108607,80648.14939,1.678184538,132.5634489
41.6,11.11898521,0.215211072,80986.82125,1.680362881,133.328314
41.8,11.31080809,0.217328391,81156.37443,1.684719562,133.9853146
42,11.13450872,0.219494913,81680.41338,1.683412544,134.7828646
42.2,11.38947661,0.221661412,82110.15338,1.682541244,135.4365963
42.4,11.1832572,0.223862791,82875.21304,1.677748897,136.2940717
42.6,11.34432046,0.226069321,83195.10056,1.679491579,136.9347285
42.8,11.8469081,0.228272137,83703.21305,1.679055973,137.6745369
43,11.58666341,0.230555247,84020.9683,1.682976936,138.4535639
43.2,12.28452141,0.232788387,84148.40331,1.688205008,139.0637168
43.4,13.01727657,0.235041154,84083.69283,1.698225409,139.7577656
43.6,13.12721744,0.237363956,84407.34664,1.699096754,140.3602883
43.8,12.91099958,0.239734747,84916.30498,1.6969184,141.0674053
44,13.00556006,0.24210571,85933.40458,1.686898098,141.9771808
44.2,13.03779414,0.244505263,87000.05694,1.67469946,142.7464039
44.4,13.15104377,0.246922876,88900.81003,1.650737853,143.8566569
44.6,13.31996441,0.249360551,90410.43766,1.633746905,144.8459703
44.8,13.2861249,0.251838135,91804.29968,1.619369929,145.7709988
45,13.41473575,0.254328154,93319.1243,1.606299969,146.9270132
45.2,13.38961347,0.256854993,94404.71388,1.600200645,148.0209219
45.4,13.42265496,0.259402672,94921.61395,1.601507647,148.882757
45.6,13.6721596,0.261959626,95468.48484,1.604121671,149.9167425
45.8,13.70353101,0.264558659,95943.26371,1.60673567,150.8777266
46,13.83212155,0.267176472,96366.90445,1.608914015,151.7450099
46.2,14.19878032,0.269802546,96925.14152,1.611092386,152.8302052
46.4,13.90107573,0.27250551,97142.26142,1.615884678,153.6593513
46.6,14.54153008,0.275164254,97171.45133,1.625033734,154.6268776
46.8,14.46526999,0.277904179,96785.84721,1.637668042,155.2653539
47,14.71100576,0.280647198,96150.49539,1.656837364,156.1119366
47.2,14.65384918,0.283440815,95572.09644,1.673392664,156.7340702
47.4,14.84847157,0.286243277,95426.6756,1.684719999,157.540339
47.6,14.69158984,0.289100723,95564.00706,1.689947975,158.2213072
47.8,14.80809218,0.291965914,96341.95305,1.687333993,159.1615909
48,15.16016944,0.294842152,97211.86637,1.682106046,160.0223389
48.2,15.0921876,0.297779225,98014.82342,1.679056376,161.0149185
48.4,15.15923344,0.300735473,98311.62891,1.681670381,161.7362025
48.6,15.24663328,0.303719941,98321.73691,1.690383713,162.5925903
48.8,15.70422478,0.306706223,98082.75887,1.701275415,163.2877274
49,15.52653616,0.309770776,97850.77386,1.711295709,163.8869785
49.2,15.52500797,0.312852665,97847.97672,1.719137697,164.6801722
49.4,15.77276538,0.315946571,98089.13155,1.720880389,165.3295466
49.6,15.68937691,0.319096852,98951.7678,1.714345393,166.2458583
49.8,15.52454853,0.322284835,99962.57995,1.705632052,167.1403778
50,15.80469865,0.325471035,100621.0528,1.701711092,167.9259463
50.2,16.00050037,0.328695777,101162.2982,1.701711118,168.8422608
50.4,16.09284137,0.331960748,101514.125,1.703889458,169.5657232
50.6,16.22464817,0.33525544,101414.5828,1.714345458,170.3469326
50.8,16.2804161,0.338589014,101087.2816,1.727415442,171.0159171
51,16.56552599,0.341938729,101208.7822,1.732207803,171.6358737
51.2,16.54109474,0.345345865,101524.3985,1.735693128,172.4508575
51.4,16.89142486,0.348758606,102014.7344,1.734386174,173.1252929
51.6,16.99079702,0.352224849,102824.6098,1.729593861,173.9980238
51.8,16.95388483,0.355736205,103789.5688,1.722187536,174.8674861
52,16.94521995,0.359280734,104570.7114,1.71739521,175.650872
52.2,17.28804909,0.362834145,105827.9627,1.707374935,176.6990236
52.4,17.1148411,0.366462524,106339.6339,1.706503583,177.4758721
52.6,17.21584693,0.370106525,107095.267,1.7038896,178.4433941
52.8,17.29441078,0.373788871,107966.6103,1.699097285,179.3716919
53,17.29402676,0.377514115,108506.379,1.698225953,180.1888558
53.2,18.01907233,0.38122165,108792.2328,1.7025827,181.1400401
53.4,18.40507682,0.384992259,109065.0047,1.705196743,181.8798486
53.6,18.46616657,0.388825475,108963.5586,1.714345737,182.7264305
53.8,18.65438839,0.392687557,108200.9184,1.731772401,183.3649092
54,18.40052875,0.39662204,107642.2902,1.745713683,183.9183989
54.2,18.56630197,0.400564123,107334.5221,1.757476686,184.6331463
54.4,18.94064202,0.404529965,107371.8262,1.762704725,185.2106115
54.6,19.54432308,0.408518279,108052.5002,1.760090804,186.0364964
54.8,19.48903967,0.41259664,109119.4914,1.751377477,186.8819885
55,19.52017048,0.416709403,110533.085,1.738307501,187.9039874
55.2,19.90861124,0.420836375,111835.7708,1.725673233,188.7734526
55.4,19.86577266,0.425037646,113200.4098,1.713910245,189.8651828
55.6,20.23176398,0.429249983,114149.8638,1.706939633,190.7488124
55.8,20.04764728,0.433546542,115427.9513,1.697354958,191.7904211
56,20.55572066,0.437833581,116538.1323,1.69169136,192.9148426
56.2,20.56022015,0.442202036,117048.8443,1.692562694,193.7788572
56.4,20.9494512,0.446585045,117829.8413,1.691691408,194.8542478
56.6,21.17081956,0.451024939,118419.28,1.691255769,195.7117268
56.8,21.38968792,0.455509667,118650.1057,1.696048123,196.6345792
57,21.41908825,0.460053811,118997.8656,1.700404788,197.681638
57.2,21.5847602,0.464633218,119540.3954,1.700404809,198.5532802
57.4,21.66317313,0.469265222,119769.415,1.705632812,199.5720116
57.6,21.71332571,0.473945976,119936.2875,1.70998948,200.3695639
57.8,21.70364109,0.478678172,120374.7083,1.711732144,201.2956826
58,22.00057637,0.483434742,120940.9917,1.712603513,202.3569081
58.2,22.41799452,0.488230013,121214.7901,1.71521756,203.1555536
58.4,22.542904,0.493095749,121970.0774,1.713910577,204.2342103
58.6,22.36782596,0.498033106,122834.724,1.709553896,205.125462
58.8,22.68716252,0.503007471,123676.2674,1.706504272,206.1420168
59,22.52703012,0.508017964,124681.5167,1.702147592,207.3002078
59.2,22.95604261,0.51305925,125451.0087,1.699533647,208.2481221
59.4,22.94047871,0.518185036,126044.6044,1.700404978,209.3333152
59.6,23.05121393,0.523352499,126113.4737,1.706068652,210.1690023
59.8,23.11623763,0.528575212,126079.5433,1.713474986,211.0482708
60,23.15050293,0.533879243,125811.8765,1.725237977,211.9950913
60.2,23.4465234,0.539163508,125784.8917,1.731773006,212.712019
60.4,23.29796281,0.544561548,126071.5455,1.73612965,213.6947931
60.6,23.3504881,0.549998349,126625.0759,1.73700099,214.6895539
60.8,23.65811215,0.555470385,127198.643,1.737001028,215.618945
61,23.77086525,0.561012311,128042.9842,1.732644381,216.5014829
61.2,24.98422781,0.566526606,128847.0183,1.730466197,217.6019422
61.4,25.5319755,0.572146731,129392.6676,1.729594931,218.4517977
61.6,25.50177528,0.577867258,130370.4906,1.7248026,219.5827527
61.8,25.89993046,0.583612698,131263.3493,1.720881652,220.663592
62,26.04920122,0.589434907,131720.5521,1.721317337,221.5406822
62.2,26.34138937,0.595304692,132513.8191,1.720010374,222.6967
62.4,25.94801866,0.601285685,132965.1898,1.721317327,223.5933966
62.6,26.39931845,0.607262432,133339.3195,1.725238378,224.6404606
62.8,26.57514244,0.613320366,134181.1038,1.723060069,225.6602825
63,26.69071151,0.619443628,135017.6418,1.720446086,226.6267163
63.2,27.10999001,0.625605317,135635.1345,1.721753136,227.7467798
63.4,27.2409124,0.631850845,136327.3871,1.72088182,228.6859749
63.6,27.52763155,0.638147107,137592.0187,1.715218193,229.9149924
63.8,27.55632473,0.644526256,138063.1802,1.717396529,230.954425
64,27.65065428,0.650964492,138570.0426,1.718267874,231.902336
64.2,27.88956221,0.657456299,139361.2213,1.717396571,233.1204574
64.4,28.04370092,0.664019793,139576.343,1.720446254,233.9833839
64.6,28.05739537,0.670659792,139376.8816,1.729595254,235.0282653
64.8,28.19655555,0.677357041,139151.1907,1.738744265,235.9456685
65,28.33653601,0.684121534,138984.4233,1.746150607,236.6865651
65.2,28.33981122,0.69096441,139511.411,1.747893277,237.7641329
65.4,29.12917239,0.697816199,140158.4522,1.747022041,238.6346938
65.6,29.27784535,0.70478565,140839.8834,1.747022058,239.6882912
65.8,29.53910353,0.711816465,141673.398,1.744843758,240.7408021
66,29.93205909,0.718908031,142488.1928,1.743101143,241.860866
66.2,29.92239872,0.726101455,142272.3957,1.750943137,242.6453432
66.4,30.00537994,0.733360036,142489.2464,1.754864146,243.6586273
66.6,30.23626211,0.740680314,142908.4145,1.755299843,244.5248238
66.8,30.10773837,0.748101462,143761.1061,1.751814496,245.5598965
67,30.61572526,0.755548805,144911.2716,1.746150893,246.757319
67.2,30.56861273,0.7631133,146348.6068,1.737001898,247.832707
67.4,31.10939896,0.770708943,148013.08,1.727417301,249.1674146
67.6,31.41500873,0.778398802,149267.0488,1.720882339,250.2667752
67.8,31.70190943,0.7861673,150046.6815,1.72044671,251.443495
68,32.28254542,0.793991478,150590.6434,1.723060779,252.6638008
68.2,32.46056424,0.80192496,150960.9515,1.725674799,253.6454886
68.4,33.0457454,0.809907254,150843.7402,1.733952532,254.7426743
68.6,32.97527896,0.81801941,150780.5173,1.740051854,255.5674641
68.8,33.3049114,0.826182325,151012.6887,1.743972894,256.5796627
69,33.46501303,0.83444026,151574.1919,1.744844247,257.7749028
69.2,33.57939815,0.842784615,152278.5271,1.742665929,258.7511428
69.4,33.78185269,0.851206223,154527.9283,1.727417628,260.2176821
69.6,34.33413198,0.859685718,156529.5845,1.713912033,261.4891961
69.8,34.70524639,0.868264111,158953.402,1.697792417,262.9971415
70,35.1395008,0.876923966,161833.8454,1.679930142,264.7959971
70.2,35.38344934,0.885685262,163575.1358,1.671652507,266.185179
70.4,35.62904585,0.8945344,164848.3886,1.669474204,267.7802864
70.6,36.1679605,0.903450255,165623.1425,1.6703456,269.0452629
70.8,36.45175324,0.912475125,165648.2786,1.678623299,270.2993419
71,36.50119812,0.921608466,165785.6508,1.686900971,271.7386405
71.2,36.45589788,0.930840689,165890.0034,1.693435965,272.8663265
71.4,36.83022259,0.940133747,165382.1424,1.706506007,274.0757344
71.6,36.83973677,0.949547944,165271.0447,1.715655008,275.3308987
71.8,37.30626924,0.959021996,165554.0362,1.72001173,276.5010835
72,37.40549798,0.968619167,165213.4479,1.729160742,277.4424579
72.2,37.26123726,0.978331288,164782.7579,1.74005239,278.5788597
72.4,37.64296488,0.98810091,165148.3104,1.741795104,279.5790732
72.6,38.11442162,0.997961978,165170.8914,1.747894495,280.7220209
72.8,38.00667671,1.007966047,165556.4259,1.750072816,281.8355408
73,38.36675182,1.018034977,166802.2308,1.743973528,282.9970089
73.2,39.00767865,1.02818373,169174.612,1.729596607,284.5921219
73.4,39.09017756,1.038477007,170778.6745,1.721754618,285.8788845
73.6,39.37292376,1.048858423,173170.4664,1.708684653,287.5611567
73.8,39.43461541,1.059360993,174985.4816,1.700842661,289.0887098
74,39.98157668,1.069932162,176670.625,1.69517906,290.7709866
74.2,40.35651033,1.080622609,177007.2882,1.699535772,291.9891119
74.4,41.11782793,1.091391067,177304.2194,1.70389253,293.1843603
74.6,41.22100015,1.102317818,177257.5154,1.712605878,294.55393
74.8,41.47206758,1.113343095,177389.4002,1.718705243,295.8428746
75,41.94415541,1.124462374,177436.0704,1.724368968,296.9269857
75.2,42.26997479,1.135704421,178061.0791,1.726547342,298.3859013
75.4,42.74784373,1.147047926,178846.0894,1.725676067,299.5669831
75.6,43.22818749,1.158505166,180108.6577,1.722626458,301.1359453
75.8,43.34870292,1.170104874,181065.6949,1.72175514,302.5578131
76,43.39191962,1.181826929,181740.7469,1.722190813,303.7236352
76.2,43.63538139,1.193651492,182762.2381,1.721755176,305.288236
76.4,44.05166606,1.205581768,183158.4584,1.726111895,306.6839595
76.6,44.35076489,1.217640905,183608.648,1.728725933,307.8530532
76.8,44.77116611,1.229811969,183463.9737,1.737439321,309.0657319
77,44.79766805,1.242135195,183660.296,1.743538661,310.3655688
77.2,44.85655815,1.254579777,183838.5082,1.748331004,311.4060925
77.4,45.06417202,1.267138151,184367.7918,1.751816365,312.7658576
77.6,45.74624976,1.279787031,185023.4054,1.752252116,313.8303601
77.8,45.6579979,1.292621757,186409.0381,1.747459771,315.2053745
78,46.09406777,1.305545422,188593.1811,1.73700382,316.8822021
78.2,46.55836997,1.318597049,189946.3158,1.731775875,318.2223593
78.4,46.72682592,1.331802268,191506.0342,1.726112226,319.8795716
78.6,47.54009365,1.345091689,192319.9647,1.725240991,321.3036294
78.8,47.98563581,1.3585426,192498.6545,1.729815548,322.6492347
79,48.33476395,1.372135991,191275.0028,1.745717435,323.705017
79.2,48.91861951,1.385848161,190938.6866,1.755520013,324.8441536
79.4,49.33875202,1.399710591,190737.6099,1.764015572,325.9309889
79.6,49.66163887,1.413719618,191391.7268,1.766193947,327.2471737
79.8,50.26495588,1.427848156,192679.7992,1.761837352,328.5633631
80,50.6127269,1.442138142,194778.1264,1.750510054,329.942743
80.2,51.23594186,1.456550666,196842.1202,1.740925456,331.6119482
80.4,51.46774667,1.471137872,198719.1179,1.733519146,333.3541468
80.6,51.7955053,1.4858643,199406.152,1.733954853,334.6016908
80.8,51.97491216,1.500749981,200386.943,1.733519209,336.0606053
81,52.32173584,1.515772476,202675.1624,1.724370243,337.8856121
81.2,52.57338941,1.530953001,204849.4964,1.714785599,339.4752738
81.4,53.16987159,1.54625968,207227.365,1.705200995,341.428852
81.6,53.57188221,1.561734855,209351.7738,1.696487702,343.091517
81.8,54.30459452,1.577340114,211432.4238,1.689081448,344.9154409
82,54.5640441,1.593138206,211867.7439,1.694309485,346.7665964
82.2,54.90988942,1.60908836,211932.8693,1.700408867,348.1274544
82.4,55.419826,1.625186324,213019.358,1.70171593,349.9524637
82.6,55.84539335,1.641452413,213833.2057,1.703022985,351.3939503
82.8,56.7794889,1.657843332,214308.8116,1.70737977,352.9454909
83,57.01595827,1.67445188,215255.191,1.709122468,354.7639599
83.2,57.43355276,1.691213603,215805.6266,1.713479188,356.5541018
83.4,57.80292419,1.708147361,215873.3082,1.718707244,357.8376033
83.6,58.06050298,1.725259807,216259.033,1.723063948,359.5144304
83.8,58.77508851,1.742509255,217303.3339,1.722192702,361.1662057
84,59.14230061,1.759958638,217928.2672,1.723935416,362.5662883
84.2,59.35741717,1.777594807,218959.9287,1.724371109,364.3586074
84.4,59.8271982,1.795388795,219639.0039,1.725678168,365.7586919
84.6,60.35844267,1.813356906,220245.4106,1.728727907,367.474748
84.8,60.77082961,1.831514566,220468.923,1.733520298,368.9391152
85,61.35353663,1.84984179,221712.5701,1.731777699,370.7554114
85.2,61.3894354,1.868394606,223633.1651,1.724371358,372.4082647
85.4,62.12539774,1.887080676,226057.3198,1.715222436,374.4457431
85.6,62.45249242,1.905985633,228020.1352,1.70868746,376.1683325
85.8,62.88176639,1.925072668,230570.013,1.699538495,378.1513272
86,63.35795977,1.944347961,232295.1686,1.696924547,380.280325
86.2,63.4439815,1.963845673,233173.7877,1.69953857,382.2306276
86.4,64.09337064,1.983496362,234177.4621,1.699974309,383.8508044
86.6,64.69370113,2.003348174,234928.8541,1.70345972,385.7629832
86.8,65.22835319,2.023404489,234914.6808,1.711301799,387.4267402
87,65.62253906,2.043673055,235227.3707,1.716529857,388.940138
87.2,65.98511566,2.064147695,235485.5629,1.723064914,390.7052215
87.4,66.25375981,2.084835089,235099.6719,1.731778297,392.0584526
87.6,67.0849386,2.10568758,235122.9601,1.739184746,393.7342019
87.8,68.07978552,2.126737241,235215.2306,1.744848546,395.2650445
88,68.68985906,2.148027542,234655.6333,1.753561972,396.482088
88.2,69.15115471,2.169543029,234193.3001,1.763146716,397.9780538
88.4,69.54843121,2.191279513,234124.2082,1.770553116,399.468571
88.6,69.86589971,2.213240542,234058.6879,1.776216835,400.6213265
88.8,70.33207708,2.235410887,234805.9334,1.777523896,402.0464728
89,70.91040024,2.257795457,236715.2052,1.77186029,403.7886804
89.2,71.27180405,2.280421406,238822.1637,1.764018318,405.3304067
89.4,72.02040459,2.303245146,241571.4796,1.753562387,407.3460964
89.6,72.90857197,2.326287679,244973.9014,1.73962113,409.5426549
89.8,73.02639169,2.349620399,246807.5178,1.735264468,411.413421
90,73.41424001,2.373166886,248259.8864,1.73265051,413.0488503
90.2,73.8028817,2.39694994,249791.894,1.730472219,415.0481898
90.4,74.67428012,2.420935128,251036.8838,1.728729654,416.6847178
90.6,75.35119282,2.445176205,253109.5578,1.723501724,418.7962873
90.8,75.55939864,2.469696477,256422.4479,1.710867384,421.0429528
91,76.17141769,2.494432459,259982.165,1.697797424,423.5718205
91.2,76.73021507,2.519420855,262685.3883,1.689084135,425.6496135
91.4,77.30974686,2.544658771,265660.445,1.681242183,428.2547491
91.6,77.9806453,2.570143345,266033.7328,1.686034609,430.0993785
91.8,78.81603556,2.595871417,265092.5936,1.698669077,431.924398
92,78.98411412,2.621908695,262877.6711,1.719145489,433.700377
92.2,79.57594692,2.648175343,260637.5338,1.737879281,434.8869141
92.4,80.33974901,2.674693017,257685.9361,1.76184111,436.2325306
92.6,81.07608674,2.701479078,257195.0963,1.770118893,437.4582945
92.8,81.56142808,2.728553351,258298.2861,1.770118954,439.1416676
93,82.13730218,2.755892724,260414.3446,1.76489101,441.1279366
93.2,83.05964815,2.783480442,262655.8043,1.757484769,442.8385581
93.4,83.72268668,2.811365166,266091.7206,1.744850478,445.1190103
93.6,84.35161088,2.839532396,268162.9545,1.740058207,447.3101178
93.8,84.8874212,2.867989753,268506.5827,1.743979286,449.0479696
94,85.55115584,2.896723436,268640.7678,1.748336048,450.6093164
94.2,86.0004537,2.925762041,269211.3853,1.752257117,452.5694346
94.4,86.76630576,2.955068416,269535.3055,1.756613893,454.0752173
94.6,87.61186075,2.984812157,270548.9618,1.758792339,455.9721518
94.8,88.22058868,3.014573223,271809.5641,1.75748541,457.4506916
95,88.29742262,3.044824265,273203.4368,1.757921089,459.4859817
95.2,89.29240871,3.075463111,274793.0102,1.756178539,461.4886046
95.4,89.97492438,3.106281187,276519.3938,1.75225761,463.2112069
95.6,90.76793513,3.137244016,279335.4724,1.743544342,465.4862174
95.8,91.61820872,3.168670169,281955.3515,1.735702418,467.6315699
96,92.13521184,3.200438445,285442.3506,1.724375106,470.2279907
96.2,93.08260817,3.232493699,287423.3547,1.720018538,472.2153614
96.4,93.43954702,3.264915977,288779.0563,1.720018582,474.5219589
96.6,94.42714264,3.297616118,288793.1959,1.72568239,476.2184181
96.8,94.98382653,3.330677616,289341.2554,1.729167805,478.2275716
97,95.84791773,3.364047852,289348.1368,1.735702936,480.2389107
97.2,96.46141724,3.397772497,289163.5763,1.743545044,482.2502435
97.4,97.34285181,3.431815506,289097.8674,1.74964451,483.8039713
97.6,97.91012413,3.466224632,290174.6416,1.750951586,485.8665128
97.8,98.84463173,3.500951545,290252.84,1.75705106,487.685003
98,99.61455122,3.536039767,290798.3972,1.759665167,489.2975651
98.2,100.1957837,3.571495089,292478.2724,1.757486897,491.4897638
98.4,101.3416061,3.607263614,294350.3774,1.753783855,493.5572237
98.6,101.8412895,3.643440635,296182.3132,1.750516403,495.6344728
98.8,102.8274503,3.679943758,298799.4475,1.743545826,497.78419
99,103.3432217,3.716849321,301168.1689,1.739624873,500.2204498
99.2,104.6483593,3.754065252,303151.5067,1.736139682,502.1969356
99.4,104.833285,3.791740328,305036.908,1.7348327,504.5569188
99.6,105.7086897,3.829741186,306272.7368,1.736575482,506.8232153
99.8,106.2487359,3.868148937,306945.9457,1.740060905,508.8792213
100,106.8352553,3.906938997,308202.3853,1.739625305,510.8415265
100.2,107.432931,3.946117789,310117.2961,1.73744704,513.3540578
100.4,108.3940953,3.985662548,312364.95,1.731783464,515.4612834
100.6,109.7432612,4.025575247,314869.7788,1.726991266,518.1492509
100.8,110.5056959,4.065933706,316748.2955,1.725248684,520.5234143
101,111.174997,4.106704676,317876.2898,1.726555778,522.5184099
101.2,111.976358,4.147875211,318749.3231,1.730476891,524.8773195
101.4,112.8324975,4.189455292,318599.3177,1.738319038,526.8325502
101.6,113.8260969,4.23144266,319357.0309,1.741368843,528.8836655
101.8,114.5915269,4.273869231,321313.8807,1.738754923,531.2000821
102,115.6930183,4.316696562,323234.6263,1.737012381,533.8335684
102.2,116.4205029,4.359982652,323870.1078,1.739626486,535.735953
102.4,117.3269934,4.403689927,324896.2264,1.741804943,538.1417174
102.6,118.1046131,4.447846233,326107.0797,1.741805038,540.166134
102.8,118.9619358,4.492440177,326395.3299,1.74703317,542.243941
103,119.8611516,4.537479133,327713.7715,1.748340285,544.6529723
103.2,120.6040723,4.582982284,330369.8259,1.742241012,546.8942124
103.4,121.7910764,4.628908993,334239.7875,1.732220764,549.7368952
103.6,122.6501879,4.67532049,337019.281,1.726121496,551.9901193
103.8,123.8337211,4.722172741,340414.0112,1.718279593,554.8121081
104,124.4496237,4.769539043,344287.0801,1.709130613,557.9914517
104.2,125.5017126,4.817347998,346309.6714,1.706516724,560.4015784
104.4,126.6509492,4.865629792,348274.4155,1.706081192,563.4240391
104.6,127.2500034,4.914438663,349636.2223,1.707823942,566.2885013
104.8,128.4256764,4.96369402,350766.522,1.7104381,568.8217559
105,129.2090505,5.01347409,351627.6688,1.713487881,571.0586366
105.2,130.1385967,5.06374318,351783.908,1.720894374,573.7051978
105.4,130.961698,5.114525388,351035.0972,1.730043533,575.6860354
105.6,131.825436,5.165814726,350227.9148,1.740499707,578.0253384
105.8,132.7148523,5.217617316,349301.6308,1.750520216,580.1369261
106,133.5493416,5.269944667,348671.1892,1.757926702,581.9183758
106.2,134.8582344,5.322761689,348733.4862,1.764026238,584.2533356
106.4,135.5945008,5.376152824,350256.6965,1.762719321,586.2723071
106.6,136.5467356,5.430063982,352945.4912,1.757927073,588.9591825
106.8,137.7041354,5.484501165,355606.5886,1.753570519,591.5904985
107,138.7176895,5.539496239,358003.236,1.750085287,593.8840452
107.2,139.8558022,5.595034335,360106.4799,1.749214087,596.588362
107.4,141.1342613,5.651119832,361262.6895,1.750521254,598.6574685
107.6,142.0935361,5.707793031,363100.6522,1.750521372,601.3171068
107.8,143.1948174,5.765024999,365286.8185,1.748343159,603.8579891
108,144.2694161,5.822833933,368068.4596,1.742679582,606.2659435
108.2,145.1436574,5.881238899,374608.3394,1.723510213,609.8059426
108.4,146.3152948,5.94020805,380679.0368,1.707390567,613.5082951
108.6,147.4702187,5.999770856,383549.5733,1.702162666,616.1831962
108.8,148.5220065,6.059939968,385474.5883,1.702162792,619.2437957
109,149.5662195,6.120714281,385024.9786,1.711747659,622.0734106
109.2,150.6078426,6.182099371,381861.3228,1.730481598,623.8385255
109.4,151.6352412,6.244102097,377933.523,1.75357224,625.8237344
109.6,152.7747226,6.306719255,377309.0417,1.762285784,627.6335259
109.8,154.130989,6.369949047,378917.8928,1.762721622,630.1035952
110,155.684927,6.433799151,381474.5293,1.759672122,632.9473906
110.2,156.6786849,6.498333398,385117.1948,1.75095884,635.5623619
110.4,158.0653918,6.563486063,390348.9165,1.737888901,638.9923362
110.6,159.3082357,6.629304444,392923.8426,1.73353235,641.6247491
110.8,160.1363172,6.695815448,394648.2369,1.734839463,644.9174207
111,161.6781018,6.762940412,395421.1322,1.737889343,647.2992447
111.2,162.6281236,6.830784968,396514.3196,1.740939153,650.2094867
111.4,163.5680654,6.89931172,397441.7536,1.742681951,652.4496498
111.6,165.1818204,6.96847571,399052.586,1.743117819,655.2150041
111.8,166.72317,7.038340147,400884.9174,1.742246666,657.9901598
112,168.126466,7.10891702,404394.6564,1.736147449,661.3209867
112.2,169.4615093,7.180208185,407209.552,1.731790905,664.0057037
112.4,170.9709441,7.252202431,411398.2759,1.724820358,667.5871343
112.6,172.0548036,7.324952498,414746.6367,1.71959244,670.4930246
112.8,173.470107,7.398408273,417923.0198,1.716542916,673.7759143
113,174.5686312,7.473000634,418964.9445,1.721335428,676.9923307
113.2,175.6978415,7.547968988,418481.9785,1.729177641,679.3207569
113.4,177.0961689,7.623671059,416300.8821,1.744426292,681.9542685
113.6,178.7354199,7.699733627,414540.9973,1.756189609,683.8730381
113.8,180.0653645,7.776968808,412953.1786,1.767517219,686.0467538
114,181.4039111,7.854979271,413198.3973,1.772745438,688.7260271
114.2,182.2740771,7.933809188,414708.1361,1.772309876,691.0435514
114.4,183.955152,8.013369426,419671.8588,1.760982636,694.4038107
114.6,184.8279736,8.093790813,424755.3333,1.749219624,697.3848768
114.8,186.0205934,8.174995754,430656.8811,1.736585307,700.9259879
115,187.3115547,8.257009294,435924.6627,1.727000698,704.6490589
115.2,188.8080522,8.339831209,439387.8142,1.722208496,707.6181633
115.4,190.3218682,8.423484024,442078.3244,1.721773008,711.2301086
115.6,191.8193466,8.507978507,442774.0149,1.725694231,713.9159263
115.8,193.288437,8.593324259,443539.6319,1.730051124,716.8686882
116,194.4540839,8.679550712,445436.2414,1.73135828,720.2093223
116.2,196.1019765,8.766606571,447134.1527,1.732447664,723.1931432
116.4,197.7576246,8.854536603,447774.251,1.737022412,726.0582002
116.6,199.0670296,8.943376562,449464.464,1.738765258,729.3443627
116.8,200.4568978,9.033102646,451603.6008,1.738329757,732.5662428
117,202.4100272,9.123685451,452788.1425,1.73963701,735.163828
117.2,204.0459937,9.215201934,455535.2685,1.737458851,738.7038691
117.4,205.8741859,9.307623202,458186.561,1.734845043,741.8729247
117.6,207.3702545,9.400997608,458935.716,1.738766276,744.8218765
117.8,209.1395666,9.495289148,459508.3607,1.743994558,747.7942638
118,210.6885186,9.590544724,459562.785,1.750094153,750.3079415
118.2,212.4288595,9.686742976,460607.8513,1.754015416,753.3881975
118.4,213.9226614,9.783926412,463702.5319,1.751401567,756.7560877
118.6,215.7071513,9.882064098,467768.7113,1.744431034,759.7731481
118.8,217.0892903,9.981218457,471186.1043,1.740074484,763.089828
119,219.0292743,10.0813266,475864.6116,1.733103967,767.1256376
119.2,220.5436367,10.18247305,477301.4111,1.734411166,769.9847053
119.4,222.6827351,10.28458831,476679.2072,1.743124875,773.1706654
119.6,224.167689,10.38777929,476845.7249,1.748353125,776.0596959
119.8,225.8839063,10.49198952,477314.7269,1.752927896,779.0849308
120,227.68264,10.59724039,476356.3894,1.76142373,781.6585458
120.2,229.5269098,10.70354537,477998.3791,1.763166639,784.9676145
120.4,230.9596744,10.81094978,479797.8716,1.763166825,787.6087724
120.6,232.3985,10.91943281,480677.059,1.767523728,790.7696493
120.8,234.172038,11.02898039,483554.6113,1.764909906,793.9033004
121,235.8573173,11.13963428,488627.9774,1.754889643,797.1186614
121.2,237.4850831,11.25139983,494429.3145,1.743998031,801.2361876
121.4,239.320416,11.36427252,499969.9083,1.732670757,804.8470657
121.6,241.0392314,11.4782881,506724.3372,1.719600781,809.4058662
121.8,243.0944126,11.59342362,511104.3403,1.713501608,813.4504111
122,244.7322572,11.70974775,513706.3775,1.712194786,816.852087
122.2,246.4945636,11.82723102,515535.9751,1.71524471,820.7833041
122.4,248.2730587,11.83241631,517612.1272,1.718294633,824.6676687
122.6,249.5047824,11.83232257,519986.6026,1.719166127,827.976724
122.8,250.3110434,11.83226105,523103.8912,1.718730551,831.6769135
123,250.8821365,11.83221732,525365.9161,1.721344658,835.7257567
123.2,251.6543273,11.83215838,528096.6309,1.720473405,839.093628
123.4,251.9969003,11.83213195,529369.5911,1.725265852,843.1032365
123.6,252.3793604,11.83210251,528150.8624,1.734850709,845.8304304
123.8,253.1449035,11.83204407,526911.2904,1.744871286,848.9008493
124,253.4492513,11.83202054,526605.8359,1.752713442,852.2490934
124.2,253.9596828,11.83198141,525911.5851,1.76142697,855.4219244
124.4,254.4077906,11.83194699,527424.1313,1.762734045,858.2417348
124.6,254.6556317,11.83192774,532723.8206,1.754891957,862.2633252
124.8,254.989064,11.83190201,537042.5587,1.749663919,865.9362587
125,254.9360894,11.83190553,540877.0989,1.7466142,869.9480311
125.2,255.209691,11.83188433,543310.9356,1.746178561,873.2101945
125.4,255.5190248,11.83186043,542514.9759,1.755327738,876.6336184
125.6,255.4228391,11.83186722,539385.9832,1.769269273,878.9293257
125.8,255.867623,11.83183306,536043.0884,1.784082221,881.3427285
126,256.0099294,11.8318218,531116.2128,1.803687539,883.6221029
126.2,256.043377,11.83181878,526804.4366,1.82024313,885.0995525
126.4,256.2355423,11.83180374,523254.6942,1.835491721,887.0019418
126.6,256.5698056,11.83177795,521363.1622,1.844640905,888.5840013
126.8,256.5525632,11.83177877,519242.2947,1.85466139,890.1104807
127,256.7189681,11.83176568,521417.1335,1.852918719,892.6055894
127.2,256.928584,11.83174933,526383.7913,1.84289826,895.5441526
127.4,256.8299054,11.83175631,530633.7793,1.834620454,898.0610401
127.6,257.1575208,11.83173102,537255.5922,1.821550296,901.6119445
127.8,257.2242078,11.83172548,542776.619,1.811529818,904.8675656
128,257.4446265,11.83170831,544113.2345,1.812401193,907.3180023
128.2,257.3542577,11.83171466,543284.5856,1.820243303,909.8632209
128.4,257.4633247,11.83170592,540831.2745,1.831135152,911.5106454
128.6,257.5973212,11.83169528,535451.6033,1.850740472,913.0033554
128.8,257.6448956,11.8316912,530532.2245,1.868167413,914.0700392
129,257.8063145,11.83167849,526550.6093,1.88298033,915.098596
129.2,257.7815933,11.83167987,523456.8256,1.894307835,915.9190369
129.4,258.0709836,11.83165747,521522.0684,1.902585668,917.0750768
129.6,258.1700789,11.83164948,522841.6545,1.901278662,918.7410273
129.8,257.9725133,11.83166395,524743.7703,1.898228923,920.4483654
130,258.6699161,11.83161067,527253.9863,1.893000935,922.1437554
130.2,258.3934072,11.83163111,530176.3425,1.887772819,924.2433349
130.4,258.1119124,11.83165194,531776.4554,1.886030089,925.8656816
130.6,258.4744291,11.83162401,531941.9674,1.889079851,927.5207456
130.8,258.6433269,11.83161073,530410.4212,1.896921995,928.6833205
131,258.7291265,11.83160375,528371.239,1.905635476,929.4994084
131.2,258.5859903,11.8316141,525756.3608,1.916527293,930.3503498
131.4,258.9215001,11.83158821,524704.6524,1.921755419,931.1522852
131.6,258.8672791,11.83159183,523538.399,1.927419167,932.0413663
131.8,258.8899239,11.83158962,524531.4005,1.926112151,933.2420678
132,258.9304349,11.83158607,526580.8465,1.921319749,934.5146814
132.2,259.0922693,11.83157333,528849.8192,1.916091691,936.1697381
132.9,259.1237046,11.74817897,1.7977E+308,1.955737977,0
133.1,258.8406528,11.62991584,1.7977E+308,1.954430917,0
133.3,258.6161853,11.51164827,1.7977E+308,1.876227509,0
133.5,258.4785555,11.39337412,1.7977E+308,1.722652617,0
133.7,258.1040957,11.27511791,1.7977E+308,1.488695962,0
133.9,257.9652194,11.15684386,1.7977E+308,1.089619128,0
134.1,257.8637374,11.03856698,1.7977E+308,0.711890301,0
134.3,257.6592135,10.9202979,1.7977E+308,0.41606807,0
134.5,257.4256052,10.80203102,1.7977E+308,0.176883386,0
134.7,257.0108427,10.68377786,1.7977E+308,0.032675501,0
134.9,257.0963318,10.56548682,1.7977E+308,0.023526361,0
135.1,256.8357166,10.44722199,1.7977E+308,0.022437177,0
135.3,256.3843909,10.32897159,1.7977E+308,0.023090687,0
135.5,256.3252889,10.2106915,1.7977E+308,0.024397706,0
135.7,256.1124553,10.09242305,1.7977E+308,0.028100929,0
135.9,255.7492137,9.974165987,1.7977E+308,0.030279295,0
136.1,255.5446899,9.855896907,1.7977E+308,0.037032231,0
136.3,255.4062291,9.737622826,1.7977E+308,0.04095329,0
136.5,255.1302408,9.619359156,1.7977E+308,0.040517616,0
136.7,254.7549501,9.501103005,1.7977E+308,0.036160882,0
136.9,254.5633064,9.38283295,1.7977E+308,0.030497129,0
137.1,254.3517193,9.264564405,1.7977E+308,0.016991257,0
137.3,254.3063285,9.146283277,1.7977E+308,0.007842119,0
137.5,253.9393477,9.028026497,1.7977E+308,0.005228079,0
137.7,253.6766551,8.909761821,1.7977E+308,0.013941544,0
137.9,253.4413849,8.791495069,1.7977E+308,0.027011741,0
138.1,253.3236987,8.673219414,1.7977E+308,0.032239819,0
138.3,252.9459151,8.554963452,1.7977E+308,0.034418185,0
138.5,252.6204834,8.436703525,1.7977E+308,0.03659655,0
138.7,252.2314815,8.318448412,1.7977E+308,0.03267549,0
138.9,252.6177861,8.200134602,1.7977E+308,0.021783661,0
139.1,251.9936162,8.081897292,1.7977E+308,0.018733947,0
139.3,251.7101491,7.963634189,1.7977E+308,0.019605293,0
139.5,251.3419218,7.845377503,1.7977E+308,0.01916962,0
139.7,251.1706373,7.727105906,1.7977E+308,0.015684234,0
139.9,251.0791271,7.608828271,1.7977E+308,0.007406444,0
140.1,250.6261397,7.490578001,1.7977E+308,0.011763175,0
140.3,251.0190921,7.372263688,1.7977E+308,0.021783658,0
140.5,250.2669511,7.254036067,1.7977E+308,0.031804139,0
140.7,250.1895676,7.135757362,1.7977E+308,0.038774909,0
140.9,250.1346206,7.017476958,1.7977E+308,0.04443866,0
141.1,249.6517178,6.899228953,1.7977E+308,0.041388946,0
141.3,249.5494048,6.780952135,1.7977E+308,0.035725195,0
141.5,249.1595721,6.662697085,1.7977E+308,0.022655001,0
141.7,248.8960486,6.544432471,1.7977E+308,0.016119904,0
141.9,248.7438767,6.426159428,1.7977E+308,0.021347981,0
142.1,248.5227333,6.307891607,1.7977E+308,0.036160866,0
142.3,248.2932801,6.189624414,1.7977E+308,0.047052692,0
142.5,247.9757428,6.07136389,1.7977E+308,0.046617018,0
142.7,247.6482338,5.953104121,1.7977E+308,0.039210575,0
142.9,247.3448232,5.834842528,1.7977E+308,0.018733941,0
143.1,246.9641313,5.716586785,1.7977E+308,0.012198845,0
143.3,246.7122416,5.598321291,1.7977E+308,0.022654997,0
143.5,246.6124216,5.480044285,1.7977E+308,0.03311115,0
143.7,246.6746431,5.36175501,1.7977E+308,0.035289515,0
143.9,246.2175009,5.243505055,1.7977E+308,0.026576054,0
144.1,245.9813999,5.125238366,1.7977E+308,0.021347977,0
144.3,245.6663556,5.006977653,1.7977E+308,0.012198844,0
144.5,245.3679309,4.888715683,1.7977E+308,0.00435673,0
144.7,244.9240845,4.770464721,1.7977E+308,0.002614038,0
144.9,244.6264908,4.652202687,1.7977E+308,0.007842113,0
145.1,244.3579815,4.533938452,1.7977E+308,0.013505861,0
145.3,244.2465278,4.415662326,1.7977E+308,0.013070188,0
145.5,243.820132,4.297410043,1.7977E+308,0.012634515,0
145.7,243.7959314,4.179127312,1.7977E+308,0.013941534,0
145.9,243.2648319,4.060882956,1.7977E+308,0.010020477,0
146.1,243.0387027,3.942615512,1.7977E+308,0.006535094,0
146.3,242.7195036,3.824355114,1.7977E+308,0.009584804,0
146.5,242.419417,3.706093269,1.7977E+308,0.015684224,0
146.7,242.1957808,3.587825636,1.7977E+308,0.019169607,0
146.9,241.9048351,3.469563099,1.7977E+308,0.026576045,0
147.1,241.5756642,3.351303455,1.7977E+308,0.036160848,0
147.3,241.1816767,3.233048719,1.7977E+308,0.034853828,0
147.5,241.0876737,3.114771272,1.7977E+308,0.025269025,0
147.7,240.7900801,2.996509239,1.7977E+308,0.017862586,0
147.9,240.5149231,2.878245506,1.7977E+308,0.006535092,0
148.1,240.3004277,2.759977181,1.7977E+308,0.008277784,0
148.3,239.9688579,2.641126299,1.7977E+308,0.01699124,0
148.5,239.5158238,2.523171744,1.7977E+308,0.021130131,0
148.7,239.1812046,2.405208223,1.7977E+308,0.028318731,0
148.9,239.0290798,2.286639466,1.7977E+308,0.035725168,0
149.1,238.5818627,2.16868447,1.7977E+308,0.041388913,0
149.3,238.154636,2.050432251,1.7977E+308,0.039646221,0
149.5,237.5661991,1.932192236,1.7977E+308,0.038774874,0
149.7,237.3870204,1.813921237,1.7977E+308,0.032675455,0
149.9,237.0013429,1.695665872,1.7977E+308,0.028754399,0
150.1,236.5845036,1.577412866,1.7977E+308,0.031368435,0
150.3,236.4148813,1.459141144,1.7977E+308,0.034853816,0
150.5,235.9477676,1.340891944,1.7977E+308,0.034418142,0
150.7,235.4428444,1.222645606,1.7977E+308,0.033111123,0
225.9,234.8342647,1.110729921,1.7977E+308,0.0143772,0
226.1,234.5183896,0.992469271,1.7977E+308,0.024833345,0
226.3,234.004741,0.874223594,1.7977E+308,0.026140362,0
226.5,233.5692046,0.755972003,1.7977E+308,0.02439767,0
226.7,233.2533296,0.637711354,1.7977E+308,0.016119889,0
226.9,232.7338642,0.519466117,1.7977E+308,0.003485381,0
227.1,232.2011031,0.401221887,1.7977E+308,0.011763161,0
227.3,231.2021615,0.283012951,1.7977E+308,0.020912285,0
227.5,230.1093192,0.164811123,1.7977E+308,0.022654974,0
227.7,228.9508295,0.046614265,1.7977E+308,0.016991229,0
227.774,228.3230271,0.002896506,1.7977E+308,0.015248538,0
,,,,,