File: TestGB_16.csv
Time On Sample,Displacement Into Surface,Load On Sample,Harmonic Contact Stiffness,Harmonic Displacement,Harmonic Load
0,0,0,865.5315521,0.251836631,2.250061011
0.2,0.115255585,0.000749099,6678.47158,0.189966734,2.319796574
0.4,0.145745082,0.001504605,13319.95173,0.161646005,2.401517921
0.6,0.10975137,0.002265134,16505.09502,0.147703492,2.483239257
0.8,0.361297534,0.003003934,17932.67657,0.142039349,2.561691788
1,0.375166229,0.003760695,18256.1361,0.144217867,2.628158475
1.2,0.417290287,0.004515321,19331.09872,0.149882013,2.894025261
1.4,0.460245386,0.005269884,19632.68884,0.159031788,3.133741211
1.6,0.553062892,0.006020679,19660.64427,0.169924377,3.377815654
1.8,0.409865005,0.006789309,20455.53366,0.173845707,3.622979667
2,0.524289553,0.007538472,21614.9873,0.173410005,3.834365572
2.2,0.501592483,0.008297996,24306.95381,0.174281412,4.299632433
2.4,0.66338632,0.009043579,27453.66291,0.173410007,4.755092774
2.6,0.752048816,0.009793494,31118.04916,0.16992438,5.20183616
2.8,0.729352107,0.010550743,34724.82425,0.166003047,5.640952194
3,1.108047786,0.01127766,36608.26199,0.16818157,6.014691265
3.2,0.87509792,0.012050797,39623.84099,0.174281416,6.752362564
3.4,0.891460097,0.012805095,42050.35553,0.179945563,7.436642657
3.6,1.093144227,0.013545388,44179.33843,0.185609711,8.118743587
3.8,0.991083183,0.014308635,43875.1676,0.202166445,8.815009435
4,1.052321529,0.015059541,43373.75545,0.218287477,9.394686227
4.2,1.073669947,0.015813462,45252.48347,0.234844212,10.50936543
4.4,0.835733841,0.016586976,45957.23416,0.254015164,11.47803568
4.6,1.218169203,0.01731361,44874.68841,0.283207309,12.43689973
4.8,1.052533587,0.01808166,43890.7672,0.312399444,13.37723995
5,1.147844579,0.018829992,42887.88472,0.338977362,14.16939229
5.2,1.01794369,0.019595342,42324.87882,0.373397939,15.39630205
5.4,1.245390067,0.020333688,41781.94923,0.405640008,16.50771255
5.6,0.940139706,0.021112289,41611.48039,0.434396433,17.60495762
5.8,1.116061592,0.021854529,41250.54497,0.464895687,18.67714184
6,1.063447437,0.022614039,40584.23916,0.495394935,19.58370399
6.2,1.16457571,0.02336193,39600.59285,0.540708106,20.86727406
6.4,0.772066136,0.024147125,38331.87292,0.588635481,22.00156597
6.6,0.790090394,0.024901298,36670.16145,0.643534128,23.00837301
6.8,0.923629231,0.025646741,34772.08471,0.707582555,23.99011886
7,0.77129026,0.026413786,33264.5485,0.7633526,24.75612019
7.2,0.990426232,0.027152761,31328.75258,0.841343547,25.72588035
7.4,0.950277679,0.027911329,29750.65617,0.905391965,26.35785878
7.6,0.80957327,0.028677496,27944.4128,0.985561408,27.09552991
7.8,0.998791797,0.029418731,26159.62976,1.07139502,27.77981028
8,1.194658648,0.030159464,24783.6334,1.144157527,28.30500633
8.2,0.930129254,0.030934988,23626.7769,1.212562963,28.78116906
8.4,0.949815592,0.031689034,22853.68223,1.267897315,29.21374749
8.6,1.101637314,0.032433096,21977.99051,1.337609896,29.68991066
8.8,1.221048471,0.033179606,21382.61281,1.38815152,30.02442365
9,1.372870196,0.033923666,20783.68637,1.441743072,30.34695078
9.2,1.720817406,0.034652905,20311.53412,1.493591831,30.71960066
9.4,1.859342494,0.03539797,20329.28506,1.514069913,31.1260285
9.6,1.972936376,0.036144918,20839.63001,1.499691707,31.54662117
9.8,1.955225907,0.036901788,22147.48762,1.448714387,32.20366083
10,2.102061398,0.037646224,23961.29845,1.376823311,32.91082324
10.2,1.836700948,0.038421809,26298.85794,1.292296793,33.70188543
10.4,2.024257409,0.039163168,29002.56349,1.211255945,34.64004682
10.6,2.192699947,0.039905972,31138.75571,1.161150047,35.54007156
10.8,1.594092378,0.040706741,31998.90288,1.150693114,36.16986972
11,1.556436944,0.041465119,31713.97073,1.177271029,36.71358899
11.2,2.466998386,0.042151842,29804.1522,1.265718931,37.20936688
11.4,2.28058675,0.04292146,28131.11684,1.346324078,37.48068143
11.6,2.460663855,0.043663383,26505.07551,1.434771924,37.75199675
11.8,2.773707401,0.044395258,25612.96015,1.489670608,37.97210017
12,2.585633681,0.045165002,25651.16639,1.500127475,38.34039071
12.2,2.729976059,0.045909625,27292.09254,1.436514765,39.06498705
12.4,2.570157707,0.046677233,29886.39588,1.34327418,39.9312332
12.6,2.772672902,0.04741746,32188.82542,1.272690216,40.68415961
12.8,2.700113776,0.048178474,34581.19531,1.209513188,41.46541561
13,2.744731324,0.048930633,36339.72376,1.173785497,42.23141705
13.2,2.787686793,0.049682918,36840.87676,1.181192461,43.05081007
13.4,3.001836555,0.050422266,36443.36099,1.20907751,43.58799216
13.6,2.499629619,0.051215747,35973.65849,1.243062349,44.23304513
13.8,2.766965352,0.051954854,35406.86062,1.276611549,44.70158133
14,2.750917563,0.052707819,34869.85758,1.308853614,45.16248979
14.2,2.880301218,0.053453573,34422.25839,1.342402803,45.77485536
14.4,3.0287988,0.054197881,34255.11653,1.361138072,46.23031605
14.6,3.066768028,0.054950543,33913.58332,1.388587403,46.75224322
14.8,3.017478028,0.055709797,33682.56032,1.410808282,47.2534675
15,2.893394404,0.056474705,33563.95879,1.428236415,47.69912098
15.2,3.056019671,0.057217946,33529.16357,1.441743243,48.15894018
15.4,3.136371953,0.057967404,33467.40231,1.458299988,48.68631559
15.6,2.922535979,0.058739093,33491.68259,1.467449743,49.09819079
15.8,3.435860245,0.059455832,33379.65642,1.484442235,49.58307201
16,3.049167891,0.060240584,33284.98764,1.497949008,49.98078159
16.2,3.126196011,0.060990294,33050.13374,1.519298493,50.45149669
16.4,3.43009813,0.061722858,32836.98854,1.537162374,50.79581691
16.6,3.422360143,0.062478973,32675.95989,1.554590518,51.1270607
16.8,3.51351595,0.063227614,32587.43738,1.571582969,51.51823385
17,3.894704827,0.063954337,32436.13934,1.591625377,51.82986568
17.2,3.827962977,0.06471491,32428.27818,1.611667737,52.21341107
17.4,4.064550844,0.06545256,32758.50457,1.612539171,52.55119327
17.6,4.057643897,0.06620861,33413.06194,1.598596654,52.94890403
17.8,3.877049523,0.066977786,34701.92831,1.561997529,53.52313211
18,4.087875141,0.067717383,36471.04994,1.507534596,54.1431256
18.2,3.961298387,0.068482477,39316.37835,1.424750893,55.05949398
18.4,3.753279684,0.069253725,41900.5874,1.359831032,55.93554649
18.6,3.931694727,0.069995772,43485.32411,1.327588979,56.62636491
18.8,4.222300218,0.07072934,44504.03186,1.3149536,57.39781525
19,4.171348133,0.071488719,44598.73963,1.324974779,57.96768542
19.2,4.087985476,0.072250547,44145.80103,1.353731214,58.65523424
19.4,4.020412585,0.073011181,43653.31757,1.379437721,59.13575594
19.6,4.144810011,0.073757309,43529.09733,1.396865881,59.73940475
19.8,3.778893645,0.074540489,43875.89908,1.402094288,60.39644343
20,4.151772125,0.07526784,44002.48699,1.411244104,60.9227301
20.2,4.088354436,0.07602816,44112.76348,1.421700979,61.47952479
20.4,4.18283441,0.076776549,44074.62784,1.438693433,62.12239979
20.6,3.735476092,0.077565884,43600.17948,1.467449832,62.65849057
20.8,4.022341898,0.078299734,42813.8857,1.501870447,63.00172116
21,4.363225331,0.079029503,42160.97725,1.534330404,63.42449405
21.2,4.593995925,0.079767592,41552.27716,1.56548324,63.81675731
21.4,4.477391651,0.080531931,41187.38969,1.58857552,64.24061842
21.6,4.640432457,0.081275137,41126.13586,1.598596721,64.59583434
21.8,4.667182645,0.082028643,41824.68689,1.585089913,65.17115295
22,4.671910264,0.082783813,42818.15161,1.560690508,65.72141015
22.2,4.795476654,0.083530003,44483.28495,1.520170079,66.52554861
22.4,4.820980281,0.084283611,46046.69305,1.4866209,67.30571519
22.6,4.720996144,0.085050895,47253.02352,1.463092892,67.93878274
22.8,4.700790675,0.085819758,48135.77278,1.452636003,68.6590207
23,4.863412879,0.086582398,48290.38405,1.461350092,69.21581605
23.2,4.927140042,0.087360298,48119.8834,1.480956764,69.85869096
23.4,5.06649062,0.08814042,47937.10916,1.498820629,70.43509945
23.6,4.987276327,0.088944911,47764.75354,1.513634546,70.88293239
23.8,5.016927066,0.089749101,47660.60822,1.527577066,71.42229342
24,5.260984944,0.090545148,47709.70451,1.534984054,71.90717418
24.2,5.05461762,0.091383479,48057.6623,1.537598255,72.57619934
24.4,5.004484573,0.092218288,48339.80891,1.541955287,73.18965407
24.6,5.002550528,0.093057885,48524.55858,1.546312323,73.66363792
24.8,4.944104404,0.093910138,48835.31703,1.549797947,74.28254085
25,5.178183154,0.094748728,49060.27632,1.553283601,74.78158708
25.2,5.006712827,0.095626573,49257.26776,1.559819138,75.4233714
25.4,4.861003361,0.096511226,49404.05483,1.56417616,75.89408577
25.6,5.213085712,0.097366904,49761.58685,1.564611901,76.51299042
25.8,5.202001984,0.098259022,49855.42362,1.572454566,77.05888915
26,5.362111192,0.099146921,50040.1503,1.57681162,77.55793476
26.2,5.482329036,0.100046814,50082.24076,1.587704225,78.15831504
26.4,5.432182147,0.100968695,50070.22321,1.596418294,78.58653486
26.6,5.889799507,0.10186131,49898.8208,1.611667973,79.08885031
26.8,5.734107586,0.102809383,50076.76541,1.616024993,79.6194941
27,5.609993664,0.103764753,50192.88353,1.62081772,80.07495382
27.2,5.834084204,0.10470309,50411.4761,1.622996264,80.55329726
27.4,5.676725652,0.105679921,51042.0222,1.616024988,81.17437886
27.6,5.897488976,0.106637735,51806.5902,1.603825309,81.7170098
27.8,5.910490637,0.107621033,52736.39067,1.589882792,82.39802132
28,5.93761843,0.108613049,53457.98507,1.580297314,82.97007099
28.2,6.020424335,0.109610914,54676.38725,1.560690656,83.78510583
28.4,5.87219937,0.11063647,55203.46912,1.556769307,84.36260272
28.6,6.265811176,0.11163114,55581.40649,1.559383572,85.04797422
28.8,5.910653916,0.11269261,55992.83938,1.560690645,85.73443249
29,6.051626131,0.113727098,56324.03039,1.561997772,86.29558631
29.2,6.07292687,0.114781024,56541.73476,1.567226218,86.8828907
29.4,6.083422402,0.115846348,57047.1743,1.566354812,87.581336
29.6,6.097240401,0.116922081,57737.56323,1.560690666,88.31247007
29.8,6.119367091,0.118007963,58009.69128,1.562869187,88.83984527
30,6.304375986,0.119092386,58273.38832,1.568533355,89.57533847
30.2,6.290764466,0.120202805,58504.80506,1.572018984,90.15174637
30.4,6.311223824,0.121321852,58899.84088,1.57245469,90.84147482
30.6,6.291791452,0.122455155,59283.75781,1.573326095,91.5279343
30.8,6.352968193,0.123593773,59535.16466,1.575504621,92.07274363
31,6.557082098,0.124732895,59877.17362,1.57637605,92.65677979
31.2,6.692217832,0.125888637,60138.21176,1.582475917,93.39445205
31.4,6.877213187,0.127058287,60012.74031,1.59685416,94.01226663
31.6,6.742257014,0.128258029,59874.43391,1.610796665,94.59303245
31.8,6.757718227,0.129452334,59924.73672,1.617767926,95.0898987
32,6.900325778,0.130655005,60158.26398,1.620382164,95.63579807
32.2,7.225760321,0.131855945,60941.38058,1.611232422,96.40398058
32.4,7.1464762,0.133099661,62057.64797,1.594675672,97.19286375
32.6,7.329798906,0.13433596,63023.38668,1.580297468,97.86080066
32.8,7.101754557,0.135615929,64337.4859,1.56112648,98.72268755
33,7.188672548,0.13688477,65073.54495,1.554155229,99.42222276
33.2,7.471714072,0.138151564,65520.10539,1.557205186,100.2743062
33.4,7.242001552,0.139469961,65327.88563,1.572890496,100.9716605
33.6,7.520052708,0.140763089,65271.09192,1.583347416,101.5142918
33.8,7.514716969,0.142090698,65204.35731,1.595982824,102.1669734
34,7.557579451,0.143428059,65467.54025,1.599468459,102.7608154
34.2,7.560549863,0.144781803,66168.6526,1.59598283,103.5987319
34.4,7.885961856,0.146124707,67151.9526,1.585961679,104.4606217
34.6,7.87646235,0.147506502,67751.86879,1.581604641,105.0980485
34.8,7.726514762,0.148912945,68338.01129,1.580297513,105.9010962
35,7.826708149,0.150314506,68760.38636,1.580733228,106.5842877
35.2,7.803905313,0.151739342,69212.14731,1.583347448,107.4461757
35.4,7.866697382,0.153171999,69654.97679,1.582911752,108.0955886
35.6,7.709261411,0.154635738,70198.54593,1.582911735,108.9149806
35.8,8.15017232,0.156068843,70560.5208,1.584218894,109.5731124
36,8.217112677,0.157544703,70967.19848,1.585526015,110.2857231
36.2,8.411199877,0.159025832,71157.33153,1.593368705,111.1399849
36.4,7.986159467,0.160568746,71193.55014,1.603389845,111.9048954
36.6,8.001568122,0.162093703,71135.76849,1.612539626,112.487841
36.8,8.197310145,0.163620356,71176.66014,1.622560832,113.2298719
37,8.199417276,0.165176994,71197.20423,1.6304035,113.8084594
37.2,8.160800926,0.166752385,71281.91744,1.637810466,114.4339006
37.4,8.56180255,0.168310245,71580.43746,1.642167545,115.1879188
37.6,8.488277498,0.169919713,72085.9756,1.639989016,115.8166282
37.8,8.413087777,0.171545585,72676.97537,1.63781049,116.6055115
38,8.406871847,0.173182466,73207.76486,1.635631975,117.2952399
38.2,8.437219089,0.174833021,73643.90345,1.635196275,117.9904166
38.4,8.593881878,0.176490532,73812.99518,1.641731847,118.7411646
38.6,9.269111386,0.178125396,73627.40913,1.653495925,119.2870673
38.8,9.503886756,0.179810023,73378.66377,1.66787418,119.9092408
39,9.500981818,0.181529505,73333.49253,1.676588254,120.4486019
39.2,9.854175046,0.183239413,73695.09998,1.679202517,121.1884545
39.4,9.695444464,0.185005394,74242.91035,1.675281161,121.8117156
39.6,9.595714948,0.186784674,75191.70255,1.664824259,122.6365559
39.8,9.503461971,0.188581173,76154.00827,1.652624551,123.341539
40,9.605254124,0.19038101,77113.61352,1.641296255,124.1184367
40.2,9.613966843,0.192206008,77791.8836,1.637810625,125.0348062
40.4,9.665059725,0.194046113,78107.13836,1.639553447,125.6842192
40.6,9.914768391,0.195889675,78634.78536,1.640424882,126.5286749
40.8,9.948403537,0.197768109,78548.9445,1.650881778,127.117069
41,9.757654681,0.199682507,78474.69492,1.661338648,127.7185372
41.2,10.00818539,0.20158261,78748.44725,1.666567123,128.5096018
41.4,10.33766194,0.203495841,79206.07116,1.665695753,129.1655542
41.6,10.56657949,0.205436036,79614.96908,1.66700289,129.9631564
41.8,10.26445891,0.207436008,80452.34269,1.65828878,130.6866614
42,10.48672185,0.209416189,81565.30613,1.64521769,131.4875324
42.2,10.3757343,0.211441566,82759.88774,1.633453674,132.5041458
42.4,10.70270198,0.213454068,83547.34546,1.627353857,133.2908521
42.6,10.69974327,0.215511855,84409.17888,1.622125411,134.2475374
42.8,10.74082642,0.217586993,84767.06199,1.623868231,134.9634172
43,10.52511468,0.219702451,84632.21259,1.634760803,135.6553233
43.2,10.68835415,0.221810326,84070.8054,1.655674606,136.4289536
43.4,10.76433097,0.223946033,83434.43973,1.67440988,136.9171031
43.6,10.67160309,0.226116048,82729.89514,1.696195062,137.5218407
43.8,11.00270255,0.22827566,82060.84974,1.715801774,137.9576904
44,10.8659226,0.230492533,81483.1134,1.735408432,138.5406352
44.2,11.07983832,0.232705034,81444.50763,1.741944015,139.0320548
44.4,11.14582525,0.23495098,81872.32057,1.741072615,139.70326
44.6,11.179398,0.237221979,82295.26036,1.7388941,140.2546075
44.8,11.24703979,0.239513257,82994.04603,1.733229958,140.9944591
45,11.24985676,0.241832321,83832.85882,1.724080178,141.6765601
45.2,11.2684598,0.244173485,84401.82261,1.720594549,142.3346899
45.4,11.77571108,0.246501205,84847.17649,1.720594609,143.0810821
45.6,11.99126333,0.24887443,85173.73637,1.721030338,143.6564021
45.8,12.25584321,0.25126772,85769.76048,1.717980442,144.3995241
46,12.33509715,0.253699184,85915.92972,1.722337491,144.9922771
46.2,12.34786393,0.256160148,86325.31758,1.721901789,145.6340625
46.4,12.61908049,0.258626254,86770.34995,1.721901821,146.3760944
46.6,12.81051321,0.261123058,87134.83034,1.721901843,146.9808346
46.8,13.09751163,0.2636378,87581.70856,1.721901877,147.7370318
47,12.91413689,0.266213545,88236.70287,1.717109113,148.4245801
47.2,13.07480896,0.26878905,88943.35403,1.711880685,149.1426399
47.4,13.26207024,0.271388394,89784.92903,1.705780852,150.0067088
47.6,13.3770268,0.274019375,90443.8996,1.700988123,150.69099
47.8,13.48948605,0.276676855,91043.75406,1.698809616,151.5267287
48,13.64931039,0.279357468,91362.98396,1.700116747,152.2012036
48.2,13.65538787,0.282076739,91540.94318,1.704038083,152.8800361
48.4,13.79692065,0.284813245,91701.13806,1.709266547,153.6449494
48.6,13.77307194,0.28758964,91974.57016,1.711445064,154.2834656
48.8,13.88384741,0.290383769,92060.18741,1.718416341,155.0091526
49,13.83090338,0.293218286,92189.55236,1.722773374,155.6193386
49.2,13.95496424,0.296082346,92531.29428,1.723644797,156.2894551
49.4,13.99093245,0.298967584,93494.62045,1.715366426,157.1665982
49.6,13.99614755,0.301884092,94407.71927,1.70795946,158.0557272
49.8,14.01798117,0.304813784,95433.78359,1.697502568,158.8282671
50,14.36557579,0.307763101,96455.04421,1.688352826,159.6716348
50.2,14.37160549,0.310783008,97217.07647,1.686174307,160.6893386
50.4,14.70257221,0.313778178,97061.6603,1.695324128,161.3147824
50.6,15.05513879,0.316817192,96724.1201,1.708395288,162.0328437
50.8,14.789406,0.31993366,96292.81329,1.721466377,162.5809205
51,14.74888037,0.323064258,95966.81817,1.732794676,163.1355362
51.2,14.84214733,0.326216127,95785.54275,1.742815878,163.8644911
51.4,15.18389051,0.329380941,96063.29035,1.743687327,164.4452607
51.6,15.04611799,0.33261382,96837.77551,1.738894567,165.2450401
51.8,15.23660152,0.335854176,97800.51704,1.731487622,166.089496
52,15.55506023,0.339117172,98521.57675,1.727566324,166.8249909
52.2,15.54691458,0.342437916,99384.85987,1.721902172,167.606248
52.4,15.57532944,0.345789163,100242.4399,1.717109431,168.4877497
52.6,15.35608874,0.349192738,100729.9588,1.71754511,169.3245752
52.8,15.89475203,0.35257306,101100.7491,1.717980877,170.0012328
53,15.97301317,0.35602237,101406.121,1.719723703,170.7214711
53.2,15.89835726,0.359517801,101639.6397,1.724080734,171.5964351
53.4,16.0788254,0.363028902,101834.8965,1.727566388,172.2567454
53.6,16.24349815,0.366576447,102255.0313,1.727566407,172.9475649
53.8,16.52118681,0.370151154,102597.73,1.730616368,173.7582436
54,16.50717438,0.373783725,102975.0708,1.731923482,174.4621376
54.2,16.57709127,0.377446507,103624.1219,1.730616379,175.3665217
54.4,16.923739,0.381125185,103777.6709,1.734102049,176.0235647
54.6,17.08505868,0.384854908,103734.0802,1.741944748,176.7710455
54.8,17.44748436,0.388606859,103720.8408,1.747608941,177.3692494
55,17.84397676,0.392393787,103978.6193,1.748916103,178.026293
55.2,18.04766155,0.396233528,104477.7505,1.748480419,178.9001691
55.4,17.98748464,0.400131848,105299.4366,1.742380558,179.6400198
55.6,18.20112956,0.404048665,106606.4756,1.730616572,180.6195891
55.8,18.40645779,0.408005614,107798.8649,1.719288293,181.4520598
56,18.55028266,0.412006923,108492.7322,1.71623838,182.2561998
56.2,18.59520723,0.416056001,108835.9752,1.71972402,183.2117961
56.4,18.24787389,0.420175471,108819.7281,1.725823837,183.8721021
56.6,18.32353396,0.424304127,108743.9183,1.734537927,184.6675246
56.8,18.48644676,0.428467723,108619.1873,1.742380619,185.2646372
57,18.58910242,0.43267767,109044.1785,1.742380627,185.9772481
57.2,18.80227986,0.436921419,110384.205,1.731923755,187.0450769
57.4,18.86337,0.441219257,111716.216,1.721466863,188.088933
57.6,19.5780672,0.445510751,112923.7935,1.711445753,188.9846048
57.8,19.78000511,0.44988425,114224.6452,1.70229599,190.1069157
58,20.0650402,0.454295214,114469.6591,1.705781656,190.9077876
58.2,20.28857116,0.458755357,114366.8425,1.713624363,191.6814199
58.4,20.39076295,0.4632696,114144.3208,1.722338452,192.3755071
58.6,20.21205558,0.467850473,113587.9574,1.736716668,193.1643898
58.8,20.52864151,0.472439783,113291.8823,1.747173605,193.9282155
59,20.39313366,0.477109408,113507.6682,1.749787814,194.6277502
59.2,20.84765767,0.481781255,114041.5145,1.74891646,195.4024731
59.4,20.60243743,0.486553123,114830.7206,1.745866502,196.309034
59.6,20.89572435,0.4913321,115881.6483,1.738023862,197.1273409
59.8,21.15659304,0.496161432,117196.2459,1.728874106,198.1995285
60,21.2886426,0.501049152,118125.5717,1.723645672,199.0755835
60.2,21.25032089,0.505998811,118920.6297,1.720595739,199.9756085
60.4,21.32335083,0.510989709,119789.8392,1.717981523,201.0456153
60.6,21.43293861,0.516028036,120029.4844,1.721467169,201.8061705
60.8,21.80512741,0.52109709,120494.7926,1.723645734,202.8031751
61,21.68200746,0.52625465,120444.4037,1.730616987,203.5669978
61.2,21.90957872,0.531437473,120391.1037,1.737152576,204.3122989
61.4,21.941847,0.536687083,120360.0361,1.744559552,205.1938011
61.6,22.61151566,0.541941127,120483.1558,1.748480969,205.8682825
61.8,23.05180851,0.547265352,120539.3505,1.754580881,206.684411
62,23.41563707,0.552648806,121130.2846,1.753273812,207.4798369
62.2,23.38554337,0.558116214,122513.1725,1.743688316,208.6108617
62.4,23.41444488,0.563634092,123907.3307,1.73236001,209.5381276
62.6,23.65857732,0.569191146,125770.4466,1.71711039,210.743249
62.8,23.85948674,0.574807272,127544.6034,1.70229647,211.8012715
63,23.99307283,0.580484864,129203.0202,1.690096767,212.9453728
63.2,24.52887394,0.58618912,130713.7758,1.682254152,214.3379119
63.4,24.36160481,0.592003961,130968.2425,1.686611176,215.277162
63.6,24.71289634,0.597837786,130687.5736,1.698375232,216.3079455
63.8,25.14562062,0.60372414,130240.7704,1.710139298,217.0848488
64,25.13206617,0.609703515,129778.4127,1.721903312,217.8475822
64.2,25.4625534,0.61571683,129343.8515,1.73497448,218.8413182
64.4,25.65923332,0.621800777,129846.3968,1.734538799,219.6770582
64.6,25.83097228,0.627947718,130787.1076,1.730617481,220.8124438
64.8,26.30686265,0.634133417,131365.4574,1.729746129,221.6710684
65,26.67720089,0.640389181,132170.3712,1.727131946,222.6321172
65.2,26.75084726,0.646730308,132932.7593,1.726696251,223.8165339
65.4,26.92254642,0.653127683,133319.3282,1.728439089,224.6675283
65.6,26.95462036,0.659600003,133958.7611,1.728874797,225.7789408
65.8,27.2684071,0.666115905,134935.8844,1.723646383,226.7552427
66,27.06610653,0.672736514,135852.417,1.719289316,227.7849312
66.2,27.11726313,0.679404258,137302.8055,1.71101094,229.1545843
66.4,27.31550345,0.686127938,138504.9628,1.704039694,230.2398464
66.6,27.81041493,0.692896645,140306.3406,1.693147142,231.6650743
66.8,27.76347089,0.699809121,141544.0322,1.687047276,232.7677688
67,27.64671376,0.706761989,142766.1034,1.681818811,233.9652593
67.2,27.77510843,0.713730951,144315.7494,1.67528326,235.4831004
67.4,28.06055328,0.720793144,145030.6448,1.675283293,236.5803504
67.6,28.60111666,0.727907069,145104.5688,1.683561739,237.8508526
67.8,28.83252113,0.735116024,145164.4128,1.689661627,238.8195269
68,29.08385913,0.742395647,144701.8205,1.701861379,239.7576926
68.2,29.10000067,0.749766337,143732.3916,1.721032375,240.8157134
68.4,29.38538799,0.757190605,143302.2394,1.731925019,241.5991532
68.6,29.65497366,0.764690701,143200.529,1.740639139,242.6430121
68.8,30.13064573,0.772250574,143898.9123,1.740203492,243.747892
69,30.0835804,0.77992603,145569.9855,1.728439467,244.8941711
69.2,30.24177015,0.787663038,147247.5075,1.717111171,246.1298011
69.4,30.36753691,0.795480285,149494.623,1.701425826,247.6618082
69.6,30.63290625,0.803365339,151567.5971,1.68704761,248.993326
69.8,31.06031616,0.811317378,152853.2739,1.682690615,250.470856
70,31.24089393,0.819368047,152661.031,1.69184043,251.5354158
70.2,31.38156882,0.827502691,152530.8358,1.70099024,252.6206795
70.4,31.45076113,0.83572442,152664.3977,1.70796152,253.8007386
70.6,31.88892293,0.844000752,151983.8827,1.72146841,254.6277647
70.8,32.50408349,0.852346736,151501.6247,1.734103913,255.668359
71,32.56575678,0.860818451,152080.6308,1.734539625,256.6806171
71.2,32.74874869,0.869365954,152985.0382,1.73192542,257.798569
71.4,33.27744043,0.877973127,153152.8108,1.738025352,258.9394072
71.6,33.2676032,0.886707576,154342.9297,1.734104012,260.2578471
71.8,33.35581498,0.89552236,155689.0737,1.727132752,261.3692615
72,33.69249426,0.904406863,156726.0879,1.723647154,262.50356
72.2,33.64937313,0.913409426,157870.1877,1.721032921,263.9592902
72.4,33.77410811,0.922489785,158743.4371,1.718854411,265.0870488
72.6,34.14814124,0.931642346,159050.5853,1.723647211,266.371716
72.8,34.24625376,0.940907863,158988.2081,1.73018279,267.3305827
73,34.48521311,0.950255912,158872.9047,1.737589795,268.3057955
73.2,35.39563955,0.959647212,158735.3306,1.746739699,269.4924034
73.4,35.70354543,0.969178669,159372.9311,1.746304031,270.4806926
73.6,35.88802633,0.978815235,160554.1418,1.741947006,271.7969559
73.8,36.34050296,0.988528329,161391.4405,1.739768536,272.8647893
74,36.49337337,0.998361616,162562.9385,1.7345401,274.0590148
74.2,36.82407113,1.008280166,163780.271,1.729311683,275.329516
74.4,37.16015482,1.018298062,164258.0859,1.731925952,276.6588568
74.6,37.41976662,1.028422431,164663.6543,1.73432236,277.7920651
74.8,37.38891301,1.038670371,165279.4487,1.734540202,278.9579581
75,38.14504015,1.048961178,165499.9874,1.738461642,279.9920176
75.2,38.5188714,1.059384457,166192.6972,1.740204497,281.3747505
75.4,38.63340079,1.069932205,166768.5066,1.74107592,282.3761116
75.6,38.82270716,1.08058015,167456.3508,1.742818762,283.686927
75.8,39.20978461,1.091320098,168093.497,1.743254513,284.7155351
76,39.70737356,1.102159548,169485.2905,1.737154711,285.9587985
76.2,40.06283697,1.113118621,170991.3136,1.731054882,287.506063
76.4,40.45900397,1.124184734,173165.5766,1.717548082,288.9116784
76.6,40.88590186,1.135359776,175810.6959,1.701862762,290.6605238
76.8,41.07676587,1.146664857,177786.6064,1.693148689,292.4202645
77,41.15375897,1.158092334,178516.4256,1.694020108,293.7397944
77.2,41.63378947,1.169603919,179141.3115,1.696634392,295.0887502
77.4,42.00077981,1.181239776,178889.5646,1.707527055,296.4747535
77.6,42.0660831,1.193015565,178492.2951,1.717112568,297.4804737
77.8,42.18455431,1.204905574,178619.6656,1.723648154,298.8130809
78,42.34788286,1.216911518,179022.6794,1.726262402,299.9615432
78.2,43.00649361,1.22900058,179593.9612,1.728876709,301.4641389
78.4,43.38169953,1.241232656,180173.7024,1.729748163,302.6191423
78.6,43.82835561,1.253582127,180976.3701,1.730619626,304.1021226
78.8,43.85863956,1.266087538,181669.7537,1.73061963,305.2353275
79,44.2686901,1.278689416,182567.3887,1.729748269,306.5178161
79.2,44.60226459,1.291423731,184372.4273,1.723648441,308.2557663
79.4,44.93498771,1.304286011,185414.3904,1.721905661,309.5491502
79.6,45.49788912,1.317260218,186923.1833,1.717984383,311.1487219
79.8,45.78818779,1.330385473,187535.6396,1.719727237,312.3930718
80,46.15325937,1.343636886,187882.1157,1.724955739,313.9109192
80.2,46.28395572,1.357039185,187576.3983,1.734105558,315.0648292
80.4,46.81934852,1.370545499,187402.2455,1.741512605,316.1413825
80.6,47.31233658,1.384190715,187309.3881,1.749355353,317.4652789
80.8,47.76624385,1.397975942,188033.0606,1.749355408,318.6006696
81,48.01735465,1.411915109,188606.2637,1.752841078,320.0150023
81.2,48.39143755,1.425984969,189483.6819,1.751969713,321.2713406
81.4,48.67408325,1.440203192,190213.7175,1.753276862,322.7129123
81.6,49.1312253,1.454550859,190193.8856,1.758941082,323.7611351
81.8,49.57006149,1.469044133,190330.4836,1.76373389,325.0458044
82,49.84515909,1.483695379,190954.8124,1.763298219,326.2084336
82.2,50.30389377,1.49848008,192346.1538,1.757634109,327.5759142
82.4,50.57063392,1.513427822,194702.7104,1.745870105,329.2452173
82.6,50.92377869,1.528519184,196846.2479,1.735413226,330.6758957
82.8,51.56942652,1.543740039,199378.3574,1.724520676,332.53153
83,51.73387611,1.559150233,201523.2465,1.715370889,334.1071245
83.2,52.46174836,1.57467243,202813.9553,1.713192449,335.6816385
83.4,52.83474039,1.590377645,203142.5398,1.718856659,337.3160761
83.6,53.50854501,1.606217686,203661.877,1.721035264,338.6116464
83.8,53.85572436,1.622241702,204748.0483,1.7205996,340.3408803
84,54.20786438,1.63842643,204699.3461,1.727135219,341.6102933
84.2,54.78186713,1.654756808,204854.9122,1.731928044,342.9156696
84.4,54.90043207,1.671285916,205937.3895,1.731056648,344.6296448
84.6,55.48932776,1.688029589,206663.1229,1.731492423,345.9796951
84.8,55.84385578,1.704875717,206907.2034,1.736720928,347.4724812
85,55.99642698,1.721820826,208224.3518,1.733235305,348.9205908
85.2,56.61600387,1.738986412,210838.7692,1.722778453,350.9778055
85.4,56.960478,1.756345373,212796.4752,1.71580721,352.5392386
85.6,57.45617432,1.773867274,215314.2395,1.707093164,354.5910027
85.8,58.18453484,1.791547632,216981.7774,1.702300491,356.1775029
86,58.50814896,1.809436369,218190.876,1.700993413,357.789059
86.2,58.91234576,1.827498588,218734.6039,1.706221924,359.6795584
86.4,59.53341607,1.845725991,219464.2323,1.707529112,361.1560062
86.6,59.8910165,1.864156331,220390.2603,1.70883627,362.9691412
86.8,60.37490612,1.882762391,221340.9896,1.708836327,364.5109651
87,60.99090197,1.901545407,222009.923,1.711014926,366.045162
87.2,61.49301486,1.920525798,222895.8447,1.713629217,368.0261017
87.4,61.88456866,1.93970523,222964.6682,1.721036255,369.7379043
87.6,62.7256865,1.959043159,222396.9432,1.731057578,370.9975209
87.8,63.37230925,1.978590239,222078.8088,1.740207469,372.5001204
88,63.58925116,1.998366331,221914.6947,1.747178782,373.7706233
88.2,63.78954063,2.018342301,221749.0061,1.754150093,375.0302294
88.4,64.47595883,2.038482095,222012.4457,1.759378641,376.5611606
88.6,64.82244803,2.058849553,222484.338,1.761992916,377.8273067
88.8,65.25034704,2.079415334,223611.5827,1.761557262,379.493345
89,65.72059647,2.100184413,224856.6148,1.758943086,380.919669
89.2,66.48998859,2.121139353,226436.2408,1.754150418,382.4843794
89.4,66.55794617,2.142357965,228337.8043,1.74805055,384.3443645
89.6,67.01812264,2.163759943,230295.8416,1.740207905,385.9777158
89.8,67.45831986,2.185378574,232388.9219,1.732800973,387.9706435
90,68.35971203,2.207179345,234702.6557,1.723215555,389.7336669
90.2,68.97186608,2.229221204,237625.6728,1.712322986,392.1210393
90.4,69.30101437,2.251506328,239296.5152,1.708401676,393.8884134
90.6,69.60685774,2.274017743,240633.884,1.708401711,395.8944128
90.8,70.09674144,2.296741395,241664.7601,1.708837473,397.5179586
91,70.8957373,2.319669964,241116.5077,1.719294503,398.9617228
91.2,71.28249863,2.342860306,240964.7453,1.729315781,400.8391486
91.4,71.96798333,2.36626098,241367.3271,1.734544328,402.5989011
91.6,72.47184754,2.389910452,242015.1849,1.736722917,404.105858
91.8,72.84603108,2.41380736,243397.2603,1.735851552,406.025779
92,73.79692123,2.437900664,245332.7792,1.730187483,407.788805
92.2,74.42034147,2.462260897,246530.3998,1.729316148,409.533303
92.4,74.93277859,2.486873101,248062.9058,1.727573387,411.626477
92.6,75.22952038,2.511748956,249172.417,1.72670201,413.252199
92.8,75.87110593,2.536848441,249650.2954,1.730623435,415.2037249
93,76.40378459,2.562208382,249738.5907,1.735851969,416.7226663
93.2,77.36441069,2.587790803,250425.4603,1.737594906,418.3952566
93.4,78.06737217,2.613649717,251024.5683,1.740644931,420.284675
93.6,78.63400106,2.639778861,251639.8617,1.742387822,421.7894569
93.8,79.33106226,2.666160617,253299.9939,1.73977367,423.8107174
94,79.67073214,2.692834495,254598.0029,1.738466593,425.5464938
94.2,80.40510567,2.719746467,255908.9911,1.737159563,427.3247722
94.4,81.17267809,2.746926112,257913.1912,1.7332383,429.5149286
94.6,81.73078382,2.774394801,260125.8326,1.726267071,431.3106376
94.8,82.38275378,2.802132335,262545.3385,1.720167265,433.5988589
95,82.95157499,2.83015479,265788.1132,1.707967564,435.7247236
95.2,83.58849714,2.858453747,269602.2656,1.695332163,438.5174395
95.4,84.45723566,2.887019458,272542.4484,1.686182437,440.7043314
95.6,85.21041335,2.915880966,274450.188,1.6844397,443.2911106
95.8,86.04166323,2.94502643,274710.1692,1.689668269,445.1129769
96,86.77563435,2.974472088,274032.9646,1.700561007,446.8934362
96.2,87.35165989,3.004225556,273215.4452,1.713632259,449.0094966
96.4,87.87611314,3.034281902,272346.6057,1.724524974,450.5164551
96.6,88.77365772,3.064611822,272333.8417,1.732803498,452.5224717
96.8,88.86670211,3.095307563,274352.9508,1.728010742,454.4402092
97,90.02260439,3.126230918,277424.6787,1.719296754,456.96598
97.2,90.75794838,3.157497132,279893.6832,1.713196953,459.1713924
97.4,91.42842095,3.18908236,281998.5971,1.710147088,461.6437613
97.6,92.0107523,3.220991554,283343.9715,1.709275744,463.5865728
97.8,92.69940653,3.253213302,283490.0823,1.716682832,465.7603852
98,93.12041269,3.285779116,282941.9415,1.726268421,467.4275183
98.2,94.10730884,3.318629116,282796.9101,1.733675545,469.1894599
98.4,94.90882944,3.351823283,284546.1148,1.732368521,471.4874942
98.6,95.3354955,3.385379311,287147.9484,1.726704389,473.9424255
98.8,96.08870893,3.419247686,289327.079,1.721476002,475.8994057
99,96.88425163,3.453453144,292472.6784,1.712326261,478.2965928
99.2,97.86672503,3.487988113,295129.085,1.707533605,481.0174064
99.4,98.63057828,3.52288679,295823.591,1.71058364,482.99073
99.6,99.3170886,3.558141807,295224.7499,1.721476383,485.1351266
99.8,99.99523219,3.593751642,294746.7864,1.729754887,486.7815629
100,100.9159843,3.629700865,293679.8034,1.741519073,488.4160195
100.2,101.5715755,3.666031418,292286.3438,1.755897468,490.3130699
100.4,102.4772535,3.702707977,292005.2707,1.763740295,492.1512864
100.6,103.239102,3.739763955,292692.1149,1.765047508,493.7258123
100.8,103.940225,3.777196879,294330.127,1.763304766,495.9170601
101,105.0044554,3.814978279,297169.93,1.754155054,498.0429411
101.2,105.9439686,3.853148807,301007.685,1.74064826,500.3747588
101.4,106.9474115,3.891697812,304819.7421,1.729320004,503.132621
101.6,107.6782097,3.930654888,307327.1521,1.723220197,505.3456645
101.8,108.6657391,3.969983897,309043.0431,1.7223489,507.8234933
102,109.4171885,4.009726093,308619.1802,1.731063124,509.7466967
102.2,110.5192761,4.049840917,307138.6403,1.74413446,511.3735333
102.4,111.0087857,4.090610791,306899.0563,1.751977242,513.3871697
102.6,112.1406616,4.131537954,306992.7351,1.758512981,515.4858143
102.8,113.0738852,4.172683297,307544.7905,1.761127335,517.1148252
103,113.7518787,4.214469473,309064.1874,1.760256003,519.0968677
103.2,114.6649917,4.256657674,311940.5895,1.754156216,521.6291788
103.4,115.5780374,4.299269814,313756.4129,1.751542084,523.6166756
103.6,116.5383848,4.342306565,316318.2972,1.746749422,526.0738034
103.8,117.9050454,4.3857448,318150.4319,1.744135343,528.116881
104,118.4256309,4.429683818,320248.5919,1.740649749,530.3778675
104.2,119.0699723,4.474054882,321880.0768,1.740649826,532.9221553
104.4,119.8688177,4.518860007,322465.5172,1.7454427,535.2321805
104.6,120.9468233,4.564094123,322174.7662,1.752414143,536.8633758
104.8,121.4338822,4.609827531,323208.532,1.754592738,539.0949406
105,122.9197868,4.655944659,324570.4864,1.754592916,541.1826992
105.2,123.4889728,4.702594742,325948.0806,1.754157278,543.2137742
105.4,124.2824671,4.749696341,329355.2208,1.745443229,545.9520219
105.6,125.2038675,4.797261561,333127.0574,1.73411495,548.360116
105.8,125.9922244,4.845314826,335259.5454,1.7315008,551.0700341
106,127.5068402,4.893795075,335947.5242,1.734115223,553.182857
106.2,128.2850706,4.942818292,337112.6882,1.735858146,555.8949544
106.4,129.5369199,4.992297431,337037.5767,1.741522491,557.7800386
106.6,130.5260794,5.042293176,336589.3863,1.74980105,560.0290522
106.8,131.9007652,5.092761895,338224.8553,1.747622677,562.0372674
107,132.8806229,5.143767332,341887.4912,1.737601522,564.6534852
107.2,133.5703635,5.19530736,345530.138,1.729758869,567.767652
107.4,134.2342594,5.247366853,348138.0391,1.72496617,570.2062523
107.6,135.3227377,5.299917153,351727.4881,1.717994977,573.2920994
107.8,136.3853696,5.352997488,353308.2635,1.718430815,575.6315572
108,137.6905825,5.406595066,352316.5806,1.729759364,577.7356602
108.2,138.9524953,5.460734786,351542.3709,1.741087912,580.2135037
108.4,139.5972685,5.515465513,351295.9259,1.748059315,582.0909466
108.6,140.7094189,5.570710429,350466.122,1.758952138,584.2745875
108.8,141.8991843,5.62650458,350585.1,1.764616484,586.3530819
109,142.5453549,5.682900617,353019.0903,1.759388068,588.4282924
109.2,143.8267721,5.739815043,357316.1097,1.748931238,591.5435686
109.4,144.7287248,5.797330025,362423.412,1.734988696,594.724212
109.6,146.0693793,5.855389653,366828.2628,1.722789028,597.4646594
109.8,147.0575769,5.914057868,371547.9331,1.711460742,600.8850235
110,148.6211823,5.973270367,374029.4726,1.708410966,603.5960583
110.2,149.4733155,6.033131958,375680.0896,1.708846774,606.3201482
110.4,150.5214807,6.093579966,377105.8018,1.711025435,609.4005518
110.6,151.7548733,6.154621264,379694.9985,1.707539915,612.1148443
110.8,153.1635199,6.216262471,383412.3059,1.701440166,615.4992655
111,154.0194206,6.278564855,386121.4754,1.697954601,618.5240954
111.2,155.5167917,6.341444569,389045.4463,1.694033401,621.684055
111.4,156.7015881,6.404980013,390552.6529,1.69621208,624.855993
111.6,157.9220182,6.469150853,388278.4607,1.712769135,627.5365098
111.8,159.4897245,6.533940121,386283.8856,1.726276276,629.5076928
112,160.1348628,6.599450251,384451.8285,1.739783311,631.5006391
112.2,161.5660691,6.665559049,382538.4404,1.755033274,633.9218316
112.4,162.5592069,6.73236531,383012.2016,1.758954769,635.9845254
112.6,164.2179088,6.799792177,383637.8835,1.763747762,638.5310349
112.8,165.5332797,6.867922556,383630.7014,1.770719256,640.9238967
113,167.000624,6.93672594,383961.5237,1.775076519,642.9343047
113.2,168.1088451,7.006247801,383789.6613,1.781612283,644.9141918
113.4,169.2194484,7.076467972,383935.8686,1.78727663,647.1283495
113.6,170.436314,7.147385542,386722.5812,1.781176859,649.4264105
113.8,171.7178884,7.219010698,394128.2761,1.758955873,652.9252457
114,173.3267822,7.291330653,401402.8986,1.73760634,656.3151249
114.2,174.4319443,7.364415513,408444.4869,1.717999578,659.8095932
114.4,175.856113,7.438210416,415186.4297,1.701878521,663.9175352
114.6,177.4073147,7.512737049,418299.9533,1.699264449,667.5787337
114.8,178.7788907,7.588026194,417590.7083,1.707978786,669.9432691
115,180.0522826,7.664079145,416529.1335,1.718435949,672.454904
115.2,181.6654528,7.740870526,415588.243,1.730200281,675.5396896
115.4,182.7399798,7.818474222,416649.9639,1.732378953,678.0447813
115.6,184.1318443,7.896833417,419495.4898,1.729764864,681.427029
115.8,185.6573829,7.97596978,422670.618,1.724972245,684.3374769
116,186.9542563,8.055918623,425623.1147,1.721922435,687.4429598
116.2,188.3665183,8.136661973,428095.7685,1.721922601,691.0703781
116.4,189.3922127,8.218245857,429690.3405,1.723229851,693.7617959
116.6,191.0909283,8.300598285,430257.5355,1.72932998,696.8258875
116.8,192.4687268,8.383802496,430612.1619,1.734558655,699.3266314
117,193.8979177,8.467838872,432708.2951,1.735865953,702.9475128
117.2,195.4059244,8.552713558,435855.124,1.731073329,705.7675243
117.4,197.4307097,8.638401733,438206.9757,1.73020215,709.2260739
117.6,198.8295766,8.72499834,442174.2336,1.722795255,712.3860445
117.8,200.1335655,8.812472196,452050.3696,1.698395676,717.0268174
118,201.9601463,8.900785457,460240.5686,1.679660377,721.2698973
118.2,203.3145489,8.990021588,464344.6908,1.674432018,725.0476883
118.4,204.8067637,9.08014384,471303.6315,1.663103738,729.9619647
118.6,206.2880311,9.171172202,474491.1756,1.661361068,733.6569503
118.8,208.0001857,9.263097716,468396.1446,1.687939558,736.74066
119,209.6972347,9.355947917,462528.9022,1.712775212,738.9962561
119.2,211.5013415,9.449722831,461029.7388,1.72410388,741.7291098
119.4,213.2238555,9.544446035,458513.6257,1.73978964,744.6951437
119.6,214.9054969,9.640124421,457824.9097,1.748068329,747.0389946
119.8,216.2553957,9.73678898,461646.0177,1.743711391,750.6446292
120,217.6831811,9.8349105,466121.0867,1.736304492,753.9931127
120.2,219.7483047,9.93348265,467571.953,1.738483287,757.0103727
120.4,221.4418703,10.03257223,469285.5902,1.740226329,760.498342
120.6,222.9731428,10.13317079,469855.127,1.743712194,763.149467
120.8,224.7361185,10.2347627,469125.9054,1.752426609,766.1808831
121,225.9163641,10.33741961,468876.3213,1.758962406,768.7677099
121.2,227.8925946,10.44104745,471574.3997,1.757655513,772.4071472
121.4,229.3160096,10.54575846,475531.6552,1.751120029,775.4363708
121.6,231.0525645,10.65149766,482159.5568,1.738484634,779.5933754
121.8,233.0274631,10.75828127,488236.6236,1.726720686,783.1271231
122,234.6365279,10.86616548,494074.2469,1.716263823,787.0705565
122.2,236.6360158,10.97510422,499379.7553,1.708856978,791.7200868
122.4,238.5031924,11.08514743,500685.1503,1.71103575,794.9945011
122.6,240.161599,11.19631214,502477.638,1.712778787,799.0044045
122.8,242.2577936,11.30856059,503412.789,1.714957587,802.0391078
123,243.9332959,11.42196884,505091.3375,1.716264916,805.4802299
123.2,245.8687373,11.53649663,505124.0916,1.724107939,809.4509201
123.4,247.9195125,11.65216648,506269.6936,1.727158158,812.3908264
123.538,249.4470645,11.73264683,506744.9974,1.732822581,815.3383361
123.8,251.1687709,11.73486097,506298.8723,1.743279848,818.64326
124,252.4085657,11.73476714,505738.7212,1.751994216,821.3815511
124.2,252.8646762,11.73473254,508572.8058,1.752865693,825.273734
124.4,253.6207973,11.73467526,513217.6717,1.747201539,829.1997048
124.6,254.2987994,11.73462389,517211.8721,1.741973085,832.483882
124.8,254.7906452,11.73458659,521941.5744,1.735873188,836.5939893
125,254.6941044,11.73459375,525633.5906,1.731951776,840.1287526
125.2,255.5566007,11.73452843,527618.9816,1.734130438,844.2682985
125.4,255.9366697,11.73449958,525906.9477,1.74458755,846.8834312
125.6,256.2448525,11.73447615,522787.5037,1.75983748,849.7775044
125.8,256.40303,11.73446406,522141.448,1.766808877,852.2760376
126,256.554559,11.73445248,522926.1641,1.77160172,855.8663794
126.2,256.8149562,11.73443266,524547.4145,1.772037464,858.5719455
126.4,257.4090219,11.73438763,528577.1224,1.767244711,862.3802327
126.6,257.2555538,11.73439909,532427.6071,1.76201616,865.5608611
126.8,257.675929,11.73436719,534981.262,1.762016207,869.3517072
127,258.144921,11.73433161,535093.22,1.767244802,872.1520803
127.2,258.1306546,11.73433256,533503.7698,1.777266151,874.6397089
127.4,258.249357,11.73432345,530259.8091,1.792951773,877.1894521
127.6,258.5018591,11.73430423,527662.7419,1.805151721,879.044016
127.8,258.6621143,11.73429199,525826.8158,1.816044517,881.428137
128,259.0999417,11.73425876,524915.4026,1.823451663,883.4134647
128.2,259.2294478,11.73424884,524892.2814,1.829115932,886.0601858
128.4,259.1611628,11.73425387,526297.1449,1.829115918,888.2961035
128.6,259.4992637,11.73422818,527113.4679,1.831730227,890.8676503
128.8,259.4226681,11.73423383,526528.2936,1.837394465,892.6698972
129,260.0641041,11.73418522,525746.6205,1.843494503,894.4852529
129.2,259.6800182,11.73421411,524889.6892,1.850465836,896.6263609
129.4,259.9075888,11.73419678,523414.0471,1.858744379,898.511437
129.6,259.9415236,11.73419408,523251.0212,1.862230074,900.102298
129.8,260.1724183,11.7341765,524520.298,1.862230103,902.2717645
130,260.2445817,11.73417091,526248.6792,1.860487268,904.2505405
130.2,260.4048368,11.73415866,527501.4104,1.860487288,906.2064352
130.4,260.581713,11.73414516,529548.288,1.859180177,908.5567776
130.6,260.5408528,11.73414811,530399.9293,1.860487306,910.3023695
130.8,260.7426607,11.73413272,529224.3277,1.868330135,912.0762986
131,261.0574921,11.7341088,528453.0963,1.873994422,913.5178952
131.2,261.0149698,11.73411187,528378.2935,1.877915819,915.4770517
131.4,261.191015,11.73409843,526903.5389,1.884451512,916.6135461
131.6,260.865103,11.73412293,525496.9381,1.89098714,918.0812634
131.8,261.2904646,11.73409065,524011.1284,1.897522865,919.4095466
132,261.2296591,11.7340951,522633.1702,1.903622816,920.4741151
132.2,261.2220412,11.73409554,522053.0377,1.907979929,921.5920745
132.4,261.3199672,11.73408801,521921.725,1.911901344,922.8680371
132.6,261.5716384,11.73406885,520940.017,1.917565624,923.6623892
132.8,261.422741,11.73407997,521761.1149,1.918001316,924.9786586
133,261.5331329,11.73407149,522597.1103,1.918001331,926.1761706
133.2,261.5180354,11.7340725,523546.4385,1.917129906,927.310475
133.4,261.5328559,11.73407124,526352.3118,1.91102995,929.0658728
133.544,261.9329591,11.73404091,528873.713,1.904930043,930.3058938
134.3,261.6567953,11.60918773,1.7977E+308,1.826066252,0
134.5,261.7101992,11.49193141,1.7977E+308,1.658317387,0
134.7,261.2899017,11.37471089,1.7977E+308,1.412140434,0
134.9,261.0956513,11.25747328,1.7977E+308,1.112371021,0
135.1,261.0144243,11.14022714,1.7977E+308,0.758137706,0
135.3,260.7071503,11.02299808,1.7977E+308,0.487560962,0
135.5,260.4796576,10.90576299,1.7977E+308,0.307612184,0
135.7,260.2646308,10.78852695,1.7977E+308,0.198248642,0
135.9,260.2282808,10.67127742,1.7977E+308,0.119384896,0
136.1,260.0074366,10.55404182,1.7977E+308,0.038778305,0
136.3,259.5954497,10.43682067,1.7977E+308,0.03049979,0
136.5,259.3280664,10.3195886,1.7977E+308,0.023092697,0
136.7,259.0964185,10.20235382,1.7977E+308,0.021785563,0
136.9,258.8506427,10.08512011,1.7977E+308,0.017864162,0
137.1,258.9339645,9.967861531,1.7977E+308,0.009149936,0
137.3,258.4704523,9.850644276,1.7977E+308,0.003921401,0
137.5,258.4191433,9.73339587,1.7977E+308,0.009585647,0
137.7,258.2033787,9.615573632,1.7977E+308,0.017864161,0
137.9,257.8919495,9.498344884,1.7977E+308,0.020042716,0
138.1,257.5097875,9.381707741,1.7977E+308,0.023528406,0
138.3,257.2889433,9.264472148,1.7977E+308,0.027014095,0
138.5,257.0672681,9.147236617,1.7977E+308,0.030499784,0
138.7,256.7699669,9.030006801,1.7977E+308,0.02919265,0
138.9,256.6962194,8.912760091,1.7977E+308,0.030064072,0
139.1,256.2260589,8.795543338,1.7977E+308,0.032678338,0
139.3,256.3509335,8.678281619,1.7977E+308,0.037906872,0
139.5,256.2630581,8.561035977,1.7977E+308,0.04095685,0
139.7,255.6873536,8.4438272,1.7977E+308,0.046185383,0
139.9,255.3260612,8.326602219,1.7977E+308,0.050542493,0
140.1,254.9431614,8.209378872,1.7977E+308,0.054463892,0
140.3,254.9732958,8.092124312,1.7977E+308,0.054463892,0
140.5,254.7225337,7.97489098,1.7977E+308,0.053592469,0
140.7,254.5307765,7.857653188,1.7977E+308,0.050978201,0
140.9,254.3838962,7.740412005,1.7977E+308,0.045313956,0
141.1,253.7757806,7.623205677,1.7977E+308,0.034421177,0
141.3,253.5831924,7.505967948,1.7977E+308,0.025706954,0
141.5,253.3249508,7.38873518,1.7977E+308,0.019606999,0
141.7,253.5827941,7.271463413,1.7977E+308,0.013071333,0
141.9,253.0951815,7.154247978,1.7977E+308,0.008714221,0
142.1,252.8344468,7.037015399,1.7977E+308,0.012635621,0
142.3,252.5271731,6.919786337,1.7977E+308,0.016992731,0
142.5,252.1210038,6.802564748,1.7977E+308,0.016992731,0
142.7,252.011521,6.685320739,1.7977E+308,0.01263562,0
142.9,251.8579924,6.568080058,1.7977E+308,0.006971377,0
143.1,251.2802104,6.450871438,1.7977E+308,0.008278509,0
143.3,251.2700386,6.333619924,1.7977E+308,0.011328486,0
143.5,250.7072157,6.216410173,1.7977E+308,0.013507041,0
143.7,250.935141,6.099140666,1.7977E+308,0.023964105,0
143.9,250.3723181,5.981930915,1.7977E+308,0.028103359,0
144.1,250.1764057,5.864693438,1.7977E+308,0.03093548,0
144.3,250.0964253,5.747447199,1.7977E+308,0.029628347,0
144.5,249.9196272,5.630208277,1.7977E+308,0.018735572,0
144.7,249.8321673,5.512962604,1.7977E+308,0.003921399,0
144.9,249.515752,5.395734232,1.7977E+308,0.004792821,0
145.1,249.1552909,5.278509189,1.7977E+308,0.013507039,0
145.3,248.7773776,5.161285465,1.7977E+308,0.020914125,0
145.5,248.5158119,5.044052949,1.7977E+308,0.028321211,0
145.7,248.4453887,4.926805988,1.7977E+308,0.027885499,0
145.9,248.0749549,4.809581698,1.7977E+308,0.030499764,0
146.1,247.8931705,4.692343153,1.7977E+308,0.03354974,0
146.3,247.8119436,4.575097009,1.7977E+308,0.029628342,0
146.5,247.2620021,4.457886284,1.7977E+308,0.024835521,0
146.7,247.0054228,4.340653391,1.7977E+308,0.020042701,0
146.9,246.8070173,4.223416102,1.7977E+308,0.012199905,0
147.1,246.4532046,4.106190556,1.7977E+308,0.013507037,0
147.3,246.1259857,3.988963001,1.7977E+308,0.023092675,0
147.5,246.1336816,3.871710137,1.7977E+308,0.034421158,0
147.7,245.8845818,3.754476679,1.7977E+308,0.038342555,0
147.9,245.5598561,3.637248935,1.7977E+308,0.04139253,0
148.1,245.2384546,3.52002094,1.7977E+308,0.038778264,0
148.3,244.4890602,3.402825288,1.7977E+308,0.028321202,0
148.5,244.6754327,3.285558922,1.7977E+308,0.016557011,0
148.7,244.1628888,3.168345372,1.7977E+308,0.007842794,0
148.9,243.9711318,3.05110758,1.7977E+308,0.016992721,0
149.1,243.6106708,2.933882537,1.7977E+308,0.027014068,0
149.3,243.192036,2.81666189,1.7977E+308,0.032678307,0
149.5,243.1024986,2.699416373,1.7977E+308,0.03442115,0
149.7,242.7794351,2.582188504,1.7977E+308,0.031371174,0
149.9,242.4995863,2.46495737,1.7977E+308,0.028321198,0
150.1,241.9820562,2.347744196,1.7977E+308,0.025706933,0
150.3,241.5110651,2.230527505,1.7977E+308,0.021785536,0
150.5,241.3284496,2.113289023,1.7977E+308,0.013507032,0
150.7,240.9289292,1.996066931,1.7977E+308,0.005664239,0
150.9,240.6607152,1.878834917,1.7977E+308,0.003049975,0
151.1,240.2304458,1.76161515,1.7977E+308,0.005228528,0
151.3,239.9190171,1.644386401,1.7977E+308,0.014814163,0
151.5,239.4230944,1.527171595,1.7977E+308,0.023528375,0
151.7,239.4490735,1.409917349,1.7977E+308,0.032242588,0
151.9,238.7636706,1.292716861,1.7977E+308,0.038778246,0
152.092,238.4632032,1.180177376,1.7977E+308,0.036163981,0
227.3,238.1320907,1.063485345,1.7977E+308,0.022221242,0
227.5,238.0176217,0.946241713,1.7977E+308,0.016557004,0
227.7,237.4394248,0.829033124,1.7977E+308,0.012199897,0
227.9,236.9310364,0.711819259,1.7977E+308,0.012635607,0
228.1,236.4758354,0.594601375,1.7977E+308,0.010892764,0
228.3,236.0488903,0.477381356,1.7977E+308,0.013507027,0
228.5,235.2845375,0.360186835,1.7977E+308,0.018299843,0
228.7,234.7911082,0.24297184,1.7977E+308,0.018299842,0
228.9,234.2877062,0.125757598,1.7977E+308,0.020478394,0
229.1,232.9067119,0.008609675,1.7977E+308,0.01829984,0
229.1,232.9067119,0.008609675,1.7977E+308,0.01829984,0
,,,,,