File: TestGB3_7.csv
Time On Sample,Displacement Into Surface,Load On Sample,Harmonic Contact Stiffness,Harmonic Displacement,Harmonic Load
0,0,0,396.6287488,0.447482372,2.176448668
0.2,0.005281412,0.000689525,3542.431778,0.308217127,2.244291714
0.4,0.360292324,0.001355121,8522.760335,0.240549059,2.320888729
0.6,0.339760368,0.002046413,11308.24689,0.213045265,2.405145413
0.8,0.586938016,0.002719386,13552.57705,0.19252656,2.50581576
1,0.607207835,0.003407886,14783.593,0.182048924,2.603203361
1.2,0.507570399,0.004104591,16022.56893,0.172444425,2.702779436
1.4,0.366298498,0.004804144,18463.78787,0.15454513,2.851596428
1.6,0.727138232,0.00546934,21616.74965,0.141011516,3.087952885
1.8,0.825680843,0.006152484,25107.31207,0.13053388,3.317743857
2,0.735202988,0.006848562,28215.93172,0.126604767,3.575985127
2.2,0.618495422,0.007546434,29921.52107,0.129224176,3.825472446
2.4,0.647508478,0.008234336,30900.53291,0.133589858,4.036661286
2.6,0.802257616,0.008913634,33682.73697,0.139701812,4.580499922
2.8,0.582712923,0.009618543,35996.98953,0.14494063,5.084945769
3,0.799081067,0.010293625,37216.70126,0.153671993,5.58282624
3.2,0.85890395,0.01097664,38274.03339,0.162403356,6.091649101
3.4,0.984925928,0.011652559,38584.54476,0.177246673,6.729592615
3.6,1.036838562,0.01233355,37791.571,0.201257922,7.483525851
3.8,1.24821119,0.013003628,36774.91742,0.228761715,8.238553372
4,1.167726229,0.013693677,36318.31762,0.2536461,8.988109606
4.2,1.173008263,0.014377856,35517.85223,0.281149894,9.721252217
4.4,0.973448736,0.015076053,35407.41773,0.300358895,10.34825322
4.6,1.119871602,0.015750576,36701.56312,0.318258188,11.37465292
4.8,1.101005647,0.016436409,37671.37953,0.336594051,12.36165984
5,1.179147992,0.017115603,38010.05271,0.359732163,13.34976103
5.2,1.403843648,0.01778477,38477.45571,0.380250865,14.30503501
5.4,1.312950072,0.01847553,38338.38808,0.401642705,15.07757032
5.6,1.360699258,0.019156804,38162.60998,0.433512181,16.21230005
5.8,1.604130422,0.019824688,37897.83978,0.464945086,17.26605594
6,1.137277642,0.020541172,37423.95873,0.499433975,18.31434017
6.2,1.050131167,0.021231677,36160.05859,0.54352736,19.25429456
6.4,1.159915704,0.021908707,34712.45427,0.590240152,20.05199761
6.6,1.233894603,0.022588186,33168.43372,0.650486557,21.09918791
6.8,1.111358834,0.023281113,31605.1698,0.712479237,22.00303227
7,1.014220087,0.023972302,29757.93967,0.785822689,22.84012785
7.2,0.929155335,0.024662665,28496.89391,0.843449688,23.47807131
7.4,1.048099454,0.025339069,27024.80306,0.919412546,24.27249155
7.6,0.995093239,0.026027238,25832.08902,0.985116055,24.8754192
7.8,0.68770045,0.026732814,24600.47173,1.05562182,25.4323885
8,0.889080808,0.027403578,23515.4532,1.129401835,26.05391849
8.2,0.83940535,0.028091519,22677.69478,1.189211675,26.49818095
8.4,1.160692963,0.028754078,21858.26095,1.25033121,26.92493594
8.6,1.172220166,0.029437832,21121.53716,1.313197025,27.41953367
8.8,1.368604388,0.030108935,20907.57313,1.342883655,27.80908424
9,1.222753319,0.030803456,20818.44396,1.369514316,28.31790691
9.2,1.531134247,0.031466897,20951.72681,1.379555376,28.74685036
9.4,1.368212651,0.032166007,21306.68437,1.378682244,29.21846882
9.6,1.440109826,0.032845628,21668.61886,1.381301651,29.76996721
9.8,1.41791391,0.033524845,21824.85375,1.390033015,30.17921395
10,1.210026696,0.034230453,21828.22696,1.409678588,30.63988986
10.2,1.425146426,0.034900275,21594.78822,1.436745808,30.9561262
10.4,1.650258824,0.035565991,21145.17573,1.475600368,31.24719511
10.6,1.435710892,0.036265211,20790.68831,1.510962395,31.57875037
10.8,2.023042721,0.036909562,20566.92477,1.537156468,31.82933267
11,1.978363399,0.037597159,20698.61139,1.545887832,32.19590386
11.2,2.17849472,0.038268003,21333.57521,1.522313146,32.58107752
11.4,2.241232313,0.038948248,22601.38784,1.467742126,33.09208897
11.6,2.194887614,0.039635957,24618.40855,1.386103883,33.79896975
11.8,2.158535185,0.040322983,27355.73483,1.285256641,34.6349711
12,2.366160708,0.040993314,29548.08575,1.218025141,35.32215582
12.2,2.099153356,0.041696122,31879.3539,1.15821531,36.13955478
12.4,1.943726363,0.042391295,33011.03244,1.138569746,36.76436714
12.6,1.479371653,0.043107607,33448.70386,1.145991415,37.48547256
12.8,2.025901708,0.043754753,32751.09468,1.183536265,37.92317023
13,2.080312408,0.044435569,31301.95071,1.251204327,38.37399835
13.2,2.255463051,0.045108123,29494.34674,1.335461977,38.69898872
13.4,2.03092285,0.045808024,28139.05488,1.405749455,38.94081609
13.6,2.178594748,0.046482458,27066.70227,1.468178697,39.18483238
13.8,2.427854734,0.04714994,26660.77569,1.503540711,39.53936737
14,2.365688939,0.047838732,27005.52294,1.499611599,39.90156159
14.2,2.156137145,0.048537608,28156.2274,1.462503312,40.47385028
14.4,2.367093426,0.049207712,29256.23767,1.428014422,40.99361579
14.6,2.289939224,0.049897528,30853.2911,1.380428495,41.70815636
14.8,2.364334466,0.050576975,31864.15223,1.354234405,42.24105265
15,2.284682197,0.051266963,32746.55516,1.336335113,42.85820534
15.2,2.349085168,0.051947094,33055.86836,1.340264225,43.41298652
15.4,2.241121464,0.052639019,33329.10223,1.343320205,43.89992436
15.6,2.231415092,0.053324221,33441.14438,1.352924705,44.39561632
15.8,2.244191329,0.054007884,33206.81441,1.377372521,44.89677949
16,2.072110552,0.054704197,32822.53027,1.408368864,45.35198431
16.2,2.56534849,0.055354985,32688.00582,1.425831576,45.71636779
16.4,2.281687353,0.056058932,32450.76999,1.448533128,46.08622141
16.6,2.549266503,0.056725161,32200.14204,1.473854073,46.52391901
16.8,2.499591046,0.057413097,32183.19987,1.488697393,46.96489875
17,2.454911726,0.058100691,32287.84533,1.494809347,47.32490454
17.2,2.539299239,0.058779454,32377.7466,1.503540709,47.75822479
17.4,2.428837467,0.059471549,32599.22603,1.505286984,48.15652897
17.6,2.890433211,0.060124502,32928.0384,1.506160108,48.65550442
17.8,2.361961436,0.060845199,33201.92619,1.507906395,49.11617973
18,2.680334629,0.061507952,33442.36206,1.508342955,49.50354219
18.2,2.598600637,0.062198081,33675.85931,1.511398935,49.95874703
18.4,2.532271396,0.062887157,33725.93673,1.520566868,50.33188368
18.6,2.759465116,0.063556148,33870.90119,1.52798852,50.81335088
18.8,2.717700208,0.064243542,34120.35049,1.530607931,51.27293269
19,2.862874036,0.064918145,34263.90617,1.535846745,51.62199626
19.2,2.898965573,0.065600211,34476.05063,1.540648993,52.06516472
19.4,2.648195663,0.066301906,34734.20846,1.541085569,52.45580882
19.6,2.73924469,0.066980213,35068.43412,1.541958703,52.95478375
19.8,2.92147319,0.067652282,35164.16254,1.548507219,53.31150719
20,3.041249996,0.068328622,35304.79617,1.554182602,53.74920454
20.2,2.965761174,0.069018322,35555.21566,1.554182605,54.14696155
20.4,3.24499797,0.069683751,35663.14448,1.561167687,54.58301781
20.6,2.982986757,0.070386214,35673.60156,1.569462489,54.92332688
20.8,3.040728214,0.071066799,35776.00903,1.57601101,55.34679894
21,3.085562988,0.071748267,35823.45453,1.58517894,55.7440091
21.2,3.18702063,0.07242586,35705.24591,1.598275981,56.03398365
21.4,3.408801868,0.07309522,35790.78459,1.603951361,56.37429353
21.6,3.06518711,0.073803267,36053.75661,1.604824508,56.8152727
21.8,3.116267053,0.074484307,36378.6999,1.602641665,57.24968715
22,3.31181858,0.075155461,36997.6007,1.589108047,57.72349472
22.2,3.12391671,0.075852854,37781.82793,1.569025918,58.16775685
22.4,3.187903336,0.07653301,38557.67578,1.551126623,58.63062171
22.6,3.308512831,0.077209293,39554.59372,1.529298212,59.24558639
22.8,3.376246559,0.077889193,40616.69565,1.506160098,59.86821054
23,3.295345221,0.078579578,41383.3069,1.492408204,60.41697316
23.2,3.5916515,0.079249383,41813.50311,1.489570503,60.91868416
23.4,3.289669746,0.079967124,42063.15391,1.491753352,61.38154805
23.6,3.240824723,0.080674408,41973.77041,1.507906375,61.93414064
23.8,3.619148466,0.081359463,41617.40611,1.531481045,62.39262914
24,3.595698817,0.082079179,41204.16754,1.554619157,62.71543068
24.2,3.760019769,0.082793118,40852.45088,1.578193832,63.13014905
24.4,3.380177453,0.083551598,40770.91596,1.590417751,63.48030588
24.6,3.56906102,0.084278624,40950.25653,1.596093132,63.97599825
24.8,3.68383438,0.085018153,41182.38897,1.596966265,64.3644547
25,3.598345119,0.085778771,41600.14054,1.593473722,64.87327737
25.2,3.723525359,0.086532512,42030.11728,1.589108037,65.379912
25.4,3.75502694,0.087302294,42345.49515,1.587361764,65.83730561
25.6,3.71241873,0.088080998,42717.9121,1.582996084,66.25749472
25.8,3.780140707,0.088861928,43092.63816,1.581249809,66.79039111
26,3.712966115,0.08965994,43400.17057,1.581249811,67.29374267
26.2,3.727394147,0.090460289,43553.4442,1.584742356,67.69532973
26.4,3.585692009,0.091279383,43495.05216,1.596093132,68.07831441
26.6,3.757496414,0.092085235,43358.93355,1.612246149,68.54446223
26.8,3.874342379,0.092903021,43326.77931,1.624033485,68.97559417
27,3.84213552,0.093743479,43285.23266,1.633637985,69.30277267
27.2,3.719998232,0.094590014,43336.51809,1.641932784,69.70326515
27.4,3.931767344,0.09543076,43621.18024,1.640623073,70.08843906
27.6,4.090243856,0.096279346,44105.87639,1.635384251,70.61477035
27.8,3.886499549,0.097161344,44425.55432,1.634947689,71.0907654
28,3.974195461,0.098032107,44766.5436,1.631891709,71.49235268
28.2,3.835399392,0.098922738,45131.89294,1.630145441,71.99132706
28.4,4.15041741,0.09979561,45252.44797,1.634511113,72.37103001
28.6,4.023276418,0.100707574,45229.5443,1.645861889,72.83170588
28.8,4.048516489,0.101618281,45220.58772,1.653720115,73.16326153
29,4.193662752,0.102529868,45095.36635,1.667253723,73.55281236
29.2,4.198916147,0.10346029,45049.0939,1.675985085,73.86795431
29.4,4.122564912,0.104405625,45119.15647,1.682970178,74.30455695
29.6,4.323498103,0.10534135,45307.12799,1.68340674,74.65252671
29.8,4.499449501,0.106288366,45669.32886,1.679477622,75.09460122
30,4.376464351,0.107265429,46206.87778,1.669873126,75.57278508
30.2,4.352568088,0.10824544,46788.68937,1.659832058,76.07613661
30.4,4.504368122,0.109223138,47401.10877,1.648917852,76.55869805
30.6,4.556244298,0.110217572,47900.52124,1.641059624,76.98764126
30.8,4.767162945,0.111211193,48491.47738,1.632764823,77.53366911
31,4.416015195,0.112253324,48896.5279,1.630145425,78.04905642
31.2,4.636923756,0.113266531,48970.48618,1.635820805,78.43751322
31.4,4.706281674,0.114300443,48906.04981,1.64586187,78.81940418
31.6,4.540820021,0.115360834,48757.56954,1.660268623,79.27898581
31.8,4.762557633,0.116405258,48614.47431,1.673802229,79.68713893
32,4.806098529,0.117472376,48560.59609,1.682970159,80.02635416
32.2,4.862961192,0.118549421,48876.8992,1.682097021,80.49359608
32.4,5.013916487,0.119630775,49311.57729,1.675985062,80.90831453
32.6,5.003328806,0.120734081,49794.31078,1.668999973,81.36789637
32.8,5.043533879,0.121844984,50346.50982,1.661141745,81.90079282
33,5.096228003,0.12296611,50881.59489,1.653720085,82.43040653
33.2,5.120609366,0.124100579,51335.35266,1.648917835,82.96768004
33.4,5.112514531,0.125248613,51648.47731,1.647608131,83.44695821
33.6,5.124402883,0.126406915,51981.30868,1.64542529,83.90325739
33.8,5.213729995,0.127571419,52252.74304,1.646298424,84.43287125
34,5.115700684,0.128760348,52547.83604,1.644988722,84.87385099
34.2,5.298286251,0.129942004,52652.88839,1.650664101,85.37501472
34.4,5.383445779,0.131142369,52699.63713,1.656776054,85.7787903
34.6,5.414479119,0.132358389,52804.21196,1.663761142,86.31715793
34.8,5.533776079,0.133580714,52985.85119,1.66594398,86.71546286
35,5.644744729,0.134815792,53080.15547,1.672492498,87.19255305
35.2,5.674941074,0.13606889,53295.54398,1.675548476,87.66964301
35.4,7.573690589,0.137206026,53480.43354,1.677731255,88.08874371
35.6,7.437346294,0.138494615,53714.04094,1.678604396,88.52315773
35.8,7.713181671,0.139767661,54401.46899,1.668126753,89.11186124
36,7.812901797,0.141065558,55698.58659,1.641496095,89.79466912
36.2,7.66198094,0.14239385,57629.3426,1.600458698,90.61097368
36.4,7.868282223,0.143710745,59955.84086,1.5524362,91.44259895
36.6,8.080827116,0.145040603,63056.67369,1.494372636,92.57514086
36.8,8.210101547,0.146389443,65212.60477,1.459010616,93.47898609
37,8.321471572,0.147753168,67332.30467,1.429323982,94.58526589
37.2,8.455738961,0.149128972,68509.0188,1.416663503,95.40813721
37.4,8.47301191,0.150526647,69339.80787,1.41491723,96.4826837
37.6,8.437823804,0.151941986,69599.39803,1.421029185,97.2946118
37.8,8.570837262,0.153359985,69867.56763,1.428887408,98.24988644
38,8.60933883,0.154798812,70301.5386,1.431506815,99.04211834
38.2,8.781901677,0.156242868,70599.0767,1.438928469,99.98316795
38.4,8.605566066,0.157725404,71096.15953,1.440238178,100.7940014
38.6,8.626992411,0.159209199,72028.93421,1.4371822,101.9057522
38.8,9.10764511,0.160676355,72903.95424,1.433907927,102.8938553
39,8.881342975,0.162206808,73341.87207,1.437618762,103.7856626
39.2,8.842394108,0.163739857,74229.23952,1.435435923,104.8722456
39.4,9.054915593,0.165270953,74483.93267,1.441984439,105.7049652
39.6,8.689965339,0.166857096,74305.39639,1.459447173,106.7477774
39.8,8.661003316,0.168436113,74024.89383,1.474727057,107.498428
40,9.032146613,0.170003423,73854.40054,1.490006931,108.3902373
40.2,8.923659092,0.17161955,73439.89598,1.509652498,109.2426523
40.4,8.928831762,0.173244061,73265.68494,1.52318611,109.971418
40.6,8.891535389,0.174887772,73390.68142,1.531917473,110.7734978
40.8,8.84715924,0.176548465,73546.89584,1.541958541,111.6806252
41,9.059249412,0.178208302,73823.76234,1.547197352,112.432371
41.2,9.169333209,0.1798919,74319.7664,1.551126462,113.3799856
41.4,8.895545329,0.181618735,74766.28011,1.554182447,114.2269287
41.6,9.411144783,0.183308661,74948.53521,1.560730953,114.949131
41.8,9.424630683,0.185050069,75462.79024,1.563350362,115.9098764
42,9.474336537,0.186806403,75698.35359,1.568152609,116.6309828
42.2,9.629791858,0.188573169,75585.34742,1.581249648,117.4647965
42.4,9.635777406,0.19036796,75683.14572,1.588671305,118.1924682
42.6,9.64384258,0.19218064,76192.15748,1.588234737,118.9792288
42.8,9.803038715,0.194001211,76784.65958,1.588234733,119.9334093
43,9.560876544,0.195867598,77168.42479,1.589981012,120.679682
43.2,9.744216373,0.197723405,77956.66551,1.586488462,121.6568418
43.4,9.909234855,0.19959926,78213.1918,1.590854138,122.4074931
43.6,9.804876204,0.201512414,78279.37327,1.599148935,123.1570491
43.8,9.734655573,0.203442434,78263.2345,1.610499708,123.9656944
44,9.862612705,0.205378291,78356.04101,1.617921362,124.6419371
44.2,9.868994955,0.207341944,78581.46359,1.624906452,125.4691849
44.4,10.01818111,0.209315427,78937.3036,1.627525856,126.1804433
44.6,9.889246768,0.211327975,79252.44882,1.631018405,126.9179624
44.8,10.10504339,0.213337078,79480.07861,1.637130351,127.7441172
45,10.25172325,0.215381493,79847.88436,1.640186324,128.5834019
45.2,9.999543807,0.21746354,80136.40227,1.642369172,129.2476061
45.4,10.15204887,0.219538699,80352.79839,1.64629828,129.950111
45.6,10.43778301,0.221614952,80651.3808,1.650663953,130.8331666
45.8,10.42124732,0.22374344,81106.04769,1.649354249,131.5050316
46,10.76276548,0.225868707,81601.72744,1.649790807,132.3815217
46.2,10.68377313,0.228044315,81922.33434,1.651537082,133.047915
46.4,10.84126196,0.230225471,82250.79621,1.653719917,133.763551
46.6,11.200259,0.232414779,83010.53195,1.650227362,134.7253919
46.8,11.54676317,0.234626797,83251.11507,1.653283328,135.3753741
47,11.73505379,0.23687203,83505.12989,1.658085571,136.1960572
47.2,11.92084372,0.239140044,83984.46914,1.658958702,137.0616045
47.4,11.71526711,0.241457685,84587.45226,1.655902732,137.7914635
47.6,11.46805335,0.24380129,85155.7028,1.654156467,138.572752
47.8,12.18176014,0.246102315,86179.18973,1.64629822,139.5389719
48,11.96951388,0.248490323,86994.12098,1.640622841,140.3388623
48.2,11.89549127,0.250892527,87603.35474,1.640186276,141.2908538
48.4,12.0929225,0.253300264,87667.02388,1.647607927,142.0185262
48.6,12.18043596,0.255739638,87743.78388,1.654593014,142.7308788
48.8,12.16386043,0.258210741,87579.15186,1.666380352,143.5209222
49,12.33796782,0.260693548,87453.57346,1.675548277,144.1490186
49.2,12.23145606,0.263220656,87403.13666,1.685589346,144.9171766
49.4,12.21487179,0.265766875,87474.46013,1.6917013,145.5693455
49.6,12.52636405,0.268316189,87693.91446,1.695193835,146.2335525
49.8,12.26496321,0.270930497,88014.99314,1.699122956,147.0323485
50,12.25419875,0.273553794,88508.59302,1.69824982,147.705308
50.2,12.61814136,0.276177568,89187.50144,1.6956304,148.5478771
50.4,12.75225867,0.278843651,89848.48849,1.692137852,149.2952457
50.6,12.5932663,0.281556667,90246.68979,1.693010993,150.0196341
50.8,12.80814818,0.284271191,90762.38743,1.693010986,150.8840871
51,13.01303461,0.287013769,91156.943,1.69301098,151.5756499
51.2,13.76332923,0.289746203,91839.48143,1.688208706,152.3186451
51.4,13.69758531,0.29256226,92483.78978,1.684716165,153.0988395
51.6,13.71094357,0.295401165,93611.03035,1.675548234,154.1252397
51.8,14.298854,0.298229087,94893.00249,1.663760878,155.1505486
52,14.48873571,0.301112918,95782.11162,1.657648919,155.9931174
52.2,14.67611601,0.3040257,96446.80519,1.656775778,156.9659005
52.4,14.61368616,0.306984954,97103.57837,1.654592941,157.8237863
52.6,14.54958748,0.309974036,97810.51196,1.651973533,158.7407622
52.8,14.82022633,0.312970185,98201.14828,1.65546607,159.7080746
53,14.72531116,0.31602152,98582.72057,1.656775778,160.5079658
53.2,14.95888827,0.319080998,99320.80875,1.654592929,161.5496866
53.4,14.97512994,0.322186252,99456.13029,1.660704882,162.3988194
53.6,15.17830666,0.325309987,99519.57832,1.667253397,163.1494713
53.8,15.04174259,0.328488405,99902.60007,1.670309378,164.102556
54,15.45100251,0.331661236,100172.7918,1.67380191,164.86634
54.2,15.75367451,0.334873356,100220.3775,1.682096694,165.7395476
54.4,15.6520722,0.338145479,100768.9104,1.681005278,166.5060646
54.6,15.91518388,0.341425522,101594.1425,1.677294441,167.4804893
54.8,15.7236435,0.344769689,101823.2498,1.682533264,168.383239
55,15.94303127,0.348119233,101908.5362,1.688208641,169.087933
55.2,16.18281599,0.351501108,102024.2891,1.695193723,169.9775537
55.4,16.12033063,0.354937733,101728.144,1.706107926,170.6122147
55.6,15.74641555,0.358430167,101510.132,1.716149003,171.2840778
55.8,15.87793867,0.361922895,102173.5772,1.713966159,172.1966774
56,16.12436879,0.365442887,102952.4445,1.708727335,172.9932878
56.2,16.26462693,0.369005628,103767.4477,1.704798218,173.9540342
56.4,16.23001621,0.372616147,104842.8402,1.696503426,174.853502
56.6,16.22079828,0.376261211,105759.0381,1.69126461,175.7573469
56.8,16.22489912,0.379941967,106221.9959,1.693884019,176.7148096
57,16.44507848,0.383644793,106444.9929,1.69868626,177.5322105
57.2,16.77142136,0.38737757,106905.004,1.699559386,178.3857221
57.4,16.86502329,0.391163845,107010.8867,1.7047982,179.1309023
57.6,16.70798139,0.395005331,106900.9569,1.71374785,179.9740159
57.8,17.1229924,0.398845995,106592.6291,1.724443754,180.679258
58,16.91972727,0.402767925,106714.8413,1.729246009,181.5174472
58.2,17.04495341,0.40670656,106845.2812,1.733175117,182.1925958
58.4,17.33546372,0.410673445,107028.7524,1.736667652,182.8830654
58.6,17.39281644,0.414696325,107807.7458,1.734048242,183.8525651
58.8,17.28654107,0.418770799,108675.1056,1.728372861,184.6294771
59,17.41757732,0.422869865,109363.613,1.727499721,185.5694331
59.2,17.77551655,0.426994602,109815.5683,1.727936278,186.2894473
59.4,17.93110751,0.431174728,110359.0619,1.727499705,187.0794919
59.6,18.03631589,0.435400336,110773.0484,1.730555678,188.0522748
59.8,18.49915929,0.439643757,110831.9314,1.735794479,188.7121062
60,19.10730198,0.44391965,110868.2299,1.742779548,189.539358
60.2,19.65881682,0.448242369,110979.4165,1.746708643,190.1816829
60.4,19.90847682,0.452629434,111696.0749,1.742342954,190.980482
60.6,19.80715325,0.45708478,113133.3354,1.729682485,192.1097405
60.8,20.19586197,0.46155113,114390.8548,1.718331705,193.026719
61,20.0899482,0.466096325,116298.5399,1.699777567,194.1740324
61.2,20.21010419,0.470671655,118306.9981,1.681223423,195.3859073
61.4,20.36814218,0.475290361,119274.592,1.67642117,196.4079319
61.6,20.48828742,0.479958054,120022.8212,1.676421167,197.6083178
61.8,20.58219753,0.484674221,120504.1885,1.6772943,198.4859013
62,20.8301496,0.489427227,120606.5533,1.685152516,199.5221518
62.2,20.92238326,0.494238726,120426.946,1.694320442,200.2640492
62.4,21.1703213,0.499112251,120734.1743,1.697812978,201.149294
62.6,21.32000204,0.50399256,121602.8905,1.696066701,202.351868
62.8,21.5304576,0.508967379,122367.4706,1.693447287,203.2710342
63,22.02985334,0.513947243,123363.9428,1.689518159,204.4747053
63.2,22.57587383,0.518974057,124193.9452,1.68558903,205.4562459
63.4,22.88457208,0.524067679,124876.3334,1.683842749,206.4738945
63.6,22.78524979,0.529214581,125502.6402,1.684715888,207.7541585
63.8,22.90991181,0.534423733,126356.358,1.680350204,208.72913
64,23.41094316,0.539659298,127854.5057,1.670745693,210.0936552
64.2,23.39486852,0.544983182,129276.613,1.661577766,211.2382337
64.4,23.60361369,0.550345095,130568.8425,1.65502924,212.4309608
64.6,23.54922286,0.555779003,131528.5897,1.654592673,213.8304979
64.8,24.1218405,0.561224323,131691.7109,1.661141176,214.8251695
65,23.69022887,0.566793418,131420.0373,1.674238229,215.9347291
65.2,24.05882483,0.572363453,131167.4457,1.684715849,216.8068438
65.4,24.33415311,0.577995872,131356.481,1.689954656,217.7785339
65.6,24.36050081,0.583702056,131996.6872,1.691700927,219.0358202
65.8,24.28109035,0.589472751,132517.3762,1.692574066,220.0239213
66,24.42316841,0.595286176,133644.1441,1.688208382,221.3107527
66.2,24.45032863,0.601165734,134534.5787,1.685152405,222.3710748
66.4,24.37006511,0.607111639,135064.0857,1.686462112,223.3744956
66.6,24.50962452,0.613102227,136011.519,1.685588972,224.7816937
66.8,24.54009468,0.619160533,136670.9526,1.686898675,226.0138121
67,24.50227727,0.625284267,136662.4351,1.693883764,226.9482956
67.2,24.64015007,0.63145759,137060.0059,1.697812871,228.1300799
67.4,24.45326696,0.637715179,137437.7325,1.700868853,229.1466303
67.6,24.85342227,0.643995224,137564.7126,1.706980792,230.1555264
67.8,24.95796566,0.650358712,137598.7421,1.714839013,231.2497707
68,25.16658772,0.65677903,137691.182,1.72051439,232.1317321
68.2,25.49177872,0.663255944,137580.8894,1.728372603,232.9600771
68.4,25.20826654,0.669839703,137520.6356,1.735794268,233.8190562
68.6,25.57924018,0.67644458,137687.2923,1.741906208,234.919868
68.8,25.81947395,0.683124734,137979.4039,1.744525607,235.7755692
69,25.87567566,0.689884598,138424.7931,1.746271878,236.8358912
69.2,26.04344978,0.696704754,139226.5085,1.743652462,237.9640574
69.4,26.38941136,0.703581218,139530.8928,1.744089022,238.6523391
69.6,27.87365063,0.710448756,140404.2279,1.741032995,239.8625847
69.8,28.71504606,0.717429012,141711.7049,1.733611313,241.1384807
70,28.96106075,0.724520469,143218.1943,1.723570243,242.24914
70.2,29.24537084,0.731680609,145013.7448,1.712656036,243.6300779
70.4,29.56714356,0.738910121,146762.1354,1.701741828,244.889555
70.6,29.6507588,0.746228675,148482.62,1.691700762,246.2365697
70.8,30.21899037,0.753587813,149596.8187,1.687335065,247.4293001
71,30.05153273,0.761071464,150581.0895,1.686025367,248.8747946
71.2,30.09390392,0.768615935,151234.0058,1.686025366,249.9821696
71.4,30.4031431,0.776217769,151647.7732,1.689081333,251.1333162
71.6,30.69613595,0.783897196,152217.4605,1.693010435,252.5722493
71.8,30.93874214,0.79165723,153005.1637,1.692573859,253.6905682
72,30.71794791,0.799527139,153648.5908,1.694756706,254.9850569
72.2,31.01424427,0.807440563,154227.7044,1.697812673,256.3222246
72.4,31.49080853,0.815421041,154962.3034,1.697812657,257.4799392
72.6,31.70048666,0.82350018,155260.5774,1.70217833,258.6223312
72.8,32.11416412,0.831646481,155290.2387,1.709599972,259.8774324
73,32.11148764,0.839903244,155513.1279,1.713529083,260.920247
73.2,32.39857725,0.848222819,155639.6404,1.719641025,262.1764412
73.4,32.72562619,0.85662334,155763.9921,1.724443262,263.2203529
73.6,33.23419147,0.86509576,156304.2662,1.725316381,264.3408629
73.8,33.55830627,0.873666132,157687.1433,1.719640988,265.7918331
74,33.70088489,0.882334967,158696.3566,1.716148441,266.9200001
74.2,33.80265164,0.891093748,160450.1578,1.707417079,268.4738269
74.4,34.19251847,0.899920778,161649.799,1.703051388,269.76285
74.6,34.32757221,0.908853948,162460.539,1.702178248,271.0026294
74.8,34.39933116,0.91788124,162533.2545,1.7095999,272.3496444
75,34.86036158,0.926972479,162629.386,1.7148387,273.3519761
75.2,34.969154,0.936179396,162322.7501,1.726189462,274.5589283
75.4,34.85935486,0.945493744,162472.7477,1.731428281,275.5875162
75.6,35.2612321,0.954866539,162797.1413,1.735357379,276.6686327
75.8,36.05779287,0.964306311,163509.772,1.736667057,277.9675078
76,36.18069738,0.973887279,163960.5012,1.740159596,279.2149471
76.2,36.48761491,0.983551884,164637.5761,1.739723018,280.2851209
76.4,36.30989628,0.99334685,165108.5308,1.741469296,281.3749861
76.6,37.35788407,1.003156037,165950.9108,1.740596126,282.6678448
76.8,37.7651064,1.013107713,166779.1483,1.739286409,283.9114578
77,38.12693555,1.023162571,168596.6935,1.729681905,285.4291774
77.2,38.66528297,1.033306238,170179.644,1.721387098,286.6886576
77.4,38.99378097,1.043566297,171843.9676,1.713528866,288.0728796
77.6,39.78690728,1.053897491,173244.5861,1.710036298,289.7065936
77.8,39.95592131,1.064375472,174188.7354,1.708726589,290.9660702
78,40.0058486,1.07496695,174406.1812,1.715275105,292.3524779
78.2,40.6507196,1.085623972,174334.5967,1.722696738,293.417184
78.4,40.38045326,1.096450945,174636.1648,1.726625858,294.5475351
78.6,40.85085088,1.107335665,175618.3508,1.726189275,296.1123093
78.8,41.03770526,1.118349406,176590.6475,1.72400643,297.3499012
79,41.28783111,1.129469462,178306.535,1.717021336,298.9978352
79.2,41.20736661,1.140723433,179754.7571,1.710909389,300.3568859
79.4,41.75182185,1.152047319,180563.6644,1.710472804,301.6667016
79.6,41.86409843,1.163514671,181333.7617,1.712219072,303.3157292
79.8,42.32775622,1.175073131,181418.7458,1.717894439,304.4789149
80,42.4166906,1.186773512,181021.4529,1.728808632,305.8182709
80.2,42.63384534,1.198582785,180498.4134,1.738849685,306.7844908
80.4,42.7926911,1.210574736,180246.1331,1.746707901,307.7824427
80.6,43.07644014,1.222558208,180594.3573,1.751510138,309.1797959
80.8,43.43010684,1.234779286,181487.874,1.749763856,310.3517347
81,44.46241484,1.246953318,183086.0219,1.743651872,311.8782164
81.2,44.97426372,1.259409838,184521.7099,1.737539906,313.1486395
81.4,45.3062519,1.271878341,185853.608,1.73273765,314.4814331
81.6,45.76895028,1.284526195,186905.0409,1.731864499,316.1304641
81.8,46.31323737,1.297295501,187650.4412,1.731427914,317.3877567
82,46.48946116,1.310218455,187905.8752,1.736230154,318.8069933
82.2,47.32682461,1.323225744,188110.2545,1.740595805,319.9373565
82.4,47.8310974,1.336386639,189078.1166,1.738849518,321.2154392
82.6,48.13467686,1.349693623,190310.4221,1.737103237,322.8721287
82.8,48.3191663,1.363142454,191509.6458,1.734047256,324.1874126
83,49.07236632,1.376687389,193816.4036,1.723569605,325.9688509
83.2,49.31094896,1.390403751,196381.4765,1.710909132,327.824692
83.4,49.50121965,1.4042612,198325.9756,1.702614338,329.4573069
83.6,49.71395672,1.418256439,200980.0595,1.689517298,331.3197134
83.8,49.81509718,1.432399805,202797.1835,1.683841914,333.25981
84,50.29009828,1.446659617,203818.5404,1.682968764,334.8169244
84.2,50.74426551,1.46106401,204060.7037,1.689517266,336.5502134
84.4,51.17926413,1.475613993,203566.396,1.700431447,337.8950454
84.6,51.45520223,1.490321058,202551.1922,1.71571131,339.1216965
84.8,52.22657281,1.50514185,201627.842,1.730991157,340.4873229
85,52.47499769,1.520147449,201262.8328,1.740159072,341.5782874
85.2,52.7175762,1.53530423,202247.7991,1.740595631,343.1835472
85.4,53.06505576,1.550606026,203922.4892,1.734483672,344.6585923
85.6,53.73143713,1.566039778,205724.8716,1.727498566,346.2529148
85.8,53.97812546,1.581657316,208404.6141,1.715711229,348.2816471
86,54.29640674,1.597426869,210411.3934,1.707416432,349.8901905
86.2,54.46561837,1.613365055,212152.7554,1.70305075,351.8291944
86.4,54.99286741,1.629438855,212943.6804,1.703923868,353.3666134
86.6,55.40435397,1.645682032,214282.1207,1.703050719,355.4073858
86.8,55.81582154,1.662088472,214984.065,1.70436041,356.8835262
87,56.40296722,1.678647574,215609.1,1.706543228,358.3749895
87.2,56.97260707,1.695374362,216260.8143,1.710035752,360.1586145
87.4,57.22996919,1.712290683,216885.8879,1.712655152,361.652262
87.6,57.542269,1.729373128,217400.1278,1.717893953,363.4873141
87.8,57.86121035,1.746626651,217805.371,1.721823053,364.8999887
88,58.80048442,1.764010996,217998.0455,1.72793497,366.5194826
88.2,59.36003218,1.78159659,218590.0216,1.729681222,367.9310654
88.4,60.11232672,1.799345888,219544.1262,1.728808063,369.4389442
88.6,60.80464694,1.817277727,220998.272,1.726188634,371.3998397
88.8,61.42158789,1.835394867,222251.8965,1.72356921,372.9635234
89,61.84365859,1.853707488,224379.6697,1.71702068,374.9889761
89.2,62.3789535,1.872196325,225791.9548,1.714619542,376.7490752
89.4,62.62195318,1.890890948,226988.3913,1.713964683,378.5682602
89.6,63.28502228,1.909744707,227472.0349,1.717020636,380.1385104
89.8,63.70076091,1.928804858,227359.7331,1.72487884,381.9166634
90,64.02113445,1.948063023,226761.3361,1.734046751,383.1739555
90.2,64.33440762,1.967515221,227058.4379,1.738848985,384.8667565
90.4,64.83251488,1.98715014,227660.3192,1.741031807,386.3549366
90.6,65.35932693,2.006980409,228682.2535,1.74103179,387.9580126
90.8,66.04682464,2.02699887,230894.8399,1.734919821,389.9725263
91,66.13018359,2.04725998,233785.8126,1.722695924,391.7747484
91.2,66.49080407,2.067705611,235502.3201,1.719639939,393.7159445
91.4,67.10661961,2.088339164,236365.5913,1.720949623,395.3288699
91.6,67.52672928,2.109193498,237842.5535,1.719421622,397.2974226
91.8,67.97179524,2.130255575,238653.5682,1.721386162,399.0908958
92,68.58462327,2.151517777,238156.1398,1.731208914,400.606981
92.2,69.20700237,2.172992819,238609.7729,1.734919719,402.2237377
92.4,69.80062863,2.194685653,239413.4944,1.735792835,403.796175
92.6,70.59907082,2.216582436,239882.7112,1.740158485,405.734095
92.8,70.6197566,2.238752703,240383.733,1.742341323,407.1391055
93,71.38775418,2.26109426,241890.0052,1.739721892,409.0945325
93.2,71.80266583,2.283684607,243389.6246,1.73579277,410.7588853
93.4,72.52856012,2.30648063,245197.0189,1.730553936,412.5271962
93.6,72.79062042,2.329537572,247758.272,1.723132278,414.8437169
93.8,73.34492734,2.352806136,249791.8901,1.717456882,416.696282
94,74.13985394,2.376291969,251892.2358,1.713091181,418.9296483
94.2,74.81692773,2.400021799,252982.3153,1.714837429,421.0163841
94.4,75.21959599,2.424069356,253230.7396,1.71963966,422.5767834
94.6,75.49817973,2.448245613,254249.438,1.720949354,424.5289214
94.8,76.20264812,2.472696522,254981.924,1.724441871,426.5500029
95,76.83256234,2.497398229,256039.1945,1.724441851,428.2198304
95.2,77.44038145,2.522349559,257474.8623,1.724005264,430.3382993
95.4,77.94200367,2.547558914,259559.3486,1.718766437,432.3046652
95.6,78.57890825,2.57301221,261571.5566,1.713964174,434.3465368
95.8,79.12418739,2.5987275,263531.6089,1.710471616,436.6400838
96,79.77976762,2.624693772,264848.2362,1.709161893,438.4795204
96.2,80.60060609,2.650909606,266437.2946,1.707852164,440.8365371
96.4,81.17826899,2.677405526,267754.8666,1.706979011,442.7853974
96.6,81.5281608,2.704182829,268569.1133,1.710908107,445.1073919
96.8,82.16904588,2.731208382,269649.2747,1.711344654,446.9326031
97,82.64086372,2.758516868,271370.3999,1.709598369,449.1889451
97.2,83.68553903,2.786060344,273263.2867,1.706105796,451.2034678
97.4,84.54782345,2.813893103,273870.1204,1.709598308,453.1260707
97.6,85.31348352,2.842012195,274541.8285,1.713963959,455.4229038
97.8,85.67026091,2.870441908,274788.082,1.720512459,457.5566895
98,86.55992536,2.899120987,274564.49,1.727934078,459.1477363
98.2,87.51119214,2.927938176,274265.3243,1.737101964,461.1239601
98.4,87.91862867,2.957523477,275601.6134,1.736228816,462.9612049
98.6,89.51680866,2.987029823,277408.6311,1.733172792,464.968077
98.8,89.85842801,3.016919047,278952.7562,1.732299646,467.2386423
99,90.55557018,3.047084085,280123.3962,1.731863056,469.0419708
99.2,91.03203262,3.077414131,280361.0288,1.737974985,471.0936896
99.4,91.77323656,3.108183909,280537.1121,1.742777202,472.7865002
99.6,92.32122093,3.13927616,280202.9639,1.750198831,474.4431974
99.8,93.277186,3.170652995,280229.0408,1.756747311,476.3526717
100,93.71434985,3.202380686,281105.7311,1.757183864,478.0378181
100.2,94.59613195,3.234396552,282748.2126,1.754564431,480.2471155
100.4,95.09650558,3.26676031,283558.6857,1.755874116,482.0208965
100.6,95.69509855,3.299442524,284409.0014,1.757183799,483.7651353
100.8,96.16458673,3.332461804,286409.9209,1.753254677,486.0192909
101,97.19943134,3.365774129,287781.6782,1.753254643,488.2121765
101.2,98.03522462,3.399434836,288744.4999,1.75412775,489.8940464
101.4,98.53540536,3.43345686,289632.7059,1.755437436,491.6492264
101.6,99.455221,3.467791739,290142.2734,1.760239647,493.7994365
101.8,100.1593304,3.502486341,290265.0551,1.765041865,495.374068
102,100.8792204,3.537527231,291504.3715,1.765041841,497.4564309
102.2,101.7997473,3.572906252,293368.5725,1.76023957,499.3199474
102.4,102.8134938,3.60863425,296712.2311,1.748452218,501.5566046
102.6,103.3484031,3.644754004,301309.7453,1.732299209,504.5088905
102.8,103.92657,3.681233675,304535.8744,1.722258141,506.836364
103,104.8444308,3.718056516,307622.4293,1.7143999,509.6310844
103.2,105.6706529,3.755255716,308902.9207,1.714399873,511.7462784
103.4,106.0738263,3.79285762,309050.0804,1.720511803,513.8231649
103.6,107.086483,3.830795477,310151.4356,1.723567741,516.4099823
103.8,108.081609,3.869115752,311568.2145,1.723131142,518.5153297
104,108.6303695,3.907851629,312295.7408,1.727496797,520.9128339
104.2,109.7436471,3.946937911,313943.9548,1.725750492,523.035692
104.4,110.4954925,3.986441759,315372.0065,1.7253139,525.2417061
104.6,111.297253,4.02633904,316427.0392,1.72749671,527.8274271
104.8,111.9340947,4.066648598,316669.0924,1.73229893,529.7598776
105,112.5517375,4.107364268,319270.4315,1.727496669,532.4703388
105.2,113.4815905,4.148467693,321481.569,1.723567531,534.6686975
105.4,114.1091299,4.190004929,324315.8666,1.717455572,537.0924642
105.6,114.8765123,4.231950032,327409.0404,1.712653307,540.253759
105.8,115.722118,4.274313127,329577.5758,1.709597309,542.5812378
106,116.6659314,4.317095031,329994.9624,1.71570922,545.101306
106.2,117.7191931,4.360299302,330511.4729,1.72138456,547.6290361
106.4,118.5184347,4.403955214,330796.6829,1.726623342,549.75955
106.6,119.7048249,4.448022969,331541.7984,1.729679274,551.9874577
106.8,120.3819752,4.492568653,332999.3364,1.730552386,554.6289844
107,121.6253009,4.537522965,334157.6313,1.731425481,556.7846748
107.2,122.5929545,4.582947944,334098.2644,1.738410525,559.1843763
107.4,123.3228227,4.628845621,334376.6293,1.742776172,561.2032759
107.6,123.9119131,4.675214109,335363.4669,1.744522422,563.3272207
107.8,125.0684258,4.722009567,336122.5063,1.748451488,565.7685094
108,125.7789797,4.769305724,337023.0772,1.750634301,567.9427922
108.2,126.9253902,4.81704712,339678.7724,1.745395457,570.4387919
108.4,127.9110362,4.865279376,341492.3719,1.743649157,572.6798305
108.6,128.7754697,4.914004668,343795.486,1.741029725,575.5653767
108.8,129.7984733,4.963208539,345705.1188,1.738410289,577.8556569
109,131.0641477,5.012889997,349018.0211,1.731425174,580.7740409
109.2,131.898432,5.063100443,351305.3265,1.727496043,583.0774477
109.4,132.8350782,5.113808232,354173.7446,1.72182064,585.7375819
109.6,133.903646,5.165016635,356334.9414,1.720947472,588.843078
109.8,134.9455079,5.216741299,357873.754,1.722257139,591.7330075
110,136.1538468,5.268974202,358242.6084,1.726622771,593.8941708
110.2,136.8187963,5.32176921,358159.4418,1.734480956,596.5236617
110.4,138.1623241,5.375048051,356970.6011,1.745831656,598.4791089
110.6,139.409198,5.428868847,356958.2142,1.751943554,600.5921272
110.8,140.3141908,5.483254002,357936.7412,1.754344643,602.956269
111,141.3777469,5.538174658,358847.1994,1.756745726,605.1770662
111.2,142.4574763,5.593645896,360599.1107,1.75674569,607.7989075
111.4,143.435553,5.649681514,363512.875,1.75063372,610.3167918
111.6,144.6342262,5.706264908,366456.6867,1.744958309,612.9320696
111.8,145.5001749,5.763439817,368585.6927,1.74364858,615.7289859
112,146.2120096,5.821199837,370403.5671,1.743648557,618.545595
112.2,147.5449613,5.879497327,371659.8632,1.74408508,620.7724184
112.4,148.6996498,5.938392938,372390.1566,1.747141011,623.0802117
112.6,149.8384485,5.997881459,373048.226,1.751070076,625.7458246
112.8,150.9850881,6.057967082,374271.6183,1.751070038,627.9715502
113,152.0254899,6.118663625,376291.8084,1.748887169,630.8603875
113.2,153.2943933,6.179954449,379059.635,1.743648324,633.8444306
113.4,154.4974428,6.241865522,381357.4092,1.739719182,636.4947259
113.6,155.8586305,6.304387728,384546.6709,1.732734067,639.2435076
113.8,157.0607018,6.367549118,387274.2815,1.729241493,642.5339381
114,158.1561154,6.43135255,389296.1199,1.727058623,645.1043525
114.2,159.2664432,6.49579278,391048.5367,1.72793172,648.2733218
114.4,160.5598867,6.560867757,392537.6254,1.729241379,650.914865
114.6,161.9989743,6.626586569,393371.3743,1.732733867,653.4229148
114.8,163.2156578,6.69298094,396607.487,1.728804725,656.8074537
115,164.4988786,6.760037722,398144.4672,1.729677817,659.2979929
115.2,165.8128304,6.827766348,401573.611,1.725312106,662.6573658
115.4,166.7861341,6.896198826,405103.4908,1.719200139,665.6457821
115.6,167.9733179,6.965651833,407691.649,1.717017266,668.6560868
115.8,169.4552728,7.035084454,409639.6753,1.717890352,671.9290188
116,170.6706046,7.10593967,413299.9749,1.712651511,675.4744148
116.2,172.1365333,7.177136144,415174.6847,1.712214897,678.2461808
116.4,173.4125262,7.249061624,416389.9995,1.714834256,681.1842694
116.6,174.4044889,7.321728963,418545.1615,1.715270791,684.6640049
116.8,175.9185041,7.39472161,419450.6622,1.718763276,687.36027
117,177.180087,7.468834093,419085.4992,1.727931136,690.3694853
117.2,178.6963853,7.543673595,420189.5439,1.731423621,693.4618685
117.4,180.1151718,7.619271911,421410.3256,1.733606408,696.2850659
117.6,181.4397764,7.695636199,422533.0083,1.735789198,698.9955518
117.8,182.7068363,7.772771675,424482.8056,1.735789157,702.3133472
118,184.1103666,7.850672809,426076.3738,1.735352544,704.9023756
118.2,185.4322026,7.929362199,427296.1388,1.7379719,708.0976164
118.4,186.9138224,8.008831163,429434.5867,1.736225585,711.028051
118.6,188.3520496,8.089101722,431518.7458,1.735788971,714.5953409
118.8,189.859296,8.170173905,433462.1237,1.734915789,717.3375679
119,191.2107352,8.252071353,435823.198,1.734479178,720.7604122
119.2,192.6137052,8.334788217,436101.3575,1.739281364,723.2400178
119.4,194.1872792,8.418324087,435261.9629,1.748885778,725.659444
119.6,195.8498535,8.502689827,435663.4539,1.755870788,728.8087368
119.8,197.5231539,8.587902778,434946.5801,1.763728931,730.9611667
120,198.8099884,8.673997929,433995.3241,1.772896786,733.5162727
120.2,200.2282867,8.760949083,434572.0959,1.775516137,735.7485794
120.4,201.3650354,8.848793116,436331.4711,1.774206399,738.4240489
120.6,203.0862271,8.937479407,439038.9873,1.770277243,741.7593671
120.8,204.7398676,9.027061543,443391.1592,1.761109291,745.2916485
121,206.5516137,9.117532782,448478.0862,1.749321935,748.4190621
121.2,208.1017905,9.208931011,452747.3185,1.741900254,752.0804632
121.4,209.8383822,9.301234701,456997.5629,1.734042,755.4595536
121.6,211.3808502,9.394479078,459380.9857,1.73273225,758.5760194
121.8,212.6650765,9.48867808,462438.254,1.730985942,762.3796664
122,214.4080026,9.583791939,464690.3571,1.730549319,765.3987497
122.2,215.8327316,9.679883205,469626.0445,1.723564209,769.4267244
122.4,217.7353099,9.77690716,474415.3221,1.715705951,772.9086807
122.6,219.2480778,9.874932703,481477.9427,1.703045477,777.7299879
122.8,220.9847236,9.973927562,485540.3899,1.697806624,781.2994789
123,222.7862031,10.07391279,489026.0817,1.695623734,785.5299043
123.2,224.6316977,10.17490318,489993.7379,1.699116205,788.7207899
123.4,226.314284,10.27692086,489982.4271,1.706101213,792.0561123
123.6,227.8739298,10.37997194,489244.9107,1.71701532,795.8313209
123.8,229.6953349,10.4840405,487657.2942,1.727929417,798.5363593
124,231.6202876,10.58914769,485232.5274,1.742336042,801.6145407
124.2,233.1828992,10.69533583,483819.1374,1.751940448,804.0088054
124.4,234.9069276,10.80257967,483201.5198,1.759798585,806.7105594
124.6,236.8506597,10.91088596,481971.4895,1.77027611,809.9222397
124.8,238.8517205,11.0202766,482946.7787,1.772458874,812.4642412
125,240.5391472,11.1307879,486496.7523,1.768093153,815.9429154
125.2,242.6648537,11.24237942,490728.5425,1.761108025,819.1053614
125.4,244.2662541,11.35512821,494791.551,1.754996044,822.4592864
125.6,246.2551379,11.46898324,501090.4194,1.744081824,826.8812138
125.8,247.9924175,11.58399947,506364.4535,1.735132161,830.8003267
126,249.9722904,11.70015465,511072.6908,1.727928754,834.6537906
126.2,252.2888488,11.81745382,515506.2166,1.722253319,839.0133571
126.316,253.6162025,11.88602778,517310.2858,1.720070445,840.817816
126.6,255.3110432,11.88828707,522529.0319,1.715268163,846.5823854
126.8,256.4413627,11.88821004,526331.447,1.713085296,851.1377898
127,257.251931,11.88815488,527625.2993,1.716141233,854.4282295
127.2,258.0562541,11.88810016,526508.5912,1.72792849,858.1322961
127.4,258.8618263,11.88804535,525959.355,1.736223219,861.116346
127.6,259.4354956,11.8880064,523270.1176,1.75062988,863.8891983
127.8,260.0682855,11.88796342,520712.6607,1.765036539,866.8809023
128,260.3038846,11.88794761,521273.6079,1.768965626,869.5443202
128.2,260.9121103,11.8879063,525769.5225,1.762853681,873.4158018
128.4,261.3021725,11.88787992,529751.221,1.757614876,876.9064783
128.6,261.3441723,11.88787735,536026.1193,1.747573856,881.4498146
128.8,261.6884368,11.88785411,539462.6133,1.744081316,884.8398195
129,262.1442811,11.88782323,542233.7027,1.743644735,888.921394
129.2,262.3524015,11.8878093,541822.4147,1.750193219,891.7577029
129.4,262.590915,11.88779329,538859.9252,1.76459989,894.776205
129.6,262.7165996,11.887785,536957.7604,1.775514037,897.5780425
129.8,262.9684361,11.88776807,536874.4513,1.781625953,900.8071889
130,263.2802258,11.88774705,536782.6325,1.786428169,903.2276848
130.2,263.5291479,11.88773033,538659.317,1.786864727,906.5465603
130.4,263.6448403,11.88772272,543338.3412,1.779006534,909.9234261
130.6,263.8113264,11.88771164,545961.509,1.777260265,913.1635138
130.8,264.0490072,11.88769569,546537.0689,1.781625917,916.5217805
131,264.4244974,11.8876703,545584.1898,1.790357225,919.5364565
131.2,264.3124504,11.88767828,542881.6955,1.802581077,921.506109
131.4,264.5301467,11.88766369,538392.7865,1.820043711,923.1223255
131.6,264.7511738,11.88764888,534858.7256,1.83576008,925.2834826
131.8,264.8464654,11.88764267,533522.163,1.843618265,926.9500325
132,264.822683,11.88764461,532610.3899,1.851039888,929.124311
132.2,265.3767842,11.887607,532958.8613,1.853659265,930.9232792
132.4,265.3396788,11.88760985,534418.0654,1.8532227,933.0515983
132.6,265.6098343,11.88759168,534736.3854,1.857151785,935.4031562
132.8,265.6643244,11.88758826,534168.629,1.862390575,936.9766943
133,266.0110869,11.88756484,534268.3338,1.866319657,938.9966925
133.2,265.951499,11.88756923,535711.0839,1.865446527,940.8875595
133.4,266.1467129,11.88755618,536356.13,1.867192785,942.7116838
133.6,266.1304247,11.88755761,538231.2009,1.865883087,945.0796485
133.8,266.2548602,11.8875494,540931.8991,1.861953989,947.5395292
134,266.3951169,11.88754011,541505.9135,1.863700248,949.3395813
134.2,266.6036536,11.88752616,541143.0555,1.868502467,951.2972034
134.4,266.535739,11.88753111,542772.5679,1.866756206,953.2712341
134.6,266.7192952,11.88751886,542983.9736,1.868939029,955.0297017
134.8,266.7105011,11.88751977,544763.4394,1.867192766,957.3648388
135,266.8066254,11.88751351,547146.1844,1.863263669,959.4034326
135.2,267.050135,11.88749715,548706.2086,1.86326366,961.7790633
135.4,267.165411,11.88748958,547856.0429,1.86937558,963.3788647
135.6,267.3256521,11.88747892,547052.1895,1.876360631,965.1898571
135.8,267.1245078,11.887493,544737.7859,1.886401656,966.2589363
136,267.1939861,11.88748855,542433.6067,1.896006105,967.2087496
136.2,267.558235,11.88746394,540973.7616,1.902991148,968.5032614
136.322,267.8799161,11.88744212,540060.0114,1.907356796,969.2375163
137.1,267.854088,11.74551007,1.7977E+308,1.947084303,0
137.3,267.5343607,11.62675819,1.7977E+308,1.892950133,0
137.5,267.2287891,11.50800533,1.7977E+308,1.756741555,0
137.7,267.2970931,11.3892269,1.7977E+308,1.550682405,0
137.9,266.8557937,11.27048333,1.7977E+308,1.264731691,0
138.1,266.7284167,11.15171828,1.7977E+308,0.844755205,0
138.3,266.5743938,11.03295506,1.7977E+308,0.509909087,0
138.5,266.2813124,10.91420135,1.7977E+308,0.252335149,0
138.7,266.0398576,10.79544411,1.7977E+308,0.078145315,0
138.9,265.8500292,10.67668334,1.7977E+308,0.020518602,0
139.1,265.5677727,10.55792889,1.7977E+308,0.013970112,0
139.3,265.576956,10.4391545,1.7977E+308,0.003929094,0
139.5,265.2122638,10.32040569,1.7977E+308,0.00218283,0
139.7,264.8492368,10.20165677,1.7977E+308,0.006985056,0
139.9,264.4787157,10.08290836,1.7977E+308,0.010041018,0
140.1,264.5295333,9.96413112,1.7977E+308,0.009604452,0
140.3,264.3247166,9.845371372,1.7977E+308,0.01091415,0
140.5,263.900071,9.726626666,1.7977E+308,0.016589509,0
140.7,263.896764,9.60785313,1.7977E+308,0.023574565,0
140.9,263.4529666,9.489109734,1.7977E+308,0.033179018,0
141.1,263.2697997,9.370348505,1.7977E+308,0.039290943,0
141.3,262.9051074,9.251599696,1.7977E+308,0.038854377,0
141.5,262.9346915,9.13282391,1.7977E+308,0.036234981,0
141.7,262.6786647,9.014067666,1.7977E+308,0.03186932,0
141.9,262.4880035,8.89530695,1.7977E+308,0.02968649,0
142.1,262.1203968,8.776558341,1.7977E+308,0.029249925,0
142.3,261.9334828,8.657797368,1.7977E+308,0.032742453,0
142.5,261.6583042,8.539042435,1.7977E+308,0.038854378,0
142.7,261.3527325,8.420289581,1.7977E+308,0.045839435,0
142.9,261.0904605,8.301533765,1.7977E+308,0.045839435,0
143.1,261.0455193,8.182763077,1.7977E+308,0.044093171,0
143.3,260.5147062,8.064025636,1.7977E+308,0.038417813,0
143.5,260.5934188,7.945246488,1.7977E+308,0.033615586,0
143.7,260.1109015,7.826505741,1.7977E+308,0.027067095,0
143.9,259.9423065,7.707743515,1.7977E+308,0.024884265,0
144.1,259.7162563,7.58898522,1.7977E+308,0.025320831,0
144.3,259.5422489,7.470223364,1.7977E+308,0.028376794,0
144.5,259.0713892,7.35148182,1.7977E+308,0.029686492,0
144.7,258.9269421,7.232717942,1.7977E+308,0.030123059,0
144.9,258.8611838,7.113948679,1.7977E+308,0.024011134,0
145.1,258.2783279,6.995214798,1.7977E+308,0.01440668,0
145.3,258.6572235,6.87641511,1.7977E+308,0.006111925,0
145.5,257.8591185,6.757695958,1.7977E+308,0.017462643,0
145.7,257.9719711,6.638914474,1.7977E+308,0.025975681,0
145.9,257.5906251,6.520166805,1.7977E+308,0.026848814,0
146.1,257.3933025,6.401406544,1.7977E+308,0.017680926,0
146.3,256.9436762,6.282663547,1.7977E+308,0.00785819,0
146.5,256.9778401,6.163887448,1.7977E+308,0.01004102,0
146.7,256.699747,6.045132714,1.7977E+308,0.019208908,0
146.9,256.5161637,5.926371513,1.7977E+308,0.027067097,0
147.1,256.0298993,5.807631023,1.7977E+308,0.024884267,0
147.3,255.9845418,5.688860364,1.7977E+308,0.026630532,0
147.5,255.7576588,5.570102126,1.7977E+308,0.028813362,0
147.7,255.3042855,5.451359386,1.7977E+308,0.02794023,0
147.9,255.1024176,5.332302501,1.7977E+308,0.025539117,0
148.1,254.9541889,5.213835817,1.7977E+308,0.026193966,0
148.3,254.8751076,5.095067466,1.7977E+308,0.024884268,0
148.5,254.2410415,4.976337089,1.7977E+308,0.023138004,0
148.7,254.3031004,4.85755908,1.7977E+308,0.02357457,0
148.9,253.8418165,4.738816881,1.7977E+308,0.025539118,0
149.1,253.7664823,4.620048273,1.7977E+308,0.023138004,0
149.3,253.1711361,4.501315247,1.7977E+308,0.023138004,0
149.5,253.0770664,4.382547922,1.7977E+308,0.021828306,0
149.7,252.770662,4.263795125,1.7977E+308,0.017026079,0
149.9,252.2843976,4.145054635,1.7977E+308,0.011350719,0
150.1,252.1445302,4.026290443,1.7977E+308,0.007421624,0
150.3,251.7756744,3.90754192,1.7977E+308,0.004365661,0
150.5,251.5675269,3.7887824,1.7977E+308,0.003929095,0
150.7,251.0888256,3.669447522,1.7977E+308,0.006111926,0
150.9,250.8956664,3.550686976,1.7977E+308,0.014406683,0
151.1,250.6200023,3.432525947,1.7977E+308,0.014843249,0
151.3,250.3485706,3.313770757,1.7977E+308,0.012660418,0
151.5,250.1296673,3.194418103,1.7977E+308,0.012660418,0
151.7,250.1330218,3.075644111,1.7977E+308,0.014406683,0
151.9,249.385225,2.957515387,1.7977E+308,0.021828308,0
152.1,249.2487575,2.838157092,1.7977E+308,0.024884271,0
152.3,248.7508354,2.719417399,1.7977E+308,0.021828308,0
152.5,248.4826654,2.601255857,1.7977E+308,0.021828308,0
152.7,248.1929147,2.482501921,1.7977E+308,0.022264874,0
152.9,247.9889306,2.363742116,1.7977E+308,0.024011139,0
153.1,247.664207,2.244990573,1.7977E+308,0.024011139,0
153.3,247.346145,2.126238573,1.7977E+308,0.027067102,0
153.5,247.0072658,2.007487999,1.7977E+308,0.024011139,0
153.7,246.7041921,1.888734974,1.7977E+308,0.021828309,0
153.9,246.163803,1.769998188,1.7977E+308,0.019208912,0
154.1,245.9456632,1.651239351,1.7977E+308,0.012223853,0
154.3,245.5793054,1.532490657,1.7977E+308,0.002182831,0
154.5,245.4311112,1.413727035,1.7977E+308,0.006548493,0
154.7,244.8316014,1.294994294,1.7977E+308,0.009604456,0
154.864,244.5651949,1.197618037,1.7977E+308,0.011350721,0
230.1,244.1880713,1.064733454,1.7977E+308,0.023138009,0
230.3,243.9153906,0.94597835,1.7977E+308,0.021391744,0
230.5,243.663527,0.827221821,1.7977E+308,0.017462649,0
230.7,243.510753,0.708458513,1.7977E+308,0.013970119,0
230.9,242.7172275,0.589739047,1.7977E+308,0.016589516,0
231.1,242.3496206,0.470990438,1.7977E+308,0.020955179,0
231.3,241.5810756,0.352269263,1.7977E+308,0.023574577,0
231.5,241.167671,0.233523787,1.7977E+308,0.028813372,0
231.7,240.2263437,0.114814435,1.7977E+308,0.025757408,0
231.878,239.0810724,0.00918415,1.7977E+308,0.024011144,0