File: TestGB_17.csv
Time On Sample,Displacement Into Surface,Load On Sample,Harmonic Contact Stiffness,Harmonic Displacement,Harmonic Load
0,0,0,250.261023,0.279723818,2.24244962
0.2,0.129228639,0.000746527,8677.886586,0.167311444,2.313275296
0.4,0.134631519,0.001501319,17024.3942,0.135940548,2.36993583
0.6,0.263029286,0.00224682,22949.26615,0.113719498,2.52466269
0.8,0.238514492,0.003003873,27876.84681,0.098905464,2.665224406
1,0.377715864,0.003748557,33023.80943,0.087577086,2.806875767
1.2,0.459575027,0.004497574,37539.05354,0.080605776,2.943078986
1.4,0.601685064,0.005242039,38215.20981,0.083220018,3.097805856
1.6,0.515257302,0.006003768,40130.39177,0.091934155,3.621915796
1.8,0.203200408,0.006782541,40999.19774,0.101519705,4.104619916
2,0.541437426,0.00751219,39967.84162,0.116333742,4.578607152
2.2,0.444621583,0.008274704,39190.24339,0.130712069,5.049325434
2.4,0.623297668,0.009016406,39507.0308,0.139426208,5.460114365
2.6,0.632855783,0.009770883,42062.9374,0.152061709,6.368862213
2.8,0.934942285,0.010503263,40977.74175,0.176025592,7.202425954
3,0.445456945,0.011295439,40013.60008,0.200425172,8.024003568
3.2,0.74837449,0.012027756,40014.24209,0.222210522,8.840133325
3.4,0.466650789,0.012804237,38884.28692,0.247481518,9.514611518
3.6,0.73466438,0.013539191,38917.04313,0.277981006,10.63474685
3.8,1.01348158,0.014273328,39400.60096,0.302380598,11.66553292
4,0.791177703,0.01504532,39933.59512,0.325473061,12.68324324
4.2,0.643668019,0.015811663,39759.99669,0.354229712,13.72383567
4.4,0.782869396,0.016556347,39490.94006,0.379065009,14.57374384
4.6,0.946171124,0.01729921,39297.52015,0.41348586,15.81809649
4.8,1.183436,0.018036485,39328.62296,0.443549644,16.98399617
5,0.564722912,0.018838424,39113.09501,0.474920523,18.09214506
5.2,0.560984282,0.019593906,38414.97551,0.506727127,18.97474188
5.4,0.434250763,0.020358679,37029.84838,0.550297811,19.8867584
5.6,0.53189981,0.021106503,35214.94404,0.611296782,21.01887966
5.8,0.332865243,0.021876738,32756.84926,0.686674069,21.98101894
6,0.477052896,0.022621046,30038.54396,0.775558284,22.79932799
6.2,0.279680422,0.023391155,27819.97074,0.86269965,23.5217496
6.4,0.3939504,0.024137723,26371.76422,0.93284847,24.16027039
6.6,0.529827588,0.024882658,25142.69189,0.99994734,24.79879121
6.8,0.331624067,0.025652831,24220.48116,1.063124825,25.54191569
7,0.638696844,0.026384834,23717.38328,1.104952711,26.10525257
7.2,0.711414496,0.02713454,23320.76468,1.148959113,26.79825461
7.4,1.013501002,0.027866919,22973.15019,1.187301344,27.36268109
7.6,0.885936432,0.028631754,22579.72035,1.232179145,27.9913949
7.8,0.843138613,0.029390186,22166.5757,1.27052135,28.44141019
8,0.774578351,0.030150564,21912.41803,1.303199363,28.98622295
8.2,0.899651938,0.030896315,21645.26754,1.330648909,29.41989426
8.4,1.295646712,0.0316216,21415.10116,1.356355654,29.83940063
8.6,1.046749339,0.032395601,21119.22733,1.391647892,30.33300083
8.8,0.824445461,0.033167593,20867.00851,1.422583061,30.6642466
9,1.109079991,0.03390129,20231.91737,1.481403523,30.99004515
9.2,1.56657222,0.034621929,19568.51607,1.545452489,31.22213613
9.4,2.221022517,0.035327688,19141.4094,1.593380322,31.42153869
9.6,2.053567698,0.036095534,19113.77374,1.611244289,31.64818063
9.8,1.988331617,0.03685566,19869.43365,1.580309089,32.07858263
10,1.937223329,0.037614718,21186.64504,1.51538875,32.5798105
10.2,2.290003707,0.038343265,23840.16082,1.394262253,33.3970304
10.4,1.979608866,0.039121909,26732.07835,1.284464074,34.1913671
10.6,2.167010963,0.039862949,30596.87648,1.166387507,35.23195997
10.8,2.233911297,0.040613092,32916.73679,1.111052729,35.98489163
11,1.719078989,0.041407181,34576.81652,1.084474568,36.80537883
11.2,2.331145914,0.042116141,34904.93092,1.091881631,37.37743347
11.4,1.909390824,0.042903198,34624.16049,1.117152603,37.93859003
11.6,2.307047721,0.043628355,33927.3339,1.160287622,38.61306897
11.8,2.377272242,0.044378247,33395.52358,1.196451305,39.20255681
12,2.020338788,0.045160407,33023.57046,1.226515055,39.78223699
12.2,1.928509215,0.045922541,32798.10315,1.246993274,40.24641736
12.4,2.130039104,0.046662514,32488.20111,1.270957174,40.72912203
12.6,2.044026856,0.047424208,32277.71877,1.295792463,41.35565675
12.8,2.105109864,0.048174791,32165.27884,1.316270695,41.94187544
13,2.314950222,0.048914136,32096.98998,1.331084751,42.38644332
13.2,2.264672979,0.049673131,32117.44754,1.347641611,42.93997303
13.4,2.619946506,0.050401489,32430.04268,1.351127299,43.45754605
13.6,2.686846843,0.051151631,32753.17969,1.354177254,43.97729772
13.8,2.492798525,0.051921486,33135.22488,1.358098599,44.60492172
14,2.78740565,0.052654427,33396.32569,1.36332711,45.09743326
14.2,2.528535692,0.053429178,33617.23658,1.372041226,45.68365145
14.4,2.567180441,0.054181455,33718.67717,1.382498197,46.15872838
14.6,2.531862038,0.054939319,33747.98319,1.398619352,46.74494709
14.8,2.970240241,0.055661399,33683.18377,1.413433431,47.16772271
15,2.741287959,0.05643389,33563.02648,1.433040223,47.69292186
15.2,2.908744946,0.057176435,33407.10232,1.450904225,48.09063556
15.4,2.988110985,0.057925635,33109.84912,1.473996703,48.47854267
15.6,2.859715351,0.05869053,32744.63027,1.502317644,48.94381251
15.8,2.96151965,0.059438035,32418.06094,1.525410124,49.26198347
16,3.201277703,0.060175118,31802.25371,1.56288095,49.61175406
16.2,3.080361488,0.060939447,31308.80753,1.592944719,49.86236767
16.4,3.21208347,0.061684692,30782.37545,1.62518705,50.09663755
16.6,3.538270386,0.062415245,30560.11774,1.646972436,50.42352618
16.8,3.648385158,0.063162121,30854.10632,1.642179672,50.73406996
17,3.957950548,0.063897707,31749.42338,1.612551631,51.15684544
17.2,3.713208964,0.064667612,33688.43376,1.54632414,51.84221956
17.4,3.825816877,0.065414299,36057.48145,1.471382548,52.55265588
17.6,3.722352639,0.066177308,38608.95855,1.400798004,53.32302112
17.8,3.681216906,0.06693561,41137.68303,1.341541848,54.1892735
18,3.970006729,0.067668988,42745.59762,1.312785213,54.98905973
18.2,3.750195946,0.068440786,43714.16363,1.302763932,55.74090103
18.4,3.689946138,0.069200532,43820.21498,1.314092309,56.36089794
18.6,3.231624952,0.069990349,43508.41798,1.335006204,56.88282751
18.8,3.712386561,0.070709225,43010.27811,1.362891496,57.47449571
19,3.357115166,0.071491258,42594.11195,1.389033882,58.058534
19.2,3.498809712,0.072235748,41935.93154,1.419097679,58.44535171
19.4,3.737321204,0.072972924,41167.34287,1.454389969,58.84088658
19.6,3.731089434,0.073728589,40684.64851,1.484453752,59.37916173
19.8,4.025281062,0.074461558,40287.45931,1.510596202,59.8564187
20,4.268363319,0.0751984,39803.8315,1.537174355,60.19856193
20.2,3.99993562,0.07597812,39594.80747,1.556781143,60.65729373
20.4,3.979574175,0.076746682,39773.93123,1.560266797,61.08333751
20.6,4.037329885,0.077517141,40319.81581,1.553295492,61.66519778
20.8,4.015303884,0.078301319,41182.66254,1.534124381,62.20129371
21,4.40422926,0.079062304,42666.57938,1.498396446,62.9291651
21.2,4.196877333,0.079876178,43983.57954,1.467896938,63.54480323
21.4,4.151578263,0.080685766,45580.20151,1.436961732,64.41323476
21.6,3.966662017,0.081514203,46480.51952,1.424326215,65.04085859
21.8,4.213057768,0.08231806,47099.88209,1.4221477,65.74693701
22,4.118723029,0.08315595,47504.5465,1.425197646,66.43013223
22.2,4.302787619,0.083981216,47558.70861,1.434347511,66.94770531
22.4,4.368011212,0.084823708,47427.20797,1.451340089,67.63525948
22.6,4.129070309,0.085697844,47290.24888,1.46441128,68.1484725
22.8,4.466874514,0.086536908,47039.7044,1.482711007,68.74994713
23,4.822129362,0.087383135,46816.34834,1.501446447,69.32418119
23.2,4.633878221,0.088279135,46877.08965,1.510596275,69.78945084
23.4,4.468063935,0.089182315,47287.19614,1.511467672,70.33208399
23.6,4.731068357,0.090062132,47866.09394,1.511031995,71.02508699
23.8,4.616776096,0.090979507,48480.23902,1.508853446,71.71264056
24,4.427688206,0.091911466,49040.80892,1.504060646,72.27924539
24.2,4.751354699,0.092814024,49642.21085,1.499703607,72.95808349
24.4,4.478328104,0.09377106,50182.29499,1.494910808,73.55083904
24.6,4.614175052,0.094706497,50798.86711,1.490989459,74.33210132
24.8,4.689354071,0.095656043,51238.45882,1.488375219,74.91178259
25,4.531838471,0.096632709,51550.73939,1.492732279,75.60914262
25.2,4.483188434,0.097611013,51494.07273,1.507110603,76.24221511
25.4,4.71792381,0.098577615,51053.71331,1.528895977,76.68678308
25.6,4.754037459,0.09956893,50502.91133,1.557216938,77.25774721
25.8,4.819236153,0.100568079,50117.06534,1.577259469,77.65546122
26,5.147044055,0.101557358,49870.20038,1.594687786,78.14252512
26.2,4.993674246,0.102593088,49930.76176,1.602966204,78.659007
26.4,5.362200227,0.103599554,50388.26282,1.599480588,79.17767044
26.6,5.450661779,0.104637558,51508.5628,1.580309487,79.92297477
26.8,5.354629273,0.105699944,52499.60771,1.563316902,80.53752366
27,5.526192175,0.106752646,54058.33314,1.534995962,81.38089468
27.2,5.563123796,0.107826173,55775.64473,1.504932179,82.27765725
27.4,5.344091265,0.10892988,56997.05391,1.485761047,82.99680952
27.6,5.50983169,0.110015415,58125.90455,1.473561266,83.92952984
27.8,5.402155936,0.11113273,58938.88452,1.464847115,84.61163534
28,5.695874061,0.112230716,59609.18673,1.462668609,85.45936566
28.2,5.544149273,0.113373692,60145.85085,1.463104301,86.29401837
28.4,5.496303544,0.114520125,60443.74075,1.46702566,86.9902891
28.6,5.384465391,0.11568283,60809.49884,1.469639892,87.72469674
28.8,5.642441228,0.116829274,60912.27956,1.480096887,88.52448325
29,5.76744773,0.117997344,60980.14109,1.490989577,89.28504262
29.2,5.947301465,0.11917298,60798.62163,1.507546464,89.99112106
29.4,6.824401666,0.120307808,60503.47752,1.524539131,90.55882009
29.6,7.386533336,0.121477665,59848.4814,1.550245909,91.08947045
29.8,7.14753383,0.122720158,59277.59255,1.575081189,91.6909428
30,7.36810134,0.123940171,58962.14041,1.593816619,92.30549323
30.2,7.383398304,0.125187969,59065.2008,1.599045106,92.80345233
30.4,7.240794352,0.126460241,59976.01259,1.587280999,93.58144488
30.6,7.407337834,0.127721941,62310.09963,1.545017428,94.62312803
30.8,7.55060999,0.128998059,64377.78303,1.509725166,95.50027784
31,7.407999931,0.130308747,66937.81675,1.469640097,96.64874281
31.2,7.224666483,0.131635655,68970.54212,1.443061946,97.75253347
31.4,7.515027678,0.132940116,69403.10184,1.447419046,98.65474504
31.6,7.832811387,0.134255349,68688.94498,1.471818676,99.30852211
31.8,8.003497654,0.135595098,67435.25786,1.5088538,100.0080633
32,7.60823875,0.136991306,66238.28766,1.545017451,100.6454926
32.2,7.416584181,0.138385835,65519.84913,1.568981322,101.1358232
32.4,8.09669569,0.139728323,65290.76381,1.582924023,101.7144182
32.6,8.175958049,0.141129974,66488.02967,1.569417111,102.6743793
32.8,8.403975582,0.14253448,67777.92678,1.554603093,103.6158171
33,8.117572741,0.143992183,68703.36477,1.546324627,104.3741954
33.2,8.37301027,0.145423274,70073.82333,1.531946319,105.3548604
33.4,8.42317688,0.1468844,71434.62054,1.516696574,106.2450853
33.6,8.458382317,0.148361299,72301.25798,1.511468092,107.1353099
33.8,8.196070553,0.149875592,73675.71873,1.498396851,108.2085903
34,8.581973083,0.15135585,75202.39313,1.482711434,109.354879
34.2,8.387802386,0.152895102,76133.4537,1.4757401,110.2461922
34.4,8.599180205,0.154418992,76772.70314,1.474868707,111.1767342
34.6,8.473980272,0.155991648,77316.59753,1.479225766,112.3110342
34.8,8.780092511,0.157539485,77196.61318,1.491861305,113.1162695
35,8.898386887,0.159109286,77064.30451,1.507546775,114.0653348
35.2,8.88287892,0.160712909,76767.02605,1.523232232,114.772502
35.4,8.849085354,0.162334051,76368.78805,1.541096222,115.500372
35.6,8.994795371,0.163957848,76185.39996,1.557217403,116.4472578
35.8,8.970969194,0.165610791,76396.84622,1.562881593,117.1816661
36,9.081769997,0.167270189,76871.7695,1.565931556,118.1448963
36.2,9.080376785,0.168954813,77801.07787,1.558524534,118.995894
36.4,8.682571443,0.170686311,78891.08607,1.549374642,119.8981024
36.6,9.009020872,0.172380242,80031.04631,1.542839069,121.0629146
36.8,8.813570038,0.174130716,80780.85307,1.539789099,121.9258973
37,8.934329828,0.175874766,81146.47761,1.545889012,122.9305335
37.2,9.362989777,0.177613042,80936.34522,1.558960273,123.6693024
37.4,9.296342859,0.179406464,80614.17909,1.574210017,124.4102479
37.6,9.23634145,0.181217428,80183.06785,1.593816834,125.265604
37.8,9.13727796,0.183049398,79569.85691,1.616037889,126.0228937
38,9.136690625,0.184892304,79305.50399,1.629544811,126.6483393
38.2,9.483893564,0.186727332,79083.75376,1.644358894,127.3892874
38.4,9.320830636,0.188619569,79085.12733,1.653508727,128.0779298
38.6,9.28865461,0.190520875,79424.50568,1.654815845,128.7567667
38.8,9.209936909,0.192444811,80257.37562,1.648715937,129.6578871
39,9.505187328,0.194359754,80988.63311,1.643051777,130.3901178
39.2,9.477157367,0.196318434,82181.99223,1.63128768,131.394753
39.4,9.676000144,0.198279569,82794.67678,1.628673459,132.177106
39.6,9.845753152,0.200262551,83200.62563,1.630416307,132.961638
39.8,9.867576606,0.202276665,83310.01574,1.63869475,133.8028298
40,10.05311311,0.204298733,83326.37953,1.646101798,134.4522478
40.2,10.1538796,0.206347404,83006.38737,1.661351563,135.1877469
40.4,10.38511722,0.208406753,82798.77749,1.672679968,135.8088354
40.6,10.52826055,0.210493554,82760.67135,1.680958426,136.4506262
40.8,10.54341926,0.212611113,82970.88286,1.686186913,137.2340676
41,10.51120491,0.214753528,83054.95926,1.691415397,137.8028523
41.2,10.54297777,0.216912558,83414.98092,1.693158237,138.5557843
41.4,10.38194423,0.219107968,83959.54418,1.69141538,139.2509648
41.6,10.45692461,0.221307369,84611.13163,1.689672564,140.1106804
41.8,10.77539829,0.223510513,85110.13297,1.687929776,140.7699065
42,11.0140879,0.225741979,85734.13506,1.686186972,141.601293
42.2,11.1671761,0.228002295,86083.27275,1.687494108,142.2387254
42.4,11.24297331,0.230291073,86551.49529,1.686622709,142.9502519
42.6,11.44591709,0.232593269,87009.67504,1.687494138,143.8143258
42.8,11.46353364,0.23493274,87165.51591,1.691851213,144.4517573
43,11.41216955,0.237300864,87213.34191,1.699258237,145.1948833
43.2,11.54695626,0.239678633,87432.66173,1.703179611,145.9532642
43.4,11.68007709,0.242080393,87555.3307,1.708408114,146.6222954
43.6,12.14976822,0.244480778,87603.2182,1.714072363,147.2096068
43.8,11.86735773,0.246962395,87888.59388,1.716686574,147.9559991
44,12.04534348,0.249433935,88611.55717,1.710150986,148.6337478
44.2,12.06875048,0.251942109,89423.87663,1.704486795,149.5000011
44.4,12.20351379,0.254467112,89916.94656,1.703179689,150.1886461
44.6,12.05654805,0.257038818,90531.33987,1.700565429,150.9252324
44.8,12.29601521,0.259606908,91440.05783,1.694465555,151.8416098
45,12.24461172,0.262222915,91671.79799,1.697515501,152.4833994
45.2,12.28046401,0.264858595,92020.62063,1.700129749,153.2919024
45.4,12.27725285,0.267523821,92493.2499,1.699258334,153.9979802
45.6,12.56739714,0.270193493,92913.72655,1.699258368,154.7356597
45.8,12.71293493,0.272901054,93296.57534,1.701436922,155.5823001
46,12.63907188,0.275652599,93919.38628,1.698386963,156.3069011
46.2,12.81036343,0.278412961,94903.05284,1.690979959,157.2428915
46.4,12.78967863,0.281215699,95712.4507,1.685315762,158.0601115
46.6,12.8379663,0.284041252,96410.2292,1.68183011,158.8871381
46.8,13.22365467,0.286869619,96809.64536,1.684008691,159.7664694
47,13.19963217,0.289757598,96631.09844,1.693594249,160.4104384
47.2,13.72575841,0.292632861,95990.71948,1.712329724,161.08819
47.4,13.50476847,0.295593721,95365.186,1.729322284,161.6003128
47.6,13.73337043,0.298550273,95068.38616,1.741086408,162.1756376
47.8,14.22707182,0.30151612,95419.26967,1.742393589,162.8926161
48,14.39915313,0.304536322,96277.4359,1.735858,163.7316295
48.2,14.55128447,0.307588398,97426.0806,1.723222505,164.4965486
48.4,14.37182303,0.310696216,99013.3284,1.704922777,165.4140125
48.6,14.63281176,0.313801859,100920.9909,1.685315977,166.6235003
48.8,14.31372442,0.316982793,102110.8224,1.675294673,167.5169913
49,14.55226482,0.320153344,103522.7145,1.664402017,168.6502044
49.2,14.6461979,0.323366731,104124.8103,1.663094906,169.4499913
49.4,14.92711152,0.326598262,104390.2972,1.667016304,170.261765
49.6,14.81908978,0.329891771,104364.6437,1.677037561,171.2456969
49.8,14.88973799,0.333204703,104245.6284,1.685751716,171.9408796
50,14.86314836,0.33655834,103796.9327,1.700565763,172.7580992
50.2,15.12991318,0.339923053,103594.0193,1.710151356,173.4042498
50.4,15.37672747,0.343323211,103730.1012,1.715379874,174.0983439
50.6,15.59444968,0.346759658,104389.3834,1.714944192,175.0702925
50.8,15.54456911,0.350250971,105077.7151,1.711458528,175.8352102
51,15.74233513,0.353758485,106060.5416,1.706230063,176.842027
51.2,15.97749269,0.357298426,106531.6599,1.70623009,177.5862437
51.4,16.04227984,0.360886964,106848.4366,1.708408635,178.3696859
51.6,16.13864107,0.364509101,106568.7278,1.720172746,179.2337607
51.8,16.24247595,0.368167071,106296.7583,1.729758321,179.861386
52,16.25821395,0.371868454,106380.7676,1.734551105,180.6764273
52.2,16.35289555,0.375601095,106918.2949,1.731501164,181.4217325
52.4,16.39937044,0.379374808,107602.513,1.726708389,182.2160708
52.6,16.65526021,0.383189874,108809.8531,1.717122857,183.3122378
52.8,16.53468547,0.387033356,109638.2096,1.711894354,184.1250973
53,17.06813594,0.390885188,110104.0629,1.714072954,185.0807049
53.2,17.37054905,0.394793234,109877.6322,1.724529967,185.7257667
53.4,17.79761306,0.398731095,109950.6954,1.731501337,186.4264005
53.6,17.71773174,0.402747011,109809.3259,1.742829721,187.2675917
53.8,18.074144,0.406770221,109633.9741,1.751543912,187.8505454
54,17.91280713,0.410873389,109858.7131,1.755900968,188.6328956
54.2,18.60079442,0.414953096,110774.0401,1.748494024,189.3891031
54.4,18.54415649,0.419130523,111403.0462,1.745444065,190.1670959
54.6,18.60053437,0.423341231,112161.6517,1.74239412,191.1292369
54.8,18.75663124,0.427586804,112751.8393,1.740215601,191.8843497
55,18.99333296,0.431868809,113633.8519,1.735422848,192.8497612
55.2,19.31188602,0.436187802,114143.215,1.734551471,193.6103232
55.4,19.41519087,0.440566287,114825.5635,1.731501531,194.4231865
55.6,19.70090367,0.444975127,116165.2895,1.721044585,195.5771039
55.8,19.93674658,0.449432009,117921.9561,1.704487728,196.7669779
56,19.77949684,0.453963176,119369.1198,1.691852193,197.7901363
56.2,19.79509781,0.458526681,120934.0834,1.680088093,199.0148766
56.4,19.93202446,0.46312681,122107.3767,1.672681082,200.0903401
56.6,20.23182914,0.467760703,122701.5008,1.673552531,201.1309363
56.8,20.75019198,0.472424617,122803.0488,1.681831033,202.2227474
57,20.65606517,0.477181868,122669.3468,1.690109466,202.99965
57.2,20.47550182,0.481993303,122124.3057,1.704923501,203.9345485
57.4,20.87749526,0.486808931,122228.3465,1.710587751,204.7550423
57.6,20.87725389,0.491703516,122645.4885,1.712766288,205.6528948
57.8,20.78060315,0.496654644,123732.1586,1.708409206,206.8100766
58,21.02218097,0.50162969,124943.4067,1.701002203,207.776579
58.2,21.13410738,0.506664654,127058.5165,1.685316749,209.1473307
58.4,21.4695776,0.511733276,128158.4203,1.680088295,210.2075405
58.6,21.49921414,0.516876061,128925.3495,1.678781175,211.2546717
58.8,21.3900575,0.52208084,129007.6285,1.687059608,212.3889732
59,21.49613393,0.527321693,128023.8953,1.705359338,213.0754392
59.2,21.85151632,0.53259632,126293.4633,1.734116075,213.7662664
59.4,22.01159406,0.537938756,125170.9815,1.754158643,214.3252466
59.6,21.96473234,0.543350617,124163.0711,1.774201185,215.041131
59.8,22.44640843,0.548776655,124009.4698,1.781172566,215.6175487
60,22.19675374,0.554312711,125164.5326,1.773329794,216.5873141
60.2,22.69004701,0.55984795,126490.9433,1.762437173,217.4786341
60.4,22.75783491,0.56547125,127866.8392,1.75154449,218.4233414
60.6,22.89708395,0.571145588,129685.1044,1.737601857,219.6960262
60.8,22.92247038,0.576885508,130848.276,1.729759124,220.667974
61,23.28192889,0.582657801,131786.7909,1.725837799,221.8044594
61.2,23.35383561,0.588509921,132491.6309,1.723223562,222.7088495
61.4,23.58861838,0.594408482,133080.9309,1.722352175,223.6481105
61.6,23.71951073,0.600374185,133838.7987,1.721480775,224.865225
61.8,23.81632062,0.606402283,134096.4162,1.726273571,225.9188957
62,24.60953905,0.612438326,133771.5552,1.73629494,226.6729263
62.2,24.63485952,0.618593178,133122.7098,1.75154471,227.5206566
62.4,24.91031562,0.624790881,132890.5584,1.758951774,228.0502178
62.6,26.10240785,0.630981198,132584.9742,1.770280316,228.9306505
62.8,26.16675797,0.637319457,132935.8905,1.772458863,229.8208763
63,26.32251326,0.643714371,133985.3314,1.765487559,230.7002066
63.2,26.84308846,0.650145949,135569.9805,1.753723514,231.8628448
63.4,26.85422089,0.656680801,136586.2746,1.747623608,232.8402408
63.6,26.79304169,0.663286835,137816.4806,1.739780862,233.9091643
63.8,26.79418059,0.669954274,138677.8738,1.737602324,235.0162253
64,27.61389123,0.676626775,139584.8868,1.733681052,235.9587622
64.2,28.00726355,0.683398563,140431.9886,1.731938268,237.1083234
64.4,28.11723762,0.690259939,141516.8693,1.726709788,238.1685322
64.6,28.12165761,0.697198292,142672.0529,1.721045588,239.3050137
64.8,28.28812093,0.704193989,143794.9732,1.716688531,240.5798793
65,28.62660006,0.711246892,144240.6997,1.717995694,241.531128
65.2,28.38915151,0.718414413,144875.1727,1.718867082,242.7569553
65.4,28.91874901,0.725595801,145188.3488,1.721917099,243.7245511
65.6,28.77851017,0.73290014,145230.3987,1.728016992,244.677973
65.8,29.35046804,0.740223718,145733.9632,1.730195598,245.8667635
66,29.4611824,0.747656056,146082.5874,1.732374151,246.7766033
66.2,29.78712642,0.75514659,146567.5873,1.734988436,247.884758
66.4,30.08978913,0.762714196,147112.7838,1.735859888,248.851261
66.6,30.32013855,0.770363361,147846.4263,1.736731331,250.1086938
66.8,30.85547053,0.778066054,148136.0207,1.73978135,250.9716853
67,30.8963164,0.785883916,148753.3512,1.741088478,252.1441251
67.2,31.180647,0.793761621,149439.1341,1.739781389,253.1193451
67.4,31.21565048,0.801737514,149987.7958,1.740217101,254.1228925
67.6,31.50078681,0.809774444,151229.9327,1.734988641,255.5187087
67.8,31.7842482,0.817892339,151983.8471,1.732810136,256.525528
68,32.2048196,0.826081568,153158.0034,1.728017399,257.869044
68.2,31.98380854,0.834401713,153746.9812,1.728017374,258.892201
68.4,32.14008019,0.8427767,154446.259,1.727145977,259.960038
68.6,32.19993688,0.851243009,154598.8193,1.733681603,261.2087519
68.8,32.42266552,0.859782133,154691.309,1.738910124,262.1382066
69,32.67446722,0.868404868,154586.3413,1.747624312,263.2049545
69.2,33.0932959,0.877101563,154755.037,1.751981441,264.0973653
69.4,33.30268648,0.885901511,154557.4975,1.760259916,264.9527264
69.6,33.96249131,0.894755715,155053.666,1.761567119,265.919234
69.8,34.44776183,0.903712065,155964.8769,1.759824346,267.1178301
70,34.73439019,0.912819229,157187.3548,1.75372447,268.1715042
70.2,34.75092775,0.921946916,158587.9766,1.747624561,269.4943123
70.4,34.9386394,0.931199515,160346.3104,1.737167593,270.7332218
70.6,35.09060119,0.940547815,162095.5195,1.727582036,272.0494934
70.8,35.06802781,0.950003416,163923.9972,1.718432167,273.558627
71,35.21331119,0.959541086,164940.3399,1.715382229,274.741965
71.2,35.6319943,0.969154025,166547.4901,1.708410951,276.2914206
71.4,36.31867522,0.978843489,167566.0873,1.705361075,277.5455914
71.6,36.24659322,0.988688017,168462.796,1.703618235,278.8542334
71.8,36.74833462,0.998587903,169144.1751,1.704925418,280.313252
72,37.38801431,1.008576774,170216.953,1.701439828,281.5554362
72.2,39.37647024,1.018563997,171278.5028,1.699697226,283.0918378
72.4,39.63632881,1.028782386,172134.0481,1.69882584,284.4037535
72.6,39.49768314,1.039133661,173147.2555,1.697082992,285.7745033
72.8,39.79947684,1.049555486,174423.8718,1.694468779,287.4187564
73,39.89598482,1.060097683,175212.5569,1.694468791,288.6707398
73.2,40.23057149,1.070727591,176362.3999,1.693597413,290.2910217
73.4,40.49325547,1.081469652,176870.9177,1.696647401,291.5582624
73.6,40.67157088,1.09232577,177095.8184,1.702311628,292.826592
73.8,40.72521162,1.10330045,177405,1.708411548,294.3106656
74,40.71899936,1.114389574,177189.0553,1.716690002,295.3686945
74.2,41.01111597,1.125567399,176319.5664,1.732375529,296.5738271
74.4,41.07052103,1.136875124,176338.8657,1.738911159,297.6285878
74.6,41.41163363,1.148275153,176395.0072,1.745446822,298.7149518
74.8,41.18345949,1.159832827,176104.5752,1.755903791,299.8971947
75,41.35500146,1.17147623,176541.1048,1.758082352,300.8996553
75.2,41.73678024,1.183220543,177861.3355,1.753725317,302.3009225
75.4,42.00634866,1.195091387,178434.0919,1.75459677,303.4352297
75.6,42.48199827,1.207065923,178802.2983,1.757211078,304.5455671
75.8,42.86953759,1.219167394,179809.4477,1.755032584,305.9599105
76,43.281158,1.231388643,180071.6641,1.757646881,307.0103181
76.2,43.89802802,1.243717232,180449.7422,1.760261209,308.2546825
76.4,44.20489705,1.256193227,180798.9495,1.762439783,309.3170745
76.6,45.0203482,1.268756168,182381.7009,1.755468557,310.8905097
76.8,49.60874346,1.281157748,183568.1282,1.750676302,312.0826321
77,49.5773157,1.294035541,186066.0969,1.73673363,313.7824519
77.2,49.80598585,1.307022976,188252.7802,1.724533822,315.2164063
77.4,49.73795061,1.320163394,191034.025,1.708412609,316.8628338
77.6,50.19844182,1.333395798,193985.81,1.69403428,318.9701822
77.8,49.94670252,1.346815172,196493.4516,1.681398712,320.6383994
78,50.33817408,1.360320492,198264.9077,1.677477383,322.5975574
78.2,50.18030037,1.374003244,199400.4493,1.676605946,324.0816288
78.4,50.51771032,1.387785748,200491.1034,1.677041694,325.6681331
78.6,50.37724477,1.401743155,201520.0963,1.680091634,327.5935034
78.8,50.72790719,1.415803495,201004.8181,1.691855802,328.870554
79,50.90236468,1.430018384,200917.5908,1.701441408,330.4995503
79.2,50.78759424,1.444398042,200637.4259,1.710155563,331.7449946
79.4,51.21132091,1.458881309,199733.0045,1.723226866,332.8869316
79.6,51.71397417,1.473504147,198973.6212,1.736733888,334.343773
79.8,51.80855876,1.488304831,199266.1541,1.740655275,335.5543518
80,52.17237977,1.503233818,199863.3298,1.744140987,337.0743888
80.2,52.05250607,1.518349593,200256.9638,1.747626641,338.258814
80.4,52.5583886,1.533569568,201193.253,1.747190993,339.5489427
80.6,52.74761691,1.54896665,203186.568,1.74021968,341.3468326
80.8,53.0805922,1.564507598,205344.1644,1.73150555,343.1534425
81,53.38279387,1.580206852,206541.3326,1.728455627,344.5427238
81.2,53.87361873,1.596049649,208605.6541,1.720612932,346.4049069
81.4,54.16164219,1.612066947,209585.4023,1.719305841,347.8857169
81.6,54.22525665,1.628262219,209900.9964,1.723227225,349.2826228
81.8,55.06587674,1.644561215,209737.8307,1.731941495,350.817923
82,55.08871787,1.66108609,210382.8097,1.734120042,352.3717336
82.2,55.5370301,1.677744579,210428.844,1.739348598,353.5420028
82.4,55.88143449,1.694578456,211062.8112,1.741091473,354.878983
82.6,56.69119995,1.711545962,211348.3715,1.746755781,356.5504879
82.8,57.35550459,1.728695123,211806.1007,1.748934404,357.7926762
83,57.65411993,1.746044282,211878.178,1.755470069,359.2484257
83.2,58.33249739,1.76353889,212472.3225,1.756777277,360.5036902
83.4,58.55460051,1.781243934,213344.0541,1.755905887,361.8406682
83.6,58.97529628,1.799111897,215809.8846,1.745884638,363.8118145
83.8,58.97046597,1.817191446,218336.9491,1.73542763,365.7459063
84,59.62629152,1.835402522,220521.1219,1.726277826,367.3520302
84.2,60.14912,1.853806766,222858.5666,1.717999422,369.3613155
84.4,60.84145334,1.872382893,224149.2723,1.71582096,371.0164741
84.6,61.18887125,1.891171872,224813.2075,1.717563836,372.5746497
84.8,61.44899891,1.910156233,225694.9656,1.718435284,374.4074107
85,62.119635,1.929300225,225698.196,1.724535286,376.0963477
85.2,62.27415841,1.948675674,225424.5432,1.731506645,377.3897401
85.4,63.00789285,1.968201837,224965.9469,1.740220908,378.6373797
85.6,63.63688379,1.987932299,224764.5417,1.749370868,380.2979852
85.8,63.77801675,2.007897937,224710.5477,1.755906517,381.451906
86,64.49004937,2.028020826,226001.1181,1.755470894,383.1702638
86.2,65.40067092,2.048330794,227629.2061,1.751113915,384.6543554
86.4,65.52259329,2.068904689,229735.9936,1.743706879,386.2877114
86.6,66.40240075,2.089627686,232111.5236,1.736735642,388.3874437
86.8,66.9746865,2.110582356,234348.0156,1.730200076,390.4130754
87,67.41646388,2.131757465,235421.9842,1.72976442,391.9233105
87.2,67.71609785,2.153155933,237013.1961,1.72802162,393.9031742
87.4,68.10378898,2.174762845,238209.9683,1.725843121,395.2140038
87.6,68.63189316,2.19657617,241004.6944,1.717129005,397.5534488
87.8,69.30872053,2.218597617,243354.2943,1.71059345,399.7065696
88,69.67551293,2.240976789,245285.5816,1.705364985,401.5447811
88.2,70.45035128,2.263324504,246373.3618,1.706236494,403.580224
88.4,70.7747065,2.286044311,247169.2211,1.707543659,405.3094727
88.6,71.96581133,2.308926462,247312.5014,1.712772306,407.013677
88.8,72.65409393,2.332077103,247324.3962,1.719743732,408.9652173
89,72.88401497,2.355495899,248011.0656,1.721050887,410.5604393
89.2,73.38149696,2.379129666,250023.8123,1.716258146,412.7898315
89.4,73.7002653,2.403014499,251306.3874,1.714951056,414.5790103
89.6,74.20972164,2.427124963,253152.2882,1.711465443,416.5261889
89.8,74.68963719,2.451479906,255033.8122,1.709286954,418.8133308
90,75.15497047,2.476080646,255177.812,1.715386937,420.376959
90.2,75.61320054,2.500929079,254315.3431,1.728893975,422.1171072
90.4,76.39965608,2.526002194,253524.0736,1.740222507,423.5456279
90.6,76.79381554,2.55135706,252032.6381,1.756343795,425.1506609
90.8,77.59681163,2.576935598,251495.4837,1.764622367,426.4331727
91,77.96720501,2.602802772,252631.2915,1.763750994,428.2604901
91.2,78.59767609,2.62891012,254514.7229,1.757215431,429.9363536
91.4,79.16411459,2.655284421,257406.8828,1.745451349,431.851935
91.6,79.87178973,2.681912702,262628.4821,1.72323026,434.7035111
91.8,80.51543146,2.708813285,265938.1341,1.710594766,436.8043312
92,81.10334983,2.735988298,268199.4611,1.705366323,439.1786471
92.2,81.48346207,2.763451689,269317.0073,1.705802077,441.0517304
92.4,82.19844415,2.791165531,269265.452,1.71277351,442.7798996
92.6,83.06795753,2.819146206,268087.3632,1.728023441,444.7630441
92.8,83.96817523,2.847405297,268282.7241,1.733687774,446.3201444
93,84.72208279,2.875959523,269234.4035,1.736737827,448.4046239
93.2,85.27981663,2.904815553,270217.5147,1.737173603,450.0183796
93.4,85.89734013,2.933956936,271834.2961,1.736737965,452.3861586
93.6,86.29957477,2.9634074,273154.9145,1.73543089,454.1393834
93.8,86.72087655,2.993152418,273172.8807,1.742402291,456.0822036
94,87.61416815,3.023160429,273753.7021,1.744580948,457.691608
94.2,88.29715581,3.053485935,274312.3605,1.748066702,459.6693024
94.4,89.10807704,3.084106336,275003.0005,1.74937393,461.3636959
94.6,89.58237347,3.115059885,275906.6817,1.749809695,463.2062718
94.8,90.4438906,3.146295026,277973.4579,1.745016998,465.4531093
95,91.53805243,3.177826232,278624.8651,1.747195668,467.0832214
95.2,91.8044363,3.209737189,279256.2023,1.751552797,469.105582
95.4,92.79793959,3.24191368,280494.6705,1.751552916,470.8936886
95.6,93.37420348,3.274445141,282464.8795,1.747195893,472.7624184
95.8,94.47480924,3.307263653,284887.996,1.741967508,475.089895
96,94.62547022,3.340483833,287451.4921,1.73543188,477.4500388
96.2,95.78746849,3.373960983,290603.5241,1.724974979,479.6282377
96.4,96.40008791,3.407816338,293379.6946,1.717132276,481.9164745
96.6,97.30019734,3.441989948,294590.522,1.71931093,484.420469
96.8,97.51297213,3.476558897,295577.0186,1.720618086,486.3207901
97,98.70633328,3.511400924,298033.0906,1.717132547,488.8661954
97.2,99.49408535,3.546623882,301376.4495,1.707982732,491.1860392
97.4,100.166265,3.582209404,305650.4404,1.695347224,493.795723
97.6,100.6480768,3.618166897,314392.5817,1.664847586,497.6977022
97.8,101.3001969,3.654472627,321877.498,1.639576485,501.0014811
98,102.7085168,3.691085862,332651.5732,1.603412714,505.4090714
98.2,103.2034517,3.728136114,340040.8348,1.583370109,509.5692972
98.4,104.0972327,3.765528319,343455.135,1.578577396,512.869811
98.6,104.9153282,3.8033019,342685.6281,1.590341655,515.6560192
98.8,106.0308802,3.841432691,339010.9581,1.615612961,518.6394555
99,106.681813,3.879981712,331367.9323,1.655262652,520.1507926
99.2,107.5911416,3.918898423,324919.1702,1.691862405,522.0086385
99.4,107.9419407,3.958248571,322751.2685,1.708419432,523.8730053
99.6,108.8079297,3.997954968,323690.6684,1.711905214,526.6058239
99.8,109.7070974,4.038057826,324717.8588,1.71277674,528.7066561
100,110.7890328,4.078549758,329173.6133,1.70014127,531.9407109
100.2,111.2393033,4.119496347,331027.4413,1.697527062,534.3357326
100.4,112.2396655,4.160812611,328726.7247,1.713212748,536.2742132
100.6,113.2366376,4.20254431,324039.1431,1.742841164,538.1309735
100.8,114.5618092,4.24467022,321703.0066,1.759398315,539.4625364
101,115.1771941,4.287273316,319229.3393,1.778133934,541.1002699
101.2,116.1706402,4.330275726,318478.9713,1.788591104,542.8633207
101.4,116.8789665,4.37373174,319592.6725,1.788155481,544.2962057
101.6,117.9412521,4.417597502,322614.8884,1.780312823,546.8045676
101.8,118.9078966,4.461911384,325960.1655,1.771163021,549.3554202
102,119.7065976,4.506683177,328274.5481,1.765934592,551.3679933
102.2,120.9057949,4.551874315,330843.9776,1.761577632,553.9155844
102.4,121.5231827,4.59756367,333593.1558,1.755042049,556.219083
102.6,122.3158498,4.643698786,334648.7747,1.756349276,558.2578074
102.8,123.4416958,4.690272168,334787.1708,1.76288507,560.4033235
103,124.2749366,4.737335721,335235.2917,1.766370856,562.2339281
103.2,125.4563138,4.78484578,335929.9585,1.769856684,564.4687976
103.4,126.6592226,4.832831501,335495.9523,1.777263911,566.1414164
103.6,127.4415416,4.881331276,338238.971,1.771599767,568.8077681
103.8,128.3983045,4.93030498,341030.5786,1.764192801,570.966356
104,129.1704953,4.979784681,344209.8327,1.756785811,573.6305304
104.2,130.3772484,5.029728631,347268.4417,1.748943162,575.9776318
104.4,131.2232443,5.080201855,351743.4893,1.735871938,578.66687
104.6,132.4206955,5.131155415,354767.9241,1.731514972,581.7429372
104.8,133.3163928,5.182643684,356383.2034,1.731079367,583.9952343
105,134.3940089,5.23463551,358426.0103,1.730208073,586.8446544
105.2,135.4125371,5.287154171,359908.5062,1.731515327,589.6210681
105.4,136.337861,5.340474651,360557.8429,1.734565414,591.8559313
105.6,137.3412611,5.394059134,361961.9318,1.734129822,594.3228903
105.8,138.5515081,5.448167785,364573.6415,1.729337144,597.3640904
106,139.3769342,5.50257409,366127.5035,1.728030109,599.7242594
106.2,140.5047336,5.557779173,367294.795,1.729773087,602.5606075
106.4,141.6623626,5.613539166,368216.5473,1.73238749,604.9523887
106.6,143.0372233,5.669843185,369041.587,1.736309054,607.3180222
106.8,144.1830386,5.726730427,368414.6792,1.74720197,609.6716645
107,144.8799935,5.78422331,369630.1324,1.750252033,612.2922535
107.2,146.1660746,5.842249098,372176.4488,1.746330785,614.5630872
107.4,146.9118774,5.900898943,375961.8721,1.73805236,617.1804091
107.6,147.9106428,5.960118946,379878.0082,1.731081098,620.4711331
107.8,149.3107133,6.019903442,384911.8304,1.72018848,623.9514655
108,150.3454396,6.080316529,386240.9191,1.721931447,626.2963881
108.2,151.3696814,6.141337264,385361.8018,1.733260065,628.8472529
108.4,152.5064341,6.202960477,383502.1433,1.746767256,630.7683143
108.6,153.9447617,6.265178998,382576.41,1.758095927,633.2843204
108.8,155.1669158,6.32803902,381379.6354,1.768117439,634.9863697
109,156.1396528,6.391549598,381313.1861,1.774653231,637.3323801
109.2,157.4995604,6.455668753,382446.0896,1.775089107,639.4136241
109.4,158.6574194,6.520446471,385498.8517,1.768117862,641.9416105
109.6,159.5367713,6.58589609,388359.2753,1.762889429,645.0013305
109.8,161.0858497,6.651952423,391558.1313,1.755046804,647.6001578
110,162.5093335,6.718681179,396553.7465,1.741975622,651.0412676
110.2,163.7108191,6.786096351,401528.1963,1.729775835,654.5270474
110.4,164.9362977,6.85418696,404654.7743,1.725418862,657.6652327
110.6,166.2813398,6.922952424,407143.7512,1.722804752,660.2945639
110.8,167.8506573,6.992391971,410135.8147,1.720626379,663.7531144
111,169.0433957,7.062557666,411868.7562,1.721497941,666.4151315
111.2,170.2418394,7.133427889,414035.3593,1.72236951,669.6731784
111.4,171.3171738,7.205019455,417265.9992,1.718012515,672.7089362
111.6,172.6117928,7.27731368,421877.2509,1.708862717,676.0879365
111.8,174.2212668,7.350310343,426298.2652,1.701891505,679.9605522
112,175.3743744,7.424074997,428858.3191,1.69927737,682.8851709
112.2,177.0018977,7.498544694,431450.9537,1.69797042,686.5147996
112.4,178.2594819,7.573790676,430822.7541,1.706684811,689.2062407
112.6,179.8510309,7.649767386,427940.384,1.724984912,692.2136875
112.8,181.240512,7.72652272,426494.9199,1.736313599,694.4006325
113,182.5185089,7.804057706,425327.6443,1.748513696,697.1585431
113.2,183.9310134,7.882361453,423329.0058,1.761585234,699.0305849
113.4,184.9802209,7.961479512,423966.967,1.765506779,701.4005781
113.6,186.3525835,8.041367788,425996.193,1.765506943,704.4537841
113.8,187.8478151,8.122049549,426223.4279,1.769864244,706.6189397
114,189.0370888,8.203565216,426380.4889,1.775528657,709.2602598
114.2,190.8063106,8.285855868,427779.3606,1.775528867,711.5932294
114.4,192.4224866,8.368984857,429200.5661,1.775964775,714.0406093
114.6,193.6720336,8.452976743,431464.2849,1.774657789,717.1275904
114.8,195.1450011,8.537795589,435614.6209,1.766815139,720.4227007
115,196.8081455,8.623452102,438853.762,1.761151074,723.0956387
115.2,198.8251839,8.709942495,442547.4154,1.755487049,726.4016646
115.4,200.2478781,8.79734707,444669.6027,1.754180082,729.2042599
115.6,202.0153218,8.885603691,444654.734,1.759844562,731.6440163
115.8,203.5249968,8.974766458,444603.0352,1.766380438,734.4749483
116,204.8749664,9.064837066,445932.1993,1.766816315,736.8918124
116.2,206.8555656,9.155764835,446970.0624,1.769866545,739.8698588
116.4,208.2035843,9.247654185,448788.5399,1.769430996,742.4360048
116.6,209.7201613,9.340453926,453027.5089,1.761588342,745.5077447
116.8,211.2183069,9.434187504,456515.8965,1.757667104,748.9074657
117,212.9165882,9.528847456,458091.4522,1.759410161,752.066384
117.2,214.4468446,9.624471266,459803.1658,1.758974632,754.647793
117.4,216.1065936,9.721045851,462777.4187,1.754617698,757.5931442
117.6,217.8792126,9.818582358,465370.3535,1.753310771,761.1672179
117.8,219.4663499,9.917112878,468672.5442,1.748518113,764.0973121
118,221.1879616,10.01662306,473318.4784,1.741982616,767.8805977
118.2,222.8047011,10.11714102,476272.9165,1.740675668,771.3903803
118.4,224.4279287,10.2186685,477781.5574,1.74285443,774.3346404
118.6,226.2512797,10.32120065,479774.6329,1.742854647,777.3508278
118.8,228.0545217,10.42476459,482467.7412,1.741112007,780.86171
119,229.6066186,10.52938803,485498.9095,1.738062196,784.6351862
119.2,231.8175789,10.63501254,487448.354,1.73719103,787.5947269
119.4,233.6602114,10.74172646,488438.3495,1.739805532,790.6229013
119.6,235.4503168,10.84951647,488468.6095,1.747212882,794.1795492
119.8,237.0349785,10.95840496,487747.0619,1.755055924,796.5430375
120,239.0649148,11.06835366,487289.6785,1.763770448,799.4655259
120.2,241.3132445,11.17939055,488031.8262,1.767692146,801.999023
120.4,242.814274,11.29159972,490123.2377,1.767692327,804.8593837
120.6,244.8943736,11.40489228,493607.5048,1.765078293,808.5991062
120.8,246.609457,11.51935078,495504.7676,1.7650785,811.3930072
120.964,248.5268081,11.61402557,496417.6729,1.767693017,813.9646272
121.2,249.8918145,11.61682525,498503.3128,1.769000324,817.9625704
121.4,251.2129068,11.61672524,501189.1011,1.766386196,821.1705193
121.6,251.6131838,11.61669479,505550.2342,1.75810767,824.2988901
121.8,252.4065527,11.61663465,513470.2738,1.741986331,828.8830339
122,253.0295541,11.61658738,520974.9388,1.726736398,832.8678688
122.2,253.5345448,11.61654902,528314.9304,1.714100738,837.6317916
122.4,253.9073969,11.61652064,532551.1727,1.708436493,840.8309867
122.6,254.1273337,11.61650382,534167.3981,1.713665093,845.2440344
122.8,254.8118337,11.6164519,533206.322,1.723250892,848.1348754
123,255.4281867,11.61640513,530873.9215,1.738065258,851.5247696
123.2,255.7727827,11.61637888,530828.0625,1.744601017,854.2935573
123.4,255.9561529,11.61636482,531585.565,1.748958184,857.3728877
123.6,256.2384194,11.61634329,533460.6752,1.751572505,861.3631545
123.8,256.5277499,11.61632122,535015.7605,1.754186827,865.0407029
124,256.5461544,11.61631962,535533.034,1.758108261,867.7571736
124.2,256.8483664,11.61629658,534279.9985,1.768129732,870.9846976
124.4,257.2606939,11.61626522,531770.9071,1.78032979,873.2773169
124.6,257.5487779,11.61624325,530940.7334,1.787736973,875.8161888
124.8,257.8996069,11.61621654,531617.9534,1.791658447,878.9391099
125,257.7709136,11.61622605,531983.8519,1.795144149,881.3395804
125.2,257.9825399,11.61620985,534006.5908,1.795144175,884.5006344
125.4,258.0940233,11.61620122,536893.8195,1.792094186,887.4720851
125.6,258.2935992,11.61618593,539983.4218,1.790351352,891.0689935
125.8,258.5945646,11.61616298,542669.752,1.788172816,893.9380294
126,258.359911,11.6161805,548328.1743,1.779022781,897.9075767
126.2,258.9787574,11.61613354,552212.3366,1.77379428,901.1187695
126.4,258.9053296,11.61613888,555306.557,1.771179984,904.4094791
126.6,259.1053211,11.61612356,559256.0543,1.767258577,908.5653731
126.8,259.4798354,11.61609506,559154.802,1.772487197,911.2644241
127,259.2784243,11.61611006,554803.7879,1.789915759,913.778213
127.2,259.6654045,11.61608062,549393.294,1.808651537,915.2601423
127.4,259.7407368,11.61607472,541773.7535,1.833922996,916.3726692
127.6,259.5667506,11.61608765,532274.9749,1.865730145,917.1713662
127.8,260.0376681,11.61605186,525569.2776,1.889258797,917.8044681
128,259.9467881,11.61605852,522790.5375,1.900587369,918.5040136
128.2,260.1218477,11.61604508,522563.1148,1.904944536,919.8497239
128.4,260.2669891,11.61603391,523756.6425,1.90450884,921.2640822
128.6,260.5949641,11.61600892,527911.7231,1.895358874,923.4967683
128.8,260.4675173,11.61601834,533444.4627,1.881851704,925.7370628
129,260.7256831,11.61599863,539942.6398,1.866601722,928.6899966
129.2,261.066124,11.6159727,544311.5992,1.857451763,931.0741434
129.4,260.7799445,11.61599411,549821.3577,1.845687429,933.8690562
129.6,260.6849092,11.61600107,551175.836,1.846994557,936.5092487
129.8,260.9289469,11.61598243,548427.9651,1.858323174,937.8723989
130,260.9078761,11.61598381,544013.6159,1.874444613,938.9783823
130.2,261.0413826,11.61597351,540025.0943,1.889258928,940.0734762
130.4,261.0884588,11.61596975,535062.5228,1.906251809,940.6248361
130.6,261.1197448,11.61596717,532430.1933,1.915837537,941.3592548
130.8,261.4493819,11.61594206,530906.2148,1.922373301,942.3421248
130.97,261.7054726,11.61592254,530181.3283,1.926294759,943.1364838
131.8,261.2666418,11.44926285,1.7977E+308,2.007773357,0
132,261.2939539,11.33309892,1.7977E+308,1.944594726,0
132.2,261.0752718,11.21695358,1.7977E+308,1.802987419,0
132.4,260.8000775,11.10081251,1.7977E+308,1.582080036,0
132.6,260.6262728,10.98466378,1.7977E+308,1.232201125,0
132.8,260.2380542,10.86853125,1.7977E+308,0.813043577,0
133,260.1290722,10.75237762,1.7977E+308,0.48538614,0
133.2,260.2004305,10.63621037,1.7977E+308,0.249228791,0
133.4,259.6410133,10.52009077,1.7977E+308,0.084528643,0
133.6,259.6101511,10.40393125,1.7977E+308,0.030064311,0
133.8,259.1180499,10.28780656,1.7977E+308,0.024835734,0
134,259.0880187,10.17164697,1.7977E+308,0.018735729,0
134.2,258.7554813,10.05551023,1.7977E+308,0.011764295,0
134.4,258.4960772,9.939367967,1.7977E+308,0.00566429,0
134.6,258.2607739,9.823223883,1.7977E+308,0.000435715,0
134.8,258.2407155,9.707063538,1.7977E+308,0.012200009,0
135,257.8674561,9.590929876,1.7977E+308,0.024400017,0
135.2,257.8424113,9.474769908,1.7977E+308,0.033550024,0
135.4,257.443389,9.358638192,1.7977E+308,0.040957171,0
135.6,257.2438214,9.242491408,1.7977E+308,0.04662146,0
135.8,256.9079598,9.12635492,1.7977E+308,0.049671461,0
136,256.7416346,9.010205625,1.7977E+308,0.050978604,0
136.2,256.7165898,8.894045658,1.7977E+308,0.048800031,0
136.4,256.5087116,8.777899502,1.7977E+308,0.046185743,0
136.6,255.8828096,8.661784924,1.7977E+308,0.039650023,0
136.8,255.7148224,8.545635755,1.7977E+308,0.030064303,0
137,255.8102815,8.429466684,1.7977E+308,0.021350012,0
137.2,255.5999101,8.313320716,1.7977E+308,0.022657155,0
137.4,254.99894,8.197204255,1.7977E+308,0.029628586,0
137.6,254.9364975,8.081047113,1.7977E+308,0.042264307,0
137.8,254.5998048,7.964910688,1.7977E+308,0.050107167,0
138,254.3520357,7.848767545,1.7977E+308,0.054900025,0
138.2,254.4400152,7.73259904,1.7977E+308,0.054028597,0
138.4,253.9504074,7.616474166,1.7977E+308,0.051850022,0
138.6,253.5572026,7.50034201,1.7977E+308,0.044007161,0
138.8,253.6318852,7.384174509,1.7977E+308,0.033550014,0
139,253.2453289,7.268041851,1.7977E+308,0.025707153,0
139.2,252.9294128,7.151903856,1.7977E+308,0.023092865,0
139.4,253.0572832,7.035732337,1.7977E+308,0.022221437,0
139.6,252.329161,6.919625481,1.7977E+308,0.020478578,0
139.8,251.9891441,6.803489308,1.7977E+308,0.023964293,0
140,251.8344539,6.687339134,1.7977E+308,0.027885722,0
140.2,251.5485483,6.570618064,1.7977E+308,0.031371437,0
140.4,251.4070627,6.455047701,1.7977E+308,0.033550008,0
140.6,251.0479315,6.338912971,1.7977E+308,0.033550007,0
140.8,250.8558436,6.222765622,1.7977E+308,0.031371435,0
141,250.6588615,6.106037835,1.7977E+308,0.022657147,0
141.2,250.6811873,5.989874289,1.7977E+308,0.007842859,0
141.4,250.250077,5.874325804,1.7977E+308,0.004357144,0
141.6,249.838589,5.758195029,1.7977E+308,0.016121431,0
141.8,249.6930404,5.642044165,1.7977E+308,0.027014289,0
142,249.734065,5.525879206,1.7977E+308,0.03006429,0
142.2,249.2124615,5.40975675,1.7977E+308,0.030064288,0
142.4,248.8691205,5.293620827,1.7977E+308,0.028757145,0
142.6,248.6371416,5.177476492,1.7977E+308,0.021785715,0
142.8,248.3652719,5.06133517,1.7977E+308,0.016992858,0
143,248.5903764,4.945156305,1.7977E+308,0.014378572,0
143.2,248.1360888,4.829028764,1.7977E+308,0.013507143,0
143.4,247.8800092,4.712886249,1.7977E+308,0.014814286,0
143.6,247.587363,4.596746497,1.7977E+308,0.017864285,0
143.8,247.4675773,4.480593686,1.7977E+308,0.017864285,0
144,247.0195227,4.364465673,1.7977E+308,0.01437857,0
144.2,246.952925,4.248308845,1.7977E+308,0.004357143,0
144.4,246.4616552,4.132184097,1.7977E+308,0.006535714,0
144.6,246.2321696,4.016039573,1.7977E+308,0.013071427,0
144.8,246.0201363,3.899893731,1.7977E+308,0.014814284,0
145,245.6285938,3.78376145,1.7977E+308,0.012199998,0
145.2,245.4414923,3.667613724,1.7977E+308,0.015249997,0
145.4,245.2967749,3.551462797,1.7977E+308,0.020042853,0
145.6,244.926009,3.435328946,1.7977E+308,0.020478567,0
145.8,244.4671507,3.319201749,1.7977E+308,0.018299995,0
146,244.3307439,3.203050194,1.7977E+308,0.020478566,0
146.2,243.9973757,3.086913518,1.7977E+308,0.02091428,0
146.4,243.6399068,2.970778663,1.7977E+308,0.021785708,0
146.6,243.2267569,2.854648013,1.7977E+308,0.017428566,0
146.8,243.0188789,2.738501857,1.7977E+308,0.014378566,0
147,242.9763819,2.622343208,1.7977E+308,0.010892853,0
147.2,242.5865017,2.506210801,1.7977E+308,0.020914278,0
147.4,242.3046593,2.390070232,1.7977E+308,0.023528562,0
147.6,241.995392,2.273931736,1.7977E+308,0.027449988,0
147.8,241.622133,2.157798073,1.7977E+308,0.026142845,0
148,241.0918037,2.041676276,1.7977E+308,0.027449986,0
148.2,241.0509688,1.925517501,1.7977E+308,0.0278857,0
148.4,240.6993174,1.809382206,1.7977E+308,0.031371412,0
148.6,240.2894918,1.693251305,1.7977E+308,0.028321413,0
148.8,240.0890934,1.577104584,1.7977E+308,0.02701427,0
149,239.1083295,1.461016814,1.7977E+308,0.022221415,0
149.2,238.6444851,1.344889994,1.7977E+308,0.011328564,0
149.4,238.7773418,1.228718098,1.7977E+308,0.00653571,0
149.518,238.3951621,1.160211472,1.7977E+308,0.00435714,0
224.8,237.6583911,1.003369641,1.7977E+308,0.026578554,0
225,237.3873526,0.887228256,1.7977E+308,0.01089285,0
225.2,236.9667233,0.771098172,1.7977E+308,0.006971424,0
225.4,236.8394582,0.654945926,1.7977E+308,0.021349985,0
225.6,236.4794963,0.538811259,1.7977E+308,0.030499977,0
225.8,235.8245081,0.422698879,1.7977E+308,0.037907113,0
226,235.2509638,0.306580346,1.7977E+308,0.029628547,0
226.2,234.5427878,0.190471983,1.7977E+308,0.017428556,0
226.4,233.4323789,0.074394006,1.7977E+308,0.006099994,0
226.53,232.6173267,-0.001049631,1.7977E+308,0.003049997,0
,,,,,