File: Test_11.csv
Time On Sample,Displacement Into Surface,Load On Sample,Harmonic Contact Stiffness,Harmonic Displacement,Harmonic Load
0,0,0,262.7751748,0.470524123,2.193289016
0.2,0.598653894,0.000712777,2056.499987,0.328059889,2.254304574
0.4,0.356358954,0.001489257,6824.042597,0.207379156,2.352365165
0.6,0.374159851,0.002246035,15645.44286,0.1402859,2.442798847
0.8,0.497494843,0.002994818,22404.73293,0.115452683,2.528874292
1,0.757941063,0.003733214,23641.12626,0.114581344,2.610591502
1.2,0.563842792,0.004506044,22908.09489,0.125037435,2.753324155
1.4,0.48940523,0.005269809,22817.78975,0.137671879,3.034431246
1.6,0.670908801,0.00601306,22335.24167,0.150741996,3.306821866
1.8,0.864877185,0.00675441,22230.35217,0.159455409,3.531271758
2,0.763017706,0.007518168,22297.2326,0.168168818,3.802572777
2.2,0.859761765,0.008266883,23067.20275,0.17688223,4.161038834
2.4,1.100264874,0.009004707,24408.89562,0.183417291,4.567445685
2.6,1.085657995,0.009761857,27061.90911,0.185159973,5.075181755
2.8,1.25802098,0.010504844,29542.16855,0.187338328,5.581828346
3,1.145358795,0.011269422,32105.546,0.187773997,6.066683598
3.2,1.127428008,0.012026824,34510.60184,0.187338327,6.497060766
3.4,1.211707413,0.012776484,39068.67949,0.186466987,7.296799617
3.6,1.077439822,0.013542698,41638.00686,0.193002044,8.012642091
3.8,1.209084926,0.01428877,42902.69968,0.205636491,8.731753356
4,1.175365572,0.015047368,43630.92008,0.220449289,9.443237608
4.2,1.331939993,0.015791551,43658.89481,0.23482642,10.03269098
4.4,1.452782397,0.016538442,43276.74414,0.262273666,11.08520838
4.6,1.638441024,0.017280422,42971.90935,0.288413903,12.09305377
4.8,1.215824342,0.018068481,42650.97345,0.313682786,13.0627641
5,1.322540133,0.018816442,41486.88789,0.345922408,14.02375826
5.2,1.469973808,0.019561318,39823.64901,0.379469043,14.7690191
5.4,1.46118377,0.020318028,38971.99154,0.418679393,15.96971693
5.6,1.493942592,0.021071591,37801.50506,0.460939438,17.06581681
5.8,1.606475227,0.021819112,36595.52325,0.506249179,18.11833426
6,1.879386467,0.022554483,35827.17386,0.541102835,18.95076025
6.2,1.287250425,0.023355384,35514.34742,0.57029274,19.80606625
6.4,1.75710326,0.024075837,35140.92134,0.610810119,20.99042114
6.6,1.456640219,0.024854643,34884.65521,0.645663752,22.04184863
6.8,1.541750606,0.02560424,34375.24101,0.684874105,23.07693308
7,1.771451031,0.026342885,33780.25181,0.724955809,24.02049447
7.2,1.38705929,0.027128049,32910.19196,0.767215834,24.76793393
7.4,1.680744959,0.027861846,31824.63556,0.825160035,25.73873446
7.6,1.785798802,0.028609934,30736.74865,0.882232885,26.5548169
7.8,1.556799799,0.029383326,29505.09106,0.946276444,27.3414808
8,1.654374846,0.03013198,28183.35371,1.015548071,28.0496966
8.2,1.912328501,0.030868485,27143.89441,1.074363617,28.62934413
8.4,1.734850083,0.031637975,25987.00005,1.138842848,29.16758779
8.6,1.366246907,0.032421943,24562.80979,1.220313213,29.67641298
8.8,2.413628949,0.033098647,23581.46782,1.282614197,30.0490449
9,2.012617642,0.033885072,22693.60797,1.347529078,30.50012323
9.2,2.505737875,0.034603764,22168.80468,1.392838867,30.86403782
9.4,2.568411884,0.035355063,22303.6814,1.408087346,31.41426707
9.6,2.471538254,0.036118449,23065.55486,1.384996797,31.94052568
9.8,2.269130511,0.036889829,24692.24681,1.329230945,32.72501032
10,2.434014724,0.037633386,26410.86005,1.273029457,33.43104719
10.2,2.545716394,0.038380972,28910.52563,1.197658456,34.29833914
10.4,2.591770858,0.039133531,31710.44928,1.13056519,35.32143855
10.6,1.442049038,0.039976672,33289.75726,1.10660322,36.19417614
10.8,1.960929552,0.040693411,33324.63731,1.123158744,36.77491387
11,2.341036878,0.041420664,31576.47451,1.199836798,37.31097938
11.2,2.951324931,0.042130482,29001.48599,1.309190173,37.54523642
11.4,3.062195629,0.042878132,26231.2589,1.445119415,37.71302934
11.6,2.997730111,0.043639064,24503.82473,1.54445231,37.80346291
11.8,3.150149676,0.044383567,23901.49733,1.58845506,37.99413673
12,3.166288959,0.045138393,24680.20215,1.559700804,38.48770864
12.2,2.958895339,0.045910153,26628.62326,1.476052026,39.14580407
12.4,3.280834282,0.046641815,29271.29064,1.376283489,39.93137935
12.6,2.972892403,0.047421191,32802.57084,1.265623126,40.93922419
12.8,3.203423839,0.048159777,35018.28594,1.21072865,41.6844855
13,3.212084327,0.048915171,36488.85557,1.186766769,42.49838883
13.2,3.032943935,0.04968479,36689.74139,1.19678718,43.08675222
13.4,3.461247984,0.050408394,36451.38885,1.223798796,43.78516286
13.6,3.581259439,0.051155353,36098.86043,1.253424411,44.41166166
13.8,3.429541295,0.051922896,35828.76241,1.276950613,44.90196461
14,3.293611722,0.052689243,35563.08942,1.30265517,45.47725326
14.2,3.510016551,0.0534289,35352.10221,1.323131711,45.94140747
14.4,3.407326071,0.054192729,34983.00926,1.352757306,46.53303973
14.6,3.683976763,0.054927822,34514.74599,1.385432632,47.06583642
14.8,3.662306576,0.055685514,34184.35607,1.408523175,47.44827296
15,3.502278657,0.056453687,33996.63255,1.430306693,47.96581493
15.2,3.588220041,0.057203227,33974.62148,1.444248164,48.4136255
15.4,3.753935255,0.057946724,34094.55285,1.453832937,48.88104824
15.6,3.785032134,0.05870042,34399.58438,1.457318307,49.4541584
15.8,3.787044201,0.059460106,34722.12295,1.45775398,49.90741639
16,3.743353716,0.060215679,34850.68656,1.468645744,50.42277949
16.2,4.061968174,0.060951382,34856.62936,1.480844556,50.83245594
16.4,3.78394206,0.061724707,34926.7614,1.493043308,51.36525148
16.6,4.05851532,0.062459959,34878.2731,1.510034494,51.8283162
16.8,3.886022733,0.063229077,34778.87421,1.52441161,52.18787155
17,4.027639608,0.063974401,34702.79279,1.539224429,52.62696569
17.2,3.919132282,0.064738672,34584.37578,1.554037222,52.96146113
17.4,3.980144348,0.065490102,34319.11829,1.578434787,53.3678682
17.6,4.452490244,0.066210373,34186.16875,1.593683315,53.67076797
17.8,4.402151335,0.066970239,34242.7811,1.604139407,54.06301047
18,4.68004852,0.06770524,34663.28364,1.599782734,54.49447809
18.2,4.652146002,0.068463407,35370.97007,1.581484564,54.92049685
18.4,4.488794159,0.069231834,36683.65754,1.544452541,55.56769685
18.6,4.705199014,0.069971494,37816.15556,1.513084277,56.09286655
18.8,4.352384312,0.070754274,39151.89945,1.47910193,56.75640958
19,4.406748562,0.071506208,40255.04668,1.45514005,57.42866967
19.2,4.60237898,0.072247442,40734.33098,1.450347695,57.94403354
19.4,4.596912853,0.073003909,40938.60246,1.457754098,58.57271125
19.6,4.511672891,0.073766419,41039.71583,1.465160493,59.02161089
19.8,4.765471734,0.074503247,41071.69579,1.478230641,59.56530352
20,4.682724703,0.075265569,41238.00145,1.486944048,60.11226375
20.2,4.872538284,0.076007243,41626.27619,1.485637058,60.58622439
20.4,4.757383131,0.07677202,42295.5445,1.479101987,61.24649889
20.6,4.385455942,0.077556248,42875.2714,1.47213122,61.79018968
20.8,4.608508618,0.078295405,43569.25503,1.463417832,62.44828626
21,4.534902339,0.079057034,44033.83486,1.45949679,62.97781372
21.2,4.131398011,0.079843654,44261.00861,1.462982116,63.49208596
21.4,4.299606172,0.080586965,44012.35602,1.484330004,64.09134609
21.6,4.619051706,0.081322149,43190.93408,1.523104722,64.53262003
21.8,4.767314703,0.082077733,42454.6424,1.557087058,64.8311605
22,4.665452253,0.082859976,41641.19135,1.596733083,65.16565625
22.2,4.658319983,0.083642927,41168.16072,1.623308994,65.45003215
22.4,4.444273085,0.084449326,41195.35973,1.63420074,65.8891253
22.6,4.607488692,0.085235131,42038.84629,1.615466919,66.45460894
22.8,4.82970242,0.086024537,42857.49971,1.596297439,66.93183819
23,4.830043908,0.086838624,43792.99006,1.576256589,67.52891863
23.2,4.912650851,0.087654766,44627.93579,1.559265442,68.05953601
23.4,4.954538607,0.088482104,45620.55814,1.541402947,68.76012505
23.6,5.304717722,0.089294276,46252.10018,1.533996586,69.36156492
23.8,5.382334895,0.090135384,47055.97691,1.521797816,70.00985509
24,5.561329982,0.090977287,47790.06524,1.510034728,70.57098059
24.2,5.644761317,0.09183483,48321.22164,1.503935348,71.131016
24.4,5.770571141,0.092697769,48813.22554,1.501757012,71.85339684
24.6,5.577284168,0.093593792,49237.8217,1.50088565,72.54091029
24.8,5.796991641,0.094467324,49332.5924,1.506985065,73.03775182
25,5.941909748,0.095355253,49574.18116,1.511777461,73.67187801
25.2,5.671337625,0.096283769,50025.79299,1.510034751,74.22755409
25.4,5.811266977,0.097190249,50463.81053,1.512213122,74.9314123
25.6,6.191347389,0.098087744,50687.73011,1.517005542,75.45985151
25.8,6.084473482,0.099031294,50998.51925,1.52136224,76.11032021
26,5.960978517,0.099985587,51350.49271,1.524411924,76.76187844
26.2,5.977917264,0.100938672,51317.19762,1.535303697,77.25980876
26.4,6.099557665,0.101893395,51328.27899,1.547066822,77.89938261
26.6,6.210393828,0.102858569,51544.37125,1.550552202,78.41583595
26.8,6.229820906,0.103840419,51978.01864,1.550552206,79.06957384
27,6.148698117,0.104839816,52349.5016,1.55098787,79.67537046
27.2,6.097488949,0.105846832,53078.54197,1.54096744,80.26264477
27.4,6.251529632,0.106848467,54423.25511,1.520055262,81.12884782
27.6,6.142148793,0.107880271,55175.9743,1.511341838,81.75316697
27.8,6.19148303,0.108910398,55954.29846,1.504371113,82.51477153
28,6.380419896,0.109940084,56648.12625,1.500885769,83.3014368
28.2,6.727240851,0.110968272,56904.55972,1.505678185,83.90396633
28.4,6.43171444,0.112055576,57143.26216,1.51352023,84.68627148
28.6,6.492675708,0.113126709,57482.8971,1.515262922,85.28117319
28.8,6.178864331,0.114237174,57796.7594,1.520055269,86.01335812
29,6.412665484,0.115316968,58082.24994,1.524847674,86.73900813
29.2,6.690506725,0.116404319,58169.32142,1.531818438,87.32192563
29.4,6.538730759,0.117535355,58212.99733,1.540096169,87.92990115
29.6,6.688597888,0.118654785,58113.54336,1.553601981,88.59562463
29.8,6.829322486,0.119786094,58194.65279,1.562751084,89.26788551
30,6.65011886,0.120953155,58492.0727,1.564929421,89.8377262
30.2,6.727685489,0.122112324,59072.22057,1.561008395,90.45986703
30.4,7.008008815,0.123267789,59892.14245,1.554909036,91.29774241
30.6,6.84209527,0.124468816,60842.63207,1.544452921,92.12363023
30.8,6.980317642,0.125658795,61407.59282,1.540531901,92.76102529
31,6.81772419,0.126883585,61685.17619,1.544888594,93.51282279
31.2,6.794733059,0.128109916,61675.85704,1.55403768,94.09900801
31.4,7.090835401,0.129324347,61474.39464,1.571028875,94.81921026
31.6,7.0287844,0.130578291,61013.94034,1.593248081,95.41955928
31.8,7.04068841,0.13183923,60743.51204,1.608496562,95.88044461
32,6.977802415,0.13311851,60634.29916,1.622002351,96.45791277
32.2,7.259770131,0.134384402,60668.93548,1.62984446,96.97545621
32.4,7.137049673,0.135693813,61176.01953,1.627666094,97.70873144
32.6,7.250324795,0.136998444,61806.53164,1.620259705,98.29273782
32.8,7.198233274,0.138328709,62666.60919,1.610239273,99.03908866
33,7.32064494,0.139659148,63709.81854,1.597169165,99.83882825
33.2,7.485434342,0.140999764,64624.637,1.586277415,100.5296123
33.4,7.36852016,0.142375201,64997.95415,1.58889143,101.1920657
33.6,7.505052003,0.143745116,65182.74678,1.596733521,101.9013721
33.8,7.417217637,0.145146049,65194.98486,1.607625284,102.5714527
34,7.584490078,0.146548738,65083.34087,1.620259759,103.1935941
34.2,7.719354414,0.147953726,64727.65605,1.636815267,103.6806296
34.4,7.594119311,0.149399884,64721.04022,1.645093001,104.2188729
34.6,7.50793788,0.150857437,64722.54475,1.653806409,104.8170428
34.8,7.634484425,0.152313468,64930.76822,1.657727463,105.4522586
35,7.817535137,0.15377982,65063.00321,1.661648524,105.9578174
35.2,8.106117674,0.155252973,65535.84773,1.658163193,106.5418243
35.4,7.749028117,0.156790054,66192.19371,1.652935104,107.3023374
35.6,8.071675956,0.158290734,66918.54185,1.645528739,108.0247198
35.8,8.063592225,0.159831739,67370.68586,1.642914716,108.6130837
36,8.04802723,0.161388814,67768.49262,1.643786058,109.3082248
36.2,8.283415059,0.162942351,67912.42156,1.649014137,109.8856944
36.4,8.950908881,0.164478678,68016.91167,1.655113608,110.4620772
36.6,9.022589147,0.166075752,68262.13802,1.659470327,111.1561293
36.8,8.871564783,0.167705916,68707.60114,1.657291958,111.7303281
37,8.962352384,0.169333973,69734.63383,1.644657515,112.5551284
37.2,9.136235165,0.170972108,70811.98777,1.629844728,113.305838
37.4,8.924541631,0.172655861,71874.36089,1.616338909,114.0914121
37.6,8.941364321,0.17433913,73125.96925,1.601526104,115.0240783
37.8,9.593051405,0.175991126,74118.68301,1.590634406,115.8020294
38,9.187731983,0.177740152,75055.78067,1.583227959,116.7477683
38.2,9.330024205,0.179465018,75744.98624,1.57974261,117.5366127
38.4,9.335202302,0.181217774,76252.00909,1.580178282,118.3265462
38.6,9.418489541,0.182982071,76458.28266,1.58802037,119.1796746
38.8,9.345550107,0.18477606,76080.36335,1.606318544,119.9031443
39,9.727152717,0.1865535,75728.17573,1.622438411,120.4740777
39.2,9.625954323,0.188385558,75291.42652,1.640300907,121.0384711
39.4,9.704244244,0.190222289,74881.00662,1.657292086,121.5941489
39.6,9.80662959,0.192075652,74705.61175,1.670362227,122.2707678
39.8,9.619000675,0.193969751,74962.31761,1.672540562,122.8460566
40,9.783703402,0.195855887,75232.09631,1.676025947,123.5553632
40.2,9.778883591,0.197774063,75716.25452,1.673847597,124.206922
40.4,9.833891126,0.199706966,76392.94369,1.668619551,124.9053324
40.6,10.04844334,0.20164712,76876.86159,1.66905525,125.6702071
40.8,10.17490879,0.203613536,76920.1488,1.676026002,126.2356913
41,9.832699548,0.205635326,76919.7913,1.685175055,126.9057706
41.2,10.10457978,0.207630653,76618.2768,1.698680885,127.4156879
41.4,10.40138617,0.209644149,76064.88042,1.717850445,127.9670088
41.6,10.07246293,0.211725539,75963.38648,1.725692486,128.4409668
41.8,10.32605192,0.213783479,76032.95768,1.730920567,129.0282426
42,10.34862575,0.215879707,76144.9385,1.733970269,129.5218154
42.2,10.51911029,0.217985846,76699.77106,1.728306573,130.1025538
42.4,10.3879465,0.220135936,77568.6549,1.718721796,130.8935758
42.6,10.60163514,0.222281317,78016.01228,1.716107798,131.4579707
42.8,11.26737237,0.224413981,78770.03308,1.709572816,132.2184901
43,11.41208299,0.226607737,79576.54144,1.7026021,132.97029
43.2,11.61745153,0.228818785,80041.30555,1.700859442,133.5891635
43.4,12.04385668,0.231035403,80598.53776,1.697809798,134.2363667
43.6,11.90270028,0.233317446,81549.45598,1.689096365,135.0807772
43.8,11.91360927,0.235610553,82365.96988,1.681254291,135.7802775
44,12.20870908,0.237905147,83550.0898,1.668619869,136.70096
44.2,12.27113138,0.240240417,84547.81621,1.658163775,137.4669236
44.4,12.08841142,0.24261782,85517.64647,1.649014665,138.299349
44.6,12.45413319,0.244977404,86229.62997,1.645965012,139.2352861
44.8,12.35367249,0.247396162,86630.49836,1.646400674,139.9413225
45,12.24572912,0.249839795,86777.29721,1.652935729,140.7704794
45.2,12.43194811,0.252285489,86790.66693,1.66034216,141.4536373
45.4,12.56664254,0.254759761,86803.6071,1.667748584,142.1422425
45.6,12.37143472,0.25728397,86968.68553,1.673847958,142.9223685
45.8,12.71054178,0.259792962,87221.62765,1.678640381,143.7221104
46,12.65326826,0.262357349,87471.43426,1.682125744,144.3714897
46.2,12.53200536,0.264952229,87833.38719,1.683868417,145.0481079
46.4,12.39578071,0.267574273,88400.25763,1.684304074,145.9426384
46.6,12.7182518,0.270187747,88878.19679,1.683432772,146.6214388
46.8,12.77812962,0.272847546,89196.02521,1.686918149,147.4298957
47,12.82221462,0.275535199,89440.92879,1.689096512,148.0705587
47.2,12.86214043,0.278250212,89559.27458,1.693453229,148.7242976
47.4,12.99430049,0.280985414,89813.40916,1.697809957,149.5719786
47.6,13.06163985,0.283753198,89869.56873,1.703473691,150.1690598
47.8,13.13063676,0.286548627,90254.77918,1.705216385,150.9589938
48,13.21791073,0.289370742,91090.4143,1.699988346,151.8012272
48.2,13.08580195,0.29223794,92082.92496,1.691710583,152.5966074
48.4,13.16060216,0.295118169,92843.89975,1.687353884,153.3898104
48.6,13.31766462,0.298021009,93899.06141,1.679511826,154.3704182
48.8,13.4954969,0.30095141,94817.27499,1.672105441,155.1636225
49,13.67166254,0.303911443,95563.46393,1.669491438,156.111544
49.2,13.56113599,0.306922949,95821.82519,1.672541125,156.8361027
49.4,13.90265676,0.309930428,96253.83041,1.673412509,157.6369345
49.6,13.90721106,0.312993739,96738.61578,1.674719525,158.5401826
49.8,14.11701206,0.316072423,96663.20932,1.685175657,159.3606256
50,13.97488889,0.319208636,96717.58116,1.691275037,160.0132733
50.2,14.31888297,0.322339412,96752.68326,1.697810146,160.6681032
50.4,14.06872262,0.32554682,96489.71257,1.710880251,161.4318856
50.6,14.31880605,0.328748387,96040.36842,1.724821757,161.9723111
50.8,14.06531155,0.332020445,95783.43143,1.736584848,162.6641821
51,14.46496073,0.335275619,95467.02523,1.747476675,163.1610258
51.2,14.31449711,0.338605383,95083.82699,1.759675449,163.6654928
51.4,14.58034827,0.341936956,94821.2079,1.771002932,164.300711
51.6,14.58859082,0.345321834,94374.08292,1.784508739,164.832418
51.8,14.81953014,0.348723735,94133.38464,1.793222192,165.246454
52,14.53442652,0.35219909,94279.01025,1.796707527,165.8402633
52.2,14.4204989,0.355696241,94592.43303,1.796271845,166.3458206
52.4,14.78437819,0.359192166,94951.67318,1.79540055,166.8906056
52.6,14.81170569,0.362748908,96309.61343,1.779280726,167.6870766
52.8,14.83819654,0.366341343,97637.45237,1.763160901,168.4116364
53,14.77161208,0.369977023,98608.9166,1.754447474,169.2386151
53.2,15.53516917,0.373585912,99296.1349,1.749219516,169.9435689
53.4,15.92810415,0.377259461,99853.23964,1.746605539,170.6626835
53.6,16.5437355,0.380952881,99766.60026,1.754447697,171.3719951
53.8,17.03471421,0.384692921,99689.71931,1.760982826,171.9135126
54,16.91076294,0.388517249,100497.5959,1.755319089,172.7154307
54.2,17.33109642,0.392338645,101530.7914,1.745734377,173.4813968
54.4,17.50462322,0.396217159,102980.9064,1.730050238,174.3584977
54.6,17.53853945,0.400145213,104923.9169,1.709138028,175.4644053
54.8,18.05607886,0.404076063,106209.6811,1.696939298,176.3393294
55,18.16560156,0.408077495,107232.2811,1.690404245,177.3733258
55.2,18.29921626,0.412117192,108015.4681,1.686047551,178.2449786
55.4,18.58489356,0.416186032,108669.7295,1.686483258,179.3214704
55.6,18.45507512,0.420327247,109478.4708,1.682562205,180.1735075
55.8,18.68672574,0.424482486,110871.0463,1.672541796,181.3197304
56,18.71893489,0.428694635,112400.6551,1.659471666,182.3199505
56.2,18.88741779,0.432938702,113716.7341,1.650322592,183.3572172
56.4,18.99689442,0.437230018,115754.7769,1.634638442,184.7987108
56.6,18.80638095,0.441587216,116714.8175,1.630281716,185.8196309
56.8,19.04215252,0.445955714,117464.8684,1.631153084,187.0660929
57,19.18484752,0.450375182,117486.7877,1.638559512,187.9464625
57.2,19.18959303,0.454849513,117787.5644,1.642480556,188.9052792
57.4,19.36218907,0.459355959,117549.2121,1.655115047,190.0220837
57.6,19.47079256,0.463912601,117752.0775,1.661650127,191.145425
57.8,19.46305177,0.468523933,118130.0578,1.663828489,192.0682856
58,19.51513408,0.473176956,118988.415,1.662085812,193.245015
58.2,19.77079871,0.477861275,119621.1101,1.660343155,194.0327722
58.4,19.84031665,0.482606834,120882.1602,1.655115112,195.4197876
58.6,20.09430427,0.48738605,121397.3595,1.656422159,196.374248
58.8,20.30922826,0.49221624,121960.5573,1.659471882,197.5793078
59,20.63300275,0.497086677,121985.0182,1.666442663,198.4749325
59.2,21.04568419,0.50199931,121406.5842,1.680819864,199.2746752
59.4,20.86503901,0.507006415,120171.1336,1.705217438,200.1463259
59.6,21.11566375,0.512031105,119197.6237,1.72395134,200.7662903
59.8,21.45851912,0.517099205,117875.1482,1.747913302,201.4309278
60,21.41246837,0.522247763,116957.3861,1.766647165,202.0813966
60.2,21.34231102,0.527449898,116673.9331,1.775360585,202.6926412
60.4,21.68264884,0.532673058,117014.8531,1.775796301,203.4073984
60.6,21.86259942,0.537960991,117892.2698,1.769696927,204.3052015
60.8,21.946979,0.54330931,118923.2558,1.761419184,205.1245542
61,22.40113557,0.548683364,120494.2718,1.747477759,206.2141222
61.2,22.64920088,0.554126811,121749.9174,1.737893022,207.1653149
61.4,23.17563539,0.559603808,122910.4397,1.730486675,208.1502862
61.6,23.16857276,0.565176475,124083.8485,1.724387277,209.2605518
61.8,23.39916117,0.57078701,125124.32,1.718287908,210.1757879
62,23.46520681,0.576466546,126194.8854,1.713931204,211.3067561
62.2,23.43069494,0.582210739,127142.6958,1.709574489,212.279737
62.4,23.45766633,0.588007951,127995.1578,1.706524795,213.2941212
62.6,23.34170011,0.59387425,128524.0225,1.70870314,214.3978483
62.8,23.59883405,0.599770952,128263.8686,1.718723615,215.173621
63,23.91661999,0.605722573,128147.1104,1.728308426,216.0888579
63.2,24.18204478,0.611737838,127858.3909,1.738764574,216.8395702
63.4,24.49898065,0.617809649,127835.8985,1.747478043,217.8038379
63.6,24.6322605,0.623956395,128399.9776,1.746606719,218.6090279
63.8,24.87605074,0.630156478,130260.6196,1.731793922,219.8326108
64,24.72096119,0.636449219,131750.722,1.720466449,220.8698743
64.2,24.8101694,0.642786562,133522.4673,1.706524977,222.0073799
64.4,25.1902101,0.649165567,135967.9093,1.687791152,223.5687299
64.6,25.47384706,0.655616034,137522.1853,1.677335073,224.7312977
64.8,25.48075772,0.662152316,138405.1055,1.676028062,226.057298
65,25.44029214,0.668757945,138977.4198,1.676463731,227.1163532
65.2,25.16215605,0.675447891,139480.5496,1.678206387,228.2179006
65.4,26.14377342,0.682109068,140257.793,1.678642175,229.633255
65.6,26.38414688,0.688893833,140714.9105,1.680384891,230.6955821
65.8,26.90538044,0.695725273,141323.0251,1.682127641,231.9605725
66,27.23049206,0.702640205,141880.3234,1.683434695,233.0174539
66.2,27.34120001,0.709641076,142242.3171,1.686920083,234.0656153
66.4,27.37627769,0.716718024,142305.9605,1.69563352,235.3447649
66.6,27.56424425,0.723854256,143104.2852,1.694762201,236.4190776
66.8,27.8992827,0.731051125,144780.0444,1.686048812,237.8627542
67,28.22101397,0.738321441,146448.8528,1.675592735,239.0961439
67.2,28.07904724,0.745700369,148356.3543,1.664700933,240.6335185
67.4,28.42817742,0.753115884,150260.2811,1.654244859,242.1447475
67.6,28.34435566,0.760638615,151160.2608,1.654680523,243.6864811
67.8,28.34195787,0.768230601,151248.0744,1.660779927,244.7869402
68,28.39189963,0.775894932,150685.3125,1.675157096,246.0290444
68.2,28.92379707,0.78359958,149739.9678,1.692148351,246.9715245
68.4,29.12744542,0.791406764,148942.254,1.707396882,247.9074628
68.6,29.43329174,0.799284621,148374.9831,1.721338411,249.0111953
68.8,29.50977523,0.80725905,148136.5987,1.730487526,249.8850274
69,29.72750601,0.815343356,148207.9779,1.7374583,250.9713255
69.2,29.82307639,0.823477634,148973.4661,1.735715628,251.9987862
69.4,29.9435631,0.831692004,149800.6072,1.733537287,253.0622025
69.6,30.28674576,0.839930363,150521.3403,1.733537331,254.2868763
69.8,30.50443076,0.848302799,151252.7358,1.731794673,255.3219657
70,30.78442586,0.856754498,152668.808,1.724823963,256.6861044
70.2,31.08102703,0.865289985,153789.9234,1.720031613,257.8661068
70.4,30.88318186,0.873948937,154983.4954,1.714803532,259.1278198
70.6,30.93794059,0.882675563,155904.6095,1.713932198,260.5191949
70.8,31.16552908,0.891476735,156519.3602,1.714367899,261.5804337
71,30.92609313,0.900401887,156435.9037,1.722645634,262.7451751
71.2,31.34560956,0.909366422,155780.5878,1.735715836,263.6375342
71.4,31.44850853,0.918445262,155114.7248,1.749221672,264.4841269
71.6,31.5198158,0.927617635,155512.2272,1.753142728,265.6118273
71.8,31.81048696,0.936865542,155443.2928,1.760113513,266.4584228
72,33.60023031,0.946092012,155504.7673,1.767084481,267.4750094
72.2,33.46790346,0.955557702,156591.7829,1.762292079,268.5035572
72.4,33.82417743,0.965081248,157729.1224,1.757064064,269.6072909
72.6,34.11229589,0.974705666,158309.8336,1.757935445,270.8079951
72.8,34.49513064,0.98441964,159365.1257,1.75270744,271.8441761
73,34.70510616,0.99424424,161516.6626,1.738765966,273.3194499
73.2,35.19843003,1.004145931,162771.6708,1.733102295,274.5310521
73.4,35.97260922,1.014125756,164208.0886,1.728310001,276.0444676
73.6,36.17505853,1.024249258,165509.1451,1.723081966,277.2517087
73.8,37.19102078,1.034412508,166574.1588,1.720032387,278.4371689
74,37.29039624,1.044747539,167322.2047,1.721339417,279.8427098
74.2,37.53019078,1.055175686,168004.1017,1.72177512,281.0336062
74.4,37.69185659,1.065714439,168556.4159,1.723082159,282.2299518
74.6,38.06457442,1.07634303,169559.9103,1.72133952,283.6736315
74.8,38.55693637,1.087069406,170526.7323,1.720032566,285.127118
75,38.5482004,1.097941532,171590.9368,1.716547196,286.3278171
75.2,39.04468279,1.108884485,172759.6652,1.712626211,287.5851835
75.4,39.3392196,1.11995287,174378.7615,1.707398182,289.292536
75.6,39.4916412,1.131143136,175170.9163,1.707398203,290.5400902
75.8,39.55346811,1.142452851,175756.0589,1.710447917,292.0011978
76,40.21773738,1.153830255,175583.9696,1.718290093,293.0798767
76.2,40.45901973,1.165354202,175047.9752,1.729181923,294.0953549
76.4,40.80166325,1.176986109,174871.2928,1.738331076,295.4159128
76.6,41.01465532,1.18874482,175101.1653,1.742252152,296.480421
76.8,41.06309458,1.200634195,175515.6226,1.746173209,297.7693774
77,41.28934456,1.212629512,176734.4549,1.741816515,298.9657232
77.2,41.6934051,1.224731876,178370.7097,1.734410143,300.2775656
77.4,42.12569966,1.236953569,180188.7362,1.727439448,301.9369797
77.6,42.73331148,1.249284783,181473.0578,1.7230828,303.2422867
77.8,42.83732972,1.261778247,183413.4185,1.714805047,304.9648908
78,43.35931099,1.274365412,185380.1482,1.706091671,306.6319331
78.2,43.59873894,1.287100496,186937.0293,1.699992293,308.1061185
78.4,44.05503238,1.299946996,188616.7251,1.693457269,309.7284885
78.6,44.06839289,1.312956301,190524.6761,1.686922192,311.6243316
78.8,44.50470153,1.326064108,191413.6373,1.686922246,313.0505811
79,44.58782266,1.339330575,192362.0432,1.687793602,314.7383181
79.2,44.63269752,1.352733198,192983.4418,1.690407642,316.1863503
79.4,45.46947509,1.366210259,193393.762,1.695200136,317.6169633
79.6,45.86664263,1.37985625,193756.0382,1.701299595,319.2218983
79.8,45.89649513,1.393667159,194697.5488,1.700863929,320.5958413
80,46.02355028,1.407609387,195070.176,1.706527684,322.224744
80.2,46.51538347,1.421664102,195685.3273,1.708706105,323.5932457
80.4,46.74792837,1.435879811,196420.9033,1.710013152,325.041282
80.6,47.39843368,1.450206446,198171.4807,1.704785166,326.9055381
80.8,47.98326871,1.464681989,199518.4461,1.70129986,328.3644759
81,48.4002226,1.479315712,201974.8525,1.691715123,330.3431335
81.2,48.94180023,1.494086825,203680.3017,1.686487123,331.9872965
81.4,49.324637,1.509018538,205149.3474,1.683437465,333.7327877
81.6,49.74484405,1.524097493,206223.9911,1.684308861,335.6319062
81.8,50.23150549,1.539322799,206105.3614,1.691715349,337.0200219
82,50.39572216,1.554725754,205811.3048,1.70130016,338.6511032
82.2,50.69868799,1.570272853,206342.1014,1.70347856,340.1536204
82.4,51.18693768,1.585961916,207218.5051,1.705221309,342.0788907
82.6,51.76573922,1.601801743,207962.0854,1.706092725,343.5073207
82.8,52.10103815,1.617819305,209717.4977,1.701736044,345.4347683
83,52.4072272,1.633999961,210991.9987,1.699557721,346.9579865
83.2,52.66851745,1.650346648,211445.6586,1.70435015,348.4539644
83.4,53.18239972,1.666838359,211541.4259,1.713499333,350.2266974
83.6,53.94222596,1.683477125,211673.2369,1.719163166,351.5352786
83.8,54.42697105,1.70030389,211695.0812,1.72700533,353.1227842
84,54.86266141,1.717303486,211715.6841,1.732669126,354.3616287
84.2,55.21605754,1.734480123,212053.4463,1.735718878,355.7094275
84.4,55.60765137,1.751826404,212981.8,1.735718927,357.5409951
84.6,55.9639007,1.769350411,214126.8315,1.732669266,358.9814071
84.8,56.3251079,1.787050349,215810.5768,1.727441243,360.8445709
85,56.84541984,1.80491505,218128.0113,1.718292186,362.7633058
85.2,57.74296863,1.822930445,220684.4722,1.707400483,364.5676431
85.4,58.10533692,1.8411677,223107.3968,1.698687079,366.4634951
85.6,58.50257733,1.859585359,225257.2071,1.693894731,368.6350071
85.8,58.92554874,1.878186208,226311.4424,1.694330455,370.2410351
86,59.56786946,1.896957197,226231.8817,1.703915329,372.0170397
86.2,60.09382287,1.91592565,225300.5467,1.717421244,373.3267071
86.4,60.50008472,1.93509389,224446.044,1.730055799,374.6548964
86.6,61.26031394,1.954427761,224406.9552,1.737898,376.279453
86.8,61.8094431,1.973971894,224361.2297,1.743997486,377.5771372
87,62.27210316,1.993818842,225190.932,1.745304562,379.2834065
87.2,62.57604578,2.013678056,225789.9765,1.747047292,380.6954899
87.4,63.400135,2.033797688,225299.5131,1.758374884,382.2699276
87.6,63.94581342,2.054140485,224144.8207,1.771880807,383.2080563
87.8,64.23801005,2.074707026,223368.6901,1.784515353,384.4795854
88,64.66562381,2.095469831,223087.4055,1.791921845,385.5005175
88.2,65.4031605,2.116417612,223684.0511,1.793228958,386.6750841
88.4,66.32514165,2.137561872,226547.7457,1.780158892,388.5796638
88.6,66.62800787,2.158965686,229470.038,1.765346059,390.1726158
88.8,67.13941628,2.180568661,232488.1853,1.751840268,392.1959508
89,67.71560676,2.202383794,235900.4727,1.736591792,394.3249743
89.2,67.96435567,2.224443107,238861.3578,1.723957313,396.2676764
89.4,68.71498225,2.246685843,241675.0824,1.713065585,398.2757615
89.6,69.57775585,2.269143602,244547.5526,1.703480887,400.594377
89.8,70.30919855,2.291836906,247398.8356,1.693024827,402.5686865
90,70.55697366,2.314795084,249813.2244,1.687361111,404.9297823
90.2,71.10802048,2.337960638,251154.913,1.686925506,406.8278178
90.4,71.70722725,2.361355417,251949.8797,1.689975289,408.7302153
90.6,72.3155375,2.384984476,253188.385,1.691282382,410.9278826
90.8,72.87228922,2.408854456,254252.7688,1.693460814,413.1375346
91,73.33676389,2.432971104,254645.2453,1.697381929,414.8220152
91.2,74.00395965,2.457314578,254383.3984,1.705224124,416.4749014
91.4,74.63704634,2.481905047,253913.9489,1.715680354,418.5440035
91.6,75.12051704,2.506753844,253794.8954,1.721779837,420.0748534
91.8,75.75269388,2.531840831,253340.2033,1.731364727,421.8465042
92,76.30505642,2.557185882,253894.148,1.735285854,423.7129423
92.2,76.66209769,2.582800553,255217.0863,1.733543207,425.4867679
92.4,77.11216806,2.608665529,256921.573,1.730057879,427.3717284
92.6,77.89459001,2.63476502,258127.0461,1.731364992,429.4702511
92.8,78.34208447,2.661152322,259748.1808,1.728315342,431.2124785
93,78.50118599,2.687826631,262354.2515,1.721344591,433.5180061
93.2,79.12310201,2.714733719,264755.1091,1.715245245,435.5653161
93.4,79.81643957,2.741905697,266549.6209,1.713066963,437.5755825
93.6,80.68008516,2.769337665,269065.5977,1.707403317,439.965022
93.8,81.24536429,2.797068065,270337.3313,1.70653204,441.7769847
94,81.97596469,2.825064342,271076.0588,1.710453193,444.0334945
94.2,82.53201411,2.853355102,270717.1111,1.718295376,445.6678578
94.4,83.18441235,2.881922754,271173.9572,1.723087858,447.9505158
94.6,83.63732915,2.910792827,271046.9608,1.729623023,449.5805188
94.8,84.66025391,2.939909488,271206.1088,1.736158246,451.5602854
95,85.08150081,2.969364586,271133.7941,1.742257721,453.070433
95.2,85.72623503,2.999098495,271678.7676,1.745307523,454.7745336
95.4,86.16650008,3.029146626,272273.557,1.749664309,456.8763194
95.6,86.82692755,3.059479976,273252.2753,1.749664388,458.4758176
95.8,87.35850428,3.09012793,275644.2342,1.744000701,460.7268771
96,88.69857835,3.121022171,278690.594,1.733980376,462.7720251
96.2,89.48683055,3.152269031,282112.6933,1.722652963,464.9827762
96.4,90.39220152,3.183820687,286238.618,1.710018542,467.9028381
96.6,90.75821421,3.21573044,288805.4488,1.703483486,470.0558322
96.8,91.5463153,3.247928719,291706.8068,1.696512805,472.7830397
97,92.25874554,3.280456321,293259.7144,1.696077218,475.3544347
97.2,93.11820788,3.313299548,294504.2453,1.696077322,477.5063529
97.4,93.87540691,3.346480426,296251.9424,1.694334719,479.8947028
97.6,94.93586185,3.379971576,297843.9875,1.69477052,482.5946768
97.8,95.75943316,3.413817238,297780.0472,1.701741399,484.4110071
98,96.76659779,3.447988929,297663.662,1.710890668,486.6250336
98.2,97.02997781,3.482560673,297523.4794,1.719168503,488.5143507
98.4,97.48027391,3.517465369,297136.7033,1.729624729,490.6967671
98.6,98.50970969,3.552676704,297489.7897,1.733981594,492.3986987
98.8,99.40945587,3.588251788,300320.7067,1.727446598,494.9864446
99,100.0199631,3.624206168,301272.9836,1.728753695,496.8703227
99.2,100.8074123,3.660508381,302260.0289,1.730060814,498.905656
99.4,101.7959017,3.697159948,303015.7197,1.733982,501.3310596
99.6,102.4328266,3.734206651,302494.7184,1.743566905,503.2999248
99.8,102.9924108,3.771631402,300885.634,1.757072867,504.6782438
100,103.8344697,3.809410686,300459.3068,1.765786451,506.6209653
100.2,104.5750883,3.847577461,300592.1268,1.770578959,508.2400817
100.4,105.3746459,3.886122963,300998.159,1.774064452,509.9507252
100.6,105.861692,3.925079652,302434.117,1.773193167,512.0721275
100.8,106.8904774,3.964386547,304351.2488,1.76927223,513.9255107
101,107.6399895,4.004109505,307975.9395,1.758816148,516.4348057
101.2,108.3586918,4.044233996,311025.358,1.750538431,518.714202
101.4,108.9958936,4.084767718,313795.1205,1.743567726,520.9347594
101.6,110.1241423,4.125671283,316688.1412,1.737468428,523.5181564
101.8,111.2182555,4.166988472,319004.7617,1.733983169,526.1211643
102,112.0393243,4.208742057,319503.4983,1.737468664,528.0431846
102.2,112.9779105,4.250907624,320692.4499,1.737904455,530.1003153
102.4,113.6384654,4.293517269,322589.0065,1.736597515,532.8384205
102.6,114.3542128,4.336549603,323803.6522,1.73616193,534.804021
102.8,115.3358067,4.37999393,325120.485,1.736597725,537.2653838
103,116.3223171,4.423874378,326848.8494,1.735726498,539.8269877
103.2,117.1226169,4.468209887,328327.1951,1.735726598,542.1456117
103.4,118.2934651,4.512962769,329973.1427,1.734419718,544.2528705
103.6,118.8252148,4.558213772,331859.9196,1.733984111,546.8711181
103.8,119.9934265,4.60387093,333389.237,1.73354858,548.9010198
104,120.8557629,4.65001005,335431.5779,1.732677338,551.6086228
104.2,121.9374057,4.696596193,335830.5278,1.73746989,553.7540149
104.4,123.0247911,4.743650024,335578.2706,1.744876491,555.6847618
104.6,123.970834,4.791187394,335852.083,1.750540378,558.0131966
104.8,125.4436068,4.839405776,336858.0806,1.751411909,560.0267606
105,126.52,4.887653623,337303.4353,1.755768789,562.3464854
105.2,127.4633198,4.936640233,338704.3306,1.754897558,564.4363072
105.4,128.3292798,4.986125012,341235.3128,1.749233896,566.7592946
105.6,129.7760195,5.03606266,344329.0616,1.742698953,569.652142
105.8,130.5844829,5.086550809,347066.7532,1.737470957,572.4196729
106,131.4975699,5.137538107,351214.9499,1.725272176,575.0270391
106.2,132.5343923,5.189028339,355502.4935,1.713944757,577.8969952
106.4,133.9907803,5.241003931,359015.2271,1.707845485,581.2747051
106.6,134.8687194,5.293545732,361931.8679,1.703053169,583.8886085
106.8,135.786462,5.346612443,363841.3646,1.704360305,587.0211484
107,137.0107536,5.400189043,363138.1714,1.713945302,589.0924569
107.2,138.392847,5.454291946,362179.1191,1.724401669,591.1855613
107.4,139.2887274,5.5089755,360526.7915,1.738779056,593.6589142
107.6,140.3124924,5.564198805,358314.0557,1.754027809,595.8184738
107.8,141.2987749,5.619979616,358541.6378,1.757949009,597.7405033
108,142.490222,5.676305268,360113.9367,1.757949157,600.3925538
108.2,143.3084664,5.73322536,361329.7577,1.758384935,602.5488379
108.4,144.6177328,5.790679953,363573.0682,1.755335372,604.9568273
108.6,145.9011471,5.848712652,365848.5163,1.753157155,607.6611801
108.8,146.8495815,5.90735334,367163.5356,1.753592949,609.7978581
109,148.4336268,5.966535551,367836.8572,1.757949898,612.2919331
109.2,149.5048593,6.02635006,369600.1677,1.756643005,614.572438
109.4,150.603419,6.086763055,371449.0569,1.755336116,616.9717061
109.6,151.7118541,6.147782218,374137.6434,1.751415176,619.8601928
109.8,153.1151921,6.209391894,378144.4285,1.742266173,622.949173
110,154.259995,6.271640303,381757.457,1.733988472,625.5870573
110.2,155.5783748,6.334501005,384417.1668,1.730503237,628.3644179
110.4,156.790288,6.398001325,387678.1797,1.726582304,631.7246934
110.6,158.2198185,6.462123135,391274.0061,1.720047343,634.4802639
110.8,158.9753163,6.526940418,394196.3121,1.717869058,637.6923444
111,160.2060352,6.592372827,396597.6116,1.717869211,640.9610976
111.2,161.6876078,6.658443405,399792.8334,1.713948303,644.0653338
111.4,163.3892867,6.725161136,401716.1147,1.713512836,646.7391965
111.6,164.7302107,6.792576593,401463.4845,1.722226514,649.5906486
111.8,166.1715767,6.860661596,402507.1788,1.724405069,652.0574853
112,167.6477356,6.929428025,403931.2165,1.726147956,655.1148715
112.2,169.2567428,6.998875315,404585.9578,1.729633556,657.6372825
112.4,170.9728367,7.06901231,407079.8588,1.728326737,661.0575046
112.6,172.2350994,7.139888381,408843.8656,1.727891216,663.7280872
112.8,173.4482209,7.211480282,409261.3559,1.733990825,666.6939391
113,174.6969605,7.283788816,409912.848,1.737912063,669.0267545
113.2,176.2995857,7.356796849,410840.0186,1.740961993,671.5862163
113.4,177.2431209,7.430588626,412324.5037,1.743140497,674.7035145
113.6,179.2460482,7.505041062,415364.7492,1.739655327,677.9178175
113.8,180.7045596,7.580283161,418535.3826,1.73442739,680.7518426
114,181.5978789,7.656324028,421413.5452,1.731377767,684.057637
114.2,183.1193041,7.733081072,422938.0599,1.732249306,686.7685443
114.4,184.5043247,7.810619798,422846.5892,1.738784622,689.3399831
114.6,185.7388127,7.888948955,422203.7438,1.747498303,692.1641993
114.8,187.3080641,7.968039568,422192.3065,1.752290939,694.4371004
115,188.686893,8.047939259,421568.7394,1.760133288,697.1414691
115.2,190.5990893,8.12860122,422635.0813,1.761440554,699.6508213
115.4,191.8945631,8.21012055,425517.0492,1.756212596,702.4434422
115.6,193.5056828,8.292434781,429706.6222,1.748806292,705.901804
115.8,194.8499236,8.375596471,432962.6617,1.744014014,708.73692
116,196.4832161,8.459571594,439486.9337,1.730072557,712.6583518
116.2,198.0091769,8.544398602,446313.9365,1.714824054,716.4392274
116.4,199.7867923,8.630058681,453091.7289,1.702189639,720.9414049
116.6,201.3498758,8.716595738,457454.0088,1.694783319,724.2820954
116.8,202.6302848,8.804023713,463596.7398,1.683891548,728.6905565
117,204.1831189,8.892309372,468124.813,1.677356577,732.370103
117.2,205.6161497,8.981491079,470969.6444,1.678663779,736.9006026
117.4,207.7013652,9.071519409,473192.7572,1.679535379,740.2543885
117.6,209.1731666,9.162498855,476038.1559,1.678664199,743.7857508
117.8,210.9082468,9.25437231,478360.9551,1.680842791,748.0536765
118,212.7437302,9.347161067,478664.9233,1.688249522,751.824761
118.2,214.2641204,9.440906142,477929.8991,1.697398928,754.9420904
118.4,215.9497281,9.535580422,477539.687,1.704805645,758.0409021
118.6,217.5994523,9.631208757,475516.8264,1.718747522,761.4328096
118.8,219.4534475,9.727782317,473151.2537,1.732689427,763.8539136
119,221.1801473,9.825335806,472288.195,1.743145899,766.9440128
119.2,223.0795375,9.923856307,473663.6389,1.74532452,769.791145
119.4,224.49181,10.02340361,476395.8272,1.743581984,772.8845024
119.6,226.036466,10.12394524,479828.419,1.740532431,776.5586072
119.8,227.8393998,10.225478,484207.2092,1.732690452,779.8742539
120,230.1361966,10.32798836,490111.5935,1.721798786,784.2141198
120.2,231.875235,10.43157129,495871.5434,1.71090705,788.0767297
120.4,233.2758947,10.53622045,501887.1845,1.702193661,792.9864118
120.6,235.2348136,10.64187857,505754.6874,1.697837116,796.6082371
120.8,237.0198868,10.74861135,511574.6023,1.690866481,801.40571
121,238.9826221,10.85640307,513935.2941,1.691738071,804.7812921
121.2,240.6411493,10.86007346,513324.2568,1.701323186,808.0751459
121.4,241.8548687,10.85998005,510877.3773,1.717007746,811.8636487
121.6,242.4860629,10.85993076,508615.5446,1.729642491,814.462312
121.8,243.3233432,10.85986586,503514.4311,1.751426506,817.098031
122,244.2304268,10.85979567,500016.0705,1.767982392,819.6988866
122.2,244.6896059,10.85975941,499599.4955,1.774517624,822.1885863
122.4,245.5094354,10.85969583,500416.5787,1.777567475,824.9278152
122.6,245.9719385,10.85965932,504096.3888,1.773210751,828.5070891
122.8,246.6795842,10.85960424,508181.0605,1.766675665,831.5873506
123,247.0872418,10.85957188,512024.6727,1.762318934,835.3485842
123.2,247.3154051,10.85955312,514503.4274,1.761011929,838.5040066
123.4,247.8743033,10.85950931,515890.8531,1.763190391,841.5167103
123.6,248.6941331,10.85944573,516864.8069,1.767547278,844.9630717
123.8,248.3971094,10.85946676,516878.0757,1.77408242,848.0334866
124,248.7939641,10.85943522,516990.1855,1.778874933,850.4120504
124.2,249.0304374,10.85941583,516364.4778,1.786281498,852.884309
124.4,249.3043053,10.85939361,515869.9143,1.794123745,855.9503863
124.6,249.5432716,10.85937403,513962.9348,1.804144381,857.8887542
124.8,249.9891549,10.85933878,512374.5536,1.814165044,860.3130809
125,250.2339381,10.85931876,510094.6958,1.825057038,862.020458
125.2,250.5967222,10.8592898,507703.1664,1.836384726,863.6918842
125.4,250.5730949,10.85929012,505352.0499,1.848583723,865.7304802
125.6,250.7538918,10.85927495,504168.3549,1.855990282,867.2308352
125.8,250.9230547,10.85926066,503003.0763,1.863832519,868.9491055
126,251.1861198,10.85923925,503960.9679,1.864268234,870.620529
126.2,250.9397865,10.85925644,507574.0638,1.856861671,872.8476118
126.4,251.3233455,10.85922591,512686.2882,1.84596976,875.8777413
126.6,251.5880725,10.85920438,518177.6799,1.834206477,879.0244485
126.8,251.4065567,10.85921666,523268.5314,1.823314494,881.7549216
127,251.8432992,10.8591821,527733.0558,1.815472338,884.9659211
127.2,251.7905872,10.85918461,527370.7577,1.821136155,887.210448
127.4,252.0918779,10.85916032,526334.8197,1.82854273,889.1542658
127.6,252.241928,10.85914747,525458.1128,1.835949294,891.3693865
127.8,252.1792441,10.85915075,522527.0982,1.849019645,893.1192444
128,252.5661271,10.85911997,520492.9035,1.85860462,894.4452723
128.2,252.4627245,10.85912632,520821.0358,1.861654364,896.1962222
128.4,252.4066885,10.85912909,521942.9113,1.862961394,898.448375
128.6,252.9439811,10.85908692,519799.8015,1.873417748,899.9008047
128.8,252.8763112,10.85909057,518332.6432,1.880824275,901.0677389
129,252.9166703,10.85908604,516416.7722,1.889537856,902.399204
129.2,252.900522,10.85908578,513251.278,1.901301179,903.2501633
129.4,253.0322903,10.85907433,510025.7581,1.913064518,903.8646911
129.6,253.2496508,10.85905639,510647.4244,1.913500227,905.2321199
129.8,253.4587014,10.85903907,512207.924,1.911321865,906.5200093
130,253.2439459,10.85905387,512537.57,1.913935916,907.7915365
130.2,253.7031252,10.85901761,513079.0051,1.915243004,908.8822236
130.4,253.7177236,10.85901503,515799.235,1.910450552,910.5917707
130.6,253.7181951,10.85901352,516638.5076,1.910450553,911.7837682
130.8,253.8524564,10.85900187,518580.0546,1.906965138,913.412688
131,254.165381,10.85897669,522374.5084,1.897815932,915.182173
131.7,254.2581707,10.77701697,1.7977E+308,1.895201879,0
131.9,253.9102587,10.66850208,1.7977E+308,1.840306333,0
132.1,253.6620657,10.55997963,1.7977E+308,1.713088158,0
132.3,253.3540414,10.45146171,1.7977E+308,1.523132267,0
132.5,253.3867239,10.34291798,1.7977E+308,1.263032166,0
132.7,252.9482337,10.23440995,1.7977E+308,0.910132499,0
132.9,252.7199846,10.12588599,1.7977E+308,0.568996182,0
133.1,252.658765,10.01734938,1.7977E+308,0.331115694,0
133.3,252.4263609,9.908825736,1.7977E+308,0.154230203,0
133.5,252.3177747,9.800292712,1.7977E+308,0.050103032,0
133.7,251.8676507,9.69178556,1.7977E+308,0.027883425,0
133.9,251.594528,9.583265,1.7977E+308,0.027447746,0
134.1,251.5216745,9.474729269,1.7977E+308,0.02352664,0
134.3,251.3682147,9.366199644,1.7977E+308,0.016991462,0
134.5,251.2521496,9.257667187,1.7977E+308,0.012634677,0
134.7,251.0164216,9.149143794,1.7977E+308,0.010020605,0
134.9,250.7275101,9.04062443,1.7977E+308,0.008277891,0
135.1,250.3912321,8.932108654,1.7977E+308,0.010456283,0
135.3,250.2859699,8.823575378,1.7977E+308,0.007842213,0
135.5,250.2903987,8.715033793,1.7977E+308,0.007842213,0
135.7,249.9532896,8.60651808,1.7977E+308,0.013506032,0
135.9,249.678505,8.497997646,1.7977E+308,0.016120103,0
136.1,249.4810027,8.389471357,1.7977E+308,0.019169852,0
136.3,249.321726,8.280942173,1.7977E+308,0.023962315,0
136.5,248.870771,8.172435084,1.7977E+308,0.021348243,0
136.7,248.7704948,8.063901431,1.7977E+308,0.014377388,0
136.9,248.7740926,7.955359908,1.7977E+308,0.016120102,0
137.1,248.2653837,7.846857195,1.7977E+308,0.020259046,0
137.3,248.3317214,7.73831092,1.7977E+308,0.022655278,0
137.5,247.8026532,7.629809748,1.7977E+308,0.027012061,0
137.7,247.7638704,7.521271436,1.7977E+308,0.031368845,0
137.9,247.3901977,7.412758493,1.7977E+308,0.027447738,0
138.1,247.0879904,7.304240136,1.7977E+308,0.023962311,0
138.3,246.7226277,7.195726564,1.7977E+308,0.020912562,0
138.5,246.9256636,7.087169933,1.7977E+308,0.012198994,0
138.7,246.7746969,6.97864012,1.7977E+308,0.002178392,0
138.9,246.4409119,6.870124155,1.7977E+308,0.001307035,0
139.1,246.093831,6.761609198,1.7977E+308,0.007406532,0
139.3,246.0351044,6.653072396,1.7977E+308,0.012634672,0
139.5,245.6124033,6.544563167,1.7977E+308,0.016120098,0
139.7,245.4190559,6.436036564,1.7977E+308,0.016120098,0
139.9,245.3860901,6.327497812,1.7977E+308,0.013941707,0
140.1,245.2293927,6.218425733,1.7977E+308,0.012634671,0
140.3,244.7850858,6.109918141,1.7977E+308,0.013506028,0
140.5,244.612427,6.001932669,1.7977E+308,0.014813062,0
140.7,244.4947,5.893400338,1.7977E+308,0.01786281,0
140.9,244.0969286,5.78488922,1.7977E+308,0.018734166,0
141.1,243.9243561,5.676361043,1.7977E+308,0.013506027,0
141.3,243.7010931,5.567836706,1.7977E+308,0.017862809,0
141.5,243.495281,5.459311047,1.7977E+308,0.023090948,0
141.7,242.9961286,5.350807609,1.7977E+308,0.021783913,0
141.9,242.9988955,5.24226615,1.7977E+308,0.016991452,0
142.1,242.926873,5.133730356,1.7977E+308,0.013070348,0
142.3,242.3745372,5.025230947,1.7977E+308,0.004792461,0
142.5,242.274261,4.916697294,1.7977E+308,0.004356782,0
142.7,241.7900666,4.808192723,1.7977E+308,0.010020599,0
142.9,241.7421429,4.699655103,1.7977E+308,0.015248738,0
143.1,241.4648655,4.591134858,1.7977E+308,0.022655267,0
143.3,241.2324616,4.482611213,1.7977E+308,0.029626118,0
143.5,241.0233255,4.374085806,1.7977E+308,0.032240187,0
143.7,240.5274972,4.265582117,1.7977E+308,0.031804507,0
143.9,240.4820665,4.157044308,1.7977E+308,0.033982898,0
144.1,240.1499436,4.048528218,1.7977E+308,0.035289932,0
144.3,240.0255687,3.93999639,1.7977E+308,0.024833656,0
144.5,239.5513462,3.831491063,1.7977E+308,0.020041195,0
144.7,239.2283643,3.72297428,1.7977E+308,0.022655264,0
144.9,239.3250331,3.614425708,1.7977E+308,0.026140689,0
145.1,238.722007,3.505930139,1.7977E+308,0.0278834,0
145.3,238.508716,3.397405046,1.7977E+308,0.03703264,0
145.5,238.1865651,3.2888882,1.7977E+308,0.040953743,0
145.7,237.979922,3.180362604,1.7977E+308,0.037032639,0
145.9,237.5140095,3.071856648,1.7977E+308,0.032240179,0
146.1,237.2250983,2.963337284,1.7977E+308,0.029190432,0
146.3,237.235344,2.854795259,1.7977E+308,0.027012041,0
146.5,236.6697126,2.746296857,1.7977E+308,0.018734157,0
146.7,236.5262248,2.637766477,1.7977E+308,0.011763308,0
146.9,236.1575384,2.529253156,1.7977E+308,0.020476868,0
147.1,235.987459,2.42072479,1.7977E+308,0.026576361,0
147.3,235.674449,2.312207251,1.7977E+308,0.033111531,0
147.5,235.2068747,2.203701422,1.7977E+308,0.036596954,0
147.7,235.0426122,2.095172615,1.7977E+308,0.031368817,0
147.9,234.9556319,1.986637954,1.7977E+308,0.022655257,0
148.1,234.5279451,1.878129103,1.7977E+308,0.01960551,0
148.3,234.3104992,1.769604325,1.7977E+308,0.018734154,0
148.5,233.8204881,1.661100195,1.7977E+308,0.021783899,0
148.7,233.4019423,1.552590651,1.7977E+308,0.02788339,0
148.9,233.0498758,1.444076071,1.7977E+308,0.030497457,0
149.1,232.6978093,1.335561492,1.7977E+308,0.037903982,0
149.3,232.0823185,1.227066867,1.7977E+308,0.044874827,0
149.5,232.120818,1.118522701,1.7977E+308,0.049667284,0
224.7,231.3595846,1.015455649,1.7977E+308,0.037032641,0
224.9,230.7956151,0.906957122,1.7977E+308,0.031804502,0
225.1,230.588972,0.798431526,1.7977E+308,0.026576364,0
225.3,230.2319195,0.689917324,1.7977E+308,0.022219583,0
225.5,229.8624021,0.581404066,1.7977E+308,0.022219582,0
225.7,229.3482921,0.472901761,1.7977E+308,0.020041191,0
225.9,228.5317013,0.36442237,1.7977E+308,0.017427122,0
226.1,227.6768848,0.255945875,1.7977E+308,0.021783901,0
226.3,226.2029799,0.147516277,1.7977E+308,0.029190424,0
226.5,224.7124553,0.039087938,1.7977E+308,0.030933133,0
226.564,224.1940376,0.00439401,1.7977E+308,0.03136881,0
,,,,,