File: Test_18.csv
Time On Sample,Displacement Into Surface,Load On Sample,Harmonic Contact Stiffness,Harmonic Displacement,Harmonic Load
0,0,0,-199.8210216,0.33897179,2.221707798
0.2,0.25253769,0.000738874,5084.969221,0.217412502,2.296890679
0.4,0.132359993,0.001505929,12341.52458,0.17514995,2.364446276
0.6,0.419385286,0.002242196,16024.66806,0.155543615,2.429822701
0.8,0.649069754,0.002982799,17865.87037,0.149443868,2.55948592
1,0.461578905,0.003754943,18847.39222,0.150750956,2.724016496
1.2,0.610238287,0.004501672,19490.4277,0.154236528,2.887457504
1.4,0.884798193,0.005238881,19485.12982,0.162514763,3.04871932
1.6,0.589689404,0.006019162,18777.43538,0.177764134,3.209981058
1.8,0.646520355,0.006772834,19158.68143,0.18691376,3.45296334
1.99,0.552109195,0.007500043,20348.14458,0.193013508,3.80054783
2.2,0.684974764,0.008283298,22132.94934,0.192577814,4.153580401
2.4,0.938343894,0.009019595,24314.71743,0.188220853,4.518598672
2.6,0.71262622,0.009792114,27421.78538,0.177764136,4.890154488
2.8,0.951452085,0.0105314,31028.07861,0.171882238,5.385380749
3,1.140832476,0.011270644,34174.85582,0.170357303,5.896951118
3.2,0.935890462,0.012041592,37694.32268,0.1703573,6.477711392
3.4,0.546460559,0.01282649,40088.78725,0.176021349,7.035589853
3.6,0.788610829,0.013563635,40095.93319,0.191706423,7.56622837
3.8,1.092672582,0.014296098,39858.71791,0.210005677,8.198200327
4,0.943409348,0.015062837,39745.92912,0.232226193,9.016494857
4.2,0.886390062,0.015822601,39225.57401,0.256625191,9.818445304
4.4,0.993498522,0.016569955,38810.3151,0.280588497,10.61058937
4.6,1.225260968,0.017307885,39180.7719,0.298452055,11.40273353
4.8,1.236801374,0.018062465,40340.04319,0.312394341,12.30928627
5,1.252496312,0.01882051,41936.97455,0.326772324,13.39671373
5.2,1.170961742,0.019582127,42086.9076,0.350299929,14.42530234
5.4,1.349539091,0.020320297,42476.19122,0.371649059,15.46805605
5.6,1.324514328,0.021077641,42179.07869,0.397355148,16.43453711
5.8,1.102536265,0.021849877,41904.03654,0.424804018,17.43915428
6,1.025156828,0.02261118,41223.27929,0.460531123,18.59958532
6.2,1.197916389,0.02335357,40995.34213,0.490594182,19.72079075
6.4,1.194498316,0.02410928,39980.64653,0.530242557,20.78751566
6.6,1.242603892,0.024861095,38675.86559,0.575990685,21.82917965
6.8,1.318133345,0.025610837,37065.62877,0.627838564,22.79239199
7,1.089507069,0.026383576,35663.43173,0.676636555,23.63029929
7.2,0.863373876,0.027156126,33507.90292,0.749833544,24.5684503
7.4,1.121729173,0.027892044,31225.22751,0.833051576,25.40091017
7.6,1.277037178,0.028635754,29095.86415,0.921497962,26.16145578
7.8,1.168078729,0.029399444,27612.14733,0.995130652,26.82502606
8,1.205380959,0.030152076,26458.08773,1.058742335,27.35566458
8.2,1.317475583,0.030899053,25292.16603,1.131067952,27.96802367
8.4,1.611565033,0.031632268,24436.67219,1.193372568,28.58801031
8.6,1.451913959,0.032399791,23862.5559,1.239120682,29.06961629
8.8,1.795865009,0.033129236,23369.21538,1.283126053,29.56211899
9,1.492446331,0.033907628,23004.82595,1.323645797,30.1167284
9.2,1.378501721,0.034671695,22803.87233,1.351094663,30.53513718
9.4,1.386718021,0.035426525,22704.69585,1.378979237,31.05705881
9.6,2.220143756,0.036118961,22643.70239,1.401199836,31.46566252
9.8,1.913400962,0.036897604,22613.04729,1.423420326,31.8873399
10,2.0038889,0.037646213,22636.97058,1.443462372,32.35042285
10.2,1.771938506,0.038419201,22759.42253,1.453919065,32.73723288
10.4,1.866581575,0.039167495,22970.80572,1.4635044,33.20903277
10.6,2.50305402,0.039874822,23383.27375,1.463068764,33.71025287
10.8,2.232045365,0.040650762,23889.98777,1.455661899,34.17769372
11,2.478766317,0.041387557,24384.44405,1.447819386,34.60590964
11.2,2.269253635,0.042158847,25271.54096,1.423856062,35.18558004
11.4,2.378855188,0.042906009,26144.14214,1.397278589,35.68788892
11.6,2.333885784,0.043664859,27349.77204,1.361115778,36.34492171
11.8,2.413570378,0.044414283,28535.78837,1.327131459,36.96926651
12,2.297963708,0.045178473,29766.02649,1.296632694,37.66116659
12.2,2.683466116,0.045904774,30513.74133,1.283126139,38.19071618
12.4,2.53129427,0.046671729,31136.17169,1.27964056,38.82704625
12.6,2.488817945,0.047430389,31609.75432,1.281383341,39.44703241
12.8,2.406452341,0.048192066,31930.5898,1.287483085,40.02016541
13,2.547632909,0.04893684,32234.0606,1.290968671,40.51157833
13.2,2.584104118,0.049689532,32518.97553,1.297504122,41.09233887
13.4,2.39786018,0.050459062,32759.26731,1.304910947,41.67963648
13.6,2.727683805,0.051189573,32909.67322,1.316239084,42.27565205
13.8,2.776620414,0.051941322,32977.41193,1.329309985,42.81282823
14,2.372647486,0.052727315,32983.98382,1.342380844,43.25847664
14.2,2.711612404,0.053457135,32899.77071,1.36285861,43.80763919
14.4,2.868582484,0.054200715,32804.07946,1.383772057,44.32084436
14.6,2.678183408,0.054970559,32700.0658,1.400764203,44.71201281
14.8,2.925735397,0.05570729,32557.65792,1.420806266,45.1511248
15,3.022456043,0.056455424,32452.37937,1.440848316,45.64144815
15.2,2.88358062,0.057221372,32475.44971,1.453265653,46.08110415
15.4,2.80453912,0.057982796,32633.13116,1.459583245,46.53274598
15.6,3.149321237,0.058712175,32900.26484,1.462633156,47.03941387
15.8,2.815154539,0.059492889,33208.38827,1.46306882,47.51012328
16,3.078080525,0.060228457,33468.74819,1.464811633,47.94596671
16.2,3.307349935,0.06096657,33652.21584,1.472218497,48.4308422
16.4,3.005593274,0.061744832,33715.93671,1.484417969,48.88956606
16.6,3.189156213,0.062486401,33844.7562,1.494003312,49.3580973
16.8,3.431306539,0.063223539,33915.2722,1.504460054,49.78740301
17,3.577057767,0.063967965,34078.81804,1.508817035,50.16549688
17.2,3.525024632,0.064727346,34586.8902,1.501845886,50.68523923
17.4,3.732687354,0.06546709,35192.13183,1.488775013,51.14396421
17.6,3.702260915,0.066224837,36037.07304,1.47004006,51.73453103
17.8,4.049951649,0.066953994,37100.67116,1.443898304,52.32836758
18,3.889054008,0.067721605,38379.01621,1.413399532,53.00174431
18.2,3.529956488,0.068504201,39459.80294,1.391614672,53.68492683
18.4,3.408948135,0.069268797,40343.66953,1.37810807,54.37028922
18.6,3.613286749,0.070008793,40815.9954,1.374622518,54.89330107
18.8,3.503081742,0.070772572,40994.40948,1.382465045,55.47841968
19,3.649663999,0.071516935,40759.33339,1.40381419,56.05591168
19.2,3.797908311,0.072261172,40622.39241,1.422984852,56.63449333
19.4,3.918313228,0.073007514,40570.19836,1.435184367,57.06488837
19.6,3.75658456,0.073775188,40284.74885,1.457840571,57.56501738
19.8,3.609398861,0.074541762,40089.43254,1.477011204,58.04117528
20,3.943793168,0.075271924,40209.55169,1.487467956,58.60123421
20.2,4.071261814,0.076017731,40205.32352,1.498796079,59.02727076
20.4,4.149699882,0.076767245,40197.61842,1.512738378,59.5186837
20.6,4.218581142,0.077517482,40760.79736,1.507510027,60.09617558
20.8,4.146603362,0.078278369,41439.32118,1.497489,60.66277086
21,4.314792323,0.079021096,41869.0823,1.494439142,61.15636334
21.2,4.17134624,0.079787387,42597.66386,1.483982412,61.7839765
21.4,4.115157969,0.080547079,43282.91421,1.475268476,62.43229244
21.6,4.105922712,0.081303222,43525.94179,1.477882655,62.90845071
21.8,4.213862231,0.082050506,43618.59917,1.489646474,63.55240877
22,4.276926125,0.082802307,43612.55466,1.502281681,64.08631611
22.2,4.117273749,0.083577814,43430.81084,1.518402437,64.50472478
22.4,4.254296713,0.084338584,43294.16155,1.535394617,65.00812359
22.6,4.417080303,0.085104988,43266.56281,1.548465532,65.51152245
22.8,4.053822031,0.085923142,43415.04255,1.554565246,65.99421719
23,4.439318893,0.086684707,43627.34598,1.557179467,66.42570262
23.2,4.300435963,0.087497784,43997.77164,1.556743756,66.97486412
23.4,4.465707571,0.08829586,44389.80556,1.555436685,67.54146026
23.6,4.512972092,0.089110919,44608.31077,1.557615174,67.98710967
23.8,4.454694901,0.089942181,44759.06153,1.562843527,68.46326777
24,4.496139601,0.09077425,44665.51227,1.576785822,68.95903889
24.2,4.643123388,0.091606632,44647.23471,1.588549646,69.44936259
24.4,4.75686476,0.092449982,44374.18598,1.608591701,69.86886164
24.6,4.575590249,0.093324203,44131.12862,1.625583848,70.19792237
24.8,4.686004783,0.09418498,44022.30268,1.638654758,70.57710587
25,4.57370274,0.095071339,44319.45295,1.639526139,71.0652493
25.2,4.596856661,0.095956304,44586.43261,1.640833232,71.53813892
25.4,4.469593312,0.096861558,45047.72698,1.633426378,71.95545801
25.6,4.725431901,0.097746809,45864.75639,1.616434241,72.53512976
25.8,4.723650731,0.098660635,46637.60511,1.601184862,73.0733954
26,4.965358989,0.099565064,47163.87391,1.595085138,73.65088804
26.2,5.404850196,0.100463656,47593.32994,1.591599614,74.20876859
26.4,5.41802317,0.101403648,47848.37851,1.591599616,74.64896946
26.6,5.481887286,0.102349226,48316.35317,1.587678355,75.21338634
26.8,5.466802358,0.103310156,48813.79903,1.582014299,75.74947293
27,5.466674374,0.104279644,49868.62442,1.562407953,76.44464224
27.2,5.459065607,0.105259392,51217.63304,1.536266158,77.1899333
27.4,5.537051048,0.106242485,52609.94885,1.509252979,77.86766901
27.6,5.777916202,0.10722305,53898.23182,1.488775265,78.65654554
27.8,5.620717876,0.108243801,54990.60934,1.473961565,79.42253861
28,5.787618409,0.109250276,55780.70573,1.468297527,80.22666915
28.2,5.829863311,0.110276237,56265.60016,1.467861834,80.86191034
28.4,5.803131324,0.111317831,56397.72781,1.477882856,81.58322988
28.6,6.169473437,0.112339932,56910.06005,1.477882895,82.32852256
28.8,6.214206491,0.113396718,57594.77617,1.473525936,83.09124764
29,6.263924018,0.114463752,58200.18229,1.471347453,83.87576489
29.2,6.227213021,0.115548165,58853.85614,1.465683396,84.56984441
29.4,6.184683103,0.116643919,59779.81691,1.456098067,85.45024669
29.6,6.443814239,0.117727685,60357.00554,1.454355306,86.2783491
29.8,6.430366801,0.118843016,60607.99652,1.460019363,87.05523885
30,6.385338559,0.119971945,60919.41875,1.463504932,87.74604952
30.2,6.525627528,0.121098151,61069.79058,1.473961666,88.54800089
30.4,6.606911769,0.122240245,61190.37775,1.485725482,89.32598066
30.6,6.738055794,0.12339011,61343.652,1.494003735,89.93289277
30.8,6.686372058,0.124565317,61556.81533,1.502281966,90.64222629
31,6.495073931,0.125762816,61659.52832,1.513174363,91.39514394
31.2,6.627874425,0.126947686,61930.13515,1.519709827,92.17857213
31.4,6.459841237,0.128167427,62085.551,1.527988046,92.94020675
31.6,6.794577425,0.129361277,62098.16316,1.536266318,93.51987903
31.8,6.594961354,0.130607677,62201.54109,1.544108837,94.21504749
32,6.721105881,0.131841813,62361.73525,1.551951391,94.96796662
32.2,6.753342397,0.133095424,62211.53231,1.56676508,95.65659839
32.4,6.974220032,0.13434736,62171.45798,1.576350431,96.17961073
32.6,7.099943069,0.135619151,62353.86357,1.583757288,96.87913909
32.8,6.7523942,0.136939614,62469.4526,1.591599791,97.50457192
33,6.977420831,0.138229858,62713.52711,1.597263873,98.20954868
33.2,7.253553545,0.13952933,63128.47736,1.598570994,98.91888426
33.4,7.084669233,0.140875518,63604.37849,1.596392493,99.51489853
33.6,7.118137858,0.14221983,64208.34969,1.593342621,100.2732652
33.8,6.895647995,0.143597205,64852.62212,1.588549935,100.9924047
34,6.951134489,0.144967187,65670.05089,1.581143099,101.8041621
34.2,7.177810363,0.146337927,66540.3732,1.572429191,102.57615
34.4,7.485093669,0.147716359,67125.37401,1.569815045,103.3176291
34.6,7.549299353,0.149127177,67465.05231,1.573736323,104.0977882
34.8,7.599790839,0.150553207,67700.17081,1.578964689,104.7994954
35,7.572994538,0.151999387,67676.31759,1.5902928,105.5317112
35.2,7.661708687,0.153451336,67478.02383,1.603799407,106.1315405
35.4,7.977290898,0.15490071,67664.91116,1.609027803,106.7705966
35.6,7.667938455,0.156412,68083.13991,1.61033486,107.5049902
35.8,7.660246431,0.157915529,68321.74768,1.615127523,108.1838157
36,8.091334292,0.159400885,68699.78904,1.617741752,108.9160336
36.2,8.022141474,0.160939218,69092.38368,1.618177442,109.5534535
36.4,7.925937821,0.162495043,69162.25241,1.626891365,110.2508016
36.6,8.276408725,0.164032683,69025.08388,1.637783822,110.7727252
36.8,7.948759073,0.165637248,69312.00837,1.640397967,111.4352046
37,7.968891701,0.167231487,69921.40666,1.636912397,112.2393349
37.2,7.886805467,0.168849408,70312.62405,1.636040995,112.8538728
37.4,8.26095051,0.170448998,71153.3603,1.628634194,113.6972305
37.6,8.314732048,0.172089049,71834.5999,1.622534448,114.368429
37.8,8.32155795,0.173749051,72146.03848,1.626020023,115.0744945
38,8.303865884,0.175427699,72001.66132,1.640398012,115.7783807
38.2,8.432016409,0.177112046,71567.86007,1.659568682,116.3765757
38.4,8.539804088,0.178814818,71223.48446,1.674382382,116.8560035
38.6,8.841633879,0.180519989,71063.72562,1.684839139,117.3441492
38.8,8.929886978,0.1822585,71042.73453,1.692681691,117.9042077
39,9.010242553,0.18401502,71566.63702,1.689196127,118.6102738
39.2,9.075221297,0.185790503,72790.91858,1.671768267,119.4470924
39.4,8.886318411,0.18760312,73768.62058,1.659133042,120.1477088
39.6,9.253369801,0.189391672,75024.83361,1.6438837,121.032472
39.8,9.141746675,0.191234667,76284.23717,1.628634304,121.8921714
40,9.360038398,0.193071068,77063.9033,1.622534575,122.6331058
40.2,9.89079342,0.194902157,77569.64847,1.621663241,123.3369949
40.4,10.10076752,0.196785479,78140.85215,1.621663265,124.2097718
40.6,10.1453657,0.19869087,78667.59456,1.621663271,125.0455009
40.8,10.24148607,0.200601788,79390.7337,1.617742012,125.8725131
41,10.31433307,0.202543429,80308.53728,1.609463783,126.6744646
41.2,10.54590317,0.204492553,81366.11016,1.600749874,127.6638295
41.4,10.74838421,0.206463467,82115.03327,1.595521536,128.428735
41.6,10.75972582,0.208468755,82825.66401,1.593778751,129.3864999
41.8,10.79017787,0.210492717,82839.43411,1.602928388,130.1579424
42,10.7026208,0.212545981,82844.29355,1.611642314,130.8607382
42.2,10.81783112,0.214604451,83138.45977,1.617306386,131.7662026
42.4,10.93968637,0.216683038,83268.82787,1.625148942,132.5932153
42.6,11.02746617,0.218785225,83385.44021,1.630813011,133.2600556
42.8,10.95236129,0.220920753,83914.94635,1.62994161,134.0696333
43,11.13404043,0.223058196,84261.20016,1.633427205,134.9783671
43.2,11.25338908,0.225222062,84164.66492,1.642576852,135.6375803
43.4,11.37356532,0.227407483,84305.50837,1.649112318,136.4820268
43.6,11.42725588,0.229620011,84569.7864,1.652162203,137.1684799
43.8,11.68371356,0.231839373,84858.63779,1.656083504,137.9072347
44,11.50055428,0.234114285,85244.83761,1.660004755,138.768024
44.2,11.48110374,0.23639958,85770.36849,1.65913336,139.4675518
44.4,11.63367221,0.238694781,86523.77892,1.656519198,140.3860914
44.6,11.70147222,0.241019528,87042.15257,1.655647813,141.1139498
44.8,11.80084756,0.243365225,87719.49718,1.652597947,141.9355144
45,11.93429127,0.245731936,88369.34757,1.651290873,142.8823841
45.2,12.34363228,0.248101437,88777.42528,1.652162314,143.62332
45.4,12.32166632,0.250527511,89093.48873,1.656083584,144.4743035
45.6,12.15759082,0.252988676,89669.42474,1.653905082,145.2141456
45.8,12.32093616,0.255449699,90165.39533,1.654340799,146.0466069
46,12.41364024,0.257940862,90748.20566,1.654340806,146.9553401
46.2,12.1980292,0.26048044,91280.90323,1.653469393,147.7289598
46.4,12.44862043,0.263010254,91830.37312,1.653905115,148.6812785
46.6,12.61028772,0.265572089,91844.00067,1.662619069,149.4832307
46.8,12.82762974,0.268155536,91681.46437,1.67351152,150.2100004
47,12.98264059,0.270769612,91609.03091,1.681789781,150.8615868
47.2,13.19581917,0.273405617,91845.59136,1.68658247,151.6875108
47.4,13.52118225,0.276059573,92193.68516,1.687889601,152.3641595
47.6,14.13490764,0.278718139,92779.5227,1.686582579,153.2423876
47.8,14.42369706,0.281428184,93677.83478,1.679611462,154.0977317
48,14.46649801,0.284184184,94722.65055,1.671768926,155.0947229
48.2,14.56580445,0.286963481,95269.37314,1.67046185,155.8727034
48.4,14.742392,0.289764836,95892.3976,1.669590476,156.8184839
48.6,14.73365594,0.292608497,96747.52479,1.663490718,157.6084495
48.8,15.01161983,0.295458918,98022.45532,1.653034025,158.626145
49,14.93888556,0.298364643,99516.54279,1.640398809,159.7560676
49.2,15.19190942,0.301274863,100950.2163,1.627763628,160.7541497
49.4,15.05019059,0.304244154,102480.6219,1.615999797,161.9494482
49.6,15.38796989,0.307206898,103480.1701,1.61251426,163.109883
49.8,15.60316789,0.310208827,103676.741,1.618178345,163.977757
50,15.34509093,0.313276714,103520.3252,1.629506437,164.8794053
50.2,15.4347941,0.31634901,102709.0393,1.6504199,165.7216726
50.4,15.5643817,0.31944909,102155.5979,1.665669307,166.3808861
50.6,15.6748507,0.322581784,101774.9332,1.679611622,167.2209744
50.8,15.72091007,0.325750861,101676.6471,1.688761264,168.0044027
51,15.73912494,0.328953977,101856.1222,1.693118236,168.7409778
51.2,15.85705801,0.332181667,102603.6025,1.690939766,169.7183567
51.4,15.70365542,0.335462405,103197.4265,1.689196962,170.5028728
51.6,15.97407167,0.3387438,103875.1358,1.6883256,171.4791635
51.8,15.79572777,0.342092358,104244.8242,1.691375459,172.3541171
52,15.75034295,0.345464363,104213.489,1.70052509,173.1963832
52.2,16.12669923,0.348838282,104126.2554,1.70836768,173.8555991
52.4,15.96745286,0.352286751,104297.6821,1.714031723,174.7283733
52.6,16.14684471,0.355744165,104351.9285,1.719260108,175.3864977
52.8,16.17997018,0.35924743,104729.0882,1.720131507,176.1906288
53,16.33151149,0.36277692,105790.9386,1.711417587,177.2072338
53.2,16.38498592,0.366349293,106518.1414,1.706624928,178.0320673
53.4,16.37862065,0.3699621,106778.9519,1.710110503,178.9375314
53.6,16.81851142,0.373577375,106991.4259,1.713160435,179.6664823
53.8,16.78097106,0.377265287,106933.8725,1.721438673,180.3965191
54,16.9569989,0.380974002,106234.8948,1.740173664,181.0753464
54.2,17.0449319,0.384726695,105821.6151,1.752808888,181.598359
54.4,17.32607282,0.388502439,105861.3042,1.759780074,182.3251296
54.6,17.69446566,0.392309305,106067.5783,1.763701392,183.0671558
54.8,17.70592602,0.396181629,106824.5352,1.758037334,183.8560319
55,17.71197851,0.400093255,107832.8251,1.748016305,184.6307433
55.2,17.98893978,0.404023624,108786.3167,1.740173793,185.5830625
55.4,17.97669715,0.408015417,109032.2014,1.741916581,186.2738739
55.6,17.89297975,0.412052776,109117.7232,1.747580633,187.0867206
55.8,17.92019813,0.416122121,109051.5338,1.754987486,187.702894
56,18.20544408,0.420212917,108871.4716,1.764572856,188.3473995
56.2,18.33320376,0.424356766,109212.7349,1.766533509,189.0425703
56.4,18.4576327,0.428542506,109877.921,1.763701494,189.7954906
56.6,18.37388253,0.43278601,110861.7789,1.75716603,190.6900577
56.8,19.17683219,0.437004783,111852.4811,1.749759278,191.5323316
57,19.4811585,0.441303686,112618.0615,1.745402345,192.3005084
57.2,19.58353819,0.445661169,113097.903,1.746273752,193.1732853
57.4,19.9127815,0.450045216,113594.8588,1.745402399,193.9033255
57.6,19.98439921,0.454492798,114177.6442,1.744966711,194.8131488
57.8,20.11501279,0.458980625,114432.6917,1.748452304,195.5813238
58,20.31293247,0.463508322,114898.8541,1.748452329,196.3080936
58.2,20.29477766,0.468098102,115907.3562,1.742788266,197.2941887
58.4,20.58907826,0.472733671,116656.7588,1.738867028,198.0721717
58.6,20.5517988,0.477394157,117450.6943,1.735817146,199.0571765
58.8,20.95910805,0.482091284,118370.9828,1.730153133,199.9986025
59,21.18773881,0.486849206,119122.931,1.72579619,200.8539465
59.2,21.07647157,0.491680772,119975.2286,1.721439207,201.9282989
59.4,21.10730238,0.496550035,120728.2632,1.717082241,202.7858204
59.6,21.48798816,0.501441654,121779.8127,1.710982527,203.8678048
59.8,21.18306811,0.506434533,122639.3934,1.707932613,204.8745998
60,21.6559822,0.511418496,123165.1022,1.708368366,205.7255886
60.2,21.49315198,0.516500833,123472.5393,1.713596714,206.7073236
60.4,21.63945604,0.52161065,123177.5511,1.725796251,207.5637568
60.6,21.76497623,0.526773492,123253.306,1.731460329,208.3101391
60.8,21.80239922,0.53199488,123618.4997,1.73363882,209.1665717
61,21.93787515,0.537261322,124206.1189,1.734074534,210.1701017
61.2,21.94785746,0.542590233,124800.266,1.734074537,211.1474799
61.4,22.28691831,0.547947752,125822.1736,1.727539121,212.043141
61.6,22.21876693,0.553389902,126016.0637,1.73276748,213.0019955
61.8,22.90351822,0.558829425,125778.942,1.741045808,213.6285273
62,23.43867584,0.564334798,125573.5229,1.75063121,214.5023984
62.2,23.37382241,0.569941222,125789.1032,1.754116781,215.4154896
62.4,23.65799182,0.575577404,125736.8999,1.759345182,216.093229
62.6,23.66957503,0.581290903,126492.0033,1.755859607,217.0716964
62.8,23.71439026,0.587059165,127765.2869,1.745838578,218.0893915
63,23.90628824,0.592874205,128874.4284,1.737996053,219.0035744
63.2,23.7599485,0.598773418,129931.439,1.733639067,220.1247799
63.4,24.14711937,0.604691304,130867.5971,1.729717837,221.0422343
63.6,24.0930049,0.610702121,131626.5901,1.729282136,222.1154974
63.8,23.96575035,0.616778923,131719.9849,1.735817582,223.0002581
64,25.22796508,0.622811163,131472.7043,1.744967368,223.7052482
64.2,25.43642656,0.628984087,131483.8513,1.752374249,224.6368654
64.4,26.02216497,0.635190353,131305.5592,1.759781174,225.3146079
64.6,26.17077262,0.641492416,131431.4981,1.764573865,226.2026405
64.8,26.3684009,0.647853921,132138.3047,1.761959707,227.1113759
65,26.46380254,0.654287211,132911.6967,1.75803844,227.9481961
65.2,26.6589173,0.660777444,134188.2487,1.749760219,229.0726739
65.4,26.69529532,0.667344928,136192.2688,1.734075125,230.3496951
65.6,26.76407294,0.673975959,137817.1278,1.721875609,231.3815549
65.8,26.94752188,0.680664884,139588.0976,1.709676108,232.6226207
66,27.37694449,0.687402346,142484.3489,1.687019899,234.1785861
66.2,27.41244892,0.694237608,144645.4839,1.671770499,235.4654138
66.4,27.36816376,0.701147425,146404.6811,1.663056549,237.0181049
66.6,27.57068295,0.708107922,147429.983,1.661749483,238.4542111
66.8,27.97596193,0.715122997,147491.3981,1.669156383,239.6200966
67,28.10283523,0.722229656,146108.6929,1.690069869,240.4438413
67.2,28.15656668,0.729413369,144380.3285,1.715340323,241.3198874
67.4,28.28757225,0.736663645,143483.9154,1.730589743,242.0433886
67.6,28.56565827,0.743975534,142402.7093,1.749324762,242.885659
67.8,28.74774885,0.751368142,142123.2016,1.758910127,243.7192121
68,29.42969115,0.758797275,142839.7067,1.75716742,244.6192363
68.2,29.7185452,0.76633077,143915.6263,1.75324618,245.7840308
68.4,30.13245698,0.773930585,144454.6455,1.753246231,246.6502748
68.6,30.76242405,0.781590236,145710.1153,1.746710846,247.8750019
68.8,31.00304208,0.78935641,146810.5811,1.74104681,249.0071084
69,31.0221786,0.797217554,147342.254,1.740611116,249.9659641
69.2,31.32385225,0.80513619,148261.2622,1.737561271,251.2135692
69.4,31.2274506,0.813164653,149054.4639,1.734947076,252.1963951
69.6,32.26165045,0.821187776,150094.5056,1.732333015,253.4352923
69.8,32.49929667,0.829351989,151123.7638,1.72971886,254.6175206
70,32.75147283,0.837597263,152329.7608,1.724490521,255.6962359
70.2,32.81665439,0.845939569,153496.7076,1.721440648,257.0146629
70.4,32.83570056,0.854369165,154386.1958,1.719262164,258.0988241
70.6,32.81110428,0.862886653,155363.6366,1.717519373,259.4466697
70.8,33.02042893,0.871472002,156026.5065,1.717955096,260.6092845
71,33.32780125,0.880136136,156572.1062,1.718826528,261.6465956
71.2,33.75108822,0.888878658,157349.4779,1.719262276,262.9900888
71.4,34.16729748,0.897709617,158463.5612,1.715558897,264.2120901
71.6,34.33543059,0.906648186,159436.1752,1.71359828,265.448253
71.8,34.71712383,0.915660077,160231.1459,1.713598325,266.7187416
72,35.07262527,0.924764646,161000.86,1.713162671,267.8552081
72.2,35.26689259,0.933973011,162304.5138,1.709241417,269.3109271
72.4,35.56543933,0.943265881,163121.1774,1.70967715,270.7034517
72.6,35.67865183,0.952666111,163785.2854,1.709677165,271.8170332
72.8,35.8641488,0.962155465,164466.8281,1.710548582,273.0864298
73,36.1609885,0.971731523,164817.2902,1.714469896,274.441907
73.2,36.02069175,0.981437149,164288.5061,1.724926622,275.3964026
73.4,36.16126723,0.99121889,163508.1763,1.738868962,276.4816544
73.6,36.43312964,1.001089,163438.0576,1.744968761,277.3903921
73.8,37.09971497,1.01102828,164001.0374,1.745840237,278.526863
74,37.2057555,1.021110044,165108.511,1.743226066,279.8572769
74.2,37.78505093,1.031256684,166628.3952,1.735383579,281.0362411
74.4,37.87485418,1.041542344,169115.4968,1.720569872,282.6652074
74.6,37.9671341,1.051931113,170620.8759,1.713598722,283.9509479
74.8,38.47574292,1.062392588,171983.0981,1.708806109,285.3750733
75,38.89209081,1.072966313,173214.3642,1.705756275,286.9691768
75.2,39.14886427,1.083658418,174272.4726,1.702706422,288.2723515
75.4,39.54357147,1.094447401,174688.8883,1.707063446,289.750957
75.6,39.93576839,1.105344834,175164.5735,1.709241981,290.9440851
75.8,40.26728278,1.116356483,175586.5218,1.7131633,292.2766813
76,40.4574957,1.127545876,175891.8782,1.718827394,293.6779209
76.2,40.80394207,1.138723455,175605.0039,1.727977087,294.6727388
76.4,41.00077636,1.150081326,175720.7041,1.734948275,295.9628384
76.6,41.26158177,1.161548364,175924.4338,1.739305284,297.0197628
76.8,41.44342112,1.173136548,175994.5971,1.744969378,298.168214
77,41.61776269,1.184841782,176215.541,1.749762075,299.4757475
77.2,42.04056328,1.196645741,176418.3498,1.752812011,300.4836419
77.4,42.4001868,1.2085732,176973.3603,1.75368345,301.8009845
77.6,42.865332,1.220612364,177393.1995,1.754990601,302.8600912
77.8,43.47007087,1.232762037,177698.4189,1.758040559,303.9823978
78,43.50470434,1.245076943,178169.4393,1.761090449,305.2441656
78.2,43.8118957,1.257494988,179275.9406,1.758911998,306.5789414
78.4,44.52460951,1.270007028,180220.386,1.757169294,307.7001603
78.6,44.8799608,1.282671814,181552.2436,1.753683755,309.1079408
78.8,45.43390786,1.295448791,183537,1.744534168,310.5821896
79,45.64628147,1.308380182,185322.5218,1.736255935,311.9311293
79.2,45.80378649,1.321445713,186775.2141,1.732334674,313.4947209
79.4,46.25545506,1.334619998,187745.242,1.730591937,314.6889391
79.6,46.55917937,1.347937913,188921.9967,1.728849183,316.2699668
79.8,46.58531863,1.361410509,189206.1389,1.733206166,317.5764094
80,47.21476374,1.374972595,189796.6446,1.734077638,318.7673622
80.2,47.65471251,1.388685222,191461.4161,1.727542222,320.4322919
80.4,47.94339203,1.402547095,193574.8432,1.716214112,321.9533919
80.6,48.23952872,1.416547527,196050.2924,1.704450303,323.8754669
80.8,48.43758156,1.430696104,198874.3761,1.690072296,325.7114616
81,48.77771786,1.444976025,201067.7245,1.680922682,327.4047195
81.2,49.56160117,1.4593655,203330.9519,1.673515907,329.4466617
81.4,49.72218934,1.473947036,204252.6254,1.674823018,330.9830136
81.6,50.20020752,1.488650927,205093.3414,1.678308659,332.8048472
81.8,50.6657368,1.503503506,206127.4987,1.679615806,334.5591272
82,50.79467536,1.518530854,206972.9587,1.680922921,336.0704178
82.2,51.29589121,1.533680953,206697.7633,1.691815428,337.7386164
82.4,51.59763576,1.548998366,206606.3044,1.700529426,339.3490661
82.6,52.12373388,1.564452592,206645.1694,1.706629262,340.688205
82.8,52.3755675,1.58008311,205821.7688,1.719700235,342.0153537
83,52.85590937,1.595853118,204682.3736,1.735385421,343.3621192
83.2,53.0495208,1.611803345,204886.1235,1.739742428,344.6020983
83.4,53.69768004,1.627879365,205461.2334,1.742356693,346.1123082
83.6,53.87628179,1.644152609,205734.5952,1.745842297,347.3010754
83.8,54.45624495,1.660558839,206284.9154,1.748020861,348.6925168
84,54.83922789,1.677144722,207659.46,1.744971025,350.3661639
84.2,55.33603543,1.693888648,208601.6451,1.743663985,351.7183771
84.4,55.61259332,1.710817573,209596.2374,1.743664019,353.3429909
84.6,55.71045273,1.727930219,210847.5273,1.740614145,354.7039154
84.8,56.21382732,1.745184627,213581.1184,1.728850356,356.6586829
85,56.82770134,1.762604127,215757.459,1.721007865,358.4467432
85.2,57.47063361,1.780196465,217864.5071,1.714908164,360.4015148
85.4,58.1409618,1.797963512,219538.2987,1.710115563,361.9825501
85.6,58.47968064,1.815934253,220279.2528,1.713165492,363.7793231
85.8,59.21560319,1.834055373,220424.0366,1.719265355,365.3287615
86,59.52600938,1.852390919,220996.7115,1.721443884,366.7463497
86.2,60.16007254,1.870886169,222093.5858,1.72144396,368.6204898
86.4,60.25559862,1.889608176,222964.6186,1.721443972,370.1230644
86.6,60.57381091,1.908501284,224552.4287,1.717958425,372.0080953
86.8,60.87703449,1.92758533,224907.0575,1.722751143,373.6446949
87,61.34144744,1.946848981,225020.8059,1.727979579,374.9576837
87.2,62.06178696,1.96628682,224468.5135,1.739743521,376.4896887
87.4,62.60633257,1.985933269,223887.6312,1.750418197,377.7890582
87.6,63.12009871,2.005779306,223945.1933,1.756300188,379.1069516
87.8,63.50460796,2.025834607,224976.1215,1.755864537,380.6629224
88,63.47190793,2.046123053,226354.3675,1.752814646,382.2918891
88.2,64.313835,2.066548868,228429.6922,1.744972176,384.071238
88.4,64.70240236,2.087214519,231391.6309,1.732772668,386.15567
88.6,65.31199084,2.108070944,233484.9977,1.724930169,387.7868276
88.8,66.09647796,2.129123668,235028.7483,1.721880373,389.5683555
89,66.38397523,2.15042561,236539.6243,1.720137615,391.5274807
89.2,67.11811741,2.171907729,238128.4641,1.71795921,393.549811
89.4,67.65984171,2.193620404,238523.3305,1.721444863,394.9935556
89.6,68.1205059,2.215557195,238880.5423,1.727108999,396.7903322
89.8,68.78847721,2.237698702,240098.3694,1.726673381,398.6121739
90,69.18549718,2.260083288,240260.7274,1.731901812,400.0363019
90.2,69.787746,2.282677185,239910.1984,1.741922952,401.688164
90.4,69.98358471,2.305528973,240225.0266,1.746279963,403.1891066
90.6,70.7266207,2.328568806,240524.3515,1.750637039,404.7532566
90.8,71.29759655,2.351853186,241157.599,1.752815602,406.3397416
91,71.81036306,2.375375996,242895.3662,1.748458678,408.2356741
91.2,72.45730351,2.399124999,244927.3213,1.741051879,409.9125976
91.4,72.9280275,2.423125991,247284.7661,1.73320936,411.9948528
91.6,73.68167935,2.447345831,249645.598,1.724495477,413.799264
91.8,74.30108112,2.471818755,251510.4257,1.720138564,415.8379378
92,75.10410169,2.496523603,252241.5853,1.722752852,417.8123279
92.2,75.88464503,2.521478238,252568.1146,1.726674234,419.4031773
92.4,76.27456392,2.546713406,252000.479,1.737566751,421.1846992
92.6,76.88383475,2.572185361,251021.4957,1.749330693,422.4148812
92.8,77.40913076,2.597919666,251022.2497,1.755866239,423.9436173
93,77.80058966,2.623922802,253398.0338,1.749330805,426.0084379
93.2,78.32746514,2.650176846,255988.8197,1.742359688,428.1844018
93.4,79.25402475,2.676664313,258745.5858,1.732774425,430.0378495
93.6,79.49244817,2.703470267,263198.2065,1.715346499,432.6049777
93.8,80.27097738,2.730641511,265679.163,1.708811108,434.817995
94,80.38301952,2.757863012,266038.0147,1.713168112,436.5014456
94.2,81.4149481,2.785425557,266130.4747,1.719703718,438.4910982
94.4,81.64738044,2.813325941,266081.7868,1.725367833,440.1168028
94.6,82.46481437,2.841462249,265865.3752,1.733210512,442.0258196
94.8,83.05865594,2.869898152,266071.4613,1.738438972,443.831318
95,83.74552766,2.898612735,266972.2605,1.738874754,445.4853626
95.2,84.6442666,2.927599717,268548.1001,1.737567765,447.6264687
95.4,85.41913558,2.956887419,269561.9404,1.739310655,449.6259221
95.6,86.09257198,2.986476964,270223.0645,1.741489232,451.2701608
95.8,87.00363621,3.016345864,271335.6555,1.74192504,453.1639255
96,87.61465033,3.046537613,272821.8672,1.740618017,455.2668887
96.2,88.22727832,3.077032626,274645.4405,1.736696799,457.1203319
96.4,88.94373661,3.10782613,277803.9975,1.727547203,459.5708845
96.6,89.4424154,3.138945589,279458.2471,1.725368768,461.4602825
96.8,90.0607131,3.170368698,280981.8536,1.724497444,463.5556181
97,90.62826772,3.202111119,281272.1351,1.730597301,465.5572491
97.2,91.28219898,3.234166095,280975.5151,1.739311365,467.4826066
97.4,91.95269972,3.266541754,280240.7758,1.74846113,468.876236
97.6,92.88076886,3.299222369,280433.363,1.754125333,470.8386472
97.8,94.0431369,3.332213658,281541.1316,1.754125474,472.7258811
98,94.75170873,3.365571125,283279.0714,1.750204266,474.5226689
98.2,95.4876515,3.399260965,285082.1652,1.74759016,476.7411355
98.4,96.290023,3.433284741,287801.1516,1.740183367,479.138301
98.6,96.66186558,3.467682427,290311.9939,1.732776523,481.0963425
98.8,97.62950345,3.502380249,292948.0181,1.726241148,483.466271
99,98.24971443,3.537453062,295903.6119,1.718834336,486.1009696
99.2,99.12084122,3.572859187,299090.4523,1.709249053,488.4251329
99.4,99.90880826,3.608627413,301876.0244,1.704020749,491.2123795
99.6,100.3510087,3.644781215,302082.338,1.709249196,493.0930608
99.8,101.3299984,3.681257428,301833.3197,1.717527607,495.1426449
100,101.8859344,3.718132248,301004.7945,1.728855861,497.2140113
100.2,102.7210385,3.755356365,299682.0376,1.741491251,498.76455
100.4,103.3416767,3.792970729,298477.5284,1.75456231,500.60601
100.6,104.219875,3.830943536,299163.3372,1.75674092,502.322171
100.8,105.1644954,3.86929277,300544.7915,1.756305334,504.3303498
101,105.7043416,3.908058025,301863.3754,1.757176801,506.5226634
101.2,106.4784771,3.947195008,302423.8261,1.76022679,508.177804
101.4,107.4320534,3.986711448,303717.5787,1.761098305,510.3330813
101.6,108.2193599,4.026637643,304859.0751,1.762841198,512.3979168
101.8,108.7523067,4.066984208,304894.9637,1.768941067,514.1184286
102,109.9242535,4.107687474,305557.2644,1.771119712,515.7441601
102.2,110.9453027,4.1488121,308548.7494,1.763277231,518.1522276
102.4,111.925981,4.190354361,310500.2568,1.759356052,520.0917628
102.6,113.0275083,4.232304778,312400.9868,1.756741986,522.4170259
102.8,113.8032037,4.274701445,316279.726,1.744542483,524.927514
103,114.8746793,4.317501518,320876.3056,1.729510964,527.5916442
103.2,115.6066094,4.360757523,324423.3885,1.719707803,530.2405115
103.4,116.4020446,4.404443155,329189.8812,1.705329798,533.4123948
103.6,117.6648664,4.448532361,333801.8749,1.690516145,536.1615233
103.8,118.8495007,4.493070547,335812.6124,1.688337783,538.9411556
104,119.5009559,4.5380966,335039.3585,1.698794662,541.5638728
104.2,120.095829,4.583579429,334272.026,1.708380136,543.5349982
104.4,121.346315,4.629469482,332385.5977,1.724936889,545.7316928
104.6,121.8525371,4.675877125,331064.9741,1.738007955,547.4282337
104.8,122.9528742,4.722705913,331702.3956,1.74280079,549.5802498
105,123.7452386,4.770028648,333657.2083,1.742365185,552.1005475
105.2,124.3584397,4.817840449,334655.6931,1.745850862,554.5205962
105.4,125.0322299,4.866127957,335408.0275,1.748465146,556.4274368
105.6,126.2639823,4.91485822,335245.0469,1.7563079,558.5696501
105.8,127.1673986,4.964103026,333810.5388,1.76894332,560.3021611
106,128.0765535,5.013842251,333030.7353,1.777875288,562.0466577
106.2,129.3330013,5.064054785,334770.3324,1.77504339,564.1779765
106.4,130.7771828,5.114757626,336982.803,1.770686563,566.5806145
106.6,131.5797249,5.166018735,339246.3611,1.765022556,568.6955769
106.8,132.8637696,5.217758195,342296.5105,1.756744403,571.2060824
107,134.1016094,5.270021146,345051.2464,1.751080446,573.885479
107.2,134.8295262,5.322847902,346562.1035,1.750644834,575.9993499
107.4,135.9329862,5.376176852,349163.7741,1.746723663,578.7245053
107.6,136.9623991,5.430047367,351265.1244,1.744109584,580.9037631
107.8,137.9913104,5.484459139,354626.4089,1.737574198,583.5809738
108,138.8593298,5.539429766,357831.2922,1.732781596,586.5382126
108.2,139.9508098,5.594935633,359350.6089,1.732781727,588.839508
108.4,141.0355529,5.650999772,360469.5783,1.735831762,591.5134538
108.6,142.1393203,5.707625873,362370.4705,1.734960493,594.2625826
108.8,142.9334369,5.764844559,363551.9023,1.736267691,596.7774358
109,144.0777435,5.822610825,365743.4321,1.732346521,599.1201409
109.2,145.3142032,5.880948004,370190.8515,1.721889849,602.4979818
109.4,146.5297939,5.939872971,373180.156,1.716225882,605.1806492
109.6,147.6372561,5.99939823,375708.3038,1.714047508,608.31986
109.8,148.6814646,6.059526302,377319.5413,1.714919035,611.1234704
110,150.0064671,6.120237181,378442.2016,1.717097697,613.5947572
110.2,151.2407899,6.181564921,380383.5269,1.717533544,616.743781
110.4,152.6337427,6.243496846,382444.8911,1.715790905,619.2815373
110.6,153.6692513,6.306078229,385846.6399,1.710998316,622.6070715
110.8,155.0370744,6.369263087,390355.3981,1.702284454,625.9903686
111,156.2011929,6.433098401,393516.8319,1.697927579,628.8419257
111.2,157.4250441,6.497570581,395829.3981,1.698799126,632.2884192
111.4,158.6071884,6.563022279,396874.2009,1.701849174,634.8588571
111.6,159.7103317,6.628811908,397399.6307,1.707949122,637.9414135
111.8,160.926444,6.694919687,397932.3835,1.712741981,640.6959969
112,162.3850602,6.76200751,397595.2772,1.719713375,643.0300014
112.2,163.5568619,6.829791286,397486.6016,1.727120439,646.0112244
112.4,164.7642901,6.898253275,398218.7626,1.731477598,648.8911178
112.6,165.8253466,6.967414277,399865.0363,1.731477726,651.3678474
112.8,167.2768798,7.037240404,400262.4217,1.737142019,653.9611787
113,168.9917402,7.107748236,403344.9343,1.733656612,657.2311695
113.2,170.0067554,7.179017619,406930.2985,1.72712121,660.0282477
113.4,171.1163951,7.250995963,412343.0676,1.7157931,663.7874588
113.6,172.5209379,7.323674967,415317.8637,1.711871951,666.6455649
113.8,174.0367237,7.397075792,418211.8193,1.70925792,669.900299
114,175.205019,7.471240477,420564.567,1.709258058,673.4208867
114.2,176.3864926,7.546149285,420978.7209,1.715358023,676.6516375
114.4,177.982534,7.621779328,420627.7944,1.722329442,679.0684601
114.6,178.975953,7.698214971,422120.4696,1.724072368,682.3961816
114.8,180.5019448,7.775378202,426644.6645,1.71492281,685.8437783
115,181.747754,7.853337706,428462.5715,1.714922958,688.7367523
115.2,183.1571533,7.932067342,429294.1749,1.720151549,692.0176338
115.4,184.2739019,8.011609505,429252.2016,1.726687213,694.3875893
115.6,186.0786228,8.09189731,427883.8993,1.739322788,697.1814278
115.8,187.3197722,8.17303477,422291.0444,1.765465066,698.8888994
116,189.1134322,8.254944779,419973.5426,1.780279159,701.1117804
116.2,190.67344,8.337695656,420079.0146,1.784636373,703.0535298
116.4,191.7147484,8.421316952,420894.1093,1.78725072,705.5901981
116.6,193.2495597,8.505740923,423273.3061,1.78332959,707.9198487
116.8,195.0476754,8.590993166,429801.7808,1.76590171,711.3598325
117,196.2946769,8.677143781,434360.5873,1.756752118,714.843386
117.2,198.0534605,8.764121168,437592.1483,1.751088198,717.675363
117.4,199.5810767,8.851989918,442802.6228,1.740631524,721.4847154
117.6,200.8567481,8.940760609,445154.5883,1.738888864,724.3112321
117.8,202.4671864,9.030397629,446127.664,1.742374684,727.2140305
118,204.4049109,9.120910268,449645.9139,1.738453592,730.7847764
118.2,205.6901258,9.212381916,452515.8773,1.735403828,733.6723096
118.4,207.1796302,9.304757159,454517.8353,1.736711112,737.0730604
118.6,208.6831149,9.398059486,459475.16,1.727997244,740.8845982
118.8,210.3850691,9.492284034,463434.9591,1.722769002,744.6144203
119,212.2048804,9.587446338,465681.2134,1.721462115,747.5520989
119.2,213.7694111,9.683584107,467641.746,1.722769412,751.2110941
119.4,215.4335131,9.780680278,469550.7128,1.723205311,754.2272187
119.6,216.9624163,9.878762205,469091.2921,1.731919549,757.394793
119.8,218.452519,9.977837444,469993.3363,1.735841056,760.5046221
120,220.1103335,10.07789539,471543.4671,1.737148363,763.3148079
120.2,221.8685442,10.17895102,474459.8044,1.735405761,766.9313149
120.4,223.777843,10.28101054,476890.8669,1.734534583,770.6023129
120.6,225.5959801,10.38410252,480196.5204,1.730177768,773.8113088
120.8,227.2755846,10.48824088,481944.7034,1.731049375,777.08023
121,228.9105625,10.59342892,483168.2195,1.734099495,780.6923795
121.2,230.7414979,10.69965899,483648.6397,1.738021045,783.3641936
121.4,232.3732298,10.80697144,484162.2433,1.744556793,786.6832368
121.6,234.0405252,10.91535946,483589.263,1.753488917,789.4111638
121.8,235.9411701,11.02481884,484415.7794,1.757628331,792.0911549
122,237.6450993,11.13539284,485209.1219,1.763292685,795.2391326
122.2,239.4980239,11.24706656,487106.6656,1.763728615,797.9861346
122.4,241.2552007,11.35986953,492735.6148,1.753707642,801.92082
122.6,243.2270216,11.47378954,500072.2622,1.738893951,806.2859135
122.8,245.343262,11.58884329,507582.1138,1.723644568,810.5747416
123,246.8870455,11.60378844,515356.062,1.707523705,814.6739518
123.2,248.260367,11.60368398,523455.6361,1.693145635,819.8671357
123.4,248.9863076,11.60362847,526686.4062,1.690967199,823.5457233
123.6,249.7990921,11.60356639,529643.3163,1.691402998,827.9184003
123.8,250.4614582,11.60351568,527871.6059,1.703602788,831.3997638
124,251.1599746,11.60346224,522660.2962,1.725388073,834.458355
124.2,251.1928271,11.60345913,519300.5479,1.74063772,836.8522541
124.4,251.5693151,11.60343004,517315.2627,1.751966071,839.3834564
124.6,252.0613179,11.60339221,515266.9804,1.764165845,842.3712148
124.8,252.3580259,11.60336915,518411.8535,1.761551657,845.8329519
125,252.88701,11.60332853,524671.1226,1.751094823,850.0225634
125.2,252.9373144,11.6033241,529676.2866,1.743252156,853.5147986
125.4,252.9053457,11.60332589,534353.3624,1.738023704,857.7490626
125.6,253.6961078,11.60326547,537593.751,1.735409573,861.0985878
125.8,253.3437726,11.60329149,538132.7528,1.741073686,864.5831792
126,253.8245564,11.60325451,535813.6992,1.754144869,867.7474558
126.2,254.021955,11.60323896,532017.3383,1.769394538,869.8907492
126.4,254.0818164,11.6032338,528113.8332,1.786387008,872.4535388
126.6,254.3793555,11.60321068,522998.0887,1.806865141,874.5358133
126.8,254.582156,11.60319472,518125.9972,1.826471854,876.1865984
127,254.9893926,11.6031633,516227.7805,1.836928806,877.6750372
127.2,254.6794406,11.60318611,516793.6132,1.84128581,879.9381692
127.4,255.0102214,11.60316048,517074.7962,1.844771486,881.7306061
127.6,255.1897527,11.60314628,519347.6933,1.843028693,884.2890446
127.8,255.4914471,11.60312284,523996.1219,1.833878944,887.1166202
128,255.8180727,11.60309752,528386.2438,1.825164901,889.8297898
128.2,255.7823643,11.60309959,530908.4317,1.822986377,892.7728525
128.4,255.9261608,11.60308809,532771.5655,1.822986396,895.6080555
128.6,256.1921204,11.60306736,532977.9384,1.826907768,897.6870614
128.8,256.2486576,11.60306246,532143.8313,1.833879043,899.7290122
129,256.2594875,11.60306101,528789.6173,1.848257285,901.5650225
129.2,256.5038401,11.60304191,526421.6233,1.858278514,902.89873
129.4,256.5046975,11.60304122,526098.8474,1.862635557,904.9134395
129.6,256.7922642,11.60301885,525553.8346,1.866556933,906.4901315
129.8,257.0698584,11.60299723,524357.0424,1.872221124,908.0101659
130,256.8862246,11.60301049,525719.0443,1.870913989,910.2133699
130.2,257.0158934,11.60300006,527294.1802,1.868735485,911.9763823
130.4,257.3425191,11.60297474,528443.8068,1.869171232,914.1523683
130.6,257.2660896,11.60297989,529959.2929,1.868735519,916.1725215
130.8,257.2602987,11.6029797,532470.7083,1.866121294,918.3386871
131,257.5370619,11.60295815,531731.956,1.872656894,919.7355921
131.2,257.5877818,11.60295369,528226.8409,1.887906551,920.8448271
131.4,257.7398888,11.60294156,525402.7403,1.899670586,921.572704
131.6,257.8762059,11.60293063,521205.1123,1.915791663,922.1937933
131.8,257.9211086,11.60292661,515800.6525,1.934962658,922.3496102
132,257.9601939,11.60292303,514548.9387,1.940191115,922.8192407
132.2,257.934458,11.60292435,516168.8186,1.936705479,924.0091047
132.4,258.1056789,11.60291077,517740.7124,1.933219868,925.1379609
132.6,258.1115225,11.60290971,520782.6724,1.925812897,926.7081045
132.8,258.2893918,11.60289563,524458.7234,1.916663132,928.4002951
133.5,258.5236299,11.5257625,1.7977E+308,1.962847819,0
133.7,258.2828039,11.40982034,1.7977E+308,1.98158307,0
133.9,257.8408659,11.29389338,1.7977E+308,1.925812865,0
134.1,257.739655,11.17794066,1.7977E+308,1.789001709,0
134.3,257.4614321,11.06200133,1.7977E+308,1.577685112,0
134.5,257.3544039,10.94604905,1.7977E+308,1.195572468,0
134.7,257.2523619,10.83009639,1.7977E+308,0.818688282,0
134.9,256.7397854,10.71417478,1.7977E+308,0.470560572,0
135.1,256.6527021,10.59822099,1.7977E+308,0.22351627,0
135.3,256.3187996,10.48228587,1.7977E+308,0.056205844,0
135.5,256.3414138,10.36632379,1.7977E+308,0.006099859,0
135.7,256.0814739,10.25038307,1.7977E+308,0.00827838,0
135.9,255.6137737,10.13445806,1.7977E+308,0.01350683,0
136.1,255.1693426,10.0185313,1.7977E+308,0.016121055,0
136.3,255.2925129,9.902561612,1.7977E+308,0.014378238,0
136.5,255.0184453,9.786621963,1.7977E+308,0.016992463,0
136.7,254.8640477,9.670673267,1.7977E+308,0.023092321,0
136.9,254.4644929,9.554743106,1.7977E+308,0.036163446,0
137.1,254.2880727,9.438796074,1.7977E+308,0.046184641,0
137.3,254.2392174,9.322839398,1.7977E+308,0.055770132,0
137.5,253.8554524,9.206908043,1.7977E+308,0.059691468,0
137.7,253.4878927,9.090975464,1.7977E+308,0.054463017,0
137.9,253.5150777,8.975013038,1.7977E+308,0.035292035,0
138.1,253.147518,8.859080458,1.7977E+308,0.011110455,0
138.3,252.6976853,8.743154099,1.7977E+308,0.013071123,0
138.5,252.5486895,8.627204994,1.7977E+308,0.030063583,0
138.7,252.4075886,8.511255292,1.7977E+308,0.039649073,0
138.9,252.2914189,8.395303704,1.7977E+308,0.037906256,0
139.1,251.9005901,8.279372884,1.7977E+308,0.027013653,0
139.3,251.8135069,8.163419098,1.7977E+308,0.020913796,0
139.5,251.4779424,8.047484099,1.7977E+308,0.024399428,0
139.7,251.4723012,7.931524155,1.7977E+308,0.031806397,0
139.9,251.4629203,7.815564494,1.7977E+308,0.030934989,0
140.1,251.0550552,7.699634961,1.7977E+308,0.024835131,0
140.3,250.4955251,7.583716896,1.7977E+308,0.015685345,0
140.5,250.5131531,7.467755193,1.7977E+308,0.009585489,0
140.7,250.2885326,7.351811806,1.7977E+308,0.017428161,0
140.9,249.7539338,7.235891856,1.7977E+308,0.024399425,0
141.1,249.6489832,7.11993942,1.7977E+308,0.030499281,0
141.3,249.6121779,7.003981833,1.7977E+308,0.028320761,0
141.5,249.3148413,6.888043943,1.7977E+308,0.022220904,0
141.7,249.0303859,6.77210508,1.7977E+308,0.021349496,0
141.9,248.787067,6.656163107,1.7977E+308,0.025924387,0
142.1,248.5811449,6.540218306,1.7977E+308,0.027449351,0
142.3,248.0644135,6.424297005,1.7977E+308,0.029192166,0
142.5,247.716799,6.308362917,1.7977E+308,0.030063573,0
142.7,247.7103268,6.192403036,1.7977E+308,0.022656606,0
142.9,247.3523243,6.076469734,1.7977E+308,0.017428158,0
143.1,247.0466773,5.960532473,1.7977E+308,0.011764006,0
143.3,246.7115284,5.844597442,1.7977E+308,0.008278375,0
143.5,247.036226,5.728612522,1.7977E+308,0.016121046,0
143.7,246.6803011,5.612679062,1.7977E+308,0.019606676,0
143.9,246.2682809,5.496749844,1.7977E+308,0.023092307,0
144.1,246.064021,5.380804918,1.7977E+308,0.02570653,0
144.3,245.737598,5.264869227,1.7977E+308,0.024835122,0
144.5,245.4336132,5.148931841,1.7977E+308,0.018299563,0
144.7,244.8844713,5.03301299,1.7977E+308,0.012635412,0
144.9,245.079111,4.917037903,1.7977E+308,0.013942524,0
145.1,244.6911911,4.801106863,1.7977E+308,0.023528008,0
145.3,244.4977347,4.68516112,1.7977E+308,0.028756454,0
145.5,244.0674317,4.569233284,1.7977E+308,0.028756454,0
145.7,243.9986314,4.453278115,1.7977E+308,0.023092303,0
145.9,243.6082184,4.337347263,1.7977E+308,0.00914978,0
146.1,243.2618505,4.221413081,1.7977E+308,0.005228446,0
146.3,243.24873,4.105453703,1.7977E+308,0.014378226,0
146.5,242.6729949,3.989536863,1.7977E+308,0.027013636,0
146.7,242.4047449,3.873596775,1.7977E+308,0.038341934,0
146.9,242.341023,3.757061423,1.7977E+308,0.046184602,0
147.1,241.8025927,3.641721562,1.7977E+308,0.057512898,0
147.3,241.5484704,3.525780405,1.7977E+308,0.064048453,0
147.5,241.1647057,3.409849051,1.7977E+308,0.060127118,0
147.7,240.7186131,3.293922409,1.7977E+308,0.050541634,0
147.9,240.4985634,3.177978676,1.7977E+308,0.041391855,0
148.1,240.385718,3.062026837,1.7977E+308,0.030063557,0
148.3,239.910539,2.946102395,1.7977E+308,0.023528001,0
148.5,239.7702693,2.83015263,1.7977E+308,0.020913778,0
148.7,239.4180842,2.714218888,1.7977E+308,0.023528,0
148.9,238.9262844,2.598295702,1.7977E+308,0.021785184,0
149.1,238.7403074,2.482349393,1.7977E+308,0.020913777,0
149.3,238.398926,2.366414834,1.7977E+308,0.011763999,0
149.5,237.9844129,2.250485804,1.7977E+308,0.006971258,0
149.7,237.8865263,2.134532834,1.7977E+308,0.00958548,0
149.9,237.7637084,2.01858175,1.7977E+308,0.020042368,0
150.1,237.1987771,1.902664093,1.7977E+308,0.03485629,0
150.3,236.7992228,1.786733933,1.7977E+308,0.040520437,0
150.5,236.7196191,1.670779581,1.7977E+308,0.047491694,0
150.7,235.9078688,1.554880586,1.7977E+308,0.051413024,0
150.9,235.8565204,1.438924098,1.7977E+308,0.050541616,0
151.1,235.4095969,1.322997519,1.7977E+308,0.045748876,0
151.3,234.7806756,1.2070847,1.7977E+308,0.038777617,0
226.5,233.6009178,1.097356435,1.7977E+308,0.033984882,0
226.7,233.0526073,0.981437522,1.7977E+308,0.035291991,0
226.9,232.5242419,0.865517101,1.7977E+308,0.033113472,0
227.1,232.3727531,0.749568184,1.7977E+308,0.025706511,0
227.3,232.0010388,0.633635918,1.7977E+308,0.022656585,0
227.5,231.5935897,0.517706355,1.7977E+308,0.018299549,0
227.7,231.3261708,0.401766203,1.7977E+308,0.015903179,0
227.9,230.7026513,0.285852977,1.7977E+308,0.011763995,0
228.1,230.1094648,0.169937456,1.7977E+308,0.012199698,0
228.3,229.6937054,0.054008521,1.7977E+308,0.01742814,0
228.382,229.2345615,0.006499484,1.7977E+308,0.020478064,0
,,,,,