File: Test_9.csv
Time On Sample,Displacement Into Surface,Load On Sample,Harmonic Contact Stiffness,Harmonic Displacement,Harmonic Load
0,0,0,241.1083467,0.305380567,2.282506671
0.2,-0.129864781,0.000767683,2120.871418,0.215203993,2.342429262
0.4,0.019456393,0.001514208,7882.778608,0.14419539,2.462274499
0.6,0.431345319,0.002240835,15036.23091,0.123284884,2.572314259
0.8,0.237500418,0.003013367,18267.64746,0.119799797,2.677995931
1,0.065259194,0.003784262,18521.45548,0.130255051,2.764066567
1.2,0.26858956,0.004526694,18342.72542,0.148987385,2.931849905
1.4,0.392983422,0.005275108,19209.20804,0.159007006,3.188972407
1.6,0.561415547,0.006020185,20773.31787,0.163799,3.494033003
1.8,0.625983976,0.006772322,22766.82243,0.161620823,3.811078101
2,0.472023024,0.0075403,27167.33359,0.147244845,4.145555201
2.2,0.437713202,0.008299211,31475.52257,0.134611412,4.432094239
2.4,0.584541896,0.009044393,37570.49856,0.125027429,5.049841925
2.6,0.326717117,0.009820242,42028.44118,0.123284885,5.620740913
2.8,0.600675137,0.01055579,48079.67613,0.122849252,6.190550565
3,0.346173999,0.011331388,50720.70977,0.125898699,6.635067319
3.2,0.72316494,0.012059127,51006.08998,0.138532136,7.199429506
3.4,0.579174913,0.012826348,52535.00461,0.158571375,8.229008895
3.6,0.553174198,0.013584628,52232.04901,0.179481885,9.168159642
3.8,0.882803239,0.014315956,51431.36396,0.200828037,10.09532605
4,0.671509448,0.015088278,48327.40794,0.232629437,10.98653863
4.2,0.583190434,0.01585128,47102.10005,0.255718125,11.77206956
4.4,0.601227983,0.016606222,47493.64286,0.281420629,13.14484216
4.6,0.889311494,0.017340699,47784.45751,0.30407369,14.40430674
4.8,0.902363579,0.018096017,47249.06697,0.328469288,15.41863318
5,0.723475302,0.018865882,46841.85506,0.358528144,16.67918694
5.2,0.871134915,0.019611,45716.94166,0.391200822,17.72510906
5.4,0.768690418,0.020375072,44258.35571,0.438685106,19.14146165
5.6,0.511696541,0.021150857,41984.66624,0.494446462,20.37041973
5.8,0.222297154,0.021929098,39164.88412,0.562405613,21.56669271
6,0.49874791,0.022664457,36774.29638,0.623830251,22.43611564
6.2,0.004113598,0.023458251,33904.98617,0.707472272,23.44826248
6.4,0.426804623,0.024182528,31183.67019,0.800698324,24.44951533
6.6,0.566986038,0.024928213,29032.43973,0.880419657,25.08905326
6.8,0.550125339,0.025685799,26860.40868,0.977566409,25.85497319
7,0.244938647,0.026465236,25215.50854,1.066436061,26.57731278
7.2,0.660151487,0.027190078,24039.11472,1.139187249,27.18089737
7.4,0.627503486,0.02794886,23226.39903,1.197562426,27.68533683
7.6,0.658835606,0.028702792,22572.33979,1.255066337,28.29218957
7.8,0.697645923,0.029456158,21985.20735,1.303421901,28.73779601
8,0.407415617,0.03023446,21182.13594,1.366589046,29.21172903
8.2,0.569200711,0.030978507,20500.79916,1.422786064,29.55928044
8.4,0.30888319,0.031754541,19966.63455,1.46983469,29.87196723
8.6,1.374699111,0.032430075,19481.27522,1.51557655,30.2184304
8.8,0.897513885,0.033222544,19470.55933,1.530823749,30.54201189
9,1.294446716,0.033948767,19799.76247,1.531695066,31.01158785
9.2,1.388097144,0.034697973,20510.03027,1.506428208,31.497506
9.4,1.453496608,0.03544932,21635.03366,1.459815199,32.06404726
9.6,1.549639769,0.036198337,23630.02233,1.382707693,32.85066808
9.8,1.77872865,0.036937278,25355.92719,1.323461262,33.51962269
10,1.052270195,0.037748636,27820.09215,1.247224952,34.43153484
10.2,0.746252575,0.038528132,29615.59379,1.203225724,35.1985437
10.4,0.642146256,0.039292327,30364.94109,1.197998088,35.85115538
10.6,0.25719213,0.040077807,29561.2536,1.24591798,36.40244277
10.8,0.54776838,0.040812091,27180.5094,1.356133831,36.70205642
11,1.798877435,0.04147358,24709.48356,1.482468308,36.74128072
11.2,1.859291439,0.042225303,22303.80798,1.626663736,36.7129539
11.4,1.878990815,0.042980112,21347.39258,1.693316004,36.74345992
11.6,1.744971702,0.043746569,21322.03435,1.704206883,36.97770263
11.8,2.174310087,0.044470332,22600.80668,1.635376493,37.43311534
12,1.96384718,0.045242582,25741.20832,1.484210878,38.31234327
12.2,1.647027699,0.046022892,28824.56947,1.366589207,39.12837993
12.4,1.645954306,0.046779274,31833.49314,1.272927532,39.94332753
12.6,1.83765221,0.047521048,34493.86025,1.207146559,40.82691425
12.8,1.779245975,0.048281774,35552.38437,1.190592398,41.46427284
13,1.975098435,0.049023232,35679.05657,1.204097124,42.12451155
13.2,2.035512441,0.049774953,35706.50092,1.217166202,42.67797896
13.4,2.292852305,0.05051175,35606.09533,1.238948013,43.37090287
13.6,2.163818651,0.051277829,35496.42575,1.256373432,43.86335761
13.8,1.889375612,0.052054926,35217.45015,1.28381846,44.44841972
14,2.130097259,0.052792983,34936.38089,1.31169917,45.00515591
14.2,2.037623681,0.05355629,34754.83536,1.333480949,45.45838862
14.4,1.979217445,0.054317015,34674.93488,1.352648917,45.95847009
14.6,1.97648163,0.05507731,34733.83449,1.368331805,46.52719023
14.8,2.074702981,0.055820481,34785.5412,1.38227216,47.08719469
15,2.148826716,0.056573056,34734.37374,1.396648148,47.5229957
15.2,2.255771127,0.057325039,34575.97017,1.414509226,47.9468123
15.4,1.894083053,0.058104959,34426.67719,1.43498407,48.49483109
15.6,2.047143613,0.058849657,34232.21962,1.455458967,48.96767553
15.8,2.159074091,0.059597473,34137.83606,1.472448774,49.42199822
16,2.279313678,0.060344659,34137.57486,1.48464659,49.85562039
16.2,2.095024454,0.061114923,34163.62526,1.49510183,50.27398899
16.4,2.286306916,0.061856724,34204.63441,1.504685839,50.70761132
16.6,2.243272529,0.062616282,34275.47477,1.514269822,51.18045516
16.8,2.407134936,0.063360162,34260.22065,1.525160736,51.5574234
17,2.352467798,0.064120601,34192.02706,1.540407983,51.99540326
17.2,2.314834332,0.064879749,34189.73353,1.55173451,52.36910239
17.4,2.783225563,0.065600549,34135.78383,1.566981815,52.72428145
17.6,2.586888126,0.066371723,33964.55194,1.587456676,53.08272711
17.8,2.459516289,0.067137671,33944.24117,1.601397008,53.45751569
18,3.109877008,0.067844679,34311.06805,1.598783269,53.87806531
18.2,2.970041504,0.06861157,34853.01577,1.58702109,54.28989688
18.4,2.778689528,0.069382366,35716.08251,1.562189833,54.76165075
18.6,2.879818175,0.070130995,37248.33408,1.516883727,55.43387407
18.8,3.042434227,0.070874965,38994.13195,1.46809254,56.15948307
19,3.357106974,0.07160741,40211.35318,1.438033705,56.73474107
19.2,3.211455092,0.072374741,41212.89378,1.417994448,57.33723555
19.4,3.217859901,0.073130548,41909.13392,1.412331186,58.05303864
19.6,3.05392798,0.073899264,42016.35116,1.423222064,58.62502695
19.8,3.09772378,0.074652237,41845.87577,1.440647506,59.08261807
20,3.154814153,0.075404203,41624.94268,1.461993664,59.6066689
20.2,3.184484468,0.076158247,41543.23265,1.476369652,60.04246983
20.4,3.534055481,0.076888046,41564.00263,1.490745673,60.62535463
20.6,3.095092049,0.077677604,41686.19596,1.497280166,61.06333331
20.8,3.660699898,0.078391031,42012.73508,1.499458405,61.62442873
21,3.439435119,0.07916409,42430.56798,1.499458379,62.2323704
21.2,3.312894184,0.079929971,42936.13954,1.493795109,62.74443615
21.4,3.382448224,0.080680991,43691.06115,1.483775493,63.43191236
21.6,3.275849152,0.08144536,44278.81324,1.476369674,63.97448423
21.8,3.377808104,0.082197778,44762.96509,1.47506278,64.61184345
22,3.488074962,0.082957144,45175.76714,1.475498431,65.24375519
22.2,4.09023993,0.083686582,45189.29151,1.485953754,65.73839121
22.4,3.955385678,0.084479526,45303.15446,1.49335955,66.25917296
22.6,3.829670195,0.085279666,45507.06021,1.500329713,66.87583092
22.8,3.877613834,0.086074598,45754.4485,1.502507898,67.37700214
23,4.073458366,0.086866234,46153.08002,1.502507922,68.00237726
23.2,4.149650434,0.087675034,46630.17991,1.498587211,68.54494974
23.4,4.119484608,0.088500024,46966.91796,1.50250793,69.2269782
23.6,4.002902714,0.089339914,47162.79925,1.509042457,69.84363614
23.8,4.247765752,0.090160827,47321.7124,1.514270115,70.32410763
24,4.555776734,0.090985104,47615.57665,1.517755237,70.94185665
24.2,4.524774701,0.091843473,47873.51093,1.519933415,71.45937021
24.4,4.22954161,0.092730451,48337.31257,1.518626478,72.16427715
24.6,4.548350347,0.093579638,48775.20295,1.515141428,72.70031364
24.8,4.604589812,0.094457539,49234.45352,1.514270164,73.36382082
25,4.591031361,0.09534949,49631.15278,1.515141437,74.00444834
25.2,4.470283971,0.096258501,50065.09414,1.513834518,74.57752619
25.4,4.723445078,0.097148315,50566.99771,1.512092004,75.17893226
25.6,4.162311967,0.098108907,51044.90891,1.512963218,75.86422745
25.8,4.513517661,0.099009571,51526.75469,1.512527622,76.53863082
26,4.631235893,0.099937222,51978.68305,1.513398908,77.22174929
26.2,4.590248623,0.100886332,52321.77593,1.51514145,77.78829025
26.4,4.543443477,0.101845317,52714.08296,1.515577083,78.39841161
26.6,4.40440568,0.102820913,53309.16092,1.512527619,79.14580986
26.8,4.458968592,0.103791619,53930.75432,1.50904254,79.88340321
27,4.842570727,0.104747078,54476.66812,1.505121861,80.49352599
27.2,4.660320872,0.105755402,54906.28657,1.504250572,81.10909424
27.4,4.805448395,0.106748762,55338.09834,1.506864404,81.88699973
27.6,4.688006415,0.107772214,55607.16698,1.512963296,82.58645969
27.8,5.054983976,0.108768951,55832.76145,1.519933511,83.28810105
28,5.126986506,0.109798217,55889.06619,1.528646238,83.81650995
28.2,4.76525182,0.110870742,55985.44579,1.537358918,84.38413924
28.4,5.201190064,0.111893326,55982.4345,1.55086368,85.08795987
28.6,5.248260287,0.112955783,55991.31622,1.562625856,85.72749804
28.8,5.08843193,0.114044782,56048.2638,1.570902922,86.24392143
29,5.252657195,0.11511986,56128.47507,1.580051295,86.85404356
29.2,5.301384088,0.116214609,56354.32061,1.583100754,87.39443718
29.4,5.650068149,0.117297522,57054.98487,1.577437529,88.16471705
29.6,5.686327889,0.118415166,57529.50614,1.57482372,88.74760092
29.8,5.542278128,0.119557756,57948.21721,1.575259342,89.42744967
30,5.653316265,0.120692385,58536.73508,1.57177427,90.14870132
30.2,5.540006596,0.121855411,58991.1448,1.570467352,90.76426965
30.4,5.520588018,0.123023038,59347.01996,1.571774259,91.3820176
30.6,5.640760663,0.124191667,60020.12065,1.566546644,92.1108953
30.8,5.880582619,0.125363109,60946.06464,1.556091412,92.91821772
31,5.994104217,0.126555908,61469.90731,1.555220155,93.69721262
31.2,5.712941106,0.127790765,61525.0029,1.563061572,94.27791626
31.4,5.992641067,0.128995244,61540.6385,1.571774323,94.87932265
31.6,5.723937744,0.130253545,61337.58504,1.586585916,95.52975482
31.8,5.75103678,0.131501996,60870.81124,1.607496444,96.10937049
32,6.084740059,0.132739552,60732.85878,1.618823018,96.57676858
32.2,6.060734085,0.134016894,60989.49506,1.622743741,97.23373867
32.4,5.923306706,0.135315641,61136.21053,1.627971358,97.78611605
32.6,6.239554745,0.136592961,61379.36664,1.63189212,98.41476028
32.8,6.179396948,0.137918267,61832.16474,1.630585207,99.07499858
33,6.394269664,0.139229498,62455.53771,1.625357604,99.76574437
33.2,6.143000186,0.140582605,62961.27698,1.622308126,100.3725963
33.4,6.138923548,0.141937272,63573.40771,1.617516133,101.0099552
33.6,6.314737026,0.143291815,64399.37789,1.610110344,101.7943979
33.8,6.407041768,0.144666319,65119.80103,1.605318362,102.5559607
34,6.490204296,0.146055305,65364.84183,1.608803461,103.1116075
34.2,6.292101157,0.147479696,65646.99903,1.611852892,103.697759
34.4,6.790299353,0.148865306,66090.23865,1.614031131,104.4756665
34.6,6.588037134,0.150318438,66462.31208,1.616644926,105.1762155
34.8,6.700687964,0.151762105,66725.27359,1.619258757,105.7362206
35,6.583174073,0.153237838,67368.00235,1.615338022,106.4923349
35.2,6.625192794,0.154716165,67779.90852,1.614466758,107.0980984
35.4,6.66471642,0.156209544,68094.50969,1.617951852,107.8847199
35.6,7.060698588,0.157690765,68254.58467,1.623179531,108.5623925
35.8,6.665650868,0.159247211,68440.05177,1.626664575,109.1398271
36,6.758345582,0.160782031,68333.54478,1.638862395,109.8142297
36.2,7.278957127,0.162299802,68434.24653,1.644961361,110.3949371
36.4,7.626736745,0.163845816,68609.5447,1.649753399,110.9941657
36.6,8.003595791,0.165405198,68927.84163,1.652802897,111.7110606
36.8,8.246675643,0.166990369,69240.93494,1.653238564,112.2808718
37,8.595278709,0.16858344,69943.61589,1.647139703,113.0489735
37.2,8.429545086,0.170231814,70538.62407,1.642783326,113.7168377
37.4,8.543825954,0.171875444,71373.72274,1.633634986,114.4282837
37.6,8.2468031,0.173566774,72578.14472,1.619258967,115.328211
37.8,8.376865986,0.175242513,73655.32557,1.607061174,116.0897745
38,8.565089965,0.176930836,74783.42996,1.596605938,117.0321957
38.2,8.55389253,0.178651263,75627.79173,1.590071398,117.8275322
38.4,8.713029189,0.180375929,76237.08364,1.588764509,118.617423
38.6,8.950268751,0.182112067,76571.41884,1.593992173,119.4737732
38.8,8.905826586,0.18388708,76543.06911,1.605318698,120.2680205
39,8.72511212,0.185690305,76835.13997,1.608368138,120.9489587
39.2,9.243191257,0.187458402,77284.58599,1.608368196,121.6713022
39.4,8.884656042,0.189311073,78157.6898,1.602704894,122.6496736
39.6,9.005553748,0.191145816,78828.75734,1.598784184,123.4221318
39.8,9.341654573,0.192982649,79789.32281,1.591814046,124.3950599
40,8.856811995,0.194900471,80166.64598,1.593556538,125.1391874
40.2,9.377369157,0.19676097,80065.27799,1.604447503,125.8430094
40.4,9.106895677,0.198700469,79789.26942,1.62013037,126.6688509
40.6,9.041654237,0.200643707,79627.67186,1.631021267,127.3007622
40.8,9.282185094,0.202583182,79619.53345,1.640605289,128.0797582
41,9.192010109,0.204567339,79722.54968,1.64626855,128.7192959
41.2,9.295434309,0.206556729,79958.18301,1.649318015,129.3708195
41.4,9.481946475,0.208559787,79944.31608,1.659773304,130.1803213
41.6,9.533847784,0.210593265,79666.71194,1.673713666,130.8536344
41.8,9.545031188,0.212650254,79222.8841,1.688960931,131.3221204
42,9.640133373,0.21472146,78726.86794,1.707693295,131.9115423
42.2,9.818323391,0.216807188,78657.36866,1.71640604,132.4236102
42.4,9.856086034,0.218924613,79082.60768,1.715534775,133.0206578
42.6,9.859777941,0.221065817,79748.32727,1.712049689,133.7702361
42.8,9.628318477,0.223246487,80465.92155,1.705515123,134.4141306
43,10.16794138,0.2253903,81479.46688,1.695059925,135.2606775
43.2,10.14087922,0.227598888,82037.31503,1.692010472,135.9437966
43.4,10.2858122,0.229816638,82333.70379,1.693753036,136.5964095
43.6,10.46813268,0.232053755,82457.28799,1.699416329,137.3307359
43.8,10.74184986,0.234306316,82512.91285,1.704643997,137.8831157
44,11.16762026,0.236569891,82269.53583,1.716841862,138.5248355
44.2,11.30672258,0.238878016,82173.79884,1.724683331,139.0641405
44.4,11.69094014,0.241190651,82122.79605,1.731653559,139.6078052
44.6,11.75525303,0.243550991,82505.6668,1.732089205,140.3061771
44.8,11.8237167,0.245934775,83135.13431,1.726425946,140.908673
45,11.75424523,0.248353041,84649.7751,1.707257951,141.7998858
45.2,11.93902887,0.250776149,86401.21623,1.684169261,142.678027
45.4,11.97756818,0.25323478,88167.37109,1.662387462,143.6106415
45.6,12.65175098,0.255669657,89998.38022,1.641477009,144.6881646
45.8,12.35791782,0.258202817,91298.09487,1.628407893,145.5891819
46,12.48036735,0.260729697,92243.78377,1.622744639,146.6242107
46.2,12.64020387,0.263279119,92437.94751,1.627536658,147.4293547
46.4,12.45853165,0.265880087,92733.50966,1.630586092,148.2671813
46.6,12.82691878,0.26846531,93240.84324,1.631893045,149.2520945
46.8,12.96430834,0.271094176,93249.97391,1.638863242,149.9461093
47,13.13326836,0.273746933,93603.31325,1.64278399,150.9016044
47.2,13.47422286,0.276413276,94139.87339,1.642348395,151.739435
47.4,13.35983349,0.279141105,94794.0431,1.642348385,152.7820882
47.6,13.56866442,0.281871732,95328.42089,1.641912775,153.6024861
47.8,13.55065208,0.284647176,96447.4003,1.634942596,154.6789147
48,13.71959044,0.287436239,97291.14822,1.631021893,155.5537871
48.2,13.46475943,0.29028526,98026.11507,1.629279321,156.4624307
48.4,13.80153301,0.293117847,99066.95583,1.625358636,157.6227544
48.6,13.72616984,0.296010377,99689.95307,1.624922994,158.509609
48.8,13.76796061,0.298922965,100341.2239,1.625794273,159.602381
49,13.64688805,0.301877144,101058.3409,1.623180445,160.4870568
49.2,13.78256248,0.304841534,101906.8196,1.619259737,161.4425524
49.4,14.26056782,0.307809609,102759.4154,1.617517249,162.6715158
49.6,14.62348716,0.310816264,103362.4408,1.617081657,163.6063122
49.8,14.32416501,0.313903629,103817.6828,1.620566715,164.6838287
50,14.78470674,0.316964178,103438.7,1.633635857,165.4334107
50.2,14.83352678,0.320086917,102827.7911,1.650190041,166.1633779
50.4,15.04810748,0.323236337,102243.5838,1.669358063,167.079652
50.6,14.90539106,0.326444688,101868.4591,1.682427136,167.735532
50.8,15.24667816,0.329632567,101027.6028,1.703773355,168.4513386
51,15.29464835,0.332874573,100903.8773,1.713357361,169.1540684
51.2,15.01897189,0.336182035,101048.1741,1.719020601,169.9167185
51.4,15.37561407,0.339474439,101347.4413,1.721198828,170.6554049
51.6,15.60345965,0.342809798,101613.1714,1.725119585,171.5052195
51.8,15.60321459,0.346196129,102042.6391,1.724248315,172.1643687
52,15.81775488,0.349599902,102645.0761,1.722505798,173.0523155
52.2,15.92842574,0.353045832,102923.3209,1.724683996,173.783373
52.4,15.70506452,0.356551786,102641.8995,1.735574877,174.4305364
52.6,15.81572429,0.360067523,102686.934,1.742109438,175.1931903
52.8,16.54125323,0.363571837,102969.4339,1.743852075,175.8294662
53,16.46577751,0.367172365,103304.5687,1.746465886,176.6367876
53.2,16.71684443,0.370784121,104020.5813,1.742109556,177.3711146
53.4,17.0036348,0.374429462,105301.6762,1.729911778,178.2492569
53.6,16.97799647,0.378135171,106581.8578,1.719456506,179.2614059
53.8,17.44757574,0.381840461,107871.5913,1.70943693,180.2811843
54,17.31473793,0.38562878,108688.017,1.705080553,181.1092063
54.2,17.65219024,0.389419364,109239.9145,1.70464496,181.9230684
54.4,17.87912521,0.39325654,109663.2833,1.708130081,182.9482932
54.6,17.96646083,0.397142825,109995.6164,1.710308275,183.7142151
54.8,18.06791576,0.401067096,110404.7791,1.712486472,184.6707996
55,18.18598268,0.405029381,111236.9178,1.706823216,185.5020913
55.2,18.27496136,0.409033658,112354.4058,1.697674866,186.4368868
55.4,18.28084245,0.413084489,113775.3734,1.686783958,187.6811003
55.6,18.46370131,0.417162649,114820.9612,1.679378164,188.6257013
55.8,18.28843058,0.421308985,115880.81,1.674586148,189.8045422
56,18.77206648,0.425446817,116364.436,1.675893114,190.6685229
56.2,19.05378414,0.429641684,116639.3104,1.68024952,191.5390381
56.4,19.53989952,0.433862947,117482.2683,1.678942664,192.7222435
56.6,19.53826274,0.438163818,118390.3013,1.674586306,193.6701115
56.8,19.51584628,0.442509582,119934.8648,1.664131031,194.9513674
57,19.73189465,0.446880856,121529.1154,1.653240146,196.2446101
57.2,19.9786798,0.451293653,122856.3405,1.644963089,197.3776962
57.4,20.40078038,0.455737468,123123.2026,1.650190778,198.4127286
57.6,19.90471594,0.460295693,122876.4118,1.662824177,199.5240175
57.8,20.3783187,0.464826004,122073.5762,1.679814054,200.257258
58,20.39408162,0.469436708,120435.7247,1.708566066,201.0340747
58.2,20.14394528,0.474113987,119372.5483,1.728605309,201.6354779
58.4,19.99517275,0.478830583,119201.0603,1.737318024,202.3796075
58.6,20.20617767,0.483567026,119400.4236,1.742110055,203.3024191
58.8,20.46204429,0.488347691,120236.3741,1.737318088,204.151145
59,20.27087253,0.493210341,121826.5365,1.725120248,205.2973014
59.2,20.60732225,0.498081646,123192.0899,1.714665017,206.3040063
59.4,20.7144324,0.503019507,123963.266,1.712051214,207.2965456
59.6,20.80325458,0.508008493,124800.5767,1.709437409,208.4230929
59.8,20.6934808,0.513062528,125039.6507,1.712486853,209.2772625
60,21.01826606,0.518134168,125258.114,1.716407623,210.3046676
60.2,21.36381601,0.523255278,125370.6852,1.720764032,211.1381417
60.4,21.76336708,0.528423833,126039.1977,1.719457174,212.1099829
60.6,21.70424631,0.533679328,126776.3379,1.718585896,213.2038441
60.8,21.86780165,0.538970547,127660.4432,1.71466519,214.1517142
61,22.14518354,0.54430621,128068.9436,1.718150318,215.199819
61.2,22.07855923,0.549721665,128264.9126,1.722506678,216.0256625
61.4,22.72152539,0.555137422,127761.6835,1.735140217,216.7817851
61.6,22.70390759,0.560658023,126806.0335,1.754308224,217.5520642
61.8,22.83667612,0.566222589,125934.1927,1.772604977,218.2112151
62,23.04421785,0.571837482,126148.027,1.776090098,218.8899782
62.2,22.84460358,0.577539706,126602.855,1.776525712,219.6232125
62.4,22.92084311,0.583278179,127988.8668,1.767377357,220.7192534
62.6,23.19649242,0.58905923,129582.102,1.753872662,221.666036
62.8,23.29764093,0.594911548,131565.5249,1.737318489,222.9156972
63,23.50846053,0.600814276,132513.5279,1.731655242,223.8406884
63.2,24.01507553,0.606753753,133222.5926,1.729041488,224.7842047
63.4,24.73273284,0.612736778,133305.6522,1.734704854,225.8301362
63.6,25.20359958,0.618798928,132807.7332,1.746902738,226.7191761
63.8,25.28392778,0.62495174,132518.3817,1.755615483,227.4044756
64,25.11164877,0.631185484,132904.4738,1.758229284,228.3784899
64.2,25.535955,0.637436337,133503.92,1.757358066,229.2217708
64.4,25.31629403,0.643799102,134649.6494,1.750823492,230.1957847
64.6,25.5070937,0.650194503,136475.9913,1.738190057,231.438911
64.8,25.72862691,0.656651884,138184.1592,1.725992262,232.526239
65,25.73494344,0.663190621,139409.3186,1.720764626,233.7562888
65.2,26.96850738,0.669701728,139988.0932,1.721636052,234.7466617
65.4,26.86096806,0.676380221,140448.9126,1.723814224,235.7315718
65.6,27.39571351,0.683076967,140411.2406,1.732091389,236.7720543
65.8,27.82159875,0.689849105,139975.3269,1.742982361,237.5249072
66,28.07131971,0.696702704,140336.8751,1.746467488,238.5534015
66.2,28.1290889,0.703639762,141201.0467,1.742982404,239.514345
66.4,28.47268096,0.710624876,141965.2748,1.740804265,240.5145131
66.6,28.53873705,0.717701139,143427.4031,1.732527179,241.801219
66.8,28.77511891,0.724835704,144309.441,1.729042116,242.8101027
67,28.85527782,0.732053703,144427.2333,1.734705406,243.9192183
67.2,28.91382143,0.739346139,143908.0673,1.746031971,244.7003937
67.4,29.34127862,0.746683939,143627.6155,1.755180397,245.5164377
67.6,29.28596379,0.754132174,143122.7342,1.767378222,246.3869508
67.8,29.39391142,0.761642884,143432.7936,1.769556422,247.1681267
68,29.66221321,0.769216887,144182.0554,1.768685184,248.2009799
68.2,29.79921868,0.776877019,145234.5039,1.763021926,249.1357759
68.4,30.26192354,0.784628355,146436.9241,1.757358709,250.3799959
68.6,30.10642305,0.792465875,147588.9116,1.750388504,251.3463842
68.8,30.21597753,0.800322344,148560.3885,1.746903426,252.5568246
69,30.58475795,0.808277729,149752.4707,1.739497649,253.5907685
69.2,31.64152153,0.81626074,151022.8656,1.73296323,254.8578756
69.4,31.72319614,0.824398062,152268.6195,1.727299964,256.1020903
69.6,32.26850721,0.832581538,152720.1912,1.72904258,257.0968143
69.8,32.69664653,0.84085602,153186.0927,1.732092093,258.3181543
70,32.35451631,0.849272328,152899.0209,1.742111701,259.3411949
70.2,33.13161242,0.857688043,152696.9084,1.748646352,260.0101605
70.4,33.4475384,0.866223396,152448.0424,1.758230405,261.1203686
70.6,33.69947047,0.874849265,153066.8908,1.756923529,262.045362
70.8,34.11009314,0.883549868,154155.8958,1.752131576,263.2754173
71,34.39191039,0.892347733,155755.4959,1.742983239,264.6089742
71.2,34.67371362,0.901233868,157382.5238,1.733399264,265.824865
71.4,34.66385217,0.910231481,159228.4234,1.722508343,267.1300916
71.6,35.07940384,0.919287203,160411.2962,1.718152027,268.3024029
71.8,35.26311629,0.928451592,161161.7546,1.7198946,269.6512118
72,35.5780984,0.937697988,161185.6946,1.726429195,270.630681
72.2,35.92713323,0.947034455,160676.7433,1.738191438,271.5480488
72.4,36.11329417,0.956477128,160042.5381,1.752131846,272.622303
72.6,36.44152621,0.966003736,159729.4284,1.76215154,273.6399043
72.8,36.89687276,0.975616424,159961.7009,1.765201056,274.5104237
73,37.35968219,0.985325113,160698.0663,1.764765482,275.6685737
73.2,37.3239282,0.995169115,161809.562,1.759973469,276.7558995
73.4,37.6595767,1.005083881,163107.0879,1.753874593,277.9336572
73.6,37.71602253,1.015119388,164981.5423,1.743419317,279.3718044
73.8,38.35076798,1.025211798,166497.2292,1.735142291,280.549568
74,38.34652497,1.035454319,168337.5392,1.725558288,282.0639786
74.2,38.54667031,1.045784015,169889.2041,1.717716843,283.3986246
74.4,38.79831576,1.056213677,171076.5247,1.713360502,284.7648671
74.6,39.24022375,1.066733529,171583.2504,1.714667474,285.9360907
74.8,39.76188264,1.077352987,171965.8649,1.718588273,287.3491856
75,40.0691489,1.088095556,172287.727,1.721637767,288.4299786
75.2,40.57000086,1.098931327,172901.0647,1.722944742,289.6317095
75.4,40.81159049,1.109895877,174208.7032,1.720330955,291.2311059
75.6,40.78062302,1.120991186,176258.1387,1.711182575,292.8817052
75.8,41.33127728,1.132153634,177745.7762,1.705519366,294.23052
76,41.73234929,1.143439656,178834.1068,1.704648142,295.7906984
76.2,42.06194472,1.15484461,179256.3953,1.707697645,297.0294685
76.4,42.06829656,1.166388745,179337.7166,1.713796568,298.2606115
76.6,42.3155949,1.178030473,178272.1141,1.730350813,299.4852165
76.8,42.77226489,1.189773191,178135.2207,1.737321065,300.490836
77,42.91649262,1.201657729,179006.7091,1.737321087,301.9311636
77.2,42.96846998,1.213668466,180394.9904,1.73209345,303.2244081
77.4,43.87211464,1.225735203,181749.1306,1.727737191,304.5841232
77.6,44.25226443,1.237963091,183792.8391,1.719024496,306.2630554
77.8,45.01544593,1.250284658,185199.9236,1.713796944,307.6020697
78,45.31163429,1.262765396,186491.5073,1.711183159,309.2297946
78.2,46.04486337,1.275338329,187431.0664,1.710311976,310.6167452
78.4,46.02526448,1.288094916,188839.6462,1.705955604,312.1148142
78.6,46.55903381,1.300937558,190497.9246,1.70116366,313.8765521
78.8,46.92244531,1.313922238,191542.9945,1.701599344,315.5424102
79,47.10552777,1.327051112,192310.6433,1.702470643,316.8563571
79.2,47.36835701,1.34030577,192986.8236,1.704213227,318.2258692
79.4,47.9909508,1.353666244,193286.5935,1.709005315,319.63243
79.6,48.32519615,1.367182906,193675.8986,1.71379737,321.235098
79.8,48.58879223,1.380840704,194529.415,1.714668679,322.8650017
80,49.18223934,1.394610766,195078.3951,1.715975666,324.1081362
80.2,49.63357818,1.40853003,195801.9869,1.716846998,325.5059791
80.4,49.87384266,1.422605063,196654.1974,1.71858958,327.2132371
80.6,49.96618199,1.43683261,197906.8552,1.715540132,328.6415807
80.8,50.09588973,1.451200218,199208.8492,1.713361963,330.3346744
81,50.67260629,1.46567828,200009.2148,1.713797673,331.7107279
81.2,50.98673089,1.48032177,200756.5249,1.714668989,333.1118378
81.4,51.65230879,1.495085739,202715.237,1.709005785,335.1285227
81.6,51.79272538,1.510037945,203436.0528,1.710312717,336.5405239
81.8,52.3203241,1.525110928,205166.0956,1.705520771,338.3600075
82,52.7614837,1.540341932,207836.8061,1.69462989,340.3941205
82.2,52.90764443,1.5557484,210043.5533,1.686788435,342.2691618
82.4,53.6271114,1.571265994,211133.8472,1.685917248,343.8337037
82.6,54.24268934,1.586947359,212642.0296,1.683739136,345.7882874
82.8,54.72861964,1.602796125,213193.0211,1.68678866,347.2820072
83,55.25856308,1.61880088,213171.6568,1.69506584,349.0252252
83.2,55.64888737,1.634977033,212608.9102,1.705521192,350.4099934
83.4,55.77246231,1.651336047,212156.8933,1.715540874,351.7838622
83.6,55.96082246,1.667854388,212594.3339,1.719897276,353.4028715
83.8,56.47155101,1.68451433,213016.8364,1.724689355,355.0665544
84,56.88669783,1.701348845,213455.8484,1.727738872,356.3478212
84.2,57.71976778,1.718320616,214749.7808,1.725560788,357.8578908
84.4,57.85484244,1.735516136,216938.7854,1.719026242,359.9366704
84.6,58.54826421,1.752841991,218032.3813,1.718155054,361.4587216
84.8,58.88021036,1.770370213,219129.8109,1.718590734,363.2825603
85,59.41279441,1.788059283,220208.5572,1.717719527,364.8035204
85.2,59.63043358,1.805950069,221338.0757,1.716412643,366.384396
85.4,60.14925077,1.823997546,222652.2832,1.715977071,368.374933
85.6,60.82757476,1.842214295,223781.015,1.716412793,370.2543434
85.8,61.05260569,1.86064866,225012.4656,1.714670272,371.8025351
86,61.46745626,1.879347802,226496.6723,1.712927774,373.7059095
86.2,61.914282,1.898139293,226930.804,1.717284209,375.2486584
86.4,62.89287842,1.916983565,227048.9361,1.723383261,376.7543734
86.6,63.23287153,1.936161328,227470.0431,1.728175321,378.5150223
86.8,63.40540466,1.955544623,227475.4243,1.734274275,379.8736391
87,64.00042715,1.975090001,227346.6723,1.742115832,381.4784917
87.2,64.40846266,1.994845474,227608.2601,1.746036626,382.8512788
87.4,64.69930764,2.014808311,228774.7176,1.744294114,384.3842188
87.6,65.30669933,2.034947746,229955.4709,1.743858553,386.1753786
87.8,65.96225197,2.055285763,231771.5274,1.73906662,388.0918324
88,66.52554061,2.075835044,233199.069,1.735581588,389.6313153
88.2,67.43528805,2.096564492,235124.8284,1.729047133,391.3538432
88.4,67.83897507,2.11754091,236847.0461,1.725562082,393.5088928
88.6,68.07561468,2.138740668,237971.496,1.723819561,395.1050253
88.8,68.39614287,2.160147013,239520.1649,1.721205775,397.1347811
89,69.13707998,2.181736424,240962.1273,1.718156402,398.7908452
89.2,69.94777954,2.203537465,241824.7508,1.719463417,400.4392841
89.4,70.35046488,2.225588769,242790.8372,1.722512936,402.5256967
89.6,71.32893939,2.247817598,244257.5922,1.721641782,404.4770212
89.8,71.44488832,2.27033514,244714.7965,1.725562541,405.977276
90,72.12997835,2.293035503,244079.5544,1.737324857,407.635517
90.2,72.56575756,2.315982753,244053.6416,1.743859486,409.0595127
90.4,73.18762524,2.339146131,243486.6828,1.75475052,410.7351844
90.6,73.87426739,2.362537214,242894.6565,1.763898998,411.924941
90.8,74.57582871,2.386162088,243144.5334,1.768255482,413.5069173
91,74.99899559,2.410045603,244570.7083,1.764334794,415.0256994
91.2,75.63151511,2.434152945,245944.9875,1.760849765,416.5956895
91.4,76.17675,2.458509279,248700.0502,1.750830158,418.8259208
91.6,76.89394555,2.483097284,250963.8001,1.742553121,420.6040107
91.8,77.24882264,2.5079597,253184.4459,1.736454231,422.7340038
92,78.04736904,2.533038261,254516.2897,1.734276138,424.3769967
92.2,78.23847598,2.558414986,256360.7891,1.729919784,426.236789
92.4,79.05605293,2.583998975,258905.2578,1.723385309,428.6130205
92.6,79.52294255,2.609866799,261076.8812,1.719028985,430.8802942
92.8,79.98148174,2.635995002,263161.4974,1.713801386,432.7553454
93,80.32198915,2.662394793,266009.8081,1.70595994,435.1010611
93.2,80.98235705,2.689035442,266874.8922,1.708138215,436.9456106
93.4,81.67342633,2.715941403,267035.3347,1.714237236,438.7542071
93.6,82.21322596,2.743129174,267014.6107,1.722078798,440.7654488
93.8,82.84438295,2.770583179,266561.0947,1.730791652,442.303848
94,83.55360223,2.798307187,265363.5868,1.744732171,443.9936876
94.2,84.42896051,2.826297032,265511.031,1.749959941,445.5734922
94.4,84.76584044,2.854609144,267104.5546,1.748217438,447.7350833
94.6,85.56383369,2.883170483,268511.6792,1.746039347,449.4728652
94.8,86.35513404,2.912019251,270316.45,1.742554339,451.6333739
95,87.25274565,2.941149854,271353.0395,1.742554452,453.6228363
95.2,87.9824657,2.970585779,271487.2133,1.74734657,455.3769596
95.4,88.61741432,3.000324627,270747.0811,1.756495063,456.7464839
95.6,89.29469218,3.030359214,270469.2774,1.764336647,458.4047296
95.8,90.1414291,3.060682591,271171.3781,1.76607931,459.9387757
96,90.93743171,3.091314554,273562.5966,1.760416109,462.0339169
96.2,91.30380159,3.122286927,277142.0683,1.747346996,464.1028998
96.4,91.89197676,3.153553491,281153.2321,1.732535353,466.4072218
96.6,92.67287466,3.185119684,285653.817,1.716852456,469.1724101
96.8,93.0208146,3.217035934,288499.5681,1.708575364,471.326374
97,94.25030624,3.249205735,290612.5335,1.705961682,473.8714939
97.2,94.85572807,3.281746352,290785.0965,1.712060702,475.7552655
97.4,95.80509756,3.314587574,290955.6183,1.71990232,478.0824771
97.6,96.45528456,3.347781595,290900.9772,1.726436986,479.7832141
97.8,96.70740939,3.381339326,290671.0209,1.735149798,481.8391241
98,97.71644598,3.415176603,290778.1956,1.74124887,483.8057061
98.2,98.23020205,3.44939163,291263.8915,1.744734048,485.6633313
98.4,99.06713022,3.483925854,292075.0834,1.746476711,487.4915446
98.6,99.8990178,3.518807313,293860.1598,1.744298621,489.7479368
98.8,100.8704438,3.554028663,295753.3057,1.740377993,491.6164665
99,101.6756302,3.589616541,298392.4329,1.734714787,494.094028
99.2,102.4217647,3.625566478,300502.8717,1.73079413,496.2458238
99.4,102.9376777,3.661895099,302078.2316,1.730794196,498.7789421
99.6,103.9113681,3.69855387,302469.6413,1.73515071,500.6104295
99.8,104.423841,3.735616024,301809.0975,1.745170476,502.59008
100,105.2104574,3.773029581,301176.4691,1.753447721,504.130664
100.2,106.1706758,3.810806025,301052.4654,1.759546792,505.8281416
100.4,107.0784862,3.848966032,301223.7396,1.766081497,507.8960508
100.6,107.5167673,3.887545034,301818.1938,1.769566669,509.8593558
100.8,108.9146967,3.926438458,303938.8506,1.764774815,511.7551343
101,109.9320037,3.965751854,306619.3461,1.757369076,513.7762
101.2,110.899393,4.005464001,309065.4383,1.751705888,515.901857
101.4,111.6290764,4.045593188,312273.3803,1.742993194,518.6387206
101.6,112.8979615,4.086084453,315582.5897,1.733844925,521.3745094
101.8,113.8227819,4.127008878,317345.8603,1.730795565,523.4021091
102,114.3827642,4.168372003,318953.9544,1.730359998,525.9864376
102.2,115.3419362,4.210121963,321357.0568,1.725132444,528.3441599
102.4,116.3251382,4.252290147,324065.7751,1.719469253,530.756358
102.6,117.4412198,4.294871966,327488.6603,1.712499159,533.6926137
102.8,118.3681995,4.337895995,329610.7837,1.709885437,536.0318139
103,119.1364053,4.381364409,330953.8849,1.712063731,538.719653
103.2,119.9319619,4.42526743,330286.5261,1.722083542,540.7853844
103.4,120.875352,4.46960047,329214.0719,1.733410292,542.6430212
103.6,121.8502283,4.514489262,327538.9151,1.747786525,544.6956826
103.8,122.9181135,4.559710531,327523.3797,1.753449977,546.4934019
104,123.6951233,4.605294239,329587.4446,1.751271878,548.985132
104.2,124.4495887,4.651568761,332008.0049,1.746479937,551.1532753
104.4,125.6032739,4.698044079,335132.1588,1.740816765,554.0819094
104.6,126.6060548,4.745113144,337745.232,1.736024853,556.3807998
104.8,127.4392533,4.792668071,339432.3768,1.736460598,559.0076302
105,128.4186175,4.840689631,340005.7942,1.739945841,561.0232511
105.2,129.5009391,4.889185923,341368.5713,1.739945978,563.2001208
105.4,130.1378107,4.938203276,342973.6438,1.739946059,565.9631354
105.6,131.3196869,4.987671805,344635.1922,1.737768008,568.2130049
105.8,132.4998224,5.037637411,347183.6353,1.732976116,571.0054522
106,133.7878977,5.088096833,349562.0227,1.728184236,573.3577397
106.2,134.6994861,5.139091888,350788.3809,1.729055631,575.7187349
106.4,135.6882687,5.190593277,352524.8308,1.730362675,578.6157688
106.6,136.9802546,5.242589141,354519.2952,1.730798477,581.3374011
106.8,138.0519639,5.295124405,355969.9952,1.731669892,583.5970751
107,138.6865258,5.34822055,357909.4035,1.731669973,586.3797033
107.2,139.7630521,5.40181668,361022.4943,1.725571144,589.0359602
107.4,141.0895996,5.45593224,363185.8565,1.723393107,591.7161938
107.6,141.8310935,5.510635895,364125.0896,1.726442684,594.4737655
107.8,142.8142978,5.565869802,364490.2322,1.730799211,596.6103247
108,144.0292407,5.621640367,364597.4264,1.737769609,599.2600493
108.2,145.4551483,5.677954999,364557.12,1.744304395,601.4020674
108.4,146.5560765,5.734859707,366051.6627,1.744304534,603.6737302
108.6,147.6577449,5.792336045,368491.4039,1.74169083,606.5653249
108.8,148.8457372,5.850383279,370417.3181,1.739512772,608.8925552
109,149.9347574,5.909021151,373432.9531,1.73472086,611.9922465
109.2,151.2904095,5.968227688,375998.5587,1.730364628,614.6038415
109.4,152.4847686,6.028041442,377698.3144,1.729929138,617.2110771
109.6,153.7978539,6.088447095,379718.0714,1.729929298,620.2759135
109.8,154.7178176,6.149489526,382093.7734,1.727315569,622.8384721
110,155.9766993,6.211119543,385428.3338,1.722523682,626.0144325
110.2,157.0609894,6.273381931,386684.4944,1.72470202,628.5868017
110.4,158.2997314,6.336258272,387356.819,1.730365501,631.5982489
110.6,159.6322672,6.399759139,389212.1848,1.72949439,634.0714809
110.8,160.8699766,6.463905214,391008.2628,1.729930183,637.1363148
111,161.874095,6.528713587,390991.8132,1.735157999,639.2815944
111.2,163.3641988,6.594135958,393261.6245,1.732544345,641.9934352
111.4,164.6423133,6.660231933,398244.4084,1.721653479,645.8133028
111.6,165.7150849,6.727007503,400181.0865,1.720346692,648.448868
111.8,167.0569683,6.794433481,401534.8812,1.723396341,651.6281033
112,167.9600179,6.862570323,404110.3929,1.720346966,654.3137788
112.2,169.9597748,6.93130822,405990.0176,1.720347217,657.1988702
112.4,171.2016218,7.000794404,407821.1923,1.722089938,660.5970994
112.6,172.3976573,7.070982149,409830.7046,1.722090087,663.8220947
112.8,173.8810797,7.141853201,411634.2412,1.721218988,666.4870897
113,174.9755178,7.213465912,413933.7215,1.720347842,669.8482707
113.2,176.5476216,7.285761772,414264.0225,1.726011376,672.3901537
113.4,177.5504286,7.358827406,414787.451,1.730803558,674.9701531
113.6,179.1788032,7.432579416,415114.188,1.737774025,677.9129779
113.8,180.457242,7.507099154,415167.2389,1.745615734,680.7403057
114,181.9191957,7.582353543,414624.0492,1.753457467,682.8409347
114.2,183.5447211,7.658351721,415852.4851,1.754764597,685.369749
114.4,184.6724028,7.735151332,416573.5738,1.759121157,688.2809638
114.6,186.1564277,7.81269529,417985.1878,1.760428271,691.1398951
114.8,187.6378361,7.891018595,419872.246,1.759121533,693.566291
115,188.9811865,7.970139385,424033.6758,1.751715793,696.8555759
115.2,190.3651258,8.050051971,427352.2876,1.746923907,699.748281
115.4,191.874407,8.130757939,430817.4263,1.741696394,702.7641068
115.6,192.9822237,8.212305317,435716.6955,1.732983695,706.3944016
115.8,194.3084431,8.294655292,439487.7302,1.726884874,709.3797113
116,195.7151306,8.37782648,442663.3688,1.724271197,712.9675297
116.2,197.3335707,8.461817226,444486.8185,1.72470704,715.8820334
116.4,198.7657501,8.54666596,446613.3718,1.726014145,719.5504757
116.6,200.2302002,8.632364789,446104.3028,1.733855886,722.070572
116.8,201.8008718,8.718916472,444816.9661,1.744747138,724.8902895
117,203.4029803,8.806335309,443202.9135,1.755202754,727.0802694
117.2,205.2326225,8.894615331,441696.5608,1.765222759,729.3192844
117.4,206.7563441,8.983805357,440470.2301,1.774807085,732.0561976
117.6,208.2159423,9.073896463,442373.022,1.772193418,734.5468809
117.8,209.6695803,9.164893187,444625.4055,1.770451034,737.64442
118,211.2817796,9.256791937,448499.1437,1.763916602,740.9369921
118.2,212.9769247,9.349607876,452990.1457,1.755639608,744.0476184
118.4,214.6436703,9.443358507,456975.187,1.749540821,747.1310029
118.6,216.1091828,9.53806628,458991.7298,1.751283577,750.334228
118.8,218.0530801,9.634170482,461617.5711,1.750412536,753.6475122
119,219.6463278,9.730299671,463770.6188,1.749541452,756.3691798
119.2,220.9518451,9.827902451,465670.9562,1.749541617,759.2902174
119.4,222.9477049,9.926433413,468798.0875,1.74692801,762.8431983
119.6,225.0244226,10.02594961,473759.1888,1.737344125,766.1782824
119.8,226.6448034,10.12650395,480725.8915,1.723403752,770.4427038
120,228.3036617,10.22806575,486162.0923,1.714255454,774.3361471
120.2,230.2934407,10.33088083,491677.1952,1.705542836,778.3728773
120.4,231.5884848,10.43426327,494179.6991,1.705978639,782.1715219
120.6,233.7150786,10.5388817,492777.7684,1.71817691,785.538206
120.8,235.4704974,10.64457961,489613.6287,1.733860285,787.9319379
121,237.4243388,10.75132456,486667.3166,1.749979333,790.6906684
121.146,238.7457727,10.82993273,485057.623,1.75912801,792.2835823
121.4,240.3680881,10.83197234,485680.0436,1.764791579,795.6981963
121.6,241.6222485,10.83187578,488313.9054,1.763920451,799.1999476
121.8,242.687789,10.8317935,492539.2169,1.75825722,802.9043417
122,243.4554426,10.83173381,496072.5874,1.753465239,805.9299579
122.2,243.9896062,10.83169181,498216.8933,1.753465307,809.0775906
122.4,244.4855472,10.8316527,498368.3979,1.759128737,811.8711306
122.6,244.994783,10.83161259,498659.2903,1.76479217,814.9893457
122.8,245.5788022,10.83156681,497688.451,1.77394076,817.912541
123,245.9816796,10.83153476,496007.024,1.783524973,820.0828718
123.2,246.4892536,10.83149477,496716.0208,1.786138901,822.6694037
123.4,246.6270657,10.83148281,500209.2526,1.781782485,826.2473795
123.6,246.8895166,10.8314614,503934.5737,1.775683509,829.1792781
123.8,247.3422496,10.83142556,509800.028,1.76522812,833.1146281
124,247.4011236,10.83141958,515345.6809,1.755208326,836.5466058
124.2,247.7458363,10.83139194,518722.0893,1.751723221,839.8108116
124.4,247.8321309,10.83138388,521701.3352,1.750851947,843.7951733
124.6,248.0862726,10.8313631,522610.0497,1.753901487,846.6170316
124.8,248.0894746,10.83136133,522408.2556,1.761307432,849.9945333
125,248.2164847,10.83135019,520375.574,1.772198543,852.311938
125.2,248.250431,10.8313461,519756.813,1.779168849,854.8897358
125.4,248.7430484,10.83130724,517011.3335,1.793109512,857.616816
125.6,249.0578478,10.83128186,515028.7963,1.804436291,860.0497162
125.8,249.1059198,10.8312767,514099.5958,1.811842243,862.0119396
126,249.3409502,10.83125737,514793.7206,1.815763069,864.6845317
126.2,249.6657207,10.83123124,514018.4242,1.823169057,866.6358704
126.4,249.3382141,10.83125454,514961.1002,1.825347236,868.9020498
126.6,249.9288809,10.83120825,514425.0105,1.83231761,871.2129398
126.8,250.0093591,10.83120063,514058.2518,1.837545346,873.0378816
127,249.9460871,10.83120391,513248.2557,1.844515639,875.0872616
127.2,250.2633792,10.83117834,513869.9118,1.846258255,877.1497246
127.4,250.2042618,10.8311813,513464.9664,1.851050336,878.8962171
127.6,250.2099566,10.83117935,515020.0403,1.850614702,881.2691893
127.8,250.5048137,10.83115548,515772.5275,1.85235731,883.5255852
128,250.5304508,10.83115202,514502.0845,1.859327615,884.9659274
128.2,250.9316665,10.83112009,512635.3243,1.868476191,886.2777228
128.4,250.6955618,10.83113646,511630.2343,1.875882106,888.0165811
128.6,250.7344937,10.83113199,509548.4385,1.885466275,889.0461763
128.8,250.7875513,10.83112645,507876.09,1.894179165,890.3198237
129,251.0043014,10.8311085,509820.6529,1.89156534,892.1317059
129.2,251.0590209,10.83110284,511902.3197,1.887644551,893.8226313
129.4,251.0123673,10.83110485,513763.795,1.884159397,895.5821986
129.6,251.1335609,10.83109415,517462.5674,1.875446545,897.9017879
129.8,251.3237214,10.83107822,519553.6014,1.871525778,899.7278265
130,251.2695895,10.8310808,519083.3042,1.875882212,901.5113589
130.2,251.2478638,10.83108092,518014.2686,1.882416869,902.7893655
130.4,251.4155892,10.83106669,515794.2355,1.894179276,904.0782715
130.6,251.5467539,10.83105523,513956.39,1.903327817,904.8768938
130.8,251.8017266,10.83103439,511519.0627,1.914654593,905.6875062
131,251.7667061,10.83103552,510541.033,1.920317961,906.4305552
131.152,251.9616819,10.83101959,511425.5298,1.919882345,907.5233473
131.9,251.8677199,10.72006237,1.7977E+308,1.959961572,0
132.1,251.6521464,10.61182483,1.7977E+308,1.935129845,0
132.3,251.6542756,10.5035708,1.7977E+308,1.840595137,0
132.5,251.4204217,10.39533465,1.7977E+308,1.669387089,0
132.7,251.2023554,10.28709731,1.7977E+308,1.414099793,0
132.9,250.7798813,10.17887546,1.7977E+308,1.006337161,0
133.1,250.8185712,10.07061865,1.7977E+308,0.662614211,0
133.3,250.2540088,9.962407567,1.7977E+308,0.382495236,0
133.5,250.2760802,9.854152024,1.7977E+308,0.17643573,0
133.7,249.9674429,9.745921544,1.7977E+308,0.036158433,0
133.9,249.678748,9.637689552,1.7977E+308,0.025267338,0
134.1,249.2271915,9.529469903,1.7977E+308,0.023960406,0
134.3,249.2010692,9.421218012,1.7977E+308,0.026574268,0
134.5,248.8184796,9.312993136,1.7977E+308,0.037029717,0
134.7,249.0491134,9.204721788,1.7977E+308,0.044000018,0
134.9,248.6590455,9.096497478,1.7977E+308,0.044000017,0
135.1,248.3030455,8.988270587,1.7977E+308,0.039207935,0
135.3,248.2735995,8.880018949,1.7977E+308,0.028752485,0
135.5,247.9616387,8.77178872,1.7977E+308,0.013069311,0
135.7,247.658818,8.663557799,1.7977E+308,0.003049506,0
135.9,247.4424136,8.555320329,1.7977E+308,0.005663368,0
136.1,247.1105106,8.447091612,1.7977E+308,0.013940598,0
136.3,247.0379424,8.338301979,1.7977E+308,0.014376241,0
136.5,246.8098191,8.230606659,1.7977E+308,0.011326735,0
136.7,246.320871,8.122389843,1.7977E+308,0.013940597,0
136.9,246.2556952,8.014140912,1.7977E+308,0.013940597,0
137.1,245.8735211,7.905916005,1.7977E+308,0.014811884,0
137.3,245.8910224,7.797660808,1.7977E+308,0.013722775,0
137.5,245.6717098,7.689423558,1.7977E+308,0.010455447,0
137.7,245.5242724,7.581180861,1.7977E+308,0.01437624,0
137.9,245.2505341,7.472947736,1.7977E+308,0.021346538,0
138.1,245.0270669,7.364710801,1.7977E+308,0.028316835,0
138.3,244.7030577,7.256481486,1.7977E+308,0.028316835,0
138.5,244.6906457,7.148228556,1.7977E+308,0.02047525,0
138.7,244.1667988,7.040014385,1.7977E+308,0.008277228,0
138.9,243.6861601,6.93179694,1.7977E+308,0.015247525,0
139.1,243.6051967,6.823549205,1.7977E+308,0.026356436,0
139.3,243.1749151,6.714786682,1.7977E+308,0.026574257,0
139.5,243.0992666,6.607079806,1.7977E+308,0.023960396,0
139.7,242.8787077,6.498842651,1.7977E+308,0.021346534,0
139.9,242.5318481,6.390615067,1.7977E+308,0.022217821,0
140.1,242.537301,6.282360784,1.7977E+308,0.024831682,0
140.3,242.1572043,6.174135719,1.7977E+308,0.023089107,0
140.5,241.7430397,6.065913236,1.7977E+308,0.019603958,0
140.7,241.5690127,5.957672554,1.7977E+308,0.016990097,0
140.9,241.7215394,5.849407125,1.7977E+308,0.012198019,0
141.1,241.2724759,5.741187286,1.7977E+308,0.010019801,0
141.3,241.3576977,5.632926958,1.7977E+308,0.009584157,0
141.5,240.8961703,5.524708064,1.7977E+308,0.013069305,0
141.7,240.7171577,5.41646776,1.7977E+308,0.019168313,0
141.9,240.3320756,5.308243073,1.7977E+308,0.023089104,0
142.1,240.2552668,5.199995023,1.7977E+308,0.029623756,0
142.3,239.7804447,5.091777137,1.7977E+308,0.031366329,0
142.5,239.7451822,4.983525939,1.7977E+308,0.034415833,0
142.7,239.3808732,4.875299678,1.7977E+308,0.033544545,0
142.9,239.1985369,4.767059626,1.7977E+308,0.034851475,0
143.1,238.8982092,4.658828516,1.7977E+308,0.032673257,0
143.3,238.6585391,4.550592809,1.7977E+308,0.026574249,0
143.5,238.2834281,4.442367366,1.7977E+308,0.021346527,0
143.7,238.0670239,4.334129896,1.7977E+308,0.016990093,0
143.9,238.2694061,4.225860688,1.7977E+308,0.013504946,0
144.1,237.3591791,4.117675799,1.7977E+308,0.016118805,0
144.3,237.1884758,4.009434865,1.7977E+308,0.023089099,0
144.5,237.3119201,3.90117164,1.7977E+308,0.031366324,0
144.7,236.9850028,3.792942545,1.7977E+308,0.042693051,0
144.9,236.5243065,3.684723588,1.7977E+308,0.05706928,0
145.1,236.2713416,3.576488888,1.7977E+308,0.062296999,0
145.3,236.1197496,3.468246506,1.7977E+308,0.060554425,0
145.5,235.7255274,3.360022512,1.7977E+308,0.056633633,0
145.7,235.5157706,3.251784538,1.7977E+308,0.057069276,0
145.9,235.193008,3.143555128,1.7977E+308,0.050970268,0
146.1,234.9707873,3.035318099,1.7977E+308,0.045742548,0
146.3,235.0094772,2.927061296,1.7977E+308,0.047049478,0
146.5,234.5388099,2.818843095,1.7977E+308,0.044435617,0
146.7,233.9518131,2.71063371,1.7977E+308,0.033980176,0
146.9,233.8816518,2.602385157,1.7977E+308,0.026138597,0
147.1,233.4533617,2.494163744,1.7977E+308,0.01873266,0
147.3,233.4737712,2.385908327,1.7977E+308,0.007405936,0
147.5,233.0604378,2.277685781,1.7977E+308,0.00130693,0
147.7,232.2598933,2.16949258,1.7977E+308,0.002613859,0
147.9,232.1947175,2.061243649,1.7977E+308,0.003049503,0
148.1,231.9475692,1.953008508,1.7977E+308,0.007405935,0
148.3,231.7835133,1.844767071,1.7977E+308,0.013940583,0
148.5,231.46906,1.736537031,1.7977E+308,0.015683155,0
148.7,231.0382772,1.628315808,1.7977E+308,0.017861371,0
148.9,230.4546043,1.520106171,1.7977E+308,0.018732657,0
149.1,230.08531,1.411880287,1.7977E+308,0.018297013,0
149.3,230.0259507,1.303630915,1.7977E+308,0.013940581,0
149.5,229.8120394,1.195393256,1.7977E+308,0.007405934,0
149.7,229.0322682,1.08719848,1.7977E+308,0.005663361,0
224.9,229.1124615,0.984322214,1.7977E+308,0.046178197,0
225.1,228.548315,0.876111098,1.7977E+308,0.031366321,0
225.3,228.2583739,0.7678792,1.7977E+308,0.016554447,0
225.5,227.9451669,0.659649066,1.7977E+308,0.008277223,0
225.7,227.6751681,0.551415658,1.7977E+308,0.017425733,0
225.9,226.9697644,0.443215246,1.7977E+308,0.018297019,0
226.1,226.7325871,0.33497935,1.7977E+308,0.014811872,0
226.3,225.9465837,0.226785046,1.7977E+308,0.013069298,0
226.5,225.042589,0.118599685,1.7977E+308,0.004574254,0
226.7,223.7808811,0.010441432,1.7977E+308,0.006099005,0
226.71,223.6760417,0.005036684,1.7977E+308,0.006099005,0
,,,,,