File: TestGB3_6.csv
Time On Sample,Displacement Into Surface,Load On Sample,Harmonic Contact Stiffness,Harmonic Displacement,Harmonic Load
0,0,0,-355.2476324,0.340524611,2.200508242
0.2,0.158274576,0.000679577,4891.282008,0.213046166,2.273822053
0.4,0.351105903,0.001356788,11804.83789,0.168952595,2.331269453
0.6,0.283720728,0.002051817,16383.26663,0.147124094,2.393093774
0.8,0.288363482,0.002741914,21263.26618,0.124422453,2.565983037
1,0.428735162,0.003422716,25695.83523,0.109579073,2.724647243
1.2,0.478343326,0.004109734,28273.10052,0.105213373,2.881122977
1.4,0.428445029,0.004800741,29984.46371,0.104340233,3.036504455
1.6,0.796558815,0.00546057,30814.27366,0.106086512,3.174378215
1.8,0.657562686,0.006155123,31725.57777,0.117437333,3.62410913
2,0.834157127,0.006828066,33290.23397,0.124859022,4.050861131
2.2,0.557766687,0.007532027,34373.87415,0.133590423,4.475424611
2.4,0.55033602,0.00821757,33451.75859,0.150180084,4.890139991
2.6,0.854332459,0.00888179,32970.07105,0.169389163,5.44272914
2.8,0.723663259,0.009575772,33345.45004,0.188598244,6.136474649
3,0.851128825,0.010252079,32238.91684,0.216538724,6.808335485
3.2,0.746273101,0.010944294,31596.99429,0.242732925,7.471442389
3.4,0.628926985,0.011637364,31724.10228,0.263251716,8.133455059
3.6,0.772213714,0.012312588,31894.04066,0.279841376,8.69151537
3.8,1.042069749,0.012979145,33199.93579,0.297304175,9.629275583
4,1.01631984,0.013665943,34575.50075,0.310401275,10.49700463
4.2,1.013884932,0.014354569,35680.72665,0.324808085,11.37895871
4.4,0.980641187,0.015038456,36430.34856,0.341834316,12.2455935
4.6,0.807504256,0.015738771,36673.03166,0.360170257,12.97544875
4.8,0.932472142,0.016411825,36250.93851,0.395532427,14.06530772
5,0.692720184,0.017113277,35278.6381,0.43438716,15.01510431
5.2,0.646985649,0.017801444,34443.08862,0.468439621,15.77778669
5.4,0.687851164,0.018483681,33134.5704,0.515152612,16.68162553
5.6,0.445601127,0.019185304,31637.05771,0.570160435,17.63908178
5.8,0.712126392,0.019852088,30344.90654,0.625168254,18.5363553
6,0.977818963,0.02051893,29315.82196,0.672754382,19.24323181
6.2,0.758051633,0.021219014,28092.41088,0.732564476,20.07156821
6.4,0.632378588,0.021912654,26992.27859,0.792374569,20.83315628
6.6,0.641601777,0.022597058,26242.25035,0.84083384,21.476567
6.8,0.416838289,0.023297484,25686.81404,0.891039395,22.28520709
7,0.519323072,0.023975501,25026.97518,0.942991225,23.00193162
7.2,0.575177058,0.024656712,24270.50426,0.998872185,23.64643663
7.4,0.880006191,0.025320874,23563.08931,1.049514301,24.13337175
7.6,1.179839166,0.025985378,22947.77366,1.099283276,24.62577817
7.8,0.748567866,0.026699944,22181.51449,1.164332216,25.2133824
8,0.868539197,0.027376764,21803.35742,1.204496654,25.65654805
8.2,0.912735484,0.028058773,21600.13005,1.240295394,26.1883467
8.4,1.357457004,0.028713356,21660.88181,1.256885044,26.65558581
8.6,0.777966387,0.029438071,21558.03275,1.288318099,27.23771881
8.8,1.088624369,0.030101834,21430.566,1.312329442,27.62507857
9,1.251063032,0.030775747,21265.18544,1.342016198,28.0912232
9.2,1.351882428,0.031453878,21010.40749,1.371702956,28.43809609
9.4,1.04884582,0.032159663,20636.66095,1.411867405,28.82217259
9.6,1.322865317,0.032825935,20489.05356,1.436315318,29.15919746
9.8,1.486136673,0.03349979,20437.44599,1.454651254,29.48856259
10,1.158951974,0.034207229,20538.60812,1.466438653,29.88467564
10.2,1.523734985,0.034867286,20779.5376,1.466438643,30.23045455
10.4,1.502981234,0.035553742,21258.26595,1.457270674,30.6812797
10.6,1.852775772,0.036214825,21902.40709,1.436315305,31.11788014
10.8,1.824527786,0.036901795,22698.70833,1.408811394,31.57855341
11,1.847906752,0.037585229,23860.9003,1.369520095,32.15849845
11.2,2.022835805,0.038258286,24995.61022,1.33197507,32.65965877
11.4,1.899660842,0.038951755,26509.86004,1.285262084,33.32276549
11.6,2.045445647,0.039626808,27373.56021,1.265179861,33.81188909
11.8,1.962239937,0.04031754,28069.15145,1.258194742,34.42684956
12,1.878201535,0.04100833,28209.53237,1.272164985,34.95536539
12.2,2.317926891,0.041663255,28051.91565,1.293556904,35.33506577
12.4,2.345469321,0.042346404,27714.73818,1.325426513,35.7924564
12.6,1.924190343,0.043060286,27659.83445,1.341579614,36.17762692
12.8,1.987538563,0.043740984,27910.57964,1.348128162,36.71927375
13,2.101681042,0.044418203,28335.69364,1.342016179,37.16243943
13.2,2.198336973,0.04509662,29093.62696,1.324989947,37.72925374
13.4,2.125123577,0.045786668,29938.88128,1.308400289,38.33436611
13.6,1.954485125,0.046483387,30654.34564,1.295303194,38.85193944
13.8,2.059467984,0.047161234,31244.07644,1.287881501,39.37826703
14,1.823879495,0.047862401,31859.52608,1.282642666,39.97353113
14.2,2.120381694,0.048527133,32050.52944,1.29312034,40.53487444
14.4,2.087970244,0.049214388,32123.73269,1.30359802,40.96490916
14.6,2.063053029,0.049901129,32173.62176,1.319751111,41.5492311
14.8,2.027310808,0.050588611,32192.46304,1.333284782,41.98583107
15,2.291337988,0.051255567,32103.16925,1.353803566,42.49574545
15.2,2.151509169,0.051950177,32194.31053,1.363844679,42.91921454
15.4,2.195705455,0.052632186,32360.81586,1.373012648,43.42912847
15.6,2.029230467,0.05332862,32351.80945,1.386982893,43.85150333
15.8,2.17418258,0.05400373,32341.2329,1.404009119,44.38658487
16,2.272503896,0.054682033,32340.75339,1.418852497,44.87461418
16.2,2.210115506,0.05537134,32133.04119,1.438934718,45.22148689
16.4,1.954542391,0.056073875,31823.41892,1.466438635,45.6318249
16.6,2.361792729,0.056731024,31674.24146,1.484774564,45.97213303
16.8,2.391833237,0.057414002,31523.42095,1.507039634,46.40654466
17,2.47100262,0.058093616,31404.65863,1.524065861,46.72059049
17.2,2.325344952,0.058788625,31489.63129,1.534106976,47.12874021
17.4,2.377868165,0.059470064,31726.99837,1.536289824,47.54783265
17.6,2.37376827,0.06015538,31852.41783,1.541092094,47.90564776
17.8,2.452521306,0.060835022,32040.80801,1.545021222,48.35100199
18,2.56374936,0.061512441,32192.77716,1.547204069,48.68802678
18.2,2.602533142,0.06219482,32485.85839,1.545894358,49.13775778
18.4,2.422735071,0.062892167,32701.70988,1.545457793,49.48244182
18.6,2.552698713,0.063568303,33068.63026,1.5424018,49.94968073
18.8,2.637280598,0.064247546,33388.09033,1.539782378,50.34579429
19,2.581553751,0.064936397,33911.25587,1.531050979,50.84257743
19.2,2.54581153,0.06562388,34165.03986,1.532360691,51.27589472
19.4,2.540878942,0.066309253,34255.19164,1.538909241,51.61401354
19.6,2.626709866,0.066988411,34390.07822,1.544148078,51.98277125
19.8,2.626773434,0.067673441,34602.49813,1.548077209,52.44672722
20,2.6501524,0.068356876,34719.94613,1.555062328,52.86363104
20.2,2.691850608,0.069039056,35152.85413,1.549823487,53.33196413
20.4,3.049139375,0.069699625,35583.03168,1.541528647,53.71166471
20.6,2.86767592,0.070397086,36190.0941,1.530614402,54.2642534
20.8,2.807785609,0.071086222,36604.09327,1.524938994,54.6953823
21,2.978551195,0.071759564,37153.37266,1.51620759,55.23484097
21.2,2.844551191,0.072454085,37494.6256,1.512715034,55.64517906
21.4,3.086095042,0.07312792,37946.01668,1.508349327,56.1693185
21.6,2.943766723,0.073834951,38060.30019,1.515334451,56.5796568
21.8,3.221114741,0.074520274,38297.16298,1.521009853,57.10051356
22,3.091275175,0.075240534,38196.38269,1.536726377,57.46598822
22.2,3.181265244,0.075956538,37852.77824,1.562920574,57.8522536
22.4,2.992302819,0.076695221,37574.17457,1.585622219,58.21225678
22.6,3.168892086,0.077412606,37574.48833,1.595226754,58.554753
22.8,3.273868512,0.078145748,37570.20827,1.606577571,58.97275136
23,3.283917095,0.078892851,37888.09465,1.602211871,59.33603769
23.2,3.064141598,0.079663221,38575.49741,1.586058788,59.85032818
23.4,3.043378788,0.080427569,39299.64935,1.569469129,60.38322098
23.6,3.160009395,0.081190162,39819.1948,1.559428015,60.81544447
23.8,3.020169726,0.081978081,40546.99407,1.5437115,61.31769836
24,3.124308133,0.082757083,41084.94513,1.536289807,61.84949721
24.2,2.950326233,0.083563052,41477.51856,1.535416672,62.38238979
24.4,3.299274469,0.084341151,41762.85182,1.538472652,62.91200076
24.6,3.108636858,0.08516422,41896.81141,1.543711498,63.31686753
24.8,3.498385161,0.085955661,41866.75664,1.555062307,63.73048955
25,3.167853268,0.08680463,41929.47976,1.565103426,64.22070656
25.2,3.129595553,0.087642031,41991.62983,1.574271397,64.69232212
25.4,3.29201583,0.088473986,42132.06488,1.580383373,65.15518413
25.6,3.51438902,0.089310142,42386.44317,1.582129646,65.60163301
25.8,3.417839882,0.090176723,42822.48691,1.576890809,66.04260997
26,3.602739905,0.091032567,43404.13401,1.569032544,66.59848202
26.2,3.347144445,0.091927279,44063.2846,1.558554872,67.16420141
26.4,3.892598398,0.092775936,44531.75412,1.552442876,67.62049905
26.6,4.11746464,0.09365512,44954.97784,1.54851374,68.10962314
26.8,3.934310391,0.094571186,45395.98324,1.545894326,68.70926406
27,4.114209127,0.095471473,45700.25259,1.547640601,69.28920958
27.2,4.332410669,0.096378253,45948.09166,1.548950305,69.74878904
27.4,4.27082639,0.097313275,46369.62487,1.546767456,70.31669748
27.6,4.169271756,0.098260517,46860.60602,1.54109205,70.82551675
27.8,4.398295043,0.099194592,47518.66077,1.534543494,71.49081293
28,4.479930624,0.10014812,48270.15549,1.524938952,72.1539201
28.2,4.489953508,0.101116186,48819.94678,1.519263542,72.69228419
28.4,4.510800272,0.102093187,49487.11351,1.512714992,73.35976828
28.6,4.709842134,0.103067877,49890.10224,1.511841848,73.90250955
28.8,4.734850068,0.104064315,50240.19877,1.514897836,74.58640709
29,4.524204787,0.105086931,50431.45443,1.521446391,75.20136716
29.2,4.756550874,0.1060893,50705.23627,1.523629236,75.72331843
29.4,4.683297539,0.107122779,51048.3398,1.525812088,76.35031532
29.6,4.47514677,0.108175881,51331.17829,1.527558373,76.87007685
29.8,5.036402892,0.109186679,51706.11629,1.529741207,77.5506931
30,4.799105465,0.110262529,52084.92028,1.531050924,78.20176287
30.2,4.949841609,0.111322539,52193.90041,1.53934575,78.81125271
30.4,5.154701544,0.11238947,52110.11214,1.550696563,79.27083236
30.6,4.825804162,0.113503864,51934.8209,1.565103382,79.72931634
30.8,4.844971064,0.114605458,51932.31511,1.577763911,80.34537124
31,4.915763634,0.115714531,52086.81172,1.585185599,80.92969344
31.2,5.12727999,0.11682504,52282.01211,1.590861002,81.49979131
31.4,5.069835278,0.117965252,52567.23362,1.591734145,81.97578344
31.6,5.481195244,0.119084829,53164.95426,1.584312443,82.52727953
31.8,5.381280555,0.12025072,53735.54752,1.580383316,83.22211915
32,5.711033965,0.1213988,54261.46865,1.576890747,83.87209621
32.2,5.45956649,0.122598357,55105.17236,1.565539935,84.59100879
32.4,5.433757354,0.123794427,55744.93496,1.557681676,85.16657672
32.6,5.305525619,0.125009479,56220.00154,1.55506226,85.7684061
32.8,5.55366958,0.126210971,56894.68629,1.550259983,86.55625666
33,5.609460112,0.127437738,57208.11284,1.553752541,87.25109688
33.2,5.491216427,0.128688763,57029.81317,1.567286214,87.7456911
33.4,5.497042508,0.12994377,56788.39001,1.583875873,88.29609192
33.6,5.740184537,0.131195258,56631.11512,1.596536396,88.7556718
33.8,5.66190571,0.132481325,56420.98547,1.613562627,89.35531281
34,5.945013282,0.133761957,56313.10858,1.627096288,89.91556261
34.2,5.908366847,0.135064468,56479.02111,1.630588849,90.37842435
34.4,5.861725822,0.136387249,56735.57963,1.63320827,90.95508657
34.6,6.072385311,0.137705637,56886.55288,1.637573964,91.44749324
34.8,5.973281547,0.139058638,57026.80664,1.644122516,92.05807669
35,5.961608941,0.14041922,57321.78493,1.645432227,92.63802182
35.2,5.964090519,0.141792532,57602.54934,1.645868797,93.10854327
35.4,5.750486734,0.143194388,58189.16154,1.640193394,93.73335131
35.6,6.053567169,0.144574778,58630.50545,1.636700825,94.26515096
35.8,6.093931427,0.145987104,59356.87859,1.628405994,94.9818758
36,6.132628639,0.14741381,59852.58613,1.625786574,95.63075767
36.2,6.094716475,0.148859917,59938.57152,1.631025414,96.10893893
36.4,6.8083078,0.150269109,59767.92489,1.644559062,96.65387067
36.6,6.801618254,0.151741959,59812.46876,1.651544182,97.12220365
36.8,7.349500356,0.153191435,59957.98589,1.658092715,97.72403532
37,7.590949839,0.154676509,60390.83142,1.654600148,98.22847899
37.2,7.893184137,0.156172472,61392.99693,1.63975676,98.94739305
37.4,7.943943483,0.157700753,62855.87024,1.614872271,99.76807031
37.6,7.712418218,0.159263715,64073.05033,1.59522663,100.4968306
37.8,8.187014558,0.16079384,65812.94802,1.567286139,101.4761735
38,8.20446079,0.162370885,66977.06522,1.551133051,102.2377619
38.2,7.972097382,0.163980768,68335.14927,1.533670259,103.2083485
38.4,8.00952454,0.165588249,69354.50821,1.523629149,104.1154705
38.6,8.174351797,0.167203198,70269.09638,1.514897746,104.9098864
38.8,8.321690613,0.168835628,70767.52626,1.515334312,105.7064908
39,8.34995247,0.170492584,71355.02469,1.515334311,106.6311206
39.2,8.768745258,0.172139478,72102.37923,1.51271488,107.5798245
39.4,8.610480061,0.173842666,72893.26898,1.507039475,108.3808049
39.6,8.488850358,0.175568995,73780.16,1.500490929,109.2200835
39.8,8.385539902,0.177294012,75248.09996,1.487830403,110.4160833
40,8.611972735,0.179022381,76046.51425,1.484774408,111.2772477
40.2,8.46202642,0.180794163,76582.23012,1.489576681,112.295981
40.4,8.713435947,0.182555956,76819.89262,1.496998364,113.0958687
40.6,8.633431701,0.184358355,76771.09694,1.509658895,113.8880952
40.8,8.684990803,0.186169763,76726.54092,1.524938842,114.8849446
41,8.895592093,0.187988481,77003.44475,1.532360525,115.8456849
41.2,8.854718046,0.189842858,77144.7414,1.539345645,116.589765
41.4,9.4125479,0.191674615,77393.2735,1.546767319,117.5406585
41.6,9.539873487,0.193554338,77744.89399,1.550696445,118.4040112
41.8,9.694675732,0.195451092,78122.82707,1.55331586,119.2060872
42,10.05098738,0.197353139,78618.06606,1.55637184,120.1777703
42.2,9.978460069,0.199303803,79492.72661,1.550259863,121.0203318
42.4,10.0741344,0.201262511,80960.90653,1.536289622,122.150678
42.6,9.771779343,0.203268165,82396.24867,1.521882823,123.1508087
42.8,10.31543772,0.205235828,83506.72195,1.514024549,124.1826757
43,10.30202238,0.207261553,84682.49397,1.50660286,125.3863354
43.2,10.1512104,0.209317001,85276.134,1.506602864,126.3273778
43.4,10.6040982,0.211351632,85524.79575,1.514461111,127.3833178
43.6,10.40331986,0.213451704,85430.16419,1.526248505,128.255423
43.8,10.44901611,0.215555887,85609.30763,1.534106763,129.1789584
44,10.40810985,0.217687285,85706.56313,1.545021012,130.2075404
44.2,10.45213577,0.219834083,85793.77643,1.55331584,131.0380658
44.4,10.3687572,0.222011179,85888.40211,1.562920381,132.0305378
44.6,10.6933955,0.224182189,85938.24355,1.571215201,132.8490277
44.8,10.54089836,0.226407721,85975.7173,1.581692884,133.8524417
45,10.56659485,0.22864335,86135.57257,1.587368292,134.6391976
45.2,10.52400793,0.230906197,86033.40393,1.599592252,135.5594501
45.4,10.62380882,0.233181909,85915.20713,1.611816207,136.4260854
45.6,10.60869545,0.235488482,85869.50913,1.622293888,137.2237838
45.8,11.00326419,0.23779002,85701.05792,1.633644693,137.8923636
46,11.0722474,0.240137099,85531.61194,1.64717836,138.7064753
46.2,11.2053452,0.242503339,85679.55401,1.652853764,139.4013164
46.4,10.97288815,0.244918489,86040.55549,1.656782902,140.2832692
46.6,11.40241897,0.247312256,86642.04769,1.654600039,141.0733098
46.8,11.64042765,0.249743482,87770.35431,1.643685785,141.9793385
47,11.43044484,0.25222988,89121.64041,1.630588692,143.0648198
47.2,11.61682084,0.254714001,90109.12822,1.622730429,143.951152
47.4,11.76239199,0.257225892,91434.60868,1.612252746,145.0891584
47.6,11.89963329,0.259763512,92292.46343,1.608760182,146.0728774
47.8,11.85034844,0.262339604,92604.90124,1.613125883,146.901214
48,11.59205475,0.264955766,92744.35978,1.622293859,147.8597644
48.2,11.77008895,0.267568297,92918.56528,1.628405834,148.6399549
48.4,11.83237581,0.270215076,92790.85704,1.64062979,149.5251923
48.6,12.45422905,0.272849957,92742.46671,1.650234309,150.3207052
48.8,12.18842885,0.275572256,93075.87866,1.652853737,151.0965173
49,12.56213341,0.278278063,93242.11172,1.658092564,151.8395057
49.2,12.65022123,0.281030632,93402.35518,1.66507768,152.742251
49.4,12.7316443,0.283811284,93771.63119,1.668133667,153.6263943
49.6,13.05787575,0.286603131,94029.84903,1.671626217,154.3726652
49.8,13.65556177,0.289404101,94068.10883,1.678611317,155.1112781
50,13.49216343,0.292285537,94757.19889,1.675991903,156.0643571
50.2,13.56108299,0.295179821,95271.44283,1.674682191,156.8423594
50.4,13.73741652,0.298095835,95747.10494,1.675991895,157.7877805
50.6,13.82631391,0.301047215,96050.74884,1.678611312,158.542804
50.8,14.22496951,0.304006855,96318.12027,1.682540429,159.3175256
51,14.53452354,0.307002438,96360.31235,1.691271818,160.1721256
51.2,14.46686431,0.310054028,96474.16434,1.696510659,160.8363272
51.4,14.48413615,0.313130502,96860.92793,1.698693508,161.7007734
51.6,14.60382561,0.316230673,97357.25971,1.697820365,162.4776822
51.8,14.80594799,0.319356524,98011.54505,1.694764369,163.2950776
52,14.70496662,0.322534527,98813.25936,1.690835243,164.2601936
52.2,14.5273738,0.325749822,99389.59481,1.6886524,165.0239695
52.4,14.84856011,0.328963028,100163.7032,1.68603297,166.0120668
52.6,15.05483108,0.332216485,100724.0825,1.685159824,166.8152374
52.8,15.39807619,0.335493187,101239.3882,1.685159814,167.6512357
53,15.5485491,0.338816272,101932.7818,1.68341353,168.6163531
53.2,15.71983545,0.342171278,102771.3709,1.680357535,169.6263342
53.4,15.63548125,0.345577533,103238.1264,1.680794108,170.4229379
53.6,15.83798568,0.348998232,103829.6781,1.679920962,171.2808204
53.8,15.9351505,0.352460578,104493.1142,1.679920959,172.3564549
54,16.0406382,0.355957058,104571.4591,1.685596365,173.0895944
54.2,16.20774108,0.359484391,104510.1324,1.694327757,173.9485707
54.4,16.46726871,0.363040776,104584.815,1.699566588,174.674051
54.6,16.1056035,0.366675681,104444.5575,1.707861428,175.3677949
54.8,16.41674968,0.370300717,104768.8899,1.711353977,176.3263477
55,16.75953394,0.373960035,105277.5963,1.710480827,177.0759015
55.2,17.08566006,0.377657302,106073.3162,1.707424827,178.0672815
55.4,17.43259918,0.381390239,106583.132,1.706988247,178.8441918
55.6,17.20081258,0.385200554,107302.2214,1.703932265,179.6966005
55.8,17.46780439,0.389014811,107968.0985,1.703495687,180.7459746
56,17.34842239,0.392893912,108345.184,1.7048054,181.5042803
56.2,17.62623021,0.396784764,108918.992,1.705241962,182.4912827
56.4,17.66171995,0.400731323,109575.3792,1.703059111,183.3119605
56.6,18.06275712,0.4046924,110329.7748,1.70000311,184.1928234
56.8,18.08657991,0.40871929,110754.6586,1.703495668,185.1995209
57,18.46928849,0.41276199,111314.2423,1.702622516,186.0048813
57.2,18.49060379,0.41687002,111823.8627,1.703932225,186.9634326
57.4,18.70010279,0.421006509,112310.4006,1.705241929,187.9416814
57.6,18.67893866,0.425221553,112717.7516,1.70480536,188.599317
57.8,18.82014709,0.429446778,113878.2962,1.697383667,189.7843763
58,18.7473511,0.433707674,114875.2679,1.692144831,190.920193
58.2,19.18582086,0.437997753,115556.9621,1.689525399,191.7977737
58.4,19.4902221,0.442340187,116293.893,1.68821568,192.8865411
58.6,19.97198179,0.446714021,116526.9931,1.693017933,193.8308703
58.8,19.83920924,0.451174179,116723.4378,1.697383636,194.6329447
59,19.89545271,0.455665961,117236.7151,1.698693344,195.6549621
59.2,20.17235445,0.460187733,118177.9639,1.693017927,196.5752168
59.4,20.30269702,0.464765088,119592.555,1.683413387,197.8138936
59.6,20.31645728,0.469396427,120965.2818,1.673372279,198.9146958
59.8,20.54671218,0.474059469,122134.6202,1.666387155,200.0351949
60,20.69535778,0.478774854,123028.7382,1.664640871,201.2716835
60.2,20.89812287,0.483533923,122981.3364,1.672499122,202.1295664
60.4,21.27158438,0.488329029,122729.305,1.685159637,203.1614339
60.6,21.35026713,0.493192657,122677.9403,1.693454462,204.0029026
60.8,21.13250566,0.498125366,122788.7852,1.700003016,204.8936096
61,21.48430014,0.503068361,123199.7144,1.703932134,205.9758118
61.2,21.59294262,0.50807771,123767.9071,1.703932131,206.8763694
61.4,21.8289812,0.513128693,124607.9628,1.701749274,208.0340733
61.6,21.7619138,0.518251274,125263.8291,1.700439567,209.011226
61.8,21.81308275,0.523417224,125842.1591,1.700439565,209.998228
62,22.07325149,0.528620664,126320.6776,1.702622407,211.1340476
62.2,22.05196407,0.533895726,126624.9915,1.705241827,212.0225675
62.4,21.80584352,0.539239184,126776.0103,1.711353812,213.0544305
62.6,22.36243231,0.544581129,126674.2642,1.719212052,213.8652638
62.8,22.4019128,0.550012396,126416.1566,1.728816588,214.6640567
63,22.71284471,0.555479489,126555.8697,1.734491986,215.6324583
63.2,22.8047721,0.561016575,126805.7405,1.737547972,216.4323459
63.4,23.30138158,0.566581389,127603.8281,1.734928537,217.4707805
63.6,23.51986524,0.572221399,128274.6588,1.733182251,218.3877522
63.8,24.19465782,0.57788653,129596.3958,1.724014265,219.4174333
64,24.11419167,0.583660652,131289.2346,1.712663452,220.7162916
64.2,24.2418919,0.589478437,132596.3282,1.704368619,221.7766084
64.4,25.05405853,0.595307727,133737.995,1.700002898,223.0174784
64.6,25.62307218,0.60121204,135099.8711,1.692144623,224.1401696
64.8,26.12379811,0.607180566,135714.2635,1.693017747,225.210337
65,25.97085349,0.613254015,135995.3386,1.698693159,226.3942999
65.2,26.2800461,0.61935657,136471.2788,1.700002861,227.345194
65.4,26.29279305,0.625540944,137454.0688,1.69738344,228.634205
65.6,26.53202512,0.631771827,138228.2464,1.695637153,229.7229724
65.8,27.01439611,0.638048564,139713.5215,1.686469173,230.9649349
66,27.12954238,0.644413758,141331.2163,1.677737773,232.4454382
66.2,27.1930543,0.650846361,142765.5312,1.671189223,233.8942095
66.4,27.62627414,0.657318098,143798.145,1.667260083,235.0168986
66.6,27.69393443,0.663880148,144808.0974,1.664640662,236.2577636
66.8,27.91313707,0.670497672,145751.8497,1.664640654,237.757964
67,28.25973393,0.67717291,146416.539,1.665513783,238.9222354
67.2,28.07589791,0.683951599,146753.0818,1.671189196,240.233129
67.4,28.45578675,0.690759661,146662.4359,1.679484011,241.2496787
67.6,28.41265988,0.697665181,146554.279,1.687778839,242.2695074
67.8,28.63681921,0.704621683,146488.0663,1.697819937,243.5968184
68,28.80767809,0.711651779,146771.1973,1.70131249,244.5958582
68.2,29.15922301,0.718740092,147272.777,1.704368468,245.8903434
68.4,29.20432884,0.725920745,147977.0053,1.703495327,246.9714494
68.6,29.43428398,0.733160875,148843.0991,1.701749041,248.1313425
68.8,29.73584221,0.740468777,149716.0396,1.701749031,249.5385336
69,29.46533223,0.74788939,150501.3609,1.7008759,250.6568415
69.2,29.45378091,0.755366765,151901.4989,1.695200494,252.1088934
69.4,29.60542857,0.762908017,152463.4378,1.696510198,253.2151682
69.6,29.9127809,0.770514301,152376.1318,1.703931875,254.2087379
69.8,29.98613777,0.778213142,152678.0815,1.70917071,255.5491791
70,30.08446639,0.78598778,152320.1145,1.718775243,256.4814691
70.2,30.4500802,0.793822088,151454.6819,1.734928313,257.4870768
70.4,31.24618679,0.801705721,151650.4893,1.740167125,258.584603
70.6,31.43650046,0.809710163,152488.266,1.73798427,259.6339777
70.8,31.89659709,0.817776538,153142.1646,1.737984256,260.7019572
71,31.87955156,0.825956911,154593.1584,1.73143571,262.0588108
71.2,32.51366191,0.834174554,155758.6767,1.726196853,263.1650903
71.4,33.31971365,0.842462679,156969.4722,1.722267699,264.5317994
71.6,34.09328069,0.850836346,157897.2207,1.719648257,265.7146764
71.8,33.94088407,0.859357766,159001.6819,1.715719134,266.9872726
72,34.25894866,0.867932438,159675.5369,1.716592263,268.3113025
72.2,34.27390322,0.876614163,160448.3811,1.715282554,269.452592
72.4,34.46870917,0.885370748,161160.1863,1.715719117,270.8203902
72.6,34.55692028,0.894222605,161480.1657,1.719211673,271.9069682
72.8,34.53853643,0.90317064,161627.1897,1.726196789,273.249597
73,34.5351306,0.912207476,161968.4077,1.728816208,274.2453526
73.2,35.12708921,0.921294291,161684.9536,1.738857293,275.3844588
73.4,35.5674872,0.93048272,161653.0387,1.746278965,276.4983966
73.6,36.24935522,0.939746858,161881.4308,1.750644641,277.5609075
73.8,36.82879125,0.949111249,161996.7186,1.755446889,278.4658468
74,37.31245671,0.958576286,162407.8347,1.758939432,279.6224594
74.2,37.28650342,0.968171522,163380.6637,1.755446875,280.6554193
74.4,37.82094084,0.977824593,164919.8242,1.748461742,282.0494826
74.6,37.79663045,0.987613001,166688.8837,1.738857209,283.4183739
74.8,38.32688167,0.99746178,168870.0004,1.724886961,284.7555362
75,38.38581755,1.007441952,171481.6038,1.709170449,286.484431
75.2,38.59628584,1.01756288,173454.5021,1.6982562,287.883963
75.4,38.97495202,1.027723286,175313.1275,1.690397933,289.5909779
75.6,39.31863926,1.037936578,176558.2478,1.686905365,290.9948864
75.8,39.24679512,1.048332698,177533.5801,1.686468798,292.4622577
76,39.7927965,1.05879071,178460.517,1.68777849,294.1189384
76.2,39.98405872,1.069378423,178389.3272,1.695200169,295.2744551
76.4,40.36349703,1.080059489,178586.4318,1.701748703,296.7374534
76.6,40.66548248,1.090853228,178460.8044,1.709606948,297.9345521
76.8,41.72270718,1.101703297,177764.9904,1.722267436,299.026612
77,41.68992505,1.11273752,176652.0422,1.739293655,300.1952572
77.2,42.1750646,1.12384689,176878.6019,1.742786197,301.2402588
77.4,42.40205657,1.135085718,177628.3959,1.74322276,302.6179058
77.6,42.85386229,1.146422048,178434.5451,1.741913037,303.8062521
77.8,42.94676444,1.157896861,180099.4547,1.73361821,305.2079709
78,43.21618392,1.169474854,182278.981,1.72226739,306.8832511
78.2,43.30656106,1.181181437,183951.4665,1.716155411,308.5497761
78.4,43.74915331,1.192981414,184717.6413,1.716155397,309.8300385
78.6,44.06183181,1.204908688,185218.8193,1.718774806,311.1267123
78.8,44.17215219,1.216969593,185359.3916,1.726196487,312.6827196
79,45.08434105,1.229096424,185123.5982,1.734054712,313.709124
79.2,45.97070228,1.24134682,184726.9726,1.744532355,315.0068989
79.4,46.24168967,1.25376265,184921.5753,1.748461474,316.0650296
79.6,46.56845295,1.266299248,185369.8197,1.750644312,317.2052288
79.8,46.81359774,1.278967475,186542.7536,1.748461456,318.7546715
80,47.11202001,1.291759352,187517.4827,1.746278598,319.9791263
80.2,47.45622541,1.30467659,189697.2477,1.736237485,321.6609737
80.4,47.82373109,1.317721929,191206.7447,1.730562068,323.0254921
80.6,48.2153696,1.330896742,193295.6272,1.720957523,324.5760303
80.8,48.92008494,1.34418246,195771.4207,1.71047983,326.5215925
81,49.39995787,1.357617076,198124.0775,1.699565574,328.1563893
81.2,49.73659207,1.371196476,199968.016,1.69432673,330.0362936
81.4,50.22725844,1.384901699,201028.7379,1.693453575,331.5211781
81.6,50.2432743,1.398777297,201241.0816,1.698692409,332.873657
81.8,50.92043146,1.412746793,200564.3222,1.712662617,334.5215865
82,51.13043204,1.426888793,198659.031,1.734491092,335.6967992
82.2,51.24965264,1.441179186,197169.4161,1.751517301,336.6083005
82.4,51.99087754,1.455570314,196552.5948,1.762431519,337.8393264
82.6,52.48144529,1.470123304,196596.037,1.76592406,338.7015913
82.8,52.75049995,1.484837692,197237.9301,1.767233761,340.2302445
83,53.09614508,1.499694705,198278.9812,1.764177762,341.4689256
83.2,53.92473421,1.514667902,199511.8044,1.761121748,342.9899258
83.4,53.86565614,1.52985248,199910.5881,1.763304598,344.1027649
83.6,54.1970929,1.545162734,200822.3199,1.762868017,345.5953091
83.8,54.89656164,1.560601506,201571.9341,1.762867996,346.8755755
84,55.1297048,1.576227474,202884.2092,1.759375431,348.4337729
84.2,55.46192004,1.59200365,204674.69,1.751080598,349.8278358
84.4,55.98646871,1.607925054,207142.2649,1.739729771,351.658502
84.6,56.41690457,1.624012901,208871.1353,1.733617783,353.2101364
84.8,56.91810045,1.640257531,210813.9801,1.726196085,354.850406
85,57.39096581,1.656667342,212791.3498,1.719647526,356.7576685
85.2,58.03035039,1.67323055,213602.9248,1.720957215,358.4679699
85.4,58.78046365,1.689952468,213946.5012,1.724886317,359.8270228
85.6,58.95683259,1.706881932,214660.8241,1.72619602,361.2626648
85.8,59.55369119,1.723952533,215365.5395,1.729251988,363.0506577
86,60.2462894,1.741188103,216096.7405,1.730561675,364.4589498
86.2,60.96468092,1.758595072,218009.8408,1.725322818,366.260075
86.4,61.11182542,1.776216221,219933.9746,1.7183377,367.8521931
86.6,61.40050697,1.794004652,221979.9839,1.710916009,369.6270505
86.8,61.82739458,1.811962254,224659.7728,1.701311466,371.931521
87,62.10604205,1.830110555,227000.9132,1.693889775,374.0696666
87.2,62.49291825,1.848433752,228700.6878,1.689087499,375.8160757
87.4,62.77735195,1.866947966,230066.9709,1.688214351,377.8666813
87.6,63.44563497,1.885621856,231051.9303,1.689087469,379.5879262
87.8,64.10348748,1.904484339,231564.2424,1.693016574,381.3233962
88,64.89746298,1.923527706,231428.6426,1.70174794,383.1923654
88.2,65.55027494,1.942772119,230022.1983,1.718337561,384.7483805
88.4,65.88705785,1.962231666,228808.9645,1.732307774,385.957519
88.6,66.48236883,1.981868959,227733.6554,1.74540484,387.1163247
88.8,67.17757998,2.0016958,226880.5368,1.759375041,388.6384189
89,67.70831134,2.021732925,226815.5829,1.765923566,389.8420884
89.2,68.43636724,2.041957889,227342.7641,1.769416099,391.3795022
89.4,68.44745183,2.062435458,228785.8402,1.765486973,392.8063897
89.6,68.89317764,2.083088726,230882.277,1.757192139,394.4105487
89.8,69.57952723,2.103933041,234262.8555,1.742348754,396.6778196
90,70.20506596,2.124990844,236740.3385,1.732307637,398.4526828
90.2,70.0370248,2.146314918,241154.2298,1.712225447,400.9716173
90.4,70.48598335,2.167810691,243634.074,1.703057474,402.8099439
90.6,71.32628191,2.189495549,245639.5154,1.697818614,404.7872444
90.8,72.0566398,2.211405863,247411.1177,1.696072314,407.1945799
91,72.38894541,2.233563764,247841.7494,1.700437998,408.8906534
91.2,72.91690769,2.255930771,247535.1197,1.710479078,410.784788
91.4,73.14424213,2.27854309,248006.1532,1.715281335,412.7555144
91.6,73.85201327,2.301349515,248399.1859,1.717900729,414.0040506
91.8,74.33992714,2.324400262,249088.1422,1.722266408,416.1301622
92,75.22334263,2.347655423,250046.6962,1.724012658,418.1556109
92.2,75.69538123,2.371172556,250205.5256,1.729251476,419.698494
92.4,76.39055373,2.394910496,249500.3547,1.741038828,421.3814425
92.6,76.68767184,2.418914444,248773.2884,1.751079915,422.7240777
92.8,77.10884712,2.443029273,248363.9215,1.758938151,424.1356526
93,77.68150122,2.46774467,248710.0185,1.762867257,425.8131279
93.2,78.29828769,2.492459489,249804.4772,1.76112096,427.3056788
93.4,78.81762035,2.517429386,251576.868,1.75631868,429.2709392
93.6,79.80990744,2.542490662,253447.524,1.750643245,431.0031336
93.8,80.63811019,2.567942187,256396.0576,1.741038692,433.3754552
94,81.14569692,2.593671325,258399.1512,1.735363274,435.150318
94.2,81.9288745,2.619640154,260077.3308,1.732743833,437.2414203
94.4,82.46387963,2.64588684,261711.4388,1.72968783,438.9889268
94.6,82.74321778,2.672414822,262940.6467,1.729687822,440.8086504
94.8,83.74863197,2.699159473,263345.7901,1.735799761,442.9139819
95,83.87136183,2.726233557,263354.9295,1.741911728,444.4470121
95.2,84.81509394,2.75352312,263487.7588,1.748460238,446.2481437
95.4,85.329958,2.781116387,263495.2114,1.754135622,447.7089608
95.6,86.00633198,2.808975723,263668.9067,1.758501294,449.2190199
95.8,86.80341365,2.837106772,266354.1509,1.749769882,451.5344418
96,87.31984539,2.86553985,270349.345,1.7336168,454.0282208
96.2,87.7679633,2.894262381,274397.3761,1.717027151,456.3119046
96.4,88.66903185,2.923242126,279417.3779,1.697381503,459.2849659
96.6,89.24614954,2.952535143,283906.0574,1.680355282,461.8826993
96.8,89.52263139,2.982143023,285918.2276,1.677299289,464.3458352
97,90.18045134,3.012022161,286141.7036,1.684720946,466.7881869
97.2,90.9431555,3.042194193,285601.4124,1.694325447,468.6232389
97.4,91.48599385,3.072684479,285723.7491,1.702620247,470.9506938
97.6,92.42182694,3.103454036,285395.032,1.711788173,472.7408849
97.8,93.390099,3.134530677,285845.6703,1.717026973,474.6853632
98,94.0710562,3.165939198,288259.6307,1.713097828,477.2874747
98.2,95.02509948,3.197644436,290545.2212,1.707858967,479.3599806
98.4,95.473662,3.229703142,291877.4382,1.709168661,481.8143661
98.6,96.61914977,3.262035883,293642.5799,1.706549209,483.9831671
98.8,97.13758311,3.294736712,295838.7662,1.7021835,486.3522039
99,97.78587809,3.327757165,296683.8886,1.705676034,488.8416102
99.2,98.09939254,3.361132457,296468.3648,1.712661132,490.6503924
99.4,98.88250593,3.394810624,297320.488,1.715717094,493.0588266
99.6,99.20676703,3.42885875,296951.7421,1.724011898,494.8730813
99.8,100.2071337,3.463202422,296156.1805,1.734926097,496.6862516
100,101.3989792,3.497878105,296487.3137,1.741038028,498.8922587
100.2,101.8730043,3.532951386,297317.8622,1.744093997,501.1059134
100.4,102.8799108,3.568340408,297940.4696,1.74671338,502.8392061
100.6,103.8617952,3.604086756,298968.7718,1.748023056,504.8066658
100.8,104.6129824,3.640208149,299534.2295,1.752388725,507.0071947
101,105.4274118,3.676688105,299550.4789,1.757627528,508.624495
101.2,106.3367254,3.713528073,299491.0897,1.764612605,510.5350534
101.4,107.1160962,3.75074703,299043.1,1.772034257,511.9838404
101.6,107.8271427,3.788344657,299335.5696,1.775963355,513.6908668
101.8,108.4457166,3.826326439,300847.8351,1.774653627,515.9132787
102,109.3015631,3.864673424,302059.985,1.77378046,517.6104598
102.2,110.064936,3.903412111,303537.6881,1.772907296,519.7464312
102.4,111.0364364,3.942525621,306093.787,1.766795298,522.0793662
102.6,112.0536892,3.982029027,307998.0976,1.762866142,524.0949743
102.8,112.7045116,4.02195444,309908.3357,1.758936997,526.1193317
103,113.248703,4.062288339,313544.7546,1.747586183,528.8615066
103.2,114.3932175,4.102986279,317365.8697,1.734489072,531.2863626
103.4,115.0247467,4.144128237,320461.1826,1.726630808,534.0974775
103.6,115.9584947,4.185662858,323541.2025,1.718772535,536.6711466
103.8,116.9038518,4.227613933,327495.6498,1.707421708,539.4374025
104,117.6526448,4.269999966,330143.9895,1.703929132,542.4028082
104.2,118.9859373,4.312771737,331057.6173,1.706548505,544.581464
104.4,119.7138135,4.356014923,334201.3111,1.701309653,547.6639542
104.6,120.4724487,4.399690449,336106.5049,1.698690215,549.7298926
104.8,121.1377714,4.443811207,335089.1996,1.711787265,552.3429512
105,122.114469,4.488353876,334533.3628,1.720518615,554.3476173
105.2,122.9420629,4.5333543,334730.7273,1.727067125,556.8523495
105.4,124.4278461,4.57876364,332996.2949,1.741473855,559.0025599
105.6,124.9705537,4.62469431,332407.8862,1.750205218,560.9251505
105.8,126.0236472,4.671051211,334981.2754,1.744529787,563.2132282
106,126.8018985,4.717892934,337005.9541,1.742783486,565.9302413
106.2,127.975207,4.765176933,338405.6069,1.742346879,568.0202642
106.4,128.6750756,4.812967371,341834.237,1.734925183,570.922203
106.6,129.8162145,4.861207642,343447.2966,1.734052009,573.2223198
106.8,130.841553,4.909940523,343023.7659,1.741910217,575.228083
107,131.7843981,4.959168656,344217.5605,1.744093032,577.8553738
107.2,132.9761603,5.008874424,345546.9336,1.744092993,579.9552445
107.4,133.778165,5.059106276,346270.5787,1.748022088,582.4348105
107.6,134.8041049,5.109827442,347796.5352,1.747148917,584.6583279
107.8,135.8591296,5.161056126,350988.7388,1.741036918,587.6948672
108,136.7900235,5.212808141,352997.1849,1.738417474,589.9763773
108.2,137.9939796,5.265061161,355956.0978,1.733178608,592.952738
108.4,138.8639655,5.317862171,358767.6389,1.727503184,595.4191745
108.6,140.3109444,5.371153993,360787.0043,1.726193431,597.955654
108.8,141.0409143,5.425030562,363646.9,1.723137426,601.2351093
109,141.8157866,5.479445326,366215.2032,1.719208281,603.8361363
109.2,143.3849821,5.534352263,367563.7767,1.721827644,606.7512274
109.4,144.3429185,5.589852894,367641.8853,1.727939578,608.9495771
109.6,145.3807283,5.645905511,368390.1828,1.731432096,611.3350461
109.8,146.7115797,5.702501283,368923.4129,1.737107448,614.1921361
110,147.9249556,5.759673762,367727.5632,1.74802163,616.1059893
110.2,149.1357666,5.817420886,367225.3717,1.757189536,618.4794254
110.4,149.9459858,5.875775774,368460.04,1.757626078,620.6449455
110.6,151.2224091,5.934982133,369776.6055,1.757626037,622.8947328
110.8,152.7419431,5.994471251,372326.348,1.754133437,625.9509817
111,153.7751513,6.054290148,375331.9506,1.74802144,628.9054555
111.2,154.9548079,6.11500246,378499.8983,1.740163164,631.4288018
111.4,156.0719419,6.176328877,380236.6324,1.739726559,634.4456496
111.6,157.5628821,6.238245836,381833.6209,1.739289942,636.9897941
111.8,158.5957702,6.300816384,384202.7518,1.736233927,639.6356928
112,159.7301734,6.364008731,388104.289,1.729248791,643.0508471
112.2,161.0526907,6.427823003,390100.1822,1.727939042,645.5807625
112.4,161.9496287,6.492307738,393458.0979,1.723136757,648.8350573
112.6,163.2828211,6.557410404,396317.6131,1.719644165,651.8147067
112.8,164.345313,6.623185692,397964.904,1.720517268,654.6192728
113,165.7374733,6.689599257,398657.0992,1.725756048,657.6503547
113.2,166.5833112,6.756717677,400306.3231,1.727065727,660.732853
113.4,168.2567648,6.824453587,401312.5241,1.729248517,663.1128671
113.6,169.2331774,6.892918095,401613.0232,1.734487309,665.6143266
113.8,170.4185152,6.962055962,402245.2518,1.740162664,668.7515456
114,171.8194391,7.031873468,403142.9845,1.74278203,671.1118595
114.2,173.342687,7.102381859,404088.3677,1.746711099,673.942698
114.4,174.3312655,7.173634824,405442.7571,1.74889391,676.8720082
114.6,175.8152113,7.245569309,408334.1686,1.744528175,679.8308735
114.8,177.1466908,7.318237068,411553.4587,1.738416172,682.6069974
115,178.5447006,7.391630204,413129.7634,1.739725832,685.7650137
115.2,179.9301342,7.465761636,414668.8343,1.739725787,688.3737204
115.4,181.133122,7.540650433,415516.4896,1.742345161,690.8653382
115.6,182.6382887,7.616270844,415325.9669,1.750203345,693.7891896
115.8,184.3007455,7.692640194,415067.4632,1.756751819,696.0958945
116,185.5392738,7.769805914,418446.8285,1.751076388,699.4705671
116.2,187.2631701,7.847713492,422029.8211,1.743218098,702.3998967
116.4,188.6747166,7.926425398,428336.9174,1.727501588,706.3785956
116.6,189.8921544,8.005941599,433826.4083,1.71484106,709.9349157
116.8,191.2660448,8.086246184,438198.4383,1.706982784,713.4715423
117,192.7339354,8.167350907,441933.9096,1.703053622,717.3353485
117.2,194.59143,8.24924356,442748.9377,1.707855815,720.1979353
117.4,195.8151519,8.33200264,442646.2488,1.717023715,723.3789286
117.6,197.2935802,8.415575547,443573.6822,1.721389352,726.2841807
117.8,198.7261128,8.499991357,445790.8345,1.721389306,729.4301654
118,200.2176677,8.5852512,449368.9369,1.717460141,733.1867397
118.2,201.3768798,8.671390633,455610.5703,1.705236189,737.42915
118.4,203.1746642,8.758351505,459665.6216,1.698687606,740.8355749
118.6,204.4410908,8.846222582,462508.1404,1.696504725,744.360165
118.8,206.1578999,8.934945586,465009.0458,1.696941239,748.6069676
119,207.7979978,9.024565392,465849.0277,1.700870302,751.7343575
119.2,209.8926395,9.115054142,464499.1862,1.71265758,755.128755
119.4,211.3609928,9.206495255,465048.3115,1.71833292,758.5931684
119.6,212.9175043,9.298848796,466812.587,1.720079144,762.0455477
119.8,214.4489271,9.392132117,468374.3285,1.721388802,765.0405329
120,216.1867479,9.486338431,470636.976,1.720515609,768.2270164
120.2,217.6480056,9.581510201,475013.7571,1.714403605,772.4924189
120.4,219.6812098,9.677598852,478522.2734,1.710474425,776.5499306
120.6,221.4586659,9.774670589,479825.6126,1.712220642,779.9027388
120.8,223.0020229,9.872733642,481014.9255,1.714403433,783.1012587
121,225.0773537,9.971745438,481232.8779,1.721825027,786.8162709
121.2,226.66378,10.07178569,481328.1591,1.72793693,789.5125327
121.4,228.7172282,10.17279888,481077.9754,1.737104796,792.8325231
121.6,230.3333963,10.274857,483636.1569,1.736231607,795.9883702
121.8,232.3574629,10.3779124,485350.5357,1.739287518,799.7942073
122,234.1915559,10.48201628,487713.1675,1.737541186,802.8679905
122.2,235.9788965,10.58716933,491915.8909,1.731429174,806.9933409
122.4,237.6761838,10.69338505,495792.1297,1.725317166,810.4982535
122.6,239.5507097,10.8006558,498409.1004,1.723134265,813.8663922
122.8,241.4571684,10.90900464,503860.8789,1.71483941,818.6865918
123,243.260663,11.01845195,507707.7515,1.710473672,822.3742474
123.2,244.9307994,11.12900824,510224.0159,1.711783322,826.5619696
123.4,246.8389556,11.24065898,510924.2189,1.71658551,829.6685861
123.6,248.8339973,11.35342508,511887.1303,1.723570534,833.9175963
123.8,250.8276588,11.46731902,512200.0088,1.729245853,836.8097418
124,252.6046879,11.58237218,513962.5526,1.732301772,840.7917516
124.2,254.1907496,11.6211053,514582.4117,1.7366674,843.8403653
124.4,255.5448449,11.62101287,517827.7587,1.734484517,847.8431524
124.6,256.4118173,11.6209538,520146.4166,1.733174785,851.2856721
124.8,257.355397,11.62088948,522603.2989,1.731865051,854.9142189
125,258.5021528,11.62081126,522880.3066,1.738413533,858.7452053
125.2,258.874508,11.62078605,524786.0098,1.738850089,861.8244234
125.4,259.268513,11.62075937,526770.9135,1.741032916,865.7177585
125.6,259.9647841,11.62071199,528409.047,1.743652301,868.9129763
125.8,260.5586345,11.62067162,529852.1209,1.748454529,872.9102721
126,260.6070736,11.6206686,531509.3312,1.749764232,875.9741613
126.2,261.1667837,11.62063056,533410.2433,1.751510485,879.7252518
126.4,261.4217297,11.6206134,534262.982,1.754566452,882.6425164
126.6,261.9206536,11.62057953,535507.9217,1.756749276,885.9274579
126.8,262.2322224,11.62055849,538982.5752,1.754129858,890.2497364
127,262.3447786,11.62055108,542448.1241,1.750200743,893.7108394
127.2,262.4448445,11.62054452,546910.6358,1.744961925,898.0363944
127.4,262.7738998,11.62052229,547615.7438,1.748454458,901.0718414
127.6,263.0921301,11.62050079,547863.3371,1.753693263,904.2254678
127.8,263.4736448,11.62047496,544551.9627,1.769846263,907.4764833
128,263.5587223,11.62046943,542097.5402,1.781633593,909.7251588
128.2,263.8994352,11.6204464,537247.6531,1.801279137,912.0974936
128.4,264.0236491,11.62043819,536822.9915,1.807391084,914.2794251
128.6,264.2128127,11.62042553,537174.5352,1.811756757,916.708655
128.8,264.1854772,11.62042769,538267.3972,1.814812733,919.7572228
129,264.411279,11.62041253,540584.1885,1.81393959,922.8003272
129.2,264.4846989,11.6204078,542888.3461,1.812193316,925.4232342
129.4,264.9311633,11.62037752,542274.1743,1.819178387,928.0943025
129.6,264.7331266,11.62039137,540644.9387,1.827909752,930.1263112
129.8,265.04303,11.62037045,539169.0013,1.836204531,932.078454
130,265.0256868,11.62037193,532809.8786,1.858906062,933.3346473
130.2,265.4413417,11.62034376,528873.036,1.873312788,934.1356481
130.4,265.5730497,11.62033504,525561.2546,1.886846388,935.3458894
130.6,265.8496456,11.6203164,523886.9661,1.8947046,936.4631231
130.8,265.9663653,11.6203087,521594.5894,1.904309089,937.3680669
131,265.9406952,11.62031075,521450.5903,1.907801633,938.7249304
131.2,266.1281934,11.62029821,520980.0155,1.912167306,940.0249002
131.4,265.8019226,11.62032084,520340.2099,1.916096428,940.9101356
131.6,266.3916094,11.62028076,520219.8473,1.918715815,941.9442152
131.8,266.3726008,11.62028236,522704.5642,1.913913569,943.6654637
132,266.7757654,11.62025504,525193.6967,1.908238172,945.175535
132.2,266.7942278,11.62025408,530352.5496,1.895577704,947.5380137
132.4,266.957578,11.62024318,535170.1837,1.884226933,949.6597605
132.6,266.9585539,11.62024341,540518.1239,1.872003033,952.1393208
132.8,267.0586198,11.62023686,546020.2327,1.860652265,955.2010249
133,267.0271208,11.62023931,550607.0428,1.851484341,957.7155983
133.2,267.1554981,11.62023081,553670.0878,1.847555226,960.550795
133.4,267.1964431,11.6202283,554855.1357,1.847555225,962.547795
133.6,267.4189142,11.62021336,553093.7073,1.856286574,964.2559193
133.8,267.439042,11.62021228,550642.5404,1.867200771,966.0395396
134,267.9820982,11.62017539,547736.5614,1.878988084,967.4598879
134.8,267.732579,11.50809617,1.7977E+308,1.940107594,0
135,267.5563795,11.39194533,1.7977E+308,1.931376246,0
135.2,267.4109895,11.27579238,1.7977E+308,1.847991788,0
135.4,267.183996,11.15964502,1.7977E+308,1.684715413,0
135.6,266.8987142,11.04350165,1.7977E+308,1.447222499,0
135.8,266.794126,10.92734591,1.7977E+308,1.025497936,0
136,266.3581276,10.81121286,1.7977E+308,0.666202581,0
136.2,266.2768546,10.69505552,1.7977E+308,0.381996894,0
136.4,265.983246,10.57891272,1.7977E+308,0.153235326,0
136.6,265.7878947,10.46276319,1.7977E+308,0.00611195,0
136.8,265.7515869,10.34660278,1.7977E+308,0.013097037,0
137,265.3155885,10.23046973,1.7977E+308,0.011787333,0
137.2,265.0544547,10.1143247,1.7977E+308,0.010914197,0
137.4,264.7750018,9.998180936,1.7977E+308,0.010041062,0
137.6,264.6312772,9.882027873,1.7977E+308,0.018335852,0
137.8,264.1736289,9.765896306,1.7977E+308,0.023138099,0
138,264.1697959,9.649733665,1.7977E+308,0.029250049,0
138.2,263.9577908,9.533585278,1.7977E+308,0.033615728,0
138.4,263.2936357,9.417467851,1.7977E+308,0.025320938,0
138.6,263.4829866,9.301291982,1.7977E+308,0.021828395,0
138.8,263.3517522,9.185138064,1.7977E+308,0.020955259,0
139,262.9049289,9.069005756,1.7977E+308,0.021391827,0
139.2,262.9327381,8.952840948,1.7977E+308,0.029686618,0
139.4,262.3643422,8.836716964,1.7977E+308,0.032306026,0
139.6,262.1173641,8.720570972,1.7977E+308,0.031869458,0
139.8,262.092714,8.604409756,1.7977E+308,0.031869458,0
140,261.7991053,8.488266957,1.7977E+308,0.029686618,0
140.2,261.6362288,8.372115206,1.7977E+308,0.022701532,0
140.4,261.3688499,8.25597061,1.7977E+308,0.020082124,0
140.6,261.0406847,8.139830177,1.7977E+308,0.025757508,0
140.8,261.0385171,8.023667422,1.7977E+308,0.03579857,0
141,260.6295811,7.90753252,1.7977E+308,0.043220225,0
141.2,260.5453937,7.79137538,1.7977E+308,0.049332176,0
141.4,260.3542058,7.675225568,1.7977E+308,0.049768744,0
141.6,260.042278,7.559084023,1.7977E+308,0.045403065,0
141.8,259.6678985,7.442946754,1.7977E+308,0.034052299,0
142,259.6507425,7.326785025,1.7977E+308,0.016153014,0
142.2,259.5195082,7.210631107,1.7977E+308,0.014406742,0
142.4,259.205915,7.094489676,1.7977E+308,0.033179163,0
142.6,258.8914891,6.978348303,1.7977E+308,0.049332178,0
142.8,258.6953051,6.862198832,1.7977E+308,0.053261289,0
143,258.7522584,6.746032028,1.7977E+308,0.046276202,0
143.2,258.2363219,6.629904453,1.7977E+308,0.029250053,0
143.4,257.9552035,6.513760798,1.7977E+308,0.016589582,0
143.6,257.653268,6.397618569,1.7977E+308,0.011350767,0
143.8,257.3196902,6.281478507,1.7977E+308,0.01702615,0
144,257.3008689,6.165316892,1.7977E+308,0.018772422,0
144.2,257.0122564,6.04917375,1.7977E+308,0.016153015,0
144.4,256.8002512,5.933025363,1.7977E+308,0.018335854,0
144.6,256.4817294,5.816303454,1.7977E+308,0.017462719,0
144.8,256.2813144,5.700735089,1.7977E+308,0.017899287,0
145,256.2017068,5.584577636,1.7977E+308,0.017462719,0
145.2,255.6682837,5.468451258,1.7977E+308,0.019208991,0
145.4,255.6028318,5.352292836,1.7977E+308,0.020082127,0
145.6,255.2742502,5.236152432,1.7977E+308,0.025320943,0
145.8,255.0822295,5.120002676,1.7977E+308,0.024011239,0
146,254.8152669,5.003858052,1.7977E+308,0.018335855,0
146.2,254.3701764,4.88714481,1.7977E+308,0.013533607,0
146.4,254.2081325,4.770993002,1.7977E+308,0.01309704,0
146.6,254.0302001,4.655423097,1.7977E+308,0.016589583,0
146.8,253.523423,4.539294895,1.7977E+308,0.017026152,0
147,253.4637999,4.423136073,1.7977E+308,0.012223904,0
147.2,253.0644397,4.307000515,1.7977E+308,0.011350768,0
147.4,253.1205604,4.190833769,1.7977E+308,0.011350768,0
147.6,252.4830512,4.074714518,1.7977E+308,0.01746272,0
147.8,252.2527268,3.958567385,1.7977E+308,0.024884376,0
148,251.9391336,3.842425954,1.7977E+308,0.0327426,0
148.2,251.6172135,3.726285094,1.7977E+308,0.037544849,0
148.4,251.36857,3.610139215,1.7977E+308,0.040164257,0
148.6,251.150736,3.493991227,1.7977E+308,0.040164257,0
148.8,251.085284,3.377832805,1.7977E+308,0.032742601,0
149,250.6068184,3.261702664,1.7977E+308,0.022701537,0
149.2,250.3781594,3.145555417,1.7977E+308,0.017026153,0
149.4,250.244427,3.029401671,1.7977E+308,0.013097041,0
149.6,249.8092612,2.913268564,1.7977E+308,0.011787337,0
149.8,249.3474493,2.797137283,1.7977E+308,0.009604497,0
150,249.3361221,2.680975154,1.7977E+308,0.008294793,0
150.2,249.1141247,2.564827452,1.7977E+308,0.013533609,0
150.4,248.648982,2.448696398,1.7977E+308,0.018772425,0
150.6,248.3420503,2.332554511,1.7977E+308,0.026194082,0
150.8,248.1108932,2.216407435,1.7977E+308,0.030996331,0
151,247.8397671,2.100263097,1.7977E+308,0.033615739,0
151.2,247.3737918,1.9841321,1.7977E+308,0.030996331,0
151.4,246.9269682,1.867999792,1.7977E+308,0.027940355,0
151.6,246.8573529,1.751841655,1.7977E+308,0.020955266,0
151.8,246.4055332,1.635709689,1.7977E+308,0.01571645,0
152,245.9162425,1.519580289,1.7977E+308,0.01789929,0
152.2,245.5768359,1.403440626,1.7977E+308,0.020955267,0
152.4,244.9951168,1.287317555,1.7977E+308,0.027940356,0
152.6,244.873042,1.17116301,1.7977E+308,0.031869469,0
227.8,244.0070501,1.061558967,1.7977E+308,0.034925447,0
228,243.8250217,0.945408527,1.7977E+308,0.027503789,0
228.2,243.2849369,0.829282605,1.7977E+308,0.015279883,0
228.4,243.0125617,0.713138352,1.7977E+308,0.007421658,0
228.6,242.1939425,0.597031503,1.7977E+308,0.015279884,0
228.8,241.971945,0.4808838,1.7977E+308,0.025757518,0
229,241.684165,0.364740601,1.7977E+308,0.034052312,0
229.2,240.7710355,0.248640224,1.7977E+308,0.03929113,0
229.4,240.1485145,0.132519946,1.7977E+308,0.036671722,0
229.6,238.8706671,0.016444542,1.7977E+308,0.029250065,0
229.622,238.7910234,0.003672077,1.7977E+308,0.029686633,0