File: Test_4.csv
Time On Sample,Displacement Into Surface,Load On Sample,Harmonic Contact Stiffness,Harmonic Displacement,Harmonic Load
0,0,0,-124.0956362,0.45135656,2.185655953
0.2,0.196084819,0.00074459,1885.877789,0.322833219,2.257566885
0.4,0.444521424,0.001485215,5512.644867,0.25573968,2.337104744
0.6,0.243397484,0.00225989,9106.557602,0.202587649,2.417732109
0.8,0.289905785,0.003015809,11366.1972,0.181239703,2.479836997
0.99,0.496088354,0.003721661,14313.07102,0.162505794,2.556106174
1.2,0.551611829,0.004512585,16368.96705,0.156842054,2.685763738
1.4,0.569036159,0.005268489,18891.38319,0.147692934,2.893869575
1.6,0.769276243,0.006010547,21282.20327,0.141593523,3.100885882
1.8,0.578124419,0.006782249,23572.51803,0.13592978,3.303543886
2,0.803293923,0.007522418,25528.2022,0.127652007,3.469156947
2.2,0.69690213,0.008287701,28625.55801,0.118502886,3.863577407
2.4,0.877198678,0.009031269,31624.60682,0.115453182,4.214415543
2.6,0.772468845,0.009796426,36590.72298,0.111532129,4.661134855
2.8,0.8663434,0.01054654,43095.79077,0.107611078,5.089331701
3,0.863824194,0.011303955,47835.51577,0.112839147,5.518618085
3.2,1.125556855,0.012041356,49533.65017,0.128523355,6.272593228
3.4,1.240205931,0.012789897,50331.24841,0.14377189,7.088673228
3.6,0.865822853,0.013575478,48497.84393,0.162505799,7.724975758
3.8,1.012464685,0.014321596,47060.9861,0.185160764,8.531249735
4,1.239296158,0.015061641,46265.09643,0.205201698,9.313553451
4.2,1.297023054,0.015814493,45933.54188,0.230470697,10.41400844
4.4,0.991195884,0.016594882,45558.17903,0.257918052,11.55477693
4.6,1.348906822,0.017325014,46257.81728,0.274909283,12.47327568
4.8,1.172297152,0.018095615,46312.11285,0.299742606,13.62058159
5,1.236671895,0.018847964,46114.17224,0.326318623,14.7450069
5.2,1.115737935,0.019614349,45858.13486,0.353765981,15.86289472
5.4,1.232879953,0.020362702,45505.33232,0.386005741,17.15184354
5.6,1.020538114,0.02113601,44483.00069,0.424344906,18.42335915
5.8,1.068708731,0.021889586,43199.14395,0.465733784,19.61860582
6,1.096520321,0.022644705,41789.41162,0.510608041,20.79750905
6.2,1.279309817,0.023388085,40903.02651,0.549382891,21.90450157
6.4,1.114749369,0.024157774,39594.48051,0.599049538,23.13461395
6.6,1.007942082,0.024923089,37796.07996,0.656993961,24.25032266
6.8,0.68258687,0.025704956,35441.01583,0.727572872,25.26034374
7,0.660539617,0.02646385,32984.24061,0.80076583,25.98816943
7.2,0.249177913,0.027252231,29942.21169,0.900534779,26.70945711
7.4,0.886098351,0.027961214,26391.80143,1.035593258,27.32723819
7.6,0.753946154,0.028728448,24078.98154,1.143639999,27.7107628
7.8,0.944214472,0.029471262,21825.57251,1.271727696,28.11172097
8,0.759295,0.030242492,20608.34045,1.356683794,28.40372261
8.2,1.026429035,0.030979484,19732.26642,1.429441109,28.71860566
8.4,1.416132734,0.031707192,19595.18589,1.461245233,29.19256448
8.6,1.061693187,0.032491263,19613.48405,1.476493731,29.57608888
8.8,0.879682146,0.033262274,19804.53421,1.486514177,30.09036074
9,2.011451657,0.033933778,19993.83015,1.491306691,30.50548451
9.2,1.942453988,0.03469623,20548.94843,1.479543529,31.09275691
9.4,1.893399858,0.035457172,21113.92608,1.463423644,31.55146127
9.6,1.863458286,0.036216667,22485.10013,1.412014297,32.26403319
9.8,2.04375485,0.036960237,24046.20668,1.354069883,32.93084378
10,2.003841508,0.037720487,26755.08764,1.263450016,33.89946197
10.2,1.634859783,0.038505661,29052.4866,1.202020174,34.74822835
10.4,0.665079008,0.039336338,30534.56656,1.178058113,35.5871874
10.6,1.043979948,0.040064865,29943.94148,1.215961642,36.04807167
10.8,2.265495399,0.040729571,27289.76433,1.335771663,36.346613
11,2.226413037,0.041489759,24164.35459,1.49392075,36.38910576
11.2,2.550469286,0.042222442,22360.71118,1.598917841,36.34334471
11.4,2.737413705,0.042965511,20470.35035,1.723084508,36.27579238
11.6,2.83793612,0.043715126,20496.13998,1.7265699,36.46973413
11.8,2.400813947,0.044505462,22536.45471,1.609373964,37.14961846
12,2.493026552,0.045255706,25366.22795,1.473444175,37.93737012
12.2,2.83120948,0.045987319,29458.31035,1.318344819,38.93431778
12.4,2.501283831,0.046769536,34477.93672,1.173265868,40.05111546
12.6,2.338385329,0.047539102,37760.02705,1.100508559,40.89879258
12.8,2.791243608,0.04826203,39474.65288,1.076982282,41.76172445
13,2.573500368,0.04903575,39342.20241,1.098765888,42.48192284
13.2,2.757951846,0.049779008,38399.05963,1.140154784,43.08444963
13.4,2.799474623,0.050533091,36865.03126,1.202020275,43.66627437
13.6,2.67978712,0.051299385,35724.09921,1.250379906,44.084665
13.8,2.972266107,0.05203446,34566.96536,1.304838988,44.60329601
14,2.594974547,0.052820265,33989.57947,1.337078714,45.03367105
14.2,2.63234242,0.053574662,33663.07893,1.362783392,45.53486858
14.4,2.801836243,0.054319053,33630.91838,1.378467616,46.11996242
14.6,2.676331874,0.055085787,33611.56261,1.39023076,46.5928309
14.8,2.445292944,0.055860514,33311.8947,1.41375705,47.10601286
15,2.567420858,0.056608492,33024.28798,1.435976356,47.50915025
15.2,2.802562166,0.057347911,32398.43089,1.474315555,48.00272124
15.4,2.94297106,0.058098292,31857.43959,1.505683986,48.31433541
15.6,2.903888697,0.058858481,31370.53825,1.539230761,48.69241254
15.8,3.532915539,0.059564279,31123.91054,1.561450124,48.99858017
16,3.409904107,0.060330826,31198.41921,1.572341923,49.41914985
16.2,3.782988255,0.061059798,32000.53508,1.55230103,49.90836285
16.4,3.591836388,0.061831507,33316.05774,1.512654815,50.45423187
16.6,3.688203905,0.062581438,35125.39201,1.458631438,51.09162444
16.8,3.463812804,0.063355664,38530.60977,1.362783474,52.05479438
17,3.640785466,0.06409949,42397.11259,1.269549582,53.09968244
17.2,3.717209442,0.064850931,45473.93617,1.208991115,54.07048031
17.4,3.091454587,0.065655557,47637.72081,1.174572939,54.92142456
17.6,3.001682391,0.066419585,48505.27058,1.172830242,55.79198241
17.8,3.095556962,0.067169704,46339.6298,1.239052463,56.39668816
18,3.304937872,0.067911074,43349.27924,1.326622646,56.65709338
18.2,3.466952876,0.068656032,38778.82229,1.476493989,56.76713936
18.4,3.815938581,0.06938683,34087.39994,1.657733776,56.5339745
18.6,4.464077424,0.07009497,31089.53468,1.794970687,56.23761608
18.8,4.282897319,0.070865925,29395.30038,1.882105163,56.06982347
19,4.360152279,0.071617305,29682.51391,1.869470671,56.24742187
19.2,4.518843371,0.072362517,31634.80403,1.777108122,56.80200811
19.4,4.46812727,0.07312359,35038.82065,1.638564262,57.62789417
19.6,4.179750626,0.073902664,40931.70208,1.448175352,58.93318569
19.8,4.055077226,0.074669338,45505.89277,1.332722131,59.95301319
20,4.279415807,0.075409578,50186.40152,1.237745549,61.16024568
20.2,4.45805044,0.076153279,52525.50406,1.203327438,62.13213334
20.4,4.244462079,0.076926688,52883.22908,1.212040869,63.04300425
20.6,4.236126005,0.077684551,52155.95012,1.24035958,63.69674021
20.8,4.2901135,0.078437694,51351.9981,1.27303502,64.42456605
21,3.672668207,0.079243074,50523.90859,1.307888764,65.12515074
21.2,4.214855702,0.079967269,49299.65718,1.351456061,65.70588769
21.4,3.991708513,0.080757445,48159.42048,1.393280601,66.17875596
21.6,4.540541448,0.081496361,45778.65605,1.473444391,66.56664079
21.8,4.506855528,0.082287143,43465.21182,1.557093509,66.80089599
22,4.591998627,0.083076819,41825.30359,1.620266027,66.93273298
22.2,4.84541411,0.083861659,41165.5626,1.65337717,67.22473577
22.4,4.753971203,0.084680792,41118.3012,1.665575991,67.61806649
22.6,4.663773474,0.085507966,42913.46432,1.616344989,68.34044419
22.8,4.680770979,0.086335248,44700.88544,1.568421016,68.99853822
23,4.693612256,0.087171168,47231.44237,1.50655552,69.91158919
23.2,5.000619459,0.087993186,49063.3625,1.468652043,70.721133
23.4,4.783691844,0.088863234,50496.29713,1.444690033,71.57861564
23.6,4.731297082,0.089729481,50643.83276,1.453403483,72.28900857
23.8,4.914484044,0.090586531,50423.04168,1.46908771,72.79456489
24,4.830924743,0.091472458,49888.34014,1.495663724,73.39055353
24.2,5.128784288,0.092338387,49364.5926,1.521368437,73.90591646
24.4,4.999933705,0.093245468,49103.35635,1.53835965,74.34936662
24.6,4.852384589,0.094163173,48891.29379,1.556657881,74.90068355
24.8,4.748045045,0.095086656,48852.8797,1.569292373,75.45744797
25,4.849371834,0.096003691,48934.34852,1.576698817,75.96245916
25.2,4.706388747,0.096948528,48964.29306,1.586719269,76.52521624
25.4,4.825163146,0.097883049,48927.4159,1.595868405,76.95123443
25.6,4.917344678,0.09882888,48860.46224,1.608067246,77.49710421
25.8,4.902328136,0.099792463,48925.29861,1.614602333,77.91222638
26,4.998661513,0.100757239,49017.70865,1.622444449,78.41778257
26.2,5.104965114,0.101730991,49049.89751,1.631157912,78.87321855
26.4,5.274421715,0.102709746,49209.77056,1.637257346,79.37550624
26.6,5.241117386,0.103713752,49613.6467,1.63682167,79.91919621
26.8,5.410570827,0.104712402,50132.18129,1.629850929,80.38879741
27,5.56672696,0.105722209,50964.97966,1.616345099,81.02074244
27.2,5.746979932,0.106740332,52118.02326,1.594561492,81.67447884
27.4,5.730288779,0.107783611,53811.34037,1.560579033,82.4851112
27.6,5.472611461,0.108855685,55457.22349,1.530081928,83.34259378
27.8,5.617958249,0.109907786,56355.55902,1.517883113,84.00068814
28,5.597107147,0.110983114,57205.68766,1.50916966,84.77318601
28.2,5.638577898,0.112064554,57881.92645,1.503941594,85.49883289
28.4,5.679215926,0.113157017,57868.56242,1.516576102,86.20813641
28.6,5.89020334,0.114247404,57633.32161,1.531824664,86.71914069
28.8,5.964908116,0.115359144,57565.55951,1.545766194,87.3717871
29,5.65320491,0.116511546,57735.5103,1.553608266,88.02552159
29.2,5.793553567,0.117641072,57771.73653,1.56362875,88.61715309
29.4,5.794295622,0.118792453,58327.68767,1.56188606,89.32863554
29.6,5.968710845,0.119942408,59138.0338,1.552301283,89.97910329
29.8,5.996040615,0.121114913,60288.24668,1.537052747,90.8180644
30,5.805651458,0.122315858,61477.63602,1.521804188,91.68317412
30.2,5.971751274,0.123501652,62512.17232,1.51047672,92.51341914
30.4,5.751443004,0.124728757,63188.89226,1.505684299,93.20855726
30.6,6.016425717,0.125931243,63665.19008,1.50786269,94.03989259
30.8,5.983084302,0.127168549,63763.77442,1.517883155,94.7960468
31,5.997106816,0.128414777,63594.24159,1.531389006,95.37678211
31.2,6.064310142,0.129669397,63287.11738,1.551429951,96.15363857
31.4,6.214609541,0.130930499,62996.09128,1.567114179,96.67880702
31.6,6.222809197,0.132214865,62719.75514,1.584541082,97.32709498
31.8,6.300809186,0.133506988,62827.61909,1.593254542,98.02332388
32,6.256652922,0.134821204,62905.5683,1.600225299,98.5670142
32.2,6.114438779,0.136156161,63217.08442,1.602839319,99.20549545
32.4,6.405994636,0.137471489,63832.46772,1.599789643,99.96165134
32.6,6.399226172,0.138822798,64347.04692,1.598482625,100.6764022
32.8,6.358385333,0.140190223,64613.38908,1.601096656,101.2614956
33,6.502851093,0.141557299,64805.57854,1.607196089,101.9533667
33.2,6.533469144,0.142953793,64626.32163,1.620701942,102.5384605
33.4,6.554945275,0.144358076,64420.07602,1.635079139,103.1344497
33.6,6.685278821,0.145761065,64301.07362,1.645535296,103.6062294
33.8,6.646088857,0.147198111,64219.03382,1.657298451,104.2043978
34,6.988316913,0.148620689,64455.46423,1.660783871,104.8123737
34.2,6.713954705,0.150104481,64988.50036,1.656427114,105.4214363
34.4,6.902446623,0.151567889,65442.53143,1.655555791,106.1122181
34.6,6.842472833,0.153065005,65938.58651,1.651199059,106.6580875
34.8,6.85728495,0.154571497,66302.86547,1.651634733,107.3194502
35,6.890376252,0.156091693,66285.51135,1.660783862,107.9274244
35.2,6.807127776,0.157635967,66209.31763,1.670804322,108.4732936
35.4,6.945748817,0.159178727,66153.26169,1.679082117,108.941805
35.6,7.152507816,0.160732016,65750.09389,1.696944717,109.4528095
35.8,7.035181688,0.162325586,65633.28111,1.706093828,109.8722892
36,7.143879899,0.163917883,65844.84008,1.709579222,110.4421298
36.2,7.042337323,0.165542273,66122.51397,1.7113219,110.9705658
36.4,7.128593906,0.167168592,66416.36563,1.711757584,111.4554203
36.6,7.27384756,0.168806721,67047.13146,1.706093857,112.1135149
36.8,7.196395638,0.170478334,67444.50703,1.704351158,112.6266973
37,7.301756896,0.172152852,67953.64575,1.701301463,113.2640905
37.2,7.235933376,0.17385714,68390.56711,1.69868742,113.8535418
37.4,7.94208862,0.175519914,68761.12287,1.698251831,114.4811321
37.6,7.737485864,0.177268583,68957.09432,1.70043017,114.9692537
37.8,7.953356782,0.179002894,69445.73879,1.69781616,115.6229906
38,8.290548204,0.180745307,69715.28932,1.698687545,116.1383544
38.2,8.914425355,0.182483555,70128.11869,1.697816274,116.7452429
38.4,8.624220392,0.184308736,70802.29621,1.692152496,117.4414696
38.6,8.689672484,0.186125178,71657.09724,1.681260683,118.0581609
38.8,8.808304494,0.187955704,72736.30794,1.668190519,118.8698834
39,8.89701825,0.189806941,73647.61532,1.657298716,119.545411
39.2,9.071735615,0.191670199,74777.9569,1.643357207,120.3407906
39.4,8.820987569,0.193584779,75891.87797,1.631594019,121.2320491
39.6,9.003177745,0.195485337,76581.35896,1.626365966,121.9413536
39.8,8.87208494,0.197428922,77082.3543,1.626801628,122.7835826
40,9.351760239,0.199345654,77384.47582,1.628544374,123.4242466
40.2,9.043246764,0.201341554,77365.74686,1.637257789,124.1084883
40.4,8.961172496,0.203340278,77141.61049,1.650327959,124.8363138
40.6,9.54138708,0.205308823,76992.36923,1.659912828,125.3680225
40.8,9.519968081,0.207342949,77072.95566,1.666883588,126.0784157
41,9.626101469,0.209387756,77219.64292,1.67124033,126.6602414
41.2,9.470056992,0.211473082,77694.81897,1.671675985,127.4065892
41.4,9.433255034,0.213570061,78432.87543,1.666447907,128.1442204
41.6,9.564723426,0.215675376,79162.17118,1.660348507,128.837182
41.8,10.45861379,0.217743936,80012.65667,1.65381352,129.6750587
42,10.5651461,0.219893026,80786.2943,1.649021133,130.5314538
42.2,10.68206223,0.22206299,81295.8431,1.647714128,131.2876091
42.4,10.73415834,0.22425973,81505.92829,1.651199516,131.9293602
42.6,10.75467366,0.226480849,81722.10377,1.656427591,132.7192914
42.8,10.63391861,0.228735062,81700.31758,1.663834014,133.3098319
43,10.76328534,0.230992911,81670.5869,1.672983155,134.0507335
43.2,11.09125301,0.233258287,81927.62575,1.67559723,134.7328002
43.4,10.75401648,0.235597129,82383.6848,1.675597191,135.5554157
43.6,11.05206146,0.237911136,82486.09155,1.680389626,136.1328844
43.8,11.2005261,0.240259791,82806.57656,1.683439352,136.9130106
44,11.27502963,0.242637766,83305.48027,1.681696671,137.5711047
44.2,11.35700819,0.245039102,83811.51824,1.681261008,138.2847672
44.4,11.46474336,0.247462482,84244.42619,1.683439384,139.0714307
44.6,11.26833544,0.249933483,84995.95502,1.677775616,139.7643893
44.8,11.32038704,0.25241031,86230.37608,1.665576787,140.7035902
45,11.73224963,0.254884609,87346.53294,1.655556362,141.6525999
45.2,11.7311105,0.257415215,88274.56789,1.647714253,142.5209793
45.4,11.73578422,0.25997076,89195.46474,1.639436472,143.3348804
45.6,12.17505713,0.262518955,89978.14607,1.635515468,144.3154873
45.8,12.3035389,0.265116532,90368.6616,1.636822501,145.0792696
46,12.26914417,0.267752493,91060.80447,1.635515479,146.0587839
46.2,12.54470133,0.27039128,91546.7137,1.636822529,146.9064637
46.4,12.4105804,0.273087873,92334.40104,1.632465786,147.7258121
46.6,12.56563672,0.275789525,93853.30341,1.618959949,148.8556868
46.8,12.57942185,0.278529161,95004.93508,1.60937515,149.7687381
47,12.47104836,0.281305479,95960.91471,1.605454084,150.8833574
47.2,12.68010534,0.284085624,96897.34995,1.600661707,151.8912018
47.4,12.86838334,0.286895317,96946.58167,1.610682202,152.8990469
47.6,12.83146088,0.289750381,96359.65471,1.627673436,153.6050811
47.8,13.00892708,0.292617747,95398.87833,1.651635458,154.3797596
48,13.06755835,0.295522983,94847.6491,1.667319685,154.9844656
48.2,13.20595921,0.298451369,94262.86461,1.684310939,155.6534567
48.4,13.48063635,0.301398804,94237.08393,1.692588754,156.4858826
48.6,13.72123856,0.304378409,94740.02739,1.691281765,157.2235164
48.8,14.05906087,0.307380425,96020.16379,1.679954312,158.2378999
49,14.098556,0.31043542,97187.16237,1.669062497,159.0888464
49.2,14.15466587,0.313519911,98607.10878,1.65599232,160.0890632
49.4,14.4500935,0.316617165,100083.751,1.643793515,161.2167596
49.6,14.2494202,0.319783252,101357.9383,1.633337345,162.1930042
49.8,14.3794725,0.322956041,102234.2449,1.630723323,163.3272371
50,14.60009672,0.326153843,102771.9074,1.631159021,164.2108723
50.2,14.49912599,0.329408112,103062.5266,1.635951411,165.1576993
50.4,14.71890895,0.332670639,103101.7767,1.645536239,166.1492011
50.6,14.78412411,0.335977857,103008.3228,1.655121048,166.9151625
50.8,14.81277078,0.339321132,103148.2161,1.663398836,167.8837812
51,14.72091708,0.342724206,103374.1355,1.667755554,168.6442935
51.2,14.85592132,0.346110205,103812.4964,1.669933934,169.524659
51.4,14.97845271,0.349548325,104497.7336,1.669498275,170.558653
51.6,15.02618749,0.353044094,105271.6913,1.66775559,171.6122576
51.8,14.97669744,0.356547203,106003.8392,1.664705875,172.4740998
52,14.9753959,0.360099542,106481.2129,1.667319912,173.5124507
52.2,15.29817153,0.3636629,106695.9415,1.672548024,174.4113404
52.4,15.44144942,0.367275822,106607.3669,1.680825825,175.1446158
52.6,15.53070774,0.370929176,105891.2563,1.699559768,175.9323686
52.8,15.91246577,0.374596909,105201.8524,1.715679709,176.5011226
53,15.8529667,0.378335011,104497.7916,1.733106616,177.1908133
53.2,16.12834727,0.382085152,104050.8117,1.746176835,177.8129542
53.4,16.27658166,0.385882683,104302.8233,1.748355218,178.4623336
53.6,16.4514014,0.389716327,105381.7641,1.739641782,179.3939093
53.8,16.42511742,0.39360396,106413.8394,1.730928322,180.2001836
54,16.5151647,0.397521666,107967.5,1.716986801,181.2832071
54.2,16.91765482,0.401455036,109308.7003,1.705659354,182.3008601
54.4,16.92542236,0.405457956,110149.8743,1.699995608,183.1528964
54.6,17.11267556,0.409487384,110988.1662,1.696074574,184.2043233
54.8,17.21350023,0.413563845,111698.636,1.692589203,185.0770623
55,17.47054298,0.41766931,112474.7009,1.689975197,186.1339382
55.2,17.51484782,0.421832309,113057.5044,1.689975202,187.0883935
55.4,17.77769424,0.426020365,113404.1027,1.692589264,187.870699
55.6,18.39868712,0.43022332,113365.9897,1.702609821,188.8109963
55.8,18.58839377,0.434501198,113000.6179,1.716551378,189.6401524
56,19.02198675,0.43880353,112869.0483,1.724829211,190.2775499
56.2,18.8601744,0.443194244,113076.3208,1.729185922,191.0805539
56.4,18.6921227,0.447629422,113599.0091,1.730057247,192.0360966
56.6,19.1323426,0.452062942,114394.8317,1.725700571,192.8630778
56.8,19.35276071,0.456557858,115700.9587,1.716115793,193.9493713
57,19.58854483,0.461096656,116828.8194,1.707838035,194.8722307
57.2,19.32074668,0.465719442,117637.7135,1.704788295,195.8288622
57.4,19.50208685,0.470354471,118892.3367,1.6969462,196.9848875
57.6,19.43329407,0.475055129,119973.9249,1.689975426,197.9622225
57.8,19.62376013,0.479783265,121150.617,1.683440355,199.1335017
58,19.66505739,0.484570312,122107.8636,1.678647954,200.1184648
58.2,19.7661777,0.489400823,123351.5685,1.671677202,201.2962805
58.4,20.04221198,0.494266647,123784.8288,1.675598291,202.4435904
58.6,19.95800786,0.499208674,123745.4377,1.683440392,203.3032527
58.8,20.37903283,0.504161925,123536.2113,1.694767943,204.2980256
59,20.58981147,0.50918101,123000.9784,1.708709505,205.0770634
59.2,20.99710932,0.514235602,122641.7561,1.720690565,205.8996856
59.4,21.08031615,0.51936557,123063.2829,1.722651104,206.8203658
59.6,21.40159112,0.524528998,123775.0604,1.721779796,207.8717951
59.8,21.10377629,0.529791324,124861.8725,1.714808993,208.8011866
60,21.75867389,0.535034016,126499.338,1.703045899,210.0454718
60.2,21.958185,0.540364077,127861.5751,1.694332462,211.2014977
60.4,22.07791333,0.545753726,128979.0075,1.687797381,212.2300442
60.6,22.32643525,0.551187775,130129.5444,1.682569334,213.5048329
60.8,22.51968819,0.556680662,130677.0163,1.682569357,214.4723643
61,22.31323002,0.562259022,131220.2849,1.684312025,215.6894012
61.2,22.70548552,0.567847787,131438.1144,1.689104475,216.707055
61.4,22.85093043,0.573511406,131247.8693,1.698253627,217.5699881
61.6,23.25064682,0.579212579,130923.0524,1.710888194,218.5898211
61.8,22.85261131,0.585031775,130787.061,1.719601608,219.3895553
62,23.38859037,0.590838276,130791.9636,1.727879461,220.3636274
62.2,23.38608374,0.59674428,131276.6114,1.729186481,221.3028287
62.4,23.47497572,0.602702576,132038.4511,1.726572453,222.2344042
62.6,23.67604078,0.608712139,133017.3585,1.72265142,223.3969675
62.8,23.6793225,0.61479721,133677.1214,1.720908728,224.3372583
63,23.91277654,0.620925898,134151.8552,1.722651449,225.4355376
63.2,23.93847527,0.627131919,134168.3221,1.728750876,226.3660227
63.4,23.81874223,0.633411276,134487.7613,1.730929227,227.2452973
63.6,24.1435746,0.639719935,134873.2097,1.733543305,228.3337718
63.8,24.29555259,0.646105232,135260.8399,1.734850343,229.2086904
64,24.26636629,0.652568364,135782.1901,1.735721686,230.2633856
64.2,24.61609752,0.659067722,136309.7964,1.736593075,231.2494413
64.4,24.72234061,0.665650836,136470.3502,1.742256839,232.2616443
64.6,24.73716514,0.672307059,136635.098,1.746613573,233.0537557
64.8,25.0860339,0.679004658,136610.662,1.754455732,233.9886022
65,25.15152703,0.685791127,137102.0866,1.754891413,234.7752663
65.2,25.34082566,0.69263647,137395.1221,1.758812495,235.6796036
65.4,25.85752035,0.699525675,137574.8663,1.76447631,236.615542
65.6,26.59939466,0.706502181,138151.2237,1.765347747,237.6048715
65.8,27.12272078,0.713494559,138548.8974,1.766654831,238.3817344
66,27.44493237,0.720608079,138461.7523,1.773189969,239.0899528
66.2,27.6449782,0.727802367,138924.7106,1.774061341,239.9823056
66.4,27.71288635,0.735078994,140189.468,1.766654905,241.1132706
66.6,27.8921345,0.742420351,140868.1252,1.764476561,241.9794732
66.8,28.31318682,0.749816922,142156.754,1.756634495,243.1311441
67,28.70181904,0.757290208,143572.2643,1.746614058,244.1640532
67.2,28.87438387,0.764855183,144577.9263,1.741821673,245.2819443
67.4,28.93392304,0.772504674,145575.9069,1.737464948,246.497895
67.6,29.30589935,0.78020744,146557.4594,1.732236914,247.5101015
67.8,29.56734274,0.78799574,147327.2937,1.730929926,248.717338
68,29.6002535,0.795879769,148198.8359,1.727444544,249.7447942
68.2,29.97302352,0.803817107,150058.0913,1.715245737,251.0609887
68.4,30.31420352,0.811836663,152155.5585,1.702611253,252.599453
68.6,30.54068858,0.819986737,153713.2741,1.693897814,253.8480929
68.8,30.97158885,0.828162172,155686.8602,1.683006032,255.4552011
69,31.36841238,0.836380875,156497.5277,1.682134732,256.6144981
69.2,31.45692165,0.844747144,156224.6004,1.692590902,257.7552698
69.4,31.38420694,0.853209757,155159.3677,1.711324848,258.8437404
69.6,31.6837589,0.861729134,154210.5546,1.727444797,259.652199
69.8,31.58193268,0.870364594,153048.7633,1.747050086,260.5347415
70,32.34099065,0.87902121,152696.7089,1.756634992,261.2974442
70.2,32.15022166,0.887837225,153086.102,1.760991703,262.4905117
70.4,32.31426818,0.896714733,153858.4093,1.758813356,263.4297145
70.6,32.91290444,0.905648444,154784.8928,1.755328043,264.4310295
70.8,33.46000551,0.91467588,156090.489,1.749664356,265.6971065
71,33.33815112,0.923844941,156634.5975,1.751407035,266.8553084
71.2,33.86943448,0.933056408,157248.2841,1.7514071,267.8871298
71.4,33.97274703,0.942393031,157875.4305,1.75097144,268.8241537
71.6,33.82342597,0.951842454,158868.6398,1.748793055,270.0945805
71.8,34.27405932,0.961341254,159826.9768,1.745307723,271.1503707
72,34.5318895,0.970950289,161198.9143,1.739208326,272.4970714
72.2,34.99994301,0.980639683,162343.4614,1.734851649,273.7086697
72.4,35.27851699,0.990440836,163220.2884,1.733544662,275.042297
72.6,36.23931222,1.000288493,163500.2086,1.736158819,276.0414371
72.8,36.99400805,1.010250719,163899.7395,1.738772951,277.3195026
73,37.14539441,1.020358913,164841.4778,1.735287582,278.4090656
73.2,37.44883452,1.030556966,165615.8863,1.733980598,279.6348267
73.4,37.55282246,1.040872578,166167.2659,1.735723305,280.9128838
73.6,37.94306749,1.051270383,166779.7552,1.736159026,281.9926442
73.8,38.15047965,1.061786782,167456.6203,1.737901743,283.293583
74,38.35205812,1.072409389,167720.0751,1.741822825,284.2970722
74.2,38.54115489,1.083139572,169034.0511,1.737466114,285.6078163
74.4,38.90432547,1.09396433,171314.3941,1.725267301,287.2345372
74.6,38.98743749,1.104919145,173136.1574,1.715682489,288.5463697
74.8,39.14199655,1.115978618,175387.1765,1.704354999,290.2384608
75,39.39417847,1.127141686,176048.5435,1.705226375,291.4685792
75.2,39.39289273,1.138436288,175888.9046,1.713504173,292.6627386
75.4,39.57315874,1.149830575,175735.5882,1.723089015,294.0061705
75.6,40.02389153,1.161318827,175915.3983,1.727881479,295.1033654
75.8,40.3271065,1.172933652,176252.1161,1.732673927,296.4337243
76,40.24306481,1.184694605,177917.8032,1.724396116,297.7194057
76.2,41.53054199,1.196469309,180505.1481,1.710019039,299.3864535
76.4,41.78093339,1.20844149,182404.8384,1.702176941,301.1199497
76.6,41.86677104,1.220546302,183595.77,1.699127242,302.4960679
76.8,42.17653932,1.232755742,184736.3174,1.698255935,304.140221
77,42.37119694,1.245096579,184692.0016,1.705662411,305.3191297
77.2,42.74034133,1.25754811,183769.0743,1.72047536,306.4686233
77.4,42.5107424,1.270170461,184184.6375,1.72483207,307.8774233
77.6,42.90436074,1.282872127,184846.248,1.727010486,309.3537846
77.8,43.17414231,1.295710759,185351.0264,1.728753214,310.5479486
78,43.93002859,1.308641495,187007.0725,1.722218199,312.1921089
78.2,44.06722718,1.3217492,189680.5922,1.707840983,313.9256035
78.4,45.00464178,1.334927776,191201.9018,1.702177336,315.4052422
78.6,45.34746689,1.348283253,193478.397,1.692592554,317.3021747
78.8,45.78084789,1.361765924,195785.4806,1.681700761,318.9659426
79,46.39203781,1.37537062,197627.8015,1.676472747,320.9238945
79.2,46.89102325,1.389120597,198098.9465,1.680829544,322.5277375
79.4,46.88724176,1.403046868,198657.9169,1.683443587,323.902764
79.6,47.21998633,1.417087473,198674.9225,1.692157102,325.5469184
79.8,47.37570898,1.431282725,197953.2082,1.704791662,326.7290965
80,47.41673326,1.445629185,198341.3667,1.710455427,328.3144098
80.2,47.71367755,1.460100344,199207.6322,1.71132681,329.8539653
80.4,48.07375346,1.474712202,200036.4774,1.711762528,331.2148337
80.6,48.37480623,1.48947527,201032.7384,1.712633912,332.9548687
80.8,49.18855231,1.504347593,201648.7516,1.714376704,334.2797889
81,49.68068401,1.51939387,201175.9463,1.725704284,335.759422
81.2,50.20270711,1.534589017,200412.6611,1.738338891,336.968845
81.4,50.88508581,1.549924656,200082.8843,1.747488126,338.3101066
81.6,51.15610311,1.565445659,200633.0201,1.748359507,339.5162571
81.8,51.47529268,1.581118929,202208.1673,1.743131459,341.2137998
82,51.74626015,1.59695345,204680.2592,1.730496948,342.7925799
82.2,52.3628916,1.612920715,207923.4292,1.713505737,344.6742635
82.4,52.85817395,1.629057612,211043.5238,1.699564229,346.8087239
82.6,53.18307884,1.645369645,212787.6923,1.69433618,348.4245508
82.8,53.49798588,1.661846336,214292.453,1.692593521,350.371604
83,53.91175369,1.678481088,214503.3455,1.697821659,351.8174601
83.2,54.05043926,1.695304002,214523.2963,1.705228134,353.3700875
83.4,55.1297718,1.712224133,214567.3318,1.713506069,355.0872571
83.6,55.41798064,1.729374495,215168.3453,1.715684474,356.4873496
83.8,55.75685212,1.746693279,216097.9805,1.716555863,358.2851338
84,56.31258275,1.764169748,217476.9119,1.713070537,359.8105303
84.2,56.57742696,1.781932742,218188.1606,1.716555962,361.7978971
84.4,56.99434131,1.799683779,218383.2106,1.720912753,363.1642155
84.6,57.44029749,1.817700858,217936.801,1.731368986,364.7299247
84.8,57.89370375,1.835898394,217755.7514,1.739211176,365.9317211
85,58.5647988,1.854262306,217688.0444,1.747924741,367.4571199
85.2,58.89682303,1.872836363,218327.4295,1.750974501,368.8986172
85.4,59.30609916,1.891591052,219369.7454,1.750103203,370.2475021
85.6,59.90647168,1.91051984,220975.681,1.746617882,372.0093356
85.8,60.36554666,1.929649585,222007.6788,1.745310916,373.4323129
86,61.03483017,1.948955351,221949.1929,1.752281785,374.9152196
86.2,61.6159985,1.968461999,222127.8501,1.756638599,376.3294829
86.4,61.92289503,1.988285086,221956.4836,1.762738077,377.4833357
86.6,62.2671699,2.00820577,221926.3258,1.769273234,378.9618786
86.8,62.80504845,2.028210505,222286.5739,1.771887346,380.1397066
87,63.41351264,2.048512093,224314.9029,1.764916632,381.8764805
87.2,63.82915602,2.069032508,226374.3145,1.757945895,383.5674899
87.4,64.37440022,2.089749193,228404.8598,1.750539498,385.1397393
87.6,64.76421726,2.110685848,230911.0899,1.741826059,387.1031377
87.8,65.34097238,2.13181865,233209.0958,1.734419665,389.0501983
88,65.77060952,2.153174926,235019.6679,1.72875595,390.6671168
88.2,66.21600128,2.174744515,237320.0783,1.720913865,392.5607858
88.4,66.99292144,2.196505796,239755.4652,1.713507493,394.7366579
88.6,67.11914591,2.218535077,241882.4458,1.706536718,396.5355297
88.8,68.07050298,2.240723001,243951.7882,1.701744412,398.7462715
89,68.4658959,2.263176072,244370.6736,1.706972553,400.666089
89.2,69.06318225,2.285839462,244318.1311,1.714379091,402.3832516
89.4,69.20588374,2.308765185,243663.2066,1.724399621,403.8018665
89.6,69.72581575,2.331892371,242652.343,1.737469919,405.4264138
89.8,70.1044434,2.355262771,242077.2536,1.746183456,406.6532694
90,70.7880052,2.378844641,243208.8187,1.74531219,408.4706743
90.2,70.86158649,2.402709741,245083.4539,1.739648431,410.3240228
90.4,71.70960762,2.426755457,248479.4775,1.726142617,412.6862115
90.6,72.03656288,2.451082142,250996.1322,1.716993496,414.5166858
90.8,72.9177463,2.475610877,253913.2257,1.707844435,416.8865041
91,73.58574292,2.500402357,255362.744,1.705666142,418.6221912
91.2,74.4888686,2.525426066,256528.1719,1.706101921,420.6204684
91.4,75.00388431,2.550730725,256619.3615,1.713508448,422.6350817
91.6,75.59323279,2.576284055,256146.8043,1.722222016,424.1070934
91.8,76.03753358,2.602105089,256798.8284,1.725271796,426.1718258
92,76.76100418,2.62816432,256840.7978,1.731371322,428.031726
92.2,77.42875718,2.654489615,256722.9654,1.7383422,429.6573676
92.4,77.97555979,2.681088725,257797.7936,1.737906592,431.2830085
92.6,78.63616494,2.707946359,260478.5371,1.730500202,433.5928975
92.8,79.05740343,2.735092095,261805.3993,1.730064577,435.2675646
93,79.7727674,2.762488249,264490.3092,1.723965221,437.4968271
93.2,80.03727809,2.790193823,266474.5739,1.720915524,439.5680931
93.4,80.66696262,2.818150058,266620.6173,1.727668562,441.354991
93.6,81.29868,2.846386962,265801.0849,1.739214021,442.942499
93.8,81.88838754,2.874910828,265485.0199,1.747491917,444.7086945
94,82.35298622,2.903730786,264312.8519,1.758819521,445.9584343
94.2,83.06434161,2.932821495,264539.5195,1.762740681,447.5862581
94.4,83.91400968,2.962193947,266389.2233,1.757948362,449.6575375
94.6,84.44494788,2.991885825,268715.205,1.750106283,451.50545
94.8,85.20020481,3.021858981,272157.3696,1.738343152,453.9079557
95,85.80832946,3.052144382,275796.7903,1.726144326,456.3671147
95.2,86.71846907,3.082711205,278381.6418,1.71960931,458.6301601
95.4,87.04811633,3.113629336,280100.2971,1.7169953,460.6077261
95.6,87.79943953,3.144825941,280530.0009,1.722223491,462.7857812
95.8,88.40404395,3.176347143,280447.7729,1.72875869,464.4528281
96,88.87148551,3.208194591,281114.3221,1.732679822,466.5197421
96.2,89.55784114,3.240344662,281418.036,1.737908007,468.3850901
96.4,90.16603276,3.272823786,282262.1095,1.739650782,470.0891834
96.6,90.82569366,3.30562531,284761.343,1.734858435,472.4960469
96.8,91.35068247,3.338766668,286622.6386,1.731373098,474.3385111
97,92.28695649,3.372209628,288510.5983,1.729194835,476.6778263
97.2,92.95061371,3.40600933,291178.2535,1.722659787,479.0520033
97.4,93.50452681,3.440156978,292634.1305,1.721352829,481.0045153
97.6,94.17139948,3.474639298,293917.3951,1.722224259,483.4331704
97.8,95.01189329,3.509454591,295474.8067,1.719610309,485.4303632
98,95.93543017,3.544613435,296691.3538,1.72048177,487.7718578
98.2,96.69271368,3.580138173,297746.0959,1.722224563,489.9858706
98.4,97.67347584,3.616002832,300482.38,1.716560901,492.6923741
98.6,98.3159693,3.652253538,302594.4037,1.7126399,494.8213974
98.8,98.96920772,3.688867642,303690.7805,1.71438268,496.8425565
99,99.4736411,3.725860956,305261.6104,1.715254092,499.3986874
99.2,100.4151144,3.763192722,305190.8901,1.722660687,501.411136
99.4,101.236035,3.800908619,303587.5057,1.738345102,503.420314
99.6,102.2455294,3.838989157,302124.8748,1.75141549,504.854205
99.8,103.1328081,3.877461504,301308.3584,1.762307486,506.7195626
100,103.6676869,3.916347363,301035.4021,1.768842686,508.2046518
100.2,104.4891942,3.955601929,302197.8072,1.768407112,510.0885316
100.4,105.4394417,3.995241275,304634.4391,1.762307771,512.4474629
100.6,106.2998794,4.035285706,306493.8416,1.758822472,514.7181371
100.8,106.8228725,4.075758054,308492.7787,1.754030105,516.7087875
101,107.4870688,4.116626303,310296.3717,1.751851808,519.0110547
101.2,108.3514677,4.157889849,311354.6902,1.754030292,521.0943249
101.4,109.4883645,4.199547256,312335.0155,1.755773134,522.8692551
101.6,110.2670395,4.241650564,314536.9948,1.753594851,525.2423475
101.8,110.8694779,4.284190094,316509.272,1.750545195,527.1915961
102,111.6804263,4.327141257,320017.1878,1.741396103,529.8665014
102.2,112.2129253,4.370545153,323271.3968,1.732682652,532.4204542
102.4,113.1949192,4.414350947,325017.9701,1.730068716,534.5538492
102.6,114.2798856,4.458588954,326516.5036,1.729633171,537.2167738
102.8,115.3356969,4.503273763,326548.0539,1.734425734,539.1039296
103,115.8853656,4.54844587,325938.9858,1.743574995,541.2503909
103.2,116.9817519,4.594030247,326747.1925,1.746189184,543.4055782
103.4,117.8578538,4.640089385,328483.1504,1.745317939,545.9203196
103.6,118.8660092,4.686601342,330530.4773,1.74226833,548.0755073
103.8,119.9538652,4.733574568,333674.3131,1.736168998,550.833227
104,120.8338992,4.781035832,335888.2657,1.732683696,553.0821148
104.2,121.6082836,4.829224548,337989.8863,1.73050541,555.5772423
104.4,122.379344,4.877413482,339812.5766,1.730505503,558.2684913
104.6,123.3663456,4.926313952,341119.6226,1.730941299,560.3975278
104.8,124.3341565,4.975706976,343135.4349,1.729198711,563.1519794
105,125.5744526,5.025575612,344524.1455,1.728763185,565.3246066
105.2,126.4224428,5.075975121,344591.2018,1.734862755,567.6410485
105.4,127.5720013,5.12685809,344166.6107,1.743140743,570.0239622
105.6,128.3973932,5.178276944,343233.2482,1.752290046,571.7542162
105.8,129.2343368,5.230211569,341141.4423,1.768410172,573.7002049
106,130.3130152,5.282649664,340001.3967,1.778866538,575.1678803
106.2,130.9478621,5.335648438,341110.2068,1.780173647,577.1890437
106.4,132.1377246,5.389137235,343911.4307,1.774945678,579.685274
106.6,133.0433038,5.443185247,349212.4503,1.758825762,582.6238612
106.8,133.8199934,5.497786196,355569.4503,1.737913388,585.5101459
107,134.9289914,5.552910437,363746.3843,1.71220861,589.2942392
107.2,135.8766895,5.608600778,370763.0107,1.691731927,592.8201053
107.4,137.0528207,5.66483324,376374.8617,1.676919063,596.0245551
107.6,138.0302559,5.721645857,380661.8263,1.669512675,599.7716042
107.8,139.1131361,5.77902048,383112.96,1.667334419,602.6578981
108,140.0505018,5.836982287,384641.5579,1.670384265,606.0693592
108.2,141.2836071,5.895503381,384833.6431,1.677790912,609.0014192
108.4,142.4177314,5.95461967,384706.9286,1.686940256,612.1404974
108.6,143.5509301,6.014331769,384756.4946,1.693475541,614.519054
108.8,144.6192162,6.074649505,383097.9059,1.708288678,617.2375561
109,145.584779,6.135580864,382013.3986,1.718745037,619.3382712
109.2,146.7663017,6.197108009,381365.1304,1.72833007,621.7691306
109.4,147.9286135,6.259254793,380362.9716,1.740529161,624.3601567
109.6,148.7551065,6.322051524,379348.6079,1.75054983,626.2462227
109.8,149.9554444,6.385450717,380559.7269,1.753164036,628.9952382
110,151.4041471,6.44946809,381616.8938,1.755342599,631.3329496
110.2,152.5249222,6.514153633,383564.2887,1.754471383,634.1947334
110.4,153.1906274,6.579523596,385734.43,1.750986049,636.6451914
110.6,154.4782239,6.645503104,388895.3295,1.744886728,639.7189017
110.8,156.024153,6.712125829,391215.7764,1.7414015,642.2009851
111,157.109192,6.77945309,393589.8016,1.739223245,645.3302577
111.2,158.4060259,6.847440754,395718.5175,1.737916372,648.2143846
111.4,159.7659066,6.916106722,397987.2904,1.735738151,650.7596583
111.6,160.9216698,6.98547803,399225.3197,1.738788032,653.7843357
111.8,162.0573784,7.055547933,399346.3804,1.744016298,655.9874784
112,163.2735813,7.126315658,399873.6362,1.749680252,658.7877075
112.2,164.6612708,7.197781415,401302.8542,1.750987454,661.2981172
112.4,165.7883308,7.269985223,401509.1212,1.756215719,663.4914545
112.6,166.7341196,7.342928229,403774.6734,1.755344485,666.4355002
112.8,167.9889205,7.416580424,406053.554,1.753166252,668.9175771
113,169.3985836,7.490961,409052.706,1.749245326,671.9793097
113.2,170.5775281,7.566106426,410195.4824,1.751423858,674.6248211
113.4,171.4887738,7.642026657,412060.4458,1.751423971,677.5754059
113.6,173.1361567,7.718650291,414055.3577,1.750552816,680.5009497
113.8,174.1983997,7.796088577,416913.047,1.745324814,683.0963372
114,175.5970705,7.874279261,421017.849,1.737482786,686.5666604
114.2,176.9482501,7.953259065,426709.1119,1.724412617,690.1263269
114.4,178.2278385,8.033037778,432563.8434,1.710906759,693.4887795
114.6,179.6635259,8.113606179,438297.0839,1.700014984,697.7011022
114.8,180.9420274,8.19499605,441829.6294,1.694787001,700.9088374
115,182.2993433,8.277197701,443677.2732,1.696965552,704.5142681
115.2,183.7712048,8.360216429,443494.4641,1.70480793,707.6043374
115.4,185.1639897,8.444075197,441987.1004,1.717442758,710.734718
115.6,186.5907114,8.528773985,441800.808,1.724413779,713.1830286
115.8,188.1552427,8.614313256,441474.902,1.733563207,716.2360576
116,189.6141015,8.70072003,442550.7235,1.735741775,718.8249237
116.2,190.821863,8.788013885,444857.329,1.734870565,721.968376
116.4,192.4167274,8.876155463,446853.2166,1.735306437,725.3330244
116.6,193.511194,8.965220589,448461.3589,1.736613605,728.7957147
116.8,195.4697502,9.055114802,449601.2362,1.737920877,731.4619602
117,196.6769462,9.145969566,451575.8459,1.738356702,734.8701795
117.2,198.3859165,9.237698786,452644.4783,1.741406658,737.8676467
117.4,199.7340899,9.330377028,454700.7819,1.740971144,740.6286689
117.6,201.3131312,9.423968982,459273.3974,1.734871837,744.394277
117.8,202.8745724,9.518502624,462335.8983,1.732257955,747.3394433
118,204.4325389,9.613986202,466057.727,1.729208393,750.9786628
118.2,206.214721,9.710412135,471879.2914,1.719187999,754.8161962
118.4,207.6410845,9.807833861,475500.0962,1.716574098,758.7092853
118.6,209.1578707,9.90622755,476113.5092,1.720931068,761.4670443
118.8,210.6595421,10.00561092,477056.8211,1.725723715,765.0038459
119,212.4502405,10.10597082,476566.6226,1.733130471,767.6733618
119.2,213.861846,10.20736796,473255.4631,1.74968644,770.1336659
119.4,215.4959958,10.30976681,472309.4555,1.759271577,773.0799291
119.6,217.051038,10.41320045,474111.1585,1.760143126,776.3824751
119.8,218.6549437,10.51766972,474400.6338,1.764500114,778.8122786
120,219.9246234,10.62321388,475893.0663,1.76493595,781.4708808
120.2,221.7891261,10.72977323,479680.2048,1.758836672,784.8802208
120.4,223.5479227,10.83741108,481657.4229,1.758836888,788.3767235
120.6,225.3223364,10.94612914,483596.9121,1.757965747,791.2173038
120.8,227.0367452,11.05594416,489432.3441,1.746202616,795.2836501
121,228.7360209,11.16686371,494081.4085,1.737924916,798.5927459
121.2,230.8929974,11.2788631,498262.3781,1.732697025,802.3758211
121.4,232.7697503,11.39200901,503447.7276,1.72572638,806.7254687
121.6,234.5499274,11.50629902,506653.4021,1.723112517,810.1108366
121.8,236.5458883,11.62230295,508658.8047,1.725726835,813.9647326
122,238.4029797,11.73890642,510195.3521,1.727469777,817.0166987
122.2,240.1934997,11.85609404,513791.2385,1.724420235,820.8095693
122.4,242.1175288,11.97504131,517254.2787,1.722677748,824.8857376
122.6,243.7837597,12.09520327,519966.4549,1.722677949,829.0861038
122.8,245.7024215,12.21655341,520657.4676,1.726599298,832.122821
123,247.6375095,12.33912162,521552.1588,1.730084971,835.2325416
123.152,249.0658312,12.43309972,522726.0007,1.732263543,838.0382464
123.4,251.0302583,12.43543632,525425.0778,1.734442178,842.7855971
123.6,251.8588548,12.43537338,527040.9696,1.736620678,845.8484199
123.8,252.7796918,12.43530345,530070.7212,1.736620789,849.9267273
124,253.1312971,12.43527664,530643.9379,1.742720353,853.5582929
124.2,253.6590733,12.43523648,528366.0094,1.754919459,856.3410806
124.4,254.5574736,12.43516825,526688.807,1.764068851,858.809002
124.6,254.8035424,12.43514943,526530.9799,1.770168403,862.0701011
124.8,255.3321498,12.43510922,527565.734,1.771911189,864.7058036
125,255.8217003,12.43507195,531807.1111,1.766247407,868.4833758
125.2,256.2547432,12.43503897,538623.6877,1.754048415,872.5289756
125.4,256.0903002,12.43505125,548345.2337,1.736621188,877.5649787
125.6,256.5765268,12.43501424,554021.934,1.728343323,881.367607
125.8,256.8084688,12.43499649,558163.3564,1.725293589,885.7422526
126,257.3291817,12.43495687,558875.8894,1.731393175,889.5928238
126.2,257.1593373,12.43496955,557691.8286,1.741413795,892.7885343
126.4,257.3688424,12.4349535,554843.4599,1.754484231,895.2934705
126.6,257.4927549,12.43494393,550060.6339,1.773654176,897.9444094
126.8,257.6515692,12.43493172,547937.9093,1.784981878,900.2194447
127,257.727284,12.43492581,545621.7555,1.797616615,902.9564575
127.2,257.9326341,12.43491007,544344.6198,1.806765929,905.3764066
127.4,258.0698426,12.4348995,542392.3632,1.81722227,907.3027766
127.6,258.2864112,12.43488291,542560.8374,1.82245046,909.9406438
127.8,258.4913458,12.43486721,542761.0856,1.82593593,912.096919
128,258.5433772,12.43486309,543667.5548,1.828114336,914.7903453
128.2,258.5509503,12.43486233,544722.0659,1.828985699,917.2963639
128.4,258.7031167,12.43485062,546914.546,1.825935957,919.7958516
128.6,258.8295222,12.43484087,548787.9625,1.825064613,922.8107081
128.8,259.1283594,12.43481805,550061.3566,1.825500329,925.0835693
129,259.531071,12.43478737,550091.261,1.830292864,927.6669654
129.2,259.6940404,12.43477484,549506.4715,1.836828093,929.8788065
129.4,259.5632527,12.43478457,548672.3384,1.843363274,931.5709078
129.6,259.640214,12.43477856,545340.0527,1.857740736,933.2978849
129.8,259.6980624,12.43477399,542480.3562,1.870375473,934.8330962
130,259.7048045,12.4347733,542270.4183,1.874296598,936.151483
130.2,259.8204071,12.43476436,543136.3558,1.875603654,937.9776103
130.4,260.1300472,12.43474073,543960.1627,1.877346412,939.9955144
130.6,260.0025835,12.4347502,546800.224,1.872553917,941.985071
130.8,260.4173446,12.43471861,550068.6511,1.866890127,944.5161668
131,260.2229858,12.43473314,549645.259,1.870811225,946.1058461
131.2,260.6011831,12.43470432,548417.5775,1.877346479,947.6650434
131.4,260.5755164,12.43470608,546753.3107,1.885188721,949.22858
131.6,260.3155088,12.43472559,544336.8492,1.894337974,950.2309768
131.8,260.7925946,12.43468928,541471.1938,1.905665725,951.2094341
132,260.5300941,12.43470898,541062.3675,1.909586814,952.2238147
132.2,260.7761631,12.43469016,541004.5393,1.912636609,953.4201775
132.4,260.8427369,12.43468493,540898.0791,1.916122061,954.639413
132.6,260.856958,12.43468367,541552.2912,1.917429104,955.9392756
132.8,260.7215999,12.43469374,541351.5843,1.920478848,956.8980918
133,260.7590889,12.43469072,540800.4128,1.924399977,957.9266519
133.158,261.0513663,12.43466844,539872.3048,1.928756819,958.5836812
133.9,260.9046347,12.3084994,1.7977E+308,1.897387815,0
134.1,260.6976277,12.18420014,1.7977E+308,1.771911854,0
134.3,260.6726088,12.0598871,1.7977E+308,1.58151955,0
134.5,260.2927547,11.93560093,1.7977E+308,1.324903807,0
134.7,260.0691279,11.81130293,1.7977E+308,1.036047748,0
134.9,260.1006167,11.68698561,1.7977E+308,0.705366403,0
135.1,259.6426491,11.56270536,1.7977E+308,0.44526525,0
135.3,259.5154177,11.43840006,1.7977E+308,0.251387521,0
135.5,259.1413806,11.31411345,1.7977E+308,0.120247754,0
135.7,258.9933744,11.18980972,1.7977E+308,0.027012176,0
135.9,258.5453787,11.06552872,1.7977E+308,0.025269454,0
136.1,258.1339468,10.94124494,1.7977E+308,0.025269454,0
136.3,258.304212,10.81691711,1.7977E+308,0.021784012,0
136.5,257.8803152,10.69263428,1.7977E+308,0.01829857,0
136.7,257.8436624,10.56832211,1.7977E+308,0.016991529,0
136.9,257.6009227,10.44402556,1.7977E+308,0.013506087,0
137.1,257.341563,10.31973027,1.7977E+308,0.010456325,0
137.3,257.3764747,10.19479111,1.7977E+308,0.009149284,0
137.5,256.8677175,10.07113628,1.7977E+308,0.010456325,0
137.7,256.6249778,9.946839728,1.7977E+308,0.017427207,0
137.9,256.3041246,9.822549092,1.7977E+308,0.026140811,0
138.1,255.9583414,9.698260344,1.7977E+308,0.029626251,0
138.3,255.7928843,9.573957938,1.7977E+308,0.032676012,0
138.5,255.5027779,9.449664973,1.7977E+308,0.035725772,0
138.7,255.5932674,9.325343182,1.7977E+308,0.038775534,0
138.9,254.8926492,9.201081309,1.7977E+308,0.037904171,0
139.1,254.9008702,9.076765749,1.7977E+308,0.042696653,0
139.3,254.6888773,8.952466867,1.7977E+308,0.046182093,0
139.5,254.3822498,8.82755358,1.7977E+308,0.045310732,0
139.7,254.2757934,8.703246705,1.7977E+308,0.036161449,0
139.9,253.847643,8.579585769,1.7977E+308,0.026576486,0
140.1,253.6123823,8.45528865,1.7977E+308,0.023091045,0
140.3,253.3538538,8.330993294,1.7977E+308,0.018734243,0
140.5,253.2316084,8.206687615,1.7977E+308,0.013941762,0
140.7,252.8908114,8.082398489,1.7977E+308,0.009149281,0
140.9,252.7029174,7.958097782,1.7977E+308,0.011763362,0
141.1,252.5241644,7.833796383,1.7977E+308,0.020912643,0
141.3,251.9648156,7.709523811,1.7977E+308,0.028754882,0
141.5,251.6979771,7.585229084,1.7977E+308,0.032676002,0
141.7,251.5890278,7.460922398,1.7977E+308,0.026140801,0
141.9,251.2174839,7.336635601,1.7977E+308,0.023091041,0
142.1,250.8376301,7.212349434,1.7977E+308,0.02701216,0
142.3,250.7170468,7.088043629,1.7977E+308,0.02526944,0
142.5,250.3679398,6.963755133,1.7977E+308,0.019169919,0
142.7,250.0952844,6.839460846,1.7977E+308,0.013070399,0
142.9,249.9406303,6.715157622,1.7977E+308,0.016120159,0
143.1,249.8142301,6.590852257,1.7977E+308,0.029190558,0
143.3,249.7518165,6.466542047,1.7977E+308,0.042696637,0
143.5,249.2556234,6.342264691,1.7977E+308,0.050103194,0
143.7,248.983799,6.217970341,1.7977E+308,0.045310714,0
143.9,249.0319077,6.093651759,1.7977E+308,0.029190556,0
144.1,248.4904254,5.969377834,1.7977E+308,0.010891998,0
144.3,248.5842389,5.84505579,1.7977E+308,0.009584958,0
144.5,247.9800165,5.720786617,1.7977E+308,0.023091035,0
144.7,247.814144,5.596484242,1.7977E+308,0.026140794,0
144.9,247.4903825,5.472193827,1.7977E+308,0.020912635,0
145.1,247.1321346,5.347906023,1.7977E+308,0.014377436,0
145.3,246.7855208,5.223617338,1.7977E+308,0.011763357,0
145.5,246.6433316,5.099313169,1.7977E+308,0.010891997,0
145.7,246.3149996,4.9750231,1.7977E+308,0.010891996,0
145.9,246.1453877,4.850721008,1.7977E+308,0.009802797,0
146.1,245.7800764,4.726433739,1.7977E+308,0.008277917,0
146.3,245.6212674,4.60213083,1.7977E+308,0.013070395,0
146.5,245.3457037,4.477836763,1.7977E+308,0.013070395,0
146.7,245.0057378,4.353547575,1.7977E+308,0.006970877,0
146.9,244.3981916,4.229278653,1.7977E+308,0.005881677,0
147.1,244.6062668,4.104947955,1.7977E+308,0.016120153,0
147.3,244.0652002,3.980673998,1.7977E+308,0.027883506,0
147.5,243.9072222,3.856371026,1.7977E+308,0.031368944,0
147.7,243.5003613,3.732086904,1.7977E+308,0.033983022,0
147.9,243.3141295,3.607786071,1.7977E+308,0.033983021,0
148.1,242.9608677,3.48349789,1.7977E+308,0.028537024,0
148.3,242.7974883,3.359195326,1.7977E+308,0.021783987,0
148.5,242.1392515,3.234930244,1.7977E+308,0.012634712,0
148.7,242.0344572,3.110623243,1.7977E+308,0.012634712,0
148.9,241.5615322,2.986344125,1.7977E+308,0.022655345,0
149.1,241.2589612,2.862052105,1.7977E+308,0.026140782,0
149.3,240.8766147,2.737766126,1.7977E+308,0.020912625,0
149.5,240.525846,2.613477756,1.7977E+308,0.01307039,0
149.7,240.2407259,2.489184413,1.7977E+308,0.007842234,0
149.9,239.9846906,2.364888867,1.7977E+308,0.009584952,0
150.1,239.4278353,2.240616106,1.7977E+308,0.013506069,0
150.3,239.1078134,2.116325407,1.7977E+308,0.017427185,0
150.5,239.1525981,1.992007077,1.7977E+308,0.016991505,0
150.7,238.6971242,1.867726637,1.7977E+308,0.017427185,0
150.9,238.0255917,1.743462562,1.7977E+308,0.015248786,0
151.1,237.8584728,1.619160282,1.7977E+308,0.012199028,0
151.3,237.3564632,1.494883367,1.7977E+308,0.012199028,0
151.5,236.9882437,1.370596318,1.7977E+308,0.010456309,0
151.7,236.5518827,1.246314431,1.7977E+308,0.015248784,0
226.9,236.0168891,1.128187618,1.7977E+308,0.030497569,0
227.1,235.6794164,1.003898241,1.7977E+308,0.025705093,0
227.3,235.2821121,0.879613395,1.7977E+308,0.016120143,0
227.5,234.9205406,0.755325843,1.7977E+308,0.002614077,0
227.7,234.2165995,0.631064223,1.7977E+308,0.019605578,0
227.9,234.150031,0.506754327,1.7977E+308,0.03485436,0
228.1,233.3123986,0.381881258,1.7977E+308,0.045746345,0
228.3,232.6624722,0.257615546,1.7977E+308,0.050103137,0
228.5,231.727416,0.133993005,1.7977E+308,0.051410172,0
228.7,230.5473154,0.009767449,1.7977E+308,0.046617694,0
228.712,230.4852016,0.002313257,1.7977E+308,0.045746335,0