File: Test_8.csv
Time On Sample,Displacement Into Surface,Load On Sample,Harmonic Contact Stiffness,Harmonic Displacement,Harmonic Load
0,0,0,-95.9320052,0.520591177,2.151775384
0.2,0.21450332,0.00074172,2138.0752,0.328909075,2.226951359
0.4,0.399924403,0.001485643,6611.64151,0.233939305,2.283605721
0.6,0.541306667,0.002232901,13290.50011,0.177741597,2.350065639
0.8,0.543094174,0.002990734,16487.6142,0.157702103,2.465553336
1,0.439354692,0.003756561,19232.13635,0.141583379,2.602831151
1.19,0.48272352,0.004473346,21265.35577,0.132870557,2.711781814
1.4,0.776960311,0.0052451,23871.71218,0.125029018,2.874118332
1.6,0.850207325,0.005995739,25650.57539,0.120236966,3.012485682
1.8,0.923454339,0.006746377,27233.81596,0.121108249,3.303383952
2,0.59121181,0.007527732,28263.90376,0.125464658,3.678174164
2.2,0.756691075,0.008271385,28609.5465,0.133306201,4.03008481
2.4,0.846556513,0.009020765,30065.68829,0.137662614,4.322072598
2.6,1.200654898,0.009750128,30458.18309,0.150296212,4.685967887
2.8,1.000528834,0.010521474,32489.71347,0.162058523,5.267764352
3,1.145235075,0.011266698,35089.336,0.170771348,5.912752311
3.2,1.075563641,0.012028162,37517.60299,0.177305966,6.542487094
3.4,1.398917949,0.012759852,38437.96702,0.188197,7.162416466
3.6,1.165555032,0.013533715,40045.87976,0.19298905,7.677753023
3.8,1.163188217,0.01429008,41005.34545,0.208672134,8.585312034
4,1.234773393,0.015040843,40594.81192,0.230454195,9.462364889
4.2,1.246532239,0.015796137,39985.97853,0.252236255,10.19124482
4.4,1.104570658,0.016563076,40038.55159,0.276196519,11.0846402
4.6,1.158706488,0.017315161,39009.59166,0.307998328,11.97040909
4.8,1.388166699,0.018053963,39123.90631,0.332829882,12.92045902
5,1.165605757,0.018827007,39760.56587,0.356354502,14.0263081
5.2,1.234698169,0.019577957,40037.22617,0.376394,14.93386718
5.4,1.170012262,0.020339042,40095.21253,0.402096829,16.00267312
5.6,1.274003367,0.021087348,40822.85725,0.421700687,17.09653783
5.8,1.146998367,0.021853153,41169.97508,0.446096591,18.2176401
6,1.037442714,0.022617637,41202.1669,0.470928137,19.20473302
6.2,1.099887756,0.023369091,40673.82946,0.507522,20.34544649
6.4,1.010274212,0.024132064,39265.912,0.55544253,21.41752092
6.6,0.960544888,0.024892016,37103.05339,0.616867937,22.40461389
6.8,0.84766555,0.025656751,35244.30233,0.676986418,23.31544133
7,1.03724154,0.026398576,33117.02229,0.75017415,24.23280612
7.2,1.096362898,0.027150282,31270.6159,0.822490594,25.06083118
7.4,1.096488848,0.027906456,29597.65434,0.897420882,25.86488717
7.6,0.971145691,0.028672136,28175.78934,0.963638338,26.44559403
7.8,1.003677568,0.029425856,26717.91693,1.03900427,27.08404496
8,1.060306163,0.030177751,25297.39147,1.117419692,27.70833239
8.2,1.123582127,0.030929142,24245.48591,1.178845109,28.1713728
8.4,0.861967886,0.031705144,22924.82038,1.258567428,28.69215661
8.6,1.453709767,0.032416503,21832.26596,1.330012642,29.14866078
8.8,1.398994914,0.03317683,21159.36608,1.380982661,29.54306209
9,1.640088034,0.033914749,20897.04749,1.412784496,29.91131575
9.2,1.624426481,0.034672116,20898.54409,1.436744763,30.38089311
9.4,1.662774811,0.035425393,21370.29074,1.429774509,30.83303848
9.6,1.59642706,0.036186599,22714.0138,1.384903458,31.54339674
9.8,1.896515597,0.036920048,24272.71175,1.333933465,32.24503937
10,1.720486234,0.037689563,25872.61735,1.282963426,32.92053331
10.2,1.610099654,0.038454105,28050.18713,1.219359798,33.80412308
10.4,1.365934749,0.039228782,29706.1803,1.178845145,34.52973431
10.6,1.667685126,0.039962107,30519.83789,1.174488759,35.30110544
10.8,2.235329729,0.040679074,30159.93625,1.206290619,35.87745553
11,2.397485944,0.041419182,29500.49775,1.246805271,36.31543746
11.2,2.467409289,0.042170062,28561.13431,1.303003001,36.78937301
11.4,2.387351333,0.042932304,27585.94798,1.362250205,37.202296
11.6,2.480540476,0.043681422,27465.87494,1.38098279,37.59887652
11.8,2.882832366,0.044407125,28500.83997,1.353537431,38.21444868
12,2.527739438,0.0451902,30059.02077,1.311280196,38.98363979
12.2,2.572319684,0.045943,31224.9036,1.282527879,39.58068962
12.4,2.832524024,0.046679466,32772.84234,1.247676602,40.39128319
12.6,2.608301209,0.047452628,33588.98716,1.236349911,41.00467494
12.8,2.75342294,0.04819781,33583.78271,1.253339935,41.58211398
13,2.650930106,0.04896175,33455.8376,1.275557632,42.21184871
13.2,2.576273137,0.049723582,33382.59955,1.292983277,42.71520063
13.4,2.804071545,0.050462502,33255.9551,1.314765363,43.29263974
13.6,2.557829314,0.05123733,33313.53519,1.330012786,43.89077845
13.8,3.162035109,0.051947737,33454.48276,1.340032594,44.45078627
14,2.89668168,0.052724012,33465.91821,1.352666168,44.92363161
14.2,3.089165935,0.053465606,33440.60123,1.369656198,45.51305519
14.4,2.894440824,0.054236531,33447.84272,1.381854137,45.96411069
14.6,3.173340905,0.054971579,33312.55362,1.401893665,46.49905911
14.8,2.750943334,0.05575975,33255.55816,1.418447993,46.9849782
15,2.911021654,0.056503798,33262.42748,1.431952891,47.41751279
15.2,2.885389046,0.057261914,33280.65594,1.447635976,47.93502836
15.4,3.006829523,0.058008889,33287.83814,1.460269582,48.34686232
15.6,3.181448972,0.058751835,33347.17719,1.472903205,48.84803587
15.8,3.01705249,0.059520462,33313.89165,1.486843711,49.28928593
16,3.25149828,0.060258877,33294.56337,1.498606049,49.68150866
16.2,3.182657759,0.061020264,33400.67368,1.508625792,50.16416003
16.4,3.149546857,0.061778945,33450.48746,1.518209901,50.53350279
16.6,3.288436688,0.062524597,33514.45009,1.531279159,50.99436494
16.8,3.310166601,0.063279124,33536.35875,1.544348396,51.39203461
17,3.342698492,0.064032832,33572.10478,1.553932512,51.73849789
17.2,3.681840392,0.064763313,33601.21926,1.565694867,52.1743015
17.4,3.386989238,0.065541819,33930.7757,1.562209704,52.55562817
17.6,3.712836398,0.066273308,34691.89763,1.544784089,53.0927559
17.8,3.284206893,0.067061948,35692.91874,1.519952492,53.64077675
18,3.448855292,0.067805647,36640.64364,1.49817045,54.15502458
18.2,3.838683406,0.068532288,37705.81783,1.476388422,54.78040241
18.4,3.626093471,0.069304562,38263.8579,1.472903272,55.36437753
18.6,3.465851589,0.070072871,38585.14484,1.473338903,55.80344839
18.8,3.745167151,0.070807883,38897.28301,1.477695342,56.40594645
19,3.778529966,0.071561525,39255.6437,1.476388424,56.87661354
19.2,3.94151653,0.072305348,40243.10056,1.457220228,57.53140781
19.4,3.404867227,0.073102169,41231.61982,1.436745034,58.10121846
19.6,3.492239935,0.073851721,41977.33004,1.427596577,58.74402783
19.8,3.621158716,0.074598125,42654.33302,1.420190689,59.35633099
20,3.675294567,0.075350193,43131.32302,1.421061979,60.01657235
20.2,3.615594179,0.076110884,42941.4779,1.441101475,60.58856327
20.4,3.254269307,0.076894424,42619.73726,1.462012223,60.99930644
20.6,4.240699042,0.077575871,42330.76871,1.482923111,61.49067698
20.8,4.286525682,0.078328567,41910.36372,1.507319032,61.94282249
21,4.126283791,0.079096872,41609.90941,1.52779416,62.42111548
21.2,4.261849844,0.079843455,41621.05031,1.53868521,62.93209462
21.4,4.268622057,0.080606133,41851.37053,1.539556495,63.36462901
21.6,4.170696945,0.081384399,42915.08942,1.517774419,64.01724335
21.8,4.321216138,0.082151536,44299.14323,1.487715185,64.69273812
22,4.302226115,0.082939252,45739.41368,1.459834139,65.46519848
22.2,4.4411099,0.083723052,46852.82583,1.442408501,66.22022745
22.4,4.270889635,0.084538127,47505.20211,1.435873865,66.79657589
22.6,4.173789157,0.085355878,47396.21873,1.452428228,67.4143259
22.8,4.480515246,0.086151132,46817.72925,1.480744949,67.92421613
23,4.50306489,0.08697602,46130.7155,1.512546772,68.41558394
23.2,4.320375607,0.087824713,45816.7617,1.531279332,68.81870093
23.4,4.479193734,0.088655925,45595.37988,1.549140646,69.33185937
23.6,4.73024282,0.089488535,45697.98256,1.557417862,69.8722556
23.8,4.567491639,0.090360956,46037.42165,1.558289128,70.41482957
24,4.563445072,0.091230149,46422.8798,1.556546564,70.89094402
24.2,4.841079538,0.092086613,46617.84994,1.563516859,71.46402579
24.4,4.588584677,0.092991952,46745.26921,1.571358377,72.00659927
24.6,4.420842359,0.093900035,46731.27897,1.58094247,72.42388003
24.8,4.87296609,0.094770067,46626.59293,1.594011763,72.87166893
25,4.956159249,0.095676934,46658.63109,1.603160244,73.38155857
25.2,4.913881791,0.096602495,46829.19819,1.607952296,73.90125324
25.4,4.982115443,0.097528856,47057.8003,1.60925923,74.3087291
25.6,4.629901278,0.09849657,47476.7159,1.607516626,74.86873447
25.8,4.683175337,0.09944296,47968.20728,1.602724579,75.39278781
26,4.756389972,0.100397535,48423.57216,1.600546383,75.9669582
26.2,4.904386046,0.101355899,48786.4893,1.600546401,76.50517494
26.4,4.897829171,0.102335652,49136.44227,1.598803837,76.9486045
26.6,5.137223524,0.103306569,49528.74467,1.597932583,77.50752253
26.8,5.077484532,0.104310076,50075.24829,1.591833599,78.06534973
27,5.339310621,0.105299118,50856.67367,1.580506954,78.70924953
27.2,5.220573004,0.10632718,51823.0282,1.564823853,79.4108915
27.4,5.247245026,0.107354531,52580.74662,1.554804106,80.08747565
27.6,5.38110431,0.10838398,53116.98091,1.549576426,80.63005051
27.8,5.578942933,0.109418818,53573.55351,1.548269525,81.24235424
28,5.782596347,0.110463677,53597.45165,1.559596226,81.85574754
28.2,6.137475848,0.11150749,53461.59921,1.574408075,82.41357672
28.4,6.582508265,0.11255765,53509.08419,1.584427879,82.97794316
28.6,6.587565948,0.113651946,53684.36126,1.588348655,83.44969982
28.8,6.588053124,0.114749343,54022.20388,1.58921994,84.03149649
29,6.474285932,0.115871987,54926.27001,1.575715045,84.7374967
29.2,6.660895144,0.116983084,56336.72548,1.550883506,85.56879133
29.4,6.620245505,0.118122548,57443.20974,1.532150921,86.23556962
29.6,6.680966489,0.119265795,58841.05734,1.509933217,87.08538543
29.8,6.607491801,0.120430659,60163.39278,1.490764988,87.93084243
30,6.892557986,0.121579909,61153.07279,1.480745266,88.82206068
30.2,6.683639365,0.122778293,61693.42645,1.47900268,89.51825474
30.4,6.856111896,0.123959765,62094.39744,1.482487832,90.3201328
30.6,6.739006309,0.125175176,62358.7338,1.488586801,91.09804033
30.8,6.974625066,0.126375924,62577.40407,1.49512145,91.82583234
31,6.837158048,0.127617088,62754.30315,1.504705549,92.62117181
31.2,6.88540007,0.128856517,62844.66824,1.512982743,93.23347521
31.4,6.838084082,0.130115857,62832.9057,1.526051984,93.97542924
31.6,7.047936375,0.131368218,62508.75344,1.545655873,94.64983496
31.8,7.264434055,0.132632595,62204.05265,1.563517199,95.25124403
32,7.259904509,0.133926604,62015.88105,1.578764651,95.89841144
32.2,7.452301361,0.135218613,62079.46404,1.585734938,96.44098678
32.4,7.188104642,0.13655828,62319.86977,1.590091325,97.12737507
32.6,7.272062017,0.137884864,63134.4932,1.581378507,97.91617862
32.8,7.572056923,0.139208433,63899.87103,1.573101355,98.64723977
33,7.432492073,0.140578857,64746.8411,1.565259795,99.5057704
33.2,7.481544287,0.141948656,65463.77218,1.55872518,100.1834442
33.4,7.432545555,0.1433396,66389.97427,1.550447984,101.0343486
33.6,7.518153935,0.144734255,67005.67255,1.550012358,101.8808963
33.8,7.646968013,0.146139693,67542.90211,1.550012374,102.6500894
34,7.629537624,0.147570291,68022.85503,1.549576725,103.3288518
34.2,7.877168975,0.148995302,68192.40861,1.557418303,104.1067612
34.4,7.750883242,0.150463031,68334.69112,1.565695482,104.8857587
34.6,8.23532273,0.151898897,68121.40218,1.580942989,105.5950305
34.8,8.342521423,0.153377851,67834.4319,1.596626094,106.1986175
35,8.555244804,0.154863814,67628.39184,1.609695368,106.7259401
35.2,8.695675614,0.156370196,67617.61882,1.620586421,107.426494
35.4,8.600953123,0.157909645,67821.94113,1.626249757,108.1281362
35.6,8.440585366,0.159469432,68479.56414,1.620150752,108.7567811
35.8,8.699830646,0.161013058,69475.94287,1.608388469,109.5368697
36,8.834435187,0.162581654,70814.60197,1.591398467,110.4858312
36.2,8.955742475,0.164167011,71812.51908,1.580507443,111.2659191
36.4,9.137704526,0.165763716,72497.96109,1.578329257,112.1538685
36.6,8.995604486,0.167401121,72785.22275,1.58181438,112.8424367
36.8,9.234064069,0.169025977,72799.8169,1.591834157,113.562602
37,9.051243645,0.170699257,72454.7636,1.610131089,114.3023765
37.2,9.045406937,0.172375739,72118.56885,1.624942903,114.8427725
37.4,9.089422853,0.174065353,72006.88485,1.636705231,115.5465946
37.6,9.237301327,0.175763931,71883.64177,1.648467572,116.2253584
37.8,9.014585907,0.177507832,71845.02493,1.657180378,116.8496451
38,9.164120737,0.179240809,72014.66249,1.66066553,117.4194582
38.2,9.405885102,0.180984388,72589.12279,1.658487353,118.2028154
38.4,9.227200198,0.182777417,73061.13615,1.656744768,118.8325496
38.6,9.461480646,0.184556935,73700.57302,1.653259665,119.618086
38.8,9.903488718,0.18633869,74612.24169,1.644111246,120.4014441
39,9.773819647,0.188181823,75254.29692,1.639754817,121.0769383
39.2,10.54071244,0.189975307,75707.41076,1.641497474,121.8908045
39.4,10.59134761,0.191841346,76027.17675,1.643240048,122.5172715
39.6,10.61788309,0.193727831,76508.80069,1.644111337,123.3300442
39.8,11.12718122,0.195596724,76653.92089,1.65021038,124.018616
40,10.66845223,0.197557967,76800.024,1.655002386,124.6189319
40.2,10.83041886,0.199491576,77246.48897,1.65587369,125.4240786
40.4,10.97160936,0.201446231,77911.03711,1.651081651,126.115917
40.6,11.2357732,0.203411209,78887.77086,1.642368852,126.9809875
40.8,11.0595452,0.205429499,80018.39268,1.630606511,127.8515025
41,11.51980027,0.20741961,81288.77437,1.615794751,128.7013214
41.2,11.41087055,0.209473124,82595.54396,1.602725492,129.735263
41.4,11.23712563,0.211552141,83246.65977,1.599240341,130.5371395
41.6,11.3084994,0.213633373,83531.39664,1.603596767,131.446879
41.8,11.33416914,0.21573902,83445.49131,1.614052171,132.2247874
42,11.39057962,0.21786349,83150.7841,1.627121428,132.8556126
42.2,11.37303465,0.220014918,82935.07738,1.641061959,133.6313416
42.4,11.44854954,0.222180744,82859.12354,1.651081727,134.2556303
42.6,11.60050577,0.224362691,83093.18671,1.657616371,135.0651352
42.8,11.55719183,0.22658146,83542.25316,1.658923293,135.8441327
43,11.77644574,0.228802395,83868.0917,1.661101529,136.5076441
43.2,11.75223591,0.23106431,84388.84457,1.66153717,137.3759815
43.4,11.82025484,0.233341837,84819.57379,1.661101538,138.0580138
43.6,11.76612458,0.235651585,85403.59253,1.660230251,138.9394249
43.8,11.88731519,0.237971162,86101.6688,1.656745134,139.7674515
44,12.00019289,0.240314651,86743.6207,1.653260016,140.5072276
44.2,11.78734538,0.242706452,87341.0646,1.652824352,141.4082492
44.4,12.1960238,0.245074881,87845.97997,1.651953118,142.1295061
44.6,12.22745979,0.247495927,88251.83868,1.654566974,143.0250819
44.8,12.45997507,0.249925986,88073.81333,1.665893686,143.7332629
45,12.45733549,0.252398408,87807.23969,1.677656012,144.3194178
45.2,12.53612232,0.254889605,87261.51206,1.695952974,145.0058079
45.4,12.41963847,0.2574206,86731.59088,1.712071703,145.5026227
45.6,12.71279521,0.259945838,86259.00632,1.728626124,146.0931381
45.8,12.94612152,0.262501081,86125.53635,1.738210271,146.6542364
46,13.01159644,0.265101183,86391.9813,1.740824131,147.3199258
46.2,13.00519245,0.267732842,87005.07979,1.736032074,147.9453032
46.4,13.25969486,0.270364548,87607.76524,1.732982616,148.6948864
46.6,13.12657,0.273038802,88198.65823,1.728626185,149.3169942
46.8,13.47495813,0.275716843,88833.11143,1.724269813,150.0219083
47,13.25706852,0.278464748,89347.6223,1.723398505,150.8085314
47.2,12.99679751,0.281243358,89693.28062,1.723834117,151.42737
47.4,13.29240898,0.284007742,90268.74969,1.721655947,152.2129069
47.6,13.37197627,0.28681638,90505.99543,1.723834167,152.817584
47.8,13.75067105,0.289630594,90566.68773,1.729497557,153.4560384
48,13.40479719,0.292528044,90517.93569,1.737774709,154.1435152
48.2,13.61729844,0.295412103,90374.06434,1.74605193,154.656675
48.4,13.66028694,0.29833805,90365.12491,1.753457846,155.2885901
48.6,13.93218986,0.301275962,90427.68231,1.758249941,155.8028394
48.8,13.84637605,0.304270654,90739.90936,1.759556858,156.3955312
49,14.00443314,0.307276823,91349.56534,1.756507387,157.1146074
49.2,14.12634031,0.31031599,91859.78039,1.753893554,157.7149272
49.4,15.55320613,0.313286343,92248.74941,1.754329375,158.4111333
49.6,15.5745621,0.31639361,92998.52689,1.747359112,159.0604801
49.8,15.81444571,0.319515406,94220.98582,1.733418607,159.892866
50,15.77014885,0.322690337,95898.5008,1.713379082,160.9137345
50.2,15.8288813,0.325889356,97515.5803,1.693775211,161.7918783
50.4,15.99147392,0.329112653,99999.20588,1.664151592,163.0208441
50.6,15.8673932,0.332389995,101486.8889,1.649339759,163.9621778
50.8,16.24767712,0.335662022,102190.4107,1.64803288,164.9187687
51,16.01390418,0.339013566,102364.462,1.655438765,165.8590122
51.2,15.92803007,0.342387502,102255.4064,1.666765444,166.7567657
51.4,16.12217143,0.345773954,101900.7006,1.679399072,167.4050252
51.6,16.17837426,0.349205033,101573.9588,1.692903979,168.2221558
51.8,16.47803186,0.352652122,101786.5531,1.697260438,169.0414676
52,16.76605105,0.356134654,102060.6347,1.699438678,169.7572766
52.2,17.69553686,0.359603293,102425.6887,1.701617006,170.6746499
52.4,17.98769959,0.36315538,102733.7186,1.70248832,171.3937276
52.6,18.12862876,0.366754597,103451.4392,1.698567564,172.3546747
52.8,18.31525294,0.370386444,104175.2827,1.694646813,173.2589678
53,18.36227632,0.374065522,104932.9882,1.689854763,174.0804572
53.2,18.67269627,0.377761508,105959.4584,1.683755815,175.134014
53.4,18.44134881,0.381535869,106923.9892,1.677656803,175.9751121
53.6,18.61382369,0.385317438,108410.6849,1.667201423,177.1180074
53.8,18.57523822,0.389152929,109903.8455,1.655874735,178.2227681
54,18.85488995,0.393002802,111099.5663,1.647597572,179.2392814
54.2,18.87528768,0.396911165,112675.9581,1.636270886,180.5466911
54.4,19.23303374,0.400833086,113630.8591,1.631043224,181.5501311
54.6,19.16284841,0.404827019,114121.8234,1.634092718,182.7355162
54.8,19.51559632,0.408828732,113918.54,1.645855092,183.7106286
55,19.38058626,0.412907902,113569.9305,1.658488693,184.4918046
55.2,20.0465791,0.41696703,112685.2685,1.680270869,185.3503431
55.4,19.92069618,0.421127262,112110.9436,1.695953965,186.0225683
55.6,19.95683654,0.425316966,111707.3083,1.710330155,186.8288047
55.8,20.18075872,0.429534469,111928.9115,1.715122245,187.657922
56,20.28252855,0.433803577,112742.7553,1.71294405,188.6853293
56.2,20.58205115,0.438100606,113575.7495,1.708152027,189.511179
56.4,21.12419632,0.442422362,114655.1744,1.701617465,190.601782
56.6,21.20766525,0.446822468,115804.1961,1.692904638,191.5529233
56.8,21.40911819,0.451257812,116769.4922,1.687676961,192.5955843
57,21.30561541,0.455760864,117514.2917,1.685498741,193.7232239
57.2,21.53115085,0.460284095,118088.9011,1.684627486,194.6395027
57.4,21.58633989,0.464865779,118596.996,1.686805705,195.7170266
57.6,21.91988074,0.469472355,118786.6782,1.691597808,196.5537721
57.8,21.86204959,0.474155141,119403.7592,1.691597803,197.5746404
58,22.19308284,0.478855213,120405.4558,1.688112709,198.7349701
58.2,22.22746916,0.483625095,121118.6828,1.686370147,199.6773947
58.4,22.10480345,0.488454848,121899.0048,1.685063209,200.826825
58.6,22.50727323,0.493293197,122705.9871,1.682013765,201.7975805
58.8,22.47682451,0.498213065,123100.6182,1.685063257,202.7846745
59,22.63000187,0.503168392,123363.7583,1.690726624,203.8927062
59.2,22.8305339,0.508170053,123723.9472,1.693340502,204.7643142
59.4,22.81501801,0.513238395,124651.9953,1.691597934,205.9486103
59.6,23.11524472,0.518333561,125285.4974,1.69116233,206.8343827
59.8,23.31076701,0.523487897,126383.0726,1.686370293,207.9543989
60,23.39161371,0.52870277,127708.7287,1.679835675,209.2116929
60.2,23.27884707,0.533984759,129135.6347,1.672429749,210.5648608
60.4,23.38875932,0.539302804,130352.4085,1.665459492,211.6532807
60.6,23.35657527,0.544685096,131385.2661,1.662409996,212.9999119
60.8,23.67752485,0.550094568,131961.1494,1.663716962,214.1700475
61,23.56804772,0.555591252,132172.4084,1.668073371,215.1484247
61.2,23.64136485,0.561129247,132197.6369,1.676350581,216.3185579
61.4,24.0104817,0.566700313,131641.6218,1.689419888,217.1574828
61.6,24.13446738,0.572346101,131143.0006,1.703360451,218.1532945
61.8,24.44041616,0.57803485,130849.5156,1.714251542,219.0575896
62,24.89259832,0.583769494,130265.6968,1.727756503,219.7875652
62.2,25.37219179,0.589559725,129395.8544,1.74561789,220.6221331
62.4,25.17041917,0.595459927,128770.4338,1.759122772,221.2475099
62.6,26.07875027,0.601334907,128418.2355,1.770449582,222.0319657
62.8,26.21098987,0.607328166,128296.2406,1.777855517,222.760848
63,26.36648579,0.613379647,128811.1121,1.776548613,223.4995365
63.2,26.66655271,0.61948054,130260.9677,1.766093241,224.5955853
63.4,26.49838476,0.625678316,131716.1274,1.754330885,225.535829
63.6,26.98497174,0.631904545,133357.5219,1.742568609,226.7484571
63.8,27.43207993,0.638196443,134558.953,1.735598392,227.7976589
64,27.29504164,0.644580251,135359.785,1.732984524,228.7335456
64.2,27.49909219,0.6509701,135948.2338,1.733855836,229.8230561
64.4,27.3682628,0.657498267,136325.6889,1.736034033,230.763845
64.6,28.45971615,0.663966188,137176.2202,1.732984673,231.8027037
64.8,28.59019392,0.670588765,138542.5278,1.724271847,232.9564945
65,28.7327095,0.677276931,140405.8783,1.7112026,234.3085764
65.2,29.08502251,0.684016387,141963.6277,1.700747232,235.4471166
65.4,29.10911009,0.690848553,143943.958,1.688113612,236.916864
65.6,29.40448321,0.697728595,145297.801,1.680707732,238.0848205
65.8,29.36249049,0.704703571,146414.4867,1.677222591,239.4161992
66,29.57641099,0.711729084,147056.3492,1.67940083,240.808594
66.2,29.61873463,0.718838227,147712.2196,1.679836479,241.9373256
66.4,30.17705026,0.725979676,148410.9535,1.681579117,243.3319029
66.6,30.70377944,0.733195102,148858.5314,1.684193035,244.3854647
66.8,30.7793057,0.740517562,149569.2721,1.685499973,245.6253257
67,30.9707341,0.747904686,150146.4937,1.688985136,246.9970195
67.2,31.11271075,0.755369839,150399.3878,1.693341578,248.0276967
67.4,31.4108891,0.76289799,150346.9279,1.702490104,249.263203
67.6,31.58940252,0.7705105,150405.9572,1.708153478,250.2208825
67.8,31.94987599,0.778185773,150310.0097,1.715995085,251.2788002
68,31.90318475,0.785969059,150797.6766,1.719044578,252.548078
68.2,32.23205846,0.79380204,151574.8963,1.717737693,253.5918308
68.4,32.19282063,0.80174142,152779.2603,1.714252552,254.9428217
68.6,32.42029653,0.809740366,153772.7331,1.711638728,256.0552128
68.8,32.76159619,0.817810882,154880.1266,1.709024917,257.3473747
69,32.73810755,0.825990369,155314.8941,1.713381332,258.6329949
69.2,33.01373832,0.834229093,155352.98,1.719480363,259.589587
69.4,33.15142263,0.842561154,155362.5907,1.726886303,260.7945845
69.6,33.35141291,0.850972138,155566.4142,1.730371471,261.777324
69.8,33.99925752,0.859433654,155485.4236,1.73690619,262.7883965
70,34.21168471,0.868013268,155686.5353,1.741262636,263.986859
70.2,34.37424277,0.876682969,156136.0924,1.741698301,264.9892093
70.4,34.90904075,0.885411424,156656.0141,1.743005296,266.1996606
70.6,34.78988795,0.894277312,156736.0839,1.747797349,267.0876089
70.8,34.97483902,0.903209133,157463.0151,1.747361736,268.1999999
71,35.3699995,0.912214684,157879.8318,1.750846926,269.3625111
71.2,35.78758056,0.921308985,158049.5154,1.75563905,270.2624511
71.4,36.34308045,0.930484071,158817.119,1.756510403,271.4565602
71.6,36.99412194,0.93974412,159759.5543,1.753460986,272.4567382
71.8,37.56787275,0.949103068,160574.9409,1.752154131,273.5789401
72,37.72199213,0.958588021,162094.1922,1.744748232,274.9517236
72.2,37.9816237,0.968160171,163302.5465,1.739084918,276.0946221
72.4,38.34178177,0.977820818,163940.4202,1.739956249,277.4042178
72.6,38.61135371,0.987585487,164097.2121,1.743877068,278.3542725
72.8,38.86512252,0.997449433,163850.2944,1.753025594,279.3751475
73,39.03495225,1.007418957,164011.7953,1.759124614,280.5245809
73.2,39.20808979,1.017488246,164593.0662,1.75956028,281.4833523
73.4,39.53908676,1.027646801,165855.2821,1.754768255,282.7874993
73.6,40.49575323,1.037859791,167136.0747,1.748669379,283.8890064
73.8,40.96963663,1.048212162,169213.9969,1.736035804,285.2705101
74,41.42023761,1.058670439,170743.7809,1.729936865,286.7892922
74.2,41.89824243,1.069231503,171417.6582,1.731243854,288.1544537
74.4,42.01893305,1.079925978,171635.518,1.735600297,289.2014743
74.6,42.66391968,1.090687927,172393.7868,1.734729093,290.3323939
74.8,42.57269042,1.101613995,172869.335,1.73734294,291.5646277
75,42.88278003,1.11261933,174497.37,1.729937055,293.0627078
75.2,43.74458568,1.123693311,177301.3623,1.712947097,294.8320829
75.4,43.79456078,1.134940384,179806.4699,1.697699611,296.3410537
75.6,43.96832561,1.146291069,182188.2268,1.685937281,298.1747007
75.8,44.42541748,1.157734095,184626.1653,1.674174984,299.9876517
76,45.01710082,1.169281821,185731.5777,1.672432485,301.382232
76.2,45.30132376,1.180969048,186825.0539,1.673303806,303.1319886
76.4,45.57057142,1.192774698,186951.1684,1.679838482,304.398003
76.6,45.97690275,1.204688482,187499.781,1.684630603,306.0191989
76.8,46.45051992,1.216716958,188036.8572,1.688551446,307.5466985
77,46.62581607,1.228888904,188711.6228,1.689858398,308.8966035
77.2,47.05867933,1.241163543,188497.0741,1.699878236,310.441534
77.4,47.15167494,1.253587406,188661.2853,1.704670321,311.6650547
77.6,47.66925304,1.266103849,188933.4772,1.710333742,313.2252398
77.8,47.7887984,1.278776269,188723.9418,1.719482258,314.5435484
78,48.03628586,1.291566387,188739.1289,1.726016933,315.671195
78.2,48.47071091,1.304470711,189810.3075,1.725581345,317.2390068
78.4,48.51541177,1.317534509,191038.0438,1.723838782,318.8449447
78.6,48.67974491,1.330720298,192113.0427,1.72166059,320.1436424
78.8,49.29524896,1.344004327,193409.355,1.718611167,321.6744129
79,49.86170731,1.357425432,194529.967,1.71599738,323.075532
79.2,50.37745786,1.370985168,195741.795,1.714254873,324.7729955
79.4,50.901496,1.38468059,196520.8042,1.714690582,326.1261755
79.6,51.74708013,1.398489082,197396.0478,1.715997615,327.8018554
79.8,52.15142127,1.412469866,198661.5759,1.713819452,329.4056208
80,52.2300176,1.426615986,200145.1844,1.709027391,330.8721016
80.2,52.3002821,1.440904844,202170.5346,1.701621471,332.7787454
80.4,52.66716388,1.455314776,203813.4376,1.696829445,334.6309179
80.6,53.26834342,1.469851694,205192.9698,1.692908732,336.1976424
80.8,53.85703591,1.484535541,206305.1192,1.691601875,337.9245252
81,54.1793935,1.499387764,206291.7063,1.699879134,339.61654
81.2,54.3650402,1.514399808,205738.9729,1.710334591,340.7932143
81.4,54.71518606,1.529550141,205281.2678,1.722096999,342.3185342
81.6,55.09603969,1.544927439,204769.0804,1.732116838,343.4374676
81.8,55.28369086,1.560397681,203946.0261,1.745621798,344.6577216
82,55.66659719,1.57592978,203379.6317,1.756948568,345.9673192
82.2,55.86541636,1.591710581,203702.636,1.759998097,347.1396356
82.4,56.30808679,1.607631419,204131.3478,1.763047656,348.5331261
82.6,56.86207572,1.623703869,205057.9955,1.762612084,350.0235856
82.8,57.80241915,1.639908349,206610.9766,1.756513199,351.5053356
83,58.28281972,1.656310744,208786.9397,1.746057825,353.0361052
83.2,58.43705607,1.672902545,210913.092,1.738216269,354.8512321
83.4,59.23647922,1.689612055,212969.724,1.729939149,356.3416957
83.6,59.3694738,1.70654011,215505.2647,1.72079066,358.3311443
83.8,59.65990165,1.723626265,217876.3286,1.71294912,360.2116439
84,60.02051538,1.74087887,219137.3316,1.711206593,361.693384
84.2,60.28055963,1.758312376,220249.922,1.712077913,363.5520929
84.4,60.82932253,1.775899166,220802.6845,1.714691842,364.9750041
84.6,61.1798817,1.793677762,221214.8432,1.719483962,366.6648409
84.8,61.8881258,1.811607766,220751.2103,1.729503846,368.0932018
85,62.27768153,1.829741695,220984.075,1.735602902,369.7351
85.2,62.9871146,1.848033179,221504.6539,1.738216851,371.0686738
85.4,63.55276847,1.866519015,221908.6976,1.743009,372.6517432
85.6,63.90816872,1.885206555,221813.3105,1.75128627,374.1509165
85.8,64.36989763,1.904073504,222754.069,1.751286329,375.6381071
86,64.99196504,1.9231178,224142.9974,1.747365618,377.0860769
86.2,65.60236912,1.942354211,226333.6982,1.739524114,379.0112545
86.4,66.07314703,1.961794419,228261.7668,1.732118237,380.6095746
86.6,66.63529574,1.981422906,231432.6544,1.718177713,382.7559214
86.8,67.11432058,2.001254848,233503.3559,1.711643126,384.7007075
87,67.44457806,2.021297497,234299.202,1.71469267,386.5768497
87.2,67.86038891,2.04153487,234803.3815,1.71817787,388.1043517
87.4,68.44816905,2.06196251,235185.3947,1.72384131,389.9140404
87.6,68.81405941,2.082612373,235154.6038,1.730376008,391.3118896
87.8,69.40426678,2.1034525,234986.9657,1.738217667,392.8208734
88,70.18887751,2.124487239,235143.598,1.743881132,394.528152
88.2,70.69260177,2.145754648,234790.3329,1.751287135,395.7745622
88.4,71.4156565,2.167219146,235691.7032,1.75172287,397.4861979
88.6,71.83871274,2.188922124,237171.3717,1.747366491,399.0038949
88.8,72.09471825,2.210855805,240222.709,1.734297215,401.0118686
89,72.68555186,2.232984407,244295.8934,1.716871546,403.4327735
89.2,73.40265092,2.255325678,247999.8751,1.701188461,405.5475285
89.4,74.37397767,2.277872167,250818.7351,1.692911353,407.9553672
89.6,74.63067208,2.300699565,252302.7741,1.692911385,410.191049
89.8,75.59444813,2.323702502,252347.9873,1.70031745,411.9909407
90,76.07375756,2.346973475,251700.9019,1.711208603,413.501013
90.2,76.30458296,2.370496948,250489.9606,1.726456165,415.1559871
90.4,76.59685933,2.394252084,249949.2892,1.736040365,416.5429411
90.6,77.51810889,2.418198087,249861.4309,1.743882069,418.2284318
90.8,77.90835839,2.4424251,250449.7094,1.746931626,419.934616
91,78.23541884,2.466900201,251033.8722,1.749109888,421.4479531
91.2,78.81337994,2.491602127,252177.4224,1.749109962,423.3578786
91.4,79.47854887,2.516545651,253185.7726,1.748674402,424.9322368
91.6,79.6268418,2.541779222,253963.9484,1.750416999,426.7495448
91.8,80.40992218,2.567217914,255705.0506,1.746496303,428.6518479
92,81.29433499,2.592904612,257676.9012,1.7403974,430.3950847
92.2,81.8355342,2.61887548,260811.4837,1.729070727,432.7484404
92.4,82.45479906,2.645101203,263726.4496,1.719922282,435.1813334
92.6,83.37980304,2.671567231,265385.1184,1.716872889,436.9997493
92.8,84.04634663,2.698318823,266302.922,1.719051192,438.9543465
93,84.88152562,2.725326448,266627.1918,1.725585956,440.9830343
93.2,85.67594614,2.752608449,266199.865,1.734298936,442.4048632
93.4,86.36562638,2.780172465,266658.3274,1.739526752,444.38779
93.6,86.97798645,2.808019241,268325.9104,1.736041677,446.180052
93.8,87.54626294,2.836149218,269994.0216,1.732992241,448.1978391
94,88.47927141,2.864534158,271874.2463,1.72907156,450.4825649
94.2,89.10396071,2.893227839,273887.6753,1.722972621,452.4099258
94.4,89.5732209,2.922221463,275289.5872,1.721665748,454.7011811
94.6,89.85879993,2.951520449,275787.6795,1.72427965,456.4629275
94.8,90.44762054,2.98109068,277369.4015,1.722537147,458.6201741
95,91.13859795,3.010950332,279557.5148,1.71905208,461.0291007
95.2,91.57692589,3.041129155,280727.4353,1.719923424,462.803926
95.4,92.21296633,3.071595982,282171.9406,1.721666081,465.0668569
95.6,93.17218877,3.102344423,283105.3971,1.725586999,467.2535275
95.8,93.89537886,3.133419762,282482.843,1.736478197,469.0534213
96,94.89604906,3.164786152,281696.0112,1.746498142,470.4556462
96.2,95.77784662,3.196476813,280466.4088,1.760003228,472.1988849
96.4,96.41779378,3.228504208,280398.7761,1.765231043,473.6958897
96.6,96.83084663,3.260870759,280216.6923,1.772201408,475.492506
96.8,97.59699197,3.293535491,281165.2289,1.77263715,477.2564439
97,98.46778204,3.326520529,282861.1289,1.768716462,478.9441205
97.2,98.73443518,3.35988297,286601.7524,1.75521152,481.3029204
97.4,99.48048025,3.393543991,289914.4187,1.743884858,483.4013384
97.6,100.2173314,3.427543998,294908.862,1.726459171,486.249342
97.8,101.2648952,3.461861962,299223.2289,1.712518676,488.9502679
98,102.1703156,3.496535487,301962.5136,1.705548475,491.2023122
98.2,103.1562808,3.53155119,303126.8283,1.707726819,493.6559174
98.4,103.6440487,3.566957331,304121.4692,1.709469459,495.6987664
98.6,104.7636806,3.602672337,304558.9179,1.715132977,498.055409
98.8,105.4632214,3.63877812,305085.7825,1.719925156,500.2551525
99,106.360881,3.675231474,306309.5981,1.720360912,502.2413565
99.2,107.0328854,3.712068337,308885.4321,1.716004549,504.8692776
99.4,107.8007734,3.749455646,310325.8042,1.717311579,507.3904305
99.6,108.9558438,3.787003393,310927.6452,1.72079688,509.3570302
99.8,109.3543245,3.824795035,311235.8297,1.726024668,511.4924856
100,110.3526447,3.863111656,311073.939,1.733866399,513.7499818
100.2,111.4718039,3.901804155,310734.1587,1.740836857,515.4561871
100.4,112.0719865,3.940924911,311485.3983,1.743450802,517.7452692
100.6,112.913076,3.980420309,313303.2906,1.739965749,519.7576222
100.8,113.7923251,4.020309641,316178.4965,1.732995541,522.2112272
101,114.7072406,4.060597051,320705.326,1.719926307,525.2063229
101.2,115.2959522,4.101314199,325763.247,1.705114452,528.3997019
101.4,116.2830292,4.142410036,328790.8881,1.698144253,530.8053721
101.6,117.1337682,4.183929225,331206.2938,1.695530487,533.6185186
101.8,118.2947929,4.225841926,332472.0264,1.697273209,536.2039647
102,118.9135697,4.26821712,331667.3662,1.707728768,538.4472882
102.2,120.0570104,4.310978292,330669.5744,1.719055682,540.6274345
102.4,120.8621948,4.354194481,330667.0386,1.725154814,542.623444
102.6,121.7745005,4.397834904,331695.0795,1.727768799,545.1217238
102.8,122.8894832,4.44189802,332939.168,1.729075873,547.4402407
103,123.9728203,4.486405825,335777.2986,1.724719556,550.3503601
103.2,125.2014991,4.531349799,338014.27,1.721234546,552.6547144
103.4,126.0412314,4.576774684,339793.6722,1.72123465,555.3578207
103.6,126.8858769,4.62265515,340134.5053,1.72733379,557.8255931
103.8,127.9631093,4.668978481,341410.1213,1.728640861,560.2704927
104,128.6771519,4.715794671,341685.9849,1.73343305,562.2795761
104.2,129.8273575,4.76304812,341663.9819,1.741274811,564.732104
104.4,130.72904,4.810795081,341697.9888,1.746938312,566.5984649
104.6,131.5683265,4.859026371,342282.6723,1.751294871,568.9921526
104.8,132.904432,4.907704419,342040.5221,1.758701019,570.9653002
105,133.5964894,4.956920501,341706.2849,1.765671435,572.7281538
105.2,134.8825829,5.006585951,341209.4524,1.773948858,574.8625486
105.4,135.8337325,5.056776013,341607.7496,1.776562855,576.5633076
105.6,136.3103411,5.107506446,342923.8076,1.776562921,578.8720024
105.8,137.423361,5.158698083,345366.5186,1.770899669,581.2188482
106,138.3667895,5.210416885,350689.3883,1.754345257,584.3043803
106.2,139.3890738,5.262649274,356577.8717,1.736048259,587.1567588
106.4,140.5400689,5.31539668,362765.9364,1.71949387,590.6192694
106.6,141.4574886,5.368691798,366686.6472,1.710781068,593.3191135
106.8,142.3698376,5.422522608,369235.9869,1.709038592,596.263009
107,143.7947847,5.476855342,369095.129,1.718187333,599.0097175
107.2,144.851543,5.531761969,368071.8406,1.728207321,601.007919
107.4,146.0719069,5.587207924,366481.153,1.74127685,603.3754711
107.6,146.8750554,5.643242564,366021.1843,1.748247289,605.2963118
107.8,148.0985652,5.699808134,366508.8507,1.751732611,607.6289982
108,149.5031277,5.756928411,367811.8276,1.752168433,610.2798303
108.2,150.6184352,5.814644595,369664.7192,1.751297282,612.9687876
108.4,151.729496,5.872941026,372974.057,1.743455792,615.4038862
108.6,152.789777,5.931826915,377745.5029,1.732564772,618.7487318
108.8,154.2413324,5.99127472,381533.8556,1.725594613,621.7612878
109,155.7925048,6.051312294,385175.3836,1.718624464,624.4960155
109.2,156.6206715,6.112007995,390175.1507,1.708604703,628.1644404
109.4,157.6174203,6.17330064,392116.5183,1.70816918,630.7084916
109.6,158.8143257,6.235193753,393674.4552,1.710783205,633.8648544
109.8,160.1199844,6.297700407,395822.5374,1.710347719,636.934063
110,161.1596453,6.360855365,397542.6882,1.712090433,640.114391
110.2,162.544042,6.424618589,398140.8022,1.716447068,642.6388417
110.4,164.0147538,6.489016072,398827.0794,1.721239361,645.6056419
110.6,165.011732,6.554096525,399301.0666,1.725160304,647.9808181
110.8,166.4307195,6.61979873,398778.3018,1.733437764,650.5205232
111,167.769002,6.686167146,398347.1723,1.741715217,653.2672361
111.2,168.9991574,6.753210562,399110.0367,1.744329251,655.5617978
111.4,170.4386006,6.820911746,401203.7206,1.743893784,658.5220603
111.6,171.3818696,6.889330869,404935.5164,1.738666143,661.8472936
111.8,172.9714944,6.958388132,408397.077,1.733874226,664.8347995
112,174.42806,7.028149362,411223.2974,1.730389232,667.5357575
112.2,175.5355229,7.098638115,413487.9974,1.730389371,670.7781966
112.4,176.8547609,7.169818917,413438.8318,1.737795532,673.5281783
112.6,178.2204177,7.241711277,411946.9426,1.748686876,675.5362027
112.8,179.4654745,7.314335172,411841.196,1.754786091,677.9571509
113,180.9198105,7.38767279,411111.9244,1.763934862,680.5317293
113.2,182.3981265,7.46174543,411321.1189,1.76829152,682.6280079
113.4,183.4475632,7.536594777,413871.9921,1.765242124,685.540324
113.6,184.7827212,7.612174561,418574.0345,1.754786762,688.9254974
113.8,186.422711,7.688490496,421790.0661,1.749559201,691.9489632
114,187.3762286,7.765625234,424936.452,1.744331555,694.6858628
114.2,189.0749699,7.843478247,428420.9922,1.739539647,698.1157208
114.4,190.3564587,7.922145393,430791.88,1.737361571,700.8079605
114.6,191.7317174,8.001595627,431989.5524,1.740846921,703.8423159
114.8,193.2580792,8.081832641,432731.7061,1.745203586,706.5345655
115,195.0659994,8.162854455,433760.3872,1.748688992,709.5308028
115.2,196.4101296,8.244725579,433366.1287,1.755659521,711.8144778
115.4,197.9984236,8.327400668,432528.4069,1.765243968,714.4511657
115.6,199.2483958,8.41093208,431355.7132,1.774392726,716.451567
115.8,200.7965399,8.495280054,430369.4672,1.783105877,718.7156378
116,202.6237426,8.580458324,430738.9922,1.787462587,721.3076649
116.2,203.6560212,8.666553064,433004.4064,1.783977538,723.6719578
116.4,205.0745467,8.75348347,436348.9999,1.777878651,726.8490422
116.6,206.5776887,8.841281168,440094.3394,1.770037182,729.5968609
116.8,207.7479016,8.929986137,445699.3042,1.757403543,732.9754996
117,209.4560027,9.019541655,450918.1968,1.747819503,736.6766546
117.2,211.2881129,9.110445394,453659.5555,1.745205844,739.4539027
117.4,212.966085,9.201360962,456628.9808,1.743463462,742.8227564
117.6,214.6455009,9.29364955,460581.1514,1.738235894,746.4018858
117.8,215.950849,9.386894041,462275.6238,1.73888953,749.2788076
118,217.42639,9.481062257,463696.7502,1.740414483,752.441191
118.2,219.006063,9.57616873,464898.8375,1.742592921,755.7424907
118.4,220.8876291,9.672207992,466145.9039,1.743464452,758.3759287
118.6,222.2505387,9.76925172,465747.8035,1.751306293,761.4909147
118.8,224.2119821,9.86722491,466425.8294,1.755227374,764.283426
119,225.9273125,9.96620138,467490.9692,1.757841481,766.8231593
119.2,227.9619795,10.06614806,470460.0036,1.756099142,770.2563114
119.4,229.6961042,10.16712176,472734.5583,1.756535009,773.6731103
119.6,231.0860605,10.26913642,474585.4698,1.756535185,776.3479342
119.8,232.8256779,10.37214946,477188.2133,1.754792809,779.5163234
120,234.6444859,10.4761877,480746.6593,1.749565253,782.6106292
120.2,236.3480436,10.58127866,484911.9372,1.744337681,786.4152979
120.4,238.4768728,10.68739307,489734.7343,1.737367565,790.2973376
120.598,240.2651927,10.79352069,494678.8793,1.728654809,793.6858125
120.8,242.2408901,10.79552732,499637.4303,1.721249019,797.5950896
121,243.1717851,10.7954555,502956.8241,1.719506538,801.6873641
121.2,244.001306,10.79539136,506388.8296,1.715585799,805.0921485
121.4,244.7095103,10.79533641,509784.3029,1.712971992,809.3216922
121.6,245.6636717,10.79526283,511845.0299,1.713407758,812.6687378
121.8,246.1957176,10.79522123,512836.6522,1.718199961,816.2816083
122,246.8283068,10.795172,514269.552,1.722120885,820.2006355
122.2,247.396083,10.79512769,512448.282,1.73475478,823.4714
122.4,247.6198515,10.79510944,510186.1741,1.747388632,825.9566053
122.6,247.9283756,10.79508476,507395.9677,1.761765097,828.759955
122.8,248.3141767,10.79505424,506667.3797,1.769171181,831.5578583
123,248.620208,10.79502975,505304.2239,1.777884205,833.8110012
123.2,248.8082463,10.7950142,504440.7781,1.787032859,836.596913
123.4,249.3868247,10.79496907,505458.7791,1.789211178,839.0113119
123.6,249.7036582,10.79494377,508129.0116,1.788339927,842.3005901
123.8,249.7080596,10.79494213,509618.1002,1.790518174,845.0854051
124,250.0531449,10.79491469,510620.8127,1.793132113,847.4736487
124.2,250.4148489,10.79488599,513304.1949,1.791825216,850.7171666
124.4,250.6228297,10.79486893,513280.7273,1.797053035,853.0204222
124.6,250.8706955,10.79484885,512120.0316,1.806637352,855.5568368
124.8,250.8593091,10.79484841,510169.9104,1.817528583,857.6171202
125,251.2276607,10.7948192,508948.0359,1.826241617,859.9116664
125.2,251.2412023,10.79481688,506819.9284,1.836261553,861.4609658
125.4,251.3901867,10.79480429,506539.2248,1.841489366,863.6737907
125.6,251.420347,10.7948007,506437.9363,1.844974566,865.4170249
125.8,251.4704499,10.7947956,507593.8889,1.845410224,867.5285172
126,251.6460242,10.794781,510502.5753,1.841925055,870.2120148
126.2,251.5897672,10.79478396,513989.8894,1.836261609,872.5708253
126.4,252.1675148,10.79473889,516810.8138,1.833647786,875.2456227
126.6,252.2417149,10.79473196,519601.345,1.830162608,877.5793809
126.8,252.4796094,10.79471264,521581.253,1.829291342,880.0613157
127,252.6934068,10.79469514,519839.8632,1.839311306,882.1434022
127.2,252.8880927,10.79467909,516856.0518,1.852380812,883.8713928
127.4,252.8958178,10.7946772,515366,1.859786853,885.212592
127.6,253.0231978,10.79466625,513665.7915,1.868499858,886.8327131
127.8,253.0375704,10.79466386,514135.6243,1.870242459,888.5182034
128,252.9497378,10.79466921,519101.7187,1.859351218,891.2006032
128.2,253.3297226,10.79463912,523199.2217,1.851073933,893.4907914
128.4,253.306703,10.79463956,527443.1086,1.843667893,896.3921856
128.6,253.368439,10.79463358,529373.3278,1.842796605,898.8980866
128.8,253.4359916,10.79462716,528128.9751,1.850638304,900.6598424
129,253.5284722,10.79461885,523786.0914,1.866757343,901.59139
129.2,253.3974309,10.79462748,519631.4178,1.882440703,902.6416823
129.4,253.7724301,10.79459777,517880.6625,1.890718093,903.9654651
129.6,253.6563456,10.79460526,518337.4217,1.891589378,905.2957678
129.8,253.555218,10.79461162,520170.2103,1.888539822,907.0684133
130,253.8437997,10.79458845,525388.3706,1.875906032,909.6200825
130.2,253.8831005,10.79458417,528265.4611,1.870242598,911.5757735
130.4,253.9232321,10.79457983,528928.5085,1.871985203,913.5706904
130.6,253.9425903,10.79457706,527277.2775,1.880262545,915.0829488
131.3,253.9274202,10.70986688,1.7977E+308,1.9125006,0
131.5,253.3573472,10.60200205,1.7977E+308,1.8310341,0
131.7,253.4811063,10.49408466,1.7977E+308,1.658952633,0
131.9,253.38716,10.38618376,1.7977E+308,1.418474195,0
132.1,253.0937889,10.27829797,1.7977E+308,1.127460424,0
132.3,252.8170366,10.17041092,1.7977E+308,0.78416875,0
132.5,252.8610258,10.06249957,1.7977E+308,0.49010547,0
132.7,252.5601763,9.954614344,1.7977E+308,0.284914641,0
132.9,252.1263769,9.84673919,1.7977E+308,0.142457316,0
133.1,252.1304811,9.738830864,1.7977E+308,0.031802398,0
133.3,251.8026262,9.630947684,1.7977E+308,0.006534739,0
133.5,251.6933076,9.52304795,1.7977E+308,0.013505127,0
133.7,251.3579742,9.415165337,1.7977E+308,0.01742597,0
133.9,250.9565814,9.307287728,1.7977E+308,0.016990321,0
134.1,250.8302286,9.199389284,1.7977E+308,0.007841686,0
134.3,250.5202389,9.091504751,1.7977E+308,0.001306948,0
134.5,250.4416649,8.983602688,1.7977E+308,0.003920843,0
134.7,250.1857289,8.875444294,1.7977E+308,0.009584283,0
134.9,249.8737047,8.767290148,1.7977E+308,0.014376424,0
135.1,249.7871511,8.659928223,1.7977E+308,0.013505126,0
135.3,249.2494847,8.552060937,1.7977E+308,0.010019932,0
135.5,249.7276383,8.444116702,1.7977E+308,0.012633827,0
135.7,248.8742161,8.336273334,1.7977E+308,0.017425967,0
135.9,248.7594964,8.228374009,1.7977E+308,0.028317197,0
136.1,248.4441056,8.120489885,1.7977E+308,0.027881547,0
136.3,248.3144291,8.012591693,1.7977E+308,0.021346809,0
136.5,248.2724163,7.904686861,1.7977E+308,0.017861616,0
136.7,248.0787577,7.796793516,1.7977E+308,0.02091116,0
136.9,247.6133829,7.688920753,1.7977E+308,0.024832001,0
137.1,247.5173593,7.581020012,1.7977E+308,0.031366738,0
137.3,247.1546051,7.473139476,1.7977E+308,0.036158878,0
137.5,247.0639826,7.365238326,1.7977E+308,0.039208422,0
137.7,247.1154503,7.257326412,1.7977E+308,0.043564913,0
137.9,246.5719675,7.149459567,1.7977E+308,0.044871859,0
138.1,246.3334383,7.04156962,1.7977E+308,0.046614454,0
138.3,246.2203805,6.93367017,1.7977E+308,0.047485752,0
138.5,245.8979268,6.825786581,1.7977E+308,0.048357049,0
138.7,246.111427,6.717862393,1.7977E+308,0.053584839,0
138.9,245.492329,6.610001275,1.7977E+308,0.059683924,0
139.1,245.3028251,6.502107615,1.7977E+308,0.056198731,0
139.3,245.154868,6.394210808,1.7977E+308,0.049663994,0
139.5,244.953731,6.28631803,1.7977E+308,0.045307503,0
139.7,244.7750293,6.178423551,1.7977E+308,0.039644064,0
139.9,244.2498272,6.070555321,1.7977E+308,0.035723222,0
140.1,244.2763667,5.962645296,1.7977E+308,0.037030169,0
140.3,244.0951722,5.854751006,1.7977E+308,0.042257957,0
140.5,243.8458409,5.746861878,1.7977E+308,0.043129254,0
140.7,243.6388874,5.63896954,1.7977E+308,0.032673677,0
140.9,243.6006139,5.531064425,1.7977E+308,0.02657459,0
141.1,243.0496528,5.423198145,1.7977E+308,0.023525046,0
141.3,242.8950482,5.315301842,1.7977E+308,0.019604205,0
141.5,242.7529077,5.207404594,1.7977E+308,0.023525046,0
141.7,242.2202272,5.09953693,1.7977E+308,0.016554661,0
141.9,242.0573133,4.991641256,1.7977E+308,0.019604204,0
142.1,241.7398453,4.883757289,1.7977E+308,0.028317183,0
142.3,241.3550715,4.775878421,1.7977E+308,0.025267639,0
142.5,241.4007225,4.667966948,1.7977E+308,0.022218097,0
142.7,241.0400459,4.560086255,1.7977E+308,0.011762522,0
142.9,240.8297686,4.452194168,1.7977E+308,0.003485192,0
143.1,240.6884591,4.344296858,1.7977E+308,0.014376415,0
143.3,240.320304,4.236416731,1.7977E+308,0.023089393,0
143.5,239.6978826,4.128555865,1.7977E+308,0.03180237,0
143.7,239.8864546,4.020633565,1.7977E+308,0.035723211,0
143.9,239.5748032,3.912749158,1.7977E+308,0.033109316,0
144.1,238.9906048,3.804885397,1.7977E+308,0.027881528,0
144.3,239.1908099,3.696962216,1.7977E+308,0.021346796,0
144.5,238.4113416,3.589113246,1.7977E+308,0.017861603,0
144.7,238.2534134,3.481217195,1.7977E+308,0.017861603,0
144.9,238.110442,3.37332001,1.7977E+308,0.017861603,0
145.1,237.7987906,3.265435603,1.7977E+308,0.017425954,0
145.3,237.438945,3.157554846,1.7977E+308,0.01481206,0
145.5,237.3865456,3.049650801,1.7977E+308,0.011762518,0
145.7,237.2726569,2.941751413,1.7977E+308,0.005663435,0
145.9,236.9136422,2.833870593,1.7977E+308,0.002613893,0
146.1,236.6086384,2.725985683,1.7977E+308,0.011762518,0
146.3,236.2795374,2.618102597,1.7977E+308,0.018732898,0
146.5,235.8714975,2.510225492,1.7977E+308,0.024831981,0
146.7,235.8647996,2.402317984,1.7977E+308,0.024396332,0
146.9,235.3229791,2.294451012,1.7977E+308,0.023960682,0
147.1,235.2032739,2.186552065,1.7977E+308,0.019604194,0
147.3,234.6897053,2.078682953,1.7977E+308,0.023960681,0
147.5,234.4270792,1.970794833,1.7977E+308,0.026138925,0
147.7,234.2774603,1.862898151,1.7977E+308,0.03093106,0
147.9,233.901827,1.755018591,1.7977E+308,0.036594493,0
148.1,233.4347908,1.647145954,1.7977E+308,0.04400052,0
148.3,232.9802186,1.539272373,1.7977E+308,0.049228303,0
148.5,232.8314307,1.431375629,1.7977E+308,0.052277843,0
148.7,232.4882039,1.323493614,1.7977E+308,0.051842193,0
148.9,232.2638009,1.215602598,1.7977E+308,0.0492283,0
149.1,231.883182,1.107723415,1.7977E+308,0.044436164,0
224.3,230.7391701,1.00480872,1.7977E+308,0.010673396,0
224.5,230.6689056,0.896906028,1.7977E+308,0.017861602,0
224.7,230.238015,0.789030653,1.7977E+308,0.022653738,0
224.9,229.7161369,0.681162171,1.7977E+308,0.02178244,0
225.1,229.3978381,0.573278267,1.7977E+308,0.022653737,0
225.3,229.303061,0.465377432,1.7977E+308,0.033544956,0
225.5,228.3358015,0.357542687,1.7977E+308,0.049228309,0
225.7,227.8978479,0.249667847,1.7977E+308,0.06229777,0
225.9,226.9588403,0.141830963,1.7977E+308,0.064911658,0
226.1,225.9209514,0.034001568,1.7977E+308,0.063169059,0
226.158,225.532059,0.002737703,1.7977E+308,0.061862111,0
,,,,,