File: Test_10.csv
Time On Sample,Displacement Into Surface,Load On Sample,Harmonic Contact Stiffness,Harmonic Displacement,Harmonic Load
0,0,0,-146.5593594,0.419971392,2.171439839
0.2,0.199491462,0.000742573,3380.664744,0.301908899,2.240080463
0.4,0.373639028,0.001487064,7253.513245,0.25529382,2.301094344
0.6,0.252800226,0.002253869,9608.357942,0.223491005,2.352302398
0.8,0.464755906,0.0029955,12962.20601,0.186460335,2.469972024
1,0.246280769,0.003769691,14930.11996,0.171648063,2.578925328
1.2,0.283321995,0.004524553,17182.22716,0.159014069,2.71620653
1.4,0.65440413,0.005254146,18839.19773,0.152479248,2.852398248
1.588,0.597153896,0.005970681,20267.49659,0.149865318,2.988589912
1.8,0.741782208,0.006759968,23026.4728,0.141587875,3.199959402
2,0.595184473,0.007525923,27997.45435,0.128518224,3.52681938
2.2,0.806725132,0.008264786,32474.79805,0.119805126,3.868932882
2.4,0.710815196,0.009026907,38136.40563,0.10978506,4.196882413
2.6,0.850894367,0.009771177,43773.12104,0.101943271,4.517205251
2.8,0.89873836,0.010522424,48750.93365,0.102814582,5.055434742
3,1.06374596,0.011264808,53345.27155,0.106299823,5.713512921
3.2,0.789182296,0.012040444,58204.46466,0.110656371,6.383575866
3.4,0.780521854,0.012795965,58141.16657,0.122854711,7.010057549
3.6,0.992062518,0.013534829,55972.02286,0.139409604,7.624554428
3.8,1.066496834,0.014284065,55423.1031,0.157707116,8.536493894
4,0.87004224,0.015053793,53886.81931,0.182975104,9.631474826
4.2,0.936998027,0.015803595,51529.31959,0.212599646,10.69812804
4.4,1.254899988,0.016534414,49313.35587,0.243966813,11.74190118
4.6,1.023545592,0.017306782,47844.82816,0.27359135,12.76933104
4.8,1.118753598,0.018054447,47988.49217,0.297116724,13.91660973
5,1.076855253,0.018812484,48721.04121,0.321949059,15.33191357
5.2,1.029971222,0.019570897,49357.09704,0.34547443,16.69491975
5.4,0.96979203,0.020330316,49854.31616,0.36812849,18.00671795
5.6,1.098237941,0.021075467,48864.67578,0.40167393,19.2945465
5.8,0.925049876,0.021843435,46958.47389,0.445239428,20.556226
6,0.498422804,0.022630574,43996.82607,0.505359806,21.86366562
6.2,0.55873101,0.023380878,39938.54118,0.58639164,23.05997324
6.4,0.487748899,0.024144896,36310.74554,0.666987814,23.87058602
6.6,1.061582713,0.024856354,31822.67986,0.788099939,24.76182507
6.8,0.634955635,0.025643494,28200.54572,0.910518975,25.43297706
7,-0.115740373,0.026451365,24860.61769,1.05384942,26.06054743
7.2,1.167722659,0.027109143,22674.66575,1.166684169,26.42554273
7.4,1.105881571,0.027868688,20652.1817,1.290845848,26.81886421
7.6,1.270058233,0.028611137,19693.11008,1.363600256,27.16097792
7.8,1.047013307,0.029382877,19066.09563,1.42197801,27.5444934
8,1.14803795,0.030130103,18627.98778,1.470771386,27.95851629
8.2,1.068746962,0.030890969,18891.97537,1.47338531,28.41067248
8.4,1.089169686,0.031644292,19466.8322,1.462929594,29.01754269
8.6,1.09962104,0.032398369,19845.77294,1.461622632,29.49366881
8.8,1.440789549,0.03312743,20268.7729,1.458573083,30.00901856
9,1.277572848,0.033894645,20837.01239,1.448553003,30.59736645
9.2,1.370288018,0.034642499,20980.55461,1.45683046,31.01465793
9.4,1.368275157,0.03539752,20930.07085,1.47904887,31.46899344
9.6,1.391190726,0.036150655,20798.67371,1.500395971,31.81110701
9.8,1.564507819,0.036892413,20480.61089,1.533941431,32.1139975
10,1.948054674,0.037618269,20195.92832,1.569229534,32.42996288
10.2,2.285068469,0.038347645,20217.57954,1.582734881,32.70234682
10.4,2.15342777,0.039112473,20801.18165,1.567051286,33.14905538
10.6,2.016801386,0.039877679,21854.77347,1.523921422,33.63498715
10.8,2.348829498,0.040607432,23769.94459,1.44332527,34.31812514
11,2.468965952,0.041353215,26346.64417,1.347481166,35.15379756
11.2,2.383027375,0.042114586,28463.36103,1.279954626,35.8652628
11.4,2.134223049,0.042888278,30576.20885,1.224626412,36.70747181
11.6,2.34160901,0.043627461,31755.02617,1.205021949,37.45816083
11.8,1.837703746,0.04442045,31929.36445,1.217220255,38.05413457
12,2.184688915,0.045149072,31693.80134,1.240310004,38.52372426
12.2,2.47849344,0.045881717,31029.20943,1.284311196,39.05650681
12.4,2.200605942,0.046657609,30351.67441,1.328747992,39.53372191
12.6,2.629854947,0.047380009,29703.95434,1.368828297,39.86603057
12.8,2.387698197,0.048153198,28995.96611,1.414136409,40.22121806
13,2.568493837,0.048894393,28615.61424,1.448117524,40.63197258
13.2,2.448486402,0.049658343,28599.68463,1.4638011,41.06669624
13.4,2.47306387,0.050411355,29003.69302,1.460751519,41.56570267
13.6,2.586552746,0.051157641,29841.28474,1.435919192,42.03093375
13.8,2.471530996,0.051921214,31383.76101,1.391046704,42.77835342
14,2.604962618,0.052665992,32475.85843,1.362293487,43.32529967
14.2,2.615413975,0.053420073,33681.56773,1.335282875,44.01497445
14.4,2.74469086,0.054165166,34402.52572,1.327005438,44.66106814
14.6,2.657921332,0.054926602,34493.17737,1.336589845,45.10341852
14.8,2.716152185,0.055677069,34439.79378,1.353144744,45.6078727
15,2.623150549,0.056438976,34358.70479,1.371006597,46.14501265
15.2,2.789820084,0.05718124,34270.71964,1.389304129,46.67670526
15.4,2.661087694,0.05794585,34352.2011,1.39888853,47.129951
15.6,2.794519319,0.058690629,34477.06559,1.408908613,47.65401693
15.8,2.731016327,0.059450306,34559.3534,1.419364331,48.1377698
16,3.0052936,0.06018443,34632.78534,1.431127049,48.65420923
16.2,3.018653276,0.060938293,34646.10194,1.44288974,49.08348556
16.4,2.525965767,0.061730435,34615.61168,1.457701968,49.56505822
16.6,2.949398161,0.062453277,34691.99848,1.469029044,50.04663306
16.8,3.071196521,0.063198936,34836.00686,1.477306506,50.49987949
17,2.944126024,0.063963422,34971.12002,1.487762218,50.98036352
17.2,2.928402528,0.064719484,35210.47039,1.49386139,51.47936991
17.4,2.957965685,0.065472121,35413.18439,1.497782292,51.87378118
17.6,2.847929617,0.066235317,35695.0097,1.499960558,52.35535468
17.8,3.108496258,0.06697048,35884.21274,1.504317139,52.80860136
18,3.865554225,0.067668086,36139.63007,1.506495496,53.3206842
18.2,3.905919708,0.068419907,36495.02388,1.504752882,53.8349443
18.4,3.795883633,0.069183106,36899.46869,1.499525011,54.26748884
18.6,4.052711029,0.069918553,37871.08263,1.477742283,54.88416544
18.8,4.004996041,0.070677038,39258.95718,1.442454213,55.52481117
19,3.951464418,0.071435963,41302.00801,1.393225177,56.35721479
19.2,3.794895263,0.072202682,43198.54046,1.35227358,57.16129022
19.4,4.192568322,0.072927475,44609.1598,1.325698655,57.84660802
19.6,3.994451772,0.073697338,45563.64883,1.31567857,58.60601253
19.8,4.026507777,0.074449789,45789.8512,1.324391678,59.26409098
20,3.717044218,0.075228074,45639.66593,1.343996133,59.95267527
20.2,3.788985719,0.075977507,45391.81391,1.365343244,60.60966446
20.4,4.251472714,0.076697398,45084.49147,1.385383428,61.11411979
20.6,4.406509007,0.077440546,44838.89057,1.404552272,61.71663252
20.8,4.418622265,0.078194506,44686.14617,1.419800207,62.28754821
21,4.277010166,0.078960095,44566.95256,1.435919436,62.89986561
21.2,4.5143103,0.079697021,44520.92207,1.448553462,63.39996253
21.4,4.499002278,0.080453056,44909.03239,1.450731739,64.04496641
21.6,4.40059938,0.081215926,45656.40019,1.443761248,64.73355132
21.8,4.553972742,0.08196573,46414.91583,1.436355127,65.39925703
22,4.911758067,0.082707784,47104.21329,1.431998614,66.14123056
22.2,5.022750658,0.083476104,47696.20398,1.426770765,66.72195241
22.4,4.989988034,0.084263001,48072.7298,1.431127315,67.45085059
22.6,4.961378903,0.085057426,48036.08902,1.445939591,68.1013021
22.8,4.953542201,0.085858265,47977.65837,1.460316214,68.70490381
23,4.777021784,0.086679962,48149.42289,1.469029302,69.35971286
23.2,4.824856026,0.087492732,48199.17407,1.477742413,69.85763011
23.4,4.874350853,0.088313628,48500.38496,1.481227662,70.51679829
23.6,4.908055697,0.089148129,48516.9876,1.492119047,71.13565354
23.8,4.970012102,0.089984698,48497.02897,1.502574781,71.70656942
24,5.052741541,0.090823885,48481.1725,1.513466172,72.35157357
24.2,5.38475336,0.091656832,48556.31127,1.519565382,72.85276034
24.4,5.210715817,0.09254102,48539.3406,1.531763712,73.45200344
24.6,5.379859765,0.09339934,48898.36078,1.533506353,74.07630692
24.8,5.433499875,0.094279438,49401.50714,1.53176374,74.68753562
25,5.355848804,0.095178291,49862.41942,1.5330707,75.3521509
25.2,5.42195033,0.09607508,50052.69046,1.538734227,75.86423213
25.4,5.601059332,0.096972443,50369.47314,1.542655146,76.48744627
25.6,5.777674051,0.097879063,50709.55057,1.545269098,77.12809284
25.8,5.739071783,0.098811135,50714.01304,1.555724822,77.67285965
26,5.894909865,0.09973782,50633.49512,1.567487532,78.14027024
26.2,5.893697292,0.100685723,50537.59185,1.581428502,78.68285817
26.4,5.773657639,0.101652152,50347.88986,1.597547735,79.22108723
26.6,5.986826613,0.102602943,50157.21926,1.610617418,79.60242508
26.8,6.424350022,0.103546432,50156.68089,1.619330575,80.09380656
27,5.882184171,0.104573732,50657.18773,1.613666998,80.69195851
27.2,6.185090864,0.10554712,51379.79869,1.602339998,81.3456801
27.4,6.179714238,0.106553926,52354.18781,1.5857851,82.05060834
27.6,6.207573968,0.107568062,53231.17448,1.571844138,82.63024076
27.8,6.521278213,0.108570712,54443.54748,1.552239688,83.34715515
28,6.441111459,0.109613399,55447.65219,1.54047699,84.11745535
28.2,6.230484194,0.11067646,56471.80672,1.528278622,84.89320268
28.4,6.173580642,0.111738423,57215.73173,1.520872479,85.51859498
28.6,6.675072509,0.11276864,58246.68505,1.509109843,86.33901583
28.8,6.250055592,0.113879701,58915.39053,1.505188903,87.07227033
29,6.708334752,0.114934645,59383.64244,1.50736723,87.84366254
29.2,6.541739238,0.116047789,59473.40662,1.518258596,88.57147063
29.4,6.410872714,0.117169417,59315.66368,1.531328249,89.08899881
29.6,6.957227113,0.118250828,58738.70497,1.557467623,89.71330414
29.8,6.719164756,0.119402755,58338.2785,1.577507741,90.24935352
30,6.418779468,0.120570907,58371.39758,1.587963437,90.90634149
30.2,6.728308242,0.121704356,58681.80189,1.589270441,91.46309472
30.4,6.80932445,0.122866727,59333.02757,1.584913898,92.1854561
30.6,6.754894256,0.124051082,60249.39913,1.574458171,92.95902495
30.8,6.751150023,0.125243376,60885.67458,1.570101617,93.65414761
31,6.857919988,0.126439242,61167.48856,1.572715568,94.22833251
31.2,6.734515421,0.127664558,61349.12579,1.579686035,94.92345462
31.4,7.012456849,0.128871665,61399.89879,1.589270486,95.58807163
31.6,7.184034971,0.130099106,61399.49938,1.597547958,96.11213831
31.8,7.187759601,0.131351676,61818.20037,1.597112304,96.76150059
32,7.564993437,0.132588415,62358.64276,1.594498417,97.48713202
32.2,7.265833482,0.133889019,62819.59072,1.594062732,98.21929745
32.4,7.320655404,0.135175574,63212.79005,1.593191431,98.81854143
32.6,7.383369274,0.136474494,63519.66397,1.597112333,99.52238041
32.8,7.436109682,0.137787282,63526.04321,1.606696758,100.120535
33,7.564048817,0.139107469,63515.75799,1.617588157,100.767719
33.2,7.676613294,0.140442145,63764.56226,1.620202104,101.3255607
33.4,7.586008802,0.141805702,64189.53481,1.620202097,101.9967131
33.6,7.906306017,0.143151735,65154.29121,1.608439442,102.8018803
33.8,7.831485213,0.144541308,66211.25216,1.594934121,103.5928817
34,7.914126882,0.145932838,67099.83036,1.584478405,104.2803782
34.2,7.978069989,0.147339805,68095.11773,1.574893997,105.1443789
34.4,7.9879992,0.14876511,68418.12901,1.579686209,105.9201272
34.6,7.608626918,0.150234188,67821.71915,1.603211556,106.5248168
34.8,7.837506388,0.151671746,67223.31334,1.625430006,107.0390779
35,8.121226145,0.153119607,66727.9051,1.646341496,107.6132637
35.2,7.921747192,0.154618772,66176.81414,1.665945966,108.0131219
35.4,7.940805231,0.156116373,66293.07421,1.672045145,108.6047391
35.6,8.230749994,0.15760849,67247.05653,1.659411176,109.3488925
35.8,8.334144489,0.159129826,68173.09248,1.647648497,110.0767016
36,8.152105845,0.160688058,68845.49849,1.641113648,110.7075408
36.2,8.282085776,0.162238253,69869.26437,1.629786627,111.5399457
36.4,8.109598062,0.163827056,70148.98994,1.631964886,112.1326514
36.6,8.321836855,0.165402543,70038.63252,1.644163262,112.7765675
36.8,8.118599012,0.167025411,69941.17543,1.655054625,113.349661
37,8.124757531,0.168648704,70065.14808,1.661589458,114.0251722
37.2,8.242260527,0.170279813,69948.33194,1.670738236,114.5230899
37.4,8.215175902,0.171938431,70190.94062,1.673787823,115.2105858
37.6,8.264535887,0.173607778,70332.05951,1.676837419,115.7520847
37.8,8.730198286,0.175262294,70288.96412,1.684243617,116.3055705
38,8.854338297,0.176959445,70021.31204,1.698184606,116.8895618
38.2,8.773231373,0.178689228,69924.2573,1.706897706,117.3373596
38.4,8.974644102,0.180414953,69848.74823,1.716917806,117.8897548
38.6,9.177715965,0.182157946,69789.37356,1.725195285,118.3244799
38.8,9.074996086,0.183941575,69891.01164,1.730858795,118.8223967
39,9.188319924,0.185726676,70171.48828,1.733472744,119.4074774
39.2,8.975909144,0.187554643,70420.09587,1.734779687,119.8661696
39.4,9.293640494,0.189360539,70742.62718,1.736522349,120.4501618
39.6,9.541569286,0.191190012,71251.00341,1.732165828,120.9491701
39.8,9.533563063,0.193057355,71741.75052,1.728680587,121.5102802
40,9.569594126,0.194940077,72337.85057,1.723452729,122.1509267
40.2,9.75020719,0.196830767,72773.61071,1.722145787,122.7686934
40.4,10.16929941,0.198722406,73182.78226,1.719967563,123.2829562
40.6,10.08483394,0.200671056,73481.48548,1.721710177,123.8963638
40.8,10.89114202,0.202571721,73999.74568,1.718225033,124.4999705
41,10.85320348,0.204555671,74405.61797,1.71648241,125.0425583
41.2,10.57511767,0.206577827,75419.52528,1.703412716,125.8063202
41.4,11.02078473,0.208565199,76345.45324,1.690778764,126.4545956
41.6,10.80584462,0.210622761,77594.54029,1.673788179,127.3316696
41.8,10.98560172,0.212671007,78291.66914,1.667253371,128.0573007
42,11.33403642,0.214737488,78834.48001,1.665075137,128.8755433
42.2,11.04430107,0.216862797,78723.16053,1.673788215,129.4203084
42.4,11.37694441,0.218951565,78479.86557,1.68685792,130.0653148
42.6,11.24757536,0.221107127,78331.68188,1.696877982,130.5566941
42.8,11.40903484,0.223262204,78625.82429,1.699491937,131.1853562
43,11.64860006,0.225432906,79477.16226,1.69252148,131.9545691
43.2,11.6895651,0.227640641,80673.30049,1.679016168,132.8033164
43.4,11.68150067,0.229874171,81738.22125,1.666817817,133.5267675
43.6,11.97340507,0.232107448,83020.22739,1.652876878,134.4594104
43.8,11.81160802,0.234397595,83718.36407,1.648955963,135.270023
44,11.52931979,0.236719921,83997.07802,1.65113421,135.9379058
44.2,11.83118465,0.239021118,84135.96532,1.658104735,136.75179
44.4,11.86381852,0.241365961,83803.57696,1.671610061,137.2965572
44.6,12.07011688,0.243721122,83084.94271,1.693828517,137.8925342
44.8,12.13099548,0.246111101,82686.57201,1.709076469,138.4242273
45,12.23175579,0.248522096,82401.11047,1.721710493,138.9058025
45.2,12.31007664,0.250959001,82089.99125,1.73565148,139.4560175
45.4,12.81882495,0.253387628,82443.52849,1.736958511,140.1260847
45.6,12.82900026,0.255878556,83210.89897,1.72868106,140.7362243
45.8,12.9812638,0.258383682,84270.5381,1.716047072,141.4771085
46,12.9806288,0.260925595,85761.75525,1.697313887,142.4195557
46.2,13.06474651,0.263486546,87200.17749,1.678580712,143.2269014
46.4,13.46628249,0.266049112,88658.59347,1.662025852,144.2281862
46.6,13.55620865,0.268661159,89559.9538,1.655491032,145.1532018
46.8,13.60458322,0.271302553,89815.90405,1.659411939,145.919145
47,13.62885606,0.2739723,89823.4616,1.666818097,146.5826718
47.2,13.58747969,0.276673889,89960.87746,1.672045957,147.2527353
47.4,13.49790399,0.279406279,90173.70381,1.677273817,148.0491845
47.6,13.77227943,0.282138407,90632.04061,1.678580822,148.9088291
47.8,14.05412904,0.284897474,91412.08072,1.673788637,149.7499514
48,14.76308192,0.287651543,92202.26873,1.668125207,150.5180788
48.2,15.00919198,0.29046856,92938.73432,1.665511305,151.4725129
48.4,14.97194406,0.293335247,93628.57083,1.66202606,152.2547984
48.6,15.03274352,0.296223174,94570.64647,1.656362548,153.2582601
48.8,15.22316637,0.299130357,95440.88895,1.650699045,154.1887241
49,15.32799685,0.302073229,96135.44344,1.647213813,155.0276665
49.2,15.63723602,0.305030216,97366.07805,1.637629429,156.1477103
49.4,15.89827543,0.308020661,97913.26213,1.63632249,156.97249
49.6,15.83233171,0.311066045,98425.31369,1.635886833,157.8114312
49.8,15.77967834,0.314140859,98801.89877,1.63893642,158.7233712
50,16.19276684,0.317211201,99216.61981,1.642421712,159.7311936
50.2,16.23815559,0.320340486,99051.32176,1.654620081,160.6289708
50.4,16.24406927,0.32350417,99285.40796,1.658976638,161.3763915
50.6,16.40121056,0.32668829,99688.84232,1.662897557,162.3188398
50.8,16.61277392,0.329900214,100618.9565,1.658105372,163.2819901
51,16.76491932,0.333148943,101512.9785,1.652877524,164.1525295
51.2,16.67857721,0.336448389,103320.7297,1.636758258,165.3760762
51.4,16.57893465,0.339782064,104838.9397,1.62368858,166.4154913
51.6,16.60933028,0.343139207,106681.063,1.608440638,167.7218436
51.8,16.56202683,0.346535985,107742.6264,1.603648423,168.8604068
52,16.94639587,0.349934096,108379.4436,1.603648469,169.8649609
52.2,17.18825176,0.353377284,108645.2488,1.610183333,171.012243
52.4,17.3673655,0.356859838,108673.678,1.617589502,171.8827828
52.6,17.46171692,0.360383719,108415.6878,1.630659185,172.9058567
52.8,17.3690992,0.363957261,108263.629,1.640679258,173.8384974
53,17.70607637,0.367533975,108351.5266,1.648521101,174.8877226
53.2,17.78586913,0.371166275,108583.11,1.652442014,175.7582613
53.4,17.82577054,0.374838065,108856.8857,1.656798578,176.8172895
53.6,17.76262846,0.37855434,109054.4873,1.660719474,177.6660362
53.8,17.99280541,0.382285732,109392.0599,1.664640405,178.618292
54,17.8748088,0.386081061,109685.6576,1.668125639,179.4779339
54.2,18.31271097,0.389872217,109499.7706,1.680324053,180.4182057
54.4,18.20633552,0.393742951,109107.1727,1.696007648,181.2658629
54.6,18.21379389,0.397643877,109023.9826,1.705156421,181.9707919
54.8,18.34505741,0.401574742,108849.2346,1.716047832,182.7247511
55,18.24531088,0.405562437,108553.0422,1.729117494,183.5081262
55.2,18.66240821,0.409550983,108843.2405,1.731731481,184.1999844
55.4,18.60087258,0.413615991,109239.6327,1.733909755,185.0988505
55.6,18.57506126,0.417719122,109427.7473,1.736959345,185.7721824
55.8,18.78274004,0.421845789,109812.084,1.737830684,186.5729922
56,18.6979182,0.426036077,110430.2397,1.736088053,187.4958278
56.2,19.324382,0.430214419,110985.8129,1.733909853,188.2650446
56.4,20.12450755,0.434421349,111927.5047,1.728246428,189.2521706
56.6,20.06293221,0.438736107,112873.7714,1.721711587,190.1009182
56.8,20.08112109,0.443088203,113730.7059,1.717355034,191.0575299
57,20.50148236,0.44745349,114550.0424,1.714305497,192.0642643
57.2,20.51633352,0.451893386,115101.3622,1.713869845,192.8879529
57.4,20.51040384,0.456379598,115763.0342,1.713434191,193.8925038
57.6,20.81191817,0.460887512,116165.1289,1.714741198,194.6704343
57.8,20.85583109,0.465460178,116785.9941,1.714741205,195.5867341
58,21.23128541,0.470053662,117284.8225,1.716483876,196.5575132
58.2,21.34664533,0.474712922,117570.1343,1.720404795,197.490156
58.4,21.56919025,0.479410932,117715.5345,1.724761383,198.2484746
58.6,22.18559755,0.484126383,118268.0092,1.725197116,199.2247039
58.8,22.25440183,0.488930758,119320.8659,1.718226633,200.246689
59,22.30408659,0.493784926,120545.68,1.708642213,201.1727939
59.2,22.59307699,0.498669596,123176.1204,1.684681178,202.6000881
59.4,22.83718833,0.503606745,125535.35,1.663769728,203.8312645
59.6,22.96412795,0.508602423,128214.4936,1.641986953,205.4001963
59.8,23.24478115,0.513662106,129718.8678,1.633709526,206.7294314
60,23.05428206,0.518783158,130416.0506,1.633709506,207.8505617
60.2,22.99340702,0.523919689,130315.8306,1.644165243,209.0686608
60.4,23.32722054,0.529103886,129955.6607,1.655492337,209.9947691
60.6,23.22893218,0.534372921,130228.2963,1.661155854,211.1954356
60.8,23.54444813,0.539663522,130902.0171,1.662027205,212.3645103
61,23.53671634,0.545031985,131640.9481,1.661591551,213.4387915
61.2,23.67605404,0.550443014,132732.0395,1.658977634,214.8148756
61.4,23.76968087,0.555911921,133631.5505,1.656363712,215.8728155
61.6,24.18238349,0.56141165,133950.916,1.662462945,217.1432176
61.8,24.29842843,0.566989153,134207.4867,1.667690832,218.2371119
62,24.70114199,0.572600942,134542.7077,1.671176129,219.2689065
62.2,25.1528726,0.578265391,134503.6234,1.680324959,220.4401611
62.4,25.44505191,0.583998841,134209.9617,1.690345083,221.301987
62.6,25.43558742,0.589812827,133839.7034,1.702543451,222.3435822
62.8,25.8166599,0.595655435,133214.974,1.716920146,223.2130361
63,26.15118987,0.601560422,132946.9657,1.727811588,224.1925314
63.2,26.17659721,0.607548235,133267.858,1.73042553,225.0598015
63.4,26.27013287,0.613590822,134103.7028,1.728247264,226.2201577
63.6,26.78079553,0.619662403,134884.3613,1.725197736,227.1506265
63.8,26.8011883,0.62583229,136204.5612,1.716920278,228.312072
64,27.06503941,0.632045713,137005.2086,1.71561335,229.5454283
64.2,26.97655803,0.638348143,137142.2444,1.719969896,230.4203245
64.4,27.46059081,0.644670433,137491.0338,1.724326517,231.5131335
64.6,27.26157298,0.651108153,137851.5171,1.727376088,232.4065502
64.8,27.54948131,0.657573414,138050.6964,1.73303966,233.3588083
65,27.92545996,0.664097083,138952.9484,1.731732736,234.5115401
65.2,28.41693021,0.670677384,140356.7308,1.723455333,235.5803808
65.4,28.63002186,0.677344923,141572.4489,1.71866315,236.8682141
65.6,28.80238633,0.684082571,142709.4729,1.712999639,237.9381399
65.8,28.88416651,0.690894888,143539.9311,1.71125703,239.0625414
66,29.29332997,0.697750801,144086.0131,1.713435363,240.3122433
66.2,29.19726509,0.704714048,144117.6714,1.71909888,241.2078403
66.4,29.30643368,0.711731472,144984.7795,1.717791929,242.4477329
66.6,29.43137911,0.718818193,145524.9853,1.718227601,243.3901826
66.8,29.77900771,0.725959371,146583.31,1.714306748,244.5777804
67,30.13576537,0.73317158,148323.3606,1.704722354,246.0421203
67.2,30.31094895,0.740470382,149700.924,1.697316222,247.2406114
67.4,30.28793937,0.74785753,150648.6692,1.695573599,248.6515596
67.6,30.78509253,0.75527935,151523.4368,1.692959723,249.8010256
67.8,31.04873695,0.762793621,152327.7548,1.692088443,251.0779645
68,31.99125538,0.77033173,152649.2228,1.696880775,252.426821
68.2,31.96819813,0.778018803,152997.12,1.699930366,253.4727752
68.4,32.27335376,0.785758351,153723.9775,1.701237374,254.8161758
68.6,32.39444166,0.793589487,154028.0011,1.705158296,255.8654
68.8,32.83626371,0.801474951,154094.3073,1.712128851,256.9756423
69,33.10897487,0.809452507,154304.509,1.718663729,258.2024628
69.2,33.17227392,0.817526135,154472.2998,1.723455958,259.161255
69.4,33.38720842,0.825669427,154984.1628,1.72650558,260.4272982
69.6,33.89088501,0.833872688,155932.3597,1.72345605,261.4950497
69.8,34.06923162,0.842182992,157380.7415,1.716485574,262.8101216
70,34.72785406,0.850540247,159201.7532,1.706465562,264.3485545
70.2,34.88913959,0.859019308,160742.7029,1.699277256,265.773669
70.4,35.27185976,0.867566781,161714.4275,1.697316851,267.0636845
70.6,35.54238801,0.876208722,162537.2687,1.697099057,268.3983693
70.8,35.54990679,0.884957446,162831.5688,1.702109108,269.6398951
71,35.67873034,0.893784587,163051.1414,1.708208314,270.8313047
71.2,36.05848674,0.90268116,163681.2318,1.711257957,272.2280942
71.4,36.01859917,0.911698943,164204.8489,1.713436236,273.3448687
71.6,36.48806959,0.920768669,164323.759,1.720842452,274.6021986
71.8,36.233768,0.929984464,165032.7087,1.720406768,275.6165532
72,36.61679044,0.939244325,165671.7571,1.723020755,277.0002698
72.2,36.84025565,0.948609498,165943.0296,1.72824866,278.2532385
72.4,37.19915078,0.958058502,166197.4428,1.732169614,279.289392
72.6,37.24143885,0.967626304,166720.3021,1.73478356,280.5783135
72.8,37.7706484,0.977253441,166813.4454,1.740447159,281.6940057
73,38.29734979,0.986977303,167219.5207,1.742189852,282.7149081
73.2,38.75922152,0.996803898,167853.0669,1.743061223,283.9558963
73.4,38.64855286,1.006772681,168655.1371,1.742625556,285.2753229
73.6,39.29486396,1.016784126,169591.7981,1.739576043,286.3823004
73.8,38.92075213,1.026973738,170679.8409,1.736090749,287.6744848
74,39.16817484,1.037218507,171977.4351,1.731734218,289.1704203
74.2,39.83770395,1.047534103,172791.4895,1.729991676,290.3177124
74.4,40.10171283,1.057984271,173966.6336,1.726506459,291.796217
74.6,40.18871263,1.068552685,174964.3598,1.723456877,293.0230355
74.8,40.47263079,1.079212343,175973.7106,1.721278632,294.3958553
75,41.06730739,1.089955392,177160.0924,1.719100424,295.9288408
75.2,41.60546219,1.100810903,177700.0217,1.720843117,297.0488911
75.4,42.03059044,1.11178392,177877.7019,1.727813675,298.4282507
75.6,42.78060281,1.122842553,177785.2022,1.73521993,299.4306345
75.8,43.11179849,1.134044153,177949.6495,1.741319164,300.6313077
76,43.05824618,1.145387584,177763.9879,1.750467948,301.8777369
76.2,43.07530657,1.156839512,177980.4396,1.753953205,302.8855588
76.4,43.41808129,1.168381711,179096.0067,1.750467997,304.2976026
76.6,43.6594616,1.180047621,180088.2775,1.746982777,305.4841111
76.8,43.89500662,1.191831248,180596.0382,1.748289778,306.7250966
77,43.90367381,1.203810369,181715.4545,1.745675843,308.1785387
77.2,44.44996603,1.215748607,182991.1246,1.741319347,309.3955586
77.4,45.15494116,1.227855254,183226.8312,1.747854284,310.6932072
77.6,45.80338247,1.240150003,183873.2229,1.750468306,312.0311675
77.8,46.29477419,1.252456258,185010.5003,1.748290086,313.3887376
78,46.13300908,1.264998205,186342.5825,1.743062189,314.6329859
78.2,46.44403493,1.277629998,187495.2109,1.74044829,316.1082231
78.4,47.03174721,1.290367746,189327.084,1.731299575,317.4745101
78.6,47.47900847,1.30324425,190855.318,1.726507408,319.1425977
78.8,47.90132066,1.316252022,191852.4475,1.725200492,320.5633602
79,48.1424648,1.329404246,192221.5894,1.728685777,321.752048
79.2,48.99433684,1.342642183,192916.8912,1.730864167,323.2632484
79.4,49.58277633,1.35603323,194209.0205,1.727814644,324.8833987
79.6,49.57457169,1.369604151,195955.7273,1.720408481,326.3324823
79.8,49.77325215,1.383295714,197829.085,1.713438,328.0158203
80,49.67027558,1.397147614,199295.8602,1.708210109,329.4812454
80.2,50.08911408,1.411099028,200345.7409,1.708210162,331.2571961
80.4,50.49048032,1.425192063,199798.0006,1.718665975,332.3979464
80.6,50.61345548,1.439447886,198249.8354,1.737834891,333.6520059
80.8,50.98901699,1.453827617,196833.9467,1.754825554,334.6859833
81,51.60885517,1.468333237,196234.7333,1.76484574,335.6338898
81.2,52.23614877,1.482983981,196373.4927,1.770509359,336.9478812
81.4,52.52937669,1.497807147,197680.3646,1.765717173,338.1932271
81.6,52.84501664,1.512777359,199561.2441,1.758311049,339.8242692
81.8,53.24455876,1.527891632,200963.1266,1.754390189,341.2602852
82,53.60751493,1.543160328,202335.9831,1.750033674,342.566646
82.2,53.90646348,1.558587333,203676.6112,1.747419766,344.1355832
82.4,54.39484428,1.574154884,204007.8216,1.752212054,345.5803178
82.6,55.02280005,1.589868278,204649.7149,1.752647791,346.7483117
82.8,55.63909745,1.60574033,206128.3233,1.747419991,348.2398987
83,55.70361784,1.62181387,207166.3422,1.746113032,349.9003546
83.2,56.57164251,1.637987752,207484.0454,1.748291424,351.1173823
83.4,56.93940868,1.654362087,208100.7002,1.749598445,352.6993964
83.6,57.51073178,1.670885608,208772.7965,1.751341147,354.1953406
83.8,57.62334333,1.68760993,209037.9705,1.756133385,355.4820859
84,57.82899473,1.704495237,209893.3805,1.756133414,356.7557584
84.2,58.24152608,1.721534481,211746.1645,1.750905584,358.4456376
84.4,59.30051049,1.738695866,213663.7565,1.743935204,359.9197999
84.6,59.37437438,1.756105368,215930.6098,1.73565773,361.8101481
84.8,60.05522058,1.773643556,217671.8319,1.729994274,363.5141962
85,60.18470243,1.791399778,218470.2125,1.730429949,364.9088063
85.2,60.40389871,1.809327564,218923.1476,1.73435089,366.5758021
85.4,61.06720998,1.827401808,218918.9942,1.73957886,367.7895586
85.6,61.3885558,1.845683719,219142.4285,1.745242447,369.3835575
85.8,62.02604954,1.864125316,219876.3928,1.746985153,370.8707868
86,62.52432946,1.882762694,221112.186,1.745242587,372.4375508
86.2,63.24028896,1.90157095,222506.1822,1.742193078,374.0032287
86.4,63.63339373,1.920592515,224507.444,1.736529585,375.9153741
86.6,64.33101194,1.939782226,225639.8933,1.734787044,377.3601134
86.8,64.89440083,1.959174833,226988.2581,1.732608829,379.0456384
87,65.3239755,1.978772526,229259.9134,1.725202711,381.105962
87.2,66.14157345,1.998537607,230779.0107,1.721281897,382.656389
87.4,66.59476742,2.01852905,232389.8511,1.718668011,384.6295494
87.6,67.19126871,2.038710416,234016.8039,1.71474717,386.3030911
87.8,67.59495692,2.059109237,235482.3915,1.712568934,388.1542233
88,67.95083282,2.079716612,236100.4016,1.716489896,390.0173384
88.2,68.44627577,2.100520427,237269.0321,1.716925616,391.9403816
88.4,69.15897953,2.121516517,238228.66,1.717361362,393.5474641
88.6,69.46780719,2.14275337,239834.8065,1.715183115,395.5805478
88.8,69.9943104,2.16418712,241872.5001,1.709955292,397.5635161
89,70.53739842,2.185835069,244555.6967,1.700370897,399.523605
89.2,71.04970668,2.207702731,247155.6599,1.692964784,401.8824637
89.4,71.16561581,2.229820201,249127.1835,1.687736911,403.7749943
89.6,72.15398951,2.252093627,250502.7214,1.688172688,406.0521462
89.8,72.6213206,2.274630348,250624.6525,1.695578924,407.9708327
90,73.05787048,2.297395825,249655.4002,1.708213046,409.3970464
90.2,73.82261022,2.320365059,247816.6809,1.727382071,410.9910556
90.4,74.4668252,2.34357426,246182.9543,1.743501481,412.1350841
90.6,75.22982935,2.367007704,244275.0375,1.762234852,413.4414552
90.8,75.90886988,2.3906831,242981.9331,1.776175982,414.6464988
91,76.3385869,2.414615119,243035.5945,1.781403929,416.1424421
91.2,76.69514188,2.43879316,243844.6064,1.780968319,417.5011044
91.4,77.67237986,2.463166998,245649.9102,1.775304895,419.3173842
91.6,78.02470258,2.487833147,247230.365,1.77007705,420.8133277
91.8,78.57475266,2.512732087,249297.3241,1.763106598,422.6459436
92,79.00593675,2.537890265,251448.3944,1.756571789,424.6496125
92.2,79.36728065,2.563306458,252816.506,1.753522233,426.1793312
92.4,80.24709851,2.588938643,253737.5223,1.754829317,428.0261171
92.6,81.24154696,2.6148197,255159.6317,1.751779838,429.6037895
92.8,81.66508953,2.641004136,256678.3792,1.749165946,431.4679982
93,82.29799041,2.667435775,257070.5802,1.753958262,433.2810041
93.2,82.90592054,2.694134826,257452.9369,1.757443602,434.7453563
93.4,83.59274858,2.721096152,259196.939,1.754394085,436.7239723
93.6,83.6571498,2.748375576,260179.4992,1.754394096,438.2460604
93.8,84.2848936,2.775886319,261462.6892,1.75352286,440.0263791
94,85.20841278,2.803651019,263852.5776,1.746988108,442.2272663
94.2,85.3391584,2.831754907,266029.8145,1.740453259,444.0664112
94.4,86.33488138,2.860075335,268391.9272,1.734354173,446.3141495
94.6,86.71731572,2.888726965,270082.9076,1.73261159,448.4801624
94.8,87.4478737,2.917640083,270703.1697,1.736096945,450.2790062
95,88.16093552,2.946845049,271421.113,1.738275325,451.912241
95.2,88.91630574,2.976488864,272384.6888,1.74045371,453.9649498
95.4,89.62345678,3.006286814,272331.7479,1.746553011,455.5023042
95.6,90.19513893,3.036243014,272282.4645,1.753087955,457.298966
95.8,91.03348524,3.066631434,273539.5135,1.751781087,459.17844
96,91.69146614,3.097339042,274271.9678,1.752652487,460.7833458
96.2,92.5396864,3.128340571,275410.1282,1.753088252,462.8175345
96.4,93.23994747,3.159664872,277880.4315,1.746553469,465.0173281
96.6,93.54628653,3.191333797,280745.3382,1.73696903,466.9894014
96.8,94.63782624,3.223261133,283826.011,1.727820344,469.2894431
97,95.14183073,3.255554131,287093.5848,1.719107244,471.8781993
97.2,96.10447014,3.288136666,289292.2523,1.713879464,473.8797051
97.4,96.97980743,3.321053188,291494.189,1.710829964,476.4575754
97.6,97.62242514,3.354318077,293189.8609,1.710394386,478.9145019
97.8,98.44198293,3.387903711,294933.9146,1.709087512,481.2178063
98,99.30303484,3.421823621,296184.9966,1.709087618,483.2193102
98.2,100.2728876,3.456076283,297677.6547,1.709959054,485.7121995
98.4,100.8870373,3.490700035,298455.3605,1.712573081,487.6265349
98.6,101.7387847,3.525653603,298508.0333,1.720415037,489.8546638
98.8,102.5896453,3.560958459,297418.9224,1.733049237,491.669857
99,103.4196758,3.596619691,296597.4803,1.743505144,493.2562461
99.2,104.3792783,3.632628601,295275.7494,1.757446336,495.0431144
99.4,104.8427437,3.669036972,295250.828,1.763109957,496.5641238
99.6,105.9734074,3.705759817,295384.2119,1.769209319,498.5024423
99.8,106.4309394,3.742902817,296700.0535,1.768338061,500.4222221
100,107.2423988,3.780391767,298052.0473,1.766595531,502.1458942
100.2,108.1053175,3.818253542,300847.5511,1.759189445,504.5712305
100.4,109.1941955,3.856478491,302936.7732,1.753961682,506.5346088
100.6,109.762004,3.895126958,307344.8887,1.73914936,509.2846218
100.8,110.6613016,3.934138499,311775.0411,1.724772737,511.9561958
101,111.4367248,3.973551486,315744.8116,1.712574387,514.4654258
101.2,112.123173,4.013367108,320358.1053,1.699504711,517.585886
101.4,112.7804741,4.053584924,323758.1094,1.692534253,520.5559888
101.6,114.0127319,4.094163089,323977.0802,1.698197966,522.6751757
101.8,114.9599074,4.135170664,324508.902,1.702990328,525.0656511
102,116.0707154,4.176578848,324549.0793,1.710396662,527.5411151
102.2,116.8698491,4.218427848,323865.6584,1.719545597,529.4554581
102.4,117.7241745,4.260693195,323973.684,1.726080585,531.7990816
102.6,118.6810554,4.303375393,325715.9629,1.724338071,533.9258894
102.8,119.2144965,4.346518602,326103.4239,1.729566044,536.13876
103,120.5592965,4.390033641,326234.9169,1.736536756,538.4932923
103.2,121.6834085,4.434002702,326513.8265,1.742636121,540.8118642
103.4,122.2810402,4.478453568,325743.0092,1.751349377,542.4766983
103.6,123.2799524,4.5233205,324748.659,1.761369663,544.4542415
103.8,124.0049931,4.568659062,325090.429,1.764855028,546.3990903
104,124.9485028,4.614436489,325294.0674,1.768776081,548.1554558
104.2,126.189837,4.660651289,325957.3798,1.771825851,550.270288
104.4,126.8685406,4.707373128,326961.2348,1.773568576,552.2249425
104.6,128.1982233,4.75451499,328182.5713,1.774875722,554.2319131
104.8,129.0167931,4.802169288,330245.5492,1.771826212,556.3401982
105,129.7272625,4.850310729,333592.0142,1.762895288,558.7938628
105.2,130.7467707,4.898912338,337750.3983,1.750914786,561.4534595
105.4,132.0229667,4.947982655,342179.2507,1.738716484,564.4410178
105.6,132.939696,4.997573433,345242.5024,1.731310389,566.818421
105.8,133.8476212,5.047663203,347049.4434,1.730439183,569.2764512
106,134.9058697,5.098242891,347523.3663,1.736538547,571.8053056
106.2,135.5747347,5.149359695,347304.5673,1.743509183,573.7436194
106.4,136.3382471,5.200982849,347606.9099,1.749608513,576.1863925
106.6,137.3925118,5.253102429,348394.6302,1.751786943,578.1388808
106.8,138.4599886,5.305744759,350873.3409,1.747430481,580.651394
107,139.7043751,5.358902557,353764.6771,1.741767062,583.4668032
107.2,140.6802779,5.412614877,355207.3923,1.741331525,585.6982135
107.4,141.6718832,5.466865473,357470.7208,1.738282031,588.4613187
107.6,143.0979922,5.52162828,359040.4435,1.738717868,591.1950199
107.8,144.2124052,5.57696506,359773.488,1.742203284,593.5789709
108,145.0633166,5.632877786,359822.0638,1.747866969,595.5412606
108.2,146.2556619,5.689326113,361140.8275,1.750045417,598.1431209
108.4,147.4952818,5.746338097,361053.1451,1.756580469,600.0139003
108.6,148.7256702,5.803923635,360726.5366,1.765293822,602.2987066
108.8,149.7764801,5.862101378,362002.4666,1.766165275,604.5649852
109,150.6385698,5.920878043,364817.7983,1.759630486,606.8029304
109.2,152.1761339,5.980193726,368695.3242,1.750046159,609.8264567
109.4,153.0986951,6.040152219,373781.3998,1.735669495,613.1561246
109.6,154.693405,6.100662048,378253.2899,1.72303555,615.9769972
109.8,155.5609308,6.161835038,381735.3591,1.715629436,619.142144
110,156.6975891,6.223602123,384221.8028,1.713015616,622.3487028
110.2,157.8765277,6.285986561,385155.7488,1.715629721,624.7871342
110.4,159.0869432,6.348995516,387158.6077,1.71606553,627.7845029
110.6,160.2731604,6.412639337,389166.9987,1.716936996,630.836349
110.8,161.7376468,6.476901516,391204.6939,1.717808496,633.7890546
111,163.2244666,6.54180761,392188.1287,1.721293961,636.200258
111.2,164.3239566,6.607395198,394140.7245,1.722165418,639.3403554
111.4,165.5878717,6.673629107,395215.5227,1.724343875,641.8485238
111.6,166.8857503,6.740525898,395099.0676,1.732185923,644.7162422
111.8,168.1943247,6.80809413,395535.4064,1.736978351,647.3246482
112,169.6049991,6.876333453,396863.7969,1.737414186,649.8153886
112.2,170.7172507,6.945281033,398570.4711,1.738285646,652.8487131
112.4,172.1227205,7.014899001,399726.8916,1.740028463,655.1967221
112.6,173.5845282,7.085566189,402642.3296,1.73697902,658.2997921
112.8,174.8801446,7.156244651,406069.2293,1.731315592,661.38106
113,176.3408946,7.228340475,407833.963,1.731315772,664.0079981
113.2,177.2706041,7.300842008,409549.6155,1.732622871,667.1491821
113.4,179.0154268,7.373641773,410616.9408,1.73480139,669.6649949
113.6,180.2282613,7.447581819,411112.9385,1.740029471,672.5871931
113.8,181.4617519,7.522263089,411004.3619,1.747000199,675.1138835
114,183.1603999,7.598038939,413174.2923,1.746564749,678.2147812
114.2,184.2740532,7.673857837,414950.7913,1.746129228,680.6957112
114.4,185.6351504,7.750802986,417754.0161,1.743515432,683.8434478
114.6,187.3235228,7.828496323,420721.7204,1.739159031,686.6185733
114.8,188.7674693,7.906988956,423676.5314,1.735673921,689.7129275
115,190.3708347,7.986258023,425457.6666,1.736981103,692.8704826
115.2,191.8386273,8.066333974,427405.1218,1.737852607,696.1021214
115.4,193.2688991,8.147217243,429087.7526,1.737852785,698.700732
115.6,194.8095594,8.228904767,431656.232,1.73611033,701.9650598
115.8,196.193038,8.311424954,434852.2015,1.731753888,705.2075933
116,197.7359293,8.394762289,438240.4708,1.726090481,708.2028051
116.2,199.1723248,8.47894491,441438.2526,1.722605366,711.8550093
116.4,200.8304524,8.563956219,444154.4075,1.719555939,714.8077329
116.6,201.9192368,8.649864195,445661.2618,1.722605705,718.3041209
116.8,203.8080988,8.736573935,445616.372,1.730012183,721.1064965
117,205.2547519,8.824188108,446435.6811,1.735240301,724.3403173
117.2,206.7519538,8.912678018,449142.6949,1.732626517,727.2886787
117.4,208.0479222,9.002071874,451197.0991,1.733498001,730.7251539
117.6,210.1381463,9.092303017,453745.4334,1.730884287,733.5362536
117.8,211.6448923,9.183484787,458103.5256,1.723478223,737.1296271
118,213.5777758,9.275550044,462095.3519,1.71825052,741.092375
118.2,214.7252544,9.368599892,463325.3274,1.720428968,743.9666399
118.4,216.5572964,9.462532397,467077.3432,1.716508237,747.9707853
118.6,218.2205035,9.557421808,469899.7926,1.713894467,751.1948123
118.8,219.8710949,9.653265393,471842.7674,1.714765989,754.6585394
119,221.5730529,9.750068093,473194.8865,1.718687153,758.4164462
119.2,223.0338778,9.84786165,474723.0183,1.720429986,761.4694087
119.4,224.9976938,9.946599798,473152.8188,1.733064431,764.6847326
119.6,226.8632982,10.04634207,473612.2261,1.737856947,767.40431
119.8,228.6215494,10.14709486,474583.8348,1.741778126,770.5553442
120,230.1773008,10.24887523,476362.4981,1.743520971,773.980937
120.2,231.7765153,10.35167495,477553.2106,1.745699481,776.7015955
120.4,233.707535,10.45548233,479911.0328,1.74569972,780.3342174
120.6,235.4069664,10.56035036,479760.8523,1.751799207,782.8326132
120.8,237.2346141,10.66626217,479845.2508,1.757898711,785.6742215
121,239.0378827,10.69814669,479521.0919,1.765305202,788.6302326
121.2,240.1735777,10.69805919,480370.8988,1.768790648,791.757276
121.4,241.2016632,10.69797983,483187.0202,1.764869812,794.5040625
121.6,241.9904316,10.69791857,489041.1226,1.753978341,798.4515232
121.8,242.4995812,10.69787847,494368.5419,1.744829487,802.1843301
122,242.8973819,10.69784679,499394.7392,1.736551945,805.573928
122.2,243.5336688,10.69779706,505629.0909,1.726967442,809.8526044
122.4,243.9231598,10.69776601,508891.8858,1.724789177,813.1190826
122.6,244.4921388,10.69772138,512152.4072,1.723917922,817.2397727
122.8,244.5230695,10.69771745,515602.8603,1.721739614,821.1229204
123,244.8776602,10.69768904,517980.5755,1.721303997,824.4188141
123.2,244.8824156,10.69768709,519226.6237,1.725224966,828.3128562
123.4,245.3230109,10.69765217,518421.1669,1.733938279,831.8778743
123.6,245.5438166,10.69763388,516699.9322,1.743958554,834.4470357
123.8,245.7978609,10.69761308,514836.8095,1.75485016,837.3027483
124,246.0768339,10.69759038,515361.6866,1.759206826,840.7555345
124.2,246.4862682,10.69755782,516544.5865,1.760513868,843.591643
124.4,246.4561232,10.69755851,518181.4783,1.762692181,847.081462
124.6,246.8298261,10.69752866,520742.7472,1.761385241,850.0178071
124.8,246.9417757,10.6975186,521839.6247,1.764870561,853.0478454
125,247.0479086,10.69750898,520287.8198,1.777504802,855.9231665
125.2,247.3534725,10.69748428,518220.2254,1.791010394,858.4552871
125.4,247.3931284,10.69747969,517586.5473,1.798416671,860.5897115
125.6,247.6579751,10.69745807,515531.2597,1.81061527,862.9660266
125.8,247.631154,10.69745851,513422.125,1.821942506,864.8988827
126,247.8926769,10.69743713,511411.0664,1.832834117,866.9483311
126.2,247.7985478,10.69744266,510498.1098,1.839369052,868.7025033
126.4,248.1548004,10.69741413,508079.1811,1.851132001,870.494819
126.6,248.2758907,10.69740338,506269.1697,1.859845279,871.8316995
126.8,248.3803616,10.69739389,505142.0888,1.866815903,873.5096097
127,248.3909338,10.6973915,504279.983,1.873350852,875.2550672
127.2,248.6374994,10.69737126,504128.8988,1.876836191,876.6289955
127.4,248.8549813,10.69735322,504949.8681,1.877271885,878.2001337
127.6,248.8688774,10.69735058,507053.4205,1.874657911,880.331289
127.8,248.9675316,10.69734152,510831.3026,1.866815993,882.6138969
128,249.0653549,10.69733254,514854.4829,1.858102748,884.8158779
128.2,249.211374,10.6973199,516580.4598,1.857231444,887.1878276
128.4,249.1155829,10.69732556,517222.1513,1.858538423,888.9082188
128.6,249.4385971,10.69729953,517165.1029,1.862895098,890.8901215
128.8,249.2813148,10.69730984,514992.1566,1.87291533,892.2084667
129,249.3226326,10.69730513,510580.3694,1.889470533,893.2086747
129.2,249.4802852,10.69729161,509125.3725,1.896441165,894.1827363
129.4,249.8016375,10.69726572,506350.3882,1.908204112,895.1361031
129.6,249.7714925,10.69726641,504647.3654,1.915610382,895.8541166
129.8,249.8169651,10.69726138,504024.5467,1.919967022,896.8172795
130,249.7660461,10.69726364,505856.7565,1.917353039,898.2685566
130.2,250.0076259,10.69724378,507085.551,1.916481748,899.6217862
130.4,249.8727796,10.69725239,509350.262,1.912125103,900.9553852
130.6,250.0362489,10.69723844,511980.1938,1.907768497,902.6441905
130.8,250.2894623,10.69721769,512453.626,1.909511186,903.9015427
131.6,250.5344572,10.59294776,1.7977E+308,1.906025923,0
131.8,250.3235384,10.48604414,1.7977E+308,1.794496151,0
132,250.0336781,10.37914649,1.7977E+308,1.611517633,0
132.2,249.7820422,10.27224595,1.7977E+308,1.378002213,0
132.4,249.6567126,10.16533586,1.7977E+308,1.065196137,0
132.6,249.2463627,10.05844732,1.7977E+308,0.722329303,0
132.8,249.0661895,9.951541372,1.7977E+308,0.438277002,0
133,249.1211789,9.844617636,1.7977E+308,0.229158752,0
133.2,248.6834073,9.737731175,1.7977E+308,0.084954287,0
133.4,248.4417429,9.630829879,1.7977E+308,0.014376879,0
133.6,248.3762426,9.523915257,1.7977E+308,0.010891575,0
133.8,247.9783572,9.417025778,1.7977E+308,0.015248205,0
134,248.0192202,9.31010311,1.7977E+308,0.013941216,0
134.2,247.6313063,9.203212877,1.7977E+308,0.011327238,0
134.4,247.411247,9.096309947,1.7977E+308,0.00435663,0
134.6,247.1039366,8.989413617,1.7977E+308,0.004792293,0
134.8,247.0392673,8.882498932,1.7977E+308,0.013069889,0
135,246.616453,8.77561134,1.7977E+308,0.022218811,0
135.2,246.746229,8.668681946,1.7977E+308,0.029189418,0
135.4,246.1979394,8.561803845,1.7977E+308,0.02526845,0
135.6,246.246281,8.454880611,1.7977E+308,0.02962508,0
135.8,246.1010083,8.347972024,1.7977E+308,0.037467012,0
136,245.5294518,8.241095683,1.7977E+308,0.043566292,0
136.2,245.610201,8.134169998,1.7977E+308,0.050536899,0
136.4,245.0743759,8.027290954,1.7977E+308,0.049665571,0
136.6,245.111084,7.9203686,1.7977E+308,0.041823639,0
136.8,244.7805067,7.81347403,1.7977E+308,0.033546043,0
137,244.4964632,7.70657594,1.7977E+308,0.027011099,0
137.2,244.4625396,7.599658929,1.7977E+308,0.020476156,0
137.4,244.1909606,7.492759896,1.7977E+308,0.014376875,0
137.6,243.9027624,7.38586212,1.7977E+308,0.009584583,0
137.8,243.3852185,7.278981694,1.7977E+308,0.010020246,0
138,243.1439697,7.172080366,1.7977E+308,0.016990851,0
138.2,242.9891409,7.065172502,1.7977E+308,0.017426514,0
138.4,242.8588256,6.958262783,1.7977E+308,0.021783142,0
138.6,242.7862622,6.851348695,1.7977E+308,0.02918941,0
138.8,242.5516611,6.744446865,1.7977E+308,0.034417364,0
139,242.2086193,6.637553238,1.7977E+308,0.036160014,0
139.2,241.9274843,6.530654928,1.7977E+308,0.041387967,0
139.4,241.6122799,6.423759195,1.7977E+308,0.041387966,0
139.6,241.3307294,6.316860916,1.7977E+308,0.034417361,0
139.8,241.1667601,6.209953743,1.7977E+308,0.028753744,0
140,240.8511402,6.103058041,1.7977E+308,0.022654465,0
140.2,240.7956115,5.996142665,1.7977E+308,0.016119523,0
140.4,240.5718129,5.889240018,1.7977E+308,0.016990848,0
140.6,240.2699039,5.782343279,1.7977E+308,0.022654464,0
140.8,240.1532995,5.675432523,1.7977E+308,0.028318079,0
141,239.9041566,5.568531793,1.7977E+308,0.031803381,0
141.2,239.6151275,5.46163408,1.7977E+308,0.030060729,0
141.4,239.4058707,5.354730332,1.7977E+308,0.021783137,0
141.6,239.2805412,5.247820236,1.7977E+308,0.015683858,0
141.8,238.9923431,5.14092246,1.7977E+308,0.016119521,0
142,238.5637124,5.034035308,1.7977E+308,0.013941207,0
142.2,238.4184397,4.92712672,1.7977E+308,0.015248195,0
142.4,238.0986651,4.820231333,1.7977E+308,0.021347472,0
142.6,238.1278945,4.713309545,1.7977E+308,0.02091181,0
142.8,237.9335952,4.606404666,1.7977E+308,0.014812532,0
143,237.3786582,4.499527068,1.7977E+308,0.008277591,0
143.2,237.2367094,4.392618229,1.7977E+308,0.008277591,0
143.4,237.2451649,4.285698013,1.7977E+308,0.015683856,0
143.6,236.7783099,4.178813751,1.7977E+308,0.022654458,0
143.8,236.5208574,4.07191365,1.7977E+308,0.024832771,0
144,236.306615,3.96501028,1.7977E+308,0.028753734,0
144.2,236.0175859,3.858112567,1.7977E+308,0.032674698,0
144.4,235.6072364,3.751224031,1.7977E+308,0.032239034,0
144.6,235.3290099,3.644325501,1.7977E+308,0.031803371,0
144.8,235.3466059,3.537404593,1.7977E+308,0.024397106,0
145,235.1182371,3.430502291,1.7977E+308,0.015248191,0
145.2,234.4087413,3.323636385,1.7977E+308,0.005227951,0
145.4,234.1853583,3.216733706,1.7977E+308,0.003485301,0
145.6,234.0026925,3.109827947,1.7977E+308,0.005663613,0
145.8,233.7510568,3.002927406,1.7977E+308,0.008277589,0
146,233.2501325,2.896045722,1.7977E+308,0.012198551,0
146.2,232.9760609,2.789146878,1.7977E+308,0.018297827,0
146.4,233.1224559,2.682216226,1.7977E+308,0.023090115,0
146.6,232.6389819,2.575333222,1.7977E+308,0.033546015,0
146.8,232.0823832,2.46845575,1.7977E+308,0.038338301,0
147,232.1132746,2.361533836,1.7977E+308,0.029189389,0
147.2,231.8524983,2.254633986,1.7977E+308,0.021783126,0
147.4,231.571779,2.147735645,1.7977E+308,0.02265445,0
147.6,231.2096254,2.040843463,1.7977E+308,0.030496374,0
147.8,230.8092476,1.933954174,1.7977E+308,0.037466973,0
148,230.8351532,1.827032637,1.7977E+308,0.037902636,0
148.2,230.4189871,1.720144542,1.7977E+308,0.037902635,0
148.4,230.0336516,1.612719524,1.7977E+308,0.035724321,0
148.6,229.8401833,1.505814582,1.7977E+308,0.033981671,0
148.8,229.4754519,1.399457186,1.7977E+308,0.024832759,0
149,229.1249318,1.292564124,1.7977E+308,0.010455898,0
149.2,228.6796821,1.185678229,1.7977E+308,0.006970599,0
149.4,228.1870677,1.078795916,1.7977E+308,0.02178312,0
224.6,227.0748155,0.977779718,1.7977E+308,0.043130598,0
224.8,226.7608576,0.87088389,1.7977E+308,0.043130597,0
225,226.6600415,0.76397194,1.7977E+308,0.031803369,0
225.2,226.0793448,0.65709629,1.7977E+308,0.017426503,0
225.4,225.9319948,0.55018786,1.7977E+308,0.002613975,0
225.6,225.2328861,0.443321168,1.7977E+308,0.013941202,0
225.8,224.7236522,0.336440113,1.7977E+308,0.023961439,0
226,224.277987,0.229554249,1.7977E+308,0.023090114,0
226.2,223.3129705,0.122707672,1.7977E+308,0.018297825,0
226.4,222.0222172,0.015885735,1.7977E+308,0.007841924,0
226.42,221.7866541,0.005211597,1.7977E+308,0.007406262,0
,,,,,