File: Test_17.csv
Time On Sample,Displacement Into Surface,Load On Sample,Harmonic Contact Stiffness,Harmonic Displacement,Harmonic Load
0,0,0,598.2630278,0.337228076,2.220614775
0.2,-0.123994276,0.000767542,5009.472332,0.231789838,2.290349476
0.4,-0.218902705,0.001532885,10586.27764,0.182120586,2.355725759
0.6,0.186465437,0.002260399,13556.01438,0.161207222,2.409116447
0.8,0.211224494,0.003016693,16029.93621,0.148572062,2.573646789
1,-0.194486767,0.003804135,17632.92826,0.145522191,2.726191424
1.2,0.04384593,0.004541632,18882.44883,0.144650803,2.877646535
1.4,0.312926528,0.005276803,21620.8581,0.133322731,3.032370473
1.6,0.403336921,0.006025485,24538.32874,0.123301742,3.162033474
1.8,0.529481356,0.006771464,33624.31979,0.102824069,3.577172967
2,0.753686654,0.007510028,46024.38389,0.084089176,3.969430783
2.2,0.67623015,0.008271402,59811.19916,0.0727611,4.349702901
2.4,0.612901058,0.009031708,65953.91068,0.0727611,4.722347765
2.6,0.680873798,0.009782086,66661.48322,0.077118053,5.050318862
2.8,0.797045945,0.010528819,67001.26628,0.0910603,6.005902421
3,0.620697555,0.01129767,58985.39996,0.118073402,6.878675939
3.2,0.790055254,0.012040381,52265.9932,0.149007764,7.72856785
3.4,0.720908992,0.012801127,46234.5482,0.187784637,8.615506251
3.6,0.589435912,0.013566585,42915.49394,0.220026082,9.33137664
3.8,0.872643935,0.014300687,42649.80733,0.254010312,10.67377007
4,0.988816084,0.015047419,42867.78557,0.28363759,11.93008464
4.2,0.951664255,0.015805745,42970.91469,0.314136255,13.19293677
4.4,1.272268379,0.016537019,42916.69537,0.344634928,14.43072822
4.6,0.877360599,0.017322397,41981.71651,0.376876366,15.42335806
4.8,0.6665247,0.018093856,40440.65463,0.427417006,16.83439631
5,0.590730245,0.018855104,39175.34862,0.470550829,17.94688289
5.2,1.007317664,0.01957912,37420.19515,0.520655795,18.9667535
5.4,0.731661871,0.020355481,35305.15894,0.584702982,20.08468791
5.6,0.830798022,0.021103501,33674.33031,0.640036278,20.9661784
5.8,0.668577043,0.021871285,31503.10668,0.7193328,22.05033512
6,0.515912843,0.022638346,28903.76193,0.81431435,22.92637741
6.2,0.746350826,0.023376439,26486.59262,0.917138434,23.70435548
6.4,0.807675373,0.024127318,24526.02011,1.00907013,24.22845556
6.6,0.795038761,0.02488379,22673.44597,1.10840864,24.71441934
6.8,1.392789486,0.025594107,20955.40533,1.217332495,25.2363409
7,1.044834571,0.026375934,20203.86347,1.277894104,25.6318671
7.2,1.283582807,0.027113397,19768.44085,1.327127687,26.17993865
7.4,1.070253828,0.027885044,19855.19749,1.341941306,26.6637231
7.6,1.016481514,0.028644626,20122.07581,1.348912426,27.19436058
7.8,1.068249283,0.029396227,20619.73356,1.348912431,27.86882609
8,0.906859325,0.030163946,21032.56453,1.346733941,28.38202987
8.2,1.104056344,0.030904551,21401.22462,1.352397998,28.9824025
8.4,1.060671833,0.031663348,21464.80631,1.368083023,29.41497558
8.6,1.39041723,0.032393929,21467.60383,1.38681795,29.85190767
8.8,1.300079846,0.033156275,21314.013,1.417316609,30.33460257
9,1.627747689,0.033887013,21038.44648,1.449122394,30.65712612
9.2,1.490041917,0.034652941,20643.20457,1.49051343,30.99708271
9.4,1.066463787,0.035440485,20561.87632,1.515348016,31.36863732
9.6,1.883189439,0.036134242,20654.88062,1.525369092,31.70096822
9.8,1.947422578,0.036884899,21013.37143,1.518833671,32.07797161
10,2.269688779,0.037616044,21983.48715,1.480928217,32.61078893
10.2,1.627135716,0.038420145,23256.01443,1.429951808,33.14796323
10.4,2.079872732,0.039141425,24797.36735,1.375489946,33.81589186
10.6,1.856571449,0.039913823,26224.82734,1.330613314,34.43260796
10.8,2.028422241,0.040656342,27560.58924,1.295757709,35.09290892
11,2.448333808,0.041380103,28271.44503,1.287479537,35.66604183
11.2,2.046777794,0.042165981,28504.71563,1.298807579,36.22173968
11.4,1.752008418,0.042943784,28732.7018,1.306214373,36.67174617
11.6,2.173582027,0.04366742,28926.37808,1.314928317,37.12720179
11.8,2.136430196,0.044425742,29107.61745,1.328870563,37.70251313
12,2.331549674,0.045166501,29498.22325,1.331484753,38.26257059
12.2,2.303123599,0.045924164,29924.74213,1.328434884,38.72238379
12.4,2.268880353,0.046682266,30316.63604,1.329741968,39.28897845
12.6,2.570370954,0.047414981,30596.16114,1.333227558,39.76731562
12.8,2.226986641,0.048196459,31085.33859,1.331049052,40.38512096
13,2.365596464,0.04894149,31529.22885,1.329741979,40.96152233
13.2,2.46099302,0.049689789,31734.69217,1.334970332,41.40826067
13.4,2.478273286,0.050443995,31972.46982,1.342812849,41.96178006
13.6,2.314390237,0.0512119,32172.58215,1.348912569,42.4226827
13.8,2.514495865,0.051952281,32343.43698,1.360676361,43.01324917
14,2.609891822,0.05270436,32445.67401,1.370261667,43.45127048
14.2,2.401134057,0.053471877,32793.66994,1.372875819,44.01350632
14.4,2.437527883,0.054224638,33290.41811,1.368518871,44.58554899
14.6,2.790542002,0.054953456,33726.94383,1.364161952,45.06715522
14.8,2.697296023,0.055716019,34373.85377,1.35806221,45.74597907
15,2.86416008,0.056462693,34640.64798,1.361112093,46.21342002
15.2,2.809972849,0.057218522,34771.62318,1.372004471,46.76040169
15.4,3.118942684,0.05795067,34732.4712,1.389432313,47.28668161
15.6,3.256721493,0.058695762,34688.84779,1.403810272,47.71489675
15.8,3.342976788,0.059444749,34632.72703,1.418623922,48.17579996
16,3.665243027,0.060175891,35095.64607,1.415138391,48.74675383
16.2,3.663409732,0.060931539,36013.08658,1.396403493,49.3939792
16.4,3.133875919,0.06172709,37060.40707,1.372004506,49.97037902
16.6,3.962236048,0.062419962,38395.58849,1.344120084,50.72656705
16.8,4.010264222,0.06317184,39553.67311,1.322771018,51.40648074
17,3.881284184,0.063937102,40312.18558,1.316671273,52.12670947
17.2,3.744824927,0.064702929,40425.38046,1.32887073,52.76194901
17.4,3.772908513,0.065456315,40179.73101,1.348912718,53.24137541
17.6,3.596560083,0.066225159,40087.52528,1.364162039,53.73714514
17.8,4.065086637,0.06694524,39759.27523,1.390303803,54.37674474
18,4.101480469,0.067697997,39457.17261,1.410781488,54.81258678
18.2,3.845353686,0.068472873,39412.87689,1.426466496,55.38135999
18.4,4.032993972,0.069214193,39568.17874,1.435180422,55.95013453
18.6,3.840025049,0.069984293,39817.45579,1.439101662,56.4600691
18.8,4.192208183,0.07071317,40892.22299,1.420802493,57.18901601
19,4.162120057,0.071470954,42194.32152,1.394225075,57.83842057
19.2,4.223444624,0.072221824,43763.57452,1.364162104,58.65889357
19.4,4.301389682,0.072971438,45289.00641,1.338020391,59.49571053
19.6,4.352741956,0.073723063,46163.42972,1.328435099,60.16581789
19.8,4.104094388,0.074497373,46376.56918,1.340198855,60.96667716
20,3.980100495,0.075262257,46223.1222,1.356319569,61.51256878
20.2,4.214278156,0.076000058,45683.60168,1.385946878,62.13800308
20.4,4.248178915,0.076753002,45115.86777,1.416445552,62.73946501
20.6,4.318644753,0.077503181,44714.6674,1.440408808,63.26465519
20.8,4.428168743,0.078250407,44441.15536,1.459579417,63.74081301
21,4.408052351,0.079010959,44042.03931,1.485721134,64.30304924
21.2,4.437796204,0.079775441,44021.19486,1.497484912,64.75523551
21.4,4.381112271,0.08055425,44099.17361,1.507941597,65.31856123
21.6,4.305313547,0.081342219,44275.35078,1.513605629,65.83612347
21.8,4.443502409,0.082121715,44668.18722,1.514912731,66.48879744
22,4.516454586,0.08291408,45219.24806,1.510991477,67.13820239
22.2,4.510042646,0.083720474,45644.47098,1.507941612,67.65467525
22.4,4.77163483,0.084514685,46135.56604,1.506198859,68.30081201
22.6,4.626439244,0.085347618,46479.81838,1.50750593,68.84561416
22.8,4.615868284,0.086178843,46706.38522,1.514477054,69.49719788
23,4.72911866,0.087009001,46806.30478,1.521012495,69.97662461
23.2,4.681979953,0.087859779,46887.26114,1.530597791,70.56719063
23.4,4.469881513,0.088731616,46968.20101,1.53974737,71.15993478
23.6,4.638806457,0.089583196,47231.74527,1.541054474,71.66987063
23.8,4.589170573,0.090459975,47752.37411,1.535826126,72.25716782
24,4.623882308,0.091338995,48412.2559,1.5292907,72.93381287
24.2,5.024658943,0.092199209,49064.16387,1.523191008,73.60174214
24.4,4.58235977,0.093132066,49503.32085,1.521883876,74.14545357
24.6,4.799892633,0.094024124,49761.38303,1.525805158,74.67718162
24.8,4.855374262,0.094937558,49714.45739,1.541490198,75.32767621
25,5.291463695,0.095831293,49486.52822,1.559789451,75.87901814
25.2,5.118410679,0.096780211,49235.0369,1.575474467,76.288709
25.4,4.999788277,0.097734412,49022.0484,1.591595183,76.81498797
25.6,5.367729233,0.098661405,48868.34676,1.60423039,77.23339784
25.8,5.490516474,0.099616192,48882.81183,1.613815703,77.79781382
26,5.179507316,0.100613666,49132.39812,1.615340604,78.28867969
26.2,5.60686195,0.101565012,49451.84956,1.615994195,78.78390702
26.4,5.560115512,0.102561965,49657.19602,1.621658231,79.32870959
26.6,5.546192955,0.103566439,49989.98077,1.620786839,79.79723977
26.8,5.980606581,0.104546998,50533.29058,1.617301325,80.41504758
27,5.938010493,0.105573655,50943.734,1.614251454,80.88684669
27.2,5.801922517,0.106617574,51720.31741,1.602923359,81.53407158
27.4,5.836608413,0.10765918,52890.41572,1.58157429,82.25756974
27.6,5.85965833,0.10871194,54019.84153,1.561968,82.9156914
27.8,5.80791434,0.109781014,55284.44842,1.540618921,83.64245793
28,6.157969063,0.110830311,56629.20942,1.520141275,84.46293212
28.2,6.058853266,0.111924373,57875.86739,1.504020535,85.32045114
28.4,6.240622067,0.113008038,58819.32473,1.49312817,86.01017215
28.6,6.205076193,0.114119062,59489.46862,1.488771213,86.6911753
28.8,5.808032824,0.115268657,60154.23231,1.487899783,87.57920193
29,6.012649466,0.116384146,60555.4862,1.490731824,88.30923825
29.2,6.125851604,0.117517861,60789.23639,1.496613725,88.99786945
29.4,6.000963371,0.11868101,60583.29392,1.513170138,89.70284346
29.6,6.045602312,0.11984297,60321.233,1.528855178,90.27924488
29.8,6.2855302,0.121001748,60099.30132,1.546283021,91.01255046
30,6.240414766,0.122193869,60017.9554,1.556739707,91.54972562
30.2,6.122998289,0.123403411,60125.78988,1.565017908,92.24053506
30.4,6.417768121,0.124593794,60644.43372,1.56414655,92.9956328
30.6,6.409212028,0.125819279,61471.44526,1.555432641,93.72893694
30.8,6.596775825,0.127042061,61959.70148,1.55368988,94.37289489
31,6.396249117,0.12830673,62440.19415,1.554125555,95.13125891
31.2,6.641980658,0.129550162,62945.28806,1.554125582,95.91141751
31.4,6.373305923,0.130845175,63116.688,1.559789595,96.50634095
31.6,6.348119369,0.13213463,63017.42647,1.57155337,97.05332267
31.8,6.619606576,0.133414479,63056.61979,1.583317176,97.79643496
32,6.752310629,0.13471765,63241.58233,1.590288319,98.48397647
32.2,7.043738309,0.136021954,63429.09526,1.597259478,99.17587727
32.4,7.127407712,0.137355241,63466.08804,1.604230615,99.6858129
32.6,7.005811879,0.138717496,63687.89024,1.607280471,100.280737
32.8,7.159281961,0.140079447,64252.67652,1.604666316,101.0848668
33,7.422447333,0.141432925,64632.18558,1.605537737,101.8170827
33.2,7.216911469,0.142842641,64829.50889,1.608587583,102.377139
33.4,7.431871877,0.144234565,65616.32819,1.601180785,103.1627452
33.6,7.316082223,0.145665535,66365.37744,1.594209646,103.8557335
33.8,7.321619899,0.147101647,66828.67425,1.596388125,104.6751173
34,7.608872667,0.148530842,67053.76611,1.600309417,105.259147
34.2,7.436566455,0.150009343,67282.23506,1.60597344,105.9859131
34.4,7.555116548,0.151480599,67087.41221,1.620351404,106.616795
34.6,7.711891456,0.152963586,66890.77159,1.63298659,107.1485236
34.8,7.635977032,0.154479324,66921.98977,1.642136187,107.8371537
35,7.515184866,0.156013599,67365.15781,1.639957698,108.4135544
35.2,7.843974664,0.157529056,68035.06404,1.635600781,109.1621149
35.4,7.949216363,0.159076829,68692.39423,1.629501057,109.8136998
35.6,7.841713242,0.160656327,69504.14437,1.622529918,110.6407097
35.8,7.950274053,0.162235221,70284.59319,1.615123108,111.3598498
36,8.01811213,0.163833062,70639.39062,1.618172985,112.1574415
36.2,7.898136045,0.165461263,71063.78018,1.617301582,112.8133832
36.4,8.079819366,0.16708287,71470.23487,1.61948008,113.5935416
36.6,8.032137242,0.168738272,72004.42125,1.61817299,114.28762
36.8,8.159798717,0.170396919,72491.71979,1.618173005,114.9947747
37,8.33731905,0.172068337,72972.54934,1.619915807,115.7978151
37.2,8.251401843,0.173776598,73039.48363,1.627322622,116.3862018
37.4,8.409803178,0.17548362,72986.00312,1.638650723,117.0889977
37.6,8.259060565,0.177231214,72561.97517,1.655207135,117.6054701
37.8,8.159007694,0.178992404,71977.83818,1.674813422,118.0957919
38,8.406320374,0.180744949,71430.53806,1.694855451,118.6558506
38.2,8.567203671,0.182521707,71095.03364,1.708362033,119.077529
38.4,8.43805647,0.184338322,71038.04218,1.717511619,119.6408547
38.6,8.346302492,0.186170304,71443.41411,1.71576883,120.1932842
38.8,8.727398709,0.187984816,72143.39524,1.70836205,120.8078239
39,8.656414525,0.189851869,73225.40916,1.693984091,121.5890707
39.2,9.00883453,0.19170545,74434.38109,1.677863401,122.4193521
39.4,9.278980109,0.193583971,75101.02698,1.670892305,123.0556834
39.6,9.240812488,0.195504633,75323.15789,1.673506473,123.6723999
39.8,9.378403544,0.197431336,75033.57396,1.688320139,124.3403289
40,9.605742213,0.199370589,74590.24142,1.704005204,124.7707245
40.2,9.392634599,0.201362744,73892.66095,1.726225654,125.2348952
40.4,9.933678881,0.203317729,73660.47311,1.737989495,125.6435006
40.6,9.825689596,0.205341642,73898.26999,1.739732265,126.1458082
40.8,9.810771882,0.207378733,74891.94637,1.72709709,126.9085317
41,10.2724437,0.209400107,76084.35882,1.709233628,127.5742832
41.2,10.28037269,0.211476288,78108.59296,1.678299251,128.5516601
41.4,10.8533953,0.213530509,79579.8276,1.657385926,129.3361793
41.6,11.32918477,0.215612535,81108.40356,1.637343984,130.1893434
41.8,11.3724224,0.217748474,82776.87902,1.618173384,131.2756806
42,11.35790036,0.219910298,83905.24136,1.60771669,132.1914939
42.2,11.68077104,0.222068155,84743.53844,1.602488379,133.102951
42.4,11.79089586,0.224263919,85408.24754,1.599438523,133.9081703
42.6,11.7393828,0.226494056,85952.12237,1.598567127,134.7406287
42.8,11.70157809,0.22874556,86607.89804,1.598131428,135.8073523
43,11.48967006,0.231032823,87070.0729,1.599874188,136.7858172
43.2,11.71529307,0.233309689,87551.98026,1.599438518,137.5561699
43.4,11.95961046,0.235608283,88313.68874,1.597260068,138.5891174
43.6,11.98744219,0.237946307,88945.50263,1.595952985,139.4411895
43.8,11.7676247,0.240326752,89372.39859,1.599002831,140.3096035
44,11.98658465,0.24269763,89729.23779,1.605102595,141.279354
44.2,11.80498674,0.24512279,89800.95994,1.612945096,142.0104782
44.4,11.68238775,0.247567753,89509.36533,1.628630125,142.8723557
44.6,12.26200101,0.249983972,89037.35954,1.645186624,143.5337503
44.8,11.94701194,0.252492446,88777.7009,1.657821762,144.2201996
45,12.15140953,0.254986659,88745.54269,1.667407089,145.0297784
45.2,12.03585849,0.257530217,88892.75989,1.672199729,145.7053328
45.4,12.30091287,0.260070417,88977.27005,1.679606586,146.5018365
45.6,12.21527062,0.262662735,89275.33255,1.681785055,147.195915
45.8,12.17657713,0.265277624,89592.30989,1.683963529,147.9248608
46,12.13372435,0.267919044,89513.43707,1.693984525,148.7017493
46.2,12.55748792,0.270551634,89197.65652,1.706184052,149.2400176
46.4,13.368505,0.273181175,89274.08269,1.713155278,149.9460881
46.6,13.2828418,0.275905298,89591.37934,1.714898052,150.6052986
46.8,13.40617704,0.278641034,90335.42045,1.711412502,151.4878809
47,13.20707016,0.281428782,91457.9476,1.699648697,152.2516925
47.2,13.62208641,0.284197877,93452.8955,1.675685486,153.3489287
47.4,13.45039447,0.287039451,94717.9781,1.662178902,154.2118954
47.6,13.67759005,0.289879278,95820.80137,1.652593624,155.1282554
47.8,13.46018266,0.292781398,96525.01757,1.651722209,156.2004258
48,13.74304776,0.295674717,96405.84911,1.661307547,156.9097611
48.2,13.56552033,0.298631915,95787.16891,1.680478136,157.6604987
48.4,13.68798826,0.301596074,95543.35491,1.692241934,158.2772165
48.6,13.83205812,0.304588249,95183.67482,1.705312822,158.8525298
48.8,13.89551374,0.307616749,95205.22242,1.714026743,159.689347
49,14.13763493,0.310662159,95649.44906,1.713155382,160.3812486
49.2,14.03903093,0.3137641,96309.37168,1.710105501,161.2562014
49.4,13.85731947,0.316903472,96600.79876,1.711412568,161.917591
49.6,14.02297153,0.320047905,96998.51886,1.711848284,162.6410907
49.8,14.13460192,0.323228071,97667.35758,1.710105516,163.5814207
50,14.02766763,0.326456748,98005.29676,1.711848287,164.2711406
50.2,14.17668392,0.329698428,98172.1629,1.717948045,165.07854
50.4,14.26668962,0.33299374,98571.66857,1.718383752,165.7595444
50.6,14.29436578,0.336310519,99374.37904,1.712719713,166.5527775
50.8,14.31705315,0.339644163,100000.9911,1.711412629,167.4854802
51,14.48433091,0.343017183,100250.2623,1.713591128,168.1599476
51.2,14.70395789,0.346420035,100806.7151,1.712719764,169.0632326
51.4,14.73410567,0.349871539,100705.6934,1.720126595,169.675592
51.6,14.9670181,0.353342293,100301.0244,1.732761799,170.2650701
51.8,14.91155923,0.356869825,100373.9106,1.739297229,171.0713783
52,14.96163494,0.360424757,100901.5807,1.737118757,171.7589201
52.2,15.19702359,0.364001408,101635.4023,1.733197525,172.6425925
52.4,15.3301904,0.367621851,102629.6294,1.724047932,173.3922421
52.6,15.41930711,0.371281947,103509.6654,1.717512508,174.2148955
52.8,15.53750387,0.374976541,103877.9996,1.720126697,175.1236276
53,15.62743985,0.37871054,103672.9329,1.729276319,175.721822
53.2,15.64507067,0.38248749,103364.131,1.741475802,176.4104531
53.4,15.68845726,0.386300403,102886.1377,1.755853767,177.0511421
53.6,15.6861314,0.390154838,102886.6441,1.761953508,177.625364
53.8,15.91731751,0.394030155,103383.3811,1.761082146,178.2998323
54,15.85431448,0.397966758,104318.8235,1.754982399,179.1519036
54.2,16.03396455,0.401924435,104934.3187,1.751932551,179.8220131
54.4,16.05737556,0.405933669,105601.1603,1.749754077,180.6555617
54.6,16.22039241,0.409972665,105907.7953,1.751061184,181.3049683
54.8,16.09005089,0.414074358,106012.622,1.756725214,182.1101862
55,16.53227928,0.418173718,105766.0479,1.765439184,182.6364694
55.2,16.87311603,0.422322057,105603.5974,1.774153141,183.2967737
55.4,17.88541471,0.426460794,105405.4104,1.781995798,183.8045394
55.6,18.75809451,0.430652127,105431.1107,1.786788551,184.3482604
55.8,18.923565,0.434939222,105839.0466,1.787224268,185.0859252
56,19.17545531,0.439262693,106900.8007,1.776331908,185.8061579
56.2,18.88301703,0.443670967,108717.4432,1.755854173,186.8194883
56.4,19.53544769,0.448051707,110706.7802,1.733198065,187.7794379
56.6,19.98676319,0.452491862,112721.0748,1.711413327,188.7884173
56.8,20.1497057,0.456998801,115421.5982,1.683964511,190.2081756
57,20.42773806,0.461542202,117521.7597,1.664793925,191.4269026
57.2,20.22917003,0.466167393,119152.943,1.653030113,192.6096683
57.4,20.54001327,0.470800377,120259.7197,1.648673189,193.8485534
57.6,20.28990686,0.475522545,121259.5056,1.644316207,194.9130963
57.8,20.31943304,0.480270749,121943.4163,1.644316208,195.9961651
58,20.3747134,0.485064812,121796.7794,1.655644308,197.0955783
58.2,20.54383659,0.489898542,121611.7435,1.666101031,198.0130283
58.4,21.02707974,0.49475689,121545.112,1.675250698,198.9174061
58.6,21.00380504,0.499702577,121251.7625,1.68701449,199.7476859
58.8,21.21861126,0.5046799,121198.3022,1.69747121,200.8089635
59,21.1820243,0.509726279,121737.0685,1.697906905,201.6741107
59.2,21.20526314,0.514818755,122989.6958,1.690935773,202.8704989
59.4,21.1138123,0.519971148,123982.7654,1.685707412,203.86095
59.6,21.42083001,0.525145047,125298.101,1.676993531,204.9669027
59.8,21.583241,0.530381941,126634.786,1.670458112,206.351794
60,21.31683441,0.535704055,126818.0815,1.675250737,207.2627021
60.2,21.5074834,0.541044895,126088.5976,1.692678596,208.2477079
60.4,21.82070016,0.546430021,125503.2379,1.706185207,208.9679412
60.6,22.16216321,0.551867049,124631.4087,1.723613085,209.641321
60.8,22.63491964,0.557348771,123217.415,1.749319202,210.4051406
61,23.01583896,0.562892728,122815.3715,1.759775952,211.0360263
61.2,23.17694313,0.568509051,122576.4796,1.769361284,211.8107379
61.4,23.40452039,0.574176782,122525.9439,1.775461056,212.4416223
61.6,23.2693459,0.57992884,122819.8376,1.777203824,213.1564033
61.8,23.594966,0.585703641,124300.4969,1.765440074,214.2579984
62,23.86198954,0.591541047,125455.9481,1.756290492,215.0980875
62.2,24.02637209,0.597444886,127755.2081,1.735377105,216.3849141
62.4,24.27841844,0.603401307,129410.2534,1.721434864,217.4124161
62.6,24.30192319,0.609434937,131168.6651,1.707492597,218.5565032
62.8,24.54605565,0.615512396,132782.4583,1.697907314,219.9729938
63,24.50929167,0.621672385,133592.1701,1.695728831,220.9863272
63.2,24.53775338,0.627889307,133933.935,1.699432251,222.0394322
63.4,25.19404516,0.634121044,134311.5241,1.702264353,223.0620342
63.6,25.68910801,0.640427579,134151.0794,1.710542636,223.9293673
63.8,26.11601668,0.646802703,133876.9043,1.721870784,225.003724
64,26.55164096,0.653241146,133780.2941,1.728841974,225.7915141
64.2,26.40969199,0.659787872,134178.8524,1.731456135,226.8255495
64.4,26.68781616,0.666368531,134851.7385,1.73014908,227.738642
64.6,26.70083256,0.673035391,136436.0556,1.718820985,228.8336973
64.8,26.93821532,0.679752158,138661.342,1.70270026,230.3177433
65,27.03680603,0.686546915,140675.3848,1.68962939,231.766922
65.2,27.26087083,0.693400317,141289.5075,1.690500809,232.8085881
65.4,27.48160055,0.700322996,141035.8629,1.701828934,233.9123622
65.6,27.74137745,0.707312205,139832.7698,1.722742378,234.7371975
65.8,27.79338669,0.714387435,138825.3642,1.740170229,235.3920516
66,28.12793348,0.721512229,138136.4164,1.754983938,236.2463073
66.2,27.97216354,0.728745897,138736.3917,1.753676832,237.0951091
66.4,28.3540559,0.736011325,140230.3863,1.743655868,238.3089346
66.6,28.72928844,0.74335029,142100.5218,1.728842246,239.4966106
66.8,29.18844291,0.750756628,143686.2174,1.717514201,240.6755698
67,29.43567392,0.758253402,145001.5375,1.710978789,242.0462986
67.2,29.61225572,0.765831053,145256.612,1.714028684,242.9964373
67.4,29.8810632,0.773516267,145349.9092,1.720999855,244.1230939
67.6,30.14239146,0.781201973,145178.0067,1.729713811,244.9969618
67.8,30.37461538,0.789005879,145587.7731,1.732763713,245.9819695
68,30.85197956,0.796869572,146048.2663,1.73624934,247.1336893
68.2,31.01436586,0.804876552,146768.4637,1.735377968,248.1077998
68.4,31.06040205,0.812932823,147720.6349,1.733199494,249.3216221
68.6,31.24936841,0.821018202,149110.601,1.725356985,250.4787871
68.8,31.21975544,0.829242404,150475.0285,1.718385844,251.7056836
69,31.40370308,0.837532988,152182.0268,1.709236246,253.118906
69.2,31.38320502,0.845922466,153359.9133,1.70400789,254.2880539
69.4,31.72003485,0.854369052,155229.9773,1.693551221,255.8156863
69.6,31.95879007,0.862908066,156353.0718,1.689194288,257.0632892
69.8,31.50944196,0.87158505,156880.1278,1.690937022,258.3141523
70,32.23598212,0.88025981,157354.0739,1.69398698,259.7262917
70.2,32.72982109,0.889039471,157766.349,1.696601216,260.8453243
70.4,33.12641596,0.897914836,157856.2952,1.7040081,262.0929293
70.6,33.08836991,0.906912337,157835.8998,1.711414933,263.1171591
70.8,33.6212246,0.915956725,158377.9617,1.714029174,264.2895834
71,34.19810924,0.925088782,159241.3833,1.714464939,265.6810193
71.2,34.34450765,0.934345241,159912.1758,1.714464958,266.7673595
71.4,35.0044656,0.943655653,160883.3881,1.713157947,268.1544375
71.6,35.8056832,0.953048989,161497.52,1.714029435,269.2909074
71.8,35.76671807,0.962600468,161795.665,1.719693484,270.6768874
72,36.32773884,0.97220214,162052.8264,1.723614818,271.7240073
72.2,36.31616703,0.981943778,162067.8057,1.731021656,272.9312919
72.4,36.62203179,0.991759103,161842.0244,1.739299925,273.8509235
72.6,36.72344837,1.001688528,162071.482,1.743221206,274.8163172
72.8,36.76002904,1.011722521,163495.6994,1.737557158,276.2927357
73,37.03260522,1.021839427,164613.3463,1.733200228,277.4193927
73.2,37.18632847,1.032066876,166607.2802,1.722743542,278.9546519
73.4,37.40070031,1.042392542,168265.4161,1.71402964,280.2545543
73.6,37.49954297,1.052830732,169698.7591,1.707929898,281.6067598
73.8,37.75460196,1.063361987,169449.0271,1.718822341,282.9872958
74,38.39856457,1.073969526,169066.941,1.728407739,283.9744888
74.2,38.81273136,1.084701439,168172.8961,1.743657166,285.0858935
74.4,38.82591063,1.095571763,167694.4721,1.753242491,285.9401461
74.6,39.28491837,1.106517282,167597.2222,1.759342297,286.9055443
74.8,39.92382592,1.117559117,168883.251,1.754114015,288.343835
75,39.98515227,1.128755894,170118.0398,1.748449972,289.4737587
75.2,40.68385825,1.140016777,172383.0216,1.735814859,291.0722223
75.4,41.28531614,1.151398112,174462.1836,1.724051125,292.398283
75.6,41.61459458,1.162914647,176751.1634,1.711851662,293.8866913
75.8,41.78388198,1.174558978,179133.6274,1.700959267,295.7477431
76,42.22905169,1.186299406,181310.7855,1.689631214,297.280827
76.2,42.71076785,1.198154932,182990.2699,1.684402906,299.0449074
76.4,43.08983325,1.210137529,183736.196,1.684838649,300.3328299
76.6,43.33965487,1.222250148,184478.9524,1.685710069,301.7580398
76.8,43.832117,1.234466102,184963.5055,1.690938486,303.4872536
77,44.09394964,1.246822404,184695.1156,1.700088149,304.6367941
77.2,44.19080371,1.259315317,185058.1541,1.705752215,306.1873057
77.4,44.48168264,1.271918921,185575.9931,1.70836643,307.4120297
77.6,44.35661245,1.284680766,185849.4314,1.715773259,309.0355425
77.8,44.51448655,1.297549346,186039.377,1.720565941,310.1611097
78,45.11569301,1.310513576,186720.0855,1.723180193,311.7061819
78.2,46.20926232,1.32357063,186843.9163,1.728408683,312.8611821
78.4,46.47510785,1.336821782,186847.0063,1.734726317,314.1229527
78.6,46.56600103,1.350219333,186931.1986,1.740608235,315.5034866
78.8,47.08194317,1.363719222,187228.7273,1.743222477,316.5952815
79,47.38719837,1.377370846,187979.584,1.744093909,318.0760633
79.2,47.25406497,1.391192861,189270.6411,1.73930123,319.3454539
79.4,48.2556771,1.405067504,191466.5009,1.729716022,321.0507054
79.6,48.81349857,1.419115335,194169.6932,1.715773794,322.6938424
79.8,49.07212783,1.433327016,196976.0922,1.701831529,324.4415776
80,49.47948827,1.447670167,199321.1869,1.693117642,326.4290285
80.2,49.45510714,1.462190316,200641.8502,1.690067763,327.8836543
80.4,49.82128564,1.476826609,201729.967,1.690503504,329.688051
80.6,50.37608399,1.491595621,202164.381,1.693989143,331.0925644
80.8,51.08376778,1.506501496,202186.9237,1.702267466,332.8185145
81,51.3971053,1.521587151,203090.753,1.702267504,334.2775045
81.2,51.92191521,1.536808342,204154.9513,1.702703263,336.0949786
81.4,52.09392969,1.552209174,205120.9082,1.70183189,337.4929486
81.6,52.44542154,1.567750903,206318.7341,1.700089145,339.0369294
81.8,53.01129376,1.583431876,207805.0115,1.698346425,341.0047702
82,53.46993841,1.599278533,208849.0584,1.699217873,342.8494843
82.2,53.81636904,1.615293023,209025.3096,1.704446277,344.198425
82.4,53.64587498,1.631507693,209288.2628,1.710546015,345.8284754
82.6,54.39696459,1.647815056,209368.3872,1.716645861,347.1828713
82.8,54.75910726,1.664315929,209316.7339,1.724052753,348.5503352
83,54.97828686,1.680993347,209450.0506,1.731023931,350.075791
83.2,55.36530741,1.697825548,210059.7023,1.734509554,351.6862386
83.4,55.76061134,1.714826428,210521.701,1.737123783,352.9589068
83.6,56.18912924,1.73199551,211027.0866,1.739738018,354.288236
83.8,56.76055651,1.749326191,212224.0957,1.738866693,356.1013541
84,57.46990674,1.766820446,213006.1917,1.738866778,357.478631
84.2,58.28393853,1.784482708,214736.633,1.733202815,359.2656031
84.4,58.77550339,1.802346776,215914.2217,1.730588692,360.658131
84.6,59.1681474,1.820397986,217799.3881,1.723617587,362.3306864
84.8,59.45937719,1.838638274,220161.9997,1.715775075,364.5175354
85,59.77717078,1.85705968,222089.2899,1.709239658,366.1704778
85.2,60.56363466,1.875630667,224034.0832,1.70488278,368.2407464
85.4,61.11156394,1.894406165,225810.0706,1.699654479,369.9143951
85.6,61.40184456,1.913390048,227183.5895,1.697911726,371.6218171
85.8,62.17658419,1.932527871,228398.7339,1.699218908,373.7640004
86,62.38120796,1.95190189,228909.2843,1.7044473,375.6512075
86.2,62.93815666,1.971443991,229233.681,1.708804338,377.1210991
86.4,63.28482405,1.99119851,229331.5804,1.716211232,378.8873596
86.6,63.72037992,2.011144644,229507.8199,1.72143965,380.3605187
86.8,64.4093675,2.031272117,229468.6435,1.728410888,381.8827151
87,64.8656351,2.051619323,230223.3948,1.731025127,383.6860261
87.2,65.23128816,2.072177814,230938.412,1.732332263,385.0883594
87.4,66.10882175,2.092904171,231617.709,1.73538225,386.8535414
87.6,66.67967285,2.11386205,232678.1915,1.734946621,388.4443813
87.8,66.98040632,2.135051031,234601.4742,1.729282593,390.2084633
88,67.61019318,2.156427729,236202.987,1.726232788,392.1643232
88.2,68.35047271,2.178010835,237640.9336,1.724490087,394.1801127
88.4,68.88545375,2.199826591,238764.8952,1.72318306,395.7197405
88.6,69.51929237,2.22185393,239492.775,1.724925925,397.3171204
88.8,69.89381499,2.244122156,240003.4701,1.729282945,399.3143802
89,70.23090574,2.266617079,240737.3526,1.730590078,400.8311225
89.2,70.7782108,2.289322021,241473.8616,1.733204329,402.7499349
89.4,71.02049213,2.312278314,241740.8559,1.736689938,404.1816844
89.6,71.00594903,2.335484517,242804.2006,1.735382846,405.8128291
89.8,72.01768919,2.358845516,243899.2677,1.736254362,407.8732999
90,72.70279783,2.382466208,244347.2588,1.739304327,409.3726154
90.2,73.19174609,2.406338722,245488.0694,1.739740084,411.2761721
90.4,73.77871762,2.430443617,247453.3082,1.735818878,413.3083045
90.6,74.56925272,2.45477524,248008.1512,1.737561763,414.5003535
90.8,75.04146501,2.479375366,249731.3124,1.73581903,416.6490725
91,75.7754121,2.504202719,251939.7331,1.730590748,418.7433174
91.2,76.49020592,2.529280913,253813.7447,1.725798165,420.4932439
91.4,76.91493066,2.554633095,254684.1669,1.728412398,422.5275522
91.6,77.7555448,2.580208928,255525.4998,1.730155293,424.2404362
91.8,78.30151828,2.606064772,255079.3002,1.739305011,425.7659006
92,78.97085826,2.632171175,253524.0002,1.755425903,427.1943923
92.2,79.30691396,2.658565068,251162.2552,1.776121589,428.2845536
92.4,80.17270852,2.685183984,249853.2557,1.790281868,429.4226688
92.6,80.81699139,2.712087059,249197.58,1.799431601,430.5035749
92.8,81.39973513,2.739265287,250327.6694,1.798560279,432.1946611
93,82.04019203,2.766712142,252416.9917,1.790282102,433.7244864
93.2,82.75373568,2.794429255,256925.3668,1.768932997,436.0115919
93.4,83.36709606,2.822432604,260854.9676,1.750633762,437.9936045
93.6,83.76102004,2.85073383,265193.3861,1.731463112,440.2098792
93.8,84.69714545,2.879278164,269775.9151,1.714035308,443.0385259
94,85.17449712,2.908144216,272864.9856,1.703578616,445.1621855
94.2,85.51634492,2.937310645,276271.7371,1.693557604,447.8317368
94.4,86.19969922,2.966744171,278341.8636,1.690072102,450.0926909
94.6,86.97358875,2.996466536,280752.6098,1.685715214,452.7001439
94.8,87.91239021,3.026475039,283449.345,1.678308459,454.9643734
95,88.44269277,3.056816156,285461.6116,1.676565729,457.6502735
95.2,88.94884706,3.08746383,285885.2808,1.680922768,459.6115827
95.4,89.68016144,3.118402324,286112.617,1.687894022,462.0011137
95.6,90.53982052,3.149641894,285337.034,1.698786573,463.8055268
95.8,91.12560547,3.18121625,283797.7851,1.714036073,465.5009735
96,91.7080159,3.213108106,283187.2778,1.725364293,467.5211241
96.2,92.28954439,3.245320432,283197.0406,1.733206928,469.4682703
96.4,93.06880655,3.277841322,283874.8263,1.736256908,471.1473774
96.6,93.9647765,3.310680215,285777.9756,1.733207129,473.1086965
96.8,94.98327095,3.343839816,288009.677,1.730157364,475.6093749
97,95.91237681,3.377339317,289122.8143,1.730593174,477.4388527
97.2,96.60998738,3.41119288,290132.6219,1.732771749,479.6747495
97.4,97.42679673,3.445377586,291033.3504,1.734950339,481.9520538
97.6,98.41723683,3.479892449,291755.4415,1.736257552,483.8240282
97.8,98.90858825,3.514792151,292609.8225,1.73669331,485.758098
98,99.54614524,3.550031569,294671.9466,1.731900706,488.1280158
98.2,100.1711805,3.585625923,296490.8717,1.728633045,490.3492018
98.4,100.6095927,3.621591951,298286.005,1.726672456,492.6117891
98.6,101.5777293,3.657879251,299494.5877,1.727979667,494.6929678
98.8,102.0754448,3.69456671,300041.7181,1.734079504,497.0291057
99,102.9063449,3.731597592,300291.7074,1.739307985,498.7430823
99.2,104.1186291,3.768969892,301767.9553,1.739308131,501.0258468
99.4,104.9336213,3.806747601,302607.5059,1.740615324,502.8368003
99.6,105.8757008,3.844895172,303232.3119,1.743229629,504.7578079
99.8,106.7387715,3.883432143,304918.3898,1.741922638,507.3064274
100,107.5402845,3.922361016,305981.1836,1.741922735,509.1892958
100.2,108.0691572,3.961701647,305719.4004,1.750201072,511.2595699
100.4,108.5173573,4.001443534,306503.8231,1.75237962,512.997512
100.6,109.6901526,4.041529721,308696.8473,1.748458475,515.0874133
100.8,110.3792241,4.082055443,310082.0089,1.750637052,517.4682313
101,111.151334,4.12298213,311205.4749,1.753251338,519.691057
101.2,111.8701926,4.164323835,312419.0799,1.753251426,521.4649631
101.4,113.3119821,4.206026159,313364.4078,1.755865792,523.6333251
101.6,113.8495434,4.248216184,313134.5636,1.762837038,525.3494763
101.8,114.5499194,4.290817692,314571.9394,1.761530028,527.340214
102,115.559371,4.33382369,316797.3438,1.757608862,529.7548194
102.2,116.4790027,4.377268548,319139.4095,1.75194489,531.7967754
102.4,117.1018869,4.421172381,322714.99,1.742359592,534.5567769
102.6,118.4310775,4.465463753,326494.3822,1.731031582,537.0901567
102.8,119.4194747,4.510226035,329551.2714,1.72318912,539.5690501
103,120.1643083,4.555456464,333092.3957,1.714475231,542.5785769
103.2,121.2381581,4.601116465,335639.0157,1.710554068,545.4889569
103.4,122.179801,4.647245419,337298.8466,1.709682782,547.8240215
103.6,122.8396133,4.694093925,338250.6864,1.712297055,550.08716
103.8,123.6531287,4.74116876,340513.2466,1.711861453,553.1642475
104,124.8164713,4.788450827,340948.4086,1.717089979,555.2421674
104.2,125.603243,4.836475785,341605.0837,1.72318986,557.8834089
104.4,126.334259,4.884987492,342179.1843,1.72711124,559.9144652
104.6,127.4466411,4.933957637,343738.8131,1.727111373,562.1983215
104.8,128.3088046,4.9834387,343363.7113,1.737132557,564.7622029
105,129.1850166,5.033416003,344689.2654,1.737132663,566.8891499
105.2,130.4193236,5.083868044,345913.2421,1.738439909,569.4475955
105.4,131.9493975,5.134804738,347278.9705,1.739311491,572.0779596
105.6,132.6915718,5.186313082,348055.5157,1.741490078,574.2833543
105.8,133.5192602,5.238332362,348868.3133,1.743232975,576.4146608
106,134.6410509,5.290851959,349482.7977,1.747590104,578.9066361
106.2,135.4270209,5.343924813,349847.1329,1.751947194,580.8243744
106.4,136.6059843,5.397501153,350545.4762,1.756304331,583.2237356
106.6,137.7898485,5.451615264,351947.1563,1.756740174,585.4476686
106.8,138.7907993,5.506287139,355460.0049,1.748026307,587.964702
107,139.6736561,5.561517206,359906.6206,1.736698227,591.0428826
107.2,140.9736032,5.617270506,365416.8907,1.721448899,594.3978386
107.4,141.931076,5.673609095,369274.5469,1.712299322,597.1894541
107.6,142.9441382,5.730509023,371443.6204,1.710556644,599.8982607
107.8,143.8241445,5.787990296,371409.9879,1.718835042,602.8282538
108,144.8860552,5.84603502,370730.7025,1.727549162,604.8941919
108.2,145.8539666,5.904669724,369178.3941,1.741491668,607.3218783
108.4,146.8699844,5.963889615,369282.5085,1.746720188,609.3300659
108.6,148.1385417,6.02368541,370554.0826,1.747591742,611.658608
108.8,149.2648969,6.084092767,372589.1243,1.747156181,614.5363088
109,150.4559764,6.145102,375267.428,1.743670722,617.4804785
109.2,151.5962651,6.206731128,377478.6312,1.740185264,619.8210026
109.4,152.7534915,6.268978173,378453.2406,1.743235303,622.6365982
109.6,153.9945531,6.331844364,379097.1138,1.746285356,624.96623
109.8,155.2579522,6.395340439,379200.1425,1.751078204,627.1705565
110,156.2420228,6.45949565,379389.3806,1.756742426,629.7998241
110.2,157.7528662,6.524255519,379293.3625,1.762406711,631.7404723
110.4,158.6773122,6.589710552,381167.5102,1.761971125,634.441653
110.6,159.8883603,6.655801468,383329.1671,1.759357072,636.8137796
110.8,160.7751998,6.722581098,387400.8639,1.750861024,639.8391198
111,162.0296651,6.790003812,390149.6824,1.747157726,642.6105917
111.2,163.580702,6.858081435,393541.4695,1.741493809,645.7149502
111.4,164.6442288,6.926880187,396177.9227,1.737136936,648.2047499
111.6,166.0529405,6.996343894,398275.6621,1.735394306,650.8994116
111.8,167.6310724,7.066492669,401271.3297,1.731473187,654.3175799
112,168.8068718,7.137376808,405520.5104,1.72319502,657.7847695
112.2,169.9779875,7.208973559,408051.2574,1.720145262,660.5829379
112.4,171.2499595,7.281282039,408807.9494,1.724938114,663.5794172
112.6,172.8139248,7.354294757,410020.5886,1.727116803,666.1967208
112.8,173.8326151,7.428082427,410409.3145,1.732345332,668.7246604
113,175.2068703,7.502584509,410532.6925,1.739316706,671.6056459
113.2,176.6071843,7.577833296,413047.1237,1.737138371,674.5122381
113.4,178.2936697,7.653816321,418131.3819,1.725810356,677.8644939
113.6,179.4893078,7.730600139,423436.7682,1.71404658,681.2641311
113.8,180.9889822,7.808132373,428892.9942,1.70402564,685.4156129
114,182.4881174,7.886443633,432473.4453,1.698797407,688.5570233
114.2,183.7806155,7.96555739,435620.7432,1.697054756,692.4393644
114.4,185.2042909,8.045456031,436820.3445,1.700104829,695.2647857
114.6,186.7786717,8.126146128,435702.5667,1.710997537,697.9354845
114.8,188.2827013,8.207652336,435201.9318,1.721018838,701.2577717
115,189.7570992,8.289979697,434600.1437,1.728861631,703.6865761
115.2,190.8116928,8.373166012,433438.8398,1.739754284,706.6438289
115.4,192.5779357,8.457133902,432004.4587,1.750647024,709.3036412
115.6,194.0814373,8.54196556,434260.7186,1.747161597,711.4731165
115.8,195.4597327,8.627659159,438638.3276,1.740190545,715.3848838
116,196.9733502,8.714203453,442466.6401,1.734526611,718.9425323
116.2,198.5022039,8.801616118,446296.7105,1.727991275,721.9858823
116.4,200.3197031,8.889885175,451712.2565,1.717970361,725.9292674
116.6,201.4232019,8.979093332,453240.9117,1.719277597,729.0140103
116.8,202.9188077,9.06916544,454267.1896,1.721891983,731.9898044
117,204.6045771,9.160128175,457227.281,1.719713676,735.6738566
117.2,206.2594532,9.252007077,461658.9365,1.713614052,739.6019836
117.4,207.7097477,9.344824703,465301.3585,1.709257208,742.9122879
117.6,209.385105,9.438557793,470440.725,1.701414777,746.7085731
117.8,210.8849641,9.533245991,476289.6005,1.693572324,751.5323563
118,212.199351,9.628899467,479138.4341,1.691829672,754.9156673
118.2,214.0354763,9.725474318,479937.9236,1.696186904,758.0952358
118.4,215.880589,9.823018852,480760.115,1.701415541,761.8283284
118.6,217.4621075,9.921563417,480407.1806,1.708822659,764.9283488
118.8,218.982803,10.0211027,480605.7014,1.715358367,768.1623886
119,220.4800707,10.12164379,480909.9236,1.722329776,771.7254905
119.2,222.3968518,10.22316322,483555.2741,1.722330004,775.5828095
119.4,224.1397842,10.32571593,485977.316,1.721894509,778.7536602
119.6,225.8401701,10.42930206,488274.0453,1.722766116,782.0465478
119.8,227.566153,10.53392686,491968.3449,1.72058781,786.1740835
120,229.0517991,10.63962126,494935.7226,1.718845179,789.4277386
120.2,230.9627679,10.74634522,495754.4848,1.724945237,793.0747629
120.4,232.2153845,10.85419147,495781.3339,1.732352326,796.4831351
120.6,234.083541,10.9636223,496290.1104,1.737580978,799.75206
120.8,235.5943517,11.07307864,495826.4824,1.744552398,802.4009803
121,237.5918881,11.18415112,494907.1467,1.75370239,805.5740258
121.2,239.34326,11.29635857,495548.6447,1.756316818,808.1880877
121.4,241.203228,11.410257,499284.7732,1.751524315,812.0661125
121.6,243.2392846,11.52471974,503733.5932,1.743681914,815.534447
121.764,244.978415,11.61885101,507685.1555,1.73671088,818.4165524
122,246.9061613,11.62102737,516964.274,1.719718702,824.2057744
122.2,248.1742754,11.62093084,521514.2393,1.714054716,827.8266277
122.4,249.0293633,11.62086555,525647.8137,1.7114406,832.1252053
122.6,249.8495476,11.6208029,527281.3003,1.714490616,835.5401018
122.8,250.304906,11.62076784,527840.5401,1.722333321,839.7002857
123,250.9480791,11.62071857,527417.4986,1.730176049,842.5899818
123.2,251.2771196,11.62069306,529763.3048,1.7319189,846.6542714
123.4,251.6169636,11.62066673,531189.2232,1.734533159,849.7248306
123.6,252.2468402,11.62061847,533148.4521,1.736276046,853.102675
123.8,252.283355,11.62061507,536293.7003,1.736276051,857.3554584
124,252.9780526,11.62056191,538764.4045,1.735840431,860.6232523
124.2,253.2929655,11.62053747,537155.3329,1.747604449,864.0076216
124.4,253.4832225,11.62052245,536308.4263,1.755447125,866.7458421
124.6,253.5488237,11.62051686,534564,1.765468301,869.3347805
124.8,254.0673411,11.62047701,531663.6808,1.779410859,872.4380347
125,253.8046819,11.62049624,528098.9833,1.793353323,874.3786368
125.2,254.0905084,11.620474,526467.8219,1.802938824,876.9664908
125.4,254.6314639,11.62043246,524652.781,1.813395762,879.276507
125.6,254.6413854,11.62043108,525608.3582,1.815574279,881.6867435
125.8,255.0709817,11.62039796,526682.1909,1.817752848,884.0239962
126,255.1648382,11.62039023,531661.3137,1.809910207,887.4159835
126.2,255.1332079,11.62039199,537559.6593,1.79945333,891.0956226
126.4,255.5993699,11.62035611,541170.6559,1.794224954,894.0463314
126.6,255.5685705,11.62035781,541208.3719,1.799017685,896.6003959
126.8,255.7496862,11.62034348,540661.5133,1.805771106,899.3217269
127,256.0384213,11.62032101,538135.275,1.817317271,901.4187119
127.2,256.1975144,11.62030835,534192.6024,1.833438306,903.3484338
127.4,256.1500943,11.62031131,532677.4489,1.841716657,904.9654257
127.6,256.5252576,11.62028231,534927.8222,1.839538191,907.244925
127.8,256.5131566,11.62028259,539355.3314,1.832566944,910.5595451
128,256.817266,11.62025896,541834.6563,1.82995276,912.9632583
128.2,256.6913127,11.62026785,543833.2579,1.829517045,915.7853654
128.4,256.610651,11.62027332,542784.2551,1.836488286,917.6398934
128.6,256.9230708,11.62024906,538807.6641,1.851737928,918.996483
128.8,257.1943542,11.62022792,533786.4539,1.870037497,920.1111755
129,257.1128615,11.62023345,529714.1433,1.885287091,921.2269419
129.2,257.1713988,11.62022839,528017.0641,1.892694051,922.3067584
129.4,257.1152528,11.620232,529383.6872,1.891386935,924.1057177
129.6,257.5390319,11.62019933,530973.439,1.888772773,925.8218846
129.8,257.5252688,11.62019973,533258.4743,1.884415741,927.728716
130,257.7475209,11.6201823,535587.7618,1.880930146,929.8763673
130.2,257.7778029,11.62017937,536003.055,1.882672964,931.3909389
130.4,257.8645956,11.62017218,534408.5888,1.890951334,932.812895
130.6,257.9858765,11.62016238,533135.8917,1.8979226,933.8905339
130.8,258.2825066,11.62013931,530276.2012,1.910122326,934.881012
131,258.2130639,11.62014393,527984.3414,1.919272083,935.4835691
131.2,258.3758967,11.62013099,527385.9363,1.923629136,936.5154442
131.4,258.5009172,11.6201209,526534.943,1.927986184,937.291258
131.6,258.4069589,11.62012737,524411.1965,1.936264532,937.8273486
131.77,258.6013788,11.62011214,524581.9884,1.937135965,938.6325906
132.6,258.5455788,11.45747148,1.7977E+308,1.722116481,0
132.8,258.0819917,11.34133287,1.7977E+308,1.480519068,0
133,258.2649531,11.22514537,1.7977E+308,1.149820443,0
133.2,257.843749,11.10900356,1.7977E+308,0.748537879,0
133.4,257.5093885,10.99285517,1.7977E+308,0.376011743,0
133.6,257.5531508,10.8766782,1.7977E+308,0.173409819,0
133.8,257.169759,10.76053353,1.7977E+308,0.074940925,0
134,257.1104725,10.64436434,1.7977E+308,0.060562724,0
134.2,256.7515963,10.52821781,1.7977E+308,0.018299528,0
134.4,256.3877339,10.41207166,1.7977E+308,0.0287564,0
134.6,256.1958967,10.2959125,1.7977E+308,0.035727648,0
134.8,256.0431182,10.17975039,1.7977E+308,0.030063508,0
135,255.9701196,10.06358224,1.7977E+308,0.021349448,0
135.2,255.6145676,9.947435464,1.7977E+308,0.014378199,0
135.4,255.7468356,9.831251797,1.7977E+308,0.012635387,0
135.6,254.9857366,9.715135683,1.7977E+308,0.022656555,0
135.8,254.9318518,9.598966092,1.7977E+308,0.024399367,0
136,254.9078845,9.482794238,1.7977E+308,0.021349446,0
136.2,254.5972086,9.366644065,1.7977E+308,0.018299525,0
136.4,254.353847,9.250488801,1.7977E+308,0.014378198,0
136.6,254.0789058,9.134335926,1.7977E+308,0.010892574,0
136.8,253.6518846,9.01819455,1.7977E+308,0.013506791,0
137,253.4833164,8.902033631,1.7977E+308,0.023963662,0
137.2,253.2391238,8.78587843,1.7977E+308,0.035291937,0
137.4,253.1170938,8.669713992,1.7977E+308,0.044005996,0
137.6,252.9410463,8.553553639,1.7977E+308,0.045748807,0
137.8,252.9104307,8.437382288,1.7977E+308,0.042263183,0
138,252.410278,8.321246442,1.7977E+308,0.03747045,0
138.2,252.3555622,8.205076914,1.7977E+308,0.035291935,0
138.4,251.9310341,8.08893535,1.7977E+308,0.03311342,0
138.6,251.5106612,7.972793471,1.7977E+308,0.03180631,0
138.8,251.3977727,7.856628342,1.7977E+308,0.02875639,0
139,251.0746314,7.740479111,1.7977E+308,0.023092252,0
139.2,251.043277,7.623726951,1.7977E+308,0.013506789,0
139.4,250.6668569,7.508162614,1.7977E+308,0.002614217,0
139.6,250.3786192,7.392010744,1.7977E+308,0.006535543,0
139.8,250.1892751,7.275851396,1.7977E+308,0.00609984,0
140,249.9176582,7.159698269,1.7977E+308,0.003921325,0
140.2,249.8338561,7.04353094,1.7977E+308,0.003921325,0
140.4,249.3669451,6.927392581,1.7977E+308,0.011763976,0
140.6,249.2557187,6.811227326,1.7977E+308,0.019170924,0
140.8,249.0996162,6.695065464,1.7977E+308,0.026577871,0
141,248.6534812,6.578925534,1.7977E+308,0.03442052,0
141.2,248.4367129,6.462768259,1.7977E+308,0.040520359,0
141.4,248.3819971,6.346598731,1.7977E+308,0.0470559,0
141.6,248.0372488,6.230451134,1.7977E+308,0.048363007,0
141.8,247.6900075,6.114303726,1.7977E+308,0.045313087,0
142,247.6568987,5.998132564,1.7977E+308,0.042263167,0
142.2,247.1043908,5.882000677,1.7977E+308,0.040520355,0
142.4,247.1543859,5.765823231,1.7977E+308,0.035291922,0
142.6,246.8112997,5.649675508,1.7977E+308,0.031370597,0
142.8,246.5072724,5.533524832,1.7977E+308,0.030063488,0
143,246.4143289,5.417358194,1.7977E+308,0.030934893,0
143.2,246.1036532,5.301208021,1.7977E+308,0.03049919,0
143.4,245.974144,5.185044148,1.7977E+308,0.029192081,0
143.6,245.6717788,5.068893346,1.7977E+308,0.020913729,0
143.8,245.4915762,4.952733307,1.7977E+308,0.007406946,0
144,245.2170507,4.8365804,1.7977E+308,0.014378189,0
144.2,244.8781198,4.720432363,1.7977E+308,0.02439935,0
144.4,244.4452816,4.604291427,1.7977E+308,0.034856213,0
144.6,244.4765783,4.488115395,1.7977E+308,0.043134563,0
144.8,244.0487263,4.371974082,1.7977E+308,0.04618448,0
145,243.6341709,4.255831764,1.7977E+308,0.047055884,0
145.2,243.2669847,4.139685863,1.7977E+308,0.051412909,0
145.4,243.1998034,4.023517278,1.7977E+308,0.055987787,0
145.6,242.9298487,3.907364025,1.7977E+308,0.056205637,0
145.8,242.5672333,3.791217779,1.7977E+308,0.052284312,0
146,242.2042023,3.675071565,1.7977E+308,0.04879869,0
146.2,242.213892,3.558897166,1.7977E+308,0.045313069,0
146.4,241.7847935,3.442755948,1.7977E+308,0.040956042,0
146.6,241.5954496,3.326596599,1.7977E+308,0.040520339,0
146.8,241.2606739,3.210448248,1.7977E+308,0.038341825,0
147,240.9425191,3.09429864,1.7977E+308,0.035291907,0
147.2,240.5038637,2.978158144,1.7977E+308,0.032241988,0
147.4,240.5193707,2.861983306,1.7977E+308,0.025270747,0
147.6,240.0109081,2.745848089,1.7977E+308,0.01721025,0
147.8,239.7658846,2.629692951,1.7977E+308,0.01045686,0
148,239.3750139,2.513548841,1.7977E+308,0.004792728,0
148.2,239.042316,2.397400333,1.7977E+308,0.00348562,0
148.4,238.579976,2.281261628,1.7977E+308,0.013506777,0
148.6,238.4749825,2.165095902,1.7977E+308,0.021349421,0
148.8,238.0841119,2.048951792,1.7977E+308,0.030499172,0
149,237.6483652,1.932811076,1.7977E+308,0.033549089,0
149.2,237.2134496,1.816670297,1.7977E+308,0.029627766,0
149.4,237.0565162,1.700508498,1.7977E+308,0.02875636,0
149.6,236.8547067,1.584350093,1.7977E+308,0.022656526,0
149.8,236.132252,1.468231056,1.7977E+308,0.01089256,0
150,235.6715742,1.352092226,1.7977E+308,0.006099833,0
150.2,235.3712868,1.235941267,1.7977E+308,0.014378179,0
150.324,235.0667439,1.163936622,1.7977E+308,0.018735202,0
225.6,234.5943677,1.009805107,1.7977E+308,0.003049917,0
225.8,234.1980953,0.893661406,1.7977E+308,0.010456859,0
226,233.5051424,0.777540139,1.7977E+308,0.017428097,0
226.2,233.1113632,0.661396249,1.7977E+308,0.017863799,0
226.4,232.7483324,0.545250035,1.7977E+308,0.017863798,0
226.6,232.4218673,0.429101055,1.7977E+308,0.0182995,0
226.8,231.849415,0.312970676,1.7977E+308,0.021349416,0
227,231.2088176,0.19684545,1.7977E+308,0.027449248,0
227.2,230.543289,0.080722109,1.7977E+308,0.030934865,0
227.336,229.6003767,0.001214451,1.7977E+308,0.028320649,0
,,,,,