File: TestGB_10.csv
Time On Sample,Displacement Into Surface,Load On Sample,Harmonic Contact Stiffness,Harmonic Displacement,Harmonic Load
0,0,0,-445.8926897,0.466191941,2.165035925
0.2,0.267330331,0.000737977,2575.383039,0.313699254,2.233680778
0.4,0.567901502,0.001473439,6989.137289,0.261851745,2.294698434
0.6,0.598390904,0.002229329,9772.60369,0.228739045,2.373149667
0.8,0.472648391,0.002997036,12676.85948,0.19126941,2.486468095
1,0.731668524,0.003735641,14826.75014,0.17035613,2.604144972
1.192,0.711176824,0.00446506,16379.30648,0.160770874,2.713105011
1.4,0.898187443,0.005236521,17852.90272,0.154235475,2.82315468
1.6,0.944466701,0.005988341,19718.53862,0.151621315,3.027999567
1.8,0.913461019,0.006746007,21473.75644,0.153364088,3.291682866
2,1.058631759,0.007490347,22698.83876,0.158156718,3.553186994
2.2,1.119038373,0.008241098,24340.58789,0.160770879,3.821228713
2.4,1.219333988,0.008988833,25060.29295,0.167741975,4.072926435
2.6,1.244006705,0.009742286,25971.02069,0.177327232,4.447748995
2.8,1.286961881,0.010494357,27640.22087,0.183862634,4.910829182
3,1.14376838,0.011260507,29908.85346,0.185605406,5.37717815
3.2,1.45348126,0.011992401,31212.05427,0.192576505,5.826093616
3.4,1.421229046,0.01275016,32754.06718,0.197804827,6.286994602
3.6,1.163770172,0.013524952,35140.42615,0.203904532,6.960367608
3.8,1.403261788,0.014262157,36055.1023,0.217846726,7.633740761
4,1.594138685,0.015003039,36261.82394,0.23571016,8.312561928
4.2,1.657453875,0.015753569,36596.75373,0.252266513,8.987024652
4.4,1.44985625,0.01652459,35778.42047,0.27622965,9.640784835
4.6,1.573835966,0.017270531,35961.09806,0.296271551,10.41440123
4.8,1.541583751,0.018028289,36389.37088,0.316749143,11.29806718
5,1.699635927,0.018767871,36901.05109,0.336791046,12.21660048
5.2,1.416830308,0.019548362,36949.5061,0.360318487,13.09263908
5.4,1.995793977,0.02025989,37319.87252,0.380360401,13.96431986
5.6,1.543460687,0.02104942,37651.40424,0.402580756,14.91554077
5.8,1.529075423,0.021805827,37870.32243,0.428722364,15.96482599
6,1.778123788,0.022542308,37623.20515,0.453121205,16.76459297
6.2,1.726342582,0.023301543,37191.06267,0.485362521,17.76157739
6.4,1.928022759,0.024041607,36146.683,0.525446327,18.68664838
6.6,1.837183568,0.024803795,35486.6492,0.560301802,19.57249346
6.8,1.79288155,0.025562464,34813.42746,0.6003856,20.60652436
7,1.81838529,0.026315852,34267.31259,0.639598014,21.5860752
7.2,1.622006443,0.027086023,33576.00732,0.682295965,22.5471026
7.4,1.902633608,0.027820116,32968.88946,0.724122553,23.47653219
7.6,1.979660646,0.028569608,32119.97185,0.770741759,24.30680781
7.8,1.551426959,0.029357315,31047.77592,0.827817581,25.17521893
8,1.883577421,0.030087511,30230.2658,0.872694028,25.82244204
8.2,1.557559308,0.030867487,29411.44228,0.925848612,26.639642
8.4,1.940402048,0.031593848,28584.92434,0.979874628,27.40454205
8.6,2.186126341,0.03233058,28071.51508,1.022572607,28.11496195
8.8,2.092794086,0.033092956,27611.05401,1.059606548,28.6902709
9,2.234640761,0.033837543,26890.18194,1.112761164,29.39633225
9.2,2.477040976,0.034574526,26431.57099,1.150666518,29.92260962
9.4,2.086203214,0.035359403,25965.05696,1.195542917,30.57201104
9.6,2.470708013,0.036085638,25478.6448,1.239112299,31.09719908
9.8,2.230285045,0.036859138,25187.48331,1.270917904,31.5482934
10,2.48930568,0.037594863,25225.41144,1.292702603,32.16173889
10.2,2.395142402,0.038357301,25207.73578,1.311437416,32.62046053
10.4,2.621753222,0.039095477,25333.82883,1.327122403,33.20230765
10.6,2.773572156,0.039839309,26051.19157,1.314051613,33.81357374
10.8,2.711818695,0.040599295,27172.63401,1.287909999,34.53597892
11,2.732336313,0.041353058,28064.29471,1.270046568,35.1178256
11.2,2.56919769,0.042124494,29537.00203,1.237369542,35.90233774
11.4,2.683621281,0.042867373,30601.90755,1.217763345,36.51251427
11.6,2.549568993,0.043632827,31430.05462,1.213842094,37.29811611
11.8,2.368979532,0.044401801,31757.18577,1.220377482,37.85381207
12,2.874812809,0.045122639,31703.61789,1.242162201,38.46398926
12.2,2.817214453,0.04588231,31320.23072,1.274839211,39.03167109
12.4,2.800336727,0.046635119,30984.75839,1.300980821,39.45770488
12.6,3.008665094,0.047374677,30537.62565,1.333657855,39.92078554
12.8,3.278489021,0.048109583,30105.4249,1.368513363,40.42527114
13,2.95080883,0.04888968,30039.93447,1.387683848,40.92757631
13.2,3.362737354,0.049613838,30074.35705,1.399447614,41.33508786
13.4,3.251953649,0.050377531,30319.21867,1.406854394,41.86572318
13.6,3.435351393,0.051118973,30911.5398,1.398576236,42.3996279
13.8,3.155039396,0.051895487,31670.9592,1.385505405,43.0163413
14,3.632618591,0.052614679,32444.64919,1.372434645,43.63196661
14.2,3.505214464,0.053379628,33183.93369,1.358492441,44.15170581
14.4,3.309666611,0.054149731,33951.12376,1.346728699,44.81636188
14.6,3.274505821,0.054907704,34261.19615,1.349778552,45.37314767
14.8,3.582556725,0.055639717,34297.79389,1.364592162,45.96153276
15,3.33049944,0.056414094,34137.81856,1.382891268,46.37884925
15.2,3.483980428,0.057157799,33714.28386,1.413389831,46.84628816
15.4,3.689815745,0.057897543,33318.47584,1.444759788,47.30501059
15.6,3.611441859,0.058658784,33139.61784,1.466108765,47.72014827
15.8,3.389301331,0.059430898,33178.98359,1.476565389,48.10041833
16,3.388212404,0.060186293,33332.42193,1.484407874,48.59182842
16.2,3.555820752,0.060928929,33608.73601,1.48658636,49.08650734
16.4,3.445037045,0.06169262,33973.52414,1.485279269,49.60515708
16.6,3.449765265,0.062447575,34105.0099,1.491378981,50.04208695
16.8,3.599091151,0.063191593,34112.44317,1.501835643,50.42453702
17,3.567254445,0.063949313,34146.47502,1.514470753,50.89306539
17.2,3.655915793,0.064697919,34123.10202,1.529284347,51.31692034
17.4,3.919091571,0.065433325,34068.85062,1.542355183,51.65578682
17.6,3.87645159,0.066191862,34155.33011,1.551504745,52.04695325
17.8,4.174530258,0.066924628,34431.55593,1.55324755,52.49477987
18,3.962361973,0.067695987,35147.13773,1.537998256,53.03413184
18.2,3.766814112,0.068466089,35930.1096,1.517956332,53.49612204
18.4,4.140515699,0.069193135,37187.74917,1.484407972,54.12591221
18.6,4.259093813,0.069939477,38527.98736,1.449988191,54.77422495
18.8,3.810084513,0.070728749,39992.2204,1.415568355,55.51079382
19,4.24860575,0.071450892,40685.97698,1.405111756,56.07738738
19.2,3.991562323,0.072225644,41210.30443,1.402497568,56.71044469
19.4,4.027038325,0.072978272,41149.10399,1.418618237,57.26614116
19.6,4.130658059,0.073725745,40959.58754,1.43866015,57.75864097
19.8,4.197712864,0.074475984,40774.15022,1.460444836,58.30344136
20,3.743717438,0.075265633,40764.60099,1.473079905,58.72729471
20.2,4.291102441,0.075979542,40494.79707,1.497043112,59.22524403
20.4,4.024086759,0.076755049,40300.4632,1.517084986,59.69921944
20.6,4.608036704,0.077466192,40113.24749,1.534948485,60.12416544
20.8,4.479801544,0.078231201,39819.96986,1.554990377,60.46085185
21,4.467909344,0.07898741,39488.12833,1.578082137,60.87163116
21.2,4.390366341,0.079749425,39790.43612,1.577646436,61.35214495
21.4,4.209775684,0.080525743,40358.18707,1.566318385,61.8021495
21.6,4.609236578,0.081265729,41242.53378,1.546276525,62.3720119
21.8,4.682520454,0.082038089,42314.7119,1.521877693,63.0442957
22,4.710512431,0.082821717,43137.9718,1.504449954,63.59018591
22.2,4.48462619,0.083632462,43642.79799,1.500092997,64.21888477
22.4,4.535884229,0.084430246,43648.01478,1.510985343,64.76586442
22.6,4.584647942,0.085236157,43509.64917,1.525798931,65.23875142
22.8,4.677454479,0.086046906,43357.89994,1.540612524,65.64408322
23,4.663889023,0.086873783,43235.42645,1.55716888,66.11696977
23.2,4.770820294,0.087699986,43272.05751,1.56893262,66.6072906
23.4,4.493818482,0.088563467,43337.60816,1.576775076,66.98973959
23.6,4.461966518,0.089417166,43568.21645,1.583310478,67.55088387
23.8,4.505736148,0.090273513,43836.93629,1.584181872,67.98018674
24,4.798810763,0.09111957,44436.01983,1.575903727,68.5522282
24.2,4.703797107,0.092003735,45131.4509,1.564575684,69.15041876
24.4,4.788282632,0.092883066,45718.5969,1.554554742,69.62766406
24.6,4.765565038,0.093779241,46340.36166,1.545405176,70.19861485
24.8,4.931487821,0.094670137,47010.13518,1.536691323,70.84256942
25,4.903781217,0.095584826,47344.34253,1.538434096,71.44402908
25.2,4.945047918,0.096503441,47514.70831,1.542791038,71.90275105
25.4,5.164151672,0.097417916,47578.17906,1.552812015,72.46607531
25.6,5.022590775,0.098368835,47616.07708,1.561961567,72.94767835
25.8,5.012329712,0.099319346,47422.70796,1.579389312,73.45107417
26,5.159130143,0.100267482,47284.65537,1.592895831,73.84551026
26.2,5.251912684,0.101229227,47273.57005,1.604223876,74.32711395
26.4,5.409513329,0.102195823,47321.40195,1.613809155,74.82615173
26.6,5.296199506,0.103192695,47512.15925,1.617294693,75.27942525
26.8,5.31418545,0.104189602,48136.30477,1.609452211,75.87325773
27,5.696988137,0.105168794,48578.76053,1.604659625,76.3341604
27.2,5.572035251,0.10619652,48977.84012,1.603352532,76.89748363
27.4,5.243480533,0.107249933,49452.76755,1.599866948,77.46080603
27.6,5.352041323,0.108280664,49748.32442,1.601174042,77.97509802
27.8,5.505475612,0.109318364,49852.81345,1.608145159,78.4970175
28,5.181902056,0.110402645,50089.24081,1.609452205,78.95029019
28.2,5.489902916,0.111449876,50412.82678,1.610323628,79.49618139
28.4,5.502889551,0.112530086,50602.80514,1.613373486,79.950545
28.6,5.580694124,0.113616204,50924.51911,1.615551965,80.57052821
28.8,5.744923173,0.114706681,51286.58514,1.61380921,81.04559473
29,5.767875973,0.115824456,51558.59483,1.616423376,81.61654564
29.2,5.758418955,0.116944613,51795.50899,1.617294763,82.06110277
29.4,5.919318606,0.118068787,52163.50224,1.616423395,82.63641264
29.6,5.760273271,0.119228527,52375.29348,1.619037541,83.13218046
29.8,6.143051032,0.120364642,52433.0765,1.627315764,83.66499692
30,6.05380873,0.121536401,52302.53274,1.641257952,84.13788348
30.2,5.916364395,0.122729426,52155.05639,1.653893054,84.49527199
30.4,5.980856319,0.123919169,52132.83828,1.664785404,84.95726317
30.6,6.24396045,0.125105688,52164.692,1.672627921,85.36913311
30.8,6.218698293,0.126326031,52257.37789,1.679599018,85.84855747
31,6.088725486,0.127566689,52678.67848,1.675677762,86.36284873
31.2,5.986174417,0.128817631,52932.90599,1.674806365,86.78343435
31.4,6.115476285,0.130063594,53126.73664,1.676549156,87.2704863
31.6,6.282172138,0.13131914,53369.12873,1.676113483,87.73792579
31.8,6.307592369,0.132597998,53872.65807,1.669578082,88.31105619
32,6.924697723,0.133844949,54155.56551,1.668271073,88.73818217
32.2,7.570055842,0.135102267,54610.68811,1.664349905,89.28189563
32.4,7.651979454,0.136415062,55028.42771,1.662171448,89.82124867
32.6,7.740549157,0.137740447,55635.72807,1.654764667,90.37803519
32.8,7.822468574,0.139079644,56440.77737,1.642565254,91.01109387
33,7.807156365,0.140439566,57409.62934,1.625137506,91.58531339
33.2,8.094333756,0.141790343,59161.94565,1.591589123,92.41777
33.4,7.751594753,0.143202528,61220.70215,1.553248042,93.32322655
33.6,8.064529415,0.144578981,63037.66475,1.522749517,94.2003572
33.8,8.29435973,0.14597564,64743.9291,1.498350694,95.17555095
34,8.171834725,0.1474131,65925.77318,1.483537097,95.9469877
34.2,8.37672987,0.148840153,66943.76092,1.475258938,96.88186642
34.4,8.414587418,0.150294272,67629.32697,1.473516168,97.7644432
34.6,8.460752866,0.151762332,68252.76582,1.472644788,98.60561586
34.8,8.517719247,0.153244326,68862.08924,1.473080493,99.52850792
35,8.489088065,0.154747628,68817.36317,1.48397283,100.2007918
35.2,8.293419175,0.156278683,68588.03471,1.500964868,101.0038268
35.4,8.551485546,0.157790719,68395.72946,1.514907093,101.6543199
35.6,8.78960499,0.159319468,68178.44943,1.532770567,102.5227331
35.8,8.81747357,0.160879487,68037.56823,1.545405688,103.1263722
36,8.787999171,0.162459567,68450.4974,1.549326931,103.9708129
36.2,8.77763574,0.164054091,69199.10679,1.543662914,104.7052039
36.4,8.946770412,0.165650943,70086.97583,1.537563221,105.6128425
36.6,9.06354818,0.167267827,70942.34135,1.531463516,106.4649111
36.8,9.11882776,0.16890573,72010.87513,1.522313961,107.4368355
37,8.972166499,0.170575431,72585.20323,1.522313944,108.356458
37.2,9.014144453,0.172247566,72659.49124,1.53015644,109.0821326
37.4,8.970524528,0.173942966,72677.27918,1.541048781,109.940738
37.6,8.772331896,0.175667158,72659.27352,1.551505408,110.6958305
37.8,9.293801151,0.177353866,72468.13728,1.564576275,111.3594001
38,9.3515577,0.179092846,72885.01485,1.568933221,112.2572319
38.2,9.498230784,0.180842485,73348.70084,1.569804625,112.9698319
38.4,9.57883486,0.182614743,73990.23487,1.569368943,113.8545885
38.6,9.795723636,0.18439448,74531.62606,1.570240357,114.6826864
38.8,9.780754578,0.186209594,75117.75678,1.570240354,115.5211343
39,10.00636335,0.188024739,75268.06293,1.578082868,116.3149099
39.2,10.07116653,0.189870472,75365.98511,1.587232446,117.1528137
39.4,9.855912512,0.191755943,75580.54407,1.591589362,117.828365
39.6,10.1114292,0.193624549,75755.91638,1.597689104,118.5965353
39.8,10.24021213,0.195521522,75750.19174,1.607710077,119.4115577
40,10.09433939,0.197458423,75867.21904,1.613374081,120.0816613
40.2,10.44458343,0.1993772,75847.92925,1.623830772,120.8759832
40.4,10.02363637,0.201373907,75653.63396,1.635594459,121.4654546
40.6,9.960856443,0.203363318,75751.14319,1.642129861,122.1420966
40.8,10.37424871,0.205336473,76417.77038,1.639080052,122.9745545
41,10.3987197,0.207359234,77282.0885,1.631237568,123.7242001
41.2,10.48302102,0.209397696,78682.35492,1.615552602,124.7157378
41.4,10.7709194,0.21144107,79973.14056,1.600739046,125.572166
41.6,11.10452069,0.213501614,81167.71436,1.589846739,126.5190315
41.8,11.02094582,0.215614624,82045.55144,1.585489793,127.5083887
42,10.81770047,0.217757929,82554.64394,1.585489772,128.288542
42.2,11.01500414,0.219892221,83285.55709,1.58374702,129.2855287
42.4,11.09762341,0.222056681,83989.50448,1.582439949,130.3032165
42.6,10.92511556,0.224262426,84579.04766,1.582004238,131.2282869
42.8,11.30107849,0.226448561,85185.53257,1.580261505,132.0585651
43,11.32385373,0.228683456,85775.95734,1.580697203,133.108941
43.2,11.1621386,0.230954837,85854.08479,1.587232594,133.8411519
43.4,11.27964311,0.233227832,85733.25543,1.599867729,134.756418
43.6,11.32983122,0.235528879,85525.07158,1.612938551,135.5213183
43.8,11.55868531,0.237839526,85338.35245,1.625138005,136.2077685
44,11.32548767,0.240208419,84997.96108,1.642565734,137.0053548
44.2,11.37483362,0.242579629,84879.24628,1.653458087,137.62207
44.4,11.55797027,0.244964488,85165.40816,1.658686435,138.4261966
44.6,11.82752938,0.247366691,85541.14293,1.661300631,139.1987259
44.8,12.23586527,0.249782548,85779.56496,1.664786229,139.8644749
45,12.27106858,0.252250958,86026.79047,1.669578867,140.6903928
45.2,12.49906497,0.254729557,85932.89082,1.680035548,141.4443983
45.4,12.61653152,0.257241468,85605.67955,1.692670685,142.0011857
45.6,12.83620973,0.259770853,85278.77801,1.706177222,142.5993786
45.8,13.15643754,0.262318013,85461.48015,1.711405588,143.3435783
46,12.94896245,0.264930925,85933.60248,1.70966279,143.9700977
46.2,12.75145546,0.267569279,87007.04458,1.699206115,144.850494
46.4,12.8522811,0.270211308,88097.10466,1.687442394,145.6066787
46.6,13.49659073,0.272838717,89339.46992,1.674371653,146.5066935
46.8,13.35308537,0.275565997,90283.79891,1.66783623,147.4807962
47,13.28354093,0.278287671,90946.46105,1.663914978,148.236979
47.2,13.61288043,0.281020158,91865.85552,1.657815303,149.2350559
47.4,13.71534437,0.283811413,92369.15701,1.656508234,149.9879715
47.6,13.63747433,0.286630532,92874.96189,1.656508227,150.8454872
47.8,13.73744073,0.289450174,93381.75115,1.657379628,151.7694698
48,13.37285917,0.292347663,93815.51779,1.658250976,152.5409052
48.2,13.73791015,0.295218716,93914.604,1.666529203,153.4234849
48.4,13.85946712,0.298137337,94125.56461,1.670886158,154.1360852
48.6,13.93863732,0.301088519,94698.46677,1.670014781,154.9674517
48.8,14.03109916,0.304068246,95670.34486,1.664350772,155.9709754
49,14.22494091,0.307070239,96653.32165,1.658686774,156.9930229
49.2,13.98581549,0.310135269,97735.5316,1.64997287,157.8843148
49.4,14.38075483,0.313183019,98761.22682,1.64256612,158.7832391
49.6,14.32776852,0.316295417,99523.43414,1.64082334,159.7671491
49.8,14.33211776,0.319434673,99979.94412,1.644308893,160.7826572
50,14.82842693,0.322568083,100050.4709,1.651280054,161.5573675
50.2,14.42141033,0.325801586,99680.03098,1.666529297,162.4323151
50.4,14.58696263,0.329024124,99271.28607,1.68003583,163.0806285
50.6,14.64032181,0.332287665,99003.32087,1.691799574,163.7921389
50.8,14.65378675,0.335586923,98837.05458,1.702256231,164.5973547
51,14.7428694,0.33891366,98807.3622,1.709227347,165.2522057
51.2,14.70895551,0.342283053,99075.20272,1.712712896,166.0846611
51.4,14.97337309,0.345663723,99561.71804,1.711405847,166.807069
51.6,15.33169076,0.349071093,100203.5983,1.709663114,167.7898925
51.8,15.54374316,0.352523746,100651.5718,1.709227447,168.5057624
52,15.77573456,0.356009643,101558.7856,1.703563454,169.4689719
52.2,15.97863462,0.359532843,102220.0188,1.700077927,170.2371427
52.4,15.87571298,0.363114663,103119.1333,1.694849589,171.2461131
52.6,16.67444447,0.366663869,104120.4686,1.687878582,172.1973416
52.8,16.73439176,0.370304843,105173.976,1.679600404,173.1017115
53,16.97134098,0.373968629,105932.3689,1.677421963,174.1608061
53.2,17.04955913,0.377681353,106605.2942,1.675243505,174.9954416
53.4,17.12278524,0.381431704,107109.055,1.677857676,175.9880692
53.6,17.47107366,0.385198729,107418.589,1.681778962,176.8782767
53.8,17.19941362,0.389050742,107639.068,1.68570018,177.6486228
54,17.49782854,0.392898229,108008.5509,1.689185769,178.5954891
54.2,17.51950698,0.396805359,108228.1196,1.693107019,179.3680169
54.4,17.55613758,0.400750587,108684.0305,1.69441411,180.2974474
54.6,17.78722104,0.404720677,108922.481,1.698771077,181.1538763
54.8,17.76234337,0.408750094,108870.6198,1.708792038,182.0408118
55,17.92693228,0.412805632,109008.8487,1.713584694,182.7250832
55.2,18.04248442,0.416905696,108955.0581,1.722734283,183.5782423
55.4,18.88101925,0.420991983,108942.127,1.729269796,184.2058604
55.6,18.79960608,0.425189186,109121.9864,1.734062426,184.965312
55.8,18.84200852,0.429419069,109764.3947,1.732755346,185.9034597
56,19.26210372,0.433663094,110099.5041,1.73406248,186.6040767
56.2,19.17360658,0.437988429,111160.8621,1.727091365,187.617406
56.4,19.18981133,0.442349278,112071.0077,1.720555958,188.4367865
56.6,19.3036542,0.446746598,113299.6035,1.710970703,189.4305042
56.8,19.18895898,0.451205282,114631.7922,1.701385421,190.5778539
57,19.33893718,0.455688794,115853.6891,1.692453711,191.634224
57.2,19.42949015,0.460221741,116930.539,1.685700465,192.6862355
57.4,19.45147654,0.46480553,117730.3467,1.682214916,193.6189347
57.6,19.43107352,0.469438337,118160.1596,1.684393386,194.5984868
57.8,19.48005347,0.474112321,118677.2022,1.686571864,195.6848197
58,19.94536806,0.478801712,118654.585,1.693978719,196.49113
58.2,20.06995607,0.483564087,118277.0643,1.707485253,197.3878737
58.4,20.25353904,0.488369884,118027.4769,1.717070547,198.1026536
58.6,20.49113081,0.493219745,118021.2587,1.724041682,198.9503669
58.8,20.47608405,0.498137686,118177.5511,1.728834318,199.8590939
59,20.52584917,0.503100091,118471.3297,1.731012796,200.6327123
59.2,20.59222682,0.508111027,119510.396,1.724913088,201.711419
59.4,20.40513469,0.513191518,120252.18,1.722298902,202.5634851
59.6,20.47897543,0.518303186,121230.161,1.719249054,203.7184639
59.8,20.61596572,0.523461336,121677.6554,1.720556154,204.5247706
60,20.74463753,0.528672104,122140.9086,1.723170336,205.5206683
60.2,21.60958676,0.533879237,122025.1767,1.731012934,206.2485301
60.4,22.4628934,0.539139728,121717.6917,1.741905392,207.0886224
60.6,22.81591625,0.54449082,121255.92,1.754104874,207.7935982
60.8,22.75258832,0.549927447,121161.6869,1.760640281,208.439732
61,23.20947172,0.555379163,121638.3556,1.760640338,209.3637185
61.2,23.01316282,0.560935278,122220.2669,1.758461845,210.0926606
61.4,23.17169162,0.5665202,123791.5266,1.745391039,211.1931605
61.6,23.42245499,0.572154222,125754.3931,1.727527607,212.3590366
61.8,23.52030123,0.577856537,127513.999,1.712278322,213.4421028
62,23.84251442,0.583599113,129350.2927,1.69877184,214.7267462
62.2,24.08660234,0.589405287,130759.5867,1.689186597,215.815261
62.4,23.88026683,0.595303946,132007.6045,1.68352255,217.0988103
62.6,24.29635772,0.601214608,132821.7827,1.682651211,218.2320005
62.8,24.35676153,0.607211798,132866.4199,1.689622328,219.1505356
63,24.48862371,0.613263789,132781.0928,1.699207618,220.2543038
63.2,24.51161229,0.619384723,132653.2263,1.707050119,221.079133
63.4,24.67503388,0.62555664,132466.8876,1.717071108,222.1033601
63.6,24.73872292,0.631798073,132535.051,1.722735143,223.0436881
63.8,24.75170963,0.638106049,133202.7789,1.720992369,223.9861947
64,25.03310652,0.644457081,134277.1735,1.716635461,225.2087304
64.2,25.10258253,0.650888005,134920.135,1.715764082,226.1348929
64.4,25.68645124,0.657344365,135646.0848,1.715764153,227.2844298
64.6,25.55646127,0.663919917,135826.6367,1.721428165,228.2792352
64.8,26.05055874,0.670514088,135498.6368,1.731449194,229.0386938
65,26.17068551,0.677203024,134911.0246,1.745827122,229.9408853
65.2,26.43124442,0.683948487,134818.1357,1.752798264,230.6665632
65.4,26.77405833,0.690789918,134833.8105,1.759769417,231.5752953
65.6,27.29969723,0.697617413,135316.2374,1.76064087,232.4720433
65.8,27.74470498,0.704589267,136862.336,1.748877178,233.4831998
66,27.94289906,0.711579572,139231.3494,1.729706651,234.8582798
66.2,27.70395842,0.718708663,141404.0439,1.711843156,236.0481227
66.4,28.17553081,0.725855274,144893.0077,1.683087384,237.7359222
66.6,28.32133086,0.733098646,148260.1157,1.657381434,239.4182686
66.8,28.56601106,0.740407232,150414.6223,1.643874937,240.8184107
67,28.5912896,0.747805894,152342.7804,1.635596748,242.5301767
67.2,28.49190291,0.755288343,153255.5517,1.636468127,244.0153032
67.4,28.85039779,0.762811228,153410.6793,1.642567891,245.1626591
67.6,29.06178964,0.770420849,152685.3748,1.65781722,246.367761
67.8,29.51084188,0.778088733,151822.0809,1.674809355,247.594659
68,29.99062971,0.78583147,151621.1863,1.683087606,248.5742169
68.2,30.55350746,0.793645742,151234.3609,1.695287117,249.8076532
68.4,30.68922702,0.801570889,150770.3431,1.706615191,250.6945919
68.6,30.97036294,0.809564506,150604.4042,1.715764809,251.738434
68.8,31.22406232,0.817640685,150483.6623,1.724914425,252.8781616
69,31.81265107,0.825772414,150384.5154,1.733628386,253.9808462
69.2,31.98737742,0.834017313,150742.0797,1.735806881,254.9146381
69.4,31.9402075,0.842361784,151635.3891,1.734064099,256.1546053
69.6,31.96033713,0.850784846,152488.9728,1.732321325,257.2518351
69.8,32.17158858,0.859278032,153441.6005,1.72927149,258.3294543
70,32.16177438,0.867873288,154260.8469,1.728835796,259.607558
70.2,32.20845601,0.876550622,154799.6344,1.731014276,260.8322725
70.4,32.70803129,0.885280747,155433.9615,1.730578644,261.8423397
70.6,32.84692868,0.894125914,156495.7442,1.72665741,263.0997424
70.8,33.11545153,0.903050141,157497.9121,1.72447897,264.4443154
71,32.91858722,0.91209955,158864.3685,1.717943529,265.6385172
71.2,32.9494088,0.921222335,160558.6563,1.710101038,267.1356314
71.4,33.38409296,0.930406305,161588.5914,1.707486922,268.3167662
71.6,33.62679618,0.939696879,162228.1239,1.709665425,269.5621851
71.8,34.04233734,0.94906787,163109.8345,1.71010117,270.9699571
72,34.23431836,0.958549821,163831.7976,1.710101193,272.1282071
72.2,34.68057729,0.968107791,164338.9977,1.713586804,273.4771411
72.4,34.50022953,0.977809529,164487.7461,1.718379428,274.5013652
72.6,34.92485112,0.987562636,164940.3014,1.720993645,275.7162778
72.8,35.28962347,0.997418327,165823.8098,1.720557994,277.1556477
73,35.35438072,1.007395852,166238.1157,1.723172169,278.2496097
73.2,35.65263957,1.017455796,166618.5565,1.727093454,279.5233592
73.4,36.71999426,1.027558778,167553.5196,1.724479419,280.6271411
73.6,36.93220996,1.037828295,168942.5245,1.719251109,282.0305525
73.8,37.29773303,1.048189432,169684.8594,1.720122545,283.4121738
74,37.50576065,1.058666651,170232.7623,1.721429654,284.5562596
74.2,37.76446397,1.069245288,171068.1208,1.721865381,285.9716573
74.4,38.00777647,1.079931319,171327.5498,1.725786664,287.057995
74.6,38.72724824,1.090688767,171360.7237,1.732322171,288.2129834
74.8,39.30085828,1.101565283,171592.824,1.737986273,289.4954546
75,39.70575325,1.112563694,172406.156,1.738422017,290.8814354
75.2,40.35702919,1.12365347,173307.1713,1.736243623,292.0080939
75.4,40.55870374,1.134888851,174726.6799,1.730143922,293.2556923
75.6,40.98806078,1.146219888,176168.1474,1.724915637,294.6907053
75.8,41.29939442,1.157673593,178206.5611,1.71533039,296.3904903
76,41.53342459,1.169248235,179940.1752,1.707052218,297.80044
76.2,41.94112017,1.180926097,181817.6702,1.699209761,299.528556
76.4,42.21250927,1.192731544,183416.3201,1.692238677,300.945044
76.6,42.41407355,1.204660903,186086.9647,1.678296468,302.7058458
76.8,42.54415072,1.216715692,189187.611,1.663047166,304.7891686
77,42.49803166,1.228904935,191298.6512,1.656076045,306.7842309
77.2,42.96795878,1.241177398,193100.5276,1.649976372,308.4491511
77.4,43.39382205,1.253576558,194316.9442,1.649976422,310.4115329
77.6,43.95262936,1.266089977,193933.4446,1.660433164,311.9653153
77.8,44.9019978,1.278699671,193071.2123,1.673939815,313.2401652
78,44.7386054,1.291520574,192199.2207,1.688753425,314.7078583
78.2,44.84278216,1.304449902,191519.9508,1.700517201,315.850854
78.4,45.09735358,1.317497621,190911.9971,1.713152385,317.2564461
78.6,45.97018582,1.330629583,191678.3935,1.714459574,318.7165278
78.8,46.15158534,1.343946032,192862.2759,1.711409732,320.1384626
79,46.32049825,1.357397123,194889.6539,1.703567245,321.9907913
79.2,46.77858595,1.370961517,196740.9306,1.696160486,323.5206001
79.4,47.12280173,1.384670825,199318.4938,1.686139543,325.5134908
79.6,47.56588749,1.398510256,200436.9261,1.686575291,327.224175
79.8,47.60174945,1.412519728,201426.4459,1.687010992,328.6951401
80,48.07387658,1.426636794,202014.4312,1.691803693,330.4014662
80.2,48.45955469,1.440902203,202085.0753,1.700081945,332.0816404
80.4,48.43052909,1.455342482,201905.2901,1.707924454,333.3564772
80.6,48.81948546,1.469896112,202010.2284,1.714459926,334.8012972
80.8,49.58487247,1.484567355,201812.9638,1.722302529,336.0423679
81,49.82419788,1.499425962,201635.655,1.731452155,337.5536512
81.2,50.2970173,1.514416173,201502.5043,1.738423334,338.691206
81.4,50.31856676,1.529591244,201735.0299,1.744087375,340.1501849
81.6,50.40823594,1.544913656,202301.9301,1.746265863,341.5285343
81.8,50.82114902,1.560365312,203168.4762,1.745394524,342.8382454
82,51.39359407,1.575960113,204707.5702,1.740601948,344.530409
82.2,51.80313351,1.59172398,207139.3786,1.72970962,346.4067133
82.4,52.27080672,1.607721997,209812.7306,1.716203129,348.0618288
82.6,52.92629148,1.623705365,212772.9762,1.702260962,350.0209472
82.8,53.20445286,1.639959064,215531.5408,1.691368618,352.1772773
83,53.48589922,1.656458589,217330.8352,1.68614031,353.9086626
83.2,54.12136189,1.672931453,218276.9122,1.688318861,355.8481675
83.4,54.21994333,1.68969405,217409.0989,1.700954035,357.1186473
83.6,55.11545029,1.706564514,216756.4376,1.713153607,358.5612978
83.8,55.83973935,1.723617499,216496.512,1.723174685,360.134699
84,56.25984628,1.740864976,215949.6661,1.734938508,361.6307329
84.2,56.88186461,1.758270379,215735.301,1.742345403,362.8162323
84.4,57.12740109,1.775879324,216688.9812,1.742345435,364.4157745
84.6,57.17595666,1.793680145,216952.6348,1.746702395,365.8072003
84.8,57.37074412,1.811648579,217460.6233,1.749752287,367.4045627
85,57.84722014,1.829776359,218761.3454,1.746266784,368.8493858
85.2,58.18737923,1.848096541,221091.2984,1.73755292,370.7213321
85.4,58.69122091,1.866588306,222912.3855,1.731453247,372.2620404
85.6,59.17259538,1.885267758,225699.2911,1.720125227,374.1917381
85.8,60.15504789,1.904096657,228484.5012,1.710104351,376.3622474
86,60.96046214,1.923128231,229765.292,1.709668752,378.3006676
86.2,61.26390712,1.942389176,229668.4115,1.71620422,379.6496029
86.4,61.85901103,1.961821429,229142.8443,1.727096678,381.3265143
86.6,62.29286519,1.981460784,228604.9556,1.736682031,382.6983348
86.8,62.73250518,2.001296989,228085.6277,1.74583169,383.9426705
87,62.94773683,2.021349414,228641.6934,1.748881586,385.5781702
87.2,63.3773409,2.041586735,230031.8314,1.746703162,387.338979
87.4,63.66314536,2.062038417,232062.9686,1.739296374,388.972301
87.6,63.96553769,2.082694101,233740.3094,1.735375153,390.7385561
87.8,64.54379727,2.103536467,235246.1884,1.733196745,392.6355667
88,65.14446127,2.124586509,236024.1862,1.734503906,394.1446805
88.2,65.45173989,2.145870249,236143.2131,1.741039377,395.842289
88.4,66.10053579,2.16734181,235234.1477,1.752803236,396.9842069
88.6,66.63295392,2.189038043,235056.9765,1.760645821,398.4083302
88.8,67.04483879,2.210961385,235842.1866,1.762824351,400.108121
89,67.68937567,2.233087333,236957.2113,1.761081647,401.5180818
89.2,67.99232593,2.255461577,238577.4828,1.757596121,403.3377271
89.4,68.75645943,2.278025415,240366.1152,1.751496478,404.8947869
89.6,69.3543519,2.300828557,241855.706,1.748446681,406.6697645
89.8,70.04112767,2.323854087,242776.0511,1.749318156,408.4545503
90,70.61235418,2.347119779,243868.8089,1.749318229,410.2905454
90.2,71.17024717,2.370620221,245314.289,1.745832731,411.8530495
90.4,71.32006922,2.39438783,247893.8965,1.737118837,413.9679751
90.6,71.67345452,2.41837871,249871.659,1.731890533,415.8998513
90.8,72.5328959,2.442572425,251548.5425,1.727969372,417.6083688
91,72.81556692,2.467054093,253821.8754,1.722305362,419.7657919
91.2,73.5153736,2.491749928,255137.7896,1.722305446,421.7957403
91.4,74.2296838,2.5166929,255694.1019,1.725355406,423.364786
91.6,74.66265209,2.541907862,257290.9868,1.72317698,425.3206356
91.8,74.82674337,2.567396588,259660.4102,1.71707726,427.626243
92,75.58913232,2.593095899,260919.554,1.715770264,429.4382715
92.2,76.12003961,2.619071199,262659.1614,1.713156153,431.6959436
92.4,76.814202,2.645294912,263296.2769,1.715334716,433.3848464
92.6,77.98574696,2.671744622,263594.0099,1.72012751,435.2502752
92.8,78.5954764,2.698502774,263436.4025,1.728405807,437.2409963
93,79.04893031,2.72554153,264229.6179,1.730148647,438.9375212
93.2,79.68516672,2.752838042,264754.0127,1.734505684,440.8770313
93.4,80.60307731,2.780387464,266313.6397,1.731455923,442.6236881
93.6,80.71651094,2.808274784,268121.7812,1.728406066,444.703747
93.8,81.27366784,2.83640858,270396.6185,1.723613478,446.9843022
94,81.89144471,2.864820457,272150.4204,1.721870769,449.2528733
94.2,82.8640243,2.893490878,273600.0008,1.720128101,451.0834311
94.4,83.29472925,2.922490409,275118.7772,1.719692458,453.2931619
94.6,83.58577553,2.951791919,277548.0219,1.714028445,455.5955045
94.8,84.46264837,2.981343276,279132.4374,1.711850069,457.5361112
95,84.84335151,3.011229211,280715.6608,1.71141442,459.9234438
95.2,85.16749716,3.041419672,282159.5102,1.710107371,461.8476959
95.4,86.21126321,3.071858827,283242.9462,1.712285976,464.1086493
95.6,86.88932917,3.102631836,283235.5342,1.719692893,466.0481617
95.8,87.48008829,3.133720475,285073.7516,1.71795018,468.4627409
96,88.10486987,3.165118846,286836.0638,1.715336078,470.4926907
96.2,88.63154021,3.196840227,288396.75,1.715336142,472.8386239
96.4,89.0526196,3.228888171,290014.7514,1.713593408,474.8576731
96.6,89.50938193,3.261255548,291369.538,1.71402916,477.1229726
96.8,90.27274134,3.293924647,290069.1346,1.728842926,479.0940878
97,91.50142337,3.32688691,288951.9618,1.741042571,480.6086673
97.2,92.74584238,3.360179105,288300.6896,1.751499435,482.3902017
97.4,93.0685999,3.393875634,288016.4297,1.760213403,484.2370923
97.6,93.72454527,3.427885341,288849.6323,1.76195627,486.0305996
97.8,94.36630888,3.462237956,290399.648,1.759342171,487.8317328
98,94.86425006,3.496946601,292696.4719,1.754113876,490.126454
98.2,95.71116703,3.531977463,295017.2389,1.747578533,492.0692425
98.4,96.14334576,3.567391842,297619.6423,1.741478836,494.5557328
98.6,96.48488602,3.603168985,298804.6201,1.742350272,496.6270827
98.8,97.33163345,3.639267044,300101.7038,1.741914678,498.4783444
99,98.02956947,3.675739124,302139.4915,1.739300584,500.9376014
99.2,98.31193386,3.712609167,302963.002,1.741043407,502.7365482
99.4,99.79424221,3.749758538,304067.4973,1.742350675,505.0639838
99.6,100.4928329,3.787340772,305857.635,1.739300884,507.2987827
99.8,101.0974576,3.825307666,307001.992,1.738865262,509.2698959
100,102.0336014,3.863630784,307562.9978,1.742786645,511.5199563
100.2,102.8799332,3.902345711,308424.9401,1.743658142,513.3047509
100.4,103.412075,3.941473584,309220.1779,1.747143781,515.4709032
100.6,104.5607448,3.981146653,309557.9045,1.752372282,517.3614001
100.8,104.9764167,4.021076816,309679.5678,1.758907785,519.4338411
101,106.0535547,4.061155216,310201.3759,1.761522098,521.1336544
101.2,107.0882142,4.101842429,310675.3837,1.765443496,523.2202777
101.4,107.8028632,4.142962715,311565.378,1.765443584,524.9593079
101.6,108.6321284,4.184487501,313603.9462,1.760651021,527.1363645
101.8,109.0773926,4.226458677,316677.7106,1.752372837,529.7176523
102,110.2588802,4.268795605,320513.3945,1.741480558,532.479836
102.2,110.9092736,4.311598317,323661.8003,1.732766699,534.6928438
102.4,111.6817597,4.354821905,327926.779,1.721438672,537.663133
102.6,112.6793853,4.398462559,331191.9101,1.71446764,540.3577576
102.8,113.2722309,4.442572379,333789.6608,1.709675045,542.7407414
103,114.1816275,4.487101422,336638.0379,1.70575388,545.7077664
103.2,114.996216,4.53208493,339134.8896,1.703575492,548.6540851
103.4,115.9786003,4.577507659,339710.5839,1.70793258,550.7832033
103.6,116.6517697,4.623410199,339891.9121,1.714468117,553.1563861
103.8,118.0279155,4.669720794,338979.2764,1.725796407,555.4968983
104,118.7832095,4.716543726,337864.0988,1.736688928,557.3165631
104.2,119.5517252,4.76383613,337318.273,1.74627436,559.5633537
104.4,120.3775064,4.811599147,338315.2101,1.747145855,561.4821753
104.6,121.190746,4.859842851,341127.4814,1.742788982,564.4274053
104.8,122.3537717,4.908543396,345075.0642,1.731896691,566.9324459
105,123.3854172,4.957743135,350541.1528,1.71664741,570.2764785
105.2,124.5399765,5.007427551,354087.5612,1.707933601,572.8447163
105.4,125.854845,5.057598994,358618.4732,1.69747702,576.2388799
105.6,126.2471919,5.108344318,360914.4683,1.695734279,579.079499
105.8,127.3300425,5.159547112,360957.8545,1.704448353,581.8994317
106,128.170982,5.211282648,360723.7638,1.712291009,584.0372683
106.2,129.0184873,5.263537434,359856.4543,1.724490641,586.6207506
106.4,130.2423651,5.316288552,357424.2036,1.741047293,588.2486592
106.6,131.0996751,5.369597628,356049.1099,1.753682624,590.2753545
106.8,132.1172885,5.423430158,355411.6687,1.762832399,592.528693
107,132.9661173,5.477816286,353980.7901,1.773724939,594.101022
107.2,134.039237,5.532731839,354491.1352,1.776774962,596.2650146
107.4,135.0574212,5.588203157,357055.6109,1.769803923,598.4976512
107.6,136.1137442,5.644228927,360738.542,1.760218706,601.6106924
107.8,137.0428304,5.700827191,364357.2277,1.750633469,604.0797718
108,137.9759813,5.757993915,370146.983,1.734077066,607.4368821
108.2,139.2963007,5.815705607,373724.7722,1.725798969,610.016024
108.4,140.4233133,5.874013955,376294.4884,1.724056316,613.0734985
108.6,141.3545254,5.932923798,377402.9331,1.727106312,615.6395564
108.8,142.3654223,5.992419479,376477.539,1.738434576,618.1783723
109,143.1933978,6.052526925,375388.3258,1.748891425,620.047076
109.2,144.3806975,6.113210968,373770.4156,1.762833909,622.2906182
109.4,145.5516954,6.174505791,373279.533,1.770240917,624.0634458
109.6,146.7005732,6.236418229,374521.5227,1.771548155,626.4017817
109.8,147.716803,6.298962824,378450.7451,1.762398621,629.3317703
110,149.0524641,6.362110097,381921.7661,1.754120521,631.8281051
110.2,150.2164171,6.425903286,386472.1665,1.74322821,635.0337716
110.4,151.5323468,6.490325818,390087.037,1.736257199,638.2546952
110.6,152.6670092,6.555409476,391682.9769,1.736693034,641.0659214
110.8,153.6411789,6.621159223,390915.3402,1.745407117,643.1002509
111,154.6077644,6.687570071,391161.6522,1.751507011,645.8243056
111.2,155.6656572,6.754641194,391401.5821,1.755864123,647.843385
111.4,156.7666566,6.822382906,392857.1684,1.757607052,650.5837875
111.6,157.8384619,6.890807417,395109.8441,1.75586439,653.2381095
111.8,159.0747019,6.959906948,398373.0941,1.749329065,655.8815408
112,160.4205277,7.029692299,402032.4455,1.742793752,659.0676037
112.2,161.7354941,7.100181164,406231.5026,1.73451564,662.4040294
112.4,163.0461929,7.171378605,408860.9286,1.730594512,665.132453
112.6,164.1074688,7.243310242,411342.1922,1.72754475,668.1114805
112.8,165.4827596,7.315940789,413017.0125,1.728416313,671.3552936
113,166.4731673,7.389330328,412740.06,1.734951912,673.7252288
113.2,167.8482251,7.463427804,411660.2141,1.745844544,676.3327089
113.4,169.3386781,7.538261027,410981.1212,1.754558699,678.4269883
113.6,170.3204207,7.613884826,409947.2108,1.765886987,680.6084197
113.8,171.7208822,7.690236518,411121.4641,1.769808448,683.2791017
114,173.0713601,7.767359188,414325.3169,1.764580228,685.7689049
114.2,174.2006606,7.84527348,420350.4374,1.750638004,689.3232515
114.4,175.6132185,7.923949104,426997.7235,1.734517317,693.0977085
114.6,176.923434,8.003422891,432427.1186,1.722753603,696.7555745
114.8,178.5119182,8.08367411,434424.1966,1.721882395,699.6409165
115,180.0994434,8.164731689,434217.475,1.729289469,702.6907907
115.2,181.3336509,8.24663028,431466.964,1.744103386,704.6848215
115.4,182.6042931,8.329349184,426506.5289,1.76850269,706.7540365
115.6,183.8764654,8.412898936,424909.5882,1.780266724,708.8417732
115.8,185.7443542,8.497242892,425553.6496,1.783316849,710.9317106
116,186.8076696,8.582495478,426533.0313,1.786366876,713.5402769
116.2,188.4268093,8.668562244,429572.0926,1.780702986,715.9767025
116.4,189.9128467,8.755503899,436526.6166,1.762839497,719.6738052
116.6,191.2142562,8.843333075,440196.1176,1.756304167,722.792318
116.8,192.757356,8.932026213,442858.6057,1.75281876,725.5556282
117,194.1008665,9.021625562,445265.9041,1.751511825,728.8386738
117.2,195.6902196,9.112106521,444733.4853,1.759790309,731.5867286
117.4,197.0708393,9.20351246,443561.8655,1.768940169,733.6842815
117.6,198.4812303,9.29583439,445046.778,1.769376042,736.3353563
117.8,199.8623878,9.389086239,448800.9786,1.762840718,739.7230101
118,201.33889,9.483741658,454277.1217,1.749334208,742.8971001
118.2,202.9442026,9.578385864,464062.4537,1.724063819,747.5258293
118.4,204.3248321,9.674962455,471622.6441,1.706200295,751.4223301
118.6,206.1981866,9.771990557,479947.7838,1.688772523,755.9115984
118.8,207.9684166,9.869508504,487291.1895,1.676573134,760.7691544
119,209.5647268,9.968512409,491348.1909,1.67483052,765.1483656
119.2,211.0029827,10.06852329,492745.917,1.679187687,768.4270616
119.4,212.9064577,10.1695035,494154.9177,1.685287709,772.4565206
119.6,214.3751412,10.27153127,493787.3272,1.694437583,775.9226336
119.8,216.0888168,10.3745656,494371.22,1.699666186,779.0313617
120,217.7857073,10.47863665,496807.1827,1.700973486,783.0477371
120.2,219.3162251,10.58376586,499730.0799,1.700537967,787.2395354
120.4,221.2546128,10.68992023,501337.3672,1.701845296,790.4931929
120.6,223.0233003,10.7971544,503624.0555,1.702281206,794.2153793
120.8,224.6497099,10.90547659,504609.4536,1.707074102,798.2328424
121,226.3839811,11.01487904,503534.0234,1.715788316,801.0985956
121.2,227.8371883,11.12540193,502324.3705,1.726681002,804.6529698
121.4,229.4456224,11.23702357,502330.2668,1.732781002,807.4337235
121.6,231.2001406,11.34975536,502460.591,1.739316722,810.5925826
121.8,233.2212411,11.46359957,503044.6103,1.744981074,814.0859643
122,234.9679188,11.57860738,503424.3638,1.749773993,816.8819801
122.2,236.7617819,11.69476765,504265.1043,1.754131218,820.2195376
122.4,238.3759562,11.81210854,505396.6759,1.757181321,823.5712528
122.6,240.5724993,11.93058156,507441.5476,1.757181588,826.8597963
122.8,242.1447462,12.0502914,508770.3188,1.758924584,829.7397099
123,243.9140126,12.05979489,511840.0937,1.757181995,833.5250969
123.2,245.0382659,12.05970884,513410.341,1.758489233,836.4256978
123.4,245.9406328,12.05963957,514310.934,1.76284635,839.6226639
123.6,246.5837167,12.05958992,515892.3508,1.765024937,842.74225
123.8,247.3547801,12.05953058,517434.7094,1.766332131,845.5055483
124,247.8449535,12.05949249,519294.1354,1.768074997,848.9661774
124.2,248.3409442,12.05945396,522073.7479,1.766767957,852.4845618
124.4,248.860204,12.05941367,524889.6053,1.764153813,855.4679469
124.6,248.7570181,12.05942046,527019.605,1.764153805,858.7749262
124.8,249.0759983,12.05939532,529535.0808,1.764153841,862.4305906
125,249.5603546,12.05935767,531914.6929,1.7632825,865.3812862
125.2,249.6125724,12.0593527,534535.1223,1.763282505,869.0565571
125.4,250.2165978,12.059306,536323.5981,1.764153981,871.9277162
125.6,250.1823879,12.05930757,537300.7657,1.768075292,875.042922
125.8,250.3920869,12.0592907,537199.7175,1.775046538,878.2681891
126,250.893895,12.05925173,537160.3667,1.780928565,881.1753015
126.2,250.9868335,12.05924368,536506.5152,1.788117646,883.8383229
126.4,251.3623242,12.05921426,535706.0391,1.79596032,886.6953078
126.6,251.4752076,12.05920471,536407.6166,1.799010243,889.3866602
126.8,251.3815786,12.05921078,537430.6377,1.800753038,891.8437367
127,251.469531,12.05920311,537601.0884,1.806417166,894.7693592
127.2,251.9912839,12.05916263,537029.9588,1.812517049,896.8647108
127.4,252.2113709,12.05914497,537092.0549,1.817745493,899.4667151
127.6,252.3749475,12.05913158,538346.4766,1.819052618,902.062188
127.8,252.5110999,12.05912026,538961.9346,1.821666844,904.3024419
128,252.6971145,12.05910518,541574.9545,1.819488363,907.3784309
128.2,252.5997459,12.05911153,546396.015,1.81164573,910.8052652
128.4,253.0300849,12.05907796,550044.6196,1.805981669,913.5238726
128.6,253.1097269,12.05907092,552337.3222,1.805110278,916.5421083
128.8,253.1070964,12.05907011,553615.2876,1.807288785,919.602834
129,253.2415867,12.05905892,553337.6649,1.812517219,921.7308559
129.2,253.2597321,12.05905653,550892.6233,1.824281156,924.0539154
129.4,253.3651362,12.05904754,547504.6988,1.837352209,925.5314407
129.6,253.5985198,12.05902887,544843.1356,1.848680473,927.2410561
129.8,253.8651448,12.05900769,542669.2628,1.858701637,929.1086665
130,253.9597455,12.05899952,540956.3861,1.866979975,930.9141641
130.2,254.167367,12.0589828,540892.5027,1.870029913,932.4287362
130.4,254.4622472,12.05895948,541787.927,1.871337056,934.5534976
130.6,254.1695852,12.0589806,542261.9039,1.873079825,936.2521921
130.8,254.4204206,12.05896061,544253.8489,1.871337054,938.4870049
131,254.3546313,12.05896457,545792.9599,1.870029943,940.2881334
131.2,254.3985387,12.05896024,547071.0496,1.870465652,942.4510212
131.4,254.5654395,12.0589466,547241.4526,1.873079883,943.9666819
131.6,254.6932816,12.05893591,546122.0342,1.880051122,945.4594612
131.8,254.9399618,12.05891624,542125.1721,1.895300701,946.4837104
132,255.1750075,12.05889744,536279.4688,1.915778695,946.8650896
132.2,255.3493876,12.05888324,531518.7058,1.93233537,947.1876213
132.4,255.2221017,12.05889185,529050.7499,1.941049381,947.4371381
132.6,255.308392,12.05888431,528927.9557,1.942792199,948.2390991
132.8,255.2010509,12.05889141,531979.3776,1.935385265,949.7100739
133.5,255.6235883,11.9750738,1.7977E+308,1.938435234,0
133.7,255.1805571,11.85455652,1.7977E+308,1.921007122,0
133.9,254.8189675,11.73403307,1.7977E+308,1.827331292,0
134.1,254.7573819,11.61348694,1.7977E+308,1.660893384,0
134.3,254.7672653,11.4929354,1.7977E+308,1.429535991,0
134.5,254.251934,11.37242359,1.7977E+308,1.043940296,0
134.7,254.3623728,11.25186444,1.7977E+308,0.687536644,0
134.9,253.9351313,11.13134596,1.7977E+308,0.402587985,0
135.1,253.6699419,11.01081523,1.7977E+308,0.188658652,0
135.3,253.3374386,10.89028959,1.7977E+308,0.050105645,0
135.5,253.4994015,10.76972654,1.7977E+308,0.016120947,0
135.7,252.8909943,10.64922177,1.7977E+308,0.021785063,0
135.9,252.9990358,10.52806006,1.7977E+308,0.030499088,0
136.1,252.6615463,10.40753479,1.7977E+308,0.033113295,0
136.3,252.2525877,10.28701493,1.7977E+308,0.031370489,0
136.5,252.000599,10.16708595,1.7977E+308,0.029627683,0
136.7,251.7595096,10.04655339,1.7977E+308,0.026577774,0
136.9,251.7195309,9.926005622,1.7977E+308,0.018299451,0
137.1,251.4244242,9.805477151,1.7977E+308,0.009585427,0
137.3,251.0944141,9.68495132,1.7977E+308,0.014378139,0
137.5,250.8890593,9.56441606,1.7977E+308,0.023527864,0
137.7,250.5216525,9.443893057,1.7977E+308,0.032677588,0
137.9,250.4733634,9.323345917,1.7977E+308,0.034420393,0
138.1,249.9871186,9.202831903,1.7977E+308,0.034856093,0
138.3,249.5906256,9.0823111,1.7977E+308,0.036163195,0
138.5,249.4800088,8.961768674,1.7977E+308,0.040520207,0
138.7,248.9995813,8.84125422,1.7977E+308,0.042698711,0
138.9,248.6828677,8.720727382,1.7977E+308,0.041827308,0
139.1,248.6054924,8.600182443,1.7977E+308,0.0387774,0
139.3,248.7524967,8.479620533,1.7977E+308,0.03485609,0
139.5,248.548804,8.359085147,1.7977E+308,0.029627676,0
139.7,248.173918,8.23856271,1.7977E+308,0.023092159,0
139.9,248.0782599,8.118019153,1.7977E+308,0.021349354,0
140.1,247.5446461,7.997508721,1.7977E+308,0.024399261,0
140.3,247.1714222,7.876986158,1.7977E+308,0.028756271,0
140.5,247.1031883,7.756440527,1.7977E+308,0.028756271,0
140.7,246.9493577,7.63590137,1.7977E+308,0.019170847,0
140.9,246.7174098,7.515368122,1.7977E+308,0.006971217,0
141.1,246.3657928,7.394843925,1.7977E+308,0.003049907,0
141.3,246.1479725,7.274309608,1.7977E+308,0.008714021,0
141.5,245.8753039,7.153779439,1.7977E+308,0.00827832,0
141.7,245.5610836,7.033252413,1.7977E+308,0.002614206,0
141.9,245.2352287,6.912726268,1.7977E+308,0.003485608,0
142.1,245.194419,6.792178562,1.7977E+308,0.010456824,0
142.3,245.030616,6.67164016,1.7977E+308,0.016992339,0
142.5,244.8327406,6.551104334,1.7977E+308,0.019606545,0
142.7,244.2426165,6.430598177,1.7977E+308,0.020042245,0
142.9,244.4793726,6.310029478,1.7977E+308,0.021349349,0
143.1,244.159335,6.189502892,1.7977E+308,0.021349348,0
143.3,243.5629782,6.068997206,1.7977E+308,0.02265645,0
143.5,243.2109458,5.94847304,1.7977E+308,0.030499067,0
143.7,243.0155635,5.827937026,1.7977E+308,0.029627665,0
143.9,242.8488519,5.707398843,1.7977E+308,0.028756262,0
144.1,242.5616403,5.586869775,1.7977E+308,0.020913645,0
144.3,242.1614078,5.466349254,1.7977E+308,0.011763925,0
144.5,242.1787706,5.345797149,1.7977E+308,0.011763925,0
144.7,241.6277053,5.225288037,1.7977E+308,0.017645887,0
144.9,241.6047628,5.104738981,1.7977E+308,0.027449157,0
145.1,241.3694908,4.984205984,1.7977E+308,0.032677568,0
145.3,240.9040222,4.863690398,1.7977E+308,0.035727473,0
145.5,240.448526,4.743174057,1.7977E+308,0.034420369,0
145.7,240.5057784,4.622618935,1.7977E+308,0.035727472,0
145.9,240.0735512,4.502100835,1.7977E+308,0.028756257,0
146.1,239.9321862,4.381560735,1.7977E+308,0.02527065,0
146.3,239.9063351,4.261011899,1.7977E+308,0.027449154,0
146.5,239.2663492,4.140509512,1.7977E+308,0.02614205,0
146.7,239.0219359,4.019977207,1.7977E+308,0.023963546,0
146.9,238.9021778,3.899435473,1.7977E+308,0.02091364,0
147.1,238.5912817,3.778908196,1.7977E+308,0.009585418,0
147.3,238.2770615,3.65838117,1.7977E+308,0.009149717,0
147.5,237.8032826,3.537866212,1.7977E+308,0.024834945,0
147.7,237.6826936,3.417324541,1.7977E+308,0.036598866,0
147.9,237.2222112,3.296808578,1.7977E+308,0.045312881,0
148.1,236.9852773,3.176275707,1.7977E+308,0.047491384,0
148.3,236.6319985,3.055751635,1.7977E+308,0.043570076,0
148.5,236.2488024,2.935229826,1.7977E+308,0.033113257,0
148.7,235.6852719,2.814721657,1.7977E+308,0.025706343,0
148.9,235.3860103,2.6941935,1.7977E+308,0.019170832,0
149.1,235.1889661,2.573657612,1.7977E+308,0.010456817,0
149.3,234.9636667,2.45312386,1.7977E+308,0.007406912,0
149.5,234.3868396,2.332616697,1.7977E+308,0.016556626,0
149.7,234.110016,2.212086843,1.7977E+308,0.024399238,0
149.9,234.0151891,2.091543223,1.7977E+308,0.030934748,0
150.1,233.5031827,1.971031157,1.7977E+308,0.033548951,0
150.3,233.055166,1.850514251,1.7977E+308,0.032241848,0
150.5,232.4185045,1.730011613,1.7977E+308,0.02744914,0
150.7,232.3004086,1.609469753,1.7977E+308,0.022220732,0
150.9,232.1224782,1.488932419,1.7977E+308,0.018735127,0
151.1,231.7517478,1.368409667,1.7977E+308,0.014813821,0
151.3,231.1209036,1.247906589,1.7977E+308,0.011763916,0
226.5,230.5323857,1.13244402,1.7977E+308,0.029627649,0
226.7,230.3569483,1.011906498,1.7977E+308,0.031806152,0
226.9,229.8432799,0.891394557,1.7977E+308,0.034420355,0
227.1,229.4509425,0.77087344,1.7977E+308,0.030934749,0
227.3,228.7735602,0.650373882,1.7977E+308,0.027449142,0
227.5,228.4659884,0.529846353,1.7977E+308,0.023092135,0
227.7,227.6755854,0.409355343,1.7977E+308,0.012199618,0
227.9,226.751386,0.288874453,1.7977E+308,0.006535509,0
228.1,225.4956039,0.168418642,1.7977E+308,0.018299424,0
228.3,223.8974356,0.047988728,1.7977E+308,0.028320534,0
228.374,223.3917931,0.003423179,1.7977E+308,0.032677538,0
,,,,,