File: Test_0.csv
Time On Sample,Displacement Into Surface,Load On Sample,Harmonic Contact Stiffness,Harmonic Displacement,Harmonic Load
0,0,0,611.3372157,0.300192106,2.228229467
0.2,0.311971522,0.000734714,7249.104103,0.22046039,2.305591019
0.4,0.451922306,0.001481214,10390.63669,0.209132388,2.384042148
0.6,0.507940341,0.002232976,12862.09071,0.192140382,2.482106046
0.8,0.31963878,0.003003218,15266.13805,0.172534219,2.579080313
1,0.598369916,0.003738134,17682.89564,0.155542215,2.67932344
1.2,0.599540695,0.004494044,19351.03525,0.147264058,2.763222546
1.4,0.615669816,0.005248823,22519.88053,0.138550209,3.033443052
1.6,1.15118585,0.005964314,25283.96992,0.133321904,3.284050853
1.8,0.829090213,0.006744675,27291.60463,0.132014824,3.532479338
2,0.921673088,0.00749367,29370.18121,0.13114344,3.781997474
2.2,0.864672533,0.00825398,31825.17759,0.129836362,4.051128377
2.4,0.655595491,0.009025793,35689.17168,0.132450515,4.611182117
2.6,1.108840639,0.009747507,38368.15974,0.137243137,5.128741671
2.8,0.879819136,0.010520828,40435.27094,0.143342829,5.643032255
3,0.949964498,0.01127152,42154.67203,0.149878217,6.155143719
3.2,0.971079734,0.012025921,43373.50625,0.155977913,6.597520841
3.4,1.125989041,0.012770201,45190.81731,0.169920074,7.508425514
3.6,0.887826329,0.013544214,45705.29252,0.186476386,8.339789325
3.8,0.965450862,0.01429434,44979.12311,0.207825319,9.153719669
4,1.249999145,0.015028814,43903.11008,0.231352718,9.953485349
4.2,1.258649096,0.015784157,42979.16875,0.252265959,10.63012623
4.4,1.047910011,0.016556095,43853.87999,0.27579335,11.84502882
4.6,1.289245304,0.017293838,44491.37849,0.29757798,12.98583894
4.8,0.916457499,0.018078033,45456.05402,0.31631275,14.12011108
5,1.10377655,0.018819861,45320.45367,0.341147226,15.16830528
5.2,1.380845665,0.019554901,44569.49459,0.367724475,16.06504534
5.4,1.012212953,0.020338782,43726.66632,0.405629713,17.39980361
5.6,1.056596724,0.021091422,42932.01838,0.442663578,18.63431912
5.8,1.182420365,0.021837902,42014.4434,0.481004522,19.80127959
6,1.073896625,0.022602108,41484.1958,0.515424225,20.94971666
6.2,0.74016672,0.02338335,40828.19338,0.547229766,21.86933772
6.4,0.71391387,0.024141334,39544.99836,0.598641479,23.14198911
6.6,0.831427318,0.024888443,37728.73772,0.65745997,24.23376726
6.8,0.867916407,0.025641681,35424.58156,0.726517232,25.13758949
7,0.817979513,0.026401457,32509.37938,0.816705577,25.95642297
7.2,0.913886466,0.0271502,29663.28629,0.914082854,26.63742238
7.4,1.003145267,0.027899446,27233.67991,1.009499517,27.21926826
7.6,0.419278629,0.028699609,24767.68693,1.121472444,27.80329253
7.8,0.833881387,0.029424246,22969.90337,1.212532208,28.17375664
8,0.840869299,0.030179715,21231.21213,1.31404856,28.60196897
8.2,0.989961473,0.030924436,20377.8375,1.378095371,28.95064078
8.4,1.106228395,0.031671638,19749.63441,1.435606792,29.26771428
8.6,1.54202216,0.032394671,19175.62344,1.49529671,29.61420731
8.8,1.602610806,0.033146085,19283.65217,1.510763801,30.01027659
9,2.050038856,0.033868236,19830.88664,1.501396459,30.49024554
9.2,1.834313643,0.034640549,20716.18507,1.470026576,31.03504472
9.4,1.854182353,0.035395042,22538.81461,1.395958849,31.83807916
9.6,1.864909852,0.036150226,24786.02034,1.310998808,32.61496317
9.8,1.654170756,0.036922163,27646.75533,1.222117516,33.60213937
10,1.313377174,0.037703938,29656.71231,1.172884234,34.38665
10.2,1.186986522,0.038469496,30689.39041,1.161556219,35.09270982
10.4,1.239264976,0.039221539,29436.8785,1.229959948,35.68654124
10.6,2.573390441,0.03987662,26342.01073,1.370688753,35.86523783
10.8,2.698383079,0.04062316,23622.76049,1.512724537,35.83799811
11,2.958000826,0.041359515,21096.15829,1.66695973,35.71705299
11.2,2.703217697,0.042134781,19866.28973,1.750176979,35.69526067
11.4,2.959511368,0.042871388,20165.90669,1.730135153,35.94368966
11.6,3.051263241,0.043620441,22549.95753,1.586792311,36.70096103
11.8,3.004234908,0.044379991,25928.46863,1.426457445,37.56719214
12,2.797650892,0.04515161,31360.56689,1.235624086,38.77228823
12.2,2.773060078,0.045909464,36425.4162,1.106223396,39.84445354
12.4,2.687804864,0.046671906,40382.80114,1.032591348,40.97000902
12.6,2.440500912,0.047446606,41078.23081,1.032591331,41.65536629
12.8,2.605382469,0.048190128,40031.03501,1.074417828,42.33309726
13,2.983835959,0.048917495,38214.52932,1.137157585,42.91712293
13.2,3.052319295,0.049668309,36631.71645,1.196411779,43.39000903
13.4,2.623853156,0.050456712,35328.71412,1.252180391,43.87487973
13.6,2.629179032,0.051212303,34061.65035,1.310998887,44.39026003
13.8,2.629518793,0.051968271,33444.23586,1.346289984,44.81847227
14,2.762821624,0.052714181,32911.42386,1.382452479,45.32949459
14.2,2.814684575,0.053466252,32670.51675,1.404672805,45.76315505
14.4,2.751035859,0.05422706,32565.09319,1.424278964,46.32538796
14.6,2.836139578,0.054976616,32576.0995,1.436042672,46.76449667
14.8,2.912102086,0.055726863,32477.86296,1.454341767,47.26026427
15,2.83765012,0.056488488,32474.30509,1.46610546,47.67540125
15.2,2.856272304,0.057243073,32373.67771,1.483097472,48.09707609
15.4,2.971292714,0.057990366,32144.08323,1.508803345,48.55688725
15.6,2.955843111,0.058747527,32029.7364,1.526231047,48.90882754
15.8,2.989423641,0.059500981,32031.11259,1.540173213,49.34902557
16,3.015524998,0.060255,31930.19408,1.555858149,49.68026378
16.2,3.449656189,0.060981936,31817.523,1.572414513,50.00605498
16.4,3.596255336,0.061726839,31903.38675,1.581999767,50.44952196
16.6,2.997430842,0.062524345,32235.6118,1.577642777,50.81889473
16.8,3.876157927,0.063213868,33005.63636,1.559779476,51.33754599
17,3.733562379,0.063980646,34145.57344,1.52579544,51.84529865
17.2,3.544429754,0.064750944,35975.03604,1.470462462,52.50341607
17.4,3.679394633,0.065496726,38650.11209,1.3985732,53.40233567
17.6,3.654803818,0.066254578,40846.99681,1.348468551,54.22934112
17.8,3.71082187,0.067006332,42487.71696,1.314920227,54.9081616
18,3.508392937,0.067777636,43862.12938,1.294878351,55.71337464
18.2,3.620920297,0.068525115,44520.09737,1.291392821,56.34752166
18.4,3.075280428,0.06932238,44888.8739,1.299670932,57.17452575
18.6,3.398886666,0.070053895,44333.45399,1.327119593,57.69099645
18.8,3.535513582,0.070799552,42948.59946,1.380709794,58.20201892
19,4.009534317,0.071519687,41155.45284,1.447806499,58.59427576
19.2,4.190205261,0.072262011,39489.1396,1.51185333,58.8165545
19.4,3.861461394,0.073042869,37715.52488,1.585921038,59.06716138
19.6,4.182574593,0.073774569,37516.48975,1.601606007,59.3776981
19.8,4.241916725,0.074526071,38551.35483,1.57590015,59.9878736
20,4.110124423,0.07529203,40125.28518,1.531459491,60.59695919
20.2,4.157832282,0.076044424,42534.91931,1.465669914,61.37493292
20.4,3.883104011,0.076825323,46181.5211,1.377659983,62.50375676
20.6,3.935796082,0.077589309,48203.58468,1.338011962,63.29916416
20.8,4.132253285,0.078349989,49533.33401,1.319712891,64.16321693
21,3.833421774,0.079155869,49938.25496,1.324505483,64.9586231
21.2,3.638466387,0.079961999,49543.08128,1.345854405,65.51976601
21.4,4.072591312,0.080728496,48189.91342,1.396394782,66.15718296
21.6,3.899239889,0.081548926,47146.13173,1.436042794,66.58757385
21.8,4.215357544,0.082340336,45873.67876,1.485711783,67.05392322
22,4.209038433,0.083164241,44754.23595,1.531895202,67.47450866
22.2,4.168646222,0.083998958,44091.07556,1.563265064,67.83080727
22.4,4.307752857,0.084828396,44174.77384,1.57110755,68.30369387
22.6,4.475943844,0.085663973,44637.88992,1.568493408,68.88662993
22.8,4.30258455,0.086533888,45718.61048,1.548015841,69.56980796
23,4.284624488,0.087400705,46591.55718,1.532766596,70.1396682
23.2,4.62150827,0.088249451,47441.10736,1.519260161,70.73132164
23.4,4.646758467,0.089130266,48112.61075,1.514467546,71.4613531
23.6,4.475055652,0.090035019,48212.03937,1.524052768,72.04319841
23.8,4.588391048,0.090927075,47954.61854,1.543658947,72.58690875
24,4.842167284,0.091817476,47951.27207,1.552808518,73.03037647
24.2,4.383758522,0.092770874,48077.08188,1.558472474,73.52505283
24.4,4.621742474,0.093680804,48239.00104,1.565879271,74.13413956
24.6,5.07121937,0.094584035,48709.2485,1.564136552,74.75630214
24.8,4.599094367,0.095566244,49126.80743,1.562829425,75.31308585
25,4.382506271,0.096538806,49359.97736,1.566750637,75.82955489
25.2,4.767990122,0.097475508,49456.20926,1.57372176,76.30244224
25.4,4.524390844,0.098469313,49603.20825,1.581564201,76.91915445
25.6,4.653502146,0.099444863,49679.97739,1.589406683,77.46613365
25.8,4.864467294,0.100424028,49929.29584,1.592456555,78.03054672
26,5.06961374,0.101413507,50282.52982,1.590713808,78.52195673
26.2,4.936533726,0.102438594,50773.19371,1.585921175,79.06021824
26.4,4.797219421,0.103474512,51415.11701,1.579821463,79.75538178
26.6,4.83657264,0.104507171,51946.66506,1.574157464,80.28383756
26.8,5.296004505,0.105518308,52811.88399,1.561522428,80.99425787
27,5.383553572,0.106567936,53724.82278,1.548015966,81.72973768
27.2,5.534673945,0.107623292,54431.8313,1.539302129,82.35952662
27.4,5.192998134,0.108726661,55670.60151,1.52056731,83.23556291
27.6,5.202841779,0.109814329,56726.65608,1.504882377,83.93181687
27.8,5.398832032,0.110898778,57752.90892,1.493554389,84.76536095
28,5.247869944,0.112020549,58419.81919,1.488326062,85.41367185
28.2,5.21989693,0.113144285,59316.76516,1.480919285,86.26682765
28.4,5.407987173,0.114262844,59547.47985,1.487454694,86.94673811
28.6,5.847874494,0.115373649,59547.10662,1.500961212,87.68657795
28.8,5.576407404,0.11654976,59429.52456,1.516210428,88.3741138
29,5.46698726,0.11772515,59308.25713,1.53145966,89.03767913
29.2,5.669197516,0.118888687,59225.4044,1.543659076,89.59337576
29.4,5.299664559,0.120107358,59462.58134,1.548451656,90.22207261
29.6,5.662257768,0.121282563,59892.45165,1.550194466,90.98806261
29.8,5.613494472,0.122500957,60272.256,1.552372925,91.71264586
30,5.607942247,0.123728265,60563.42438,1.554551388,92.31192534
30.2,5.655573307,0.12496385,60802.62223,1.560215398,93.04195683
30.4,5.794614535,0.126204879,60880.91245,1.568057882,93.64777485
30.6,5.866341203,0.12746352,60976.97357,1.576771743,94.33967044
30.8,6.151637843,0.128718676,61203.50568,1.580257316,94.90081543
31,6.150230771,0.130008228,61407.26126,1.586357014,95.59162134
31.2,6.417240916,0.131290394,61595.50863,1.59071397,96.16475169
31.4,6.09090113,0.132630468,62038.18707,1.592021013,96.94272398
31.6,6.044612781,0.133962609,62426.54853,1.594199472,97.67711355
31.8,6.470341343,0.135272343,62720.32043,1.595506597,98.22845275
32,6.409921415,0.136632269,63137.15337,1.596813669,98.9464983
32.2,6.409332716,0.138001318,63607.00405,1.595506592,99.57955531
32.4,6.251679169,0.139395951,64091.18241,1.595942268,100.3607971
32.6,6.482109486,0.140775103,64291.09666,1.599863528,100.9252108
32.8,6.303676024,0.142199169,64392.60799,1.608577362,101.6181949
33,6.422745269,0.143614857,64688.32869,1.611627225,102.3035534
33.2,6.786131966,0.145026308,65013.03392,1.613370036,102.9278958
33.4,6.654228785,0.146489656,65316.89556,1.615112793,103.5500561
33.6,7.029245146,0.147929253,66053.4918,1.608577445,104.3313007
33.8,6.849137021,0.149432824,67059.93408,1.59637803,105.1550367
34,6.988970191,0.150919703,67731.91161,1.592456812,105.9384593
34.2,7.087251221,0.15241708,68011.03104,1.595070979,106.5878611
34.4,7.429848363,0.153918719,68464.74117,1.595071017,107.2732206
34.6,7.333664796,0.155468807,68553.12365,1.604656247,107.996714
34.8,7.177645341,0.157039064,68556.9202,1.615548548,108.6886088
35,7.327438586,0.158601708,68810.98468,1.618598414,109.2791721
35.2,7.05424042,0.160212075,69208.85129,1.61946977,109.9361995
35.4,7.466630788,0.161786502,69822.60224,1.617727045,110.7926264
35.6,7.833312556,0.163380367,70371.82192,1.614241545,111.4507463
35.8,8.061211515,0.165000816,70832.97063,1.614241571,112.2505133
36,8.087170128,0.166652919,71119.5239,1.615984345,112.8737643
36.2,8.262709632,0.168310224,71360.45399,1.619034214,113.5177183
36.4,8.178968378,0.170003904,71573.4812,1.625569597,114.3327381
36.6,8.359488632,0.171694602,71963.7216,1.628183774,115.0900109
36.8,8.367154121,0.173415381,72483.27106,1.626876697,115.750308
37,8.383958098,0.175152614,73268.33632,1.622519772,116.5991057
37.2,8.552004842,0.176895968,73996.86602,1.617291479,117.3193318
37.4,8.399275253,0.178681125,74738.71627,1.612063149,118.0700647
37.6,8.106100503,0.180494908,75657.11181,1.605092034,118.9820577
37.8,8.290759135,0.182290474,76297.15118,1.601606513,119.7011944
38,8.394805986,0.1841103,76845.62373,1.602042218,120.555441
38.2,8.768100255,0.185928133,77052.77973,1.607706265,121.2625932
38.4,8.3801777,0.187821865,77350.6526,1.611627461,121.9969808
38.6,8.678674315,0.189682427,77408.74656,1.621212732,122.794569
38.8,8.829246463,0.191572983,77422.00979,1.629055219,123.4287172
39,8.805301459,0.193495886,77572.30003,1.635154915,124.195795
39.2,8.842848866,0.195433244,77692.63345,1.639947541,124.8680779
39.4,9.023328542,0.197379281,77776.35355,1.647354338,125.6994432
39.6,8.833170348,0.199373103,77881.80582,1.652146937,126.3303203
39.8,8.872370376,0.201369583,78103.29617,1.656939565,127.0995777
40,9.042868319,0.203376133,78068.78669,1.665217748,127.6629016
40.2,8.984832674,0.205420123,78280.60585,1.66957467,128.2817937
40.4,9.088842587,0.20747237,78640.65677,1.673060221,129.0750227
40.6,8.929416004,0.209565228,78941.51416,1.675238671,129.6960933
40.8,9.193806087,0.211646923,79170.61636,1.680031321,130.4457393
41,9.228831422,0.213767002,79535.94414,1.680467019,131.0689904
41.2,9.245570956,0.215909669,79532.71888,1.688309492,131.6584638
41.4,9.60468717,0.218047813,79360.08363,1.700944628,132.3361969
41.6,9.60646151,0.220234648,79223.15618,1.710529866,132.8276062
41.8,9.561279764,0.22244691,79089.87375,1.721857875,133.4116312
42,9.399751746,0.224690161,79155.7437,1.728828938,134.0239849
42.2,9.942924806,0.226902503,79751.35442,1.724036385,134.6744791
42.4,9.852857347,0.229185168,80549.04707,1.714886825,135.32388
42.6,9.717080162,0.231494242,81599.35153,1.702687411,136.1530642
42.8,10.0001332,0.233794751,82463.53543,1.693102203,136.8525889
43,10.03470767,0.236137251,83404.83307,1.683952659,137.7079244
43.2,10.08548331,0.238501987,83886.68095,1.682645587,138.3834763
43.4,10.05481522,0.240896706,84197.12477,1.684824048,139.0426841
43.6,10.41056746,0.243286254,84266.08216,1.692666561,139.7683595
43.8,10.24651307,0.245739212,84081.47854,1.703123169,140.3066204
44,10.28189949,0.248201685,83804.67239,1.716629651,140.928782
44.2,10.21839063,0.250696367,83530.37904,1.72839335,141.4212808
44.4,10.19435125,0.25321302,83243.48665,1.741028439,141.976976
44.6,10.5488373,0.255726305,83399.56062,1.744514025,142.5457495
44.8,10.63116039,0.258285532,84035.68385,1.739721414,143.2605271
45,11.13688395,0.260838329,84562.56434,1.73580024,143.8554522
45.2,11.26282742,0.263445523,85158.5043,1.731007634,144.497227
45.4,11.44860015,0.266074447,85799.23256,1.725779343,145.1651527
45.6,11.23173957,0.268760495,86315.32073,1.724036547,145.9278706
45.8,11.60406774,0.271428734,86847.55857,1.721858127,146.6807863
46,11.45118715,0.274163641,87634.09234,1.714015638,147.3454415
46.2,11.49026776,0.276911436,88649.37342,1.703123323,148.109251
46.4,11.49942726,0.279689145,89638.35666,1.693538082,148.9013897
46.6,11.88669633,0.282466068,90907.43503,1.681338728,149.8602398
46.8,11.69640222,0.28531473,91690.50046,1.677853163,150.7798606
47,11.93989589,0.288159045,91910.26891,1.680903042,151.4205469
47.2,12.57562638,0.291002167,92042.03823,1.68613143,152.0928346
47.4,12.53656422,0.293925163,92146.20144,1.693102513,152.9470803
47.6,12.89804897,0.296847084,92084.544,1.700073641,153.5311084
47.8,12.88972521,0.29982645,92603.57661,1.699637948,154.3864437
48,13.13319572,0.302816601,93139.9398,1.697895206,155.0696247
48.2,13.26945989,0.305845025,94276.78307,1.688745671,156.0884015
48.4,13.25862869,0.308915066,95241.99732,1.681338892,156.8925257
48.6,13.20790365,0.312018877,96536.48685,1.670882257,157.9167492
48.8,13.7314084,0.315110295,97331.06958,1.666089695,158.7121606
49,13.71723835,0.318273493,98290.30295,1.660425687,159.7243984
49.2,14.22078865,0.321429279,98884.86357,1.659118666,160.5514083
49.4,14.21408766,0.324655562,99340.49864,1.659990052,161.4263572
49.6,14.3436688,0.3279039,99702.71073,1.663039917,162.3884746
49.8,14.18238777,0.331206943,100026.9602,1.665218364,163.1490142
50,14.0967243,0.334537375,100384.6728,1.669139592,164.1089505
50.2,14.34844957,0.337875783,100404.5189,1.676110708,164.8455217
50.4,14.50460223,0.341254941,100614.3,1.680903349,165.6572746
50.6,14.7189209,0.344663619,101063.5845,1.683081839,166.6117657
50.8,15.18669522,0.348087268,101587.4381,1.682210508,167.4039083
51,15.03203009,0.351592704,102265.8682,1.680467719,168.3583965
51.2,15.01032258,0.355123144,103125.5808,1.675239401,169.2289866
51.4,15.33763781,0.358662712,104122.7808,1.668704045,170.1725827
51.6,15.29929571,0.36228369,105019.4997,1.665654191,171.2600024
51.8,15.02660305,0.365940811,105340.9458,1.668704011,172.0466919
52,15.45944348,0.369562592,105726.3119,1.672625298,173.0262454
52.2,15.7975389,0.373246455,105781.9624,1.680032118,173.7922365
52.4,15.6228891,0.377006231,105446.5812,1.693102888,174.5342523
52.6,15.88534982,0.380770653,105072.7283,1.707045094,175.3383796
52.8,16.04558906,0.384580646,104960.838,1.71532328,176.0008575
53,16.26482464,0.388424512,104678.4166,1.727087017,176.7592204
53.2,16.57879037,0.392299729,104821.5456,1.730572599,177.4467612
53.4,17.02322007,0.39620408,105502.2089,1.727958495,178.4143296
53.6,16.49867409,0.400221373,106620.1483,1.717501801,179.2260766
53.8,16.55915987,0.40423437,108257.2613,1.701816861,180.3440065
54,16.74013713,0.408278636,109815.9179,1.686567628,181.302856
54.2,16.92609406,0.412363177,111781.1432,1.667397157,182.3989946
54.4,16.79376378,0.416512848,113910.14,1.64953373,183.7936815
54.6,16.80768641,0.420693069,114751.1807,1.648662346,184.9737184
54.8,17.33351073,0.424876608,114773.4737,1.656069187,185.8094459
55,17.13384782,0.429157161,114484.946,1.669139956,186.7846354
55.2,17.20924573,0.433459881,113223.0393,1.693538774,187.4253212
55.4,17.23477558,0.437809548,112063.8714,1.716194815,188.0333184
55.6,17.12068709,0.442213516,111247.3262,1.734493909,188.7600801
55.8,17.27168701,0.446641505,110975.5624,1.744079175,189.3778845
56,17.83569686,0.45108265,110893.5201,1.75235741,190.1427889
56.2,18.04402301,0.455595391,111378.4964,1.751050357,190.85321
56.4,18.06951753,0.460167277,112362.3917,1.74495066,191.8458364
56.6,18.31439409,0.464768373,113064.3546,1.741029451,192.6063787
56.8,18.60164532,0.469412509,114348.8828,1.731008551,193.6698308
57,19.18223928,0.474081085,115345.6691,1.723601835,194.5382473
57.2,19.49773032,0.47881681,116303.5708,1.71750217,195.4535151
57.4,19.39936577,0.483631241,117394.517,1.710095376,196.4243477
57.6,19.64004983,0.48846806,118959.8903,1.698767382,197.6163723
57.8,19.77767965,0.493361339,120244.1712,1.691360614,198.7953208
58,19.79646576,0.498312765,120846.6469,1.69092493,199.6746281
58.2,20.18006187,0.503286208,121429.4316,1.691360666,200.6214942
58.4,20.22126969,0.508335599,121361.1825,1.701381614,201.6566146
58.6,20.34141638,0.513429709,121257.5065,1.709224102,202.4127982
58.8,20.62360388,0.518562772,120940.5381,1.721423545,203.3215273
59,20.51852771,0.523776853,120948.2397,1.727523239,204.0668127
59.2,20.43837384,0.529041363,121296.8571,1.729266003,204.8763847
59.4,20.75710127,0.53432868,122084.289,1.727087573,205.9866903
59.6,21.20629046,0.539659273,122360.9734,1.729701787,206.784282
59.8,21.12361811,0.545083786,122930.9292,1.730137468,207.7823543
60,21.29065873,0.550543823,123429.0476,1.730137492,208.608273
60.2,21.46890938,0.556057945,123652.836,1.734058749,209.423296
60.4,21.22291533,0.561659733,124527.7421,1.732315948,210.5314166
60.6,21.32261682,0.567291455,125366.8927,1.728830416,211.4150827
60.8,21.60471828,0.572965919,126466.7732,1.723602132,212.531926
61,22.18514701,0.578674714,126823.5163,1.725780667,213.3371463
61.2,22.1826058,0.584485264,127325.3063,1.726652054,214.2251701
61.4,22.18587246,0.590353734,127602.013,1.73144468,215.2886196
61.6,22.26599915,0.596275242,127761.5709,1.735365929,216.0611474
61.8,22.59417595,0.602237532,128162.807,1.737544435,217.0537762
62,22.4324567,0.608296888,129173.6171,1.731009018,217.9853829
62.2,22.17765351,0.614424066,130361.9992,1.722730819,219.0150523
62.4,22.61591156,0.62056024,131463.969,1.717502553,220.2495732
62.6,23.23947738,0.626743992,131975.7671,1.717502627,221.1441421
62.8,23.43173372,0.633022592,131894.2873,1.726216514,222.1607409
63,23.73533684,0.639355472,131333.6407,1.738851655,222.8602674
63.2,24.17106211,0.64574192,129994.8852,1.761943449,223.5390933
63.4,24.33503347,0.652213311,129349.1239,1.77544996,224.1830488
63.6,24.34193162,0.658761574,129176.2561,1.782421053,224.8193752
63.8,24.46599319,0.665366784,129923.1186,1.779371217,225.7477162
64,25.01885085,0.672005717,131147.1528,1.770657419,226.7599607
64.2,25.05812718,0.678750434,133356.6474,1.750179842,227.8811599
64.4,25.18215685,0.685556427,135724.5343,1.72926658,229.1026029
64.6,25.71337575,0.692399871,138614.5874,1.705303513,230.6345869
64.8,25.66370031,0.699356248,140125.3413,1.695718256,231.781935
65,25.76775259,0.706370732,141945.5782,1.684825937,233.2136713
65.2,26.08869004,0.713439268,142103.7367,1.690489987,234.2509746
65.4,26.15366186,0.72059826,141536.6793,1.703996488,235.195658
65.6,26.56765092,0.727802654,140323.4838,1.723602736,235.9049927
65.8,27.12622608,0.735068473,139019.3783,1.745387469,236.7145728
66,27.36401567,0.742431609,138047.7816,1.761943845,237.3291095
66.2,27.66495107,0.749863962,137810.4865,1.770222056,238.037354
66.4,27.91102724,0.757375188,138547.4644,1.7693507,239.126957
66.6,27.95432234,0.764977373,140086.1803,1.757586985,240.1108665
66.8,28.10646904,0.772647516,142739.3531,1.735802336,241.52408
67,28.39156682,0.78038457,145014.9699,1.717938943,242.7542424
67.2,28.56363341,0.788208043,147447.1455,1.701818309,244.3973617
67.4,28.96671129,0.796092589,148638.1131,1.696154343,245.5109382
67.6,29.45204767,0.804049979,149204.5339,1.699204254,246.826092
67.8,29.33986736,0.812132747,149608.7033,1.701818402,247.8350604
68,29.90080102,0.820245588,149633.1415,1.710096643,249.0336284
68.2,29.90992389,0.82848186,150277.4952,1.710532338,250.1264965
68.4,30.02623529,0.836792818,151106.4486,1.709225272,251.2760272
68.6,30.046135,0.845194558,152261.5089,1.705739728,252.6587304
68.8,30.46408031,0.85365035,152514.4434,1.709661019,253.6796913
69,30.82716472,0.862195425,153314.9257,1.709225368,254.9992017
69.2,31.11627463,0.870831997,152914.0664,1.719682046,255.9558751
69.4,31.51339647,0.879591244,152342.6496,1.732317204,256.8874881
69.6,32.09499793,0.888380817,152045.3125,1.742773917,257.9335118
69.8,32.28268856,0.897243668,152509.3509,1.743645327,258.8139118
70,32.50027466,0.906238162,153269.6773,1.743645354,260.0026683
70.2,33.04693073,0.915298045,154773.3092,1.73493155,261.1794443
70.4,33.12155237,0.924484914,156663.8658,1.722732141,262.4826081
70.6,33.42718319,0.933746534,159139.1894,1.706611518,264.0973998
70.8,33.37712221,0.943128231,160626.7571,1.699204723,265.3667849
71,33.74172578,0.952572562,162317.1175,1.691362283,266.9042146
71.2,33.93678597,0.962124693,163667.997,1.686133984,268.2291725
71.4,34.41936419,0.971751045,165357.5796,1.680470024,269.9649121
71.6,34.36758047,0.981514712,166333.3821,1.678727245,271.2310286
71.8,34.70054392,0.991347325,168046.8097,1.67219188,272.9526012
72,35.0924942,1.00127417,169013.6302,1.670449152,274.2492316
72.2,35.2716872,1.011316982,169951.507,1.669142092,275.5807265
72.4,35.38770656,1.021465408,170532.0376,1.673063349,277.2717879
72.6,35.5020477,1.031715802,170294.7833,1.682212928,278.4354834
72.8,36.03437612,1.04203753,169460.7596,1.69789796,279.6809041
73,36.19854568,1.052490805,169065.3678,1.709661707,280.960098
73.2,36.96685101,1.063003162,168179.999,1.724475381,281.8960756
73.4,37.26145746,1.073657114,167617.8569,1.736674838,282.8767206
73.6,37.32336095,1.084435648,168132.9195,1.739724702,284.1624507
73.8,37.24895974,1.095332787,168892.6841,1.739289003,285.2640358
74,37.67730904,1.106301034,169981.9673,1.737110584,286.644566
74.2,37.82392459,1.117401014,171727.474,1.727961036,287.9564476
74.4,38.16996755,1.128597269,174476.1256,1.710533334,289.5374639
74.6,38.40712885,1.139914268,177347.7287,1.693977002,291.433373
74.8,38.62682062,1.151346316,179529.2668,1.6822133,292.9806102
75,38.99690901,1.162881775,181610.7619,1.673499469,294.8634445
75.2,39.47999791,1.174524502,182202.6625,1.67567799,296.3028158
75.4,39.89991059,1.186289054,181535.8104,1.688748855,297.5427879
75.6,40.04639842,1.198192665,180633.7511,1.704869544,298.8361465
75.8,40.26101101,1.210210645,179924.6255,1.717504684,299.8418514
76,40.58363722,1.222341098,179410.3774,1.730139842,301.1254062
76.2,40.74585689,1.234605739,179613.2956,1.735368185,302.2662209
76.4,41.08340253,1.246980168,180879.8572,1.731446983,303.6064352
76.6,41.30209235,1.259487869,182009.5016,1.729704233,305.1242528
76.8,41.79250616,1.272101131,183264.0055,1.72578305,306.4241543
77,41.94134993,1.28486738,184365.4413,1.724475988,307.9637629
77.2,43.11565397,1.297683957,184876.3647,1.726654593,309.2298971
77.4,42.94035846,1.310731802,184911.1354,1.732754287,310.457875
77.6,43.02348985,1.323891074,185007.5747,1.738854013,311.8231466
77.8,43.47889793,1.337154224,185072.7857,1.743211005,312.8975004
78,43.81586423,1.350559812,185226.899,1.748003677,314.2017569
78.2,43.80876615,1.364126181,185689.5655,1.749746453,315.3567355
78.4,43.99984508,1.37781375,186453.4617,1.749746477,316.6272123
78.6,44.76763123,1.391595015,187669.6073,1.747132406,318.1559347
78.8,45.05672686,1.405551158,189005.6482,1.743211197,319.5440914
79,45.55397117,1.419631723,190784.1038,1.735804461,320.9943586
79.2,45.99219044,1.433858356,192289.0834,1.730576187,322.4184744
79.4,46.34520727,1.448234351,193951.8834,1.726219291,324.204336
79.6,46.86565206,1.462742006,194907.7666,1.725347965,325.5292999
79.8,47.66779013,1.477373998,195859.0585,1.725783755,327.0874424
80,47.93389573,1.492193736,195923.4808,1.731447809,328.2010204
80.2,48.14180613,1.507166763,196661.4402,1.732319222,329.5357845
80.4,48.67836186,1.522264885,197505.2637,1.733626369,331.2116
80.6,48.83096141,1.537543491,198447.8093,1.732319306,332.5104073
80.8,49.14558585,1.552963274,198896.709,1.73624059,334.02278
81,49.55575321,1.568530669,199480.986,1.737547722,335.283455
81.2,49.6110493,1.584281477,199536.9776,1.743211751,336.4722113
81.4,50.37601306,1.600136686,200217.3222,1.745826008,338.0793862
81.6,51.11269678,1.616153322,200770.4857,1.747568873,339.3073792
81.8,51.54187676,1.632354284,201959.2147,1.745826149,340.8873101
82,52.08321888,1.648709442,203078.7369,1.74321205,342.2199006
82.2,52.67190318,1.665225295,204583.7013,1.737983792,343.6952325
82.4,52.84588104,1.681938548,205714.8527,1.73754812,345.4484029
82.6,53.44448456,1.698787518,207177.6094,1.734062639,347.1623578
82.8,53.61923984,1.715838018,209094.0012,1.725784472,348.6725482
83,54.01501982,1.733042975,211848.8604,1.713149389,350.6447342
83.2,54.70329219,1.75039855,214465.5853,1.701385728,352.4676504
83.4,55.07076223,1.767952963,217247.2169,1.689186335,354.4060587
83.6,55.39665314,1.785686895,219970.5414,1.679165407,356.6408366
83.8,55.71919163,1.803599299,220709.6087,1.681343916,358.2621706
84,55.81898754,1.821708507,220764.2324,1.689622119,360.0828964
84.2,56.27277007,1.839972732,220584.5446,1.697900362,361.5418814
84.4,56.51544375,1.858436528,220152.6158,1.707921359,362.9997732
84.6,57.60988597,1.877021055,219424.3155,1.720556621,364.5873427
84.8,57.55831854,1.895879462,219294.9331,1.727527724,365.8654448
85,57.89979464,1.914897402,219392.7233,1.734934568,367.496585
85.2,58.33597693,1.934099289,220141.2861,1.736241703,368.9217921
85.4,59.08126897,1.953470535,221200.5024,1.735370404,370.4668612
85.6,59.72265229,1.97304428,223492.73,1.727527984,372.482637
85.8,60.42383801,1.992810123,225802.0615,1.717942792,374.1791598
86,60.30975895,2.012836657,228467.8053,1.707486116,376.3485557
86.2,61.15381705,2.032991463,229974.6606,1.70400066,378.0853975
86.4,61.5075396,2.053386034,231387.0007,1.704000703,380.2482647
86.6,62.33158845,2.073949809,232335.9904,1.704872188,381.8380097
86.8,62.98856893,2.094732932,233419.1626,1.707050738,383.8450687
87,63.48845294,2.115736717,234859.6219,1.704872325,385.4969152
87.2,64.22846895,2.136933744,236544.4553,1.701386857,387.3329093
87.4,64.49310595,2.158380576,239289.9468,1.692673,389.8182973
87.6,64.78097736,2.18004095,240718.8174,1.690058867,391.6041611
87.8,65.13363397,2.201914099,243258.4381,1.682652103,393.9805899
88,65.39816723,2.22401363,245174.6553,1.677859495,395.8808617
88.2,66.28343934,2.246288132,247301.0638,1.672631263,397.9238827
88.4,66.82712548,2.268812272,249599.2483,1.669581465,400.5302239
88.6,67.53698027,2.291550191,251438.6569,1.666531685,402.5122237
88.8,67.7897361,2.314551223,251894.6741,1.673067133,404.8025735
89,68.38566774,2.337757252,251475.5358,1.682216789,406.427182
89.2,68.9948587,2.361195478,251462.3297,1.689623668,408.2010678
89.4,69.99293109,2.384839739,250684.7892,1.703130318,410.2724219
89.6,70.48237957,2.408760158,249933.2076,1.715329827,412.0735456
89.8,70.79644397,2.432934207,249552.581,1.724043758,413.5052891
90,71.40382098,2.457328921,249243.2949,1.734064808,415.2693676
90.2,72.22805612,2.481952293,248512.4997,1.744957274,416.6183135
90.4,72.66915022,2.506852162,247994.615,1.754542612,418.0130132
90.6,73.34953929,2.531984135,247641.3168,1.764127979,419.590772
90.8,73.78058122,2.557387554,248412.8707,1.764999421,421.0312357
91,74.23817537,2.583044039,249378.373,1.765435173,422.7615344
91.2,74.93589445,2.608939423,250905.2102,1.761514005,424.3763414
91.4,75.47484673,2.635106917,253293.48,1.754107259,426.5697229
91.6,76.27303662,2.661517385,255257.3756,1.747571934,428.3185528
91.8,76.76121259,2.688216697,257278.8534,1.742343656,430.4214964
92,77.50613228,2.71516451,259627.0182,1.734501238,432.2803756
92.2,78.23521949,2.742384411,261655.461,1.728837301,434.1283568
92.4,78.50387615,2.769912716,264545.0675,1.720559128,436.6606023
92.6,79.5553132,2.79765809,267138.2161,1.712716745,438.6960033
92.8,79.85629154,2.825739297,269302.2602,1.709231224,441.1149264
93,80.80209953,2.854053454,270111.7904,1.710974114,442.8855544
93.2,81.62487079,2.882661684,270642.6332,1.71445977,444.7411665
93.4,81.8559074,2.911602322,271142.789,1.720123835,447.0271592
93.6,82.4483932,2.940806141,271463.1409,1.724916547,448.7171469
93.8,82.89374116,2.970314544,272513.4284,1.727095072,450.920331
94,83.5085709,3.000106484,273692.906,1.727095151,452.6669824
94.2,84.13664939,3.030197241,275345.4423,1.72491675,454.5356661
94.4,84.61426432,3.060602902,276744.8288,1.725788201,456.8739657
94.6,85.52147017,3.091281333,277691.5734,1.726659699,458.6500395
94.8,86.392062,3.122270898,278424.2147,1.730145362,460.8358036
95,87.15083164,3.153580246,278897.3802,1.733195322,462.5573943
95.2,87.69597809,3.185220452,279410.0393,1.737552332,464.8303177
95.4,88.4725143,3.217160884,279863.7526,1.740166601,466.451666
95.6,89.26395796,3.249421186,279607.8474,1.748009208,468.3377895
95.8,90.22778769,3.28199256,280010.4569,1.751494885,469.9133765
96,90.68921122,3.314929363,280927.0813,1.754109113,471.9247954
96.2,91.13313065,3.348198382,281927.7928,1.754980558,473.6322152
96.4,91.89195522,3.381777787,284155.6833,1.750623698,475.9737909
96.6,92.81568456,3.415682052,287603.0759,1.73842434,478.1181525
96.8,93.36124364,3.449955731,291445.2739,1.725789242,480.7931433
97,94.11907479,3.484557562,294668.8757,1.714896948,483.0203106
97.2,95.13862348,3.519487181,297974.6543,1.704876075,485.4719442
97.4,95.97238243,3.55478194,300804.5852,1.700083524,488.3485184
97.6,96.5393261,3.590451696,301573.4214,1.703569155,490.3272535
97.8,97.10953698,3.626479188,301762.1951,1.711411741,492.6622883
98,97.82304238,3.662856171,301030.4195,1.723611299,494.7772274
98.2,98.59632352,3.699594068,300330.0253,1.733632388,496.4748479
98.4,99.62550167,3.736681724,300049.483,1.741039335,498.2324048
98.6,100.0047592,3.774191316,301023.1148,1.742782164,500.5608988
98.8,100.8867269,3.812039613,301329.5776,1.746267835,502.2280142
99,101.8766674,3.850260009,303187.3191,1.743218085,504.6676641
99.2,102.7493725,3.888873223,304688.6541,1.741039712,506.7412021
99.4,103.7607972,3.927863871,306500.3419,1.737554269,508.8659565
99.6,104.6990294,3.967251896,307722.2036,1.738861469,511.2783638
99.8,105.3122679,4.007060312,310019.9865,1.733633195,513.4238085
100,106.0584069,4.047258614,312498.8289,1.729712023,516.0138174
100.2,106.7554513,4.087864396,315003.8068,1.72535515,518.3118126
100.4,107.5305472,4.128872339,317248.8339,1.722305372,520.6435868
100.6,108.5332786,4.170274928,320014.0469,1.717948534,523.471136
100.8,109.2367748,4.212116302,321065.9734,1.719691401,525.5719117
101,110.2643042,4.254353309,321909.0903,1.723612786,528.1118059
101.2,110.9942591,4.297037346,322475.8599,1.72709844,530.1657308
101.4,112.3374427,4.340103639,324074.9265,1.726227208,532.396186
101.6,112.7099197,4.383676353,326922.9806,1.721434599,535.2008379
101.8,113.5734633,4.42764951,329458.4458,1.716642046,537.5042869
102,114.4892913,4.472060519,332725.1223,1.710542412,540.4549603
102.2,115.3152977,4.516924576,335207.3875,1.706621246,542.9360141
102.4,116.0822296,4.562243923,336770.1697,1.708364121,545.895402
102.6,117.2222198,4.607990201,337018.3323,1.713592608,547.9754891
102.8,118.1103362,4.654215198,338274.6726,1.71620689,550.682091
103,119.1429774,4.70089367,339429.0441,1.717514101,552.8471649
103.2,120.0409178,4.748051336,340463.338,1.720128385,555.1506139
103.4,121.096678,4.795670718,341780.7322,1.723178384,558.0315592
103.6,122.3285397,4.843755345,342274.0676,1.727535493,560.1476072
103.8,123.1630942,4.892353242,342973.6487,1.731892555,562.651541
104,124.1363525,4.941428784,343821.8024,1.735378242,565.1511253
104.2,125.0696433,4.991000383,344977.6988,1.736685443,567.5929572
104.4,125.8624115,5.041080742,346922.5653,1.733635665,569.8648062
104.6,127.2451285,5.091619535,350434.1028,1.725357599,572.9429828
104.8,128.0601738,5.14270943,351221.7914,1.727100483,575.0622862
105,129.0080602,5.194564248,351058.8123,1.734071739,577.5847506
105.2,130.3756152,5.246386667,350132.4892,1.743657225,579.5689621
105.4,131.0948451,5.299041002,348557.9669,1.75629251,581.3341437
105.6,132.0940469,5.352203222,346303.9282,1.773284795,583.1865018
105.8,132.9236344,5.405912452,347049.0346,1.77677047,585.3570207
106,133.502166,5.460180352,348711.684,1.775463452,587.2725666
106.2,134.5908616,5.514954706,351885.3673,1.768492441,589.5912784
106.4,136.0301631,5.570253029,356391.9557,1.757600208,592.7381049
106.6,136.6740835,5.626167193,360288.082,1.74714356,595.2289604
106.8,137.7824589,5.682607691,363467.8484,1.741479637,598.1741979
107,139.3228783,5.739582734,364413.0593,1.743222609,600.3632618
107.2,140.2233159,5.797178748,364459.6665,1.748451079,602.5141719
107.4,141.2100884,5.855346837,365929.5147,1.749322592,605.406017
107.6,142.2433056,5.914095798,366400.342,1.752808292,607.3684277
107.8,143.4983133,5.973418234,367026.6345,1.757165413,609.8723806
108,144.8579359,6.033328757,368521.723,1.757165578,612.0342017
108.2,145.9058276,6.093864986,370360.7272,1.756294312,614.4237399
108.4,146.6860318,6.155029694,370839.7904,1.761958468,617.0104909
108.6,148.0727887,6.216761936,371192.5917,1.765879909,618.9478509
108.8,149.4552921,6.279114488,372035.1605,1.768929957,621.2905492
109,150.5352019,6.342115991,374161.3464,1.766315907,623.9056387
109.2,151.8560094,6.405731938,376829.4059,1.761087703,626.4281192
109.4,153.2332253,6.469982461,379652.4029,1.755423808,628.9429737
109.6,154.5671254,6.534881054,382894.6015,1.749324215,631.9699439
109.8,155.6815305,6.600448484,386214.546,1.741917491,634.6090059
110,156.8614823,6.666669719,389254.4244,1.737560661,637.7896068
110.2,158.4526873,6.733524975,390844.546,1.737996553,640.333893
110.4,159.4196835,6.801099351,393085.0159,1.735818187,643.0361497
110.6,160.8685683,6.869315988,396471.2787,1.730154288,646.2679709
110.8,161.8511374,6.938253343,399111.0616,1.726233133,648.9179276
111,163.0130986,7.007869678,402040.2562,1.722747694,652.1649951
111.2,164.4209331,7.078166847,405148.4827,1.71751949,655.1571026
111.4,165.6134191,7.149186556,410107.7793,1.70793429,659.0895351
111.6,167.0185352,7.22090362,413610.7819,1.702270384,662.0827329
111.8,168.2299066,7.293359175,416759.8189,1.700092042,665.7765428
112,169.6796676,7.36652511,419282.8963,1.697913723,668.6019434
112.2,171.0707244,7.440430651,421207.5591,1.69878528,671.6474432
112.4,172.6943514,7.515061042,420764.899,1.709242214,674.8912579
112.6,173.9015138,7.590472922,420274.5926,1.718392007,677.6300275
112.8,175.6607748,7.666600517,419323.8971,1.728848969,680.2772912
113,176.5647852,7.743558149,418630.8486,1.737563034,682.56223
113.2,178.1600893,7.821236312,419567.2245,1.740613106,685.160998
113.4,179.5566534,7.899710119,422464.4662,1.738434785,688.6957359
113.6,181.1566945,7.978956994,425384.4028,1.735385091,692.0844678
113.8,182.5197658,8.059018111,427881.91,1.732335368,694.768221
114,184.1706612,8.139861761,430074.2225,1.731899868,698.0381944
114.2,185.4096523,8.221548935,430992.9955,1.734949903,700.6881637
114.4,186.7611177,8.304048343,432746.0809,1.735385764,703.6475871
114.6,188.3480484,8.387358771,433492.3492,1.740614332,706.7377729
114.8,190.0146251,8.471500201,435531.5553,1.740178834,709.4444196
115,191.4421465,8.556505331,439535.4774,1.734514928,712.9421131
115.2,193.0768742,8.642348763,442231.1052,1.732336633,715.9636576
115.4,194.421436,8.729073456,444335.256,1.733643889,719.4373789
115.6,195.9470243,8.816654609,446642.9917,1.732336977,722.3270746
115.8,197.26056,8.905131732,446851.8466,1.738872611,725.384567
116,198.8623222,8.99447597,446817.9902,1.744536885,727.7970172
116.2,200.4439971,9.084719385,448652.18,1.744537075,730.6474938
116.4,202.022204,9.175869608,451630.4085,1.741923074,734.238905
116.6,203.533783,9.267940758,455896.0011,1.734952077,738.0035585
116.8,205.1033873,9.360932462,461323.3507,1.723188401,741.3846744
117,207.0509624,9.454829823,467658.202,1.710989066,745.6734503
117.2,208.6701304,9.549695527,472111.9017,1.704018077,749.4141403
117.4,210.8176831,9.645474174,476446.9466,1.697918545,753.0960118
117.6,212.461478,9.742253448,479694.4482,1.69704734,757.245308
117.8,214.1333737,9.840002948,479769.0722,1.70401872,760.2374386
118,215.5940314,9.938750582,479594.4725,1.712732872,763.7798171
118.2,217.0553626,10.03849007,479854.4544,1.718832833,766.7370751
118.4,218.681079,10.13921924,479552.8724,1.726239911,769.7989412
118.6,220.235166,10.24096584,481710.111,1.726675796,773.4786141
118.8,222.1190103,10.3437097,486084.6029,1.719269133,776.889168
119,223.6860675,10.44751006,491666.099,1.710119635,781.1899218
119.2,225.2704108,10.55235174,497332.0488,1.700098738,785.2030212
119.4,227.5775849,10.65819199,503477.7139,1.691385021,790.1564794
119.6,229.3211504,10.76513854,506586.7156,1.689206727,793.8677624
119.8,230.9681455,10.87316683,507735.2384,1.693999614,798.0127084
120,232.7321439,10.98227153,507775.4767,1.700099614,801.1454086
120.2,234.768547,11.09245185,505302.3287,1.71404224,804.067825
120.4,236.1690343,11.20378736,502028.6351,1.731906092,807.4968874
120.6,238.1701807,11.31619581,499876.9061,1.744977323,809.9594899
120.8,240.1861065,11.42973246,498654.8141,1.756741459,813.0867545
121,241.8927069,11.54443352,499128.0199,1.761534365,815.6430505
121.2,243.790262,11.66027235,501473.8659,1.761098896,818.747432
121.4,245.6992668,11.77727405,505735.1394,1.754999329,822.1634424
121.56,247.2763646,11.87171742,511394.1468,1.74454272,825.6459066
121.8,248.7453796,11.87457309,519633.3456,1.730164795,830.9981395
122,249.8336625,11.87449036,524122.1758,1.724065123,834.6233216
122.2,250.5147391,11.87443844,527459.6769,1.721886704,838.3007924
122.4,251.4218568,11.87436942,530849.9103,1.721015411,842.7671491
122.6,251.9857577,11.87432636,531125.6068,1.726679579,845.9096161
122.8,252.709217,11.87427123,530630.7613,1.735393668,849.4378086
123,252.9199286,11.87425489,531125.9622,1.739750695,852.4647611
123.2,253.6408949,11.87419995,533136.0291,1.740186481,855.9395632
123.4,253.861579,11.87418285,534735.4238,1.743236409,859.9744076
123.6,254.3922386,11.8741423,535767.8656,1.746286374,863.0471385
123.8,254.696857,11.87411886,534917.0643,1.755436116,866.4314867
124,255.2183753,11.874079,532853.5712,1.766764384,868.8711499
124.2,255.331856,11.87407001,530123.7764,1.779835405,871.1342806
124.4,255.4253919,11.87406253,525266.4535,1.799877628,873.5270736
124.6,255.8854137,11.87402733,521393.9095,1.815562893,875.1647817
124.8,256.0944633,11.87401111,519728.0406,1.826019726,877.4224679
125,256.452268,11.87398364,520104.591,1.829069673,879.4219244
125.2,256.230842,11.87399999,519791.6791,1.834733749,881.4082781
125.4,256.5437709,11.87397591,521740.5239,1.834733789,884.1552042
125.6,256.7320446,11.87396126,526786.8885,1.825584108,887.4240514
125.8,256.7898461,11.87395649,530056.3093,1.820355712,889.893116
126,257.1418335,11.87392946,531967.3775,1.820791457,892.742465
126.2,257.1796901,11.87392619,534401.037,1.818612961,895.3477331
126.4,257.5350017,11.87389891,536610.4977,1.816870204,897.9181467
126.6,257.7058238,11.87388558,537499.9086,1.819484428,900.6476343
126.8,257.7145942,11.87388451,539109.4726,1.81992013,903.5242119
127,257.8746128,11.873872,541641.0029,1.816434548,906.042311
127.2,257.7329661,11.87388231,543338.1131,1.815563131,908.6617348
127.4,258.143957,11.87385082,544262.2693,1.817741687,911.742092
127.6,258.5549479,11.87381932,544545.5539,1.820791643,913.9856228
127.8,258.3750736,11.87383253,542282.342,1.831684129,916.2193211
128,258.236751,11.87384258,540147.4261,1.841269514,917.8057872
128.2,258.6061902,11.87381423,539689.0278,1.846933672,919.7311534
128.4,258.5310262,11.87381951,538889.3707,1.854776272,921.807952
128.6,258.8630689,11.87379399,539566.8654,1.856954813,923.6287098
128.8,258.9050807,11.87379041,539816.2617,1.861311816,925.7120459
129,258.7858719,11.87379902,540875.1917,1.862183208,927.4238278
129.2,259.2961714,11.87376002,541920.7235,1.863054675,929.3350316
129.4,258.6837439,11.87380594,542919.1007,1.864361699,931.6896573
129.6,259.2102485,11.8737657,541535.7934,1.871768672,933.3219211
129.8,259.0141691,11.87378013,542152.3336,1.872640051,934.96069
130,259.0628291,11.87377604,541696.3198,1.876997058,936.7574637
130.2,259.4875321,11.87374351,539687.9787,1.88527542,937.9560572
130.4,259.3604285,11.87375272,537564.6969,1.894860809,939.409592
130.6,259.5690626,11.87373654,538082.8857,1.895732241,940.7138711
130.8,259.392097,11.87374952,537830.4932,1.899653518,942.2153497
131,259.5899276,11.87373415,538142.4942,1.900960642,943.4291827
131.2,259.4852619,11.87374166,539333.72,1.90008923,944.9470112
131.4,259.545972,11.87373666,542368.684,1.894425133,947.1186115
131.566,259.758841,11.87372022,543212.5075,1.894425161,948.540575
132.4,259.9112258,11.70510815,1.7977E+308,1.973069096,0
132.6,259.3259819,11.58642042,1.7977E+308,1.927102629,0
132.8,259.5954565,11.46766804,1.7977E+308,1.805977964,0
133,259.2242038,11.34896412,1.7977E+308,1.599020254,0
133.2,259.0083545,11.23024845,1.7977E+308,1.273116379,0
133.4,258.664526,11.11154246,1.7977E+308,0.852665535,0
133.6,258.6406456,10.99281227,1.7977E+308,0.506283776,0
133.8,258.4705032,10.87409314,1.7977E+308,0.254448986,0
134,258.0643471,10.75539186,1.7977E+308,0.07145485,0
134.2,257.8933737,10.6366728,1.7977E+308,0.010021107,0
134.4,257.6052245,10.5179626,1.7977E+308,0.004792703,0
134.6,257.4890993,10.39923938,1.7977E+308,0.005228403,0
134.8,257.0862674,10.28053786,1.7977E+308,0.013942409,0
135,257.1463214,10.16180132,1.7977E+308,0.024399215,0
135.2,257.0127445,10.04307942,1.7977E+308,0.03137042,0
135.4,256.3439818,9.92439801,1.7977E+308,0.030934718,0
135.6,256.1796567,9.805678442,1.7977E+308,0.027013415,0
135.8,256.0735039,9.686954474,1.7977E+308,0.011763907,0
136,255.8792615,9.568237169,1.7977E+308,0.009149705,0
136.2,255.3326609,9.449546517,1.7977E+308,0.028756215,0
136.4,255.3295563,9.330814754,1.7977E+308,0.037034519,0
136.6,255.0530416,9.212103672,1.7977E+308,0.043134321,0
136.8,255.0158647,9.093374486,1.7977E+308,0.038777319,0
137,254.8440602,8.974655484,1.7977E+308,0.029191914,0
137.2,254.5417835,8.85594635,1.7977E+308,0.02178501,0
137.4,254.0192829,8.737253875,1.7977E+308,0.019170808,0
137.6,253.9787818,8.618524941,1.7977E+308,0.021349309,0
137.8,253.7155636,8.499812853,1.7977E+308,0.02701341,0
138,253.5362799,8.381094417,1.7977E+308,0.029191911,0
138.2,253.0220897,8.262401313,1.7977E+308,0.026142009,0
138.4,252.7488992,8.14368998,1.7977E+308,0.012199604,0
138.6,252.9302841,8.024944261,1.7977E+308,0.009149703,0
138.8,252.3995675,7.90565875,1.7977E+308,0.022220706,0
139,252.2068929,7.787534984,1.7977E+308,0.029191908,0
139.2,251.9893817,7.668819439,1.7977E+308,0.030063308,0
139.4,251.8134221,7.550100751,1.7977E+308,0.017863704,0
139.6,251.6615625,7.43138024,1.7977E+308,0.010456802,0
139.8,251.3410032,7.31267249,1.7977E+308,0.019170804,0
140,250.8209957,7.193979826,1.7977E+308,0.026142005,0
140.2,250.7406994,7.074660244,1.7977E+308,0.027013405,0
140.4,250.5381468,6.955943567,1.7977E+308,0.021785003,0
140.6,250.5483388,6.837210799,1.7977E+308,0.010456802,0
140.8,250.324916,6.719089359,1.7977E+308,0.003921301,0
141,249.7716672,6.600399209,1.7977E+308,0.010892501,0
141.2,249.4885044,6.48168863,1.7977E+308,0.015685201,0
141.4,249.1945381,6.362978869,1.7977E+308,0.015685201,0
141.6,249.1465578,6.2442505,1.7977E+308,0.009585401,0
141.8,248.7204572,6.125550733,1.7977E+308,0.0008714,0
142,248.8303732,6.006810421,1.7977E+308,0.0095854,0
142.2,248.3602278,5.888113986,1.7977E+308,0.0161209,0
142.4,248.0321892,5.769406801,1.7977E+308,0.022656399,0
142.6,247.7722954,5.650694462,1.7977E+308,0.022220699,0
142.8,247.3453638,5.531994758,1.7977E+308,0.017863699,0
143,247.3405972,5.41326312,1.7977E+308,0.008713999,0
143.2,246.9161587,5.294563228,1.7977E+308,0.0021785,0
143.4,246.8906163,5.175833162,1.7977E+308,0.006099799,0
143.6,246.5517743,5.057126795,1.7977E+308,0.008278299,0
143.8,246.3184735,4.938412444,1.7977E+308,0.009149699,0
144,246.0610728,4.819699916,1.7977E+308,0.0026142,0
144.2,245.7895445,4.700988457,1.7977E+308,0.012199598,0
144.4,245.3335268,4.582290953,1.7977E+308,0.027449094,0
144.6,245.2897016,4.46356227,1.7977E+308,0.038777291,0
144.8,245.0497526,4.344848422,1.7977E+308,0.046619889,0
145,244.6012143,4.226150353,1.7977E+308,0.045748488,0
145.2,244.1526759,4.107452283,1.7977E+308,0.040084388,0
145.4,244.1321197,3.98872184,1.7977E+308,0.03398459,0
145.6,243.8107295,3.870014153,1.7977E+308,0.03006329,0
145.8,243.5699494,3.751300368,1.7977E+308,0.024399192,0
146,243.5219691,3.632571999,1.7977E+308,0.020042193,0
146.2,243.1581962,3.513867518,1.7977E+308,0.015685194,0
146.4,242.7337579,3.395167625,1.7977E+308,0.015685194,0
146.6,242.5191554,3.27645186,1.7977E+308,0.010892495,0
146.8,242.0352982,3.157756462,1.7977E+308,0.011328195,0
147,241.7953493,3.039042614,1.7977E+308,0.013942393,0
147.2,241.3206335,2.920346524,1.7977E+308,0.016120892,0
147.4,241.2007688,2.801623593,1.7977E+308,0.016556592,0
147.6,240.9932302,2.682907294,1.7977E+308,0.01917079,0
147.8,240.5106196,2.564211801,1.7977E+308,0.016120891,0
148,240.0986469,2.445510965,1.7977E+308,0.010456794,0
148.2,240.0568993,2.326782125,1.7977E+308,0.010892494,0
148.4,239.4857838,2.208093328,1.7977E+308,0.010021094,0
148.6,239.2429263,2.0893797,1.7977E+308,0.007842595,0
148.8,239.0403738,1.970663023,1.7977E+308,0.006317646,0
149,238.5457134,1.851968442,1.7977E+308,0.012635291,0
149.2,238.0111633,1.733276879,1.7977E+308,0.017210137,0
149.4,237.6486371,1.614572303,1.7977E+308,0.018735086,0
149.6,237.3068867,1.495866155,1.7977E+308,0.014378089,0
149.8,237.2256651,1.377140301,1.7977E+308,0.008278293,0
150,236.6616135,1.258450969,1.7977E+308,0.017427985,0
150.12,236.2458965,1.187243216,1.7977E+308,0.02352778,0
225.4,235.4079122,1.027460085,1.7977E+308,0.033984573,0
225.6,234.6884575,0.908782507,1.7977E+308,0.04836266,0
225.8,234.7792596,0.790043641,1.7977E+308,0.056640953,0
226,234.1462323,0.671359526,1.7977E+308,0.060997947,0
226.2,233.7267804,0.552659256,1.7977E+308,0.064047842,0
226.4,233.140291,0.433971621,1.7977E+308,0.06361214,0
226.6,232.769039,0.315267706,1.7977E+308,0.058383743,0
226.8,231.5227098,0.196629982,1.7977E+308,0.04749125,0
227,230.5389869,0.077972394,1.7977E+308,0.032677463,0
227.132,229.3927725,-0.000304023,1.7977E+308,0.026577668,0
,,,,,