File: TestGB_1.csv
Time On Sample,Displacement Into Surface,Load On Sample,Harmonic Contact Stiffness,Harmonic Displacement,Harmonic Load
0,0,0,621.3341379,0.311508786,2.223809816
0.2,0.016356816,0.000758103,6400.810791,0.221759402,2.307706613
0.4,0.132432288,0.001508651,11750.66053,0.181677154,2.385066004
0.6,-0.043169309,0.002281298,15186.91379,0.154665201,2.461335798
0.8,0.274836444,0.003016547,17431.47528,0.141159229,2.534336945
1,0.371799176,0.003768543,19388.25801,0.136802464,2.702130545
1.2,0.549367825,0.004514432,21952.61296,0.129395962,2.91895476
1.4,0.399526876,0.005285127,24012.92588,0.127653255,3.133599785
1.6,0.458264123,0.006040019,25868.98611,0.125474872,3.342796994
1.8,0.549409934,0.006792456,26738.78022,0.123732166,3.521486287
2,0.579062572,0.007549552,29167.4844,0.120246753,3.956224238
2.2,0.729208592,0.008297518,31480.91305,0.120682431,4.340842054
2.4,0.643353782,0.009063365,33680.39445,0.122860814,4.815894029
2.6,0.635611922,0.009823294,34951.92433,0.131574347,5.284408595
2.792,0.807473889,0.010539242,36070.79431,0.146387354,5.756191923
3,0.873580108,0.011322016,36784.31431,0.163814421,6.361992204
3.2,0.639809584,0.012097175,38039.07738,0.181677161,7.167183479
3.4,0.563926941,0.012860372,38963.00763,0.199975579,7.963658233
3.6,0.53707264,0.013619854,40398.47277,0.214352908,8.778655652
3.8,0.917402872,0.014348484,41180.54248,0.228730243,9.567503637
4,0.89054857,0.015107966,41652.68989,0.247028662,10.48274141
4.2,0.846243503,0.015868769,42219.35319,0.264455727,11.3511277
4.4,0.867586554,0.016624599,42452.11479,0.289289297,12.45377136
4.6,0.721069859,0.017393146,42321.83165,0.31586557,13.50956343
4.8,0.875371126,0.018138902,42263.7896,0.338085082,14.33000884
5,1.03299635,0.018884406,42816.79235,0.362482979,15.38362198
5.2,0.834127355,0.019656921,43229.32952,0.391237634,16.6595069
5.4,0.756582734,0.020420243,43228.12753,0.42129932,17.84822639
5.6,0.823630172,0.021172609,42571.56416,0.456589132,18.99445282
5.8,0.443605614,0.021958849,42061.97957,0.484908101,19.90206327
6,0.812302,0.022688362,41151.53253,0.528911455,21.22697928
6.2,0.251121878,0.023488327,39907.8724,0.568993685,22.14330604
6.4,0.453620493,0.024230432,37441.65005,0.635216544,23.20999409
6.6,0.594625936,0.024977196,34469.97838,0.716688083,24.13067988
6.8,0.801279499,0.025718986,31243.37698,0.815586692,24.93914017
7,0.452001528,0.026502897,28436.00924,0.917970683,25.59506015
7.2,0.62957048,0.02724689,26285.15449,1.011641173,26.1093369
7.4,0.902703153,0.027983644,24333.28079,1.114896562,26.70533133
7.6,0.828482486,0.028746713,23068.62625,1.196368088,27.28171307
7.8,1.111587029,0.029482711,22316.61007,1.252134724,27.73497411
8,0.64015369,0.030275875,21819.19489,1.296573701,28.22527939
8.2,0.80318034,0.03102097,21347.00008,1.340577058,28.74936225
8.4,1.064263677,0.031758636,20849.59941,1.383273394,29.12090561
8.6,1.088099696,0.032514276,20294.87051,1.434683244,29.53167309
8.8,1.363725345,0.033250839,19850.34423,1.477815261,29.82585704
9,1.248370727,0.034017024,19293.23957,1.53009645,30.07427858
9.2,1.702243497,0.034740081,18973.29917,1.571485783,30.36846282
9.4,1.815826319,0.03548892,19185.20004,1.574971209,30.68334842
9.6,1.9701276,0.036234674,19888.80452,1.552751715,31.16820677
9.8,1.983576259,0.0369911,20865.62216,1.511362431,31.63563187
10,1.854925813,0.037758291,22606.70617,1.436426028,32.30462693
10.2,1.857156122,0.038515567,25076.29124,1.339270128,33.13923662
10.4,1.835703247,0.039274637,27521.30243,1.258234263,34.00544377
10.6,1.817574328,0.040033454,29275.35299,1.20856712,34.67988695
10.8,1.646958944,0.040803826,31105.46711,1.165870791,35.51340681
11,2.043493492,0.041531227,31915.03759,1.157592967,36.19983593
11.2,1.827173715,0.042305061,31664.45957,1.185911934,36.85357689
11.4,1.95488335,0.043052828,31155.59421,1.218587696,37.30356899
11.6,2.033980135,0.043804279,30450.9942,1.261719695,37.8330996
11.8,2.105598019,0.044556297,29745.98631,1.301801958,38.20573229
12,1.966560211,0.045324275,29296.135,1.335784727,38.66008229
12.2,2.207284342,0.04606348,29461.30054,1.347983697,39.23973337
12.4,2.23818377,0.046818583,29960.03249,1.344498287,39.79160006
12.6,1.989039927,0.047594903,30483.15925,1.34231988,40.35545149
12.8,2.178242745,0.048338012,31031.47608,1.337527454,40.86972833
13,2.295980517,0.049086535,31454.51949,1.338398819,41.42867749
13.2,1.966230747,0.049868962,31817.94062,1.342319879,42.0224918
13.4,2.051144455,0.050619972,31971.39233,1.353647481,42.58579904
13.6,1.950332137,0.051385054,32062.18858,1.366282096,43.11968761
13.8,2.218478903,0.052122182,32176.56847,1.374995655,43.56205314
14,2.343695576,0.052870138,32303.15587,1.385451908,44.05344894
14.2,2.246207212,0.053634968,32266.18801,1.402878967,44.55682961
14.4,2.55299497,0.054369167,32276.36523,1.418563359,45.06130063
14.6,2.55522528,0.05512644,32435.58899,1.424662833,45.4884117
14.8,2.56493449,0.055883147,32763.60036,1.426405541,46.02665882
15,2.666883474,0.056632866,33065.53529,1.427276905,46.53548772
15.2,2.841128501,0.057377106,33523.71423,1.423791509,47.10642227
15.4,2.609019921,0.058152135,33906.55288,1.421177426,47.585832
15.6,2.827307362,0.058893038,34067.67155,1.430762335,48.12625862
15.8,2.85529833,0.059648359,34048.13283,1.44383264,48.51414525
16,2.868331496,0.060404813,34094.20679,1.456467266,48.96304772
16.2,2.996041142,0.061152579,34082.18439,1.472151641,49.45880182
16.4,2.906862663,0.061916777,34040.32964,1.487835994,49.91097268
16.6,3.231516701,0.062649621,34272.20697,1.490450088,50.33045752
16.8,3.163112946,0.063412245,34806.61592,1.483914931,50.85454015
17,3.012441281,0.064181102,35520.21899,1.470844614,51.3818909
17.2,3.006361099,0.064942793,36556.94679,1.449496454,52.01166199
17.4,3.05014146,0.065693129,37777.10316,1.422484502,52.68937388
17.6,2.891990896,0.066462553,38882.937,1.397650914,53.25812852
17.8,2.812784286,0.067225996,40115.74068,1.372817334,53.96634798
18,3.232171067,0.067951662,40730.97164,1.367153576,54.588493
18.2,2.983442701,0.068727949,40925.45351,1.375431411,55.21826329
18.4,3.099518503,0.069476595,40780.63552,1.391551461,55.69767405
18.6,3.350214523,0.070215042,39977.90768,1.430762391,56.18580139
18.8,3.676530549,0.070947759,38882.60419,1.480865249,56.57913653
19,3.499267231,0.07171863,38449.81286,1.507441512,56.96920197
19.2,3.659385455,0.072463939,38246.02004,1.527046983,57.42137358
19.4,3.787926097,0.07321164,38452.86926,1.529661057,57.84303692
19.6,3.722015307,0.073974073,39424.00793,1.50831289,58.4640912
19.8,3.617879022,0.074739403,40954.37534,1.470409003,59.18865427
20,3.611799442,0.075497304,42187.31472,1.444268398,59.8598287
20.2,3.640621401,0.07625256,43309.50572,1.422048887,60.49940584
20.4,3.796584681,0.076998183,44203.01681,1.410721307,61.22288006
20.6,3.398278283,0.077785801,44311.15199,1.421613187,61.84175388
20.8,3.675565958,0.078522232,43887.73505,1.447318143,62.37782276
21,4.075009029,0.079249408,43513.31899,1.470409051,62.8703091
21.2,3.684181524,0.080036459,43228.84947,1.489578788,63.28870253
21.4,3.666468098,0.080795241,43378.82973,1.497420968,63.85418864
21.6,3.590585439,0.081558429,44014.33242,1.490885809,64.49594456
21.8,3.914408505,0.082291335,44832.88482,1.477379864,65.06361117
22,3.986441895,0.083043316,45738.21296,1.463873895,65.73260673
22.2,3.764305165,0.083817586,46449.86607,1.457338721,66.44409456
22.4,3.672633715,0.084581971,46716.18135,1.46300251,67.10219383
22.6,4.089527556,0.085307825,46611.79501,1.476508534,67.57288906
22.8,4.0269405,0.086071395,46258.72251,1.499163718,68.11985249
23,3.978479142,0.086840914,45955.38397,1.519204844,68.59054614
23.2,3.818664018,0.087626634,45577.20968,1.544038399,69.1070013
23.4,3.942214917,0.088398691,45116.19387,1.571050373,69.56679983
23.6,4.1023281,0.089175749,44833.67334,1.589348814,69.91873116
23.8,4.005664402,0.089980218,44596.10329,1.608518583,70.35782714
24,4.168268034,0.090772929,44575.34793,1.619410517,70.77513263
24.2,4.285166012,0.091577016,44766.2252,1.623331626,71.26870779
24.4,4.363837222,0.092392005,45147.40371,1.618974868,71.69363998
24.6,4.813128253,0.093187156,45806.88963,1.607211641,72.24932175
24.8,4.561063192,0.094043656,46575.91688,1.592834283,72.87146478
25,4.85578761,0.094867167,47459.55636,1.57453589,73.47508707
25.2,4.869636378,0.095720373,48563.48083,1.552752049,74.17023217
25.4,4.625877164,0.096601679,49313.33914,1.540553074,74.72591146
25.6,4.481004272,0.097484184,50353.57257,1.523997341,75.45156394
25.8,4.605370439,0.098355118,51194.16257,1.514412466,76.16523215
26,4.976954497,0.099215917,51588.50141,1.516155212,76.76449639
26.2,4.758950362,0.100130381,51808.34777,1.523126018,77.40080388
26.4,4.751600517,0.101037984,51914.978,1.530096846,77.90309513
26.6,4.817791752,0.10194917,51756.90674,1.546216894,78.48492529
26.8,5.129123348,0.102850752,51563.03598,1.562772646,79.02317364
27,4.68716182,0.103818854,51531.25515,1.573664518,79.54071717
27.2,5.038793414,0.104736075,51428.87644,1.587170537,80.08223428
27.4,5.012323472,0.105691347,51468.7623,1.595012716,80.53658465
27.6,4.958013851,0.106658447,51838.95939,1.595884064,81.14783261
27.8,5.272661874,0.107607164,52257.26443,1.594577069,81.75908208
28,5.416124617,0.108578449,52661.395,1.593270054,82.32565851
28.2,5.502247548,0.109563904,53366.3094,1.583249498,82.89223482
28.4,5.270100047,0.11058351,54363.42596,1.568000785,83.62551404
28.6,5.555241695,0.111573892,55133.94226,1.55928728,84.32610798
28.8,5.328076923,0.112613283,55930.27931,1.548831013,84.93735508
29,5.446186488,0.113636875,57074.6461,1.531403954,85.68262094
29.2,5.534378834,0.114672874,58018.50324,1.52094772,86.49217107
29.4,5.485456291,0.115729833,58709.28394,1.517026624,87.29518344
29.6,5.475173061,0.116794451,59250.63402,1.513541209,87.92168539
29.8,5.673466437,0.11785376,59732.38693,1.513976907,88.69310124
30,5.460002969,0.118955108,59745.15378,1.524433128,89.3413939
30.2,5.6715887,0.120035251,59662.81312,1.537939131,90.03980861
30.4,5.603129364,0.121147461,59624.96925,1.547959691,90.57914512
30.6,5.400463503,0.12228104,59696.33876,1.558415913,91.27537888
30.8,5.534346453,0.123400381,59748.71049,1.568872171,91.95418103
31,5.762960374,0.124523828,60037.69727,1.571921934,92.59811732
31.2,5.608070977,0.125687817,60452.94527,1.570614887,93.17122986
31.4,5.653032625,0.126848276,61032.16026,1.568000831,93.9263016
31.6,5.834274652,0.128010002,61574.21442,1.565822467,94.68355296
31.8,5.873415651,0.129194333,62054.37842,1.563208411,95.30787612
32,5.641236789,0.130411189,62605.43494,1.560594325,96.01936369
32.2,6.019002068,0.131593795,62896.80649,1.564951134,96.75155594
32.4,6.07351064,0.132812992,63060.89939,1.572357646,97.45650741
32.6,5.895340301,0.134062051,63127.90411,1.582378194,98.14402477
32.8,5.914112427,0.135308566,63355.67315,1.588041995,98.81302014
33,6.363334972,0.136534896,63555.25857,1.59414152,99.46676389
33.2,6.345539593,0.137809231,63727.81141,1.599369641,100.0366083
33.4,5.969585844,0.139123497,64149.78526,1.600240953,100.749185
33.6,5.991673855,0.140420541,64727.44138,1.597626895,101.5042562
33.8,6.306267985,0.141708464,64932.29145,1.601548021,102.0795506
34,6.723071729,0.143001632,65081.35503,1.607647544,102.6940694
34.2,6.904703468,0.144325616,65434.75263,1.610261625,103.4175444
34.4,6.583584575,0.145701254,65625.83682,1.615925389,104.0800007
34.6,7.134171229,0.147024329,65816.67748,1.622024926,104.7773279
34.8,6.941019263,0.148424299,66246.8146,1.620282198,105.3569775
35,7.250614663,0.149793224,67209.49858,1.608518957,106.1251256
35.2,7.320884107,0.151186926,68236.10983,1.59675569,106.9640943
35.4,7.337966875,0.152605833,69287.99641,1.585428094,107.8390181
35.6,7.443132255,0.154032206,70172.99694,1.576278892,108.5679406
35.8,8.052705862,0.155434611,71098.08543,1.568872452,109.4537636
36,8.168669576,0.156888679,71599.04749,1.569743818,110.2447914
36.2,8.070235702,0.158373781,72003.3226,1.571486516,110.9584585
36.4,8.401420978,0.159840911,72673.45456,1.570615198,111.8715195
36.6,8.219883461,0.161361939,73080.0903,1.572357886,112.5840968
36.8,8.283485386,0.162879519,73543.66249,1.575407632,113.4655588
37,8.40193019,0.164408139,74045.02032,1.575843322,114.2544074
37.2,8.75720451,0.165934177,74493.08152,1.576279038,114.9735252
37.4,8.40447345,0.167529454,75016.16161,1.57758603,115.8909403
37.6,8.24951533,0.1691256,75526.21189,1.57671466,116.6187718
37.8,8.294823118,0.170722401,76187.0399,1.574971958,117.5383687
38,8.562833484,0.172318422,76774.47365,1.573664956,118.3718906
38.2,8.418670573,0.173961882,77350.24811,1.574536295,119.310009
38.4,8.7772536,0.175583617,77702.40149,1.577150396,120.0400223
38.6,9.19317231,0.177217316,77959.01196,1.583249918,120.9029634
38.8,8.94928285,0.178917534,78078.06847,1.589785045,121.5828534
39,9.305365016,0.180589201,78513.62165,1.591963469,122.4065697
39.2,9.240963869,0.182309702,78953.37128,1.594577524,123.3196285
39.4,9.396772183,0.184030636,79386.42659,1.597191603,124.2261512
39.6,9.281675191,0.185789538,79886.42095,1.596755914,124.98667
39.8,9.505619065,0.187540344,80595.0944,1.594577555,125.933507
40,9.31655841,0.189340136,80877.14873,1.598934302,126.7397872
40.2,9.445763845,0.19113367,81303.41638,1.600677025,127.5024863
40.4,9.589093215,0.192944287,81680.12588,1.605033811,128.4308006
40.6,9.544616064,0.194787515,81685.95774,1.612875993,129.083452
40.8,9.437811794,0.196653807,81435.73586,1.626817642,129.8537768
41,9.496371434,0.198526294,81150.27348,1.640323638,130.5456537
41.2,9.451054401,0.200425528,80789.75655,1.653393935,131.1449165
41.4,9.585228046,0.202330211,80672.4023,1.663850199,131.8890932
41.6,9.765934046,0.204250572,80934.35913,1.667771313,132.6746739
41.8,9.740551615,0.206205814,81553.61707,1.663850218,133.3578337
42,9.859758206,0.208169805,82318.82696,1.65862211,134.1652053
42.2,9.876749972,0.210161231,83004.71324,1.656443725,135.0412192
42.4,9.853020076,0.212175755,83304.93012,1.658622107,135.6873336
42.6,9.75283594,0.214216308,83405.75724,1.666899958,136.4598376
42.8,9.849593041,0.216262375,83095.35393,1.680405958,136.9959064
43,9.723641716,0.21834588,82699.89836,1.696525986,137.573377
43.2,10.01442828,0.220418509,82766.35311,1.70523956,138.2805097
43.4,10.19468994,0.222520411,82954.45605,1.709160676,138.8427287
43.6,10.17841924,0.224658378,83271.93345,1.711774734,139.5792775
43.8,9.97018655,0.226832479,83789.48843,1.708724971,140.2112264
44,10.3133119,0.228986436,84586.61875,1.701754181,140.9662999
44.2,10.2708547,0.231191358,85142.40925,1.700011468,141.7638647
44.4,10.25997158,0.233416029,85730.58755,1.69674389,142.4982341
44.6,10.62760063,0.235634174,86521.82937,1.690862295,143.2849058
44.8,10.49538592,0.237912917,87441.32438,1.683020094,144.1080746
45,10.5439078,0.240200671,88093.85538,1.680406039,144.9661108
45.2,10.42996758,0.242523775,88584.22249,1.678663318,145.6612551
45.4,11.4993527,0.244780282,89036.80385,1.679970473,146.5252911
45.6,12.09673223,0.247095233,89043.80032,1.686070021,147.1234691
45.8,12.02433049,0.249484309,88602.45653,1.701318708,147.8218828
46,12.15842582,0.251881812,88281.31705,1.713517681,148.4309529
46.2,12.57754676,0.254281723,88210.93576,1.721359917,148.9702929
46.4,12.07301894,0.256775993,88436.59498,1.725716627,149.6992113
46.6,12.27441282,0.259241413,89121.76435,1.720924205,150.3442376
46.8,12.65654296,0.261718104,90147.32979,1.71221071,151.18103
47,12.55129376,0.264256691,91369.54977,1.700011741,152.0308933
47.2,12.60517503,0.266808593,92429.92928,1.689555499,152.8262798
47.4,12.6922918,0.269383688,93495.56252,1.680841969,153.8079822
47.6,12.65060107,0.27199443,93824.68808,1.682148996,154.5020377
47.8,12.82911842,0.274614616,94467.38143,1.680406309,155.4249045
48,12.82772233,0.277274838,94843.85344,1.682149017,156.2279171
48.2,13.21480963,0.279932287,94960.9405,1.687812864,156.9089007
48.4,12.95247429,0.28266588,94893.43319,1.697833406,157.6661498
48.6,12.88126223,0.285412226,95247.78114,1.700883137,158.4909534
48.8,13.12249786,0.288162489,95267.48267,1.707418321,159.0989351
49,13.32550359,0.290943292,95280.23247,1.714824856,159.7657534
49.2,12.99833347,0.293792404,95666.03144,1.716567525,160.5589573
49.4,13.66876187,0.296594325,96256.88919,1.713517866,161.2530189
49.6,14.00803642,0.299449604,96920.95313,1.710903844,162.138841
49.8,13.95757225,0.302363234,97651.72652,1.705675714,162.8688521
50,14.24780922,0.305280129,98897.77869,1.69347679,163.7960781
50.2,14.42835085,0.308234923,100710.1167,1.67430702,164.9346797
50.4,14.0745614,0.311259922,101886.6843,1.66385073,165.8499156
50.6,14.36395315,0.314266415,102806.212,1.659493993,166.928592
50.8,14.62342447,0.317305421,103286.7884,1.659494023,167.7599351
51,14.94272219,0.320370465,103223.5168,1.670385987,168.783044
51.2,14.73267455,0.323506558,102590.0437,1.686506016,169.3768577
51.4,15.17577986,0.326624416,102180.3157,1.700883412,170.1417392
51.6,15.29063922,0.329798661,102385.6084,1.70480452,170.8466919
51.8,15.33652139,0.333009923,102709.8335,1.70872562,171.7063624
52,15.286001,0.336277216,103080.6344,1.710904,172.5082854
52.2,15.27619912,0.33954133,103802.4797,1.706982905,173.2982231
52.4,15.5888108,0.342846814,104363.7562,1.707418619,174.2407039
52.6,15.48509392,0.346200797,104569.8571,1.711339701,174.9456543
52.8,15.60407967,0.349554486,104746.969,1.716567841,175.7693701
53,15.69646567,0.35296095,104873.4132,1.721795978,176.5266217
53.2,15.72818398,0.356406208,104760.1169,1.72963817,177.1444079
53.4,15.80809421,0.359882358,104730.3734,1.737480368,177.9125552
53.6,15.78163218,0.363401621,104520.3411,1.746193908,178.4987434
53.8,16.03271513,0.366935129,104328.337,1.755778836,179.2113241
54,15.94225561,0.370530147,104310.1118,1.761878305,179.8389156
54.2,16.51907518,0.374110535,104548.8381,1.763621084,180.4534374
54.4,16.15271557,0.377798696,105235.4913,1.7605713,181.2836871
54.6,16.42371928,0.38147533,106064.8768,1.754471853,182.0017156
54.8,16.14709482,0.385230662,107069.1772,1.747500986,182.8777276
55,16.45963615,0.388978809,108319.4999,1.737044773,183.7886098
55.2,16.37495837,0.392794801,109316.3184,1.730945283,184.7267291
55.4,16.35176774,0.396644472,109661.0042,1.732252312,185.4447554
55.6,16.21306337,0.400541645,109815.7996,1.737044744,186.2543042
55.8,16.40259376,0.404452922,110031.3749,1.73965883,186.9396455
56,16.49489209,0.408411003,109756.6688,1.749679416,187.6075525
56.2,16.86639668,0.412387616,109609.03,1.757957327,188.3473734
56.4,17.00272483,0.416421901,109912.5841,1.758828699,189.0098335
56.6,17.25206115,0.420488122,110701.4421,1.754471958,189.9043723
56.8,17.35347478,0.424606533,111448.5148,1.749243844,190.6365637
57,17.25378228,0.428781595,112652.0972,1.738787581,191.5594288
57.2,17.30532326,0.432987105,113855.6536,1.730074044,192.6043264
57.4,17.29120935,0.437239804,114636.6211,1.726152948,193.4204142
57.6,17.2114405,0.441539806,114862.4336,1.731381068,194.3018758
57.8,17.4033985,0.445862206,114846.4809,1.737916246,194.9763206
58,17.96680208,0.45019988,114411.301,1.750550953,195.6409635
58.2,18.79528457,0.454560812,114102.3483,1.761878659,196.3829688
58.4,19.13679998,0.459002721,114126.8686,1.766671157,197.0062057
58.6,19.37942048,0.463496867,114856.964,1.762314409,197.88767
58.8,19.82230241,0.468020917,115632.5015,1.756650662,198.6318505
59,19.71339975,0.472632354,117085.37,1.74314465,199.6059249
59.2,19.82968802,0.477272974,118852.7604,1.727024609,200.7597805
59.4,20.13626561,0.4819457,119959.7067,1.718746779,201.6782909
59.6,20.31237029,0.486675394,121057.0833,1.712647315,202.7787582
59.8,20.21507169,0.491473393,121742.2184,1.710033246,203.6384279
60,20.06790604,0.496323327,122087.3408,1.71264729,204.5623817
60.2,20.79576516,0.501155492,122648.2155,1.713518725,205.631257
60.4,21.52984903,0.50603572,123372.6516,1.710904754,206.5083682
60.6,21.2954061,0.51103888,124599.4439,1.704369568,207.6894598
60.8,22.04567847,0.516017492,125696.5023,1.698270173,208.6679011
61,22.04015736,0.521103614,126851.4215,1.692606369,209.8021434
61.2,22.08241007,0.526237201,127703.3786,1.691735019,211.0039395
61.4,22.23351429,0.531414044,128181.9065,1.693477747,211.9322545
61.6,22.22007419,0.536655406,128181.0541,1.702191292,212.9629878
61.8,22.42226768,0.541932999,128226.7705,1.708290799,213.768182
62,22.57417783,0.54726748,128777.586,1.709597849,214.7891106
62.2,22.58896609,0.552665942,129771.9581,1.706112433,215.9691156
62.4,22.92907838,0.558093959,130442.1214,1.704805441,216.9192241
62.6,23.0211314,0.563595511,131272.7895,1.702409227,218.0087949
62.8,22.91789298,0.569166993,131729.6667,1.704369763,219.0188254
63,23.00203392,0.574780342,131992.859,1.708726547,220.0059764
63.2,23.17632835,0.580443126,131970.2896,1.717004438,221.0345328
63.4,23.23552159,0.586171619,131972.0027,1.723539605,221.858248
63.6,23.437636,0.591946805,131703.7321,1.734431564,222.7854748
63.8,23.87324948,0.59776206,131883.5206,1.738352713,223.5895819
64,24.3753329,0.603630751,131937.1346,1.744452257,224.4764975
64.2,24.51509517,0.609586099,132273.3427,1.747937694,225.4625602
64.4,24.86467299,0.615585235,132634.2121,1.749680446,226.2699355
64.6,25.2163187,0.621644629,133904.3455,1.742273973,227.4074501
64.8,25.19982603,0.627792758,134605.165,1.740095584,228.2758375
65,25.39273311,0.633986775,135687.4811,1.734431801,229.337081
65.2,25.5324469,0.640247199,136348.3952,1.734431819,230.4604296
65.4,25.59279112,0.646576467,137137.8175,1.731382084,231.4105357
65.6,26.0549091,0.652938637,136965.2113,1.740095689,232.3846168
65.8,26.12562043,0.659394678,136774.5101,1.747502214,233.1255248
66,26.2108638,0.665914352,136229.7999,1.759701193,233.8653442
66.2,26.47226671,0.67248619,136249.589,1.76580071,234.8045571
66.4,26.72202527,0.679124963,136030.8738,1.773207258,235.4735557
66.6,26.68009558,0.685852633,136668.4748,1.772335898,236.4203917
66.8,26.9630724,0.692623189,137736.8957,1.765800771,237.3116641
67,27.14964358,0.699468779,139587.3034,1.751423438,238.478596
67.2,27.18911852,0.706394316,141924.7822,1.733560667,239.8460073
67.4,27.30669551,0.713383461,144024.3135,1.717876292,241.0412667
67.6,27.45334601,0.720440567,146192.8276,1.703498953,242.5274426
67.8,27.76618332,0.727556031,147418.0117,1.697399505,243.6464348
68,27.85214888,0.734760189,147924.4526,1.700013581,244.8013807
68.2,28.38600683,0.742002603,147563.6616,1.711776937,245.9236439
68.4,28.3763854,0.749359234,146860.9878,1.725282939,246.7321059
68.6,28.81631811,0.75675553,145859.6043,1.74314577,247.6331846
68.8,28.82246195,0.764259108,145231.0604,1.755344742,248.3512121
69,29.24907506,0.771805936,145210.3696,1.76144428,249.2348588
69.2,29.69977483,0.779426898,145908.1347,1.761008658,250.33751
69.4,29.80227735,0.787151072,146794.8703,1.757087573,251.2625562
69.6,29.97623275,0.794947274,148189.6168,1.749681076,252.5112062
69.8,29.95904785,0.802836438,149225.488,1.744888621,253.4885503
70,30.30831721,0.810777001,150306.6076,1.740967566,254.6391412
70.2,30.59857351,0.818802113,150665.6474,1.744888699,255.7581338
70.4,30.96858562,0.82694263,150326.6312,1.754473651,256.5469872
70.6,31.14331497,0.835097747,149716.534,1.767979678,257.4578707
70.8,31.73767505,0.843344124,149097.431,1.779743047,258.0996351
71,31.63897569,0.851726141,148178.4182,1.794991752,258.7555558
71.2,32.06378712,0.860152493,147672.0469,1.805883745,259.510633
71.4,32.40797899,0.868669657,148053.172,1.805883789,260.2297537
71.6,32.54690256,0.877287984,149502.2593,1.795863221,261.333491
71.8,33.16030809,0.885956873,151243.633,1.781921613,262.3402614
72,33.65237515,0.894722065,154737.3585,1.753166947,264.019297
72.2,33.91008879,0.903593205,157610.7843,1.73051174,265.3311424
72.4,34.23343655,0.912548448,160981.7055,1.706113828,267.0646536
72.6,34.19695099,0.921620937,162585.3473,1.697400271,268.3340034
72.8,34.39395936,0.930766878,163682.7321,1.695221906,269.8452394
73,34.87265903,0.939983391,164144.658,1.698271707,271.1254916
73.2,35.13611737,0.949308696,164170.6534,1.704371226,272.1791112
73.4,35.60481557,0.958712184,163905.3757,1.71439187,273.4201377
73.6,36.03693517,0.968212884,164511.7931,1.714827599,274.5129825
73.8,36.33525007,0.977819123,165741.8741,1.711777891,275.9828173
74,36.44740766,0.987536036,166947.8273,1.708292482,277.370932
74.2,37.14872237,0.99730568,168375.6598,1.701757399,278.6838746
74.4,37.39796238,1.007207884,170253.4154,1.693043873,280.3116962
74.6,37.78928608,1.017198561,171160.7648,1.692172564,281.5821412
74.8,38.06508608,1.027298375,172040.9089,1.693043952,283.1358735
75,38.22536217,1.037508535,172047.6538,1.700450494,284.4063158
75.2,38.41055172,1.047819265,171616.4703,1.710906784,285.4621121
75.4,38.52758353,1.05823876,170727.6823,1.7265912,286.6279545
75.6,38.69695113,1.068758991,170319.9579,1.736176128,287.5845995
75.8,38.90618953,1.079381798,169956.9733,1.746632422,288.7264731
76,39.34310253,1.090094105,169933.7796,1.753603325,289.7790049
76.2,40.09909906,1.100889681,170103,1.758395872,290.7367479
76.4,40.0274111,1.111856927,171194.2009,1.756217473,292.0464112
76.6,40.03049486,1.122928422,172098.0028,1.754039089,293.1065638
76.8,40.53547965,1.134072955,173335.62,1.750118047,294.472893
77,40.9490376,1.145336483,175478.7675,1.737919116,295.9547155
77.2,41.39332423,1.15671099,176721.8802,1.732691035,297.2088181
77.4,41.66557752,1.168212812,177505.1348,1.732691068,298.6666681
77.6,41.81981168,1.179839168,177958.2093,1.733998123,299.8074513
77.8,41.96322439,1.191583098,178597.1251,1.735305173,301.2075522
78,42.86655984,1.203387813,178363.4616,1.743583165,302.3309132
78.2,43.56628363,1.215326446,178941.4935,1.744890282,303.4466444
78.4,43.69966769,1.227428298,179951.5142,1.743583266,304.8380287
78.6,43.99299829,1.239639488,180503.1217,1.745761692,306.0480022
78.8,44.2563937,1.251975662,181073.6417,1.747504436,307.2852145
79,44.40675456,1.264444489,181762.6092,1.748375811,308.5621942
79.2,44.48396825,1.277044136,182324.7115,1.749247177,309.6899012
79.4,44.38623814,1.289783607,183587.5649,1.746197419,311.1477463
79.6,44.87059719,1.302606848,184624.0576,1.744019088,312.3484612
79.8,45.35493578,1.315558962,185790.3688,1.742276435,313.7801649
80,45.41295503,1.328673712,186739.6727,1.741840765,315.1388606
80.2,46.00278795,1.341879582,187541.4524,1.741405158,316.3134283
80.4,46.18541392,1.35524916,188338.8079,1.742276537,317.7603815
80.6,46.66011208,1.368730891,189283.9687,1.740533882,318.995963
80.8,47.72063784,1.382303473,190925.4761,1.734870195,320.6259778
81,48.43129448,1.39603906,193249.3907,1.72354265,322.2908545
81.2,48.75385609,1.409942157,195803.7288,1.711125862,324.0091134
81.4,48.89482379,1.423998851,198358.7264,1.699144731,325.7807586
81.6,49.15460088,1.438187654,200302.6224,1.692173911,327.504465
81.8,49.37862265,1.452521836,202044.849,1.6869458,329.2641266
82,49.28144322,1.467024477,202408.2651,1.692173927,330.8625262
82.2,50.1461136,1.481599659,202202.3058,1.701758949,332.4304335
82.4,51.44786248,1.496287981,202115.923,1.708729954,333.6834615
82.6,51.5778894,1.511213141,202665.6603,1.712215396,335.2927611
82.8,51.70539951,1.526288449,203636.8339,1.711344055,336.7135643
83,52.09257055,1.541495257,205738.6666,1.703066215,338.4884831
83.2,53.05933418,1.556810833,208544.2137,1.690867338,340.638224
83.4,53.14605289,1.572347289,210692.1051,1.682153783,342.3444945
83.6,53.4920163,1.588020039,212770.0635,1.676054328,344.4364778
83.8,54.34278233,1.603811891,214089.2024,1.673876036,346.1068061
84,54.32222799,1.619828849,215456.5285,1.673222516,348.0990869
84.2,54.88957495,1.635962,216766.6094,1.672569065,349.9312115
84.4,55.29568383,1.652268711,218515.3054,1.669955043,352.0493463
84.6,55.3851587,1.668763235,219653.2883,1.669519375,353.7556176
84.8,55.60590396,1.68541361,220606.2247,1.671697793,355.7364624
85,55.75432634,1.702236634,220496.4278,1.679975699,357.451452
85.2,55.93845451,1.719226033,219767.8196,1.691303359,358.8199574
85.4,56.38265611,1.736366231,218055.3614,1.710908937,360.323574
85.6,56.87585887,1.753674959,217131.2305,1.723543669,361.5373662
85.8,57.31668151,1.77116153,216536.1526,1.735307039,363.0213701
86,58.20953601,1.788789527,216615.0126,1.741842323,364.4716064
86.2,58.25641225,1.80665896,217110.3894,1.744020722,365.7780029
86.4,58.9680538,1.824657294,218238.0415,1.743149451,367.5376742
86.6,59.71124436,1.842833991,219437.0068,1.74053547,368.9584907
86.8,60.49180057,1.861190586,220698.7138,1.738792851,370.7671937
87,60.85184533,1.879763642,221554.9535,1.739228573,372.3841247
87.2,61.08721159,1.898532723,222817.7364,1.736614531,373.8550519
87.4,61.46963354,1.917479104,224466.6073,1.733564828,375.706242
87.6,61.95756129,1.936607865,226319.9495,1.727901066,377.325356
87.8,62.13799128,1.955952233,229454.6367,1.716137768,379.4707255
88,63.02390298,1.975437528,232579.3884,1.704374552,381.544199
88.2,63.56158184,1.995245041,234960.135,1.696532402,383.371421
88.4,63.90647051,2.015066783,237299.9146,1.690432943,385.635558
88.6,64.48066557,2.035170401,237952.3691,1.694354118,387.6218593
88.8,65.06480044,2.05547535,237702.0823,1.702196402,389.1418241
89,65.63062107,2.07598569,237689.1317,1.708731649,390.8121484
89.2,66.24709953,2.096698209,237383.5496,1.717445296,392.6339261
89.4,66.32506164,2.117659797,237459.9393,1.722237771,394.0503721
89.6,67.11265808,2.138777982,238185.5626,1.724851938,395.9865561
89.8,67.31852587,2.160152655,238599.7846,1.728337393,397.4847235
90,68.02627919,2.181703927,238926.4613,1.732694265,399.0896761
90.2,68.35589636,2.203500504,239164.0467,1.739229486,400.836268
90.4,69.15332774,2.225480441,239579.4174,1.744893407,402.5643448
90.6,69.68231333,2.247701685,240165.7976,1.747507544,403.9165158
90.8,70.16722083,2.27014947,242047.1176,1.743150815,405.9082637
91,70.49004886,2.292835224,243911.2902,1.738358388,407.7049745
91.2,70.7122905,2.315756572,246149.6318,1.730516197,409.4624601
91.4,71.63169873,2.338854955,249765.0256,1.716138906,411.866076
91.6,72.18044716,2.362213903,251406.985,1.712653541,413.6824038
91.8,72.98759717,2.385787862,251767.5694,1.718753142,415.6294869
92,73.42325572,2.409626384,252311.9984,1.722674304,417.3837085
92.2,74.10069528,2.43368564,251652.1679,1.734437716,419.1357554
92.4,74.78806842,2.457985604,250052.9716,1.75012224,420.3277617
92.6,75.11807567,2.482557002,249252.2445,1.761885611,421.8640657
92.8,75.64166515,2.507360314,248732.5149,1.770163577,423.0560707
93,76.3405546,2.532399613,248599.5264,1.776698847,424.4540045
93.2,76.87902239,2.557702666,249125.392,1.779748667,426.076391
93.4,77.70580451,2.58323791,250306.8896,1.777570375,427.5233619
93.6,78.57492654,2.609026614,252637.1879,1.769728256,429.464997
93.8,79.0667364,2.635103124,255902.8918,1.75535091,431.29549
94,79.53856076,2.661443246,258898.6156,1.744023314,433.4060044
94.2,80.11504828,2.688039954,262149.1977,1.732260045,435.7671201
94.4,80.22779893,2.714939214,265079.48,1.721368084,437.756683
94.6,80.99699155,2.742058737,267901.5346,1.71309027,440.2420157
94.8,81.6630977,2.769458511,269079.3026,1.713961713,442.4048328
95,82.01421353,2.797157547,269967.7726,1.716140149,444.4063864
95.2,82.61624523,2.82511571,269722.1259,1.723982444,445.9753849
95.4,83.70602552,2.853318281,269147.982,1.735310236,447.8244144
95.6,84.24979779,2.881846671,268992.222,1.742716849,449.2811858
95.8,85.34696643,2.910619491,268407.0335,1.753608965,451.0016464
96,86.06224748,2.939710547,268202.2337,1.761451276,452.6185888
96.2,86.60920582,2.969106817,269674.2009,1.758401592,454.2616777
96.4,87.61814989,2.998763181,271854.4295,1.752302204,456.4321317
96.6,87.93732165,3.028769985,273326.8784,1.74838113,458.1645601
96.8,88.81695097,3.059035513,275821.0582,1.740103329,460.4308921
97,89.51329779,3.089619238,278919.1243,1.72877575,462.7429835
97.2,89.98190341,3.120527593,281724.8578,1.720933578,465.3143885
97.4,90.52109419,3.151741085,282875.3834,1.720933643,467.1121974
97.6,91.29623748,3.183250267,284844.6907,1.719191018,469.4918433
97.8,91.51955033,3.215118059,286583.118,1.717012649,471.478142
98,92.57214455,3.24724279,287680.2559,1.718755492,473.5385498
98.2,93.64338491,3.279688959,287683.2498,1.727033531,475.7155433
98.4,94.24880117,3.312496612,288334.7051,1.73008336,477.5220711
98.6,94.67300829,3.345647659,288378.4888,1.737489964,479.583555
98.8,95.19231133,3.379124579,287625.2021,1.747510657,480.9869378
99,95.98038766,3.412917254,287609.6446,1.754481626,482.7324541
99.2,96.97615865,3.44703386,288778.2821,1.755788786,484.7797868
99.4,97.32162197,3.481542808,290407.578,1.75448179,486.9938086
99.6,97.99859706,3.516373019,291974.4909,1.751867796,488.7829066
99.8,98.9273079,3.551534119,293888.7606,1.748382472,491.020914
100,100.0832397,3.587031264,294928.1265,1.749253972,493.0061441
100.2,100.6345662,3.622931147,295770.1667,1.750561078,494.7876117
100.4,101.5265433,3.659165691,296089.7531,1.756225024,496.824048
100.6,102.1296918,3.695786304,296218.4217,1.762106775,498.5374188
100.8,103.0115806,3.732753663,297840.7468,1.760582004,500.5046673
101,103.6943872,3.770107682,300246.8831,1.75491825,502.6544125
101.2,104.1415471,3.807854769,303139.3418,1.747511748,505.134295
101.4,105.0232571,3.84594811,306455.3723,1.73661986,507.2731518
101.6,105.7652992,3.884434754,310441.6639,1.723985234,510.0603015
101.8,106.7840013,3.923286052,311983.4971,1.721806956,512.1283402
102,107.4091655,3.9625567,313804.5129,1.719628632,514.57663
102.2,108.3068333,4.002201204,315234.0519,1.72006442,517.1578527
102.4,108.8770258,4.042268975,316127.8752,1.723549928,519.6170387
102.6,109.8177781,4.082711127,317025.9334,1.726164121,521.5543263
102.8,110.8515375,4.123552476,319592.72,1.722678805,524.0941505
103,112.0796846,4.164789375,320673.5305,1.725293033,526.3060192
103.2,112.6305046,4.20649216,321663.8498,1.72877854,528.6660531
103.4,113.4372047,4.248594365,321819.8784,1.734442479,530.5695611
103.6,114.3410641,4.291112299,321816.8439,1.74141347,532.8304515
103.8,115.0504027,4.33407221,321205.7191,1.749691479,534.5421933
104,115.8352932,4.377458005,320245.3444,1.759712219,536.2975178
104.2,117.0140065,4.421249631,319900.6547,1.767554607,538.3742793
104.4,117.6948835,4.465519158,320585.6297,1.769297412,540.0980042
104.6,118.8917382,4.510194188,322180.7595,1.768426199,542.4253692
104.8,119.432035,4.555368068,323576.5464,1.767119225,544.2558696
105,120.2905311,4.600971304,325979.8098,1.762762528,546.5429114
105.2,121.2428569,4.6470259,328384.5861,1.759277203,549.0729302
105.4,122.2931667,4.693535759,329869.8309,1.758405971,551.0494484
105.6,122.7641602,4.740795417,331130.934,1.75971307,553.3811539
105.8,123.9896982,4.787997472,332430.3755,1.75927754,555.2792255
106,125.2026579,4.835913644,334336.7258,1.756663606,557.5532028
106.2,125.9684653,4.884345121,337485.8064,1.749257131,560.3436258
106.4,126.823943,4.933256483,340775.2735,1.740107945,562.6960441
106.6,127.7441603,4.982654379,345516.3672,1.726601961,565.8318678
106.8,128.7382575,5.032542797,349476.6655,1.715710066,568.5013565
107,130.0912656,5.082905296,352075.9954,1.711353421,571.3026921
107.2,130.8724677,5.133817261,352965.9549,1.71483896,574.0604302
107.4,132.2784979,5.185193191,353382.164,1.720502976,576.6928864
107.6,133.014663,5.237136343,353947.7182,1.724424191,578.8851319
107.8,134.3739927,5.289553906,355220.4142,1.727038439,581.6025738
108,135.0343705,5.342551325,358275.7512,1.72224603,584.3777422
108.2,136.371926,5.396029747,361079.1805,1.717889383,586.8761791
108.4,137.1210505,5.450090189,362915.2492,1.719196515,589.7962648
108.6,138.5664641,5.504640923,362221.2825,1.728345986,591.7139608
108.8,139.7741256,5.559757817,361467.7128,1.738802473,594.0685677
109,140.7914008,5.615443111,361038.9281,1.747080534,596.2640952
109.2,142.0603793,5.671668524,360468.7645,1.755794308,598.6154384
109.4,142.9561505,5.728486812,361477.4933,1.756230099,600.681302
109.6,143.855155,5.785875493,365192.7736,1.746645227,603.6384386
109.8,145.3075122,5.843797815,367777.1638,1.742288592,606.5541868
110,146.2271079,5.902342199,370420.8208,1.737496212,609.3053964
110.2,146.862409,5.961496141,373568.312,1.730961073,611.9356523
110.4,148.1059058,6.021197921,377293.7559,1.723990325,615.1869877
110.6,149.1939109,6.081511429,378715.7614,1.724861818,617.5655664
110.8,150.4106243,6.142420991,380172.0576,1.72747605,620.4758626
111,151.516718,6.203950746,380288.1226,1.73444708,622.945967
111.2,152.9634225,6.266072873,380070.3362,1.74141816,625.0826702
111.4,154.1208407,6.328841242,380384.1772,1.747953522,627.7685116
111.6,155.6678967,6.392210395,381649.771,1.748825067,629.9738631
111.8,156.9888203,6.456233572,384142.1343,1.746211141,632.9124934
112,157.9980175,6.520923729,386628.8221,1.743161493,635.5874368
112.2,158.9663925,6.586266863,389175.2631,1.739676159,638.0836885
112.4,160.050172,6.652257726,391561.3807,1.738369247,641.1236431
112.6,161.1105782,6.718913267,393045.8348,1.740112104,643.9794588
112.8,162.2934503,6.786229512,395032.1584,1.738805201,646.4038059
113,163.3320363,6.854236157,398493.2712,1.733141463,649.4895223
113.2,164.4311766,6.922921582,400595.0117,1.733141601,652.6144657
113.4,165.8555432,6.992272183,402671.7694,1.731834724,655.2284079
113.6,167.1310504,7.062331115,406074.5259,1.727042385,658.5167953
113.8,168.6358015,7.133076484,408348.678,1.726171201,661.6875163
114,170.0361494,7.204540705,409564.6456,1.728349778,664.4703436
114.2,171.3998193,7.276725718,411964.1314,1.725735852,667.2466316
114.4,172.6723797,7.349642897,414766.3987,1.722686231,670.5230341
114.6,174.0196137,7.423287007,416369.3959,1.722686393,673.1598568
114.8,175.2200588,7.49768234,418546.6017,1.722250855,676.4918259
115,176.4257868,7.572824654,422438.7008,1.71571577,679.9305763
115.2,177.9230755,7.648699683,425640.5942,1.710923446,682.931325
115.4,178.9964336,7.725369416,427848.7116,1.711359256,686.4496094
115.6,180.3015182,7.802791855,429275.3221,1.713973505,689.4993833
115.8,181.5844577,7.880993869,429709.6695,1.719637526,692.3824509
116,182.8934489,7.959979593,429483.5157,1.727479963,695.1685473
116.2,184.3020341,8.039751351,429970.6011,1.733579684,698.2815217
116.4,185.6593855,8.120328562,432379.4435,1.731401437,701.1231899
116.6,186.4980645,8.201754806,435878.7935,1.726609033,704.7373513
116.8,188.3184397,8.283924436,439655.7248,1.719638334,707.803488
117,189.843679,8.366942324,444456.1263,1.710924868,711.5516913
117.2,191.4115824,8.450790908,449189.4332,1.70308277,715.5777427
117.4,192.995972,8.535480755,450562.915,1.705261371,718.5872145
117.6,194.6408895,8.62101688,452549.9458,1.707004296,722.3681125
117.8,196.0347086,8.707431635,454603.6511,1.707004462,725.3612356
118,197.2011111,8.794732043,455747.5861,1.710490062,728.5744461
118.2,198.5290039,8.882897136,454300.0142,1.723125019,731.7310069
118.4,200.1052252,8.971929232,453389.45,1.732274545,734.2501696
118.6,201.3883767,9.061878203,452551.9881,1.742295404,737.1757379
118.8,203.1600131,9.152693822,450546.5935,1.755801787,739.8714197
119,204.4387213,9.244459281,450357.8079,1.762337186,742.4908179
119.2,206.196355,9.337110058,452919.8291,1.758851939,745.2115627
119.4,207.5749052,9.430716165,457803.3436,1.749267083,748.9532299
119.6,209.4145116,9.525227658,461238.4502,1.743603427,751.9332992
119.8,210.7470566,9.620727337,464151.1565,1.741425174,755.4189152
120,212.4351178,9.717159527,465743.4115,1.743603794,758.4992196
120.2,213.9867409,9.814570954,465449.3287,1.752317646,761.5392025
120.4,215.8124391,9.912940223,465040.4244,1.759724483,763.8535419
120.6,217.1551685,10.01233457,467395.9917,1.759724648,767.2062304
120.8,218.7104758,10.11271133,470756.3428,1.754932323,770.1492459
121,220.5647835,10.2140739,476109.0147,1.744476149,773.7874265
121.2,222.184587,10.31647265,481243.1292,1.736198361,777.8200265
121.4,224.0252737,10.41988329,484880.5456,1.731406065,781.0899268
121.6,225.4486325,10.52436474,487003.8903,1.732277604,784.8000054
121.8,227.3430028,10.62985995,488276.5773,1.734020567,787.6874673
122,228.7851397,10.73644937,489669.0887,1.736634843,790.9660737
122.2,230.8952323,10.8440591,492915.8893,1.73445668,794.9311384
122.4,232.5115379,10.95278746,494059.8373,1.736635294,797.8316674
122.6,234.0262878,11.06261599,494805.7268,1.741427999,801.3194758
122.8,235.7502751,11.173532,495599.9991,1.744913678,804.1480967
123,237.671033,11.28554757,495788.3063,1.750577802,807.2556594
123.2,239.4719479,11.39869783,494687.7309,1.760163068,810.250989
123.4,240.7748202,11.51359844,495047.4787,1.764520068,812.8649473
123.6,242.5570883,11.62904667,495988.4707,1.768441443,816.0792847
123.8,244.5337203,11.7450536,495552.6502,1.774976948,818.4720851
124,246.1585597,11.8628393,495385.742,1.781512411,821.0337583
124.2,248.2186569,11.9817751,496673.0624,1.784562456,824.087938
124.4,250.013201,12.02000038,499903.5474,1.780205835,826.9383572
124.6,251.3634393,12.01989788,507065.9904,1.765828419,831.0134494
124.8,252.2325267,12.01983184,515305.8531,1.747965468,834.7758133
125,252.7525927,12.01979223,526331.832,1.724438577,839.6386386
125.2,253.4953677,12.01973576,536110.8045,1.706139923,844.7760495
125.4,254.3694413,12.01966933,542856.1713,1.697426338,849.6345335
125.6,254.5072457,12.01965869,543773.8397,1.702218883,852.9904534
125.8,255.3489102,12.01959472,542132.8724,1.715289514,856.7103226
126,255.7717489,12.01956249,539424.5093,1.730102835,859.8897392
126.2,256.2444478,12.01952647,537394.5899,1.741866371,862.6169869
126.4,256.6564834,12.01949505,535001.8194,1.755372639,865.7887791
126.6,256.818387,12.01948259,535745.2557,1.758858134,868.5922806
126.8,257.1905345,12.01945419,534859.5814,1.768007553,871.8545075
127,257.0856858,12.01946194,535407.6391,1.772364386,874.800735
127.2,257.8808142,12.01940149,535189.6632,1.778464066,877.3678211
127.4,257.9039402,12.01939954,534455.156,1.786742074,880.27919
127.6,258.114873,12.01938336,534000.4511,1.792841683,882.655577
127.8,258.2285783,12.01937455,536910.6987,1.790663275,886.0550813
128,258.6597271,12.01934168,537872.1148,1.793277436,888.9315968
128.2,258.7194172,12.01933696,537447.7205,1.798941333,891.2938108
128.4,258.8738417,12.01932506,537528.298,1.804169571,894.2454999
128.6,259.2966805,12.01929282,537658.0031,1.808962154,897.0958634
128.8,259.0738293,12.01930951,535912.2684,1.818111506,899.0385796
129,259.6038676,12.01926915,533986.1529,1.828132313,901.0793961
129.2,259.4965259,12.01927708,536086.0919,1.82682524,903.9428097
129.4,259.5080178,12.01927601,536489.812,1.829875036,906.055511
129.6,259.5535808,12.01927236,535814.7416,1.836846002,908.3109492
129.8,259.850938,12.01924963,535348.6903,1.842074253,910.152357
130,260.0020386,12.01923798,537538.1525,1.84033153,912.5984769
130.2,260.0326435,12.01923546,538520.123,1.842945642,915.0543977
130.4,260.4330452,12.01920493,540290.3577,1.842074324,917.215058
130.6,260.4570022,12.01920291,543555.4164,1.837717483,919.9706137
130.8,260.668766,12.01918667,546638.2828,1.833360662,922.4200052
131,260.5543608,12.01919514,547955.8623,1.834667705,925.0567932
131.2,260.8164003,12.01917508,547758.5793,1.839460265,927.1455322
131.4,260.9055911,12.01916813,548053.2378,1.843381442,929.5426183
131.6,261.0999038,12.0191532,547470.8269,1.848609685,931.2761564
131.8,260.9863296,12.01916161,545523.0512,1.858194731,933.1567727
132,261.3983654,12.01913019,543929.4539,1.866037104,934.794432
132.2,261.1264849,12.01915059,543206.5675,1.871265287,936.5824254
132.4,261.0494749,12.01915623,542554.9982,1.875622124,938.0653462
132.6,261.3592972,12.01913255,543253.5343,1.876929218,940.0516681
132.8,261.7056837,12.01910611,545115.8952,1.87475084,941.7852112
133,261.4579023,12.01912468,547438.0945,1.872136701,943.8521382
133.2,261.8101058,12.0190978,551105.5858,1.866472847,946.3843441
133.4,261.784618,12.01909953,551413.4622,1.870394005,948.3314285
133.6,261.7138405,12.01910469,550360.1872,1.876929265,949.7032108
133.8,261.6887682,12.01910639,548543.1509,1.885642954,951.1578012
134,262.0118866,12.01908171,544858.6114,1.89914922,952.048007
134.2,262.0429071,12.01907916,540792.0438,1.913091132,952.5056336
135,261.9107352,11.90860516,1.7977E+308,1.920497752,0
135.2,262.1149962,11.78849904,1.7977E+308,1.834232223,0
135.4,261.4267588,11.66846053,1.7977E+308,1.67825705,0
135.6,261.5703565,11.548359,1.7977E+308,1.45692929,0
135.8,260.9922272,11.42831216,1.7977E+308,1.169813093,0
136,261.0336114,11.30821837,1.7977E+308,0.801006099,0
136.2,260.5913513,11.18816123,1.7977E+308,0.499730196,0
136.4,260.5143174,11.06807642,1.7977E+308,0.283412808,0
136.6,260.556948,10.94798254,1.7977E+308,0.136369268,0
136.8,260.1907248,10.82791963,1.7977E+308,0.018734436,0
137,260.1406985,10.70783277,1.7977E+308,0.017863067,0
137.2,259.6535642,10.58777903,1.7977E+308,0.01917012,0
137.4,259.5827629,10.46769375,1.7977E+308,0.02309128,0
137.6,258.961006,10.34765021,1.7977E+308,0.025269702,0
137.8,259.3123546,10.22753294,1.7977E+308,0.02701244,0
138,259.0429433,10.1074627,1.7977E+308,0.027448124,0
138.2,258.5674431,9.987408075,1.7977E+308,0.025705385,0
138.4,258.3869492,9.8673311,1.7977E+308,0.023526963,0
138.6,258.2721047,9.747249152,1.7977E+308,0.022219909,0
138.8,257.8921699,9.627187288,1.7977E+308,0.019605802,0
139,257.3468654,9.507137954,1.7977E+308,0.018298747,0
139.2,257.3732915,9.387045302,1.7977E+308,0.01176348,0
139.4,257.2102488,9.266967005,1.7977E+308,0.005228213,0
139.6,256.8984564,9.146899979,1.7977E+308,0.000871369,0
139.8,256.6813984,9.026825775,1.7977E+308,0.003049791,0
140,256.597301,8.906741497,1.7977E+308,0.008278004,0
140.2,256.1666751,8.786683474,1.7977E+308,0.005663897,0
140.4,255.8382626,8.666617706,1.7977E+308,0.004356844,0
140.6,255.7250801,8.546535632,1.7977E+308,0.009585057,0
140.8,255.4016536,8.426469487,1.7977E+308,0.01481327,0
141,255.1164534,8.306400446,1.7977E+308,0.014813269,0
141.2,254.8994909,8.185725782,1.7977E+308,0.018734428,0
141.4,254.7097606,8.066249959,1.7977E+308,0.026141063,0
141.6,254.3298259,7.946188096,1.7977E+308,0.034854749,0
141.8,254.1867273,7.826108288,1.7977E+308,0.047053911,0
142,254.0270086,7.70602974,1.7977E+308,0.060560125,0
142.2,253.8631349,7.585951506,1.7977E+308,0.064916968,0
142.4,253.7532764,7.46586918,1.7977E+308,0.071452233,0
142.6,253.2844244,7.345814053,1.7977E+308,0.074502021,0
142.8,252.8438266,7.225756785,1.7977E+308,0.074937702,0
143,252.8611116,7.105664826,1.7977E+308,0.066224016,0
143.2,252.5634464,6.985596729,1.7977E+308,0.055767591,0
143.4,252.2076109,6.86553304,1.7977E+308,0.036597481,0
143.6,252.0196381,6.745456632,1.7977E+308,0.014813266,0
143.8,251.7111698,6.625389353,1.7977E+308,0.004356843,0
144,251.5414791,6.50531156,1.7977E+308,0.012634844,0
144.2,251.3277452,6.385237104,1.7977E+308,0.014813265,0
144.4,250.7699759,6.265188715,1.7977E+308,0.010892106,0
144.6,250.7540209,6.145099274,1.7977E+308,0.004792527,0
144.8,250.4181295,6.025034073,1.7977E+308,0.001307053,0
145,250.2243397,5.904958106,1.7977E+308,0.002614105,0
145.2,249.9690557,5.784886798,1.7977E+308,0.006535263,0
145.4,249.6514464,5.664820212,1.7977E+308,0.015684632,0
145.6,249.4152755,5.544747456,1.7977E+308,0.026576737,0
145.8,249.1491884,5.424676967,1.7977E+308,0.037033157,0
146,248.79086,5.304613466,1.7977E+308,0.044875471,0
146.2,248.6020563,5.184537121,1.7977E+308,0.046618207,0
146.4,248.1946987,5.064477335,1.7977E+308,0.045746838,0
146.6,248.1662786,4.944388839,1.7977E+308,0.047489574,0
146.8,247.9001916,4.824318349,1.7977E+308,0.047925257,0
147,247.5094541,4.704257304,1.7977E+308,0.049667993,0
147.2,247.2633112,4.584185304,1.7977E+308,0.056638938,0
147.4,247.1908479,4.464100144,1.7977E+308,0.064045568,0
147.6,246.151928,4.344088209,1.7977E+308,0.064045563,0
147.8,246.2136717,4.223992881,1.7977E+308,0.05838167,0
148,246.1316519,4.103908446,1.7977E+308,0.050539356,0
148.2,245.7986692,3.983843025,1.7977E+308,0.044004093,0
148.4,245.7112479,3.863758999,1.7977E+308,0.043132725,0
148.6,245.0408779,3.74371914,1.7977E+308,0.036161778,0
148.8,245.0369724,3.623628786,1.7977E+308,0.027448096,0
149,244.6391715,3.503568276,1.7977E+308,0.016991678,0
149.2,244.1628408,3.383513716,1.7977E+308,0.010892101,0
149.4,244.0172492,3.263434097,1.7977E+308,0.012199153,0
149.6,243.7590568,3.14336301,1.7977E+308,0.010020733,0
149.8,243.4626383,3.023294818,1.7977E+308,0.010456416,0
150,243.1146976,2.903230531,1.7977E+308,0.011763468,0
150.2,242.7754824,2.783165582,1.7977E+308,0.010456416,0
150.4,242.6315529,2.663085837,1.7977E+308,0.005663892,0
150.6,242.4934404,2.543005651,1.7977E+308,0.004792524,0
150.8,241.8118521,2.422966643,1.7977E+308,0.006970943,0
151,241.6953457,2.30288482,1.7977E+308,0.011763467,0
151.2,241.040765,2.182843765,1.7977E+308,0.015248938,0
151.4,240.865673,2.062766382,1.7977E+308,0.018734409,0
151.6,240.4500056,1.942707225,1.7977E+308,0.023962616,0
151.8,239.8461161,1.82266233,1.7977E+308,0.033983345,0
152,239.4832175,1.702599175,1.7977E+308,0.038775866,0
152.2,239.1996796,1.582530008,1.7977E+308,0.037468814,0
152.4,238.8027098,1.462469435,1.7977E+308,0.035290394,0
152.6,238.6608579,1.342389533,1.7977E+308,0.0270124,0
152.8,238.2647191,1.222328897,1.7977E+308,0.016120303,0
228,237.6484265,1.108815044,1.7977E+308,0.009585045,0
228.2,236.9585284,0.988776665,1.7977E+308,0.009149361,0
228.4,236.6965966,0.868705861,1.7977E+308,0.011763464,0
228.6,235.851301,0.748679256,1.7977E+308,0.020912823,0
228.8,235.9857574,0.628578419,1.7977E+308,0.037904492,0
229,235.2418442,0.508544132,1.7977E+308,0.051410687,0
229.2,235.1162923,0.387862543,1.7977E+308,0.061431414,0
229.4,234.50192,0.268418894,1.7977E+308,0.06360983,0
229.6,233.8710232,0.148376044,1.7977E+308,0.052717734,0
229.8,232.7599025,0.027769127,1.7977E+308,0.041389953,0
229.83,232.6244242,0.009765794,1.7977E+308,0.040082901,0
,,,,,