File: Test_1.csv
Time On Sample,Displacement Into Surface,Load On Sample,Harmonic Contact Stiffness,Harmonic Displacement,Harmonic Load
0,0,0,-278.8031494,0.315002406,2.235840131
0.2,0.24544832,0.000740135,3518.561046,0.217408303,2.312111507
0.4,0.064588276,0.001512531,10999.60189,0.153362168,2.412353835
0.6,0.305050534,0.002253044,18101.71794,0.128092267,2.502789892
0.8,0.105077249,0.003026886,22017.68376,0.115021626,2.593225906
1,0.266593514,0.003773373,23504.46405,0.113714564,2.681482771
1.2,0.337529639,0.004526714,25047.32174,0.115893004,2.911386425
1.4,0.31206855,0.00528735,27209.152,0.116328692,3.207755106
1.6,0.520121405,0.006030315,29396.0657,0.113714566,3.512840529
1.79,0.493232586,0.006753124,29860.7939,0.118071445,3.749281717
2,0.428480091,0.007552295,30253.93744,0.125913829,4.032575302
2.2,0.762015899,0.008283447,32844.14577,0.13506328,4.581729102
2.4,0.370910566,0.009069436,34594.01874,0.144212724,5.070955259
2.6,0.547385391,0.009812474,35389.91806,0.159897493,5.636452888
2.8,0.771227817,0.010551926,36564.2916,0.17209676,6.200860971
3,0.83634724,0.01130339,37956.66641,0.181681897,6.766358589
3.2,0.842464918,0.012059319,40486.58219,0.192138409,7.609701831
3.4,0.969079119,0.01280613,42750.62935,0.202159235,8.467209833
3.6,0.824783895,0.013573441,44953.93532,0.211308681,9.320359324
3.8,0.709574041,0.014338551,46477.33765,0.222636567,10.16479211
4,1.024827626,0.015071085,46264.63745,0.241806844,10.9885229
4.2,0.858095118,0.015840094,45993.61513,0.265333994,11.99857342
4.4,0.885819069,0.016594388,46011.66843,0.291910963,13.17097315
4.6,1.017419334,0.017340821,44616.99241,0.325458942,14.2191595
4.8,0.711908073,0.018120331,43149.85921,0.356828471,15.05705462
5,0.482018772,0.01889412,41596.41353,0.396040385,16.09870318
5.2,0.612788022,0.019640617,41021.33129,0.427845613,17.14144163
5.4,0.608933574,0.0203973,40154.12081,0.467928908,18.35088736
5.6,0.52613313,0.021159958,39535.2542,0.504962385,19.5036743
5.8,0.775736882,0.021897461,38791.06829,0.543738626,20.6215947
6,0.525072317,0.022672822,37400.31301,0.591664297,21.64580969
6.2,0.901820677,0.023400703,35830.9169,0.644382561,22.60900836
6.4,0.859739745,0.024160279,34091.39641,0.706685944,23.62014857
6.6,0.485254616,0.02494501,32182.41506,0.776831693,24.54412108
6.8,0.679180665,0.025686727,29999.14585,0.860483799,25.37765827
7,0.704411584,0.026441209,28260.29202,0.933679385,26.02269614
7.2,0.75706585,0.027193616,26359.3146,1.019074237,26.64049412
7.4,0.781881264,0.027948129,24238.57737,1.123203672,27.2201564
7.6,0.792153994,0.028703743,22735.17171,1.207291458,27.60042362
7.8,1.099097478,0.029436907,21265.34291,1.302707159,28.03952913
8,0.865053117,0.030211009,20338.22227,1.375031347,28.44049814
8.2,0.958426899,0.030960334,19885.11436,1.423392725,28.79788408
8.4,0.917592483,0.031719815,19695.25098,1.45432657,29.12803011
8.6,1.250712802,0.032450997,19563.35289,1.483517701,29.54534386
8.8,1.563473369,0.033183719,19544.21602,1.500073879,29.89292368
9,1.92152402,0.033913013,19791.7329,1.505302173,30.35491073
9.2,1.399534491,0.034708904,20357.81153,1.488310286,30.83759867
9.4,1.466731445,0.035460208,21268.99631,1.451276811,31.34643766
9.6,1.708855519,0.036202059,23116.4269,1.377645559,32.11786832
9.8,1.609850363,0.03696594,25142.12389,1.304885649,32.83481898
10,1.89269516,0.037697141,27943.6045,1.218183755,33.77731545
10.2,1.668207408,0.038470518,30239.40498,1.15980154,34.60758327
10.4,1.881662223,0.039210754,32490.55676,1.11274725,35.52284001
10.6,1.261197946,0.040014097,33649.11436,1.096626746,36.20819169
10.8,0.821062974,0.040803795,33924.76292,1.108390289,36.94039596
11,1.067758197,0.041541517,32570.50095,1.162415622,37.39148689
11.2,1.874970042,0.042236821,29694.48829,1.273080449,37.70093211
11.4,2.536339571,0.04294316,25991.20359,1.439077657,37.75977115
11.6,2.343430212,0.043714146,23377.71306,1.580676256,37.68023066
11.8,2.557300542,0.044454349,21112.82412,1.73098866,37.55492812
12,2.74250101,0.045196721,21051.81192,1.745802077,37.70202329
12.2,2.86122063,0.045944123,22538.29604,1.663021358,38.2043249
12.4,2.918860969,0.046696148,25536.42526,1.511619761,39.01171188
12.6,3.001847133,0.047446255,29548.82452,1.351504403,39.97382085
12.8,2.600354102,0.048233025,33776.68213,1.22036226,40.91631605
13,2.645529281,0.048985993,38210.39364,1.114925753,42.02551973
13.2,2.637935286,0.049742955,40108.00174,1.085734652,42.85687751
13.4,2.568431,0.050504602,40034.16886,1.107083363,43.5967096
13.6,2.57454868,0.051260526,39071.44479,1.151959234,44.24937461
13.8,2.662936411,0.052010225,37954.0614,1.197706488,44.69828618
14,2.62750356,0.052769293,36562.79633,1.256524374,45.23218559
14.2,2.644839884,0.053524368,35507.49297,1.304014375,45.70615768
14.4,2.66633126,0.054279129,34788.09843,1.340176484,46.1409046
14.6,2.610123144,0.055039769,34172.47182,1.37416015,46.68678956
14.8,2.412227719,0.055811132,33892.65607,1.393330405,47.11608782
15,2.850470921,0.056534355,33696.35328,1.414243475,47.64562983
15.2,2.667118178,0.057304617,33626.04865,1.43167098,48.12395995
15.4,2.691102587,0.058059188,33403.72448,1.4530197,48.52492947
15.6,2.828104441,0.058805207,33015.87496,1.485260631,48.96403477
15.8,2.652230794,0.059574903,32730.98429,1.51009483,49.30507631
16,2.699899005,0.060327683,32243.20811,1.543207131,49.68098542
16.2,2.79077977,0.061077192,31762.64755,1.574140993,49.9926085
16.4,2.993431465,0.061818242,31635.62966,1.590697163,50.29442568
16.6,3.181124972,0.062560425,31857.70623,1.593311314,50.71609782
16.8,3.365494439,0.063302858,32163.89942,1.591132892,51.07784247
17,3.716066044,0.064032714,33160.76132,1.564991646,51.61828044
17.2,3.555981589,0.064801214,34743.10781,1.51706594,52.23498851
17.4,3.568747356,0.065556633,36799.8958,1.457812361,53.00097097
17.6,3.397859764,0.06632595,38523.02765,1.413372159,53.64382918
17.8,3.566024526,0.067069609,40688.59746,1.362396668,54.45666446
18,3.440842521,0.067835467,42185.33861,1.33233418,55.12240419
18.2,3.371338231,0.068597112,43251.58185,1.321006284,55.95703089
18.4,2.91541399,0.069388,43487.73961,1.327977252,56.51381037
18.6,3.472491735,0.070102228,43016.78658,1.357168405,57.10328078
18.8,3.553400377,0.07085249,42373.21557,1.391587773,57.66986835
19,3.761453654,0.07159313,41859.71472,1.418600455,58.07955513
19.2,3.474224565,0.072371251,41400.71753,1.448227218,58.66357502
19.4,3.39807219,0.073133399,41263.8121,1.463040606,59.08633605
19.6,3.42828918,0.073887497,41834.01607,1.45824804,59.72701567
19.8,3.708640385,0.074622666,42523.90338,1.450405683,60.40365224
20,3.428059383,0.075400284,43059.32827,1.444306022,60.9342825
20.2,3.789849635,0.07612929,43672.03667,1.438206425,61.57169434
20.4,3.491817407,0.076908228,44312.64362,1.432978139,62.28864425
20.6,3.726463025,0.077646856,44480.77481,1.438642108,62.8181859
20.8,3.785765391,0.078398753,44660.61514,1.446048812,63.45559707
21,3.754487592,0.079157503,44934.64804,1.451277067,64.09736594
21.2,3.91184922,0.079901979,45058.59019,1.460426533,64.68574548
21.4,3.588886668,0.080682804,45209.32158,1.466961823,65.18913558
21.6,3.93239469,0.081413193,45441.2533,1.473932867,65.82109946
21.8,4.049867605,0.082161954,45615.13721,1.482646642,66.43889781
22,3.75765114,0.082948663,45694.2869,1.490924687,66.92703341
22.2,4.008914446,0.083701958,45915.47702,1.49615297,67.49035282
22.4,3.914476082,0.084489086,46220.40966,1.500509842,68.1397491
22.6,4.341080219,0.085244424,46348.83786,1.509223649,68.76081734
22.8,4.286527928,0.086043879,46532.97878,1.513144837,69.26311848
23,4.640831646,0.08682039,46725.73303,1.51880882,69.85258833
23.2,4.527275034,0.087640402,46915.95076,1.523601378,70.40718984
23.4,4.55332694,0.088457935,47136.16714,1.52839395,71.02607788
23.6,4.435612665,0.089294679,47584.85486,1.524908434,71.54908094
23.8,4.474958088,0.090127907,47778.93914,1.532315136,72.15053528
24,4.572472944,0.090965035,48109.96829,1.535800652,72.76506491
24.2,4.578575264,0.091817599,48244.4716,1.544078728,73.31857719
24.4,4.489941018,0.092685777,48220.26949,1.554970922,73.74787605
24.6,4.697145213,0.093540263,47937.6651,1.575448287,74.2687013
24.8,4.483025574,0.094435363,47867.00655,1.588518908,74.80368939
25,4.745073696,0.095303209,47639.99713,1.603985866,75.21827979
25.2,4.678040153,0.096204826,47513.42078,1.616620815,75.6573849
25.4,4.640090534,0.097113379,47512.87411,1.62511673,76.10139283
25.6,4.820279798,0.098014474,47672.51672,1.630345008,76.60914303
25.8,4.847561632,0.098936276,47972.51524,1.631216388,77.13323639
26,4.883567607,0.099866678,48466.84128,1.624245382,77.59086467
26.2,4.890071203,0.100808736,48939.50437,1.619452814,78.1116893
26.4,4.8487902,0.10176372,49409.69789,1.615531617,78.66629105
26.6,4.713603456,0.102735408,49877.64213,1.612481785,79.23505707
26.8,4.76497708,0.103702702,50134.36246,1.616402985,79.7667776
27,5.008312651,0.104665164,50170.40228,1.624681087,80.17755433
27.2,5.00275936,0.105653619,50582.96784,1.625116775,80.78336695
27.4,5.000942433,0.10666183,51154.68324,1.617710077,81.27150374
27.6,5.299535896,0.10764734,52066.77388,1.602896713,81.9339762
27.8,5.107831425,0.108679861,53184.4085,1.583290726,82.64874719
28,5.239803603,0.109700788,54362.58895,1.561506333,83.28615855
28.2,5.236319379,0.110742308,55486.22474,1.544514496,84.04505881
28.4,5.457206401,0.111777339,56025.2321,1.541900391,84.70153836
28.6,5.334053301,0.112848811,56329.58749,1.54625726,85.4010552
28.8,5.215884557,0.113930667,56426.11726,1.55279257,85.91643128
29,5.396462475,0.11500071,56387.32578,1.564120482,86.52333413
29.2,5.320671845,0.116100971,56442.09125,1.572398549,87.1117131
29.4,5.425208811,0.117198566,56853.85682,1.573269937,87.81014126
29.6,5.594562864,0.118302312,57317.62076,1.571091515,88.38326701
29.8,5.941751469,0.119403708,58191.39062,1.560635037,89.12528006
30,5.649890979,0.120564635,58831.94345,1.556713813,89.84222976
30.2,5.726997468,0.121709123,59300.59673,1.556278133,90.50361196
30.4,5.914626549,0.122856864,59588.13818,1.561506412,91.22819081
30.6,5.56001922,0.124057287,59731.52902,1.56717032,91.76971599
30.8,5.851936453,0.125220445,59458.87709,1.585033567,92.37444044
31,5.997593898,0.126406534,59484.01043,1.593747347,92.93558037
31.2,6.208483812,0.127599541,59709.65915,1.598104253,93.55011072
31.4,6.444302157,0.128802598,60125.10503,1.597668591,94.17335791
31.6,6.393835309,0.13003962,60887.48783,1.589826199,94.9055629
31.8,6.326746278,0.131290265,62103.11116,1.572398664,95.73256234
32,6.434998577,0.132539974,62845.68454,1.564556289,96.36997359
32.2,6.478014488,0.133807431,63638.63828,1.557585283,97.13050846
32.4,6.458702541,0.135092458,64356.26867,1.552792709,97.95641833
32.6,6.533708303,0.136383081,64693.3348,1.555842535,98.71586376
32.8,6.808985631,0.137671476,64793.00106,1.561942198,99.31840895
33,6.733989789,0.138999507,65126.83845,1.56455632,100.0822116
33.2,6.882949284,0.140323772,65448.13186,1.567170465,100.8013428
33.4,6.765567645,0.141681695,65679.2325,1.574141466,101.5531602
33.6,6.737933032,0.143046351,65972.36328,1.577626971,102.1524348
33.8,6.795059367,0.144418188,66346.4753,1.581548168,102.8900883
34,6.985145259,0.145793713,66770.23761,1.584162319,103.6462655
34.2,6.984511946,0.147197553,66975.14937,1.589826268,104.3000202
34.4,6.941079304,0.1486189,67259.90975,1.594183143,105.0551066
34.6,7.08669938,0.150040162,67398.66097,1.598975728,105.6358595
34.8,6.794374444,0.151508855,67248.66815,1.611610656,106.293971
35,7.111178167,0.152946075,66910.22906,1.628166844,106.9128604
35.2,6.984219753,0.15443147,67096.13007,1.632523714,107.5535394
35.4,7.341738334,0.15589506,67485.98756,1.633830822,108.2715824
35.6,7.145801276,0.157415471,67989.0256,1.630345291,108.8545121
35.8,7.40110076,0.158916731,68878.73149,1.620760181,109.6608109
36,7.129536886,0.160473205,69879.12892,1.610303636,110.5161391
36.2,7.226108394,0.162017249,70313.96225,1.611175024,111.2418075
36.4,7.477245476,0.163565053,70829.90208,1.608996611,111.8846675
36.6,7.739183252,0.165127465,71439.21441,1.607689576,112.7105788
36.8,7.712757717,0.166727545,71855.58639,1.608125262,113.3567065
37,7.960563239,0.168322934,72324.68772,1.609432355,114.1793491
37.2,8.196732066,0.169935228,72876.63591,1.608125316,114.9420642
37.4,7.889417111,0.171605106,72940.00405,1.615531983,115.5718462
37.6,8.089016217,0.173253113,73007.75481,1.624681459,116.3193068
37.8,8.144016776,0.174928682,73141.25385,1.630345413,116.9153138
38,8.095138259,0.176629133,73191.51793,1.639930549,117.6289958
38.2,8.276447091,0.178329084,73038.58403,1.652565529,118.2555118
38.4,8.449443101,0.180046733,73221.60264,1.656922432,118.8297272
38.6,8.517728946,0.181789819,73258.03798,1.666071894,119.5281557
38.8,8.286017045,0.1835731,73170.31208,1.675221321,120.0380829
39,8.543767789,0.185337103,73308.33568,1.681320987,120.7168998
39.2,8.351938761,0.187152936,73633.44989,1.682192342,121.3412345
39.4,8.591401557,0.188954226,73759.50322,1.686549253,121.8914794
39.6,8.815072248,0.190774952,74140.10654,1.687420656,122.5909983
39.8,8.997189493,0.192617065,74570.82875,1.687420677,123.2981443
40,9.269884026,0.194470668,74731.12559,1.691341904,123.844031
40.2,9.380528423,0.196355332,75050.90734,1.693084671,124.4705467
40.4,9.584243042,0.198251927,75577.27543,1.691341942,125.1951263
40.6,9.541144367,0.200186164,75943.86464,1.690470561,125.7540862
40.8,9.621863249,0.202130463,76384.52556,1.689599194,126.460142
41,9.826399665,0.204084986,77027.60646,1.683499582,127.0986436
41.2,9.925394551,0.206067162,77821.13629,1.67696427,127.9648692
41.4,9.758462735,0.208089353,78402.23865,1.67217168,128.5968314
41.6,10.21894107,0.210084273,79175.37474,1.666072097,129.4260132
41.8,10.28800998,0.212128947,79947.74647,1.658665404,130.1375169
42,10.26898844,0.214200948,80645.65419,1.654308519,130.9470833
42.2,10.71948489,0.216258038,81273.4335,1.650823064,131.7315916
42.4,10.50059858,0.218386624,81744.6545,1.651258728,132.5738445
42.6,10.49610978,0.220520122,82334.61752,1.64820891,133.2929747
42.8,10.82235999,0.222650083,82871.98545,1.648208948,134.146127
43,10.79792009,0.224828075,83290.09801,1.648208946,134.8445547
43.2,10.81128773,0.227024983,83515.21106,1.653001519,135.5865668
43.4,10.80927816,0.229245137,83856.56623,1.656922714,136.3939536
43.6,11.01418682,0.231471947,83966.64018,1.663022375,137.0368141
43.8,10.8900115,0.233746084,84179.7467,1.669121998,137.8180501
44,10.67899186,0.236049782,84411.4412,1.673478858,138.4511015
44.2,11.04676786,0.238332468,84909.27604,1.673478901,139.1822198
44.4,11.28781098,0.240647842,85690.04023,1.669557734,140.0756863
44.6,11.10503472,0.24301865,86309.01529,1.666507895,140.798084
44.8,11.39136048,0.24537761,86974.23689,1.664329487,141.6948199
45,11.66272427,0.247761468,87225.54497,1.66650796,142.3376807
45.2,11.58256456,0.250208297,87595.88291,1.667815016,143.1123796
45.4,11.40559204,0.252662492,87726.99311,1.674350322,143.9208553
45.6,11.66572555,0.255120417,87631.96597,1.68306412,144.5332076
45.8,11.49996186,0.257635493,87396.56778,1.695699063,145.232724
46,11.50953755,0.260162419,87536.13902,1.701798702,145.9518544
46.2,11.63254222,0.26270615,87362.36949,1.712690926,146.5674743
46.4,12.0339316,0.265254194,87376.07727,1.718790611,147.1199004
46.6,11.84779194,0.267872725,87579.58094,1.723147473,147.8292229
46.8,12.05679396,0.270487429,87975.36601,1.72271181,148.4437538
47,11.88934371,0.27315706,88658.02195,1.718790595,149.2315274
47.2,11.98365773,0.275833578,89647.1988,1.709205463,150.029109
47.4,12.04514254,0.278539488,90649.43347,1.699184638,150.7874653
47.6,12.17518145,0.281267372,91868.87797,1.687421068,151.7419482
47.8,12.14649287,0.284034713,92631.19544,1.681757116,152.4839599
48,12.6903666,0.286786453,92876.63191,1.686549752,153.3283973
48.2,13.14407125,0.289572626,92576.57233,1.699184769,153.9897827
48.4,13.44943594,0.292398056,91947.24498,1.716176653,154.4801011
48.6,13.80465681,0.295248011,91121.36716,1.737961117,155.037975
48.8,13.50711373,0.298176212,90642.78363,1.751903111,155.4890634
49,13.72271549,0.301094742,90505.38236,1.760616906,156.0872507
49.2,13.82571054,0.304051265,90958.17864,1.758874165,156.7377377
49.4,13.93410245,0.307036985,91887.73565,1.748417657,157.40021
49.6,14.17004983,0.310043064,93354.5805,1.730990148,158.3154688
49.8,14.36028678,0.313082886,94645.45639,1.716830297,159.1664413
50,14.24387569,0.316176458,95826.74604,1.705720229,160.0359344
50.2,14.13950934,0.319300099,96713.07707,1.699620575,160.8988898
50.4,14.6849889,0.322405792,97304.60284,1.697006509,161.6452646
50.6,14.6765944,0.325584792,97807.9951,1.697442197,162.5441777
50.8,14.79949462,0.328785829,98501.35365,1.693521015,163.2894587
51,14.72793306,0.332033793,99458.91852,1.687421369,164.2777177
51.2,14.55830698,0.335321757,100366.5982,1.681757401,165.2093174
51.4,15.14946659,0.338584966,101075.5504,1.678271965,166.0079925
51.6,15.33965799,0.341911432,101549.3769,1.680450429,166.9701034
51.8,15.50158968,0.34527353,101536.076,1.687421462,167.6510995
52,15.55631549,0.348677761,101702.3715,1.693521107,168.5325796
52.2,15.53956888,0.352121608,102039.5551,1.696135239,169.3541316
52.4,15.81117774,0.355578192,102232.417,1.700056467,170.0514725
52.6,15.82101247,0.359089391,102794.1245,1.700056466,170.9928798
52.8,15.9829167,0.362624252,103540.0361,1.695699606,171.7991796
53,16.15146338,0.36619419,104008.3971,1.697006683,172.7427667
53.2,16.08898316,0.36981749,104385.2641,1.698749433,173.5621391
53.4,16.38549412,0.373449944,105015.6244,1.696135343,174.3706193
53.6,16.28809983,0.377148856,105511.4473,1.697442398,175.3120251
53.8,16.40177657,0.380868782,105630.0805,1.702670674,176.0311575
54,16.72486226,0.384610168,105629.4097,1.710948794,176.8668771
54.2,16.64988745,0.388419531,105530.3214,1.719662556,177.6023514
54.4,16.86908465,0.392244673,105100.6075,1.732297549,178.1874637
54.6,17.17968701,0.396101372,104746.6863,1.744932554,178.9120447
54.8,17.547623,0.399992546,104721.1377,1.751032238,179.5113231
55,17.75350554,0.403935051,105353.0198,1.748853821,180.3579379
55.2,17.93528244,0.407919028,105912.2291,1.745804024,180.9931719
55.4,18.20763325,0.411936114,106826.6674,1.739704417,181.9269541
55.6,18.39521446,0.416000053,107395.4303,1.737090309,182.6406381
55.8,18.20052384,0.420133902,108331.0078,1.730554958,183.5864021
56,18.3390623,0.42428377,109101.0507,1.726633778,184.5289004
56.2,18.28729245,0.42848993,109399.6894,1.728812215,185.3319294
56.4,18.73993994,0.432700013,109781.1485,1.729247958,186.0499743
56.6,18.54356061,0.437001817,110591.2394,1.725326738,187.0099028
56.8,18.91226234,0.441303743,111043.344,1.724891094,187.7519186
57,19.11890994,0.445661237,111127.7303,1.731426448,188.6050707
57.2,19.17679949,0.450073809,111810.5627,1.729683701,189.4582217
57.4,19.36182679,0.454521011,112622.9899,1.725326838,190.2514463
57.6,19.61997601,0.459007355,113449.3511,1.722712737,191.2277227
57.8,19.73767708,0.463549565,114279.3644,1.72009862,192.1887436
58,19.87282211,0.468136209,115264.2475,1.713563308,193.0375376
58.2,20.00962188,0.472768676,116137.7029,1.709206438,194.0257984
58.4,20.00846628,0.47745825,116245.4146,1.715306079,194.9628473
58.6,20.19926691,0.482180303,116291.8705,1.720534366,195.7103093
58.8,19.91721434,0.486985716,116145.6545,1.72794104,196.4163621
59,19.86617545,0.491821182,115512.451,1.743625824,197.1768968
59.2,20.31290485,0.496667512,115036.8473,1.756696537,197.8241186
59.4,20.7521474,0.501563138,115141.6004,1.762360543,198.5977334
59.6,20.99277034,0.506523075,115199.9058,1.767588836,199.2242504
59.8,20.92341793,0.511556616,115661.148,1.768895895,200.0545192
60,20.92303144,0.516635566,116190.2241,1.767153141,200.7191704
60.2,20.91224919,0.521766349,116968.3494,1.762796254,201.5243788
60.4,21.09550001,0.52693386,117637.1215,1.761053522,202.4156667
60.6,21.09965743,0.532180193,118280.1927,1.759746457,203.303684
60.8,21.48441407,0.537423859,118964.4751,1.756260995,204.0293562
61,21.4166743,0.542767946,119769.6355,1.752775478,204.968584
61.2,21.56457358,0.548149176,120247.7953,1.753211185,205.8151983
61.4,21.65886401,0.553588527,121223.3536,1.746240179,206.6618124
61.6,22.16117254,0.559051643,122453.8863,1.7362194,207.5748953
61.8,22.17608392,0.564606611,123581.4858,1.729248383,208.6797418
62,22.34970969,0.570205387,124331.7588,1.726198584,209.5427005
62.2,22.54368629,0.575858959,125467.0812,1.720098966,210.6486381
62.4,23.00399321,0.581548885,126024.2582,1.720970398,211.6129321
62.6,23.49753381,0.587279092,126247.1155,1.725545189,212.4960516
62.8,23.63621855,0.59312297,126808.7278,1.726198739,213.4401848
63,23.88001455,0.599032804,127741.4304,1.722059725,214.4442458
63.2,24.1595441,0.604939727,128880.3407,1.716177961,215.6019407
63.4,24.19557294,0.610954515,129960.2225,1.709642635,216.5760363
63.6,24.76801042,0.61698893,131637.2873,1.698314795,217.8759258
63.8,24.8916918,0.623118014,132633.976,1.693522233,218.9077704
64,25.0373852,0.629307125,133346.5383,1.693522251,220.0976069
64.2,25.33389742,0.63554678,133817.541,1.69570073,221.1392604
64.4,25.50159279,0.641859126,134124.8153,1.69918626,222.0784911
64.6,25.48313139,0.648248921,134254.6238,1.705721591,223.1452014
64.8,25.68529349,0.654686137,134444.3753,1.710078503,224.0103394
65,25.55628702,0.661213162,135338.6887,1.708335733,225.2186961
65.2,25.70358161,0.667784866,136104.867,1.707028685,226.2821395
65.4,25.91983971,0.674417381,136916.5907,1.7055038,227.4076905
65.6,26.22500554,0.681109559,137524.5471,1.705721681,228.4580612
65.8,26.50855436,0.687870751,137894.0252,1.709207225,229.6064943
66,26.99984541,0.694684083,137643.2541,1.71792106,230.444396
66.2,27.08600716,0.70159679,137405.9859,1.726634848,231.3945216
66.4,27.19293319,0.708577241,137249.6723,1.73447726,232.410023
66.6,27.80177943,0.715589652,137630.0983,1.734913022,233.2893307
66.8,28.12391526,0.722694392,138689.8097,1.729249106,234.487886
67,28.23953326,0.729886049,140280.487,1.717049832,235.5829274
67.2,28.14738671,0.737165754,142370.9716,1.702672089,236.9340209
67.4,28.04027036,0.744519545,144362.2917,1.691344167,238.3679235
67.6,28.2173484,0.751925758,145837.3291,1.684373163,239.532699
67.8,28.69773409,0.75938328,147106.6653,1.681759087,240.9339211
68,28.74224197,0.766948815,146934.6777,1.693087,242.1074117
68.2,28.94047502,0.774578738,146599.6559,1.703979245,243.1141971
68.4,29.26500976,0.782275693,146515.2089,1.711385999,244.0545195
68.6,29.75407265,0.790037438,146423.8574,1.719664144,245.1811642
68.8,29.9481138,0.797899533,146263.2112,1.726635191,246.0724525
69,30.21444045,0.805835206,146565.1258,1.730120733,247.2415883
69.2,30.53435474,0.813846492,146751.6367,1.734913352,248.258182
69.4,30.59788897,0.821957563,146775.0081,1.740577316,249.1407526
69.6,30.94021489,0.830128846,146290.8852,1.753212335,250.0843439
69.8,31.15455187,0.838391979,146214.7861,1.760183388,250.8448821
70,31.33563517,0.846740586,146709.9673,1.762361853,251.9083266
70.2,31.45188616,0.855178059,147533.9177,1.759747735,252.9390825
70.4,31.76507363,0.863685302,148706.646,1.753212438,253.9513178
70.6,32.2901557,0.87226179,150756.2758,1.738834764,255.3144046
70.8,32.60580892,0.880940541,152391.8903,1.727942578,256.4584807
71,32.67131355,0.889725487,154227.1896,1.71748605,257.9228939
71.2,33.10494268,0.89857065,155630.4673,1.710950774,259.2282326
71.4,33.17457421,0.907532407,156626.583,1.70790096,260.3908289
71.6,33.41371799,0.916571284,156940.6971,1.713129257,261.6634759
71.8,33.77583718,0.925691645,157075.0244,1.717921879,262.6157839
72,33.67423685,0.934938789,156811.9233,1.727942716,263.7522284
72.2,34.23161466,0.944228831,156655.8498,1.736220875,264.8004237
72.4,34.18981761,0.953657754,156716.5027,1.742756206,265.9390475
72.6,34.61337253,0.963146007,157360.3815,1.74188488,266.9077011
72.8,35.12998573,0.972722505,158417.8038,1.738835119,268.1999643
73,35.31833365,0.982420231,159394.3561,1.735349629,269.2568714
73.2,35.45846737,0.99221897,160635.5012,1.730992756,270.5044574
73.4,35.83542404,1.002098192,161916.6357,1.727071599,271.893693
73.6,35.92566558,1.012098444,162950.1796,1.725328854,273.2306254
73.8,36.2361095,1.022182457,163494.5702,1.726635959,274.2744589
74,36.23573859,1.032391345,164037.6442,1.729685784,275.5863284
74.2,36.94337417,1.042649089,164392.6753,1.731864314,276.5212084
74.4,37.21304971,1.053043115,164416.0503,1.738835373,277.7252115
74.6,37.49184977,1.063540944,164353.2561,1.746242123,278.8878119
74.8,37.88946792,1.07413512,164401.5839,1.751034752,279.8346729
75,38.13997989,1.084846925,164223.6723,1.758441499,280.9624049
75.2,38.44199755,1.095662521,164052.8768,1.764976874,281.9201613
75.4,38.75646312,1.106585831,164548.2097,1.765412602,282.8920826
75.6,39.16149166,1.117612027,165606.4595,1.762362827,284.1451198
75.8,39.59226399,1.128747062,166900.3736,1.756263231,285.2554213
76,39.62994948,1.140023765,168895.5604,1.745806695,286.6740721
76.2,39.78645181,1.151404662,171189.5813,1.732736038,288.1265012
76.4,40.4997146,1.16285763,172875.8347,1.724458028,289.4231268
76.6,40.69274502,1.174465281,174989.8983,1.71400151,291.0662358
76.8,40.92065947,1.186186843,176775.0847,1.704852063,292.3922733
77,41.14440013,1.198026455,178753.2461,1.696573994,294.1334464
77.2,41.34194499,1.209986995,179990.5847,1.693959882,295.6359985
77.4,41.98032304,1.222034792,181060.8441,1.693959957,297.267128
77.6,42.43585899,1.234217633,181291.6906,1.698752593,298.4286407
77.8,42.84234573,1.246526615,180979.7341,1.710080563,299.8331329
78,43.28787043,1.258956403,181431.8111,1.712694752,301.0055412
78.2,43.41925235,1.271534859,182088.6628,1.714437526,302.37952
78.4,43.81612287,1.28421947,182456.2428,1.718794467,303.8461187
78.6,43.97114834,1.297049896,182795.7132,1.721844311,305.0381356
78.8,44.32975153,1.309993738,182676.7815,1.729686763,306.3903268
79,45.16034952,1.323031912,181925.7081,1.741450476,307.3557181
79.2,45.24384586,1.336257826,180822.0574,1.756699615,308.3570557
79.4,45.62149976,1.349594252,180864.2188,1.762799313,309.5784956
79.6,46.14871475,1.363053247,181276.1488,1.764542135,310.6245132
79.8,46.60818069,1.376652643,182364.0376,1.761492366,312.0050344
80,46.72026136,1.390415136,183529.0708,1.756699796,313.1610952
80.2,46.77622668,1.404320047,185789.3223,1.7445005,314.7083185
80.4,47.40556895,1.418321123,186599.1253,1.744936265,316.1204412
80.6,47.60649011,1.43256721,186677.5708,1.750164564,317.1926044
80.8,47.99230027,1.446871437,186934.9742,1.755828574,318.5186447
81,48.46494006,1.461239974,187114.9365,1.760185527,319.5003761
81.2,48.58062511,1.475852702,186516.8201,1.771949158,320.5158791
81.4,49.33907568,1.49056349,187680.5531,1.769335114,321.8637181
81.6,49.60138774,1.505459973,189332.5611,1.762146269,323.2213551
81.8,49.87614123,1.520505018,191134.7422,1.754086047,324.6356522
82,50.24352871,1.535694192,194076.9931,1.737965579,326.4258602
82.2,50.61172294,1.551035935,196323.0556,1.727073385,328.0362855
82.4,51.28986073,1.566508283,198297.8551,1.717923985,329.5562791
82.6,51.4074552,1.582178672,201297.6153,1.703110554,331.5622232
82.8,52.01158308,1.597969501,203327.9468,1.694396834,333.1944437
83,52.49892834,1.613928022,204663.4398,1.692654133,335.0369544
83.2,52.80467164,1.630060681,206260.4476,1.688732963,336.7966539
83.4,53.13282657,1.646353642,206547.6397,1.693961277,338.1793536
83.6,53.48089981,1.66280883,205081.4614,1.713567352,339.5707702
83.8,53.9465352,1.679420456,203432.7815,1.734044822,340.7791367
84,54.27128728,1.696209547,202952.9302,1.743630034,341.8011819
84.2,55.18437028,1.713122659,202085.5147,1.757136524,342.9474496
84.4,55.12181615,1.730279736,202558.5033,1.760186345,344.3355909
84.6,55.39496423,1.747583414,204200.3015,1.753433189,345.7934721
84.8,55.75824969,1.765053995,206738.9785,1.740580387,347.5139467
85,56.37787504,1.782680508,208820.7633,1.732302357,349.3259515
85.2,56.61645243,1.800512997,211056.9777,1.722717212,351.093277
85.4,57.01954208,1.818512205,212215.8614,1.720103119,352.5141148
85.6,57.7558396,1.836666717,213084.1673,1.721845966,354.2858066
85.8,58.20125326,1.855025904,213097.1874,1.727509984,355.5061597
86,58.54982449,1.873576873,213490.2472,1.732302614,357.1481832
86.2,59.16138202,1.892294271,213703.8841,1.737530969,358.5439631
86.4,59.88468109,1.911191138,214301.5689,1.739273813,359.8525779
86.6,60.33662391,1.930298575,215843.2515,1.73578835,361.6264449
86.8,60.31984433,1.949633362,218214.0318,1.727074549,363.5550261
87,61.09249737,1.969101698,219893.3671,1.721410676,365.1000842
87.2,61.68063421,1.98877966,221635.2718,1.716182466,366.8892082
87.4,61.94048905,2.00868028,223551.1414,1.710954221,368.9038725
87.6,62.97066227,2.028722366,223622.4867,1.716182623,370.2495398
87.8,63.24291855,2.049023427,223527.7042,1.724460763,371.9569388
88,63.60738502,2.069521276,223337.4445,1.733174606,373.512886
88.2,63.71254231,2.090244811,223808.6298,1.737095826,375.0056321
88.4,64.69106251,2.111110248,223500.7411,1.745809744,376.2368915
88.6,65.17925097,2.132222633,224458.5478,1.747116873,377.8865462
88.8,65.48873766,2.153560662,225455.6942,1.746245535,379.3084726
89,66.11397574,2.175089057,226528.6746,1.746245614,381.0267761
89.2,66.55718731,2.196847605,227182.597,1.747988428,382.5642012
89.4,67.27626094,2.218803813,228468.0773,1.744502995,384.0395259
89.6,67.64128736,2.241007523,230169.9659,1.739274758,385.941965
89.8,68.02954675,2.263432531,231371.8353,1.736660665,387.4445223
90,68.72192167,2.2860596,232963.9789,1.733175228,389.3556847
90.2,69.30290454,2.308922459,234837.0197,1.727947017,391.1949315
90.4,69.78662219,2.332022486,237135.6251,1.720976033,393.2586327
90.6,70.24204847,2.355356804,238996.8095,1.715747806,394.9649467
90.8,71.05643584,2.378898204,242082.7556,1.704855648,397.3152176
91,71.5849166,2.402697844,244318.136,1.697884668,399.2089437
91.2,72.24382867,2.426726788,246331.6093,1.693092153,401.3009779
91.4,72.99577607,2.450990028,247888.9797,1.691785171,403.5619017
91.6,73.34214951,2.475527881,247978.604,1.697449185,405.227899
91.8,73.9585636,2.500291705,247197.95,1.709648585,407.0704159
92,74.45111697,2.525313697,246605.2311,1.71879814,408.4389587
92.2,75.06246551,2.550578121,245834.7956,1.730561851,409.9796568
92.4,75.67543575,2.576096264,244613.4093,1.745811086,411.4898464
92.6,76.16869911,2.601879906,244635.539,1.754089262,413.1384148
92.8,76.66690739,2.62792231,244551.1354,1.761060369,414.3478746
93,76.77117297,2.654256249,245764.5809,1.761496073,416.0999458
93.2,77.62497209,2.680797721,247981.0287,1.754525131,417.9195865
93.4,78.42221983,2.707610198,250986.5923,1.742325897,419.7490331
93.6,79.08480034,2.734702275,254132.5043,1.730998026,422.0328381
93.8,80.02240366,2.762045579,257271.9964,1.719670187,424.4070854
94,80.8261699,2.789673887,258540.4157,1.717927521,426.1951267
94.2,81.2401459,2.817609332,259704.1693,1.717927571,428.1629442
94.4,81.67319064,2.845824059,260426.5495,1.720977457,430.1994067
94.6,82.5923343,2.87428532,262087.2643,1.717492042,432.063724
94.8,82.99911143,2.903072463,264520.8015,1.711392423,434.4259747
95,83.93229079,2.932109224,266769.1734,1.705292866,436.4308494
95.2,84.50102356,2.961465434,268210.4787,1.704421553,438.5501248
95.4,84.98411485,2.991123218,269561.1294,1.705292991,440.9189151
95.6,85.90177991,3.021045951,270026.5948,1.708778625,442.6187037
95.8,86.35402853,3.051304624,270575.136,1.714006967,444.8077103
96,87.09791531,3.08184512,271386.4934,1.71749258,446.9073777
96.2,87.87582499,3.112689984,272803.2851,1.71531422,448.5744755
96.4,88.43679034,3.14386128,275142.1262,1.710521689,451.032615
96.6,89.1639091,3.175333047,277853.151,1.703986415,453.5365223
96.8,89.83987016,3.207124894,279612.5635,1.70137235,455.5817082
97,90.17589499,3.239262121,281828.4893,1.697886865,458.1727744
97.2,90.79441389,3.271700763,282979.2279,1.699629701,460.3879355
97.4,91.70872266,3.304442812,282952.7837,1.706600861,462.2152084
97.6,92.50954551,3.33752255,282885.1178,1.714879082,464.3835214
97.8,93.33067548,3.370933003,282838.0627,1.720978852,466.0756829
98,94.09482753,3.404683537,281768.1026,1.734049669,468.0151807
98.2,94.87928559,3.438771771,281499.8612,1.741456509,469.8206593
98.4,95.58263744,3.473383153,281977.5616,1.74407074,471.4321881
98.6,96.47463003,3.507980014,283563.5006,1.742763775,473.6059524
98.8,97.23897859,3.543109298,285711.6691,1.739278339,475.8625233
99,97.7880379,3.578607807,287921.1102,1.734050114,477.8031063
99.2,98.7749861,3.614429771,289993.6128,1.731000396,479.9289317
99.4,99.20592723,3.650653919,292435.5176,1.72751492,482.4404614
99.6,100.0298813,3.687212194,293535.9978,1.728386401,484.2917039
99.8,100.6485159,3.724153347,294690.0411,1.73012924,486.5373765
100,101.2479782,3.761467166,296298.9439,1.729693621,488.8920084
100.2,101.9267429,3.799149897,298667.6476,1.724465409,491.2379252
100.4,102.4932603,3.837219731,300383.8801,1.721851331,493.3288737
100.6,103.7943356,3.875616272,302500.2398,1.718801648,495.904711
100.8,104.5664075,3.914438938,304029.1192,1.717494666,497.9913072
101,105.4485272,3.953643232,305944.0971,1.715752007,500.4450998
101.2,106.3804454,3.993237804,306430.6053,1.720980413,502.5883583
101.4,106.9283706,4.033259413,306796.5803,1.725773082,504.4940756
101.6,108.0791345,4.073637251,307631.1635,1.729694441,506.7855263
101.8,108.6364881,4.114465882,309505.7988,1.728387435,509.2349547
102,109.7505579,4.155662072,310502.1887,1.729694642,511.1537608
102.2,110.7743966,4.197278915,312209.2399,1.728387691,513.4550152
102.4,111.334046,4.23934879,314787.7258,1.724030845,516.1332574
102.6,112.4591353,4.281798046,316432.6486,1.722288209,518.236208
102.8,113.3302813,4.324692854,316419.7709,1.729695072,520.5505337
103,114.0900025,4.368026928,317612.4274,1.730130855,522.7858612
103.2,114.9410666,4.411789222,319733.7158,1.72642758,525.2276701
103.4,115.6744718,4.456000084,322639.5883,1.719238753,527.8824914
103.6,116.8312098,4.500622946,325923.0783,1.711396445,530.8385987
103.8,117.552008,4.545727456,329277.3059,1.70224701,533.3479594
104,118.5025105,4.591267471,332850.5122,1.69527605,536.5132618
104.2,119.5169287,4.637260197,333311.9238,1.69963309,538.4985345
104.4,120.5906915,4.683708678,331284.5554,1.716625188,540.7790898
104.6,121.6265691,4.730626341,329733.3579,1.73143883,542.9648493
104.8,122.2709624,4.778045152,329214.8028,1.739717049,544.7354622
105,123.5518396,4.825891956,329227.9927,1.745816888,546.9724397
105.2,124.2584072,4.874263266,330567.3131,1.745816976,549.2410005
105.4,125.3322075,4.923092508,332754.1837,1.741895878,551.3973428
105.6,126.4906937,4.972406046,335205.9927,1.738410486,554.1093823
105.8,127.0100485,5.022263618,336465.2125,1.740589011,556.5718871
106,127.8891544,5.072594622,336896.3717,1.745381728,558.5004989
106.2,128.5770458,5.123445931,339455.0849,1.741024895,560.9924276
106.4,129.5881221,5.174783534,344289.0415,1.727518566,564.0923628
106.6,130.624047,5.226635071,348257.9439,1.717062083,566.7586383
106.8,131.329975,5.279032554,352448.2191,1.70747694,570.0764802
107,132.6848446,5.331907199,356257.4878,1.697891874,572.7416743
107.2,133.5318776,5.385351761,358133.2441,1.697891978,575.5637589
107.4,134.8932258,5.439294097,357355.3466,1.709220133,578.1799215
107.6,136.0085064,5.493797102,357408.0357,1.717062724,580.869082
107.8,137.4968274,5.548819381,358988.7074,1.717062901,583.2095796
108,138.4955907,5.604431639,360656.397,1.718370096,586.0959535
108.2,139.7294436,5.660584894,362067.9126,1.720113012,588.7306378
108.4,140.6249822,5.717328005,364729.4758,1.716191889,591.3249984
108.6,141.6101804,5.774634372,368162.1787,1.710528006,594.5164605
108.8,142.8637061,5.832495989,369626.2127,1.71139954,596.9321356
109,144.3057809,5.890924637,370925.1332,1.714449557,599.871914
109.2,145.5632763,5.949954481,372006.8949,1.717499553,602.6133804
109.4,146.3802374,6.009610785,371888.0355,1.725342115,605.291639
109.6,147.2212028,6.069864531,370966.7129,1.734927451,607.2790933
109.8,148.4867229,6.130691486,370728.0345,1.742770068,609.8309688
110,149.5277707,6.192146631,371481.1381,1.744948657,611.9687936
110.2,150.5412968,6.254221347,374786.6901,1.738413391,614.8584396
110.4,151.7383791,6.316905815,379396.7586,1.72752122,618.1033012
110.6,152.6710973,6.38024009,383480.7362,1.719243172,621.4331459
110.8,153.7998349,6.444195691,386140.9985,1.715322073,624.1593548
111,155.0481373,6.508784897,387642.1335,1.717500685,627.3148716
111.2,156.1492463,6.574034106,386521.8667,1.727957442,629.6967691
111.4,157.7870898,6.639898002,385022.0007,1.73928565,631.7387289
111.6,159.0259388,6.70645412,384694.4378,1.747128271,634.3483575
111.8,160.1765935,6.773685615,386557.888,1.745385639,636.711733
112,161.3462544,6.841591276,390286.289,1.737979001,639.8705195
112.2,162.2278583,6.910201821,393784.7051,1.731879407,642.885469
112.4,163.2448087,6.979494022,397461.3264,1.724472749,645.6912208
112.6,164.8142767,7.049440468,400842.9868,1.720551699,649.1572849
112.8,165.9057967,7.120126014,402383.9814,1.721858909,651.7571053
113,167.2136845,7.191505333,402604.4957,1.729265847,654.5759402
113.2,168.6215965,7.263594186,403476.9404,1.733622947,657.2694772
113.4,170.3497518,7.336383036,403659.3043,1.741029938,660.0915966
113.6,171.6843029,7.409933249,404198.6248,1.744951338,662.3580073
113.8,172.9676289,7.484226198,405634.4503,1.746694267,665.3032377
114,173.9707823,7.559287062,407688.6232,1.744515922,667.7940949
114.2,175.3170275,7.635075983,409951.6426,1.741901925,670.6303703
114.4,176.5979167,7.711631287,413164.8261,1.73667376,674.0103516
114.6,177.6646958,7.788972069,415910.5352,1.732316954,676.7496415
114.8,179.1954767,7.86705457,418765.1034,1.729702977,680.1960985
115,180.4323671,7.945944074,420959.7056,1.727960352,682.9582762
115.2,181.5378303,8.025636123,422338.2776,1.730138952,685.8806225
115.4,183.0927166,8.106297275,423978.045,1.732317606,689.1854326
115.6,184.6570956,8.187361149,424209.787,1.737546117,691.6512521
115.8,186.053031,8.269456833,424037.4478,1.745388771,694.5921313
116,187.626192,8.352782387,423772.0528,1.751924367,696.7833716
116.2,189.0792034,8.43653967,424860.0458,1.7549744,699.5313958
116.4,190.3946146,8.520723557,425799.3946,1.758895804,702.3654938
116.6,191.7168876,8.606178438,427211.3877,1.761074434,705.2268303
116.8,193.0614618,8.692490235,430657.6589,1.754974885,707.9214592
117,194.5787509,8.779656186,434557.2033,1.748875354,711.2578717
117.2,195.6483955,8.867731959,437443.4281,1.745825627,714.4090367
117.4,197.5206668,8.956631587,440202.3455,1.742340301,717.2562305
117.6,199.1671739,9.046441771,444168.1257,1.736240783,720.9663792
117.8,200.4395777,9.137182731,445304.4564,1.737983713,723.6631892
118,202.0816416,9.228807355,446710.2282,1.739726687,726.9516632
118.2,203.6961356,9.321354818,448506.3678,1.739726881,730.0396519
118.4,205.3445539,9.414829633,449553.4742,1.741469857,732.756089
118.6,206.6770346,9.509267598,451193.1974,1.742777101,736.089228
118.8,208.3637956,9.604627753,452819.8142,1.742777305,738.7021546
119,210.0113465,9.700948996,454547.9482,1.744084587,741.9328841
119.2,211.4572207,9.798253242,456984.1347,1.742777678,745.170144
119.4,213.2706672,9.896507424,460542.5853,1.738856647,748.7484651
119.6,214.8845116,9.995763833,463488.3968,1.73580698,751.7754393
119.8,216.4346246,10.09602077,466638.4409,1.733628693,755.4322012
120,218.3070147,10.19726009,469335.2499,1.731450445,758.3916305
120.2,219.9502967,10.29953251,472206.4501,1.730143558,761.8598965
120.4,221.6590663,10.40282793,474687.5262,1.730579457,765.5482647
120.6,223.6003578,10.50714282,476245.739,1.731886774,768.4205302
120.8,225.325417,10.61252176,479317.5227,1.729708507,772.050062
121,227.0764853,10.71895731,482596.6169,1.725787463,775.2884278
121.2,228.6553619,10.82647525,486058.9127,1.722302086,778.9342998
121.4,230.2752027,10.93507048,489056.4312,1.721430891,782.9658919
121.6,231.9235405,11.04475466,492133.7463,1.719252613,786.278348
121.8,233.7711495,11.15552367,494105.6804,1.722302697,790.1443317
122,235.2662281,11.26742891,494120.6222,1.729274002,792.8716668
122.2,236.9763634,11.38044211,493663.7621,1.73798811,795.8038575
122.4,239.0087559,11.4945662,495345.2297,1.74103822,799.3887308
122.6,240.5456758,11.60987465,497011.7549,1.743652579,802.8798811
122.8,242.463021,11.72631259,498823.8777,1.744088505,805.8665603
123,244.2571888,11.84392974,501812.6236,1.741910245,809.5854489
123.2,246.1716676,11.96271956,504087.1237,1.741474779,813.1180207
123.332,247.695131,12.04175413,505201.0435,1.742346353,815.3964432
123.6,249.2624966,12.04464341,507740.302,1.742782239,819.8224771
123.8,250.4113941,12.04455612,510153.4079,1.742346682,823.4541734
124,251.4963027,12.04447367,512612.513,1.741039722,826.6162482
124.2,252.3078042,12.04441192,516546.8286,1.736682866,830.4418862
124.4,252.7386961,12.04437896,518307.1778,1.737554309,833.5396467
124.6,253.2917488,12.04433677,519309.3425,1.741911332,837.2236184
124.8,253.6586519,12.04430866,520930.2224,1.744525543,840.8389406
125,253.9482697,12.04428639,524041.8473,1.741911411,844.1175738
125.2,254.3941201,12.04425231,526286.9147,1.742782856,847.6206701
125.4,254.8773668,12.04421539,531084.4801,1.737554566,851.8527148
125.6,254.8428847,12.04421766,534457.8832,1.734504692,855.1291551
125.8,255.1424748,12.04419464,536132.2677,1.737990294,858.9918134
126,255.6340317,12.0441571,534155.0655,1.751061226,862.2170627
126.2,255.4200481,12.04417294,532661.6514,1.761517898,865.1175812
126.4,256.1700539,12.04411584,528846.5355,1.777638733,867.204206
126.6,256.2851564,12.04410679,525405.4515,1.792452403,869.1535127
126.8,256.041256,12.0441249,522246.2345,1.806830334,871.5081394
127,256.1380759,12.04411723,519272.3405,1.820336916,873.7145909
127.2,256.4758931,12.04409132,517178.1826,1.830793657,875.5800093
127.4,256.735594,12.04407132,517957.1208,1.832100777,877.6241187
127.6,256.8855996,12.04405962,520453.406,1.829486622,880.4396626
127.8,256.9616439,12.04405352,522988.1747,1.826436761,882.8269883
128,257.1789625,12.04403673,529858.8979,1.812058828,886.4510231
128.2,257.426198,12.04401767,534896.8158,1.802909247,889.7394599
128.4,257.395871,12.04401962,536728.3229,1.802473548,892.346883
128.6,257.5309181,12.04400906,537594.1723,1.805523436,895.3040763
128.8,257.7191508,12.04399447,537113.527,1.812058897,897.9474693
129,257.8159708,12.0439868,534047.324,1.825129784,899.5372039
129.2,258.0573891,12.04396818,532310.7825,1.835150819,901.4701725
129.4,257.7436825,12.04399158,530808.1545,1.844736088,903.5850804
129.6,258.3582313,12.04394473,529181.5402,1.853450083,905.0538948
129.8,258.1508959,12.04396007,525112.3271,1.870006499,906.3189166
130,258.1945302,12.04395642,523321.3949,1.878284726,907.4324939
130.2,258.4953669,12.04393331,519694.4306,1.892662728,908.7127933
130.4,258.3088071,12.04394708,517460.8826,1.901812316,909.5027497
130.6,258.5485634,12.04392859,514827.5183,1.912704744,910.3918767
130.8,258.4372115,12.04393668,514902.7923,1.914447514,911.4139215
131,258.469627,12.04393388,515848.1163,1.914447519,912.8162426
131.2,258.8253113,12.04390662,517019.788,1.913576174,914.1237854
131.4,258.6088347,12.04392265,520123.5543,1.906605013,915.6775514
131.6,258.9321091,12.04389784,524641.9212,1.896148355,917.8458814
131.8,258.9312835,12.04389756,528974.7967,1.886563047,920.1187939
132,258.898879,12.04389967,531773.0879,1.880898997,921.9351642
132.2,259.1868348,12.04387753,535732.8955,1.872620813,924.2876342
132.4,259.374652,12.04386297,537393.4884,1.87131375,926.518064
132.6,259.2163471,12.04387461,537990.0409,1.872185122,928.1927782
132.8,259.2869898,12.04386891,537269.5203,1.877413482,929.9655683
133,259.2167736,12.04387388,535736.1347,1.884384608,931.1881027
133.2,259.4706573,12.04385432,532627.8218,1.89614843,932.221058
133.338,259.2535183,12.04387052,530979.5344,1.90268384,932.8344999
134.1,259.3644412,11.91626146,1.7977E+308,1.798988237,0
134.3,259.0062958,11.79591147,1.7977E+308,1.582447351,0
134.5,258.6543832,11.67556101,1.7977E+308,1.34760725,0
134.7,258.5804485,11.55518952,1.7977E+308,0.958095159,0
134.9,258.4475111,11.43482249,1.7977E+308,0.548976757,0
135.1,257.9913048,11.31447992,1.7977E+308,0.282330894,0
135.3,257.8741568,11.1941117,1.7977E+308,0.128965963,0
135.5,257.5928814,11.0737559,1.7977E+308,0.099774341,0
135.7,257.3514951,10.95339707,1.7977E+308,0.10282421,0
135.9,256.8632944,10.83305693,1.7977E+308,0.035291359,0
136.1,256.7955924,10.71268496,1.7977E+308,0.026577443,0
136.3,256.7145941,10.592314,1.7977E+308,0.022656181,0
136.5,256.4063104,10.47196024,1.7977E+308,0.018734918,0
136.7,256.1553674,10.35160214,1.7977E+308,0.017427831,0
136.9,256.1641198,10.23122439,1.7977E+308,0.016120743,0
137.1,255.7108221,10.1108816,1.7977E+308,0.018734917,0
137.3,255.2770536,9.990537341,1.7977E+308,0.02657744,0
137.5,254.9064429,9.870188297,1.7977E+308,0.028320222,0
137.7,254.83791,9.749816394,1.7977E+308,0.030934396,0
137.9,254.8196541,9.629440686,1.7977E+308,0.032895027,0
138.1,254.5595698,9.509083279,1.7977E+308,0.034637809,0
138.3,254.2595964,9.38872889,1.7977E+308,0.033112874,0
138.5,254.1636396,9.268359062,1.7977E+308,0.030498699,0
138.7,253.8536939,9.148005427,1.7977E+308,0.021784785,0
138.9,253.4872384,9.027656069,1.7977E+308,0.018734914,0
139.1,253.4947443,8.907278412,1.7977E+308,0.013724414,0
139.3,252.9296738,8.786944084,1.7977E+308,0.007842522,0
139.5,252.8918888,8.666569854,1.7977E+308,0.004356957,0
139.7,252.528342,8.546220276,1.7977E+308,0.004356957,0
139.9,252.2844628,8.425861642,1.7977E+308,0.001307087,0
140.1,252.0970933,8.305498732,1.7977E+308,0.012199478,0
140.3,252.1640175,8.185116578,1.7977E+308,0.015685043,0
140.5,251.8378668,8.06476417,1.7977E+308,0.018734912,0
140.7,251.2831842,7.944429056,1.7977E+308,0.016992129,0
140.9,251.1016319,7.824065706,1.7977E+308,0.013070868,0
141.1,251.000689,7.703696255,1.7977E+308,0.003485565,0
141.3,250.3861727,7.583365669,1.7977E+308,0.008713912,0
141.5,250.5370303,7.462977164,1.7977E+308,0.015249346,0
141.7,250.2275002,7.342623498,1.7977E+308,0.020041997,0
141.9,249.9661695,7.222266185,1.7977E+308,0.024834648,0
142.1,249.6923734,7.101909815,1.7977E+308,0.025706038,0
142.3,249.4210704,6.981553256,1.7977E+308,0.018734909,0
142.5,249.1622328,6.861195754,1.7977E+308,0.012635171,0
142.7,248.7671072,6.740848566,1.7977E+308,0.010020997,0
142.9,248.7018984,6.620476411,1.7977E+308,0.010892388,0
143.1,248.3225622,6.500128028,1.7977E+308,0.014377952,0
143.3,248.347104,6.379749081,1.7977E+308,0.014813648,0
143.5,247.9951917,6.259398623,1.7977E+308,0.018299211,0
143.7,247.5335841,6.139056465,1.7977E+308,0.026577425,0
143.9,247.3611731,6.018692423,1.7977E+308,0.033984248,0
144.1,247.3749116,5.898314294,1.7977E+308,0.036598421,0
144.3,246.7612265,5.777983645,1.7977E+308,0.033548551,0
144.5,246.7167933,5.657609918,1.7977E+308,0.02788451,0
144.7,246.465435,5.53725185,1.7977E+308,0.024834641,0
144.9,246.1351293,5.416899757,1.7977E+308,0.026141727,0
145.1,246.0208901,5.296531312,1.7977E+308,0.026141727,0
145.3,245.475349,5.176195507,1.7977E+308,0.02570603,0
145.5,245.2480904,5.055835615,1.7977E+308,0.027448812,0
145.7,245.0233249,4.935475535,1.7977E+308,0.022220466,0
145.9,244.9955122,4.81510055,1.7977E+308,0.021349075,0
146.1,244.6469241,4.69474984,1.7977E+308,0.022220466,0
146.3,244.2534606,4.574402526,1.7977E+308,0.02265616,0
146.5,244.2580579,4.454025089,1.7977E+308,0.020477683,0
146.7,243.9842619,4.333668719,1.7977E+308,0.018734901,0
146.9,243.3689149,4.213338196,1.7977E+308,0.015249338,0
147.1,243.3751742,4.092960633,1.7977E+308,0.014377947,0
147.3,242.7124588,3.972633694,1.7977E+308,0.014813642,0
147.5,242.542541,3.852269463,1.7977E+308,0.020913376,0
147.7,242.1071108,3.731925325,1.7977E+308,0.022220462,0
147.9,241.6409327,3.611583513,1.7977E+308,0.021784765,0
148.1,241.4892974,3.491217899,1.7977E+308,0.022438308,0
148.3,241.3256123,3.370853196,1.7977E+308,0.01851705,0
148.5,240.9063871,3.250507832,1.7977E+308,0.01568503,0
148.7,240.86865,3.129832656,1.7977E+308,0.013942249,0
148.9,240.3870502,3.009792954,1.7977E+308,0.013506553,0
149.1,240.1755812,2.889431867,1.7977E+308,0.01655642,0
149.3,239.7513699,2.76908688,1.7977E+308,0.025488172,0
149.5,239.4031974,2.648736138,1.7977E+308,0.023963238,0
149.7,238.6611672,2.52811426,1.7977E+308,0.021131218,0
149.9,238.6000657,2.408042736,1.7977E+308,0.018299199,0
150.1,238.5120038,2.287672311,1.7977E+308,0.01089238,0
150.3,238.0400087,2.16733094,1.7977E+308,0.011328075,0
150.5,238.0051323,2.04695649,1.7977E+308,0.020695522,0
150.7,237.1861847,1.926641374,1.7977E+308,0.025706015,0
150.9,237.2801171,1.806257176,1.7977E+308,0.027448796,0
151.1,236.7138007,1.685922943,1.7977E+308,0.027448795,0
151.3,236.2434678,1.565581446,1.7977E+308,0.025706013,0
151.5,236.0096568,1.444620166,1.7977E+308,0.023091842,0
151.7,235.6814289,1.324267915,1.7977E+308,0.01612072,0
151.892,235.0824398,1.209353122,1.7977E+308,0.010020987,0
227.2,234.3200441,1.031123152,1.7977E+308,0.012199464,0
227.4,233.8019273,0.910785271,1.7977E+308,0.010456683,0
227.6,233.4475222,0.790435001,1.7977E+308,0.014813634,0
227.8,232.9102918,0.670098567,1.7977E+308,0.022656145,0
228,232.3639202,0.549762824,1.7977E+308,0.026577399,0
228.2,231.9538365,0.429416767,1.7977E+308,0.024398923,0
228.4,231.4490161,0.30907788,1.7977E+308,0.027448788,0
228.6,230.6126172,0.188764085,1.7977E+308,0.032677127,0
228.8,229.8543346,0.068444379,1.7977E+308,0.03834116,0
228.904,229.2735459,0.005892243,1.7977E+308,0.039212548,0
,,,,,