File: TestGB3_15.csv
Time On Sample,Displacement Into Surface,Load On Sample,Harmonic Contact Stiffness,Harmonic Displacement,Harmonic Load
0,0,0,83.94222615,0.318261367,2.198294859
0.2,0.174411011,0.000679058,7813.033384,0.202569648,2.28802119
0.4,0.322175698,0.00135994,12479.81924,0.186853037,2.354768833
0.592,0.311546217,0.002024028,14287.58122,0.180741022,2.434647143
0.8,0.62270196,0.002715323,16896.59468,0.156729533,2.516713927
1,0.436139261,0.003413148,19059.76744,0.14232264,2.598780669
1.2,0.434851773,0.004098287,21423.93185,0.134464335,2.79683511
1.4,0.527659111,0.004776982,23557.01749,0.13009861,3.046318063
1.6,0.444350912,0.005467737,25622.60809,0.126169457,3.289235654
1.8,0.771978967,0.006130353,27466.96706,0.124423166,3.543095534
2,0.733220089,0.006818057,28537.61606,0.125732884,3.742244194
2.2,0.810622522,0.007497808,33672.02762,0.121803731,4.20838339
2.4,0.937154112,0.008174194,37644.53499,0.123113449,4.652638141
2.6,1.028296054,0.008853003,41968.65191,0.124859738,5.171300079
2.8,1.323448901,0.009517843,44336.70674,0.13053518,5.672454472
3,1.234728169,0.010208969,45567.8444,0.138393486,6.169231905
3.2,1.239269564,0.010893708,46220.10718,0.154110096,6.986616828
3.4,1.1272333,0.01158643,46979.82266,0.168953562,7.844488
3.6,0.967733273,0.012282402,45959.92049,0.190345615,8.704547591
3.8,1.064704099,0.012960812,45034.9891,0.208681661,9.364364358
4,0.999298898,0.013650341,44779.01248,0.229200569,10.22661243
4.2,1.026323128,0.014333541,45750.7475,0.246663469,11.203754
4.4,1.097480329,0.015013719,46810.43786,0.267182377,12.33955795
4.6,0.730638606,0.015723888,47315.04929,0.28988415,13.48411552
4.8,0.767655207,0.016406404,46734.73161,0.31782479,14.598035
5,0.822991154,0.017087665,44691.24709,0.356243171,15.63317043
5.2,0.998235552,0.017760716,42101.00267,0.403393002,16.68143659
5.4,0.801264134,0.018459253,38669.21402,0.469752025,17.85334977
5.6,0.535178817,0.019162524,35435.26228,0.543532783,18.90708674
5.8,0.739567631,0.019833579,32551.62471,0.623425551,19.87438044
6,0.706637635,0.020520884,29848.60515,0.710303482,20.74866491
6.2,0.589605184,0.021213948,27726.83314,0.793688834,21.50915009
6.4,-0.031209307,0.021941508,25755.8437,0.8849325,22.26963492
6.6,-0.4455148,0.022654927,23633.05324,0.984471042,22.7696947
6.8,0.690662615,0.023262179,20831.50513,1.132032532,23.20191386
7,1.009130997,0.023925422,19016.35978,1.249470532,23.4579624
7.2,0.74637647,0.024628464,17379.03282,1.373457132,23.64835705
7.4,1.10647973,0.025288857,16148.24826,1.484346541,23.82452733
7.6,0.868706131,0.025990189,16119.7998,1.510104326,24.2118822
7.8,0.942361425,0.026670196,16910.76106,1.47299566,24.71303663
8,0.787024885,0.027365882,18229.50563,1.410565795,25.44178927
8.2,0.988082909,0.028037165,19713.6223,1.34464334,26.15084625
8.4,0.638727834,0.028746137,21039.8334,1.293127792,26.77893023
8.6,0.885584224,0.029414284,22046.69218,1.267370008,27.48579881
8.8,0.867642785,0.030100563,22287.66857,1.273918596,27.98804733
9,0.754773822,0.030793342,22459.34073,1.287452347,28.5909643
9.2,0.938345196,0.031465823,22428.63308,1.306661534,29.07898814
9.4,0.828806625,0.032161797,22276.49268,1.329363307,29.4838507
9.6,0.785051561,0.032849844,22168.30377,1.354684514,29.97843965
9.8,0.991938865,0.033517304,21958.1257,1.383061722,30.33296825
10,0.775815403,0.034217153,21650.88751,1.421043537,30.72798271
10.2,0.9169192,0.034892541,21473.77654,1.449420747,31.07266322
10.4,1.101323272,0.035564965,21339.30353,1.473868803,31.35716152
10.6,0.942655942,0.03626088,21146.69149,1.504428883,31.6919937
10.8,0.807304145,0.036955198,21124.81605,1.519272352,31.97977435
11,1.14159378,0.037617358,21111.34739,1.536735244,32.32117243
11.2,0.68398802,0.038333743,21094.3034,1.552451867,32.60676425
11.4,1.423801373,0.038968135,21105.86118,1.564239304,32.86500174
11.6,0.967861011,0.039684405,21438.91939,1.559873592,33.22718924
11.8,1.524480896,0.040331342,22023.06495,1.541974102,33.6462774
12,1.638938371,0.041008555,22712.63368,1.514470033,34.01503088
12.2,1.651806741,0.041692724,23764.93993,1.471685927,34.49867763
12.4,1.734621708,0.042372103,25463.233,1.403144041,35.13989265
12.6,1.501011599,0.04307315,26655.91493,1.362106231,35.65308322
12.8,2.065958455,0.043719516,27929.40214,1.324560982,36.26256634
13,1.709941805,0.044428944,28976.61679,1.298803212,36.84141019
13.2,1.701992737,0.045114539,29606.59814,1.290944907,37.38195657
13.4,1.776480728,0.045794489,29703.7791,1.300986073,37.78244242
13.6,1.721067898,0.046483333,29896.02051,1.311463815,38.31642344
13.8,1.535754248,0.047181073,30166.8401,1.318012407,38.84274464
14,1.61690382,0.047860567,30212.00768,1.330236436,39.24541899
14.2,1.751346035,0.048536411,30343.28403,1.340714173,39.71812366
14.4,1.77670487,0.049219725,30612.71621,1.34726276,40.25867011
14.6,2.172614119,0.049877666,30785.28594,1.352938193,40.6690045
14.8,1.944832895,0.050578313,30858.16448,1.365162229,41.16687585
15,2.035142139,0.05125718,31052.44252,1.371274242,41.6745956
15.2,1.85315928,0.051954691,31294.46121,1.375203399,42.16261904
15.4,1.913491412,0.05263561,31545.72272,1.380442268,42.68565799
15.6,1.868903651,0.053323714,31817.21105,1.382188559,43.09161488
15.8,1.990022705,0.054000471,32171.43834,1.384371417,43.60699432
16,1.973746661,0.054686635,32468.33414,1.389610288,44.12237346
16.2,1.954139827,0.055373028,32751.88077,1.393976015,44.61477408
16.4,2.08941474,0.056048816,32960.36237,1.399214882,45.04152144
16.6,2.245507091,0.056723178,33102.09005,1.408382899,45.53829914
16.8,2.367458842,0.057399878,33109.81633,1.422789788,46.03398257
17,1.935666715,0.058114494,33069.92865,1.437196693,46.47933084
17.2,2.304929642,0.05877426,32890.14322,1.456842447,46.88309989
17.4,2.346942427,0.059456433,32696.34461,1.47517849,47.22012078
17.6,2.410605349,0.060137125,32632.19293,1.491768244,47.65015071
17.8,2.299401784,0.060829789,32728.72668,1.502245987,48.09878216
18,2.353905033,0.061511108,32881.09901,1.507048283,48.45112221
18.2,2.197735799,0.062206852,33066.96734,1.511850586,48.85926719
18.4,2.632781831,0.062862113,33452.15491,1.50923114,49.34182045
18.6,2.582781536,0.063550587,33698.50971,1.51097743,49.81014816
18.8,2.596482605,0.064234699,33852.15363,1.513596866,50.18546672
19,3.043186399,0.064889162,34090.52589,1.514469999,50.66364319
19.2,2.751703816,0.065594171,34408.92277,1.511413999,51.11883972
19.4,2.90613077,0.066268647,34727.51304,1.508357988,51.51494883
19.6,2.928991511,0.066952132,35242.26782,1.5018094,52.0423646
19.8,3.254121462,0.067614919,35858.08688,1.492204796,52.57525204
20,3.03383452,0.068315054,36395.02138,1.483473352,53.00965829
20.2,2.585388447,0.069030811,37123.08967,1.472122479,53.63008226
20.4,3.068730934,0.069682765,37431.2791,1.471249322,54.06448983
20.6,2.783493339,0.070389437,37727.21624,1.473432192,54.61269526
20.8,2.803022264,0.071081978,37817.9132,1.481727069,55.10947274
21,3.282199431,0.071749954,37524.15835,1.501809391,55.45196561
21.2,3.293399792,0.072456718,36924.27641,1.535425473,55.7889865
21.4,3.358724664,0.073166903,36564.68942,1.562056394,56.17087063
21.6,3.277493943,0.073894221,36310.33478,1.584758166,56.53196425
21.8,3.272870547,0.0746236,36308.12546,1.597855341,56.9193193
22,3.483914967,0.075345492,36801.60877,1.588687313,57.30667479
22.2,3.395187412,0.076095304,37790.35472,1.562056393,57.8253366
22.4,3.804412114,0.076818516,38844.48216,1.536298605,58.42168906
22.6,3.425904068,0.077603197,39763.68951,1.517089426,59.01694608
22.8,3.465409315,0.078366756,40246.85874,1.51097741,59.47542573
23,3.631483678,0.079129466,40254.24913,1.523201435,59.96126136
23.2,3.594378954,0.079913718,39978.29084,1.544593489,60.36393562
23.4,3.527296202,0.080707904,39777.06356,1.561183245,60.7009563
23.6,3.83825721,0.081484146,39635.7311,1.576899847,61.12879829
23.8,3.561332829,0.082308597,39750.664,1.582575297,61.57305247
24,3.796516017,0.083110177,40174.9489,1.577336421,62.08296121
24.2,3.765235999,0.08392994,40553.9071,1.572534124,62.56223094
24.4,3.665673334,0.084766845,40924.40217,1.567295257,62.98241252
24.6,3.785109168,0.08559695,41397.62284,1.561619812,63.52843039
24.8,3.766316228,0.086444967,41898.01995,1.555507797,64.05912881
25,3.93404655,0.087288692,42187.47455,1.55507122,64.47383981
25.2,3.952723026,0.088151107,42659.00539,1.551142067,64.98484233
25.4,3.908946173,0.089026515,43165.20308,1.547649489,65.55821541
25.6,4.179927978,0.089889058,43604.81292,1.546339764,66.11408142
25.8,3.81222974,0.090804223,43754.43655,1.551142072,66.52660285
26,3.955806746,0.091693346,43994.62973,1.55507122,67.05073639
26.2,4.34752658,0.09257439,44152.83913,1.560310079,67.53657241
26.4,3.933194137,0.093519779,44197.47582,1.567731823,67.93815154
26.6,4.066775051,0.094441577,44263.79759,1.57646327,68.43602356
26.8,4.046306374,0.095378633,44576.61431,1.577772988,68.96234493
27,4.04831944,0.096323523,44789.91971,1.582138713,69.47115898
27.2,4.097795713,0.097269911,44930.01411,1.588250726,69.93948669
27.4,4.165589682,0.098229234,45089.48816,1.591743305,70.34434955
27.6,3.941938365,0.099218392,45408.85714,1.592179884,70.87176477
27.8,4.115482656,0.100189945,45669.01477,1.594362741,71.4024638
28,3.983425789,0.101192422,46075.31722,1.589560448,71.84124698
28.2,4.055378665,0.102190847,46588.11056,1.583011858,72.37851083
28.4,4.437926556,0.103178009,47194.73614,1.575153543,72.96501569
28.6,4.101022597,0.104224606,47653.29217,1.572097545,73.54933012
28.8,4.277891812,0.105246371,48088.28204,1.567731815,74.0362601
29,4.304041571,0.106288791,48452.66542,1.568168387,74.62714086
29.2,4.156156333,0.107353556,48709.55003,1.571224399,75.14470819
29.4,4.261409905,0.108411641,48844.19606,1.576463266,75.59990538
29.6,4.437441535,0.109475481,49053.05502,1.581265558,76.1459235
29.8,4.379483902,0.110566147,49309.96005,1.585194713,76.70507146
30,4.30320565,0.111669019,49565.64554,1.588687295,77.24561769
30.2,4.752358267,0.112746841,50014.37351,1.586067847,77.80257875
30.4,4.601134688,0.113876771,50350.35944,1.585194707,78.26105807
30.6,4.404944127,0.115021078,50720.20615,1.586067857,78.86397468
30.8,4.623435623,0.116148286,50716.6538,1.596982163,79.40780428
31,4.75948872,0.117292678,50755.88268,1.603530747,79.81376144
31.2,4.86223259,0.118450755,50669.9417,1.617064491,80.37947558
31.4,4.656044305,0.119641786,50780.47049,1.621430222,80.78871452
31.6,4.848716768,0.120817262,51145.02146,1.620993644,81.36208821
31.8,5.06220529,0.122003168,51633.38,1.615318196,81.85120669
32,4.836028118,0.12323123,52261.0444,1.60789647,82.4628771
32.2,5.127787375,0.124436123,52815.55016,1.601784447,83.03187419
32.4,4.697596467,0.125702585,53307.74262,1.598728452,83.67199355
32.6,4.971033505,0.126933448,53444.15999,1.603094169,84.12937999
32.8,4.947196078,0.128197121,53680.11507,1.60658675,84.6983762
33,5.241447635,0.129451643,53809.63085,1.613135329,85.24439444
33.2,5.214276473,0.130740867,53833.03527,1.622303352,85.74664298
33.4,5.192099991,0.132042684,53897.15876,1.630598229,86.28500117
33.6,5.088317627,0.133363206,54120.28042,1.632344523,86.74566878
33.8,5.303456876,0.134675111,54217.88738,1.638893102,87.2829332
34,5.433659442,0.136006027,54352.25346,1.643258826,87.79503031
34.2,5.052584164,0.13738543,54652.89338,1.642822262,88.32791595
34.4,5.47256232,0.138723562,54881.00761,1.644131969,88.78967975
34.6,5.398749255,0.140109205,55021.70754,1.649370839,89.31600106
34.8,5.205026123,0.141517016,55422.86723,1.648061129,89.90141007
35,5.357703539,0.142915042,55840.88013,1.644568545,90.37192667
35.2,5.419615282,0.144333401,56267.50862,1.64238568,90.91356753
35.4,5.559798939,0.145760614,56656.81968,1.641949105,91.51867361
35.6,5.71413677,0.147201337,57010.47455,1.642385673,92.10955482
35.8,5.483766663,0.148682898,57189.9128,1.647624548,92.65338321
36,5.762173032,0.150144276,57210.93368,1.655046273,93.06700049
36.2,5.700837095,0.151643723,57171.15978,1.665087443,93.52548001
36.4,5.515843828,0.153166668,57162.00111,1.675128616,94.01459736
36.6,5.568583932,0.154688546,57276.31274,1.682113774,94.52997688
36.8,5.886536425,0.156207476,57273.58759,1.690408642,94.95234808
37,5.83060593,0.157767519,57357.70286,1.696084086,95.39113139
37.2,5.908737915,0.159334027,57445.03956,1.701322953,95.8167846
37.4,5.794931298,0.160929381,57630.59804,1.704815537,96.31027929
37.6,5.902620351,0.162525622,57882.45472,1.706125251,96.81362207
37.8,5.873745149,0.164147242,58314.00531,1.700886382,97.25240563
38,5.963943796,0.165776998,58834.52402,1.695210938,97.79951803
38.2,5.985859341,0.167427816,59337.31143,1.689535495,98.3236512
38.4,5.967803475,0.16909797,59760.88021,1.686479488,98.89592999
38.6,6.052167455,0.170777857,59973.17924,1.688662348,99.42553465
38.8,6.178164345,0.172471798,59868.91543,1.697393794,99.80194769
39,6.567291667,0.174164729,59915.69363,1.703505797,100.2943499
39.2,6.130381064,0.175931422,60098.27425,1.705688673,100.761582
39.4,6.36212452,0.177669855,60277.57515,1.709181246,101.2682081
39.6,6.060939527,0.17946236,60537.97848,1.709181255,101.6851061
39.8,6.303503921,0.181235554,60963.06676,1.706561813,102.2311248
40,6.387853713,0.18303743,61169.9859,1.709617818,102.7541638
40.2,6.586280958,0.184849596,61036.38364,1.720095551,103.1623099
40.4,6.544889189,0.186696515,61157.50078,1.724461277,103.6350144
40.6,6.643388463,0.188552242,61166.44672,1.730136717,103.9972028
40.8,6.761870314,0.19042519,61218.04666,1.7366853,104.4578714
41,6.787920542,0.192323388,61356.93102,1.740614452,104.8933725
41.2,6.977177273,0.194229386,61700.28128,1.739304729,105.3551354
41.4,7.235545666,0.196149818,61791.4033,1.743233873,105.7151361
41.6,8.00685347,0.198054365,61894.82906,1.748036146,106.1517338
41.8,9.545906172,0.199924858,62235.16741,1.746289808,106.6375749
42,10.01410767,0.201888006,62927.70273,1.734065765,107.103716
42.2,9.833635537,0.203915507,64629.62683,1.700013119,107.9386081
42.4,9.730601893,0.205958102,66516.23067,1.661594747,108.6793969
42.6,10.0131048,0.207994707,69792.71879,1.597855161,109.8305215
42.8,10.07160968,0.210067298,72853.82001,1.543720176,110.8656574
43,9.763725276,0.212185727,76519.68224,1.486965766,112.2017034
43.2,10.02373807,0.214286476,79241.97456,1.451603391,113.3867488
43.4,9.943175134,0.216431736,81300.75308,1.429774771,114.4765953
43.6,10.0616244,0.218584811,83229.76306,1.414494732,115.7962296
43.8,10.46984986,0.220739645,84177.21769,1.411438715,116.7722787
44,10.55665158,0.222938276,85338.10677,1.407946133,118.0317307
44.2,10.87494061,0.22514318,86384.29846,1.404890118,119.1970802
44.4,10.9525762,0.227397867,86854.40584,1.409255841,120.2300277
44.6,11.09516086,0.229659574,87220.31777,1.417550714,121.4544649
44.8,11.03123391,0.231958231,87527.82624,1.42366273,122.4195698
45,10.90485331,0.234272641,88021.24187,1.43021132,123.6560423
45.2,11.07907243,0.236601362,88624.67537,1.433703895,124.7995066
45.4,11.29825449,0.238950372,89657.69272,1.429774737,125.8893548
45.6,11.14188725,0.241348851,90936.61453,1.425409017,127.2954318
45.8,11.29111719,0.243750267,91742.68385,1.424972441,128.4005982
46,11.31044351,0.246184807,91913.64469,1.435886751,129.6819345
46.2,11.45633698,0.248635227,91753.20633,1.449857066,130.7914778
46.4,11.36157804,0.251126724,91269.07082,1.466883393,131.7160966
46.6,11.30845106,0.253640371,90443.26311,1.491768024,132.8278277
46.8,11.50596309,0.256162022,89883.75548,1.510104061,133.6572502
47,11.66183727,0.258711985,89877.88665,1.522764658,134.7755476
47.2,11.46964093,0.261311586,90002.73816,1.532369257,135.7581598
47.4,11.75124643,0.263904569,90330.27466,1.541100698,136.9092845
47.6,11.64647727,0.266550227,90803.9102,1.544156708,137.8262436
47.8,11.61498239,0.269217436,91045.66329,1.550705295,138.7311666
48,11.88575359,0.271890524,91092.59783,1.562492744,139.8046013
48.2,11.81844651,0.274613616,91472.77688,1.567295043,140.8058158
48.4,11.85688882,0.277356804,91808.43502,1.573407056,141.8814381
48.6,12.36413658,0.280095393,91751.52485,1.583448207,142.7163331
48.8,12.34345095,0.282897928,91814.79682,1.593052802,143.7317728
49,12.43517621,0.28572076,91947.79131,1.599164813,144.5404046
49.2,12.53272704,0.288571657,91622.14911,1.614008273,145.3807691
49.4,12.55533177,0.291456321,91269.10125,1.630161452,146.2933519
49.6,13.16998103,0.294329111,91529.7505,1.634527159,147.0844786
49.8,13.66388579,0.297239137,92161.32015,1.635400289,148.1119575
50,14.23939149,0.300172798,92809.84436,1.633653983,148.954513
50.2,14.01800232,0.303190824,93706.84077,1.62841512,149.9207112
50.4,14.17382157,0.306213126,94712.11225,1.623176247,151.058705
50.6,14.59610045,0.309247506,95477.87418,1.619247083,151.9745724
50.8,14.8818134,0.312321882,96384.21122,1.615317923,153.1202264
51,14.6062847,0.315465712,97137.14305,1.61182535,154.0010755
51.2,14.69214301,0.318616169,98472.65399,1.602220755,155.1456338
51.4,14.63727179,0.321807938,100309.7897,1.586940724,156.47621
51.6,14.86051777,0.325012701,101527.854,1.579082412,157.5211948
51.8,14.92554748,0.32826062,102927.1711,1.571224107,158.8386411
52,14.93644807,0.331544846,103868.4789,1.567294956,159.9044153
52.2,14.99647397,0.334858712,104646.6983,1.566421809,161.0511623
52.4,15.0573287,0.338205746,105145.2896,1.570787532,162.3084259
52.6,15.17147217,0.341582638,105316.2555,1.577336115,163.2614956
52.8,15.04995834,0.345009461,105279.3299,1.588687001,164.4312203
53,15.23570586,0.348449572,105280.668,1.597418444,165.3438041
53.2,15.39147225,0.351926384,105261.4252,1.607459605,166.3483025
53.4,15.44439643,0.355445227,104994.0939,1.621866494,167.423925
53.6,15.82789737,0.358976737,105194.0442,1.627105352,168.3233789
53.8,16.05234895,0.362554859,105846.3956,1.628415062,169.4942
54,15.95787327,0.366190748,106200.1547,1.631907645,170.4013112
54.2,15.85465002,0.369863698,106333.2876,1.639329379,171.3686042
54.4,16.08283604,0.373550799,106580.6267,1.645877959,172.4398511
54.6,16.44924551,0.377265422,106756.93,1.651553389,173.2758402
54.8,16.5774992,0.381033711,106631.2683,1.66334084,174.2704903
55,16.83981278,0.384830487,106857.9969,1.667706557,175.0977252
55.2,16.81317593,0.388685252,107453.0496,1.667706557,176.0770556
55.4,16.79319615,0.392578314,108306.8295,1.665087124,177.2041061
55.6,17.33111907,0.396472185,108805.9938,1.66552368,178.0980908
55.8,17.25783756,0.400447176,109432.6096,1.665523683,179.1945027
56,17.35025818,0.404450694,109824.5714,1.667269969,180.0709767
56.2,17.6408561,0.408480816,110253.7681,1.669452823,181.0732875
56.4,17.62918016,0.412572275,110602.7659,1.673381975,182.1051408
56.6,17.93892062,0.416682702,111120.087,1.673381966,183.0024062
56.8,17.84896155,0.420861941,112096.0243,1.669452817,184.1765078
57,17.80313055,0.425080128,112845.2487,1.666833384,185.0945618
57.2,17.95048042,0.429327276,113473.3248,1.667269952,186.1198506
57.4,18.13529672,0.43361445,114052.0984,1.669016236,187.2129815
57.6,18.43252214,0.437937125,114679.5104,1.668579655,188.1255664
57.8,18.50657962,0.442318504,115165.774,1.672072232,189.2438638
58,18.46905054,0.446751568,115492.9322,1.675564813,190.1181485
58.2,18.65218106,0.451214085,116134.9642,1.675564807,191.1193647
58.4,18.78451184,0.4557249,116799.8578,1.676437948,192.2759604
58.6,18.94348098,0.460302221,117122.082,1.68124024,193.3483012
58.8,19.0816327,0.464880889,117398.3649,1.684732815,194.2182101
59,18.97746145,0.469545393,117769.7836,1.68691568,195.0979656
59.2,19.08562257,0.474242121,118163.1571,1.689535111,196.0740141
59.4,19.05138696,0.478995794,118738.3259,1.690844829,197.1748031
59.6,19.14121771,0.483788653,119570.3483,1.687352248,198.1344382
59.8,19.3059856,0.488624602,120785.6265,1.681240229,199.3501219
60,19.34501056,0.493517694,121450.2334,1.680367084,200.3020975
60.2,19.62967553,0.498442983,121850.6134,1.683423082,201.3208223
60.4,19.70116421,0.503432439,121983.1517,1.690408238,202.4150467
60.6,20.68694873,0.50840923,121794.0984,1.699139655,203.2028947
60.8,20.88582846,0.513490081,120791.8202,1.718785406,204.0016796
61,21.29787275,0.51860739,120256.4547,1.732319136,204.8431407
61.2,21.88977369,0.523763643,120495.341,1.735811697,205.7032055
61.4,21.80468569,0.529018342,121051.1404,1.734938555,206.5315324
61.6,21.76122642,0.534322862,122178.673,1.728389971,207.5994949
61.8,22.36976292,0.539635989,124212.0604,1.709617341,208.7079486
62,22.30297571,0.545048877,126511.2713,1.69040816,210.1151204
62.2,22.2886421,0.550512621,128209.8748,1.678184134,211.3734777
62.4,22.60904642,0.556008213,129088.7608,1.674691546,212.4086167
62.6,22.49643845,0.561616916,130162.1553,1.67119897,213.7457577
62.8,22.61948051,0.567237843,130174.4234,1.678620697,214.6725662
63,23.10557533,0.572861796,130241.5424,1.686915557,215.8083746
63.2,22.97962775,0.57861294,130394.8637,1.693027574,216.8303787
63.4,23.16760034,0.584400137,130986.6757,1.693027568,217.7932977
63.6,23.65034099,0.590225316,131514.523,1.695210415,218.9706866
63.8,24.12724595,0.59610948,132344.0111,1.692154395,219.9981668
64,24.0295829,0.602092287,133823.852,1.683859523,221.3725113
64.2,24.41237919,0.608102162,135062.7877,1.677747499,222.6232129
64.4,24.27140189,0.614208364,136248.2143,1.671635491,223.7546398
64.6,24.56342002,0.620346171,137889.3457,1.662904035,225.2230909
64.8,24.59313135,0.626563669,138819.5872,1.659848028,226.3906283
65,25.49217135,0.632783844,139372.439,1.662467435,227.7529448
65.2,25.93988216,0.639097515,140251.9394,1.661594277,229.0671113
65.4,26.03785275,0.645498681,140624.2233,1.665086853,230.1317923
65.6,26.10916956,0.65196594,141026.9225,1.669889147,231.4776891
65.8,26.56435223,0.658471788,141732.1507,1.670325706,232.5927071
66,26.76139119,0.665060491,142910.0947,1.667269693,233.9845618
66.2,26.65032447,0.671736616,143912.3074,1.665523408,235.323892
66.4,27.07051077,0.678443306,144914.8674,1.662467389,236.5144112
66.6,27.11680818,0.685243126,146359.1277,1.65722852,238.0485143
66.8,26.80920133,0.692135568,147071.0571,1.657228529,239.2193316
67,27.34094523,0.69903945,147322.6703,1.663777098,240.5783626
67.2,27.14407099,0.706062887,147161.9351,1.673381695,241.7480866
67.4,27.35437749,0.713128789,146714.196,1.685169141,242.7263248
67.6,27.91857205,0.720241446,145925.3558,1.701758872,243.8282135
67.8,28.03226909,0.727456573,145421.6363,1.715292611,244.877576
68,28.7180207,0.734704734,145012.3597,1.726206897,245.7190405
68.2,29.37461943,0.742027726,145160.4106,1.731882317,246.726826
68.4,29.54741252,0.749457604,145686.8421,1.734501744,247.8845173
68.6,29.67190049,0.7569654,146609.8641,1.731445736,248.915278
68.8,29.83301837,0.764546123,148247.0732,1.722714284,250.3027562
69,29.87754978,0.772211086,149996.0817,1.711363403,251.4910843
69.2,30.47914665,0.779914723,152437.5269,1.694773638,252.9792344
69.4,30.67687638,0.787723514,155199.5647,1.676437595,254.6840378
69.6,31.40502507,0.795574376,157136.3845,1.665086695,256.0682386
69.8,31.54361501,0.803544505,159685.4873,1.650243232,257.9174793
70,32.19596978,0.811559429,161436.2928,1.641075195,259.3202809
70.2,32.85164596,0.819654697,162779.8642,1.637146026,260.9145719
70.4,32.86197239,0.827875699,163664.815,1.638455742,262.6434468
70.6,33.19037953,0.836157292,164640.406,1.637146016,264.067036
70.8,33.25731336,0.844511988,165243.6132,1.641511736,265.7007139
71,33.46745472,0.852997624,165514.862,1.648060315,267.124302
71.2,33.49064894,0.861553166,165808.5036,1.654390612,268.5320221
71.4,33.47885989,0.870197006,165882.7356,1.662903772,269.9298941
71.6,34.05078141,0.87888764,165410.8799,1.675127778,271.049291
71.8,34.45781875,0.887676987,165018.9337,1.687788362,272.4323948
72,34.67790532,0.89656732,164773.1667,1.696956373,273.506925
72.2,34.76641535,0.9055561,164393.9874,1.707870677,274.6657094
72.4,35.0630892,0.914620554,164733.1496,1.713109535,276.0564724
72.6,34.95922516,0.923803424,165474.2191,1.712672966,277.2447992
72.8,35.40576318,0.933040713,166528.0035,1.711363236,278.7438909
73,35.46175546,0.942397734,167372.1988,1.710053517,279.8917334
73.2,35.83249631,0.951827134,168541.7412,1.7069975,281.2857785
73.4,35.78937569,0.9613796,169861.488,1.703504924,282.8975716
73.6,36.01020887,0.971010004,170339.4795,1.706124351,284.0880899
73.8,36.61074068,0.980711089,171056.4216,1.707870621,285.5642047
74,36.71747177,0.990543565,171233.791,1.712672913,286.6934464
74.2,37.61109012,1.000420698,171271.7455,1.719221469,287.9200808
74.4,37.90598773,1.010438165,170669.3428,1.732318627,289.1554636
74.6,38.45567893,1.020538845,171051.7432,1.734501471,290.2299979
74.8,38.42080499,1.030781132,171693.0738,1.735811189,291.62404
75,38.69318428,1.041105281,172835.693,1.731445458,292.8451971
75.2,38.90226654,1.051537488,174104.663,1.727079729,294.2272049
75.4,39.44524811,1.062051689,175554.7366,1.721840846,295.8324379
75.6,39.84083003,1.072681489,176117.9481,1.723150551,297.0229593
75.8,40.22640715,1.083418841,176208.8792,1.730572266,298.3513522
76,40.60447745,1.094264632,175984.8846,1.738867127,299.2967655
76.2,40.4404493,1.105256685,176432.1517,1.74235971,300.5015062
76.4,40.85430007,1.116319299,177916.4079,1.737993975,302.031236
76.6,41.03081926,1.127509295,179668.8134,1.729262525,303.3475908
76.8,41.69278771,1.138778539,182322.4766,1.71441905,305.1366546
77,42.0807857,1.15017965,184913.5962,1.700448727,306.9946535
77.2,42.41214694,1.161699432,186376.3165,1.695209851,308.5790946
77.4,42.69769638,1.173338025,187239.5578,1.694336698,309.9479726
77.6,42.90495871,1.18509893,187482.883,1.700448702,311.5586742
77.8,43.21962521,1.196970653,187176.7169,1.709616709,312.6933891
78,44.14381203,1.20891966,186919.9286,1.720094413,314.0797813
78.2,44.66162875,1.221016671,186745.4044,1.728825841,315.2921881
78.4,45.0770096,1.233242275,186406.8696,1.737993844,316.3229529
78.6,45.30418666,1.245603571,186460.2521,1.745415564,317.6841708
78.8,45.58547457,1.258085454,186847.2102,1.748034988,318.8134143
79,45.70936817,1.270703542,187810.2384,1.74716184,320.2720184
79.2,46.38032892,1.283410753,188964.693,1.744105814,321.6638795
79.4,46.76982323,1.296265111,190266.8068,1.739303508,322.9889904
79.6,46.84787388,1.309269958,191775.1032,1.734501212,324.6533077
79.8,47.19903392,1.32238672,193297.7799,1.72838919,326.0550143
80,47.43693186,1.335643025,195117.5166,1.721404029,327.8298497
80.2,48.10780885,1.349070191,196718.8592,1.71572857,329.448216
80.4,48.0600605,1.362614794,198071.9058,1.71136285,330.8542948
80.6,48.46279333,1.376195832,199650.9469,1.707433688,332.7035402
80.8,48.80887891,1.389985872,200096.7017,1.710489683,334.0603832
81,49.30150302,1.403904498,199236.2306,1.725333121,335.4795988
81.2,49.36110848,1.41799274,198175.093,1.740613144,336.6252532
81.4,49.81289772,1.432195475,197703.5689,1.750217717,337.6921276
81.6,50.81841379,1.44650286,197561.1928,1.758075984,339.0205294
81.8,51.06865704,1.461006047,198208.579,1.758512548,340.2132377
82,51.69442964,1.475629074,200052.6757,1.75065423,341.8677135
82.2,52.11034555,1.490413357,202151.4936,1.740613058,343.4674757
82.4,52.9142809,1.50531964,203244.7053,1.7379936,344.8090052
82.6,53.19110171,1.520411953,204284.0755,1.73755702,346.441593
82.8,53.60363448,1.535646481,205421.3062,1.73624729,348.0555804
83,53.90040459,1.551041993,206568.686,1.734064421,349.4441556
83.2,54.36785957,1.56658041,207378.7833,1.73493755,350.8983863
83.4,54.55301215,1.58229442,209244.7882,1.729262107,352.7531007
83.6,54.9146781,1.598154147,210893.1057,1.723586659,354.2521939
83.8,55.27549285,1.614172964,212914.2385,1.717038066,356.168187
84,55.71789321,1.630346771,214144.1018,1.71441862,357.6541504
84.2,55.89630979,1.64670122,215589.265,1.71136261,359.4333634
84.4,56.33367596,1.6632021,217238.0482,1.707433448,361.3996916
84.6,57.19736359,1.679839542,218500.5634,1.704813989,362.9710102
84.8,57.41569177,1.696688499,219424.4408,1.706123698,364.8443262
85,57.69811791,1.713702378,220867.4476,1.703940829,366.7964286
85.2,57.81065403,1.730898812,222351.9462,1.701321394,368.6358233
85.4,58.60181792,1.748221418,222556.9673,1.706560234,370.1261682
85.6,59.13316017,1.765735848,222276.7266,1.716601376,371.8506742
85.8,59.87015806,1.783412075,222333.552,1.72227679,373.2009581
86,60.08336902,1.801302022,222345.396,1.729698508,374.8510531
86.2,60.78118856,1.819338472,222504.4533,1.735373923,376.3162294
86.4,61.20919329,1.837574622,224430.8595,1.728825329,377.9510087
86.6,61.79955257,1.855982766,227857.9096,1.713981861,380.144939
86.8,61.85280095,1.874612863,231076.4549,1.701321269,382.3815371
87,62.5064019,1.893388685,233374.1662,1.693462953,384.2001484
87.2,62.9826165,1.91236545,235409.588,1.688224074,386.257299
87.4,63.53791511,1.931527472,235743.3071,1.694336066,388.2641163
87.6,63.85170927,1.950898647,234661.3191,1.707433217,389.6100181
87.8,64.46525161,1.970443768,232964.7617,1.725769223,391.1014559
88,65.22699111,1.990175061,231948.2958,1.738429789,392.3215278
88.2,65.51906664,2.010136856,231215.0963,1.750217224,393.675089
88.4,66.2765962,2.030267792,231588.3637,1.755456064,395.345982
88.6,66.75764689,2.050620369,233204.489,1.751090329,396.8910353
88.8,67.33568294,2.071170906,236374.7417,1.738429722,399.058705
89,67.5581335,2.091952463,238442.3895,1.731444564,400.7350619
89.2,68.23146501,2.112911706,240363.4909,1.726642251,402.6762276
89.4,68.65079954,2.134099097,241558.3411,1.72707881,404.6491229
89.6,69.17544545,2.15549203,241482.7081,1.733627374,406.0464565
89.8,69.7933284,2.177093192,240233.9581,1.748470802,407.5554026
90,70.52651466,2.198902735,239388.1839,1.760258223,409.0019797
90.2,71.13810175,2.220939635,238936.7509,1.768553071,410.3281904
90.4,71.8629098,2.243190205,238838.1623,1.773791911,411.5832768
90.6,72.56437635,2.265665848,240232.6987,1.770299313,413.3187297
90.8,73.18421236,2.288373003,241795.1755,1.765497002,414.850655
91,73.929759,2.311299701,243533.621,1.760694687,416.727263
91.2,74.24310933,2.334486481,245677.9344,1.753272954,418.5743212
91.4,74.78375873,2.357890544,248097.6882,1.744104926,420.3185253
91.6,75.51756637,2.381516457,249675.5089,1.741922043,422.3144045
91.8,76.28798504,2.405377221,251418.5608,1.737119728,423.9951475
92,76.57874262,2.429510801,254624.0389,1.725768848,426.3543027
92.2,77.2058814,2.453863557,257273.5886,1.717473962,428.5022787
92.4,77.58651356,2.478478012,258850.8387,1.714417947,430.323076
92.6,78.14781209,2.50332728,261271.9201,1.707869351,432.7161581
92.8,78.9139249,2.528412176,262787.6167,1.706559612,435.0085729
93,79.46517269,2.553763972,262714.2274,1.712671602,436.6269421
93.2,80.15045498,2.579361233,262581.449,1.719656731,438.4980781
93.4,80.97226958,2.605206192,263218.7897,1.723149281,440.5453886
93.6,81.44099069,2.631335082,263509.2262,1.727951557,442.1911126
93.8,81.81308848,2.657733113,263928.375,1.73362698,444.1585367
94,82.51989936,2.684373453,265125.1167,1.732753814,445.8075469
94.2,82.90359292,2.711303532,266157.8331,1.73450009,447.6961878
94.4,83.6811204,2.738477126,266406.2748,1.741485215,449.6165664
94.6,84.08307005,2.765949523,267927.9891,1.740612059,451.6748133
94.8,84.72563685,2.793681423,269899.3679,1.735809748,453.5361018
95,85.31571135,2.821695659,270905.1573,1.737556017,455.5133788
95.2,86.00401128,2.849984585,273457.0597,1.729697702,457.6996537
95.4,86.96290446,2.878539061,276104.9283,1.720529664,459.8126202
95.6,87.55371248,2.907405845,277788.3345,1.717473642,462.2210217
95.8,88.35682432,2.936548001,278397.5622,1.718783333,464.0834089
96,88.99086474,2.965994656,279893.7807,1.716600454,466.5213566
96.2,89.64152467,2.995735944,280167.1395,1.721402724,468.4647131
96.4,90.45369291,3.025765071,280623.8904,1.725768417,470.2450328
96.6,91.25416832,3.056096572,281564.2432,1.729697539,472.4750804
96.8,91.92720574,3.086741623,282987.5241,1.731007233,474.6569791
97,92.29544051,3.117715523,283915.5391,1.732753509,476.3541307
97.2,93.53047589,3.148940912,285586.2723,1.731443755,478.4616315
97.4,94.15261031,3.180522362,287226.2365,1.730570592,480.7529533
97.6,94.85797746,3.21241522,289509.8188,1.724895137,482.7860378
97.8,95.71400645,3.244780603,292984.5051,1.714853959,485.4953584
98,96.47342365,3.277316214,296516.4507,1.704812785,488.293309
98.2,97.09957136,3.310188419,298494.9124,1.702193335,490.7411046
98.4,97.78731958,3.343219861,300410.4827,1.699137311,492.9350423
98.6,98.8347345,3.376725445,300982.3264,1.70437614,495.4681955
98.8,99.33586158,3.41060525,300773.3057,1.711361273,497.3086936
99,100.0176441,3.444813069,299667.6149,1.724458404,499.4555794
99.2,101.0291343,3.479341974,299659.076,1.731443521,501.4580304
99.4,101.8174216,3.51423319,299701.3371,1.737118929,503.1365893
99.6,102.5507102,3.549478751,300169.1359,1.742357766,505.3305277
99.8,103.1990226,3.585084234,300088.4474,1.748906322,507.0068954
100,104.461823,3.621005158,301370.2499,1.749779425,509.192088
100.2,105.2707621,3.657318316,302872.7284,1.748906256,511.3017731
100.4,105.8456712,3.694012356,304347.5741,1.748906238,513.6171672
100.6,106.920155,3.731040663,306136.9771,1.745850202,515.562723
100.8,107.4758259,3.768476628,309044.2956,1.738865038,518.1626168
101,108.6193365,3.806248337,310853.642,1.735809,520.2460462
101.2,108.9367685,3.84445605,312623.4728,1.733626132,522.5089148
101.4,109.5664169,3.883024845,314835.3953,1.730133539,525.1460142
101.6,110.4674792,3.921962509,316319.1861,1.728387224,527.1736336
101.8,111.5200467,3.961281009,317893.548,1.728387191,529.7888558
102,112.3185959,4.001011897,319014.5737,1.729260309,531.850395
102.2,113.1121025,4.041142292,320011.1077,1.731443143,534.1099905
102.4,113.963851,4.081671788,320282.5133,1.737991691,536.5107402
102.6,114.7331151,4.122614194,320258.353,1.745413384,538.7495446
102.8,115.8587253,4.163943496,319956.6379,1.752398495,540.4390523
103,117.1808034,4.205674439,320551.5139,1.756327597,542.6111188
103.2,118.0381884,4.24785665,321909.2892,1.75632757,544.8258521
103.4,118.5649438,4.290485375,324544.8936,1.749342407,546.9847728
103.6,119.7653004,4.333495998,328168.7578,1.739737794,549.8144683
103.8,120.6117109,4.376963277,331411.4773,1.730569765,552.1878648
104,121.2648852,4.42088053,334986.6251,1.721401741,555.1269728
104.2,122.2302691,4.465217592,338249.5748,1.713543422,557.8724093
104.4,123.3962808,4.509986232,339986.0889,1.713543386,560.7557213
104.6,124.1758694,4.555231256,341006.3714,1.715289648,562.9748315
104.8,125.1769022,4.600915569,342911.9429,1.715289616,565.8318802
105,125.8939323,4.647078354,344123.9515,1.716599309,568.0542712
105.2,126.8690442,4.693687243,344363.9473,1.722711281,570.4386137
105.4,128.0356216,4.740751355,346087.35,1.723147817,573.2573676
105.6,128.9231909,4.788307491,348429.831,1.719218644,575.7434714
105.8,129.660403,4.836351978,350499.8853,1.717472335,578.7044674
106,130.863452,4.884849185,352575.7667,1.714416297,581.129301
106.2,131.8645155,4.933847776,355752.9621,1.708304265,584.0640411
106.4,132.8138947,4.983342111,358632.42,1.704375093,587.2427941
106.6,133.6470549,5.033341675,358809.0717,1.712233353,590.0298103
106.8,134.5850764,5.083836388,358669.5634,1.71965504,592.1395015
107,135.4560069,5.134843061,358311.5709,1.729259585,594.6912602
107.2,136.4521984,5.186353654,356758.7792,1.742793269,596.7648423
107.4,137.6756559,5.238363679,355560.7279,1.755017231,598.942382
107.6,139.0447743,5.290886166,356818.7579,1.755017187,600.9754869
107.8,140.2281402,5.343949103,359389.813,1.750651435,603.7362509
108,141.2798782,5.397554228,362465.7831,1.743229688,606.1807782
108.2,142.4980926,5.451686449,366363.2018,1.733625078,609.1220898
108.4,143.6454646,5.50636751,372359.5558,1.717035328,612.7724608
108.6,145.0434141,5.561580624,375635.1263,1.710486714,615.5923185
108.8,146.0599244,5.617374747,378925.3908,1.705684397,618.9756944
109,146.9048343,5.673741159,381031.6315,1.705684371,622.1391288
109.2,148.5274159,5.730620463,382431.055,1.707867178,625.0377763
109.4,149.4921016,5.788116589,382965.4077,1.712232861,627.462607
109.6,150.5358261,5.84618494,383625.4369,1.717471685,630.3907858
109.8,151.6952274,5.904828598,384513.0847,1.721837362,633.3703974
110,152.7971042,5.964065551,385755.538,1.72271047,635.7470861
110.2,153.9913409,6.023891215,386793.9064,1.725329861,638.4323509
110.4,154.8923989,6.084338102,388357.65,1.726639547,641.5366986
110.6,156.1189702,6.145369969,390226.1573,1.725329794,644.1738181
110.8,157.285516,6.207019074,391320.5418,1.728385757,647.2103303
111,158.6643271,6.269272957,390686.9249,1.736680568,649.4075727
111.2,159.779101,6.33217051,390384.2343,1.744102244,651.8641428
111.4,160.8896379,6.395700385,391498.009,1.747158208,654.7299532
111.6,162.0542257,6.459864835,391949.6429,1.751523884,656.9698666
111.8,163.4810376,6.524655796,393889.8622,1.751087267,659.9046225
112,164.7895309,6.590105873,396968.5169,1.744975228,662.5078253
112.2,166.1579019,6.656209371,400330.6236,1.740172901,666.1210021
112.4,167.2414137,6.722996763,400697.5065,1.743665436,668.3740456
112.6,168.6462679,6.790432898,401263.2688,1.747594533,671.1960947
112.8,169.7179651,6.858569588,401394.4374,1.752396782,673.3889571
113,171.4390849,6.927346206,400174.8671,1.763311006,675.7755115
113.2,172.2949541,6.996873462,401311.9371,1.765493835,678.3316517
113.4,173.4746604,7.067076741,403865.0924,1.762001228,680.7729054
113.6,175.1988673,7.137947903,406173.1523,1.76112803,683.7229891
113.8,176.3684163,7.209569374,408449.9902,1.76025485,686.6796265
114,178.0641449,7.281874115,410772.7476,1.757635369,689.1384013
114.2,179.3117991,7.35493621,411092.4369,1.762874183,691.5512077
114.4,180.4161443,7.428742218,410887.3484,1.770732427,694.1762929
114.6,182.015024,7.503255649,412308.1136,1.770732376,696.5081347
114.8,183.3431908,7.578536369,414797.1493,1.768112906,699.5588799
115,184.9302377,7.654555488,417430.0479,1.763747144,702.0570461
115.2,186.4389224,7.731344103,422784.8015,1.750649964,705.3135115
115.4,188.144866,7.808890612,429117.8259,1.735369923,709.2363691
115.6,189.1620343,7.887659513,433879.34,1.724892186,712.4862569
115.8,190.5738536,7.966799229,440547.6655,1.709612155,716.8041242
116,192.1895904,8.046721433,445035.3942,1.700444113,720.1809598
116.2,193.5854497,8.127055335,447833.9257,1.697824644,723.8094639
116.4,195.0153082,8.208600375,449770.7893,1.699134313,727.6666609
116.6,196.3484789,8.290971499,449917.7332,1.705246265,730.5565577
116.8,197.8897269,8.374155864,448473.502,1.717906775,733.5733918
117,199.2643388,8.458187433,446850.898,1.731440432,736.6186708
117.2,200.6688294,8.543061297,447065.0167,1.737552381,739.449482
117.4,202.2555809,8.62877554,448466.9323,1.738862043,742.1533654
117.6,203.6457164,8.715364283,451647.1583,1.735806003,745.7873428
117.8,205.2131145,8.802810958,455162.9837,1.730130531,748.8654531
118,206.7171256,8.891140622,459676.2496,1.723145349,752.8233271
118.2,208.2376873,8.980356404,461218.8234,1.725328156,756.0994931
118.4,209.9846377,9.070453089,461409.7689,1.732313235,759.3778562
118.6,211.6981749,9.161457203,461331.0043,1.738425173,761.9537209
118.8,213.348321,9.253380068,460581.8475,1.748029679,765.0110458
119,215.0974503,9.346219476,460479.4325,1.753705044,767.4370023
119.2,216.8456387,9.439988521,462948.1016,1.751958705,770.601566
119.4,218.328088,9.534717555,466491.1781,1.747592949,774.2826003
119.6,220.144337,9.630375701,470623.4194,1.741917471,778.1026107
119.8,221.6365561,9.727016525,473162.4094,1.74017114,781.0406633
120,223.221924,9.824622087,475396.603,1.739734519,784.0137307
120.2,225.1677344,9.923183243,476673.384,1.742790452,787.1651709
120.4,226.8028347,10.02275621,479089.7173,1.7427904,790.8845113
120.6,228.4344878,10.12332973,481752.5475,1.741480636,794.5075564
120.8,230.1234791,10.22490979,485378.3421,1.735805163,797.8088999
121,231.6008475,10.32752515,489433.8897,1.730129697,801.876201
121.2,233.5968643,10.43113564,493484.1711,1.724454214,805.7213876
121.4,235.3171382,10.53580605,494847.4577,1.726637014,808.7776258
121.6,237.1688555,10.64151895,495225.6911,1.733622086,812.339402
121.8,238.9138643,10.74830141,492996.2616,1.746719149,814.6800125
122,240.9218796,10.85613868,491551.9688,1.758506492,817.6706064
122.2,242.6791279,10.96507663,490394.1936,1.76854756,820.3865421
122.4,244.4703893,11.07510668,492051.3885,1.768547502,823.0970053
122.6,246.3131491,11.18623871,496317.3553,1.761562312,826.9104578
122.8,248.4022564,11.29847031,502803.2832,1.747155416,830.6079291
123,250.1365048,11.41185384,511002.6055,1.730129109,835.4193203
123.2,251.908092,11.526374,518698.4981,1.714849083,839.9670029
123.3,253.1976918,11.58403831,521188.9603,1.710919908,841.8425541
123.6,255.1324564,11.58622244,526416.7735,1.708300425,848.159616
123.8,256.4181768,11.58613472,528026.361,1.71222952,852.3155516
124,257.2588223,11.58607747,528797.3268,1.716595199,855.5085473
124.2,258.1839863,11.58601444,528010.5998,1.726199721,858.8809999
124.4,258.7610842,11.58597524,528646.429,1.731875119,862.7578842
124.6,259.4589228,11.58592777,529131.1975,1.736240802,865.7954966
124.8,260.0818189,11.58588544,528509.6679,1.744972193,869.3441109
125,260.4569886,11.58586007,527740.8237,1.752393878,872.0414065
125.2,260.9104315,11.58582933,529177.0245,1.754140146,875.4401079
125.4,261.5578921,11.58578531,531006.9204,1.756322977,879.275415
125.6,261.8855982,11.58576319,532663.4925,1.758069249,882.3108269
125.8,262.1858255,11.58574295,536224.1188,1.755886387,886.2566403
126,262.7575109,11.58570412,538692.8308,1.755013228,889.2844013
126.2,262.9453246,11.58569158,538158.6302,1.764617772,892.940239
126.4,263.2072479,11.58567396,537798.9186,1.771166321,895.5456157
126.6,263.6073984,11.58564688,538948.9796,1.774222301,898.9432226
126.8,263.7102773,11.58564015,538677.4882,1.779897714,901.4785648
127,264.0837816,11.58561489,539385.9581,1.783826836,904.7426749
127.2,264.2774241,11.58560195,542079.6374,1.781643977,908.0582075
127.4,264.5776514,11.5855817,544121.6207,1.781643968,911.6188514
127.6,264.8570613,11.58556289,545538.717,1.7825171,914.4726183
127.8,265.1123231,11.58554573,547711.4354,1.782517091,918.0245091
128,265.3983946,11.58552645,548515.6521,1.785136505,920.7721369
128.2,265.6894622,11.58550684,547289.3444,1.793867904,923.3479725
128.4,265.901424,11.58549264,547480.7293,1.799543313,926.40636
128.6,265.9943105,11.5854866,546346.3508,1.807401578,928.6265624
128.8,266.2295877,11.5854708,543650.9832,1.820062112,930.9233671
129,265.9993891,11.58548688,541814.5214,1.829230099,932.7058649
129.2,266.4037031,11.58545952,540143.9993,1.838398065,934.7717903
129.4,266.8604767,11.58542855,537315.8836,1.851058592,936.5849485
129.6,266.9616902,11.58542194,536804.0501,1.855860863,938.2580341
129.8,267.0470825,11.58541641,538190.3276,1.856297431,940.6872342
130,267.3056751,11.58539902,540793.993,1.853241429,943.2926121
130.2,267.5842523,11.58538026,543089.7478,1.849748857,945.2491108
130.4,267.5847099,11.58538055,548004.6148,1.840144308,948.4169192
130.6,267.7342196,11.58537062,551830.6502,1.834468888,951.5081316
130.8,267.6181001,11.58537889,553252.1864,1.834468892,953.7348906
131,268.052391,11.58534947,553518.1958,1.838398011,956.2100615
131.2,267.942933,11.58535728,553911.4645,1.841890578,958.5407751
131.4,268.3813874,11.58532758,551082.0195,1.853677965,959.9895544
131.6,268.1411965,11.58534434,546770.4294,1.869831078,961.3354522
131.8,268.5480085,11.5853168,544334.3864,1.879872184,962.4909763
132,268.3194754,11.58533276,542408.9853,1.88904017,963.9222247
132.2,268.5522544,11.58531714,539020.5466,1.901700704,964.8402952
132.4,268.6892738,11.58530808,539129.6453,1.903446982,966.0581822
132.6,268.4873868,11.58532222,539210.4396,1.906066411,967.5135051
132.8,268.9308373,11.58529217,536840.5598,1.915670945,968.4797278
133,268.7239542,11.58530665,534695.5993,1.92352922,969.0749848
133.2,268.9217601,11.58529342,531632.6411,1.934880043,969.7687338
133.306,269.1465385,11.5852782,530270.6629,1.93968231,969.8508107
134.1,269.2146038,11.4370023,1.7977E+308,1.8335957,0
134.3,269.1336067,11.32117027,1.7977E+308,1.644997289,0
134.5,268.6729015,11.20536424,1.7977E+308,1.399644733,0
134.7,268.7984124,11.08951807,1.7977E+308,1.087496888,0
134.9,268.3318783,10.97371245,1.7977E+308,0.743915983,0
135.1,268.4407354,10.85786742,1.7977E+308,0.462764636,0
135.3,267.8359741,10.74207126,1.7977E+308,0.258449687,0
135.5,267.8224252,10.62623461,1.7977E+308,0.138392822,0
135.7,267.5415818,10.51041627,1.7977E+308,0.066358704,0
135.9,267.3256884,10.39459348,1.7977E+308,0.013533683,0
136.1,267.0848142,10.2787724,1.7977E+308,0.015716535,0
136.3,267.0621057,10.16293638,1.7977E+308,0.012223972,0
136.5,266.743791,10.04712061,1.7977E+308,0.009604549,0
136.7,266.6861094,9.931286982,1.7977E+308,0.013097113,0
136.9,266.1704463,9.815484719,1.7977E+308,0.007858268,0
137.1,265.8579604,9.699668543,1.7977E+308,0.00960455,0
137.3,265.9801406,9.583822603,1.7977E+308,0.012223972,0
137.5,265.6818106,9.468005458,1.7977E+308,0.014406824,0
137.7,265.2485841,9.35219755,1.7977E+308,0.021828522,0
137.9,265.2175487,9.236362102,1.7977E+308,0.023574804,0
138.1,264.9408687,9.120543474,1.7977E+308,0.022265093,0
138.3,264.7840965,9.004716636,1.7977E+308,0.02008224,0
138.5,264.6481417,8.888888372,1.7977E+308,0.0192091,0
138.7,264.0175669,8.773093977,1.7977E+308,0.016153107,0
138.9,263.9698776,8.65725967,1.7977E+308,0.013097114,0
139.1,263.5108376,8.541453529,1.7977E+308,0.01004112,0
139.3,263.4198482,8.425622186,1.7977E+308,0.012660543,0
139.5,263.312205,8.309791984,1.7977E+308,0.015279966,0
139.7,262.9089555,8.193982023,1.7977E+308,0.011787402,0
139.9,262.832122,8.078149711,1.7977E+308,0.007421698,0
140.1,262.4188801,7.962340434,1.7977E+308,0.003492564,0
140.3,262.2895869,7.846511715,1.7977E+308,0.017899389,0
140.5,262.0786896,7.730688583,1.7977E+308,0.031433074,0
140.7,261.8161654,7.614868986,1.7977E+308,0.03754506,0
140.9,261.5881979,7.499047022,1.7977E+308,0.042783906,0
141.1,261.565073,7.383211033,1.7977E+308,0.039291342,0
141.3,261.073558,7.267407116,1.7977E+308,0.028377081,0
141.5,260.8680733,7.151583613,1.7977E+308,0.020082242,0
141.7,260.9253034,7.035742121,1.7977E+308,0.019645671,0
141.9,260.4358701,6.919938062,1.7977E+308,0.019209101,0
142.1,260.5339022,6.804093776,1.7977E+308,0.020518813,0
142.3,260.2130893,6.68827817,1.7977E+308,0.013533685,0
142.5,259.8806188,6.572463363,1.7977E+308,0.003492564,0
142.7,259.7380024,6.456635555,1.7977E+308,0.007421698,0
142.9,259.511284,6.340813507,1.7977E+308,0.010477692,0
143.1,259.0763921,6.225005712,1.7977E+308,0.013970256,0
143.3,258.696458,6.109194155,1.7977E+308,0.013533685,0
143.5,258.6404418,5.993360417,1.7977E+308,0.006111987,0
143.7,258.4128906,5.877538426,1.7977E+308,0.003492564,0
143.9,258.1978299,5.761715579,1.7977E+308,0.006548557,0
144.1,257.9194844,5.645897065,1.7977E+308,0.012660545,0
144.3,257.858472,5.53006367,1.7977E+308,0.022265096,0
144.5,257.4169186,5.414256332,1.7977E+308,0.027503942,0
144.7,256.9953498,5.298447625,1.7977E+308,0.032742788,0
144.9,256.7128408,5.182629397,1.7977E+308,0.035362211,0
145.1,256.7600786,5.066788589,1.7977E+308,0.036235353,0
145.3,256.5225351,4.950967282,1.7977E+308,0.029686795,0
145.5,256.3016455,4.835144834,1.7977E+308,0.022265096,0
145.7,256.0624367,4.71932364,1.7977E+308,0.014843398,0
145.9,255.6833352,4.603512026,1.7977E+308,0.01702625,0
146.1,255.380009,4.487695223,1.7977E+308,0.029686796,0
146.3,255.32316,4.371861542,1.7977E+308,0.048022758,0
146.5,254.9299028,4.256050897,1.7977E+308,0.059373592,0
146.7,254.8813808,4.140216647,1.7977E+308,0.06592215,0
146.9,254.3732118,4.02441387,1.7977E+308,0.06592215,0
147.1,254.362161,3.908577054,1.7977E+308,0.05719074,0
147.3,254.1096291,3.792756772,1.7977E+308,0.038418207,0
147.5,253.7388546,3.676944588,1.7977E+308,0.02444795,0
147.7,253.8177347,3.561101613,1.7977E+308,0.023138238,0
147.9,253.1255404,3.445311438,1.7977E+308,0.019209104,0
148.1,252.9046508,3.32948899,1.7977E+308,0.021828527,0
148.3,252.7287266,3.213663463,1.7977E+308,0.023138239,0
148.5,252.1364556,3.097866445,1.7977E+308,0.024884521,0
148.7,252.1403933,2.982028602,1.7977E+308,0.027940515,0
148.9,251.7546303,2.866217444,1.7977E+308,0.035362215,0
149.1,251.5528926,2.750393685,1.7977E+308,0.035798786,0
149.3,251.2445701,2.634577224,1.7977E+308,0.037108498,0
149.5,250.8088455,2.518769487,1.7977E+308,0.031869651,0
149.7,250.9068776,2.402925201,1.7977E+308,0.024447951,0
149.9,250.1339119,2.287140556,1.7977E+308,0.027503946,0
150.1,249.9063607,2.171318564,1.7977E+308,0.037545069,0
150.3,249.6688172,2.055497257,1.7977E+308,0.04540334,0
150.5,249.5495162,1.939667853,1.7977E+308,0.044530198,0
150.7,249.0696588,1.823863137,1.7977E+308,0.040164493,0
150.9,248.8978981,1.708037325,1.7977E+308,0.039727923,0
151.1,248.2548327,1.592243786,1.7977E+308,0.03754507,0
151.3,247.7966926,1.475858394,1.7977E+308,0.034489076,0
151.5,247.6248645,1.360611776,1.7977E+308,0.034925647,0
151.7,247.2549227,1.244799534,1.7977E+308,0.033615936,0
151.848,246.843638,1.159107893,1.7977E+308,0.031869654,0
227.1,246.0764196,1.019115637,1.7977E+308,0.032306226,0
227.3,246.2502269,0.903266163,1.7977E+308,0.034489079,0
227.5,245.5571997,0.787476044,1.7977E+308,0.037108503,0
227.7,245.2796869,0.671657473,1.7977E+308,0.036235362,0
227.9,245.0071702,0.555838561,1.7977E+308,0.037981644,0
228.1,244.4848453,0.440036753,1.7977E+308,0.045403345,0
228.3,243.9133914,0.32423831,1.7977E+308,0.044093634,0
228.5,243.2066248,0.208449132,1.7977E+308,0.039073072,0
228.7,242.3029261,0.092673439,1.7977E+308,0.032742799,0
228.858,241.417494,0.001222385,1.7977E+308,0.028813663,0