File: Test_13.csv
Time On Sample,Displacement Into Surface,Load On Sample,Harmonic Contact Stiffness,Harmonic Displacement,Harmonic Load
0,0,0,731.1197497,0.301060454,2.217318472
0.19,0.16447299,0.000707952,7188.508181,0.206516146,2.285962755
0.4,0.202713232,0.001498413,12486.99286,0.175582293,2.366592527
0.6,0.2521319,0.002250196,15566.70333,0.156412019,2.482089221
0.8,0.129531365,0.003014996,17033.02331,0.146391192,2.598675487
1,0.322299368,0.003755932,16714.48358,0.14726257,2.713082616
1.2,0.565759025,0.004493031,16655.13239,0.149005325,2.822041791
1.4,0.316429364,0.00526742,17318.4289,0.15423358,3.037780862
1.6,0.644652108,0.005998105,18850.77236,0.156412024,3.337418554
1.8,0.505846862,0.00676413,20812.14675,0.159461839,3.634876996
2,0.582273379,0.007513868,22901.19688,0.161204593,3.869139166
2.2,0.924623312,0.008243483,25074.83891,0.164254413,4.166597699
2.4,0.681110719,0.009017432,27483.202,0.166868539,4.542506703
2.6,0.899640063,0.009756416,30216.22758,0.171661111,5.062241887
2.8,0.922050888,0.010510241,32814.3125,0.17427524,5.556916404
3,1.133932151,0.011249728,35194.49227,0.176889372,6.051590976
3.2,1.120609516,0.012006256,37283.88128,0.180374876,6.544086334
3.4,1.146344384,0.012759829,39912.1752,0.187345887,7.288277298
3.6,1.11141547,0.013517992,42531.41762,0.193881208,8.049901737
3.8,1.28008418,0.014260749,44370.5672,0.203030661,8.804988686
4,1.256789417,0.015018031,44916.149,0.217408368,9.545910897
4.2,1.269228114,0.01577261,44967.93722,0.233964517,10.2759372
4.4,1.359781819,0.016521277,45513.35228,0.250084979,11.11492268
4.6,1.426236213,0.017271768,45284.7968,0.274919204,12.19579749
4.8,1.140342063,0.018048922,44824.92616,0.300624797,13.25814902
5,1.176880071,0.018801677,44938.29199,0.317616635,14.09059693
5.2,1.443608049,0.019537012,44569.2493,0.342015175,15.10173803
5.4,1.523358616,0.020286497,44437.12298,0.372077658,16.41033748
5.6,1.318903514,0.021057487,44910.90927,0.392554996,17.424747
5.8,1.210845657,0.021821184,44545.20821,0.424795914,18.6047745
6,1.34461192,0.022566581,42946.18508,0.469236106,19.7477561
6.2,1.272287523,0.023327573,41209.158,0.516726109,20.8155557
6.4,1.288881275,0.024081837,39327.77699,0.569444372,21.85175724
6.6,1.055340799,0.024855029,37303.15543,0.631747764,22.96531949
6.8,0.888281183,0.025623191,35339.16791,0.696229598,23.95139952
7,0.896564827,0.026378084,33149.26252,0.772039331,24.89280666
7.2,1.282958347,0.027104364,31413.25618,0.836521194,25.5629059
7.4,1.469078288,0.0278458,29059.65678,0.932372593,26.41823543
7.6,1.457417675,0.028602201,27291.36846,1.009489392,26.96738952
7.8,1.282878957,0.029370928,25256.11806,1.106212144,27.57647087
8,1.150721789,0.030136448,23850.0699,1.179843428,28.01993462
8.2,1.232965387,0.030885743,22460.79663,1.261752803,28.55274482
8.4,1.875310233,0.031592654,21483.78427,1.326234705,28.9613426
8.6,1.71074364,0.032360626,20859.6,1.378517268,29.4298667
8.8,2.030656324,0.033091935,20722.98773,1.4042229,29.82429949
9,2.201818083,0.0338345,21151.09393,1.406401359,30.42248545
9.2,1.881852471,0.03461423,21849.03097,1.390716556,30.95202643
9.4,1.560224844,0.035394086,23156.52404,1.351068907,31.64173735
9.6,1.678201909,0.036140676,24697.54574,1.307935794,32.41752679
9.8,1.71473992,0.03689343,25652.47363,1.287458456,33.01571267
10,2.068724048,0.03762216,25994.78215,1.297915004,33.66946808
10.2,2.323817901,0.038358373,25990.77015,1.317085307,34.14562011
10.4,2.56062952,0.03909597,25776.70975,1.345405061,34.6261304
10.6,2.172521013,0.039880855,25886.09396,1.360654112,35.17964232
10.8,2.260581696,0.040629709,26647.51004,1.344097972,35.72334865
11,2.426757396,0.04137265,28492.23291,1.291815409,36.52528826
11.2,2.297093248,0.042137978,30059.4382,1.251296399,37.1953869
11.4,2.470748047,0.042880354,32266.7693,1.199885212,38.14660076
11.6,2.395930612,0.043641532,33589.62255,1.174179605,38.81452009
11.8,2.101726327,0.044419311,34222.19991,1.174615271,39.56851698
12,1.424426082,0.045226081,33695.41217,1.208163204,40.20047875
12.2,2.880330542,0.045871426,32276.73232,1.267852607,40.5916452
12.4,3.017420871,0.046616567,30591.31083,1.343226677,40.93595637
12.6,3.028197552,0.047371266,28892.53165,1.429057252,41.25956507
12.8,3.071383657,0.048123513,27973.50613,1.482646905,41.50145454
13,2.739783869,0.048904121,27629.06666,1.515759174,41.882811
13.2,3.063020628,0.049635175,28727.8942,1.480904155,42.3851133
13.4,3.053022038,0.050391446,30330.02143,1.429492949,43.02579322
13.6,3.028896263,0.051148786,32153.95219,1.375903301,43.78850735
13.8,3.118618976,0.051897511,33640.22846,1.335819997,44.43463546
14,2.89920565,0.052669629,35104.51524,1.302707676,45.2115138
14.2,2.976463199,0.053419297,35344.73116,1.306628878,45.75522009
14.4,3.183358444,0.054159156,35335.48291,1.319699544,46.32943538
14.6,2.997185551,0.054928758,35305.99004,1.33625568,46.94941282
14.8,2.989679994,0.05568484,35085.33268,1.360654219,47.50619404
15,3.350312252,0.056413064,34727.85363,1.386359858,47.92023981
15.2,3.258874596,0.057175497,34026.59666,1.428185918,48.37350962
15.4,3.335301137,0.057925228,33397.05247,1.467397866,48.75486687
15.6,3.11921185,0.058697093,32710.20259,1.507045471,49.05123532
15.8,3.462392884,0.059426638,31980.53969,1.549307265,49.38138259
16,3.228852366,0.060199824,31554.06916,1.577191286,49.64397348
16.2,3.899451703,0.060904591,31322.44236,1.598104395,49.98937585
16.4,3.876987949,0.061661804,31455.35816,1.600718524,50.35220983
16.6,3.947596818,0.062415756,32302.62095,1.575012928,50.87739311
16.8,4.121251644,0.063158127,33616.42869,1.532315502,51.40475601
17,4.164438356,0.063906587,35698.36045,1.468269338,52.15112642
17.2,3.922587717,0.0646804,37960.81944,1.404658835,52.85391257
17.4,4.338066727,0.065404471,41336.18812,1.322749488,53.89556331
17.6,4.096216085,0.066178284,43229.81646,1.28528028,54.61469329
17.8,3.743840994,0.066960461,44486.64145,1.269595474,55.4384234
18,3.477060034,0.067736161,44133.38789,1.294865368,56.10525298
18.2,3.579247917,0.068483941,42332.77159,1.356297417,56.50840223
18.4,3.625342564,0.069235966,39201.04813,1.462605348,56.75791884
18.6,4.248158798,0.069944348,36311.3069,1.569784719,56.7927876
18.8,4.117663622,0.070709733,33465.53441,1.690470347,56.73721803
19,4.577186223,0.071430471,32486.65167,1.73839611,56.78516136
19.2,4.369407025,0.072201704,32458.17809,1.747981228,57.03903584
19.4,4.71425012,0.072931119,33947.61901,1.692648863,57.54896573
19.6,4.605361225,0.073694869,37375.54807,1.572834584,58.45114745
19.8,4.577080395,0.074452519,40830.72469,1.469576467,59.30865604
20,4.611125388,0.075205453,44631.14838,1.375032122,60.34812654
20.2,4.736581505,0.075951997,47418.28294,1.31882835,61.3036989
20.4,4.45484126,0.076735542,48840.47826,1.299222355,62.11871272
20.6,4.357584229,0.077512821,48965.61627,1.309678865,62.7463172
20.8,4.634280911,0.078269505,48371.99141,1.339305693,63.3848191
21,4.695744513,0.079050268,47570.4788,1.375467825,64.01242386
21.2,4.680753867,0.079844609,46846.58768,1.409015821,64.57465333
21.4,4.664930948,0.080646943,46296.73717,1.436899873,65.08894092
21.6,4.696474368,0.081453799,45918.60848,1.459119976,65.55746533
21.8,4.603364861,0.082278131,46008.44561,1.470447861,66.1828907
22,4.706372606,0.083096056,46254.49913,1.4769832,66.83446715
22.2,4.781124684,0.083924262,46607.49563,1.476983213,67.35747147
22.4,4.786901526,0.084766017,46973.21517,1.478290277,67.96328455
22.6,4.916497673,0.085606793,47584.25209,1.47349772,68.67696762
22.8,4.821719479,0.086473169,47747.93738,1.480904413,69.33181199
23,4.821675171,0.087340992,47917.05946,1.485696986,69.84827853
23.2,4.928829918,0.088209277,48084.49674,1.49266801,70.47261502
23.4,4.965347317,0.089091805,48218.88448,1.500074719,71.05227801
23.6,4.908790056,0.089990345,47985.86343,1.519680684,71.62976149
23.8,4.864696543,0.090896867,47812.71741,1.537543899,72.17564686
24,4.995113928,0.091799073,47487.31208,1.556714201,72.57334836
24.2,4.979271907,0.092721587,46965.59635,1.58416256,73.03206649
24.4,5.080600958,0.093644549,46618.20377,1.604639925,73.44393259
24.6,4.976668813,0.094592327,46519.71507,1.618146247,73.93751734
24.8,5.159433981,0.095527776,46543.50955,1.626860035,74.42674457
25,5.382917195,0.096469563,46708.35982,1.629909885,74.8397009
25.2,5.00225385,0.097466744,47104.83651,1.627731397,75.38558462
25.4,5.268946553,0.098424661,47443.61815,1.627295741,75.8715437
25.6,5.091046796,0.099426021,47904.90556,1.624245904,76.41089103
25.8,5.420062185,0.100399005,48340.0516,1.620324751,76.86089402
26,5.198115669,0.101423653,48876.41072,1.615096466,77.43510801
26.2,5.278655566,0.102435517,49350.55348,1.609868217,77.90145348
26.4,5.369996998,0.103456689,49887.88892,1.60463997,78.45932484
26.6,5.495408244,0.104485598,50368.61688,1.602461544,79.05424256
26.8,5.220270505,0.105555256,50877.87242,1.599411697,79.65460664
27,5.411328287,0.10660018,51555.38543,1.592005019,80.27349546
27.2,5.692964604,0.107648791,52053.87629,1.58721248,80.77470906
27.4,5.622250535,0.108734727,52770.98776,1.577627332,81.38923849
27.6,5.661228195,0.109823255,53765.88664,1.561942559,82.1214442
27.8,5.704359187,0.110922316,54713.31579,1.548000539,82.86999411
28,5.859674915,0.112023957,55250.35655,1.54233661,83.45837462
28.2,5.785629816,0.113154088,55722.52995,1.540158162,84.16442964
28.4,5.889419292,0.114282062,56089.48563,1.540158175,84.80728912
28.6,5.728945421,0.115441502,56297.86522,1.545386419,85.49700043
28.8,5.767081357,0.1165975,56427.51403,1.551050373,86.04288625
29,6.021278359,0.11774858,56771.00538,1.55410022,86.7108072
29.2,5.982126572,0.118933648,57241.46612,1.555407282,87.41904169
29.4,5.834110453,0.120138778,57698.29368,1.556278645,88.07933387
29.6,6.178882003,0.121318642,58098.14257,1.556714371,88.64810209
29.8,6.148865634,0.122538907,58452.87199,1.560199877,89.33018651
30,6.381446842,0.123751469,58630.80269,1.568042293,90.01227207
30.2,6.432865686,0.12498996,58542.49794,1.578934509,90.49932006
30.4,6.402012458,0.12624707,58361.42894,1.595054975,91.1585229
30.6,6.831537418,0.127481817,58268.12578,1.605511544,91.6455726
30.8,7.233637056,0.128731011,58531.30447,1.608561409,92.28952333
31,7.281723911,0.130019758,59236.07323,1.599847649,92.99122079
31.2,7.306540403,0.131323161,60179.08237,1.583727184,93.62972181
31.4,7.701985836,0.132611421,62057.34458,1.550179224,94.64413366
31.6,7.546468736,0.13395466,63632.85759,1.523602219,95.42428101
31.8,7.538869508,0.135300052,65362.34902,1.498767983,96.42888462
32,7.767275321,0.136641053,66704.62055,1.483954603,97.40624966
32.2,8.059666846,0.137990779,67530.15892,1.480469128,98.2670287
32.4,7.776996439,0.139397658,67943.79763,1.485261673,99.10492382
32.6,8.084341778,0.140773864,67878.23312,1.497025292,99.78483055
32.8,7.991137484,0.142194364,68166.04139,1.503124921,100.6150994
33,8.493766012,0.143583853,68239.78109,1.514888562,101.4769691
33.2,8.476179254,0.145026852,68184.17394,1.525345083,102.102395
33.4,8.392940303,0.146489316,68233.3799,1.535365909,102.8542132
33.6,8.465098125,0.147954683,68308.27141,1.546693817,103.6768554
33.8,8.79071205,0.149415566,68207.94096,1.561071571,104.4330342
34,8.624364936,0.150928565,68568.18693,1.562814308,105.0813404
34.2,8.768813662,0.152433,69123.91811,1.562814325,105.8974457
34.4,8.570882081,0.153986382,69556.65473,1.564992748,106.6721446
34.6,8.79510423,0.1555078,70145.18069,1.564121397,107.520938
34.8,8.821542022,0.157067303,70825.77475,1.561507271,108.3860742
35,8.701719326,0.158653608,71178.65625,1.563250013,109.0605313
35.2,8.999061793,0.160224095,71694.48743,1.564121424,109.9583568
35.4,8.78865381,0.16184906,72299.62366,1.562378649,110.796252
35.6,8.869512721,0.16346811,72793.8411,1.561942971,111.5306375
35.8,8.829872407,0.165112564,73384.7541,1.561942969,112.4491636
36,9.236898065,0.166739579,73860.97997,1.561943014,113.200984
36.2,9.263733445,0.168411779,74178.18773,1.567606968,114.0748372
36.4,9.135167011,0.170112713,74503.00579,1.571528152,114.8833138
36.6,9.284571181,0.171809473,74963.90681,1.57152817,115.6242373
36.8,9.403225197,0.173525779,75339.53326,1.57544938,116.5231514
37,9.45124051,0.175264678,75656.08208,1.578499206,117.2542682
37.2,9.626397792,0.17701135,76372.23803,1.575885096,118.21311
37.4,9.73756441,0.178780431,76892.04879,1.576320798,119.064082
37.6,9.808008651,0.180570353,77049.75934,1.582420446,119.7908408
37.8,9.954903064,0.182372557,77148.32219,1.591569921,120.6701424
38,9.774376103,0.184217787,77191.8989,1.599412295,121.3533157
38.2,9.82736042,0.186063669,77174.00142,1.610740203,122.1552559
38.4,9.827157059,0.187932142,77115.96964,1.621632416,122.8667596
38.6,10.03968962,0.189803333,77441.71058,1.624246572,123.5597414
38.8,10.09515804,0.191705227,78085.0992,1.622503826,124.4270571
39,10.07167735,0.193632142,78817.5439,1.617275564,125.1701591
39.2,10.12381561,0.195572729,79585.76404,1.613354375,126.113746
39.4,10.10863885,0.197537957,80358.00828,1.608561806,126.9832411
39.6,10.35107249,0.199503323,80790.20162,1.609433212,127.7405092
39.8,10.10819232,0.201525317,81311.36199,1.611175942,128.6764674
40,10.20934767,0.203541404,81363.03247,1.618582659,129.3476569
40.2,10.25814608,0.205581685,81108.15553,1.633396073,130.1190878
40.4,10.09004725,0.207658909,80946.45597,1.645595333,130.8120681
40.6,11.33466457,0.209649769,81000.47804,1.652566492,131.4582042
40.8,11.37929815,0.211751891,80540.80205,1.669994037,132.1653499
41,11.5768345,0.21386347,80377.91359,1.6800149,132.7319392
41.2,11.57326268,0.216011576,80774.05728,1.681321964,133.5033706
41.4,11.60458991,0.21817867,81082.70317,1.683500416,134.1832764
41.6,11.79712993,0.220355204,81304.38752,1.688293013,134.9296484
41.8,11.8392534,0.222564943,81986.19808,1.683500448,135.6139127
42,11.83816074,0.224800204,82801.78165,1.677836491,136.4637947
42.2,12.00575986,0.227045042,83346.25913,1.67522239,137.1491494
42.4,11.94482721,0.229329852,84120.03401,1.669122742,137.9565369
42.6,12.60603996,0.231582721,84890.5457,1.663023174,138.7094491
42.8,12.43873055,0.233921455,85812.75446,1.656487829,139.6595725
43,12.33208127,0.236278877,86628.59286,1.650823868,140.4342719
43.2,12.36836223,0.23864908,87537.02667,1.6460313,141.3789488
43.4,12.50685382,0.241035358,88170.08282,1.64515994,142.2015919
43.6,12.88301091,0.243427589,88855.54486,1.644288607,143.1658835
43.8,13.25999521,0.24584375,89295.14217,1.64472434,143.883928
44,13.44750499,0.248298686,89512.30754,1.650388315,144.7403486
44.2,13.29512711,0.250803989,89663.59594,1.655180874,145.4224326
44.4,13.49093909,0.253308149,90082.15782,1.658230718,146.4183213
44.6,13.70253628,0.255836272,90485.72376,1.659102121,147.1439916
44.8,13.25596822,0.258439887,91171.42623,1.656923629,148.0864857
45,13.63209755,0.2610069,91838.76851,1.653002476,148.8426657
45.2,13.79049771,0.263616372,92736.57771,1.647774233,149.8581669
45.4,13.78435339,0.266264645,93508.70474,1.643853037,150.7581701
45.6,13.84634781,0.268934292,94119.68158,1.641674603,151.5906196
45.8,14.07038524,0.271618431,94873.23081,1.639496187,152.6093897
46,13.8182487,0.274365699,95405.29495,1.639060472,153.4320301
46.2,14.07136286,0.277102211,96105.51372,1.638189125,154.4660551
46.4,13.78099101,0.279907595,96531.1529,1.640367537,155.375863
46.6,14.14378988,0.282691327,96863.72872,1.642981711,156.1887017
46.8,13.987202,0.285542576,96754.92953,1.653002533,157.0745392
47,13.93531705,0.288414464,96735.49903,1.660409235,157.782774
47.2,14.08785637,0.291299732,96457.01046,1.673044224,158.6348366
47.4,14.31019605,0.294208762,96159.49821,1.685243532,159.3408941
47.6,14.29569277,0.297164952,95784.4235,1.698749879,159.9467073
47.8,14.39087831,0.300142527,95500.42928,1.713127616,160.6669289
48,14.66888169,0.303135981,95231.70543,1.724891244,161.2248025
48.2,14.82887662,0.306168547,95358.20681,1.731862283,161.9515616
48.4,14.99052872,0.309231563,95954.54079,1.730119549,162.7131883
48.6,15.18790945,0.312322537,96821.45849,1.722712868,163.4584709
48.8,15.15509504,0.315461722,98371.06827,1.706156698,164.4826876
49,15.38736835,0.318612439,100031.6694,1.688729181,165.5483111
49.2,15.34540273,0.321815761,101271.0001,1.676965585,166.4472252
49.4,15.33584147,0.325048685,102576.6032,1.666509058,167.4834269
49.6,15.76754229,0.328280634,103401.5849,1.664330666,168.5337979
49.8,15.24689846,0.33161736,103735.713,1.66694474,169.2986876
50,15.67941983,0.334915081,103867.6311,1.674787187,170.2477263
50.2,15.6673446,0.338279891,103667.8625,1.684808027,170.9003922
50.4,15.75747846,0.341670619,103302.3253,1.697878699,171.6347783
50.6,15.84594488,0.345095619,103431.7543,1.704414041,172.5271559
50.8,15.71418772,0.348571651,103446.1333,1.710949357,173.2103291
51,16.03532643,0.352048265,103506.9474,1.718356104,174.0482286
51.2,15.48555922,0.355625955,103515.4008,1.724455682,174.6801874
51.4,15.96374792,0.359161295,103389.4722,1.733605203,175.3840685
51.6,16.4377759,0.362732689,102924.0453,1.747982988,176.0759634
51.8,16.53285678,0.366368819,102837.5418,1.754518331,176.6360157
52,16.60798465,0.370061361,103323.5516,1.753211276,177.4401353
52.2,16.8077613,0.373763259,103901.5005,1.749725793,178.1320284
52.4,16.5346893,0.377519351,104741.6543,1.743190432,178.9492206
52.6,17.11921255,0.381266898,106011.8362,1.732298286,179.9483822
52.8,17.56079579,0.385062933,106690.5497,1.72924852,180.7034735
53,17.62135396,0.388926378,106758.7916,1.737090926,181.4890705
53.2,17.94409025,0.392808562,106788.5398,1.743190608,182.1144994
53.4,18.14923215,0.396738767,106848.8468,1.749290277,182.8063928
53.6,18.72541462,0.400680209,107005.4292,1.754082925,183.5756506
53.8,19.12790932,0.404674432,107440.6402,1.753211597,184.2533807
54,19.08082018,0.408742783,108575.6889,1.743190752,185.2045948
54.2,18.96890561,0.412856921,109574.8706,1.734912654,186.007624
54.4,19.25753224,0.416981996,110823.6733,1.724020471,186.9566619
54.6,19.13064627,0.421180197,112485.9098,1.708771351,188.0941951
54.8,19.47743048,0.425384374,113538.6115,1.700493307,188.9865753
55,19.55579108,0.429651261,114844.0173,1.690908165,190.1513506
55.2,19.51946518,0.433969844,115686.7558,1.686115586,191.0709666
55.4,19.87952516,0.438301568,116425.478,1.684372874,192.0984557
55.6,19.84401646,0.442706988,116621.2326,1.690908204,193.0801786
55.8,19.95143481,0.44714578,116823.1522,1.696136484,193.886479
56,20.27740227,0.451612405,117090.9771,1.702236167,194.8583982
56.2,20.4047507,0.456139111,117520.3466,1.703978939,195.6799524
56.4,20.7572962,0.460694017,117775.4217,1.708335871,196.5450931
56.6,20.94030798,0.465307501,118397.8805,1.708771583,197.6019992
56.8,21.21721675,0.469960272,119079.8153,1.706593173,198.4802141
57,21.51655542,0.474658083,119502.7561,1.708771658,199.4728358
57.2,21.87239545,0.479398711,119958.6789,1.709207392,200.317274
57.4,22.17088805,0.484191441,121117.4192,1.701800717,201.3752726
57.6,21.89846762,0.489075717,122474.011,1.693086913,202.5890756
57.8,22.12049166,0.49397138,123269.596,1.690037122,203.5239495
58,22.56106411,0.498899573,124602.6872,1.682630462,204.7584626
58.2,22.63099722,0.503905557,125301.8053,1.683066161,205.8851025
58.4,22.67432996,0.50896384,125614.721,1.687423052,206.8929764
58.6,22.79660078,0.514066883,125980.5996,1.690037201,207.8115046
58.8,22.99697861,0.519215253,126914.834,1.687423093,209.0351196
59,23.18238998,0.524416666,127405.8716,1.688294498,209.9819778
59.2,23.6411961,0.529649423,128403.9575,1.684373355,211.2339248
59.4,23.58476623,0.534974011,129478.5429,1.678709388,212.3856241
59.6,23.51420067,0.54035312,130427.6565,1.67435249,213.4338119
59.8,23.86744279,0.545753965,131461.9854,1.670867025,214.7402376
60,23.90073654,0.551233549,132387.4106,1.667381524,215.8254727
60.2,24.02709491,0.556761088,133910.5692,1.65997483,217.2452137
60.4,24.5390342,0.562314774,135058.9255,1.656489368,218.5135042
60.6,24.4584528,0.567969413,135958.2671,1.654746605,219.6205306
60.8,24.61968698,0.573662382,136721.8706,1.656489381,220.9313125
61,24.7958703,0.579411398,137115.6633,1.659974915,221.9620696
61.2,24.64545656,0.585243122,137423.599,1.665638856,223.1900395
61.4,25.01026118,0.591094241,137538.5908,1.672609923,224.3362948
61.6,25.11993567,0.597023473,137162.9075,1.685244918,225.4716525
61.8,25.31353294,0.603005874,137026.673,1.693087343,226.3716583
62,25.52374092,0.609047085,137116.8712,1.700058393,227.5146442
62.2,25.53449626,0.61516425,137076.7731,1.70702942,228.4081106
62.4,25.61172283,0.621337775,137680.3665,1.707900809,229.4955251
62.6,25.90167873,0.627557136,139052.366,1.70136551,230.8270114
62.8,26.04038042,0.633850569,140011.058,1.697880017,231.8784702
63,26.82809281,0.640157823,140904.069,1.697008732,233.1576618
63.2,26.96677438,0.646577865,141693.8143,1.69700875,234.4008887
63.4,27.1636166,0.6530579,141557.142,1.706158245,235.4261987
63.6,27.07125612,0.659624997,141187.9542,1.716614773,236.2553782
63.8,27.20575155,0.66624086,141149.8119,1.724892882,237.328629
64,27.54134145,0.672907956,141239.0237,1.730121192,238.2079348
64.2,27.39659548,0.679678433,141586.1678,1.73360669,239.2800931
64.4,27.93409997,0.686465205,142187.3596,1.733606756,240.3293778
64.6,27.81924879,0.693369666,142842.816,1.732299677,241.3089205
64.8,28.14565425,0.700309973,143146.6838,1.736220919,242.4159516
65,28.54351571,0.707314612,143348.2195,1.74014217,243.2963477
65.2,29.06851093,0.714379991,143590.4252,1.744934815,244.354348
65.4,29.17715754,0.721548,143917.716,1.748420343,245.3197292
65.6,29.22512878,0.728792675,144258.124,1.751034485,246.167434
65.8,29.47668655,0.736094623,145263.035,1.747984694,247.3572733
66,29.55870607,0.74348294,146222.2801,1.743627814,248.3542517
66.2,29.99888027,0.750918115,146978.7195,1.742756491,249.5135846
66.4,29.84071346,0.758473573,148000.9874,1.738399583,250.6445808
66.6,30.03571499,0.766078009,148726.4105,1.736656852,251.6219486
66.8,30.13596892,0.773766033,149543.1224,1.735785487,252.832488
67,30.42817451,0.781516745,150550.6108,1.733171389,254.0484776
67.2,30.79266585,0.789339767,151474.4292,1.730121611,255.0955815
67.4,31.14467951,0.79724233,151756.3744,1.734478546,256.1459544
67.6,31.72853314,0.805206626,152208.8453,1.737528442,257.3216329
67.8,31.90185372,0.81328224,152515.993,1.7401426,258.2717605
68,32.33859249,0.821418907,152143.8438,1.750599195,259.2883571
68.2,32.27338651,0.829675514,152274.2744,1.754956081,260.1556729
68.4,32.91369725,0.837961435,153265.5175,1.751034957,261.2692445
68.6,32.99970921,0.846372673,154458.4226,1.746242388,262.5342648
68.8,33.41478882,0.854843503,155581.9445,1.742756926,263.7709594
69,33.46836428,0.863427034,156867.8558,1.736221596,264.8551052
69.2,33.41721842,0.872104648,158111.0077,1.7318647,266.2203653
69.4,33.55802269,0.880854847,158388.5196,1.735785921,267.2881687
69.6,33.88163583,0.889679045,158552.1389,1.739707165,268.2295819
69.8,33.88861178,0.89866113,158809.6191,1.743628371,269.4107018
70,34.248761,0.907661869,158638.9868,1.750599445,270.2671266
70.2,34.57067654,0.916710124,158053.0265,1.762798785,271.2357799
70.4,34.62664618,0.925915431,157984.3806,1.769334133,272.1641146
70.6,35.23106962,0.935171964,157666.6709,1.778047994,272.9301073
70.8,35.33396195,0.944559621,157300.0613,1.788504552,273.8224858
71,35.36869621,0.954046849,157159.3971,1.795039898,274.5492451
71.2,36.0387248,0.963580976,157346.4245,1.799396876,275.4525276
71.4,36.65638447,0.973214233,157957.4963,1.799396954,276.3776021
71.6,36.90755196,0.982972385,159142.1978,1.793733026,277.4671974
71.8,36.92768225,0.992846009,160767.8484,1.782840797,278.5175675
72,37.59515602,1.002769527,163098.7097,1.766720374,279.891554
72.2,38.02993023,1.012810679,165416.7831,1.750164232,281.1565786
72.4,38.11150783,1.022979536,167823.1752,1.734043737,282.615546
72.6,38.369244,1.033237072,170155.6057,1.720101709,284.2107145
72.8,38.68845876,1.043592996,171715.9205,1.71225934,285.4931712
73,38.82400306,1.054067057,173706.3705,1.702238502,287.1842226
73.2,39.21548272,1.064626802,174787.234,1.698753034,288.4579634
73.4,39.260413,1.075318956,175398.2858,1.70006011,289.8373897
73.6,39.38011742,1.086112737,176203.6641,1.700931505,291.4162136
73.8,39.40340709,1.097022079,177064.9412,1.70006013,292.6725156
74,40.10063111,1.107989841,177620.4576,1.703981419,294.120595
74.2,40.03496743,1.11912575,178326.0376,1.707031239,295.5937265
74.4,40.5651225,1.130328251,178748.4413,1.711823888,296.907784
74.6,40.70385244,1.141672897,179132.5053,1.715309421,298.0638455
74.8,41.21485825,1.153103238,178396.0788,1.729251553,299.2940041
75,42.00257326,1.164627523,178372.9223,1.735351301,300.3520115
75.2,42.16867188,1.176314756,178813.1495,1.738401147,301.6976644
75.4,42.5125887,1.188105941,179952.0193,1.734479986,303.0346015
75.6,42.78169551,1.200021114,181435.846,1.727944679,304.3584623
75.8,43.33415888,1.212034557,184347.9664,1.711824232,306.1900782
76,43.47358937,1.224200125,186537.1355,1.700932012,307.7111538
76.2,43.68612963,1.236482297,188563.4392,1.693525318,309.510077
76.4,44.11055873,1.248871772,190159.3197,1.689168471,311.108518
76.6,44.48760026,1.261389454,191018.7985,1.689604208,312.5239067
76.8,44.62113485,1.274051294,191792.8884,1.692218364,314.2509156
77,45.01475648,1.286820587,191859.7927,1.698318066,315.4908799
77.2,45.13661627,1.299738797,191873.034,1.706596182,317.0391952
77.4,45.03325074,1.312803975,191700.805,1.71487428,318.3761259
77.6,45.81323183,1.325933212,191586.5574,1.723152476,319.8340151
77.8,46.48100513,1.339203032,191275.2237,1.731430652,320.9541285
78,47.11717876,1.352608454,191008.2721,1.738837464,322.0557184
78.2,47.45333504,1.366171404,191047.5544,1.744065777,323.4057312
78.4,48.05539408,1.379850439,190895.6013,1.751036882,324.6348021
78.6,48.58845714,1.393672204,191801.834,1.751036948,326.0970465
78.8,48.59131134,1.407673042,192794.1089,1.749294191,327.2977806
79,48.92987277,1.421788996,195023.5643,1.74058044,329.0095373
79.2,49.10220888,1.436059505,196234.0333,1.738402014,330.2712905
79.4,49.43407686,1.450461264,197142.9019,1.739273435,331.6648873
79.6,49.45512268,1.465031289,197750.0575,1.742758958,333.1445569
79.8,49.89580723,1.479715795,197690.8581,1.749294359,334.2254419
80,50.34976455,1.4945469,197219.9581,1.76018666,335.5024549
80.2,51.09206004,1.509505182,197492.5928,1.76323658,336.5441191
80.4,51.25594596,1.524657541,199022.1879,1.757572635,338.008537
80.6,52.03725109,1.539915193,200806.3977,1.750601694,339.6592856
80.8,52.24679424,1.555369598,202611.2866,1.742759305,341.0855679
81,53.03636052,1.570935188,205212.3413,1.730560085,342.953147
81.2,52.93339283,1.586725103,207076.7994,1.724024728,344.7193776
81.4,53.47194282,1.602624783,207830.3933,1.725331863,346.2437301
81.6,53.64731424,1.618711943,208326.8913,1.727510335,347.5131108
81.8,54.43262438,1.634914169,209007.7041,1.72968888,349.1998175
82,55.00267599,1.651295698,209302.5093,1.733174469,350.4550402
82.2,55.2112103,1.667869166,210392.9974,1.732303116,352.1406465
82.4,55.97151158,1.684567286,211413.6221,1.731431829,353.6976907
82.6,56.09356728,1.701481679,212231.3276,1.730996156,355.0738506
82.8,56.40506722,1.718551575,213419.9633,1.729253435,356.7921474
83,57.15282242,1.735759841,214535.2908,1.726639386,358.2729214
83.2,57.18338477,1.753195625,214618.8323,1.732303362,359.9138501
83.4,57.99341075,1.770747259,214720.8148,1.73709605,361.3652056
83.6,58.84246643,1.788472275,215737.5858,1.736224774,363.0617203
83.8,59.39399066,1.80639805,216207.9215,1.738403292,364.418275
84,59.87983615,1.824508852,217082.8264,1.740146112,366.0330646
84.2,60.3681458,1.842801316,218462.0498,1.737096342,367.4190374
84.4,60.74091521,1.861286484,220285.2489,1.732303798,369.1569485
84.6,61.36046645,1.879938481,221895.8372,1.730125423,370.9994654
84.8,61.66835744,1.898801706,223203.5002,1.728382701,372.5118286
85,62.08923631,1.917845731,225146.1438,1.723154472,374.4622132
85.2,62.5400013,1.937078937,226263.1436,1.723154527,376.2622318
85.4,62.87439355,1.956514081,227669.6616,1.720976118,378.0219335
85.6,63.29434926,1.976138161,229482.826,1.715312198,379.6781261
85.8,64.15388043,1.995925938,231165.0898,1.71269816,381.6928043
86,64.22142299,2.015972731,232623.6414,1.710084029,383.3184817
86.2,64.41441677,2.036211402,234700.1769,1.705291462,385.422494
86.4,64.78521538,2.056639879,235813.5786,1.705727198,387.2148843
86.6,65.1401921,2.077274803,235550.1257,1.714005356,388.6782179
86.8,65.63059128,2.098106767,235396.732,1.72228353,390.4444618
87,66.1201262,2.119148132,235125.5714,1.730126015,391.8206306
87.2,66.90546883,2.140378382,235399.6463,1.735790084,393.5879682
87.4,67.21294403,2.161858179,236067.4904,1.738404265,395.2572356
87.6,68.10955706,2.183618887,237528.855,1.735354542,396.8284494
87.8,68.3413582,2.205429853,240644.8356,1.724026623,398.9913004
88,69.12988693,2.227528568,243727.9007,1.71313446,401.2707502
88.2,69.55106279,2.249933678,245469.7435,1.709213298,403.0587845
88.4,69.93150108,2.27245408,247309.7405,1.705292132,405.076724
88.6,70.32809917,2.295256385,248971.4091,1.701806657,406.937761
88.8,70.58671247,2.318297542,249275.3524,1.707470665,409.0101768
89,71.3966676,2.341527813,249256.8501,1.713570428,410.5388958
89.2,72.15090766,2.364995689,249345.3562,1.720541566,412.4304485
89.4,72.94915408,2.388696028,249265.3043,1.728384091,414.0910092
89.6,73.51883349,2.412651907,248028.3991,1.743633328,415.6709352
89.8,74.12503934,2.436845683,247899.4173,1.750604451,417.0383897
90,74.58411685,2.461293793,247996.7582,1.756704176,418.6847781
90.2,75.03983126,2.485987806,248572.4792,1.758446995,420.0849178
90.4,75.60852436,2.510921314,249780.1632,1.757139994,421.7825211
90.6,76.23784178,2.536100683,253031.5238,1.744505046,424.0608789
90.8,76.70507101,2.561545352,255118.566,1.737534055,425.7693757
91,77.25037509,2.587239651,258512.6316,1.725334785,428.1839306
91.2,78.29258549,2.613154099,260953.3143,1.718799552,430.4808211
91.4,78.86606179,2.639364384,262928.791,1.712699952,432.1904096
91.6,79.51013261,2.665832579,264694.9443,1.710085886,434.5123522
91.8,80.40180388,2.692547705,265807.9663,1.711393065,436.7351469
92,80.72584885,2.719574133,265917.8164,1.716621394,438.3662804
92.2,81.74042477,2.746819441,266808.4187,1.719235661,440.4419817
92.4,82.14914673,2.774384517,268328.4729,1.71836433,442.4348627
92.6,82.37666325,2.802240249,270767.6489,1.713571763,444.7796814
92.8,83.15426777,2.830334031,273309.6645,1.707036499,446.8455715
93,83.69498795,2.858727973,276523.4969,1.698758441,449.4486282
93.2,84.36613227,2.887397463,279050.3719,1.692223158,451.5635517
93.4,84.73141698,2.916378187,280360.2285,1.693094584,453.8048597
93.6,85.30939551,2.945633939,281508.6743,1.695273107,456.2510165
93.8,86.15242145,2.975163461,282314.624,1.697451663,458.1719939
94,86.38294143,3.005036301,283375.5053,1.699630141,460.5734698
94.2,87.45357098,3.035145285,284618.3691,1.699194583,462.5478428
94.4,87.88759417,3.065605135,286502.4601,1.69788756,465.382983
94.6,88.59580405,3.096350204,287710.0293,1.697887648,467.4052904
94.8,89.29066861,3.127405159,288241.2298,1.701373257,469.3709387
95,90.15002483,3.158759664,288976.2375,1.705294581,471.7593543
95.2,91.29520063,3.190407497,288701.424,1.714879922,473.9178719
95.4,91.53701118,3.222442042,288817.3283,1.720543933,475.5620792
95.6,92.25660499,3.254762076,289076.5571,1.727515072,477.7412874
95.8,92.72933535,3.28742556,289032.4323,1.734486187,479.4334407
96,93.1878863,3.320418185,289293.0191,1.741021618,481.4982416
96.2,94.13086717,3.353705501,290869.2326,1.740150344,483.7580877
96.4,94.82781404,3.387346094,292146.2842,1.738843356,485.4546041
96.6,95.60697785,3.421318398,295412.4661,1.729258246,488.0685667
96.8,96.26226599,3.455641392,299596.6453,1.715751899,490.912431
97,97.30724615,3.490279651,302912.984,1.705731126,493.2997629
97.2,98.01893336,3.525291306,305741.4782,1.699631535,496.0433849
97.4,98.45051206,3.560675875,307860.07,1.69701744,498.6377259
97.6,99.50363481,3.596368817,308635.9638,1.699631713,500.6556848
97.8,100.5085017,3.632424018,310666.9341,1.698324758,503.4799464
98,101.1260571,3.668870853,311731.2448,1.699631907,505.5327635
98.2,101.9080957,3.705671478,312807.1947,1.70268184,508.0693654
98.4,102.4266433,3.742861764,313741.0786,1.706603125,510.4566855
98.6,103.1936055,3.780406763,314015.7765,1.714009971,512.8505517
98.8,103.7793461,3.818342961,312836.3311,1.726645094,514.5645021
99,104.4697343,3.856652133,310594.5418,1.745815602,516.4495234
99.2,105.2149085,3.895342191,308395.6733,1.762371969,517.7309085
99.4,106.255863,3.93439849,306672.8879,1.776749917,519.2313106
99.6,107.0865079,3.973863165,305098.2042,1.790692149,520.8210539
99.8,107.6586434,4.013743968,304660.3535,1.797227595,522.1514687
100,108.6761405,4.053991601,306357.5327,1.793742191,524.1846833
100.2,109.667812,4.094645434,309053.4212,1.784592792,526.0609971
100.4,110.4790877,4.13572153,312500.9024,1.773264912,528.3382764
100.6,111.3185525,4.177208246,316416.2709,1.760629959,530.9751246
100.8,112.1645993,4.219111186,320550.364,1.74668793,533.3047089
101,112.6681999,4.261461193,324168.0385,1.737538467,536.0701213
101.2,113.6146653,4.304202923,327148.0337,1.73187459,538.7418401
101.4,114.8710321,4.347350691,329021.3186,1.731003359,541.1389878
101.6,115.514039,4.39097855,330726.2948,1.730132054,543.3149325
101.8,116.4835663,4.435019831,331787.703,1.733182014,545.7730924
102,117.4937431,4.479500533,332477.9406,1.73623198,547.7289462
102.2,118.4980319,4.52442858,333786.2213,1.737539178,550.2383193
102.4,119.1083465,4.569838035,336662.957,1.731003875,552.7727416
102.6,120.1822966,4.615668501,339583.3873,1.725775702,555.7223132
102.8,120.9204423,4.661984891,341738.5787,1.722290256,558.0213855
103,121.9011714,4.708748214,345965.6646,1.711833768,561.1910544
103.2,122.9233767,4.755978244,349429.472,1.703555742,563.7941324
103.4,123.9471688,4.803682504,352513.2781,1.69832756,566.7208222
103.6,124.7440167,4.851883357,355640.0909,1.693970735,569.9732967
103.8,125.3986836,4.900579378,357767.4581,1.692228045,572.5306022
104,126.3183676,4.949744483,358598.6651,1.69745646,575.5466374
104.2,127.3858944,4.99939232,357607.1304,1.707913198,577.5253796
104.4,128.0577772,5.049568985,355879.1575,1.722291121,579.7656126
104.6,128.8716841,5.100239057,354485.7385,1.735797678,582.1845457
104.8,129.594098,5.151425307,353310.5514,1.747125764,584.3637645
105,130.6928817,5.203097177,353378.9536,1.751918513,586.2161122
105.2,131.7200735,5.255556843,355300.9445,1.75017587,588.8900179
105.4,132.7197993,5.308285407,356245.0989,1.752354454,591.2708222
105.6,133.5279335,5.361292323,357952.2227,1.750611785,593.451133
105.8,134.6729185,5.415074305,360710.207,1.746690694,596.224196
106,135.4646347,5.469423436,363136.8147,1.743205253,598.5875598
106.2,136.6214971,5.524290437,366399.1001,1.737977085,601.5513027
106.4,137.9706532,5.579691948,370808.0773,1.727520629,604.5619055
106.6,138.8477021,5.635685958,374317.176,1.721421041,607.7958625
106.8,140.0994512,5.692214102,376664.5789,1.718371344,610.4120283
107,140.7627486,5.749354959,377551.1894,1.722292658,613.3278168
107.2,141.9478349,5.807030238,376911.3849,1.730570959,615.3948225
107.4,142.7904491,5.865311024,375574.9003,1.742334763,617.5293732
107.6,144.1049894,5.924141558,375108.9633,1.751484469,620.007161
107.8,145.1759471,5.98358161,375134.9903,1.756712912,621.9281588
108,146.2625993,6.043617734,376047.2656,1.759762895,624.500737
108.2,147.2710399,6.104263056,377861.2512,1.758891634,627.2182289
108.4,148.6882453,6.165486765,379033.1091,1.758891808,629.1969865
108.6,150.138594,6.227322982,380111.3587,1.76107045,631.8425799
108.8,151.167517,6.28981194,381208.6669,1.763249042,634.4576533
109,152.4755631,6.352907222,381873.2721,1.76586336,636.4908859
109.2,153.4535936,6.416661159,382836.0263,1.768913332,638.9545015
109.4,154.4647633,6.481052432,384251.522,1.769349151,641.290637
109.6,155.6636408,6.546075923,385893.846,1.768477913,643.5091005
109.8,156.8674008,6.611751863,387609.9254,1.768478062,646.2549313
110,157.7835231,6.678109503,389840.5433,1.765864026,648.9865887
110.2,159.0726675,6.745105249,392329.6755,1.761071553,651.4131711
110.4,159.9403778,6.812806255,395739.2584,1.753664886,654.2134735
110.6,161.1146264,6.881164186,400341.3768,1.743208393,657.5978103
110.8,162.3319791,6.950205508,404898.3832,1.732751903,660.540859
111,163.5326013,7.019941908,410282.3312,1.721859714,664.2586169
111.2,164.8743856,7.090368279,414460.6686,1.713581707,667.2365393
111.4,166.2908495,7.161496245,417840.5829,1.709224942,670.5435239
111.6,167.8218808,7.233330321,420442.7898,1.708353737,674.0934937
111.8,168.8674814,7.305922921,421904.2283,1.709225252,676.8447707
112,170.2212748,7.379221512,423175.7094,1.712275262,680.2934028
112.2,171.4070851,7.45326934,422688.9406,1.720117893,682.692744
112.4,172.8088427,7.52804465,421773.9122,1.730574703,685.3819265
112.6,173.896355,7.603595159,420849.8148,1.741467177,688.1070557
112.8,175.0743281,7.679897647,418844.1138,1.756280903,690.5194728
113,176.5530092,7.756943983,417474.0874,1.767173418,692.4655509
113.2,177.9443101,7.834771067,416029.9219,1.778937328,694.7069083
113.4,179.0919975,7.913398661,415168.7649,1.787651341,696.7423231
113.6,180.4257083,7.992802034,415138.9435,1.792444135,698.6371831
113.8,181.7850541,8.07300121,417682.3264,1.788523061,701.3732222
114,182.9306994,8.154022373,421758.6995,1.779373634,704.4263256
114.2,184.1061321,8.235855363,425688.0152,1.770224209,707.0708251
114.4,185.4011014,8.31850143,431471.8218,1.756282165,710.4072316
114.6,187.1056326,8.401946689,436384.0549,1.7471328,713.9909924
114.8,188.5939651,8.486246752,438283.7728,1.747132981,716.5723126
115,190.3987824,8.571369747,437696.6612,1.75671847,719.3279784
115.2,191.8029114,8.657378559,437012.333,1.76499683,721.4734543
115.4,193.1312801,8.744257213,434301.1006,1.781553372,723.9381833
115.6,194.3755769,8.832015066,433418.0764,1.789396023,725.8777192
115.8,195.8075448,8.920640288,434644.5561,1.789831896,728.0972888
116,197.5701182,9.010130861,437580.5974,1.785910867,731.0360098
116.2,198.7059579,9.100568183,441759.6952,1.778068512,734.2176897
116.4,200.4964992,9.191864338,445044.1511,1.771969012,736.6432109
116.6,202.0217985,9.284097904,448183.8827,1.768483646,739.848875
116.8,203.3159264,9.37727588,448891.5559,1.77284075,742.6808
117,204.9015946,9.471367888,450761.3787,1.771969558,745.1836762
117.2,206.3998553,9.566411849,452649.425,1.771969743,748.2030199
117.4,207.7724799,9.662420062,454752.6688,1.770662829,751.1134039
117.6,209.5679422,9.759360739,458479.0801,1.763256242,753.9464378
117.8,211.3316709,9.857277875,464339.6476,1.750185617,757.7579327
118,212.9082632,9.95619306,468165.3386,1.742343304,760.8415672
118.2,214.4697393,10.05610301,473461.8989,1.731015429,764.9799403
118.4,216.5845178,10.1569748,479707.4136,1.717509143,769.1259595
118.6,217.7875024,10.2589294,484044.5249,1.710102475,772.5157631
118.8,219.4980799,10.36186965,490657.5926,1.699210305,777.1673466
119,221.3464431,10.46583383,495937.9679,1.691803708,780.8426481
119.2,222.6785746,10.57088182,501969.3809,1.685268441,785.3449418
119.4,224.7293743,10.67693048,505109.863,1.685704376,789.303551
119.6,226.4409471,10.78407044,507859.3479,1.687447358,793.6446004
119.8,227.9071968,10.89230549,507650.478,1.695290045,796.8437365
120,229.7995893,11.00159557,506311.5453,1.70705404,800.4983424
120.2,231.7516413,11.11197913,505914.4357,1.714025397,803.5100846
120.4,233.4949301,11.22348765,504675.3997,1.724046599,806.6917978
120.6,234.7751602,11.33615161,502994.2192,1.734503444,809.3940695
120.8,236.6095041,11.44990531,501000.8372,1.747138834,812.5147696
121,238.2051624,11.56482007,498827.6057,1.760209894,815.3739575
121.2,240.3416347,11.68084823,496337.6211,1.772845327,817.4464686
121.4,241.7530681,11.70002344,494180.4976,1.786352065,820.2980196
121.6,242.872553,11.69993754,495957.9726,1.786352204,822.8106938
121.8,243.9238939,11.69985679,499782.05,1.781123986,826.285487
122,244.6345145,11.69980183,504160.2448,1.773281552,829.3059016
122.2,245.041811,11.69976982,511109.9539,1.760210731,833.3538003
122.4,245.7757004,11.6997131,518660.8118,1.745397166,837.4747143
122.6,246.0791187,11.69968895,523285.0508,1.738426072,840.9385835
122.8,246.4033126,11.69966323,527955.9733,1.733633459,845.0703784
123,246.6444041,11.6996438,532314.9379,1.729712227,849.2315922
123.2,246.9366036,11.6996205,536509.3918,1.724483914,852.7749987
123.4,247.3804652,11.69958573,539131.1457,1.724919664,856.6714454
123.6,247.3639388,11.69958579,540838.3466,1.728405231,860.7868843
123.8,247.8181883,11.69955023,541297.5126,1.73319794,863.9282348
124,248.1,11.69952772,540333.7466,1.742783283,867.3605042
124.2,248.259651,11.69951445,538035.2998,1.754547092,869.7423892
124.4,248.3993574,11.69950269,535328.0052,1.768053681,872.403212
124.6,248.8124711,11.69947024,532873.4976,1.781124608,875.1686472
124.8,248.7676898,11.69947244,530409.3372,1.79419548,877.8065785
125,249.0162605,11.69945244,528550.4009,1.804216517,879.786403
125.2,249.3687095,11.69942458,527474.0596,1.812930479,882.3175733
125.4,249.5965045,11.69940616,528229.6297,1.815980381,884.8400164
125.6,249.5184822,11.69941087,529806.3029,1.815980373,887.187024
125.8,249.7296568,11.69939371,531558.1552,1.816416097,890.1017289
126,249.7796125,11.69938874,531725.3489,1.820773064,892.7037076
126.2,249.9060224,11.69937799,530999.4045,1.826872824,894.6748097
126.4,250.115535,11.69936094,529496.0586,1.83558677,896.6666185
126.6,250.2394519,11.69935038,525082.8437,1.852578927,898.2421935
126.8,250.1597675,11.69935522,522783.9647,1.862599924,899.5170291
127,250.3111083,11.69934258,522083.8568,1.868699688,901.3344988
127.2,250.7341944,11.69930938,522310.3904,1.87131392,902.8643199
127.4,250.8539562,11.69929913,522383.4424,1.874363808,904.5673804
127.6,251.0942167,11.69927976,525639.1087,1.868699794,906.9667034
127.8,251.2239508,11.69926875,528344.0387,1.863907163,909.0162574
128,251.161718,11.69927227,530169.2843,1.862600067,911.3207715
128.2,251.4593192,11.69924857,532047.9086,1.859985933,913.3104032
128.4,251.2807428,11.69926089,534485.3508,1.856500347,915.667214
128.6,251.5126931,11.69924215,534768.5641,1.859114553,917.7549086
128.8,251.4895185,11.69924272,534483.2648,1.863907202,919.7456143
129,251.5012469,11.69924064,534901.7535,1.866085695,921.3822055
129.2,251.7805657,11.69921832,533700.1255,1.873928256,922.985028
129.4,251.787308,11.69921662,530766.7702,1.88656344,924.0724551
129.6,251.7151028,11.6992209,528487.2394,1.896584442,924.9223447
129.8,251.5822328,11.69922976,526596.7301,1.90573404,926.0762314
130,252.0119672,11.69919606,524669.1077,1.914448016,927.0688818
130.2,252.0544436,11.69919166,524302.2342,1.917497894,927.9917801
130.4,252.2797457,11.69917342,527463.1786,1.910091096,929.6915752
130.6,252.2673744,11.69917317,532500.4871,1.89789161,931.9699401
130.8,252.2616513,11.69917241,535872.1353,1.89048478,933.73837
131,252.5600837,11.69914864,540817.1841,1.879592415,936.2902346
131.2,252.2975736,11.69916732,545401.0595,1.869571384,938.5141132
131.9,252.7289642,11.62484202,1.7977E+308,1.855193469,0
132.1,252.5083192,11.50786777,1.7977E+308,1.764568679,0
132.3,252.3583115,11.39088818,1.7977E+308,1.602054066,0
132.5,252.0063645,11.27392386,1.7977E+308,1.365906819,0
132.7,252.123116,11.15692408,1.7977E+308,1.06832649,0
132.9,251.7985929,11.03995769,1.7977E+308,0.722819579,0
133.1,251.4134049,10.92299589,1.7977E+308,0.459223518,0
133.3,250.9833415,10.80603749,1.7977E+308,0.254010724,0
133.5,251.099262,10.68903777,1.7977E+308,0.130708778,0
133.7,250.7672597,10.57207195,1.7977E+308,0.037034153,0
133.9,250.585673,10.45509474,1.7977E+308,0.016556445,0
134.1,250.3118424,10.33812451,1.7977E+308,0.017427836,0
134.3,249.8493691,10.22116856,1.7977E+308,0.013506573,0
134.5,249.8107188,10.10418054,1.7977E+308,0.006535438,0
134.7,249.5086334,9.987212454,1.7977E+308,0.006535438,0
134.9,249.5173516,9.870220848,1.7977E+308,0.010021005,0
135.1,249.1271775,9.753259426,1.7977E+308,0.00740683,0
135.3,248.7935132,9.636293729,1.7977E+308,0.002178479,0
135.5,248.824669,9.519300424,1.7977E+308,0.002614175,0
135.7,248.2425281,9.402353529,1.7977E+308,0.007842525,0
135.9,248.4265926,9.285348654,1.7977E+308,0.008278221,0
136.1,247.9317094,9.168395156,1.7977E+308,0.013506571,0
136.3,247.5606489,9.051432288,1.7977E+308,0.017863529,0
136.5,247.6549627,8.934434204,1.7977E+308,0.02396327,0
136.7,247.4816863,8.817456369,1.7977E+308,0.032241491,0
136.9,247.1621494,8.700489603,1.7977E+308,0.038776927,0
137.1,246.6680972,8.583536042,1.7977E+308,0.038776926,0
137.3,246.6842946,8.466543869,1.7977E+308,0.039212622,0
137.5,246.4611567,8.349569808,1.7977E+308,0.03616275,0
137.7,245.9687666,8.232616121,1.7977E+308,0.027884529,0
137.9,246.0597563,8.115618289,1.7977E+308,0.020477701,0
138.1,245.858225,7.998642592,1.7977E+308,0.020042005,0
138.3,245.4231757,7.881684567,1.7977E+308,0.018734918,0
138.5,245.3546085,7.764698808,1.7977E+308,0.019606309,0
138.7,244.9253763,7.647740343,1.7977E+308,0.027448832,0
138.9,244.6764767,7.53076823,1.7977E+308,0.033112876,0
139.1,244.5995992,7.413783101,1.7977E+308,0.034419963,0
139.3,244.06732,7.296832433,1.7977E+308,0.039212614,0
139.5,243.9114951,7.179853278,1.7977E+308,0.040955397,0
139.7,243.4872492,7.062894434,1.7977E+308,0.042698178,0
139.9,243.4893191,6.945903331,1.7977E+308,0.049233614,0
140.1,243.2512228,6.828930401,1.7977E+308,0.052283483,0
140.3,242.9433204,6.711962754,1.7977E+308,0.045312351,0
140.5,242.6262767,6.594995799,1.7977E+308,0.037034132,0
140.7,242.5062325,6.477721462,1.7977E+308,0.027013131,0
140.9,242.0342491,6.360473756,1.7977E+308,0.019606304,0
141.1,241.7112953,6.244092197,1.7977E+308,0.024398956,0
141.3,241.855886,6.127090309,1.7977E+308,0.033548565,0
141.5,241.4482606,6.010130208,1.7977E+308,0.042262477,0
141.7,241.3780314,5.893144575,1.7977E+308,0.047490824,0
141.9,240.9163894,5.776188562,1.7977E+308,0.046183736,0
142.1,240.9874344,5.659192239,1.7977E+308,0.039648302,0
142.3,240.4908894,5.542238866,1.7977E+308,0.034855649,0
142.5,240.2561172,5.425265685,1.7977E+308,0.030062996,0
142.7,239.9432287,5.308298415,1.7977E+308,0.023091866,0
142.9,239.7425286,5.191322656,1.7977E+308,0.013506563,0
143.1,239.6465376,5.074338973,1.7977E+308,0.008713912,0
143.3,239.3851726,4.957367804,1.7977E+308,0.003049869,0
143.5,238.767298,4.840423613,1.7977E+308,0.008278216,0
143.7,238.7569026,4.723433453,1.7977E+308,0.016120736,0
143.9,238.4357039,4.606466812,1.7977E+308,0.017863517,0
144.1,238.144422,4.489497907,1.7977E+308,0.02832021,0
144.3,237.7608965,4.372535982,1.7977E+308,0.035727033,0
144.5,237.5095038,4.255564059,1.7977E+308,0.03790551,0
144.7,237.2265323,4.138594525,1.7977E+308,0.037469814,0
144.9,237.3009014,4.021597951,1.7977E+308,0.035291336,0
145.1,236.6722235,3.904654577,1.7977E+308,0.032241466,0
145.3,236.2122437,3.787698438,1.7977E+308,0.03180577,0
145.5,236.4312112,3.670690922,1.7977E+308,0.024398947,0
145.7,235.9720624,3.553734719,1.7977E+308,0.017427819,0
145.9,235.5760715,3.436773738,1.7977E+308,0.013942255,0
146.1,235.4111055,3.319795275,1.7977E+308,0.006971127,0
146.3,235.195447,3.202820647,1.7977E+308,0.010892386,0
146.5,234.8385143,3.08585671,1.7977E+308,0.016556427,0
146.7,234.395986,2.96889925,1.7977E+308,0.016992122,0
146.9,233.9958401,2.851938583,1.7977E+308,0.010020994,0
147.1,233.6289351,2.734975401,1.7977E+308,0.011763776,0
147.3,233.5686782,2.617989014,1.7977E+308,0.013506557,0
147.5,233.3779505,2.5010125,1.7977E+308,0.01699212,0
147.7,232.859799,2.384060763,1.7977E+308,0.018299206,0
147.9,232.6865228,2.267082928,1.7977E+308,0.010892384,0
148.1,232.1259892,2.150134398,1.7977E+308,0.004792649,0
148.3,231.9161479,2.03315933,1.7977E+308,0.011763774,0
148.5,231.6996584,1.916184766,1.7977E+308,0.017427814,0
148.7,231.3443878,1.799220703,1.7977E+308,0.024398939,0
148.9,230.8204193,1.682269406,1.7977E+308,0.023091852,0
149.1,230.542434,1.565299495,1.7977E+308,0.023963242,0
149.3,230.2478282,1.448330841,1.7977E+308,0.020041984,0
149.5,229.6839706,1.331382563,1.7977E+308,0.010020991,0
149.7,229.4807775,1.214406992,1.7977E+308,0.010456687,0
224.9,228.5877414,1.105227518,1.7977E+308,0.006099736,0
225.1,228.2615566,0.988261254,1.7977E+308,0.010892385,0
225.3,227.6486684,0.871316686,1.7977E+308,0.017863511,0
225.5,227.3150044,0.754350988,1.7977E+308,0.026577419,0
225.7,226.863335,0.63739422,1.7977E+308,0.030934372,0
225.9,226.3510007,0.520442043,1.7977E+308,0.033548543,0
226.1,225.7422677,0.40349716,1.7977E+308,0.035727018,0
226.3,225.1750859,0.286549133,1.7977E+308,0.038776884,0
226.5,224.1591509,0.169635064,1.7977E+308,0.033112842,0
226.7,223.2429389,0.052713449,1.7977E+308,0.020041982,0
226.792,222.4149111,-0.001039728,1.7977E+308,0.013942248,0
,,,,,