File: Test_19.csv
Time On Sample,Displacement Into Surface,Load On Sample,Harmonic Contact Stiffness,Harmonic Displacement,Harmonic Load
0,0,0,-79.89251623,0.312396006,2.229344636
0.2,0.804676136,0.000697127,5673.446143,0.213056702,2.312155183
0.4,0.666963082,0.00146549,12484.03408,0.173843811,2.387338346
0.6,0.6971183,0.002221164,15981.59356,0.160772848,2.462521534
0.8,0.6973564,0.002979099,17710.31833,0.14944468,2.519181318
0.992,0.93296561,0.003692715,20421.90883,0.13593802,2.664099656
1.2,0.992848413,0.004474003,24040.84247,0.124174153,2.91906871
1.4,0.839346751,0.005237371,27117.39988,0.11763867,3.131542894
1.6,0.846233483,0.005992395,32158.80964,0.105439105,3.325493709
1.8,1.035530931,0.00673741,37658.81123,0.096289432,3.541236778
2,1.15543849,0.00748011,44188.3872,0.091932444,3.959647546
2.2,1.035592983,0.008244713,50152.64784,0.090189649,4.476123291
2.4,1.056191728,0.0089987,51710.02425,0.094110938,5.011122451
2.6,1.194381369,0.009743798,51597.72772,0.099775023,5.427354025
2.8,1.230769704,0.010496592,47183.81138,0.115895879,5.946009022
3,1.013278046,0.011268576,47064.37075,0.134195226,6.874357801
3.2,1.377092626,0.011996619,47831.37781,0.149444687,7.679580701
3.4,1.418882664,0.012749004,49257.19784,0.169486832,8.691829638
3.6,1.304023342,0.013513229,48025.59145,0.19867865,9.671390204
3.8,1.30841698,0.014268441,47146.59285,0.225256277,10.59102215
4,1.410041257,0.015016303,45863.46768,0.255755194,11.60000231
4.2,1.070388027,0.015797522,44149.6674,0.295839477,12.83235251
4.4,1.135446935,0.016548148,42887.05022,0.335488068,14.09848089
4.6,0.965324048,0.017316551,41971.39363,0.372086762,15.27961947
4.8,0.838414778,0.018081688,40184.73835,0.418706529,16.43133854
5,1.059707525,0.018820505,38575.4792,0.465326306,17.50896432
5.2,1.12310437,0.019571257,36807.34216,0.520660054,18.68356537
5.4,1.060184492,0.020331557,34350.89282,0.58993616,19.75683242
5.6,0.87011686,0.021101468,31847.59308,0.667490535,20.73530324
5.8,0.811352138,0.021861454,29651.29521,0.746352012,21.6091715
6,0.445105928,0.022644683,28068.1237,0.816063798,22.42420033
6.2,1.047010896,0.023354729,26773.52113,0.878804458,23.10629772
6.4,0.85278811,0.024124955,25622.07124,0.949823348,23.98125539
6.6,0.999288061,0.024869424,24843.17477,1.00297861,24.61867819
6.8,0.73858279,0.025644675,23964.75207,1.065719217,25.37704736
7,0.776217671,0.026397375,23073.02101,1.12671705,25.98614013
7.2,0.853742042,0.027147059,22017.29218,1.199478754,26.56581345
7.4,1.104120878,0.027883676,21111.83129,1.261348003,26.97659725
7.6,1.246465677,0.02862846,20280.08929,1.32539574,27.47128099
7.8,1.304876336,0.029379588,19787.71687,1.368965619,27.83412165
8,1.351652561,0.030131596,19431.57557,1.407307123,28.2263818
8.2,1.349397951,0.030887309,19394.69323,1.429527762,28.69818352
8.4,1.898947998,0.031601311,19464.05356,1.442163082,29.08935477
8.6,2.333815767,0.032323982,19475.0668,1.462640973,29.52411033
8.8,1.822970103,0.033118139,19724.38883,1.465690814,29.91201126
9,2.29440324,0.033838045,20232.48661,1.461333874,30.46335531
9.2,2.257245322,0.034596396,20768.17023,1.447391502,30.88939331
9.4,2.446958909,0.035337597,21679.9348,1.416892603,31.39279396
9.6,2.469635235,0.036091424,23317.51578,1.358508962,32.11084795
9.8,2.581231895,0.03683853,25169.13246,1.298818232,32.88556187
10,2.503353449,0.037599958,27097.66494,1.241741679,33.63412476
10.2,2.251789494,0.038374515,28583.49847,1.203400161,34.251934
10.4,2.636795404,0.039100954,30267.69324,1.166801491,35.0658744
10.6,2.511548182,0.039865962,31280.74435,1.156344709,35.84058789
10.8,2.437824893,0.040627076,31496.60411,1.165930078,36.38975186
11,2.226981465,0.041398556,31055.68156,1.199478871,36.92910916
11.2,2.270433568,0.042150812,29896.15891,1.262655205,37.42488232
11.4,2.903086772,0.042858531,28685.48883,1.326267292,37.74631899
11.6,3.01052828,0.04360595,27503.08228,1.394236323,38.10915975
11.8,2.915198177,0.044368696,27060.64902,1.428220824,38.42296784
12,2.863912728,0.045128113,27041.73323,1.444341677,38.83375113
12.2,2.832572028,0.045886022,27879.20281,1.422992431,39.41451408
12.4,2.671590463,0.046653732,29313.32068,1.375936941,40.00944146
12.6,2.464071156,0.047424959,31305.02857,1.317117579,40.80376794
12.8,2.683701869,0.048163897,32617.93975,1.284875885,41.42702604
13,2.779508939,0.048912196,33694.11779,1.26352665,42.08842033
13.2,2.971715627,0.049653207,34300.13115,1.260041077,42.79013061
13.4,2.908795741,0.050413504,34207.40014,1.276161929,43.29679969
13.6,2.75778655,0.051180459,33999.1673,1.299253955,43.88845832
13.8,2.737249255,0.051937552,33937.49633,1.313632015,44.37115622
14,2.997600501,0.052673412,33948.49467,1.329317198,44.92467938
14.2,2.825815529,0.053441937,33856.60383,1.351102125,45.48147055
14.4,3.203342177,0.05416894,33638.18477,1.373322802,45.91840544
14.6,3.048177827,0.054936209,33338.46544,1.401643214,46.42180565
14.8,2.91545132,0.055701782,33183.46318,1.422556746,46.82060308
15,3.00959633,0.056450205,32955.94299,1.446520193,47.25208951
15.2,3.156927337,0.057194608,32912.08662,1.462205367,47.73478779
15.4,3.285144628,0.057940456,33102.80085,1.470919357,48.24472615
15.6,2.906432884,0.058724623,33261.226,1.476583405,48.65986716
15.8,3.193377133,0.059458473,33262.9359,1.490090099,49.13602808
16,3.181981181,0.060214874,33338.56995,1.499675473,49.56315572
16.2,3.447318624,0.060950357,33320.01219,1.511875069,49.93798278
16.4,2.984672724,0.061740868,33243.37389,1.527124481,50.39234973
16.6,2.962473367,0.062498085,33147.34324,1.542373939,50.73230836
16.8,3.049139096,0.063247074,32958.41197,1.563287494,51.12129997
17,3.34439366,0.063980295,32783.19879,1.582458276,51.45799059
17.2,3.758485698,0.064704533,32778.52331,1.594222191,51.76090357
17.4,3.378111879,0.065488824,32888.53118,1.603807525,52.14771472
17.6,3.496356798,0.066235425,33251.40521,1.598579152,52.50074916
17.8,3.725959904,0.066973609,34311.27318,1.568515955,53.04555549
18,3.509299236,0.067745525,35561.63959,1.531917228,53.60234643
18.2,3.594302907,0.068494638,37016.95169,1.491397242,54.24848614
18.4,3.374318116,0.069266805,38587.58542,1.450441526,54.93820974
18.6,3.972068063,0.06997716,39652.02868,1.426478147,55.49064422
18.8,3.092243873,0.070802984,40611.21926,1.409921506,56.15966339
19,3.556197778,0.071523453,41018.35797,1.409921551,56.73171073
19.2,3.626243488,0.072269917,40968.96592,1.425171019,57.29504005
19.4,3.74531884,0.073020234,40707.74109,1.446084577,57.76629736
19.6,3.81827316,0.073766479,40582.32926,1.463076841,58.2473611
19.8,4.068236538,0.074503122,40564.80804,1.477019231,58.77037537
20,4.18772801,0.075249627,41209.28871,1.468740964,59.34024245
20.2,4.35417275,0.075992584,42507.96516,1.441291951,60.05502813
20.4,4.085157104,0.076768456,43842.05006,1.412535798,60.68591243
20.6,3.919189337,0.07753654,45190.44486,1.387700946,61.45408811
20.8,4.219430109,0.078269382,46256.91392,1.372451514,62.22444431
21,4.291137101,0.07902065,46616.21147,1.375501413,62.87821131
21.2,4.371568824,0.079778164,46485.21313,1.393365076,63.54614348
21.4,4.354353149,0.080550757,46139.71738,1.413407224,64.01249725
21.6,4.420239372,0.081324801,46248.44785,1.423428306,64.65427865
21.8,4.358145524,0.08211641,46429.17597,1.432577977,65.32003112
22,4.405746559,0.082907567,46728.02663,1.43737067,65.91822805
22.2,4.535618419,0.08370051,47118.75403,1.441291973,66.5959666
22.4,4.604823729,0.08450601,47434.72064,1.444341873,67.14404155
22.6,4.370701322,0.085342582,47282.76181,1.462641204,67.74223739
22.8,4.433255771,0.086165003,47187.83589,1.47876207,68.3273592
23,4.557305215,0.086991087,47172.17479,1.490961653,68.87979261
23.2,4.54838833,0.087835537,47266.80912,1.500547028,69.48888546
23.4,4.521187411,0.088689834,47607.87152,1.503161219,70.13720434
23.6,4.497309253,0.089552467,48262.36942,1.494882938,70.71796699
23.8,4.736035619,0.090403839,49082.41502,1.484861891,71.44255973
24,4.732930515,0.091282065,49781.55805,1.478326408,72.13119431
24.2,4.780516904,0.092165366,50363.00831,1.473969426,72.74137675
24.4,4.59125796,0.093075454,50641.6339,1.479633494,73.41911447
24.6,4.796737443,0.093964774,50380.22355,1.499239961,74.02929789
24.8,4.958170854,0.094866328,49973.27086,1.521896324,74.59480688
25,5.081375383,0.095779851,49361.22683,1.54890967,75.06116109
25.2,4.85720734,0.096728929,48766.82822,1.573744488,75.40438793
25.4,5.226394173,0.097642531,48161.09609,1.60206496,75.86529498
25.6,5.219122328,0.098593951,47886.18684,1.620364313,76.33055912
25.8,5.088856322,0.099564244,47889.07956,1.629078273,76.72499804
26,5.044185021,0.100537653,48259.58961,1.62820687,77.21750231
26.2,5.255469822,0.101501454,48812.2592,1.622978513,77.79390764
26.4,5.165088691,0.102497856,49482.58068,1.614264524,78.38665601
26.6,5.598255746,0.103464507,50072.74703,1.609036181,78.98376482
26.8,5.370751286,0.104491115,50339.48451,1.610343257,79.43159433
27,5.361806479,0.105511226,50415.47796,1.618621535,79.90884418
27.2,5.631255524,0.106520678,50471.70901,1.628206938,80.42532087
27.4,5.658872832,0.107558566,50513.45997,1.637792318,80.92436308
27.6,6.075411183,0.10857738,50986.45151,1.633871076,81.47788772
27.8,5.42988976,0.109687039,51622.47052,1.623414229,81.97256851
28,5.693514931,0.110738812,52572.10062,1.605550602,82.59909617
28.2,5.87403528,0.111807487,53802.88163,1.582458578,83.35964597
28.4,5.655658845,0.112917176,54792.17604,1.566337694,84.08641593
28.6,5.748086379,0.114014458,55269.38821,1.562416414,84.65192495
28.8,6.484561529,0.115073852,55446.36127,1.56808058,85.27518553
29,6.617706157,0.116189771,55584.3148,1.57418038,85.84941169
29.2,6.735890424,0.117318126,55767.69947,1.57984448,86.4737595
29.4,6.616397919,0.11847567,56331.57668,1.575923177,87.16566262
29.6,6.78360941,0.119623153,57001.50949,1.567209216,87.75078459
29.8,6.735581919,0.1207985,58189.62179,1.548909854,88.55491798
30,6.674256052,0.121986635,59349.58103,1.531481889,89.32745224
30.2,7.050881881,0.12315343,60776.4843,1.510568378,90.25580327
30.4,7.29454078,0.124342267,61802.86132,1.497061735,90.97930618
30.6,7.027944452,0.125581714,62711.31889,1.489219127,91.84118788
30.8,6.993203968,0.126815793,63415.46935,1.486169231,92.70198112
31,7.138795338,0.128048635,64026.37177,1.484862149,93.5246385
31.2,7.012637453,0.129314413,64249.53303,1.490090524,94.19148035
31.4,7.495623627,0.13054673,64508.70545,1.497061758,95.02067714
31.6,7.144252195,0.131854815,65014.71693,1.498804519,95.85422846
31.8,7.550779432,0.133118364,65386.21119,1.50359725,96.66599114
32,7.432092696,0.13443473,65657.88426,1.510568422,97.44070468
32.2,7.561882307,0.135745298,66015.96286,1.514054028,98.11517483
32.4,7.619370078,0.137074555,66370.72964,1.52015382,98.95199692
32.6,7.65109374,0.138419183,66379.27522,1.532789095,99.7288902
32.8,7.512453799,0.139790211,66416.10323,1.541503061,100.3358031
33,7.692927772,0.141150798,66398.20517,1.554574051,101.1671778
33.2,7.55012831,0.142549581,66282.31795,1.56590221,101.7479403
33.4,7.830321668,0.143930282,66157.7334,1.579844609,102.4605476
33.6,7.656769609,0.145359265,66338.61985,1.587251474,103.2145581
33.8,7.832248513,0.146776106,66511.11723,1.592044182,103.7931428
34,7.830715424,0.148220704,66779.68428,1.595965474,104.4545373
34.2,7.864914388,0.149677083,67069.10606,1.600758167,105.2041905
34.4,8.093572396,0.151133407,67350.93694,1.604679484,105.9331415
34.6,8.445220766,0.152594955,67547.8185,1.608600814,106.5302505
34.8,8.354758005,0.15410477,67967.94036,1.609472203,107.2668278
35,8.592550292,0.155604922,68554.56046,1.606422336,107.9903312
35.2,8.491279309,0.157145822,69612.67776,1.595094151,108.8870814
35.4,8.430726417,0.158699085,70546.27078,1.585073067,109.6443611
35.6,8.526404997,0.160255999,71769.79473,1.572002107,110.6206537
35.8,8.484960873,0.161839002,72371.11774,1.569387909,111.3604998
36,8.435203911,0.163438511,72805.04006,1.570695001,112.1450199
36.2,8.740294869,0.165027221,72863.69059,1.580280413,112.9753061
36.4,8.824328878,0.166648752,72748.42106,1.591172899,113.6149085
36.6,8.43259406,0.168326793,72482.70768,1.606858022,114.3493049
36.8,8.730198597,0.169960971,72527.99897,1.614264939,114.969296
37,8.621009886,0.171646707,72748.02891,1.619057617,115.6840804
37.2,8.637303581,0.173344078,73164.61368,1.621236114,116.4577049
37.4,8.803597127,0.175038566,73564.34225,1.624286027,117.2574811
37.6,8.720993325,0.176773249,73978.07566,1.624721717,117.9068891
37.8,8.883541076,0.178506738,74142.23764,1.632128619,118.6826936
38,8.642620214,0.180288295,74011.02509,1.644328166,119.321205
38.2,9.157104246,0.182030325,73771.14319,1.656963497,119.8485798
38.4,9.107315016,0.183832817,73369.76728,1.674391454,120.4827334
38.6,9.066248744,0.185652729,73112.33433,1.686591023,120.9578043
38.8,9.449421206,0.187458749,73096.62592,1.695305049,121.5821539
39,9.463612727,0.189311011,73524.42193,1.693997954,122.2217562
39.2,9.538466594,0.191177319,74460.74122,1.683105487,123.0008292
39.4,9.831878813,0.193045743,75455.85657,1.670470248,123.7036309
39.6,9.797030545,0.194957858,76531.15547,1.656963573,124.4402082
39.8,9.923399381,0.196876847,78011.41787,1.638228528,125.3936192
40,9.948379281,0.19882287,79068.1531,1.627771753,126.2489645
40.2,9.919339026,0.200792469,80242.52499,1.617314973,127.2361525
40.4,9.965919505,0.202776139,81082.60735,1.610779492,127.9868956
40.6,10.35737496,0.204753596,82023.24233,1.605115448,128.971907
40.8,10.49785571,0.206769801,82324.49522,1.608601056,129.6975898
41,10.89096689,0.208787119,82668.51018,1.612086693,130.5126218
41.2,10.99570682,0.210846694,82574.93148,1.623850581,131.3396378
41.4,11.24338094,0.212916063,82573.36906,1.631693198,132.0086612
41.6,11.13786325,0.215033065,82734.61014,1.638664372,132.8324071
41.8,10.97583203,0.217175631,83201.19972,1.638228655,133.5319373
42,11.10050334,0.219317921,83692.63081,1.638228668,134.3197275
42.2,11.25342631,0.221479588,84537.71546,1.633435998,135.2676905
42.4,11.76784464,0.223635556,84999.44056,1.633436054,136.0173474
42.6,11.78613356,0.225850912,85307.53686,1.637357349,136.914098
42.8,11.8085741,0.228088188,85230.21985,1.645635638,137.5744031
43,11.89666257,0.23034304,85366.10022,1.650864032,138.3164294
43.2,11.77532744,0.232636341,85482.3742,1.656963812,139.1510714
43.4,12.32712439,0.234901652,85736.98695,1.659142371,139.8473372
43.6,12.22406467,0.237239416,86144.68027,1.660449457,140.7070403
43.8,12.21407679,0.239593537,86767.90967,1.656963861,141.4523349
44,12.30131587,0.241963948,87479.31046,1.653042576,142.3022328
44.2,12.4392441,0.244354372,88475.35052,1.646507112,143.2839742
44.4,12.58215471,0.246768384,89249.50352,1.642585829,144.0848397
44.6,12.41010039,0.249230647,90247.98842,1.637793126,145.0742066
44.8,12.60369615,0.251689854,91013.7536,1.636921744,146.0363348
45,12.54299224,0.254193088,91363.14872,1.641714429,146.8753362
45.2,12.79142817,0.256697962,91407.2666,1.649557042,147.5661515
45.4,12.62849934,0.259259345,90981.86566,1.666113592,148.3201621
45.6,12.61265907,0.261835145,90457.28414,1.68223446,148.8932979
45.8,13.0355995,0.264403521,89611.76696,1.704890866,149.5339926
46,12.9574236,0.267035889,88787.42694,1.725804418,150.0330345
46.2,12.78783,0.269701596,88216.47018,1.741489568,150.4710573
46.4,12.9373484,0.272369735,88218.38064,1.748460773,151.1270049
46.6,13.37024439,0.275043232,88412.14183,1.750203622,151.6641865
46.8,13.92280471,0.277734527,89056.1782,1.745846697,152.4029475
47,14.03574486,0.280486289,90053.25019,1.734954231,153.1504228
47.2,14.47943131,0.283240645,91588.29112,1.716654917,154.1180013
47.4,14.19679147,0.286077826,92570.74483,1.706633803,154.843681
47.6,14.16844286,0.288924164,94111.45093,1.690512929,155.8679156
47.8,14.47333354,0.291773702,95462.29099,1.676134891,156.7167262
48,14.68597511,0.294658914,96886.69031,1.66262824,157.7289779
48.2,14.55207176,0.297599395,97630.41895,1.660885428,158.7227027
48.4,14.6392182,0.300552707,98137.03767,1.660885439,159.4985073
48.6,14.81029416,0.303529257,98833.61553,1.659578361,160.4704426
48.8,14.97637917,0.306536147,98802.45247,1.667420967,161.1874085
49,15.31365199,0.309560086,98885.60304,1.674392193,162.0133378
49.2,15.72903695,0.312608812,99687.59286,1.670906647,163.0146938
49.4,15.83278007,0.315711588,100554.2773,1.664371171,163.866772
49.6,15.87252875,0.318850574,101280.5942,1.66175698,164.8899181
49.8,15.84080367,0.322026495,102698.492,1.649557398,166.0318312
50,15.89965602,0.325227385,103879.7016,1.64084342,167.073501
50.2,16.05988915,0.328452795,104575.1716,1.638664942,167.9702532
50.4,15.9724696,0.331729374,105235.9013,1.639972031,169.0555062
50.6,16.097789,0.335022752,105779.614,1.640843444,169.9435412
50.8,16.46493348,0.338330844,105910.0072,1.648686073,170.9448978
51,16.36503264,0.341707729,105726.6796,1.659578544,171.8111388
51.2,16.89587977,0.345070543,105595.9808,1.66872829,172.5542587
51.4,16.53917925,0.34853472,105284.3033,1.681799228,173.4357521
51.6,16.93705035,0.351976196,105118.7823,1.692691757,174.2791157
51.8,16.96427566,0.355480331,105251.263,1.698355851,174.9993495
52,17.16933623,0.359006277,105804.4724,1.698791575,175.8241876
52.2,16.80264107,0.362611128,106796.9662,1.693998841,176.8560473
52.4,16.92541807,0.366214953,107745.5584,1.687899066,177.7168422
52.6,17.14708214,0.369847443,108987.8077,1.679620805,178.8543991
52.8,17.33633014,0.373519023,109713.0374,1.676570932,179.7402553
53,17.12667689,0.377257669,110154.7025,1.678313706,180.7045608
53.2,17.04250351,0.381024319,109897.6892,1.690077578,181.5947729
53.4,17.49517091,0.384787743,109516.9047,1.702277212,182.280143
53.6,17.33868574,0.38863537,108964.247,1.718833768,183.0722901
53.8,17.44895577,0.392501197,108527.8824,1.731904761,183.6672197
54,17.48525776,0.396411543,108132.5362,1.744975745,184.3329728
54.2,18.15936747,0.400332826,108453.7251,1.747372172,185.0929835
54.4,18.54385938,0.404295728,108867.6993,1.748025768,185.869336
54.6,18.73637975,0.408292799,109861.5641,1.739965353,186.7377586
54.8,18.85949932,0.412355608,111095.3364,1.728855035,187.6911708
55,18.9851055,0.416459054,112249.1424,1.719269665,188.6783605
55.2,19.54201085,0.420570979,112924.241,1.715348436,189.4977544
55.4,19.64308847,0.424758799,114195.8857,1.705327363,190.6091599
55.6,20.30676823,0.428946062,114934.8846,1.703148944,191.6530147
55.8,19.94702508,0.43325298,115614.4444,1.700534706,192.5214323
56,20.59573274,0.437526522,116773.5496,1.692692193,193.5718249
56.2,20.42794434,0.441905094,118343.2066,1.68136399,194.8118021
56.4,20.77995968,0.446288012,119187.6273,1.677878435,195.7499617
56.6,20.94747885,0.450729025,120400.4861,1.672214363,196.9877632
56.8,21.27787325,0.455202348,121481.6296,1.666550308,197.9804035
57,21.24094422,0.4597485,122491.6705,1.663500409,199.1059728
57.2,21.10179096,0.464348016,122956.6095,1.667857388,200.288201
57.4,21.32579149,0.468966145,123386.7786,1.670035911,201.2132843
57.6,21.56225014,0.473629723,124076.3844,1.670907338,202.4194875
57.8,21.63997415,0.478352269,124166.1957,1.67657144,203.2900886
58,21.79497665,0.483116272,123966.0082,1.686156846,204.232605
58.2,21.76797544,0.487941977,124521.3075,1.687463942,205.3810564
58.4,21.78667333,0.492812617,125054.7389,1.687899644,206.32684
58.6,21.74469808,0.497736757,125714.8971,1.688335339,207.4861879
58.8,22.04593135,0.50268422,126220.1964,1.689206773,208.3949276
59,22.04466094,0.507704355,127059.2421,1.687899675,209.5063321
59.2,22.16471323,0.512765718,127753.8262,1.68877109,210.6602334
59.4,22.35622623,0.51787257,128280.365,1.689642513,211.5907646
59.6,22.62003089,0.523025175,128562.884,1.69530664,212.6890965
59.8,23.34089518,0.528194866,128940.0136,1.699663716,213.7852544
60,23.20412572,0.533481702,129268.2799,1.7018422,214.6013729
60.2,23.27261284,0.538806012,129244.9013,1.710556201,215.6593874
60.4,23.2829192,0.54418815,128879.7294,1.72144869,216.423206
60.6,23.4893406,0.549609575,128545.3408,1.732776896,217.340662
60.8,23.91182182,0.555068955,128255.6755,1.743233735,218.2254319
61,24.03678468,0.56060585,128128.6134,1.751512046,219.044822
61.2,24.26727984,0.566190288,128479.4071,1.752819164,219.7922987
61.4,24.39305597,0.571838851,129143.956,1.751947785,220.8143568
61.6,24.62519524,0.577536165,129720.9557,1.750640716,221.6217623
61.8,24.95040108,0.583283501,130422.8411,1.749333658,222.6623459
62,25.0063432,0.589109017,130927.3129,1.749769363,223.6037719
62.2,25.20521362,0.594982242,131273.5737,1.75064079,224.3970121
62.4,25.33759203,0.600919616,132113.5862,1.747155206,225.4626548
62.6,25.18824094,0.606937947,132905.4404,1.743233897,226.3397914
62.8,25.38874495,0.61299019,133740.4805,1.740619725,227.4239583
63,25.4521189,0.61911373,134661.4167,1.736698431,228.4580012
63.2,25.59443119,0.625292651,135241.8457,1.736698448,229.3275139
63.4,26.03507431,0.63151109,135346.2333,1.743669694,230.3092596
63.6,26.24135628,0.637809994,135201.0721,1.751948012,231.0469299
63.8,26.54901421,0.644164248,135407.5506,1.757176444,232.0123309
64,26.72618987,0.650592271,135712.704,1.760226363,232.8883811
64.2,27.1534961,0.657065913,135996.9818,1.762404913,233.6576525
64.4,27.03064835,0.663646434,136922.4701,1.758919302,234.7374574
64.6,27.80447437,0.670224967,137853.4687,1.753691,235.6298589
64.8,27.64005396,0.676940864,139111.5112,1.746719787,236.8066388
65,27.76066705,0.683702545,139946.8093,1.744105605,237.8308768
65.2,28.47878189,0.690486803,140838.1301,1.740184394,238.7701309
65.4,28.51543906,0.697390903,141742.6818,1.737570201,239.9578099
65.6,28.78726745,0.704346634,142602.7717,1.734084637,240.9112236
65.8,28.8546507,0.711387628,143577.8967,1.731034748,242.1326809
66,29.23781516,0.718475435,144552.5765,1.727113497,243.2854962
66.2,29.61265798,0.72563514,145468.0329,1.723192244,244.3042885
66.4,29.80549317,0.732880627,146612.1982,1.718835271,245.596572
66.6,29.8844653,0.740207522,146604.0573,1.724935077,246.5053104
66.8,29.99251188,0.747605785,146203.5107,1.736263282,247.5175616
67,30.1047018,0.755078156,145630.6089,1.749334287,248.384895
67.2,29.95094928,0.762645719,144942.0268,1.76240526,249.0811559
67.4,30.19109425,0.77025942,144562.5303,1.772862082,249.9354158
67.6,30.56502337,0.777939357,145153.5083,1.771555029,250.7657051
67.8,31.23728104,0.785673886,146349.0982,1.765455315,251.9217926
68,31.51478574,0.793516114,147624.2011,1.757612754,253.047366
68.2,31.73161251,0.801441712,149009.2048,1.748463086,254.1130104
68.4,31.72903395,0.809463527,150474.4146,1.740620491,255.4042019
68.6,32.1535935,0.817533571,151256.2236,1.738877743,256.4066518
68.8,32.16927194,0.825715819,152474.6828,1.734520748,257.7022022
69,32.69103641,0.83394178,153642.8159,1.730599512,258.8909765
69.2,32.70419553,0.842289134,154318.0605,1.730599514,259.8890615
69.4,33.36388503,0.850671184,155163.0586,1.730163893,261.1791721
69.6,33.68865484,0.859162881,156108.5015,1.727114034,262.2589827
69.8,33.53556709,0.867776172,157092.4578,1.724935517,263.5414566
70,33.6791444,0.876453348,157965.7422,1.723192736,264.7792584
70.2,33.79195961,0.885220159,159287.1734,1.716657252,265.9778345
70.4,33.99285033,0.894068376,160935.6427,1.70925038,267.4673375
70.6,34.10231328,0.903012455,161885.7213,1.707071894,268.6430328
70.8,34.52423042,0.912022501,162124.5194,1.713171742,269.9582008
71,35.00596755,0.921118578,162429.0855,1.717964497,271.1338999
71.2,35.17605273,0.930329838,162199.219,1.726678515,272.0971198
71.4,35.68435368,0.939608014,161876.6981,1.737135372,273.2314135
71.6,36.33183788,0.948968949,161811.5283,1.743235248,274.1358017
71.8,36.68054305,0.958494846,162901.8053,1.739749691,275.4531497
72,37.06497499,0.968066191,163724.8917,1.738442638,276.6746115
72.2,37.18097178,0.977729793,164552.6215,1.736264153,277.7271792
72.4,37.61399237,0.987466151,165210.9895,1.737571304,279.0499751
72.6,37.5998976,0.997358843,166102.5441,1.735392804,280.1341408
72.8,38.22568268,1.007302367,166338.1505,1.741056978,281.3741301
73,38.33247156,1.017385331,167088.359,1.741056991,282.5934081
73.2,38.86348688,1.027537284,167561.3894,1.742364155,283.5860535
73.4,39.35667397,1.037794167,168508.0381,1.741057114,284.9535252
73.6,39.6732501,1.048167554,169085.4506,1.742799953,286.2087642
73.8,39.79327034,1.058659561,169944.5932,1.740621468,287.2962007
74,40.01798403,1.069249075,170496.4927,1.742364295,288.504585
74.2,40.37897034,1.079934388,171454.0077,1.739750139,289.6508628
74.4,41.06570471,1.090702426,172512.1491,1.738007421,291.0423094
74.6,41.02360551,1.101634052,173786.795,1.734521816,292.4729716
74.8,41.21334721,1.11265785,174775.4867,1.731907639,293.6225163
75,41.74628813,1.123766391,176040.5941,1.727986403,295.0183183
75.2,42.02574611,1.135005795,177041.2155,1.727115036,296.4805846
75.4,42.86031658,1.146315882,178516.7453,1.720579634,297.7968497
75.6,43.43309343,1.157759572,180139.1941,1.714044201,299.4192926
75.8,43.88535217,1.169327243,181293.0731,1.710558653,300.7355533
76,44.09243754,1.181029611,182997.206,1.703587476,302.2947944
76.2,44.36681796,1.192844385,184388.5162,1.700101908,303.9869679
76.4,44.7242829,1.204771489,184186.8032,1.707944553,305.0907521
76.6,44.96787721,1.216826871,183941.4021,1.717965685,306.5018056
76.8,45.26048325,1.228999743,184042.1187,1.72275842,307.5870646
77,45.75667312,1.241279451,183862.9869,1.731036784,308.8401286
77.2,46.00353325,1.253701544,184273.1124,1.734958123,310.2490024
77.4,46.23790805,1.266249321,185486.5578,1.731036843,311.5412885
77.6,46.66838681,1.278908229,186792.4132,1.727986993,313.1103386
77.8,47.1661591,1.291689168,187216.5656,1.731036954,314.2871291
78,47.34645607,1.304622638,187979.0246,1.732344078,315.6720311
78.2,47.54002893,1.317685017,188404.0069,1.736701103,317.1026972
78.4,48.11751856,1.330849617,189074.1796,1.737136876,318.3230737
78.6,48.28611853,1.344177375,190129.9177,1.735829792,319.8485359
78.8,48.83614177,1.357610192,190996.2545,1.734522757,321.0787186
79,49.03794035,1.371204438,191237.1884,1.738879782,322.4069613
79.2,49.07600352,1.384947717,191456.761,1.744108198,323.8528797
79.4,49.33593082,1.398812183,190908.4129,1.754565036,324.8411637
79.6,49.57755325,1.412817278,191052.7777,1.76066487,326.1628694
79.8,49.68369476,1.426973448,191657.3548,1.761536279,327.2513955
80,49.82388606,1.441269218,192592.4074,1.760664898,328.5502177
80.2,50.8640644,1.455640251,193737.0914,1.758922222,330.0353783
80.4,51.40809248,1.4701934,195356.6402,1.751515381,331.3429243
80.6,51.54655272,1.484923512,196416.9438,1.749772597,332.8596695
80.8,52.08388582,1.499771186,197224.7779,1.748465561,334.1029272
81,52.52645732,1.514775379,198469.9222,1.744544311,335.5281503
81.2,52.9332704,1.529932998,200115.8181,1.738444555,337.224686
81.4,53.24864552,1.545249919,201457.0209,1.73539469,338.839499
81.6,53.66870651,1.560712697,202674.4324,1.732780538,340.176463
81.8,54.33639099,1.57631215,203087.6231,1.737573323,341.6790522
82,54.78050237,1.592085342,202984.1628,1.744980284,342.9299367
82.2,55.07832657,1.608027919,203279.072,1.748901624,344.087113
82.4,55.53152873,1.624118889,203568.4578,1.754130085,345.5123347
82.6,55.88996727,1.640378815,204265.7113,1.754565829,346.7446941
82.8,56.53508672,1.656780287,206071.6356,1.7484661,348.37259
83,56.69402486,1.673383563,208038.2222,1.741059211,349.9743266
83.2,57.58590887,1.690097849,209934.3035,1.734959511,351.796176
83.4,57.63592834,1.707043931,210969.9254,1.733216715,353.130956
83.6,58.10393106,1.72412863,211315.7644,1.738009478,354.6956493
83.8,58.47135133,1.741392645,211581.1134,1.741495126,355.9247415
84,58.96672336,1.758820385,212006.9766,1.74454509,357.3477868
84.2,59.37065375,1.776430293,212173.7267,1.750209247,358.8144145
84.4,59.83189745,1.794212576,212591.6897,1.754130608,360.2875818
84.6,59.8834127,1.812204653,213468.2849,1.753694914,361.5940308
84.8,60.77923036,1.830313536,214812.9967,1.751080819,363.2132131
85,60.99606382,1.848656011,215998.8979,1.749338043,364.7299618
85.2,61.14139903,1.86718804,217725.5655,1.743238252,366.2303628
85.4,62.01302898,1.885851018,220247.6285,1.732781541,368.144831
85.6,62.31952554,1.904744489,223063.7528,1.720581959,370.2140148
85.8,63.08056794,1.923793249,224783.9551,1.71491794,371.8146726
86,64.02025244,1.943019856,226395.8777,1.710996744,373.6408846
86.2,64.64411303,1.962463717,226550.3626,1.717532329,375.4147878
86.4,65.22971499,1.98210589,226552.7489,1.72406791,376.7996994
86.6,65.69395452,2.001954486,225650.6392,1.73801039,378.2488959
86.8,66.11661062,2.022005679,225229.8122,1.747160158,379.456197
87,66.48189332,2.042262559,225814.0698,1.750210108,380.9369903
87.2,67.02498515,2.062709506,227152.8699,1.748467371,382.6575028
87.4,67.6021168,2.083359259,228261.1223,1.746724637,384.0783716
87.6,67.98226017,2.104231494,230428.6739,1.73975347,386.0418646
87.8,68.5850876,2.125296603,232012.3127,1.734960833,387.5902187
88,69.00671577,2.146587118,232502.6567,1.73801079,389.1821545
88.2,69.71086189,2.168070046,233538.5491,1.738446575,391.048678
88.4,70.28948745,2.18977826,234532.6087,1.738882345,392.8683463
88.6,70.8456404,2.211706326,234729.7382,1.743239421,394.2521693
88.8,71.30120308,2.233862351,234915.061,1.748903589,395.8953161
89,71.90839432,2.256229557,235740.6561,1.749121513,397.3298076
89.2,72.26748567,2.278841336,237453.7281,1.744546696,399.109701
89.4,72.76448364,2.301727277,239088.0141,1.741496849,401.0230758
89.6,73.57933443,2.324703723,240768.4059,1.736704236,402.6248259
89.8,74.34176535,2.348091096,243291.3976,1.728426008,404.7397836
90,74.76845807,2.371503482,245268.1804,1.723633347,406.6793087
90.2,75.36005513,2.395256948,245483.4128,1.72842613,408.1557486
90.4,76.19552319,2.419230632,245421.9589,1.735833148,409.9351073
90.6,76.7625285,2.443465758,245377.0839,1.74149733,411.3548874
90.8,77.33074169,2.467944181,245283.555,1.748468617,413.0525194
91,78.02564877,2.492658771,245214.4113,1.754568516,414.562741
91.2,78.70389572,2.517622774,245960.2921,1.755875702,416.0282877
91.4,79.51132902,2.542826948,247536.3744,1.754132995,417.9035324
91.6,79.6065245,2.568338375,249375.5086,1.7515188,419.7809413
91.8,79.90278989,2.594090862,250471.4713,1.751518837,421.2159723
92,80.58793889,2.620072467,251495.1696,1.752390322,422.8569473
92.2,81.56058483,2.646293287,252636.7413,1.75282614,424.7311075
92.4,82.03456742,2.67281556,254000.3197,1.75021199,426.3459263
92.6,82.71460457,2.699588589,255151.7873,1.74934067,428.2767399
92.8,83.55249581,2.726618713,255884.1832,1.749776472,429.8272819
93,83.94740177,2.753953962,257299.3106,1.746726611,431.6632912
93.2,84.54005064,2.781548959,259424.4045,1.740626864,433.8131169
93.4,85.06035534,2.809426553,260753.9331,1.738884121,435.5183758
93.6,85.92217146,2.83755769,262967.1936,1.734091509,437.6921791
93.8,86.7307564,2.865975487,265747.589,1.725813279,439.9575073
94,87.27253342,2.894698913,267812.2904,1.721892031,442.0495821
94.2,87.93144073,2.923701739,268998.6525,1.72189211,443.8093267
94.4,88.70498476,2.952987187,270161.0825,1.723199306,445.9765886
94.6,89.41947851,2.982571243,270974.9695,1.724942195,447.7210799
94.8,90.20373208,3.012447293,271525.6902,1.729299305,449.8207883
95,90.85663425,3.042633415,272453.2362,1.730606483,451.7701249
95.2,91.50948826,3.073122738,273894.2661,1.728428063,453.627935
95.4,92.41326658,3.103899449,276263.2092,1.722764045,456.0131256
95.6,92.77682212,3.135026325,277920.5958,1.719714175,457.9014383
95.8,93.61235668,3.166430067,280577.5612,1.713614456,460.3737965
96,94.4312204,3.198150659,282313.2407,1.712307449,462.5715711
96.2,94.91512577,3.230215299,283382.5319,1.713614606,464.4359158
96.4,95.63998056,3.262583875,283154.9366,1.722764429,466.4658877
96.6,96.35564228,3.295278439,283157.2343,1.730607146,468.565595
96.8,97.12693128,3.328297212,282323.1558,1.740628376,470.0300573
97,97.84830539,3.361651494,281412.7743,1.751085308,471.6743053
97.2,98.31117384,3.395360412,280520.9962,1.760670796,473.0951761
97.4,99.19366208,3.429376077,280652.4603,1.765899332,474.9540825
97.6,99.93980598,3.463743979,280708.5775,1.770256437,476.4425162
97.8,101.1172032,3.498424517,282168.3866,1.768513773,478.4550656
98,101.7552021,3.533494364,284874.1621,1.760235517,480.5318902
98.2,102.6748666,3.568895232,289577.692,1.742807553,483.201473
98.4,103.4565224,3.604662224,293189.6104,1.730172292,485.3447689
98.6,104.1998935,3.640791394,297451.4471,1.717101323,488.1309361
98.8,105.0811591,3.677273172,299596.9407,1.713180109,490.2121243
99,105.9216456,3.714124603,301353.3927,1.712744507,492.5777037
99.2,106.7953149,3.751343611,301342.3316,1.72145865,494.8822647
99.4,107.5118587,3.788948585,301502.2924,1.72886567,497.0299185
99.6,108.2366528,3.82693076,302420.648,1.730608565,498.8779268
99.8,109.1492008,3.865280273,304608.8779,1.727123057,501.3295887
100,109.9295526,3.904025027,306785.9386,1.723201831,503.6973447
100.2,110.5735525,3.943169472,309288.6124,1.717102078,505.9081938
100.4,111.6994916,3.982670679,312176.1329,1.710130976,508.6616842
100.6,112.4622043,4.022596286,313449.7205,1.710131067,510.815877
100.8,113.4259644,4.06290783,314568.2142,1.713181096,513.3383654
101,114.1154177,4.103645184,315094.299,1.718409604,515.5546654
101.2,115.2627078,4.144756952,315033.7791,1.727123785,517.8516076
101.4,116.1863832,4.186298934,315203.503,1.732788025,519.6146309
101.6,117.1108233,4.228258187,315986.3152,1.736709456,521.9518847
101.8,117.4418354,4.270683936,316349.2278,1.740195115,523.7236123
102,118.6054798,4.313472657,317437.5225,1.741066659,525.9072349
102.2,119.6036794,4.356703801,320430.392,1.734095541,528.6868753
102.4,120.3782607,4.40038634,322695.2817,1.730610014,531.3390246
102.6,121.4860186,4.44448248,324179.407,1.729303039,533.3668318
102.8,122.7183619,4.489012415,327817.0243,1.720589136,536.2598008
103,123.3256934,4.53403707,330456.669,1.715796481,538.896692
103.2,124.0069155,4.579508457,331190.0695,1.718410777,540.9996723
103.4,125.2357192,4.625395221,333160.5456,1.717103814,543.7825891
103.6,126.2666626,4.671757949,335030.4124,1.714925423,546.0501108
103.8,127.3698324,4.718580992,336178.9548,1.717104067,548.7436778
104,128.1779088,4.765896834,337578.4629,1.717975568,551.2312987
104.2,129.2476868,4.813668178,340582.5732,1.711875857,553.7527028
104.4,130.5143448,4.861904671,343860.2799,1.706647573,556.8287294
104.6,131.1584779,4.910672946,346616.9867,1.70359773,559.7968665
104.8,132.3127908,4.959892571,350468.581,1.69488381,562.5405578
105,133.1454133,5.00963098,353943.4761,1.688784068,565.5817064
105.2,134.1283744,5.059857737,356581.6753,1.686605669,568.8462311
105.4,134.9982341,5.110597648,359128.0579,1.683120147,571.6019007
105.6,135.8912819,5.161845728,360539.5955,1.685734468,574.6681115
105.8,136.9845283,5.213593387,360240.7534,1.693577248,576.9879409
106,137.8649461,5.265877174,361491.2611,1.695755866,579.7784794
106.2,139.1408551,5.318656158,362487.1266,1.700548747,582.856689
106.4,140.0734608,5.371991561,363209.6595,1.704470184,585.2691305
106.6,141.345045,5.425838912,366211.6043,1.700113302,588.4726466
106.8,142.6468762,5.480225888,369342.3511,1.694449314,591.2740954
107,143.6506929,5.535182124,371266.1927,1.694885135,594.2901885
107.2,144.5916785,5.590695203,373577.4284,1.694013839,597.5427306
107.4,145.476851,5.647052768,374019.4052,1.698806677,599.9649796
107.6,146.5385738,5.703683418,372927.7834,1.711006491,602.6280398
107.8,147.8221396,5.76057837,370940.7527,1.726256256,605.0927953
108,148.9534656,5.8184898,369398.1171,1.738891786,607.3505194
108.2,149.9526102,5.876700987,368939.3171,1.745863159,609.2835348
108.4,151.356355,5.935613239,370246.8108,1.747606141,612.0784499
108.6,152.5244061,5.995135194,371962.5271,1.746299171,614.2838742
108.8,153.4492834,6.055270629,374201.1663,1.744992172,617.1408843
109,154.5884731,6.115994047,376208.007,1.744120903,619.6928096
109.2,155.6934933,6.177330166,377552.8696,1.746735256,622.5160478
109.4,156.8133743,6.239281315,378128.9593,1.749785316,624.5863599
109.6,158.0370365,6.30184706,379715.8198,1.750221167,627.3148034
109.8,159.240654,6.365042926,381261.8248,1.749349905,629.6488067
110,160.8929323,6.428839841,383582.1302,1.745864474,632.4546292
110.2,161.7689172,6.493336648,386512.8287,1.74107184,635.519757
110.4,163.0968852,6.558447198,389807.2557,1.735843555,638.654633
110.6,164.2793171,6.624222979,391608.337,1.734972288,641.0954199
110.8,165.6444731,6.690645687,394259.0058,1.732793932,644.1572953
111,166.9380537,6.757741127,395459.7908,1.735844014,646.9217047
111.2,168.3777904,6.825499001,395904.5175,1.740636928,649.1630976
111.4,169.9030165,6.893930151,396600.8484,1.745865557,651.952573
111.6,170.8073459,6.963095808,398152.2993,1.746301371,654.3007346
111.8,172.5168437,7.032894449,398861.2527,1.751094319,657.1131012
112,173.6170772,7.103440642,401856.6075,1.746737412,659.9755697
112.2,175.2041882,7.174658218,405418.8024,1.739766338,662.7715863
112.4,176.3715099,7.246623197,408992.0515,1.734102324,666.1407322
112.6,177.7024319,7.319298611,411420.9832,1.731052552,668.7994511
112.8,178.8861436,7.392715286,414917.3923,1.72625995,672.3102491
113,180.3323472,7.466849956,415403.1194,1.731488572,675.0801098
113.2,181.9762205,7.54171417,415198.3877,1.738024333,677.3749059
113.4,183.3748172,7.617349229,415229.45,1.744995768,680.2373869
113.6,184.9685879,7.693729483,415679.1302,1.750224412,683.0246908
113.8,186.1284331,7.770909909,416655.5031,1.751967372,685.2976796
114,187.683731,7.848835786,418566.6981,1.751096147,688.1111339
114.2,189.1375176,7.927552365,421272.4599,1.74804639,691.28525
114.4,190.6427031,8.007055782,424068.899,1.744125233,694.0224301
114.6,192.0156262,8.087368034,426939.4435,1.74151117,697.3425536
114.8,193.6851032,8.168464742,427786.7515,1.745868415,700.347787
115,194.886574,8.250411736,428763.0259,1.747611378,702.5891801
115.2,196.4236553,8.333156437,430875.8838,1.74761156,705.8570087
115.4,198.0944023,8.416722515,430927.389,1.75371163,708.7031587
115.6,199.5431277,8.501145052,431242.8022,1.757633149,710.9914151
115.8,201.137982,8.586404691,433925.1626,1.755019112,714.1906008
116,202.4011142,8.672546028,437006.0773,1.75109792,717.2524832
116.2,204.170214,8.759514435,439629.0861,1.747612495,719.9079545
116.4,205.9508097,8.847355932,444713.3822,1.738027199,723.6367061
116.6,207.5251667,8.936095518,453253.4393,1.717984956,728.0355683
116.8,209.2847048,9.025712561,459433.7114,1.704478306,731.6030543
117,210.5978298,9.116263877,465187.1299,1.693585832,735.6652143
117.2,212.3737014,9.207689842,470227.8895,1.686614756,740.0880555
117.4,213.8352928,9.300058218,472569.746,1.686179221,743.4201749
117.6,215.6590717,9.393327134,469248.92,1.704479054,746.7348726
117.8,217.0530525,9.487565692,464859.5479,1.724521662,748.8302686
118,219.0045131,9.582708794,460520.7898,1.745871457,751.0869505
118.2,220.8145447,9.678818503,455076.9192,1.771578295,753.249917
118.4,222.3443611,9.775915163,451380.6721,1.789442406,754.7874334
118.6,223.9837205,9.873978955,452479.0644,1.792492547,757.4745047
118.8,225.896337,9.97300731,454414.4522,1.79074996,759.7420819
119,227.4123875,10.07306064,457519.3093,1.785957385,762.659058
119.2,229.5008678,10.17407582,461718.998,1.778114939,766.0217155
119.4,230.9301689,10.27615598,466125.1948,1.769836705,769.4693395
119.6,232.8288473,10.37922611,467214.3099,1.771144053,771.9286915
119.8,234.4597649,10.48335206,469824.3517,1.768965723,775.1289779
120,236.3182227,10.58850695,472365.1065,1.766351714,778.1887114
120.2,237.9429892,10.69473609,475843.8413,1.760252028,781.1950456
120.4,239.5360066,10.80203487,480982.2877,1.750666689,785.001165
120.6,241.3125137,10.91039771,487441.4248,1.738467134,789.1788546
120.8,243.3955035,11.01982602,490786.0575,1.734981734,792.3671718
121,245.12928,11.13038021,494016.0355,1.733239116,795.8769202
121.2,246.7373922,11.24205482,495365.848,1.73759637,799.3703186
121.342,248.203966,11.32199966,495574.166,1.741953608,801.4439249
121.6,250.0815265,11.3246865,495041.7394,1.751975076,805.2162862
121.8,250.9345379,11.32462167,496754.4248,1.751975178,808.0351758
122,251.6977964,11.32456363,498370.7882,1.752846682,811.2474196
122.2,252.7502588,11.32448372,500025.2817,1.754153927,814.7059326
122.4,253.2650347,11.32444446,502088.9588,1.755025402,818.1513468
122.6,253.7847969,11.32440482,504469.3727,1.754154052,821.0530375
122.8,254.2189615,11.32437165,506747.5264,1.755461223,824.494089
123,254.6606055,11.32433792,509583.1187,1.75502557,827.9623851
123.2,254.9800857,11.32431342,512098.7278,1.754154196,830.9174606
123.4,255.3211732,11.32428729,515540.4375,1.751539998,834.662516
123.6,255.6223705,11.32426417,517764.5612,1.751975741,838.1689426
123.8,256.0390831,11.32423232,519312.2811,1.752847204,841.056464
124,256.0377798,11.32423207,520495.6207,1.755025737,844.3144454
124.2,256.3730499,11.32420638,520784.3204,1.759818549,847.7576729
124.4,256.5454351,11.324193,520077.4354,1.766354168,850.3651545
124.6,256.7568795,11.32417666,517802.9734,1.77811827,853.2254294
124.8,256.9716481,11.32416008,515764.568,1.788139546,855.3218764
125,257.311489,11.32413404,512834.6213,1.802517903,857.4226861
125.2,257.3833177,11.32412826,510642.5266,1.815589108,859.6749442
125.4,257.4605481,11.32412207,509636.9252,1.824738956,861.974057
125.6,257.8095306,11.32409534,510090.4998,1.828224652,863.9179638
125.8,258.0317786,11.32407819,511359.7495,1.829967506,866.3478382
126,258.1006986,11.32407264,511631.5955,1.833453168,868.4824148
126.2,258.2348557,11.32406214,510897.067,1.839988783,870.6900026
126.4,258.2892324,11.32405768,510598.7947,1.844345856,872.4769875
126.6,258.5646673,11.32403651,509247.8146,1.852624316,874.4099973
126.8,258.6788793,11.32402753,509242.6092,1.856109984,876.0858421
127,258.5736952,11.32403513,511687.0815,1.853060025,878.2672705
127.2,258.8773857,11.32401183,515047.3934,1.848267292,880.9466711
127.4,259.1087752,11.32399399,516970.5198,1.846524495,882.9624874
127.6,259.2055353,11.32398632,519681.9995,1.843474562,885.5830389
127.8,259.2948159,11.32397922,519849.2096,1.846524519,887.3667629
128,259.2727364,11.32398054,517699.2136,1.856545769,888.9696016
128.2,259.9121695,11.32393186,515398.8163,1.867002809,890.5463136
128.4,259.5418817,11.3239595,514348.0962,1.873538361,892.0619668
128.6,259.8065131,11.32393914,514264.9313,1.877024048,893.8522357
128.8,260.0836101,11.32391785,515864.9711,1.874845551,895.5433428
129,259.9543256,11.32392727,519182.3523,1.868309936,897.7585484
129.2,260.1524733,11.32391194,522712.7595,1.861774363,900.2309157
129.4,260.3581004,11.32389605,524798.1872,1.859160149,902.2031444
129.6,260.51802,11.32388361,526394.0667,1.85916017,904.4673948
129.8,260.5167166,11.32388336,525563.8797,1.866131477,906.2391248
130,260.6782983,11.3238708,522250.6051,1.879638399,907.322219
130.2,260.931295,11.32385132,518587.2388,1.893581044,908.0152287
130.4,260.6923125,11.32386904,515199.9696,1.907087927,908.8487817
130.6,260.9328435,11.32385051,513634.9765,1.914059258,909.6049958
130.8,260.8426182,11.32385698,513907.8915,1.915802075,910.8700465
131,261.0598799,11.3238402,516615.1419,1.910137917,912.4521891
131.2,261.373543,11.32381614,521307.7012,1.899245291,914.5606281
131.348,261.5762181,11.32380057,524786.7497,1.890966897,916.0654097
132.1,261.6502842,11.20322852,1.7977E+308,1.835632157,0
132.3,261.3902375,11.09004114,1.7977E+308,1.738033835,0
132.5,261.1426565,10.97685281,1.7977E+308,1.568543918,0
132.7,261.0139151,10.8636555,1.7977E+308,1.33544085,0
132.9,260.9217398,10.75045543,1.7977E+308,1.036981796,0
133.1,260.5893921,10.63727351,1.7977E+308,0.705844735,0
133.3,260.2902863,10.52408908,1.7977E+308,0.426992485,0
133.5,260.3019916,10.41088115,1.7977E+308,0.235281573,0
133.7,260.0377897,10.29769408,1.7977E+308,0.109362359,0
133.9,259.5359087,10.18452497,1.7977E+308,0.046184899,0
134.1,259.5941527,10.07131353,1.7977E+308,0.044006366,0
134.3,259.3565443,9.958124449,1.7977E+308,0.045749192,0
134.5,259.157164,9.844932478,1.7977E+308,0.05097767,0
134.7,258.9793909,9.731738874,1.7977E+308,0.055334735,0
134.9,258.6270982,9.618558463,1.7977E+308,0.054899027,0
135.1,258.538247,9.505358137,1.7977E+308,0.047056309,0
135.3,258.2266755,9.392174647,1.7977E+308,0.037035057,0
135.5,257.9491769,9.278988581,1.7977E+308,0.024399566,0
135.7,257.7963352,9.165793093,1.7977E+308,0.020042501,0
135.9,257.5204988,9.052606902,1.7977E+308,0.02265674,0
136.1,257.3925884,8.939409529,1.7977E+308,0.022656739,0
136.3,257.0228438,8.826230436,1.7977E+308,0.014814021,0
136.5,256.8409155,8.713037146,1.7977E+308,0.007407011,0
136.7,256.6889049,8.599841595,1.7977E+308,0.007842717,0
136.9,256.5967295,8.486641521,1.7977E+308,0.012199782,0
137.1,256.2776787,8.373458596,1.7977E+308,0.015685434,0
137.3,255.8057154,8.26028723,1.7977E+308,0.016992553,0
137.5,255.7143711,8.147087093,1.7977E+308,0.023092443,0
137.7,255.5432465,8.033892987,1.7977E+308,0.02832092,0
137.9,255.2723963,7.920706418,1.7977E+308,0.033549397,0
138.1,254.9899115,7.80752073,1.7977E+308,0.03311369,0
138.3,254.7282029,7.694333471,1.7977E+308,0.028320919,0
138.5,254.3784034,7.58115287,1.7977E+308,0.019171083,0
138.7,254.3444013,7.467948399,1.7977E+308,0.012635486,0
138.9,254.0885099,7.3547607,1.7977E+308,0.009149835,0
139.1,253.7952216,7.241575828,1.7977E+308,0.006535596,0
139.3,253.3573313,7.128401886,1.7977E+308,0.007407009,0
139.5,253.3972922,7.015191824,1.7977E+308,0.014378311,0
139.7,253.1040039,6.902006952,1.7977E+308,0.018735375,0
139.9,252.7475561,6.788826854,1.7977E+308,0.018735374,0
140.1,252.5913903,6.675631617,1.7977E+308,0.01437831,0
140.3,252.2831431,6.562447875,1.7977E+308,0.016121136,0
140.5,252.1535708,6.449250628,1.7977E+308,0.033113684,0
140.7,251.6890871,6.336078697,1.7977E+308,0.043570635,0
140.9,251.4838896,6.222887166,1.7977E+308,0.047056285,0
141.1,251.4208009,6.109684893,1.7977E+308,0.041827809,0
141.3,251.0601979,5.996505109,1.7977E+308,0.027885205,0
141.5,250.8707903,5.883312385,1.7977E+308,0.015249721,0
141.7,250.6294423,5.770123587,1.7977E+308,0.020913903,0
141.9,250.4454365,5.656930454,1.7977E+308,0.026578085,0
142.1,250.1425912,5.543746304,1.7977E+308,0.028756616,0
142.3,249.9573388,5.430553266,1.7977E+308,0.023963846,0
142.5,249.6594798,5.317368739,1.7977E+308,0.016121133,0
142.7,249.2693748,5.204191186,1.7977E+308,0.012635482,0
142.9,249.3550882,5.090694648,1.7977E+308,0.01111051,0
143.1,249.246337,4.97721281,1.7977E+308,0.009149832,0
143.3,248.6874397,4.864614049,1.7977E+308,0.005010622,0
143.5,248.3567545,4.751432004,1.7977E+308,0.002614237,0
143.7,248.1490639,4.638240661,1.7977E+308,0.004792769,0
143.9,247.6629732,4.525070363,1.7977E+308,0.006535593,0
144.1,247.5275835,4.411873555,1.7977E+308,0.013506893,0
144.3,247.1038212,4.298698546,1.7977E+308,0.022656723,0
144.5,247.0631708,4.185494577,1.7977E+308,0.035292202,0
144.7,246.2853832,4.072346328,1.7977E+308,0.038342144,0
144.9,246.3793621,3.959132183,1.7977E+308,0.033549376,0
145.1,246.2223653,3.845937008,1.7977E+308,0.028320902,0
145.3,245.928246,3.732752199,1.7977E+308,0.025270958,0
145.5,245.581771,3.619571348,1.7977E+308,0.026142369,0
145.7,245.3192315,3.506384151,1.7977E+308,0.025270957,0
145.9,245.0367469,3.393198462,1.7977E+308,0.023092425,0
146.1,244.8323805,3.280006869,1.7977E+308,0.022221013,0
146.3,244.5939413,3.166817851,1.7977E+308,0.018299657,0
146.5,244.1460788,3.053644663,1.7977E+308,0.01350689,0
146.7,244.1644326,2.940436234,1.7977E+308,0.012635477,0
146.9,243.254509,2.827297973,1.7977E+308,0.017428243,0
147.1,243.3850538,2.714081064,1.7977E+308,0.023092423,0
147.3,243.1233454,2.600893805,1.7977E+308,0.029628014,0
147.5,242.7951534,2.487711571,1.7977E+308,0.033113661,0
147.7,242.2957661,2.374542278,1.7977E+308,0.036163603,0
147.9,242.1894632,2.261343272,1.7977E+308,0.040084957,0
148.1,241.8870336,2.148159091,1.7977E+308,0.042263486,0
148.3,241.474075,2.034983264,1.7977E+308,0.039649249,0
148.5,241.0694269,1.92180681,1.7977E+308,0.035727893,0
148.7,240.834312,1.808617541,1.7977E+308,0.031370833,0
148.9,240.449609,1.695439579,1.7977E+308,0.02396383,0
149.1,240.1047961,1.582258602,1.7977E+308,0.026578065,0
149.3,239.7757731,1.469076431,1.7977E+308,0.029628007,0
149.5,239.5198821,1.355888732,1.7977E+308,0.033113654,0
149.7,238.9939015,1.242721449,1.7977E+308,0.039213536,0
149.892,238.6311021,1.134070113,1.7977E+308,0.045313418,0
225.1,237.8724259,1.024185432,1.7977E+308,0.005664178,0
225.3,237.6855115,0.910992519,1.7977E+308,0.012199767,0
225.5,237.1844623,0.797823352,1.7977E+308,0.016556826,0
225.7,236.8022525,0.684645202,1.7977E+308,0.016992532,0
225.9,236.1707293,0.571485897,1.7977E+308,0.00958553,0
226.1,235.8267476,0.458304857,1.7977E+308,0.004792765,0
226.3,235.392182,0.345130664,1.7977E+308,0.017863942,0
226.5,234.6451436,0.231980091,1.7977E+308,0.02744947,0
226.7,234.0260862,0.118819844,1.7977E+308,0.033549351,0
226.9,233.1452498,0.005679385,1.7977E+308,0.035292172,0
226.906,233.0268114,0.002292127,1.7977E+308,0.035292172,0
,,,,,