File: TestGB_12.csv
Time On Sample,Displacement Into Surface,Load On Sample,Harmonic Contact Stiffness,Harmonic Displacement,Harmonic Load
0,0,0,810.8885374,0.261852366,2.230420003
0.2,-0.022971065,0.000760264,7940.962393,0.224382643,2.299065074
0.4,0.219985421,0.001498838,9712.111618,0.23745348,2.348097296
0.6,0.506155325,0.002232714,10855.76446,0.228739596,2.411294382
0.8,0.287063352,0.003004797,12698.60368,0.203469314,2.514806766
1,0.440269604,0.003748726,15542.89752,0.176020565,2.682605846
1.2,0.683226326,0.004485869,18058.46595,0.158157094,2.825344054
1.4,0.701806882,0.005239978,21719.08034,0.139422232,3.001859957
1.6,0.633130039,0.006000686,25323.56458,0.126787092,3.178375854
1.8,0.816253118,0.006742353,26361.64535,0.126351399,3.322203655
2,1.070844167,0.007478615,25859.28969,0.140729319,3.720998889
2.2,0.610755558,0.008268921,25433.82457,0.154671538,4.088195478
2.4,0.82047137,0.009008576,26099.54178,0.162949735,4.475005062
2.6,1.198053804,0.009735537,27040.58974,0.168178074,4.808424089
2.8,1.222451522,0.010489206,30617.24878,0.16294974,5.183247992
3,0.892002172,0.011271598,37641.30803,0.154671541,5.866429844
3.2,1.033989925,0.012014484,43046.76748,0.151839529,6.451002622
3.4,1.185534141,0.012758538,44930.02923,0.162514046,7.126012586
3.6,1.280568804,0.013506865,43615.09295,0.181684604,7.72311582
3.8,1.391392902,0.014253997,41599.26045,0.203033636,8.226513085
4,1.380056635,0.015010368,40986.79676,0.229611001,9.165752055
4.2,1.352930933,0.015767931,40117.13789,0.257495448,10.05704843
4.4,1.419295307,0.016518426,40267.21819,0.279280175,10.94834484
4.6,1.29286237,0.0172835,41300.23293,0.295400869,11.88758376
4.8,1.457287445,0.018026579,41820.8279,0.31065018,12.66556139
5,1.34581292,0.018790521,42626.03333,0.333741986,13.91206876
5.2,1.230183281,0.019554777,42497.43258,0.359883653,15.0158379
5.4,1.416214951,0.020296222,41585.72525,0.39147151,16.01391566
5.6,1.390751295,0.021053661,39968.641,0.430030473,16.94334817
5.8,1.551852281,0.021796991,37867.05718,0.479917498,17.93434352
6,1.535114365,0.022553769,36595.97684,0.52501188,18.95366843
6.2,1.232920085,0.023332133,35329.07719,0.574681042,20.0073156
6.4,1.538619053,0.024064529,34148.92783,0.627400089,21.06641137
6.6,1.321604619,0.024836452,33243.02895,0.677069253,22.06339912
6.8,0.99572589,0.025618498,32492.58469,0.71889591,22.85880998
7,1.293114925,0.026349633,31381.14577,0.778586071,23.86233597
7.2,1.349090912,0.027104693,30386.4307,0.834790666,24.74055718
7.4,1.222243065,0.027866017,29170.76439,0.899273445,25.56211875
7.6,0.969910162,0.028640611,28050.22956,0.957220797,26.16358002
7.8,1.005110575,0.029397243,26842.15195,1.022139279,26.74107041
8,1.430061928,0.030116841,25407.32574,1.104921266,27.39265436
8.2,1.057230703,0.030900546,24068.17841,1.186396109,27.91021607
8.4,1.200880205,0.031645196,23150.40917,1.248700434,28.32317625
8.6,1.398130685,0.032385793,22249.13024,1.3162331,28.79170636
8.8,1.417542266,0.033139838,21769.05083,1.360673942,29.19594966
9,1.424488504,0.033894825,21514.1147,1.392479643,29.59474491
9.2,1.364121886,0.034654902,21462.39978,1.416007141,30.07526038
9.4,1.605416584,0.035392168,21447.18969,1.43387064,30.45553265
9.6,1.279122635,0.036172354,21713.98316,1.439970332,30.9611086
9.8,1.44562527,0.036915275,21918.14834,1.446070073,31.38932339
10,1.548139143,0.037663035,21988.40858,1.459576614,31.77068516
10.2,2.086109034,0.038377866,22225.63536,1.466112086,32.22831989
10.4,1.959260578,0.039142969,22738.13736,1.453912628,32.65980302
10.6,2.356787604,0.039868419,23435.09413,1.436920581,33.20569546
10.8,2.225784031,0.040633836,24279.48467,1.411214592,33.7047341
11,2.073173863,0.041400886,25775.43607,1.361109707,34.42278326
11.2,2.181504902,0.042148205,26959.82183,1.324075683,34.97303363
11.4,2.320583791,0.042893199,27992.74129,1.300112497,35.61590055
11.6,2.376560385,0.043644476,28716.40181,1.289655833,36.23152714
11.8,2.263008294,0.044408572,29164.3124,1.287913047,36.75780591
12,2.323971025,0.045159473,29530.19446,1.29444847,37.3897765
12.2,2.298507368,0.045916908,29542.93117,1.309262086,37.81908076
12.4,2.212379035,0.046678931,29842.4328,1.316668885,38.38567487
12.6,2.477773417,0.047414372,30250.70397,1.316233215,38.8640119
12.8,2.207989008,0.048190283,30838.03205,1.315361808,39.54065556
13,2.459255999,0.048926793,31105.73987,1.319283075,39.99066272
13.2,2.478667583,0.049680834,31485.11591,1.322332942,40.56706372
13.4,2.351819123,0.050445936,31720.60054,1.330611128,41.13583702
13.6,2.407795718,0.051197213,31784.26736,1.341939192,41.57712695
13.8,2.638287139,0.051935293,31708.47513,1.358495606,42.0064316
14,2.699249873,0.052686193,31838.26962,1.371130754,42.58501171
14.2,2.529188216,0.053454562,32065.43653,1.37853755,43.11782797
14.4,2.551923892,0.054208352,32123.83155,1.389429915,43.52860892
14.6,2.542249671,0.054964593,32360.21924,1.396401026,44.07232154
14.8,2.673018336,0.055710213,32649.98301,1.39814382,44.53976216
15,2.53952169,0.056475817,33011.14297,1.400322278,45.13795475
15.2,2.743420379,0.057215907,33392.06057,1.399886602,45.69038449
15.4,2.793579815,0.057967623,33883.51055,1.392479805,46.16436276
15.6,2.774764341,0.058724554,34273.9556,1.392044109,46.7374947
15.8,2.874785157,0.0594725,34672.72964,1.389865642,47.23871285
16,3.008046895,0.060217931,34869.53005,1.398579547,47.82818921
16.2,2.749896796,0.060992961,34968.03406,1.409907582,48.35664674
16.4,2.928033774,0.061734999,34961.52696,1.422542747,48.76415948
16.6,2.914204439,0.062491553,34957.23638,1.438227746,49.26646692
16.8,3.173781677,0.063227432,34790.5579,1.456962639,49.65327714
17,2.988761599,0.063996931,34733.46484,1.473954709,50.15885311
17.2,2.941691343,0.064755998,34596.91565,1.490075404,50.52822897
17.4,3.399883087,0.065476858,34456.79777,1.507503235,50.96080321
17.6,3.479959356,0.06622631,34474.31375,1.518395608,51.41407889
17.8,3.141200014,0.067007434,34659.41521,1.521009741,51.8106942
18,3.349253828,0.067747209,35094.02477,1.518395597,52.34024234
18.2,3.383623829,0.068500117,35686.45206,1.507067542,52.79242841
18.4,3.53516808,0.069244164,36674.70828,1.484847135,53.39606974
18.6,3.260397509,0.070020449,37642.04722,1.464805157,54.01387479
18.8,3.396152321,0.070765691,38324.03886,1.452605724,54.51618293
19,3.738831875,0.071495285,38929.90804,1.44607034,55.15905058
19.2,3.640238188,0.072258247,39190.08412,1.447813109,55.619953
19.4,3.447738896,0.07302831,39287.33023,1.456962677,56.14514188
19.6,3.758839576,0.073760291,39346.71589,1.468290769,56.689945
19.8,3.575066025,0.074529694,39530.87047,1.473083391,57.13232403
20,3.741568694,0.07527261,39859.11731,1.47787605,57.74032382
20.2,3.666659162,0.076033792,40020.93712,1.483104378,58.16417974
20.4,3.890917292,0.076776392,40068.97544,1.49530385,58.68719064
20.6,3.790244185,0.077551215,40076.59824,1.507938984,59.18078123
20.8,3.924749411,0.078315782,40007.28626,1.521009837,59.59592095
21,3.788339875,0.079108635,40025.08895,1.533644967,60.1298269
21.2,3.974366036,0.079885012,40130.31169,1.541051795,60.55967629
21.4,3.970502187,0.080683531,40496.66277,1.539309017,61.02330312
21.6,3.915529126,0.081494048,40929.57806,1.538001929,61.58771811
21.8,4.154321452,0.08229036,41211.1454,1.539309039,62.0300984
22,3.985911163,0.083125659,41636.78635,1.538437633,62.60758817
22.2,4.007388323,0.083954942,42069.12398,1.53408069,63.07611827
22.4,4.428586272,0.084762315,42379.43839,1.535823513,63.62419065
22.6,4.138842653,0.085631668,42712.70901,1.534080705,64.08291333
22.8,4.102144203,0.086490474,43209.86469,1.529288062,64.67347889
23,4.074585634,0.087357229,43604.20815,1.526673892,65.18559305
23.2,4.16295341,0.088223875,43890.41063,1.52928807,65.74347101
23.4,4.358106285,0.089091077,44304.54995,1.528416702,66.32641003
23.6,4.526665006,0.0899692,44555.76561,1.531030889,66.77423807
23.8,4.288852027,0.090886845,44855.07891,1.535387811,67.3582654
24,4.356023091,0.091790479,45179.17848,1.536694902,67.87582781
24.2,4.498815797,0.092697592,45638.26857,1.53495214,68.47620045
24.4,4.678172088,0.093610966,46021.79751,1.53408077,69.01228654
24.6,4.473178323,0.094565111,46525.38832,1.528852414,69.55817775
24.8,4.446853762,0.095510576,47126.21662,1.520574215,70.11714489
25,4.753351328,0.096447449,47724.50009,1.515345912,70.80904478
25.2,4.562897077,0.09742181,48070.84467,1.517088672,71.44210444
25.4,4.740168254,0.09838289,48220.60844,1.521881332,71.92262074
25.6,4.741260966,0.09936711,48142.78446,1.535823561,72.49684246
25.8,4.797615165,0.10035691,47847.7818,1.554558437,72.92723654
26,4.754245001,0.101364233,47366.02039,1.5815715,73.43499196
26.2,4.617383124,0.10238876,47116.40895,1.598127882,73.80109875
26.4,4.924285986,0.103389902,46834.05376,1.61816987,74.25655459
26.6,4.897115909,0.104426598,46685.0999,1.63341918,74.6847691
26.8,4.94141217,0.105468291,46728.65564,1.6403903,75.06939971
27,5.014792592,0.106518156,46998.23796,1.640826004,75.51504834
27.2,5.098143603,0.107577902,47320.03311,1.641261709,76.01953572
27.4,5.070135819,0.10865671,47769.39084,1.63777615,76.54472498
27.6,5.208330943,0.109733801,48288.9363,1.629933663,77.00344901
27.8,5.293338888,0.110825588,48817.65302,1.622526864,77.48178593
28,6.373910983,0.111852498,49296.91014,1.619041428,78.0832517
28.2,6.766394157,0.112942305,50093.35361,1.605099242,78.7130448
28.4,6.752505189,0.114074004,51093.0695,1.58549298,79.36680752
28.6,6.345540424,0.115246755,52108.82671,1.565450982,79.9660887
28.8,6.491204273,0.116389322,53501.89215,1.537130844,80.66561552
29,6.621907879,0.117544505,55726.4335,1.493125695,81.64952919
29.2,6.648731719,0.118719251,57461.35613,1.464805544,82.57460348
29.4,6.811841507,0.119895431,58584.19485,1.449556247,83.27413076
29.6,6.768855621,0.121099179,59533.59088,1.442149434,84.13927666
29.8,6.953568213,0.122297654,59708.67303,1.449556263,84.79195071
30,6.948805569,0.123522598,59505.52308,1.468726836,85.59716842
30.2,7.125204077,0.124745941,59494.1328,1.479183525,86.19318346
30.4,7.075562285,0.125998757,59742.27566,1.486154635,86.98641555
30.6,7.336721219,0.127240551,60234.04104,1.487461747,87.80362025
30.8,7.292892582,0.128518138,60865.94731,1.483976188,88.52058003
31,7.20751073,0.129811766,61542.9886,1.480054932,89.25933173
31.2,7.059800074,0.131123052,62228.60174,1.478747831,90.13101493
31.4,7.281061698,0.1324194,62355.8651,1.489204527,90.92424819
31.6,7.213956136,0.133750795,62171.75164,1.505325227,91.64338707
31.8,7.072887409,0.135100945,62036.58073,1.518396051,92.24375871
32,7.195250896,0.136444812,61940.05255,1.530595517,92.86156519
32.2,7.330077597,0.137801189,62053.60999,1.53974512,93.62864758
32.4,7.300359499,0.139183751,62392.43294,1.543666367,94.39899806
32.6,7.195847109,0.140585785,62961.11188,1.540616497,95.04513324
32.8,7.491054701,0.1419716,63598.46632,1.540180831,95.94623778
33,7.427257984,0.143398662,63910.50041,1.543230688,96.5792979
33.2,7.43742009,0.144834294,64406.89006,1.544537774,97.38887406
33.4,7.831512668,0.146255377,65093.33887,1.541487954,98.2300507
33.6,7.725326922,0.147728663,65449.97784,1.542795028,98.87291715
33.8,7.619969836,0.149216755,65977.76486,1.541052239,99.57244284
34,7.736493617,0.150702919,66777.23263,1.53625961,100.504056
34.2,8.08653259,0.152186327,67137.50919,1.5401809,101.3419634
34.4,8.194741396,0.153702976,67057.30391,1.551508976,101.9772035
34.6,8.300454703,0.1552351,67088.99462,1.562401357,102.7323004
34.8,8.324725283,0.156788718,67142.95881,1.570679561,103.3544649
35,8.528494434,0.158344348,67444.07317,1.57677931,104.1956408
35.2,8.579352791,0.159927235,67957.14365,1.575472232,104.8711963
35.4,8.326885081,0.161549009,68873.85232,1.568065395,105.7483269
35.6,8.90128308,0.163124319,69584.23771,1.562837121,106.4685586
35.8,8.825818233,0.164764881,70300.10818,1.560222945,107.3772886
36,8.70630654,0.166425164,70663.04524,1.562837102,108.1138612
36.2,9.090392387,0.168063978,70995.58626,1.567629786,108.9713818
36.4,8.712427106,0.169777207,71132.43495,1.573729473,109.6284116
36.6,8.727533212,0.171477584,71225.17906,1.582879066,110.4292715
36.8,8.912996405,0.173182126,71195.65863,1.592900067,111.0873938
37,9.081836408,0.174905063,71148.84151,1.60509954,111.8882546
37.2,9.176297058,0.176650979,71036.13366,1.615556226,112.4679247
37.4,9.209674726,0.178418881,71134.46341,1.622527347,113.1581896
37.6,9.322827798,0.180198652,71296.76701,1.627755698,113.8495446
37.8,9.35703081,0.182002231,71873.36623,1.623398755,114.5458025
38,9.414499598,0.183822169,73102.94655,1.609456529,115.5373433
38.2,9.434569408,0.185663327,74170.71106,1.597257078,116.3142315
38.4,9.473749821,0.187521506,74916.69213,1.59420722,117.1968117
38.6,9.470545082,0.189401496,75350.0231,1.597257084,118.0140155
38.8,9.667613988,0.191285248,75176.09419,1.61032795,118.641629
39,9.833932026,0.193190216,74784.7259,1.627320067,119.2518089
39.2,9.743876252,0.195133917,74112.15847,1.650847577,119.8783311
39.4,9.806310219,0.197085363,73847.84186,1.663918429,120.4057006
39.6,10.22940525,0.199029178,74014.86582,1.66958251,121.1226627
39.8,10.14474182,0.201031032,74154.29556,1.67393945,121.7066908
40,10.19179241,0.20304304,74537.1421,1.673939456,122.3517373
40.2,9.967510629,0.205095757,75189.46299,1.669146789,123.1427892
40.4,10.3556899,0.207122645,75991.05566,1.659997243,123.824884
40.6,10.33791094,0.209200657,76834.26834,1.653026125,124.6693278
40.8,10.09159719,0.211316958,77622.92378,1.646054981,125.3819281
41,10.30816019,0.213419261,78514.82885,1.639955279,126.3266172
41.2,10.78358364,0.215523168,79003.9972,1.639519639,127.0217879
41.4,10.78407291,0.21768974,79065.47698,1.646926452,127.6483108
41.6,10.50575206,0.219888262,79120.33948,1.655640318,128.4143014
41.8,10.95207937,0.222059392,79408.78778,1.657818844,129.0724254
42,10.90726828,0.22428962,79662.38219,1.661304398,129.7523389
42.2,10.64347892,0.226558876,80086.61659,1.663047149,130.5695411
42.4,11.35073607,0.228782948,80574.26983,1.661740146,131.2451004
42.6,10.9884632,0.23110503,81188.17699,1.660433021,132.0917214
42.8,11.26524285,0.233407656,81315.03483,1.666532781,132.7411281
43,11.0338507,0.235754431,81583.17181,1.670018315,133.4177712
43.2,11.41699487,0.238089841,81914.06835,1.673503918,134.2164541
43.4,11.63600815,0.240461261,82106.12138,1.677425198,134.8397096
43.6,11.81886811,0.242859295,82276.83848,1.682653558,135.5653882
43.8,11.92194598,0.245287469,82768.66736,1.680910792,136.2583775
44,12.09898108,0.24773433,83058.56061,1.682653593,136.9393815
44.2,12.05994614,0.25022218,83422.74426,1.683960674,137.7108219
44.4,12.50788706,0.25269815,83713.82826,1.685267811,138.3504231
44.6,12.70236183,0.255218243,84220.52046,1.684396445,139.171987
44.8,12.35916025,0.257804457,84584.48669,1.684396406,139.8431811
45,12.88686737,0.260350436,85151.88691,1.683525079,140.7214067
45.2,12.89434958,0.262961622,85686.58423,1.681346606,141.3926035
45.4,13.29988799,0.265568764,86540.64572,1.676118315,142.2686487
45.6,13.32813745,0.268230886,87292.93535,1.671325675,142.999774
45.8,13.28990076,0.270924751,88249.56417,1.663483163,143.7919167
46,13.24418058,0.273646144,89832.09557,1.647798143,144.8847904
46.2,13.39042254,0.276380263,90955.82975,1.636905787,145.7150709
46.4,13.4552198,0.279148096,92454.99669,1.622527863,146.847171
46.6,13.52499878,0.281943343,93451.93601,1.614685364,147.7232138
46.8,13.8748283,0.284745416,94032.33201,1.616428183,148.8302551
47,13.94958448,0.287596569,93836.65991,1.627320565,149.5755462
47.2,13.89386539,0.290486232,93614.27472,1.639084332,150.2859679
47.4,13.80822483,0.293407163,93157.51242,1.65651212,151.0879169
47.6,13.91537713,0.296342737,92841.92942,1.669147278,151.7220677
47.8,14.1405301,0.299298893,92864.96215,1.676554124,152.423775
48,13.95515261,0.302316021,93259.69662,1.680475362,153.3532078
48.2,14.05065634,0.305342001,93517.61597,1.683960931,154.0527346
48.4,14.18272027,0.308395746,94135.18844,1.683089556,154.9701837
48.6,14.51838017,0.311464582,94608.08278,1.682653898,155.6860569
48.8,14.23741549,0.314611271,94816.83253,1.686575124,156.3953878
49,14.41517094,0.317754572,94898.25744,1.69398196,157.2954031
49.2,14.25303263,0.320955362,95190.58746,1.695289027,157.9633299
49.4,14.34933762,0.324168558,95507.22533,1.698338905,158.8295668
49.6,14.43400315,0.327414924,95755.87352,1.701824474,159.6576675
49.8,14.91173774,0.33066416,96218.10578,1.700953136,160.3898859
50,15.00137902,0.333975544,96936.14642,1.697467596,161.2125386
50.2,14.83672173,0.337339448,97389.51706,1.698774659,162.0907592
50.4,15.05433004,0.340708087,97463.75933,1.704438715,162.7543293
50.6,15.18550647,0.344117235,97764.6861,1.708359992,163.5606395
50.8,15.08814592,0.347577898,98052.0544,1.711409845,164.2688822
51,15.43371554,0.351039739,98416.15685,1.713152662,165.0000092
51.2,15.33385085,0.354570191,99069.93208,1.711845567,165.8989337
51.4,15.7525394,0.358096796,99830.25465,1.706617283,166.6485856
51.6,16.22274583,0.36165476,100794.4432,1.700081908,167.6314124
51.8,16.3339443,0.365275579,101584.579,1.694853582,168.4529758
52,16.35621745,0.36893937,102301.5271,1.69093233,169.3115853
52.2,16.34524378,0.372642557,103276.2526,1.6848326,170.3379932
52.4,16.70822495,0.376354611,104036.1294,1.680911388,171.1791716
52.6,17.12687882,0.380099646,105026.3556,1.675247402,172.2099421
52.8,17.31533308,0.383899852,105872.8989,1.670890474,173.1273913
53,17.5669391,0.387733337,107019.7053,1.663047993,174.1211136
53.2,17.79028418,0.391607541,108353.7141,1.653462728,175.2553944
53.4,17.74769541,0.395540813,109746.5784,1.644313128,176.4910067
53.6,17.97518315,0.399493118,110493.3392,1.64213468,177.4117255
53.8,18.15446519,0.40348882,111400.7664,1.638213445,178.4119848
54,18.1251538,0.407540626,111779.3247,1.643006089,179.5843996
54.2,17.99860615,0.411640397,112074.3303,1.646491636,180.4942195
54.4,18.18202392,0.415757749,112308.9684,1.652155694,181.6001707
54.6,18.48177847,0.419907691,112571.379,1.655205594,182.4391695
54.8,18.5376208,0.424118115,112473.9911,1.663919503,183.3010478
55,18.59096332,0.428371129,112696.2538,1.670890632,184.4440447
55.2,18.53211082,0.432675292,112440.8832,1.681783003,185.2089472
55.4,18.64485791,0.437009678,112303.2469,1.693111089,186.1285755
55.6,18.99153134,0.441369907,112502.0372,1.697903776,186.910915
55.8,19.44623094,0.44576576,113197.3743,1.69616105,187.7880516
56,19.33873576,0.450248301,114065.121,1.694418258,188.9277781
56.2,19.36918341,0.454765425,114836.0682,1.691804092,189.8256134
56.4,19.52884809,0.459318177,115622.1657,1.690061331,190.9359229
56.6,19.70678803,0.463915281,115785.8756,1.694418304,191.7280678
56.8,20.02474817,0.468548094,116065.9318,1.697468208,192.5975756
57,20.1415931,0.473242588,116537.5222,1.699646698,193.6839137
57.2,20.32241941,0.477979317,116846.575,1.701825196,194.4978511
57.4,20.6121023,0.482755488,117577.4883,1.70095384,195.5645777
57.6,20.8544092,0.487583121,118228.2343,1.699646784,196.4220996
57.8,20.86526816,0.492476904,118642.4503,1.702260958,197.3035909
58,21.42667283,0.497378054,119099.0674,1.705746585,198.4269794
58.2,21.69180955,0.502350941,119773.906,1.704003837,199.3204587
58.4,21.89378049,0.507378627,120831.8141,1.698775519,200.4612778
58.6,21.76333371,0.512482028,121959.429,1.690932992,201.4353839
58.8,22.07539919,0.5176031,123096.7044,1.683526211,202.502111
59,22.03136261,0.522802604,124341.6261,1.677426474,203.8423254
59.2,22.17014095,0.528053757,125103.2025,1.675248015,204.8229718
59.4,22.36334721,0.533327019,125327.6748,1.681347771,205.9387298
59.6,22.4460167,0.538675015,124971.7879,1.693547248,206.8485518
59.8,22.72521491,0.54406171,124749.7823,1.702261185,207.563336
60,22.72268508,0.549537796,125014.0966,1.707925224,208.6834501
60.2,22.79494311,0.555035441,125156.3865,1.712717881,209.5224475
60.4,23.4808971,0.560583944,125944.4224,1.710975181,210.6098815
60.6,23.32917865,0.566195646,127452.7208,1.70138987,211.8738221
60.8,23.87592272,0.571838807,128690.1274,1.693983115,212.9383727
61,23.78027597,0.577587361,129269.6964,1.694854496,213.9822144
61.2,24.00913509,0.583368865,129848.693,1.696597304,215.1393779
61.4,24.03022885,0.589224388,130124.4181,1.700518565,216.0470199
61.6,23.82028852,0.595156075,129973.558,1.710975228,217.0538136
61.8,24.16463197,0.601105301,129814.4906,1.72012487,217.8873658
62,24.43001859,0.607120386,130338.9805,1.721431988,218.8516696
62.2,24.27572831,0.613227674,130646.2298,1.724481837,219.6884854
62.4,24.72059686,0.619350839,130567.7415,1.733195797,220.6745836
62.6,25.07653601,0.625542387,130871.0379,1.736681402,221.6813827
62.8,25.59534608,0.631783802,131432.1231,1.736681465,222.660944
63,26.13741489,0.638086099,131918.1311,1.736681531,223.511932
63.2,25.92573446,0.644508787,133743.9256,1.722739257,224.7965758
63.4,26.13038701,0.650964533,135792.3571,1.70618286,225.9722623
63.6,26.11314572,0.657501998,138485.8788,1.685269484,227.4955311
63.8,26.24963353,0.664093408,140662.7489,1.669584469,228.8150452
64,26.41104154,0.67074918,142465.8558,1.658692105,230.1759651
64.2,26.76772971,0.677456839,143252.5202,1.659999233,231.5761124
64.4,26.96651253,0.684243793,143466.6281,1.665227601,232.6493767
64.6,27.33315148,0.691086166,142964.8702,1.679169895,233.8435894
64.8,27.65656625,0.698000483,142230.1705,1.69354788,234.7643102
65,28.24340476,0.704964354,141949.6273,1.703133248,235.7384245
65.2,28.33743457,0.712035653,142125.5038,1.7087973,236.9402602
65.4,28.56441702,0.719167891,142630.5815,1.709233023,237.9219983
65.6,28.61604192,0.726384952,143654.3374,1.706183167,239.2186311
65.8,28.87541144,0.733658741,144359.4746,1.7061832,240.306061
66,29.17881366,0.741002344,145020.1339,1.707054629,241.4348965
66.2,29.69494647,0.748403568,145020.9564,1.715332903,242.5789889
66.4,29.80054127,0.755910393,144414.0633,1.727968085,243.3885676
66.6,30.00667806,0.763485011,143985.898,1.739296188,244.3539611
66.8,30.20366149,0.771136422,144337.9696,1.741474694,245.2746806
67,30.29426152,0.778872854,145033.8733,1.741039006,246.3043595
67.2,30.35659439,0.786688945,146649.6102,1.732325104,247.6097084
67.4,30.39481505,0.794585471,148736.6828,1.717947163,248.7799459
67.6,30.85019754,0.80252958,151288.9591,1.70182648,250.3555219
67.8,31.11193857,0.810568287,152957.2785,1.692676907,251.606393
68,31.09194938,0.818709044,154541.7066,1.684834394,252.9564149
68.2,31.48330445,0.826900447,155825.062,1.68134887,254.4949436
68.4,31.40013126,0.835210288,156167.2456,1.686141512,255.8340686
68.6,31.62608603,0.843580102,155938.2538,1.694855449,256.8572117
68.8,31.69496375,0.852045931,155132.217,1.709233409,257.8073492
69,32.0629969,0.860574019,154799.7386,1.720561536,259.0538625
69.2,32.62298316,0.869173355,154446.995,1.730146905,259.9549749
69.4,32.87547651,0.87788241,154756.0692,1.734068195,261.1448273
69.6,33.2559338,0.886669165,155522.5097,1.731889764,262.1734201
69.8,33.45521364,0.895557918,156480.6121,1.728404224,263.265208
70,33.8015707,0.904524785,157263.0053,1.728839962,264.6806118
70.2,34.08226247,0.913586826,158127.903,1.726225823,265.7887448
70.4,34.56903396,0.922724266,158885.4614,1.726225882,267.0450673
70.6,35.00592936,0.931957417,159770.1302,1.725354543,268.343883
70.8,35.39876572,0.94128657,160986.3521,1.720126244,269.515216
71,35.8879861,0.950702146,162606.2209,1.711848086,270.8510796
71.2,35.91763457,0.960247258,164055.2597,1.706619743,272.3351241
71.4,35.98466393,0.969885464,165652.2887,1.700084318,273.897621
71.6,36.29101313,0.979602245,166373.7642,1.700084355,275.0656822
71.8,36.35053237,0.989435355,166982.986,1.70139145,276.3111036
72,36.77319388,0.999339703,167818.5778,1.702698587,277.889949
72.2,36.64362332,1.009385877,168807.9817,1.700520095,279.1157547
72.4,37.14810888,1.019484959,169926.027,1.699213068,280.6455692
72.6,37.61809075,1.029688257,171252.7503,1.694420471,281.9378493
72.8,37.55786229,1.040034294,172205.4917,1.693549074,283.2813332
73,37.8541271,1.050457216,173269.67,1.693549109,285.0007364
73.2,38.04067996,1.060993087,173846.6562,1.695291915,286.2570557
73.4,38.6069945,1.07160616,174209.9338,1.700084635,287.763989
73.6,38.88035573,1.082347959,174383.1401,1.704441625,288.9048107
73.8,39.25300732,1.093190178,174849.426,1.707055844,290.1665812
74,39.40168029,1.104158356,175697.4004,1.708362949,291.7563188
74.2,39.51875678,1.115239134,175821.8934,1.714027009,292.8993182
74.4,40.00894595,1.12640288,176161.8167,1.719691112,294.3256202
74.6,40.10313371,1.137708941,176402.2746,1.724048082,295.3803605
74.8,40.02403466,1.149141671,176415.5105,1.73058351,296.4405474
75,40.71278476,1.16063095,176719.5774,1.736247638,297.8723
75.2,41.00677947,1.172265703,178277.1392,1.729712237,299.2849796
75.4,41.78482791,1.183980609,180011.0482,1.721869806,300.7565045
75.6,42.13612611,1.195845623,181770.4501,1.71446302,302.4170698
75.8,42.61746087,1.207819851,182684.3154,1.711413207,303.4936095
76,42.85570157,1.219932881,183803.5401,1.710106149,305.2609553
76.2,43.38436633,1.232145589,183846.004,1.715770258,306.4148567
76.4,43.79168185,1.244490398,184088.6168,1.721434353,307.8934591
76.6,44.29911628,1.256951444,184960.4514,1.720563022,309.1650381
76.8,44.60708468,1.269552873,186544.2334,1.714463317,310.6218465
77,44.77957579,1.282291185,189266.9247,1.701828158,312.6594151
77.2,45.19138192,1.295139359,191167.2705,1.693114289,314.1859605
77.4,45.310231,1.308138929,192584.9213,1.690064433,316.027398
77.6,45.58778522,1.321257037,193230.2587,1.69180725,317.3806942
77.8,45.65049838,1.334523202,193722.4773,1.695728521,318.8015422
78,46.58492554,1.347923994,193397.9489,1.707928118,320.4435942
78.2,46.76144652,1.361450185,193365.9873,1.715334971,321.6247308
78.4,47.03227825,1.375036311,194267.7884,1.717077788,323.229727
78.6,47.14767565,1.38883883,194853.4894,1.719256282,324.5230933
78.8,47.18992075,1.402785556,195093.0926,1.724048944,325.8175466
79,47.69585597,1.416837077,195684.1565,1.727534573,327.4846534
79.2,47.70980148,1.431067248,196036.0786,1.730584448,328.7355229
79.4,48.14588538,1.445408252,196232.4249,1.735812853,330.1433022
79.6,48.80964746,1.459876002,196501.5978,1.739298501,331.3451492
79.8,49.2814195,1.474503722,197528.1542,1.737120078,332.6930012
80,49.78142306,1.489276341,199417.2566,1.730149002,334.5137426
80.2,50.33625074,1.504193295,200844.3667,1.725792108,335.9509436
80.4,51.29410222,1.519229462,201909.1343,1.725356527,337.5821021
80.6,51.66771846,1.534461065,202892.4017,1.725356572,339.203443
80.8,52.07953757,1.549842876,203149.947,1.729713583,340.502262
81,52.30933745,1.565392932,202800.9849,1.740170318,341.9939389
81.2,52.91806038,1.581070403,202994.6987,1.744091658,343.1402161
81.4,53.23174402,1.596927946,204432.0618,1.741041823,344.796424
81.6,53.48058233,1.612949504,205732.8398,1.737991981,346.1791402
81.8,54.23715205,1.629093396,207364.9868,1.732763718,347.6631982
82,54.34881971,1.645448431,209929.2331,1.723614113,349.6942282
82.2,54.86434003,1.661936813,211146.5899,1.72187139,351.1248918
82.4,55.46210562,1.67858461,212264.8419,1.721871462,352.8366755
82.6,55.8421158,1.695416127,213907.7522,1.718385938,354.7162553
82.8,55.90630912,1.712440711,215702.979,1.7122862,356.3550253
83,56.50233207,1.729595934,217349.7749,1.707493612,358.0755266
83.2,56.761762,1.746949065,219950.8504,1.697472637,360.2100723
83.4,57.73750894,1.764422014,221933.7759,1.690501609,361.9371171
83.6,58.01516585,1.782123655,223276.8825,1.689630248,363.9093132
83.8,58.29445654,1.800003076,223936.319,1.69224446,365.4881597
84,58.59864949,1.818060164,224905.72,1.69485867,367.5976445
84.2,58.95683033,1.836294526,225001.9921,1.700522775,369.064264
84.4,59.36401261,1.854708413,225207.3701,1.706622569,370.84578
84.6,59.91659514,1.873296223,225379.781,1.711415295,372.31785
84.8,60.18493691,1.892092575,225536.4221,1.716207984,373.759406
85,60.30781906,1.911088585,225240.453,1.726229018,375.50496
85.2,60.9766553,1.930233989,225471.0772,1.732764546,377.1895059
85.4,61.17343788,1.949607783,225552.7919,1.738428624,378.4425586
85.6,61.7125725,1.969150033,226446.4771,1.740171472,380.1728658
85.8,61.97993023,1.988909247,227335.9102,1.740607204,381.6830673
86,62.47246463,2.00884988,228585.3455,1.738428781,383.298965
86.2,62.90513328,2.028995393,229816.1151,1.73712174,385.1480361
86.4,63.74164873,2.049312692,231096.789,1.73407197,386.6822214
86.6,64.26898984,2.069857594,232819.1371,1.72971507,388.6424361
86.8,64.99823764,2.090593705,234760.3949,1.7236154,390.4283146
87,65.59698117,2.111547971,236492.5367,1.719694204,392.2240021
87.2,66.16494327,2.132715044,238949.915,1.713158824,394.4380964
87.4,66.467774,2.154115082,240398.9133,1.712723164,396.4375325
87.6,67.16115319,2.175700484,241227.9754,1.714466033,398.0087607
87.8,67.5195941,2.197528125,241074.1068,1.722308615,399.5418467
88,68.13063236,2.219555816,241263.6277,1.729279834,401.4998846
88.2,68.92030626,2.241791315,240589.5557,1.739300951,402.7834584
88.4,69.29027604,2.264282147,240324.1531,1.74801493,404.4679995
88.6,69.74081952,2.286992839,239657.3355,1.757600311,405.5728714
88.8,70.51210323,2.309907254,239978.9249,1.761521676,406.9392562
89,71.01991478,2.333071869,241394.6351,1.759778951,408.8221092
89.2,71.38724576,2.356479953,244068.352,1.749757973,410.8869256
89.4,71.94152049,2.380108923,246314.9252,1.741479803,412.6335782
89.6,72.54894319,2.403971601,250185.3092,1.724487704,415.0339969
89.8,72.88416622,2.428095791,252793.7321,1.714902416,417.0236293
90,73.46325726,2.452443677,254066.2266,1.714031092,418.9075744
90.2,73.54951027,2.477073504,254767.553,1.717516678,420.8634236
90.4,74.12187489,2.501913986,255885.1262,1.718823837,422.8595985
90.6,74.67799483,2.527005298,255976.0345,1.724923659,424.4221081
90.8,75.26565374,2.552346371,255924.9209,1.731459182,425.9737223
91,76.00119509,2.577930849,256922.1601,1.733637755,428.1246254
91.2,76.54181965,2.603787318,257901.9839,1.734073517,429.7546911
91.4,77.27810993,2.629888605,258230.1726,1.739301969,431.604862
91.6,77.63956517,2.656280523,258471.0637,1.74540177,433.4245166
91.8,78.56441495,2.682894757,258639.8855,1.749323154,434.6089396
92,78.67730831,2.70983818,258844.5198,1.755858623,436.5157588
92.2,79.29334583,2.737014142,259083.1845,1.761087062,438.2667721
92.4,79.84493536,2.764467924,259702.2686,1.762829918,439.7105169
92.6,80.42972216,2.792195119,261007.6011,1.761522899,441.5759396
92.8,81.55837234,2.820159564,262636.724,1.75803746,443.2997249
93,82.08282075,2.848450888,264829.1555,1.751937766,445.21091
93.2,82.71068694,2.877018678,267664.4411,1.743659599,447.5089093
93.4,83.35305054,2.905872359,269964.931,1.736688524,449.35799
93.6,83.81835912,2.93502947,272117.6879,1.732767307,451.5971471
93.8,84.72157288,2.964446223,273924.0434,1.729281839,453.5116097
94,85.50050102,2.994168011,274787.5218,1.731024721,455.3704998
94.2,86.31428492,3.0241857,276123.6976,1.731024819,457.6249193
94.4,86.98591511,3.054515927,277018.9613,1.732331991,459.3857421
94.6,87.6624831,3.085150265,278615.9755,1.730589284,461.6358017
94.8,87.98789281,3.116119147,279999.7763,1.729282232,463.5807616
95,88.73998599,3.147366882,281195.6129,1.72971802,465.4745194
95.2,89.216959,3.178949358,282756.9282,1.730153775,467.780143
95.4,89.94152797,3.210830517,284306.7748,1.728411074,469.6314051
95.6,90.55384434,3.243121663,285915.2172,1.728411148,471.9544683
95.8,91.16403131,3.275739211,287081.9212,1.729282616,473.8885387
96,91.8236255,3.308598275,288535.8898,1.728411301,475.9697088
96.2,92.46698883,3.341621129,290155.8818,1.727104286,478.3396237
96.4,93.22495484,3.375134023,290637.7814,1.730154259,480.1004512
96.6,94.04934964,3.40897855,292213.7176,1.728847266,482.5074169
96.8,94.75983951,3.443171895,294164.1137,1.724490377,484.6594141
97,95.4519922,3.477710067,295990.0676,1.721004881,486.8081405
97.2,95.88563986,3.512615001,297826.2337,1.718826446,489.2706687
97.4,96.63169855,3.547846891,299531.1107,1.716212351,491.3736319
97.6,97.47410035,3.583425326,300842.5768,1.717083846,493.8285425
97.8,98.22087707,3.619368522,301414.8711,1.720569516,495.8486987
98,98.64598829,3.655697351,302427.6426,1.72361945,498.4103822
98.2,99.57963113,3.692352461,303548.4953,1.724055259,500.3651646
98.4,100.8265133,3.729352178,304571.5107,1.726233896,502.6479269
98.6,101.7176562,3.766750634,305780.2713,1.726234003,504.6005297
98.8,102.7342248,3.804515315,307445.0351,1.724491334,506.778685
99,103.5238621,3.842676765,308846.8512,1.726234219,509.4286375
99.2,104.2270116,3.881228138,309239.9077,1.730591281,511.2722752
99.4,104.6550289,3.920187562,310460.7665,1.732769822,513.6694272
99.6,105.3813236,3.959515276,310250.102,1.740612469,515.4041052
99.8,106.3510471,3.999219387,309004.7459,1.754119217,516.9851544
100,106.9791542,4.039348249,308378.4183,1.765447436,518.9682615
100.2,107.7193863,4.079871298,308478.6867,1.771111599,520.563469
100.4,108.7745139,4.12077734,308415.746,1.778082894,522.3962209
100.6,109.7622628,4.162099287,310661.3576,1.773290339,524.6909653
100.8,110.5014681,4.203855359,312693.6999,1.768062056,526.7187491
101,111.6220492,4.246001912,314949.25,1.761962431,528.798846
101.2,112.3104277,4.288604811,317487.6498,1.755427041,531.3147746
101.4,113.2405678,4.331617362,319228.9779,1.752377266,533.3403843
101.6,114.0451539,4.375071585,319960.1036,1.755862955,535.5163583
101.8,114.7640745,4.418968882,321075.6662,1.757170134,537.4253751
102,115.3582706,4.463316685,321606.4332,1.76109149,539.2646538
102.2,116.6496298,4.508057206,321722.499,1.768498515,541.3534716
102.4,117.2627974,4.553298632,322664.7093,1.771112779,543.4433614
102.6,118.2299115,4.598967708,323890.0899,1.770677201,545.2772022
102.8,119.2725764,4.645089856,324333.3678,1.773727212,547.0848946
103,120.0334486,4.691696785,325942.8076,1.772420215,549.4700734
103.2,120.7900913,4.73877242,328325.0034,1.765884833,551.55343
103.4,121.7660507,4.786304214,331429.6944,1.757170992,554.20448
103.6,122.6546761,4.834320338,334156.3997,1.749764223,556.3848159
103.8,123.7975202,4.882799458,338793.702,1.734950622,558.9672254
104,124.9461041,4.931765331,345422.6061,1.714472939,562.6218127
104.2,126.1901784,4.981215922,350161.1367,1.701402132,565.4090707
104.4,126.8325078,5.031209151,355005.6362,1.690945447,568.8958465
104.6,127.8030144,5.081679465,357100.4085,1.689638466,571.423771
104.8,128.9454638,5.13264388,357540.2464,1.69530268,573.89831
105,129.5700999,5.184159716,356409.9535,1.709245105,576.7073449
105.2,130.6874549,5.236155657,353905.8819,1.725801781,578.4485773
105.4,131.7507099,5.288678209,351496.2385,1.742794151,580.5787969
105.6,132.6859024,5.341738111,351660.1904,1.748458346,582.9999412
105.8,133.7398476,5.395322213,351530.783,1.754558254,585.0070352
106,134.6258391,5.449457304,351914.5676,1.758043951,587.0479034
106.2,135.641385,5.504126398,353966.054,1.755865582,589.6913315
106.4,136.854629,5.559329785,355551.5913,1.754994332,591.8444394
106.6,137.6215214,5.615121787,357069.3209,1.756301522,594.3865268
106.8,138.6085478,5.671457523,359273.9065,1.754123149,596.7575501
107,139.7567045,5.728347066,362053.9286,1.749766301,599.2255551
107.2,140.6907794,5.785827,365458.7865,1.743666631,602.1141426
107.4,141.7668689,5.843874022,368677.2038,1.737131279,604.6486141
107.6,142.6995128,5.902515129,372158.7158,1.731031607,607.8052473
107.8,143.9374672,5.961722292,374527.1146,1.727981863,610.442146
108,145.0373759,6.021534756,376287.1124,1.727110597,612.9940503
108.2,146.2547801,6.08193932,377700.9067,1.728853539,615.9371303
108.4,147.1816424,6.142972833,377878.1227,1.733646339,618.1098459
108.6,148.296636,6.204605284,377776.2465,1.741053357,620.7892354
108.8,149.14477,6.266877206,378435.4669,1.744539053,623.1657066
109,150.4195395,6.329742418,379140.6308,1.7475891,625.5182191
109.2,151.6314657,6.393244061,380555.6053,1.748460645,628.2455569
109.4,152.879856,6.45738098,383324.5633,1.743232406,630.7854825
109.6,154.1734353,6.522158911,388238.3589,1.731032985,634.2167126
109.8,155.3206495,6.58759877,392760.7947,1.720140641,637.3058006
110,156.3692821,6.653703543,397033.5041,1.712298179,640.9484089
110.2,157.7032687,6.720450918,399165.3582,1.71099124,643.7106184
110.4,159.0770383,6.787865934,399736.1611,1.717091193,646.7594005
110.6,160.400423,6.855962159,398457.5998,1.728419535,648.84714
110.8,161.5113702,6.924758664,396649.383,1.741926351,650.8727674
111,162.8657002,6.994227907,395998.5375,1.752383302,653.6240844
111.2,164.2145176,7.064395594,397181.889,1.753690564,655.8796267
111.4,165.2490928,7.135292228,399687.8198,1.751076493,658.8989794
111.6,167.0830083,7.206840313,402519.4569,1.745848319,661.5304544
111.8,168.1564147,7.279165252,407387.5752,1.734084559,664.9644066
112,169.3028365,7.352211241,411955.9703,1.724063605,668.36894
112.2,170.5929105,7.425980217,414257.7904,1.723192359,671.6563466
112.4,171.7490705,7.500500639,415203.7535,1.726242396,674.2311431
112.6,173.2744757,7.575931079,417425.3047,1.726678278,677.4956754
112.8,174.1237756,7.651790225,416829.3189,1.736263776,679.9745753
113,175.614066,7.728554033,415194.1695,1.748899251,682.1015513
113.2,177.0082497,7.806096485,414950.9927,1.757177718,684.7112236
113.4,178.1545992,7.884830291,415696.3311,1.760227758,686.9460619
113.6,179.683992,7.963932505,415912.8786,1.765892044,689.615666
113.8,181.0870055,8.043437166,417719.1393,1.764585115,692.0924092
114,182.6984176,8.124126587,421699.0407,1.757178411,695.5367334
114.2,184.1684253,8.205637685,425108.614,1.750643088,698.3349135
114.4,185.3565826,8.287988947,429637.8101,1.741929229,701.8783796
114.6,187.1122045,8.371124617,432732.3549,1.737572438,704.7321414
114.8,188.4205977,8.455129591,435723.7476,1.734086994,707.7373422
115,189.882598,8.539966912,439906.7112,1.727987365,711.5259825
115.2,191.3826906,8.625653809,441584.3952,1.728423245,714.2675055
115.4,192.5219777,8.712229076,443896.0466,1.728423382,717.7357908
115.6,194.0641782,8.799643574,446251.3414,1.727987866,721.1485181
115.8,195.7333874,8.887926735,445631.7665,1.736266374,723.7473094
116,197.2320939,8.977109712,445463.8142,1.742802062,726.3907683
116.2,198.5536477,9.067202299,446976.7859,1.744980725,729.6433174
116.4,199.9581612,9.158193821,447343.891,1.7493379,732.1527482
116.6,201.6101779,9.250080688,449338.1008,1.7493381,735.417298
116.8,203.1224341,9.342901468,454757.3311,1.737574365,738.8376542
117,204.9096148,9.43663388,460298.975,1.72624636,742.3593566
117.2,206.5487219,9.53131853,466613.2034,1.714046933,746.5566155
117.4,208.1303368,9.626957725,472995.9908,1.700976096,750.2570066
117.6,209.9453198,9.723541055,480765.9892,1.686162478,754.933704
117.8,211.4086211,9.82112007,484185.9825,1.683984144,758.6722298
118,213.0230152,9.919667663,486264.4628,1.685727137,762.3268611
118.2,214.9829631,10.01917757,485886.4349,1.695748489,766.1013659
118.4,216.373493,10.11973044,483554.1278,1.710998199,769.4508965
118.6,218.0198215,10.22127416,480230.1828,1.727119332,771.7533169
118.8,219.5114153,10.32384981,478997.8734,1.737140634,774.443638
119,221.0718214,10.42745078,479831.6108,1.741933537,777.849838
119.2,222.7384348,10.53208453,482946.6033,1.739319531,781.6047196
119.4,224.3242709,10.63777556,486369.7096,1.734962707,784.8213283
119.6,226.1309939,10.74451176,492813.1281,1.723198986,789.1057701
119.8,227.6799255,10.8523398,496375.6828,1.719277859,792.6797728
120,229.3757785,10.96124001,500458.2743,1.714049646,796.4499127
120.2,230.84874,11.07125125,503978.7072,1.711871315,800.5894247
120.4,232.9182101,11.1823225,506878.844,1.710128746,803.9782144
120.6,234.6675541,11.29453401,508654.5253,1.712743171,807.9869845
120.8,236.4341708,11.40787176,511977.8364,1.710129167,811.6884838
121,238.4607213,11.52232826,513068.7101,1.714050719,815.0641985
121.2,240.1064744,11.63796367,515473.2263,1.715358021,819.1862867
121.4,242.1077268,11.75473379,518774.3212,1.71405115,823.4522181
121.6,243.8578198,11.87269637,520841.6506,1.714922761,826.7527414
121.716,245.0152108,11.94164615,521608.772,1.71753711,829.090018
122,247.0475322,11.94447628,524282.4117,1.71971586,834.623177
122.2,248.0335608,11.94440106,524776.6606,1.724072997,837.6360107
122.4,248.5550396,11.94436097,524255.9033,1.732351398,841.296059
122.6,249.222781,11.94430981,523982.3501,1.738451307,844.235875
122.8,249.5763903,11.94428241,525207.1844,1.742372669,848.0321188
123,250.4444117,11.94421612,526251.7149,1.746294092,851.0514843
123.2,250.685831,11.9441972,527868.3261,1.749779739,854.7540174
123.4,251.2214375,11.94415604,529871.6073,1.750651208,857.6840218
123.6,251.8808687,11.94410551,533372.2897,1.749779883,861.5794325
123.8,251.9469391,11.94409986,535278.6282,1.751958403,864.7818237
124,252.225755,11.94407812,538540.0971,1.751522735,868.8711718
124.2,252.7995894,11.94403406,541343.627,1.750215698,872.0430745
124.4,252.9080427,11.9440252,544680.9831,1.748908605,876.1291469
124.6,253.3331213,11.9439924,545401.0923,1.752394275,879.0569688
124.8,253.1810443,11.94400324,545983.8227,1.756315577,882.1776275
125,253.5180329,11.9439771,545609.7167,1.763722556,885.7951773
125.2,253.841725,11.94395196,542698.3015,1.776357961,888.1171655
125.4,254.1986585,11.94392431,539498.1247,1.790736179,890.7911034
125.6,254.2040632,11.94392324,538003.3452,1.799450225,892.9191288
125.8,254.401022,11.94390769,536969.888,1.807292891,895.2803385
126,254.3611351,11.94391004,535917.3776,1.816006932,897.9934876
126.2,254.8817831,11.94387001,537427.249,1.816006997,900.3645205
126.4,254.9798484,11.94386194,537484.8098,1.820799735,903.0537017
126.6,254.9744496,11.94386169,536479.6288,1.827770972,904.9975789
126.8,255.1788878,11.94384557,535145.6073,1.836920746,907.2879676
127,255.1090835,11.94385019,534355.3795,1.843456272,909.1261508
127.2,255.3937168,11.943828,531154.0996,1.857398782,910.7529623
127.4,255.3272367,11.94383237,529546.8809,1.866330671,912.2484621
127.6,255.6160252,11.94380988,528822.6248,1.872212689,913.8202482
127.8,255.582371,11.94381176,528236.4032,1.877005411,915.2748884
128,256.0240705,11.9437777,527129.8842,1.883976705,916.9834297
128.2,256.0008043,11.9437788,529454.8468,1.880055383,918.7486095
128.4,255.9729675,11.94378025,534057.4842,1.87046993,921.3571548
128.6,256.097626,11.94377016,536866.7512,1.865677222,923.4143609
128.8,255.92228,11.94378276,539956.0787,1.860448773,925.6077526
129,256.5771406,11.94373258,544232.2653,1.853041918,928.5802625
129.2,256.4350361,11.94374267,544172.54,1.85652752,930.3062135
129.4,256.3577525,11.94374785,541634.6313,1.867420069,931.9798631
129.6,256.7117774,11.94372042,538914.5226,1.878312673,933.2797922
129.8,256.9083208,11.9437049,536173.9622,1.889205257,934.3334626
130,256.9087392,11.94370421,534231.7052,1.897919304,935.3631515
130.2,256.9029248,11.94370399,534855.2812,1.899662114,936.9071422
130.4,257.1929599,11.9436814,535616.9149,1.90096926,938.4642194
130.6,257.0832658,11.94368903,538670.5057,1.894869414,940.199978
130.8,257.32053,11.94367043,543869.6426,1.882669781,942.4969034
131,257.3404778,11.94366826,548714.2832,1.872212928,945.3157467
131.2,257.3010064,11.94367059,549863.0132,1.87134152,947.1332321
131.4,257.3562734,11.94366575,550355.129,1.873084337,949.1751766
131.6,257.5652823,11.94364928,548477.3599,1.881362709,950.39883
131.722,258.0768668,11.9436102,544932.3195,1.893998144,950.8325195
132.5,257.7322796,11.80151087,1.7977E+308,1.82689994,0
132.7,257.5273022,11.68209477,1.7977E+308,1.64956906,0
132.9,257.32648,11.56267835,1.7977E+308,1.399911599,0
133.1,257.0001711,11.44327143,1.7977E+308,1.088820108,0
133.3,256.8392387,11.323852,1.7977E+308,0.748536584,0
133.5,256.8179207,11.20442201,1.7977E+308,0.472737015,0
133.7,256.3353767,11.0850269,1.7977E+308,0.277106665,0
133.9,255.9201468,10.96562669,1.7977E+308,0.148574481,0
134.1,255.9594945,10.84619212,1.7977E+308,0.062305428,0
134.3,255.8376209,10.72676973,1.7977E+308,0.008714046,0
134.5,255.4514773,10.60736733,1.7977E+308,0.018299496,0
134.7,255.2780794,10.48794884,1.7977E+308,0.023963625,0
134.9,254.851215,10.36854952,1.7977E+308,0.024399326,0
135.1,254.8257418,10.24911985,1.7977E+308,0.017863793,0
135.3,254.7254752,10.12969583,1.7977E+308,0.011328259,0
135.5,254.3135695,10.01029538,1.7977E+308,0.016992387,0
135.7,254.2922514,9.890865389,1.7977E+308,0.029627752,0
135.9,253.885332,9.771464559,1.7977E+308,0.043570223,0
136.1,253.643789,9.652051224,1.7977E+308,0.049670053,0
136.3,253.6316124,9.532620544,1.7977E+308,0.049234351,0
136.5,253.5246975,9.413197028,1.7977E+308,0.040956008,0
136.7,252.984812,9.293806253,1.7977E+308,0.030063452,0
136.9,252.9003351,9.17438104,1.7977E+308,0.018299492,0
137.1,252.5640539,9.054974869,1.7977E+308,0.009149746,0
137.3,252.2718176,8.935565367,1.7977E+308,0.005228426,0
137.5,251.9081122,8.816161269,1.7977E+308,0.007406937,0
137.7,251.8419181,8.696734674,1.7977E+308,0.01002115,0
137.9,251.5255818,8.577326995,1.7977E+308,0.012635362,0
138.1,251.3580012,8.457908066,1.7977E+308,0.013506767,0
138.3,251.3807282,8.338474747,1.7977E+308,0.014378171,0
138.5,250.9048327,8.219079133,1.7977E+308,0.010021149,0
138.7,250.5785239,8.099672208,1.7977E+308,0.003921319,0
138.9,250.4741021,7.980248504,1.7977E+308,0.007842638,0
139.1,250.1095657,7.860844469,1.7977E+308,0.01437817,0
139.3,250.0300751,7.741418879,1.7977E+308,0.02483502,0
139.5,249.9447672,7.62199373,1.7977E+308,0.031806254,0
139.7,249.3998956,7.502603332,1.7977E+308,0.029627742,0
139.9,249.2780221,7.383180947,1.7977E+308,0.027013529,0
140.1,249.16529,7.263757871,1.7977E+308,0.030934848,0
140.3,248.6495047,7.144365274,1.7977E+308,0.033113357,0
140.5,248.3689031,7.024954892,1.7977E+308,0.034420462,0
140.7,248.4290267,6.905518745,1.7977E+308,0.030499144,0
140.9,248.1309733,6.786109683,1.7977E+308,0.024399315,0
141.1,247.4921946,6.666726386,1.7977E+308,0.017428081,0
141.3,247.2049447,6.547316507,1.7977E+308,0.013942465,0
141.5,247.256758,6.427880988,1.7977E+308,0.016120975,0
141.7,247.0434704,6.308465516,1.7977E+308,0.019606591,0
141.9,246.8276897,6.189050233,1.7977E+308,0.023092206,0
142.1,246.4884999,6.069644281,1.7977E+308,0.024835014,0
142.3,246.4850492,5.950212941,1.7977E+308,0.027884928,0
142.5,246.2056942,5.830802465,1.7977E+308,0.024399311,0
142.7,245.8045922,5.711401196,1.7977E+308,0.019170887,0
142.9,245.4296679,5.591997946,1.7977E+308,0.012635357,0
143.1,245.2878495,5.47257707,1.7977E+308,0.011328251,0
143.3,245.0496308,5.353163483,1.7977E+308,0.013942463,0
143.5,244.7977,5.233750933,1.7977E+308,0.011328251,0
143.7,244.4817794,5.114343222,1.7977E+308,0.003485615,0
143.9,244.3549197,4.994921215,1.7977E+308,0.00217851,0
144.1,243.8100483,4.875530817,1.7977E+308,0.010892548,0
144.3,243.8161546,4.756098754,1.7977E+308,0.01829948,0
144.5,243.4428924,4.636695379,1.7977E+308,0.020913691,0
144.7,243.22171,4.517280504,1.7977E+308,0.019170883,0
144.9,242.9377843,4.397870374,1.7977E+308,0.01612097,0
145.1,242.4859892,4.278472938,1.7977E+308,0.007406932,0
145.3,242.2211774,4.159061362,1.7977E+308,0.011328249,0
145.5,241.9459776,4.039650571,1.7977E+308,0.017428074,0
145.7,241.6923848,3.920238147,1.7977E+308,0.017863776,0
145.9,241.3955781,3.800828991,1.7977E+308,0.015685266,0
146.1,241.00154,3.681427187,1.7977E+308,0.013506757,0
146.3,240.8239871,3.562009013,1.7977E+308,0.023527898,0
146.5,240.5296735,3.442599668,1.7977E+308,0.035291847,0
146.7,240.2789894,3.323187024,1.7977E+308,0.046184392,0
146.9,240.0096069,3.203775793,1.7977E+308,0.049670005,0
147.1,239.7801142,3.084361547,1.7977E+308,0.047055793,0
147.3,239.3860762,2.964959743,1.7977E+308,0.047927196,0
147.5,238.886081,2.845565951,1.7977E+308,0.047491492,0
147.7,238.8626854,2.72613612,1.7977E+308,0.039213159,0
147.9,238.3294488,2.606744842,1.7977E+308,0.034638289,0
148.1,238.0729475,2.487332638,1.7977E+308,0.033549034,0
148.3,237.7707391,2.36792389,1.7977E+308,0.028320612,0
148.5,237.5819672,2.248506564,1.7977E+308,0.023092191,0
148.7,237.1541774,2.129704467,1.7977E+308,0.023527892,0
148.9,236.6086651,2.009119808,1.7977E+308,0.02832061,0
149.1,236.5516126,1.889692522,1.7977E+308,0.034420434,0
149.3,236.2534645,1.770880621,1.7977E+308,0.040084555,0
149.5,235.878956,1.651477341,1.7977E+308,0.040955957,0
149.7,235.3772989,1.532083675,1.7977E+308,0.035727536,0
149.9,235.1149803,1.41267191,1.7977E+308,0.027013502,0
150.1,234.8501686,1.293260335,1.7977E+308,0.016120961,0
150.266,234.2437186,1.194177965,1.7977E+308,0.010021137,0
225.5,233.6343725,1.062004724,1.7977E+308,0.050105696,0
225.7,233.2781467,0.942600061,1.7977E+308,0.044441572,0
225.9,233.0731697,0.82318396,1.7977E+308,0.037034643,0
226.1,232.7194371,0.703779108,1.7977E+308,0.030499117,0
226.3,232.2111317,0.584385945,1.7977E+308,0.026577801,0
226.5,231.8017196,0.464985304,1.7977E+308,0.023527889,0
226.7,231.2161279,0.345597985,1.7977E+308,0.028756307,0
226.9,230.466822,0.226223046,1.7977E+308,0.031806217,0
227.1,229.3626635,0.10687494,1.7977E+308,0.028756304,0
227.28,227.9200783,-0.000504414,1.7977E+308,0.029192002,0
,,,,,